Workbook

Sheet 00_Cover
A1: Grupo de Inversiones Suramericana S.A. — Institutional Financial Model
A2: Insurance / financial holding company | USD millions | As of 2026-07-15
A4: Model field | B4: Value
A5: Ticker / identifier | B5: BVC: GRUPOSURA
A6: Model archetype | B6: Financial institution / residual income
A7: Decision readiness | B7: Source-backed summary / residual-income framework
A8: Reporting currency | B8: COP
A9: Model currency | B9: USD millions
A10: Market-data date | B10: Not applicable
A11: Current market price | B11: Not available
A12: Primary source | B12: https://gruposura.com/relacion-con-inversionistas/informes/informe-anual-2025/
A13: Key limitation | B13: 2025 consolidated revenue and controlling net income from the annual report page; share-count and detailed balance inputs remain user-fillable.
A15: Institutional-grade means auditable sources, explicit assumptions, formula-driven forecasts, valuation, sensitivities, checks and governance. It does not mean that missing private-company disclosures have been invented.

Sheet Sources
A1: Sources and data lineage
A2: Every hardcode is mapped to a source, date, currency and transformation.
A4: Source ID | B4: Use | C4: URL / reference | D4: As of | E4: Source currency | F4: Transformation | G4: Limitation | H4: Status
A5: S1 | B5: Historical financials | C5: https://gruposura.com/relacion-con-inversionistas/informes/informe-anual-2025/ | D5: Latest annual filing/results | E5: COP | F5: Converted at current snapshot FX (COP to USD = 0.00031032) | G5: 2025 consolidated revenue and controlling net income from the annual report page; share-count and detailed balance inputs remain user-fillable. | H5: Source-backed summary / residual-income framework
A6: S2 | B6: Market price | C6: Not applicable | D6: 2026-07-15 | E6: N/A | F6: Dated market input; not a historical financial source | G6: Market prices move after the as-of date | H6: Not loaded
A7: S3 | B7: FX snapshot | C7: Yahoo Finance COP/USD chart snapshot | D7: 2026-07-15 | E7: COP | F7: COP per USD, inverted | G7: Current FX used across historical years for comparability; not historical spot | H7: Loaded
A8: S4 | B8: Forecast assumptions | C8: Model Assumptions sheet | D8: 2026-07-15 | E8: USD | F8: User-editable scenario inputs | G8: Forecasts are estimates, not reported facts | H8: Model input

Sheet Historical
A1: Historical financials
A2: USD millions; blanks are intentional when the cited source did not support a defensible value.
A4: Metric | B4: 2021A | C4: 2022A | D4: 2023A | E4: 2024A | F4: 2025A | G4: Source tag / note | H4: Quality
A5: Assets | G5: Issuer results / manual source mapping | H5: Missing / not inferred
A6: Liabilities | G6: Issuer results / manual source mapping | H6: Missing / not inferred
A7: Equity | G7: Issuer results / manual source mapping | H7: Missing / not inferred
A8: Net income | F8: 558.57774 | G8: Issuer results / manual source mapping | H8: Source-backed / see note
A9: Loans | G9: Issuer results / manual source mapping | H9: Missing / not inferred
A10: Deposits | G10: Issuer results / manual source mapping | H10: Missing / not inferred
A11: Interest income | G11: Issuer results / manual source mapping | H11: Missing / not inferred
A12: Interest expense | G12: Issuer results / manual source mapping | H12: Missing / not inferred
A13: Cash | G13: Issuer results / manual source mapping | H13: Missing / not inferred
A14: Diluted shares (mm) | G14: Issuer results / manual source mapping | H14: Missing / not inferred

Sheet Assumptions
A1: Assumptions and scenarios
A2: Blue-font cells are user inputs. Scenario selector: 1 = Base, 2 = Bull, 3 = Bear.
A3: Scenario selector | B3: 1
A4: Metric | B4: Bear | C4: Base | D4: Bull | E4: Active | F4: Rationale / source
A5: Asset growth | B5: 0.03 | C5: 0.06 | D5: 0.09 | E5: =CHOOSE($B$3,C5,D5,B5) -> 0.06 | F5: Historical trend bounded to a reasonable range
A6: Target ROE | B6: 0.09 | C6: 0.12 | D6: 0.15 | E6: =CHOOSE($B$3,C6,D6,B6) -> 0.12 | F6: Latest reported/inferred ROE with scenario spread
A7: Dividend payout | B7: 0.45 | C7: 0.35 | D7: 0.25 | E7: =CHOOSE($B$3,C7,D7,B7) -> 0.35 | F7: Explicit capital-retention policy assumption
A8: Cost of equity | B8: 0.14 | C8: 0.12 | D8: 0.105 | E8: =CHOOSE($B$3,C8,D8,B8) -> 0.12 | F8: USD investor required return
A9: Terminal growth | B9: 0.02 | C9: 0.03 | D9: 0.04 | E9: =CHOOSE($B$3,C9,D9,B9) -> 0.03 | F9: Long-run nominal USD growth

Sheet Forecast
A1: Forecast model
A2: Formula-driven five-year projection in USD millions.
A4: Metric | B4: 2025A | C4: 2026E | D4: 2027E | E4: 2028E | F4: 2029E | G4: 2030E
A5: Assets | B5: 0 | C5: =B5*(1+Assumptions!$E$5) -> 0 | D5: =C5*(1+Assumptions!$E$5) -> 0 | E5: =D5*(1+Assumptions!$E$5) -> 0 | F5: =E5*(1+Assumptions!$E$5) -> 0 | G5: =F5*(1+Assumptions!$E$5) -> 0
A6: Asset growth | C6: =IF(B5<>0,C5/B5-1,0) -> 0 | D6: =IF(C5<>0,D5/C5-1,0) -> 0 | E6: =IF(D5<>0,E5/D5-1,0) -> 0 | F6: =IF(E5<>0,F5/E5-1,0) -> 0 | G6: =IF(F5<>0,G5/F5-1,0) -> 0
A7: Equity | B7: 0 | C7: =B12 -> 0 | D7: =C12 -> 0 | E7: =D12 -> 0 | F7: =E12 -> 0 | G7: =F12 -> 0
A8: Equity / assets | C8: =IF(C5<>0,C7/C5,0) -> 0 | D8: =IF(D5<>0,D7/D5,0) -> 0 | E8: =IF(E5<>0,E7/E5,0) -> 0 | F8: =IF(F5<>0,F7/F5,0) -> 0 | G8: =IF(G5<>0,G7/G5,0) -> 0
A9: Net income | B9: 558.57774 | C9: =C7*Assumptions!$E$6 -> 0 | D9: =D7*Assumptions!$E$6 -> 0 | E9: =E7*Assumptions!$E$6 -> 0 | F9: =F7*Assumptions!$E$6 -> 0 | G9: =G7*Assumptions!$E$6 -> 0
A10: ROE | C10: =IF(C7<>0,C9/C7,0) -> 0 | D10: =IF(D7<>0,D9/D7,0) -> 0 | E10: =IF(E7<>0,E9/E7,0) -> 0 | F10: =IF(F7<>0,F9/F7,0) -> 0 | G10: =IF(G7<>0,G9/G7,0) -> 0
A11: Dividends | C11: =C9*Assumptions!$E$7 -> 0 | D11: =D9*Assumptions!$E$7 -> 0 | E11: =E9*Assumptions!$E$7 -> 0 | F11: =F9*Assumptions!$E$7 -> 0 | G11: =G9*Assumptions!$E$7 -> 0
A12: Ending book value | B12: 0 | C12: =C7+C9-C11 -> 0 | D12: =D7+D9-D11 -> 0 | E12: =E7+E9-E11 -> 0 | F12: =F7+F9-F11 -> 0 | G12: =G7+G9-G11 -> 0

Sheet Valuation
A1: Residual-income valuation
A2: Valuation is formula-driven and scenario-sensitive; private-company outputs are enterprise-value ranges only.
A4: Metric | B4: Year 1 | C4: Year 2 | D4: Year 3 | E4: Year 4 | F4: Year 5 | G4: Total / output
A5: Beginning book value | B5: =Forecast!C7 -> 0 | C5: =Forecast!D7 -> 0 | D5: =Forecast!E7 -> 0 | E5: =Forecast!F7 -> 0 | F5: =Forecast!G7 -> 0
A6: Residual income | B6: =B5*(Forecast!C10-Assumptions!$E$8) -> 0 | C6: =C5*(Forecast!D10-Assumptions!$E$8) -> 0 | D6: =D5*(Forecast!E10-Assumptions!$E$8) -> 0 | E6: =E5*(Forecast!F10-Assumptions!$E$8) -> 0 | F6: =F5*(Forecast!G10-Assumptions!$E$8) -> 0
A7: Discount factor | B7: =1/(1+Assumptions!$E$8)^1 -> 0.89285714 | C7: =1/(1+Assumptions!$E$8)^2 -> 0.79719388 | D7: =1/(1+Assumptions!$E$8)^3 -> 0.71178025 | E7: =1/(1+Assumptions!$E$8)^4 -> 0.63551808 | F7: =1/(1+Assumptions!$E$8)^5 -> 0.56742686
A8: PV residual income | B8: =B6*B7 -> 0 | C8: =C6*C7 -> 0 | D8: =D6*D7 -> 0 | E8: =E6*E7 -> 0 | F8: =F6*F7 -> 0
A10: Output | B10: Value
A11: Current book value | B11: =Forecast!B7 -> 0
A12: PV explicit residual income | B12: =SUM(B8:F8) -> 0
A13: Terminal residual income | B13: =F6*(1+Assumptions!$E$9) -> 0
A14: PV terminal value | B14: =IF(Assumptions!$E$8>Assumptions!$E$9,B13/(Assumptions!$E$8-Assumptions!$E$9)*F7,0) -> 0
A15: Implied equity value | B15: =B11+B12+B14 -> 0
A16: Diluted shares (mm) | B16: 0
A17: Implied value / share | B17: =IF(B16>0,B15/B16,0) -> 0
A18: Current market price

Sheet Sensitivity
A1: Valuation sensitivity
A2: Equity value sensitivity to cost of equity and terminal growth.
A4: CoE / g | B4: 0.1 | C4: 0.11 | D4: 0.12 | E4: 0.13 | F4: 0.14
A5: 0.01 | B5: =Forecast!$B$7+SUMPRODUCT(Valuation!$B$6:$F$6,1/(1+B$4)^{1,2,3,4,5})+IF(B$4>$A5,Valuation!$F$6*(1+$A5)/(B$4-$A5)/(1+B$4)^5,0) -> 0 | C5: =Forecast!$B$7+SUMPRODUCT(Valuation!$B$6:$F$6,1/(1+C$4)^{1,2,3,4,5})+IF(C$4>$A5,Valuation!$F$6*(1+$A5)/(C$4-$A5)/(1+C$4)^5,0) -> 0 | D5: =Forecast!$B$7+SUMPRODUCT(Valuation!$B$6:$F$6,1/(1+D$4)^{1,2,3,4,5})+IF(D$4>$A5,Valuation!$F$6*(1+$A5)/(D$4-$A5)/(1+D$4)^5,0) -> 0 | E5: =Forecast!$B$7+SUMPRODUCT(Valuation!$B$6:$F$6,1/(1+E$4)^{1,2,3,4,5})+IF(E$4>$A5,Valuation!$F$6*(1+$A5)/(E$4-$A5)/(1+E$4)^5,0) -> 0 | F5: =Forecast!$B$7+SUMPRODUCT(Valuation!$B$6:$F$6,1/(1+F$4)^{1,2,3,4,5})+IF(F$4>$A5,Valuation!$F$6*(1+$A5)/(F$4-$A5)/(1+F$4)^5,0) -> 0
A6: 0.02 | B6: =Forecast!$B$7+SUMPRODUCT(Valuation!$B$6:$F$6,1/(1+B$4)^{1,2,3,4,5})+IF(B$4>$A6,Valuation!$F$6*(1+$A6)/(B$4-$A6)/(1+B$4)^5,0) -> 0 | C6: =Forecast!$B$7+SUMPRODUCT(Valuation!$B$6:$F$6,1/(1+C$4)^{1,2,3,4,5})+IF(C$4>$A6,Valuation!$F$6*(1+$A6)/(C$4-$A6)/(1+C$4)^5,0) -> 0 | D6: =Forecast!$B$7+SUMPRODUCT(Valuation!$B$6:$F$6,1/(1+D$4)^{1,2,3,4,5})+IF(D$4>$A6,Valuation!$F$6*(1+$A6)/(D$4-$A6)/(1+D$4)^5,0) -> 0 | E6: =Forecast!$B$7+SUMPRODUCT(Valuation!$B$6:$F$6,1/(1+E$4)^{1,2,3,4,5})+IF(E$4>$A6,Valuation!$F$6*(1+$A6)/(E$4-$A6)/(1+E$4)^5,0) -> 0 | F6: =Forecast!$B$7+SUMPRODUCT(Valuation!$B$6:$F$6,1/(1+F$4)^{1,2,3,4,5})+IF(F$4>$A6,Valuation!$F$6*(1+$A6)/(F$4-$A6)/(1+F$4)^5,0) -> 0
A7: 0.03 | B7: =Forecast!$B$7+SUMPRODUCT(Valuation!$B$6:$F$6,1/(1+B$4)^{1,2,3,4,5})+IF(B$4>$A7,Valuation!$F$6*(1+$A7)/(B$4-$A7)/(1+B$4)^5,0) -> 0 | C7: =Forecast!$B$7+SUMPRODUCT(Valuation!$B$6:$F$6,1/(1+C$4)^{1,2,3,4,5})+IF(C$4>$A7,Valuation!$F$6*(1+$A7)/(C$4-$A7)/(1+C$4)^5,0) -> 0 | D7: =Forecast!$B$7+SUMPRODUCT(Valuation!$B$6:$F$6,1/(1+D$4)^{1,2,3,4,5})+IF(D$4>$A7,Valuation!$F$6*(1+$A7)/(D$4-$A7)/(1+D$4)^5,0) -> 0 | E7: =Forecast!$B$7+SUMPRODUCT(Valuation!$B$6:$F$6,1/(1+E$4)^{1,2,3,4,5})+IF(E$4>$A7,Valuation!$F$6*(1+$A7)/(E$4-$A7)/(1+E$4)^5,0) -> 0 | F7: =Forecast!$B$7+SUMPRODUCT(Valuation!$B$6:$F$6,1/(1+F$4)^{1,2,3,4,5})+IF(F$4>$A7,Valuation!$F$6*(1+$A7)/(F$4-$A7)/(1+F$4)^5,0) -> 0
A8: 0.04 | B8: =Forecast!$B$7+SUMPRODUCT(Valuation!$B$6:$F$6,1/(1+B$4)^{1,2,3,4,5})+IF(B$4>$A8,Valuation!$F$6*(1+$A8)/(B$4-$A8)/(1+B$4)^5,0) -> 0 | C8: =Forecast!$B$7+SUMPRODUCT(Valuation!$B$6:$F$6,1/(1+C$4)^{1,2,3,4,5})+IF(C$4>$A8,Valuation!$F$6*(1+$A8)/(C$4-$A8)/(1+C$4)^5,0) -> 0 | D8: =Forecast!$B$7+SUMPRODUCT(Valuation!$B$6:$F$6,1/(1+D$4)^{1,2,3,4,5})+IF(D$4>$A8,Valuation!$F$6*(1+$A8)/(D$4-$A8)/(1+D$4)^5,0) -> 0 | E8: =Forecast!$B$7+SUMPRODUCT(Valuation!$B$6:$F$6,1/(1+E$4)^{1,2,3,4,5})+IF(E$4>$A8,Valuation!$F$6*(1+$A8)/(E$4-$A8)/(1+E$4)^5,0) -> 0 | F8: =Forecast!$B$7+SUMPRODUCT(Valuation!$B$6:$F$6,1/(1+F$4)^{1,2,3,4,5})+IF(F$4>$A8,Valuation!$F$6*(1+$A8)/(F$4-$A8)/(1+F$4)^5,0) -> 0
A9: 0.05 | B9: =Forecast!$B$7+SUMPRODUCT(Valuation!$B$6:$F$6,1/(1+B$4)^{1,2,3,4,5})+IF(B$4>$A9,Valuation!$F$6*(1+$A9)/(B$4-$A9)/(1+B$4)^5,0) -> 0 | C9: =Forecast!$B$7+SUMPRODUCT(Valuation!$B$6:$F$6,1/(1+C$4)^{1,2,3,4,5})+IF(C$4>$A9,Valuation!$F$6*(1+$A9)/(C$4-$A9)/(1+C$4)^5,0) -> 0 | D9: =Forecast!$B$7+SUMPRODUCT(Valuation!$B$6:$F$6,1/(1+D$4)^{1,2,3,4,5})+IF(D$4>$A9,Valuation!$F$6*(1+$A9)/(D$4-$A9)/(1+D$4)^5,0) -> 0 | E9: =Forecast!$B$7+SUMPRODUCT(Valuation!$B$6:$F$6,1/(1+E$4)^{1,2,3,4,5})+IF(E$4>$A9,Valuation!$F$6*(1+$A9)/(E$4-$A9)/(1+E$4)^5,0) -> 0 | F9: =Forecast!$B$7+SUMPRODUCT(Valuation!$B$6:$F$6,1/(1+F$4)^{1,2,3,4,5})+IF(F$4>$A9,Valuation!$F$6*(1+$A9)/(F$4-$A9)/(1+F$4)^5,0) -> 0

Sheet Checks
A1: Model checks
A2: All critical checks should read PASS before decision use.
A4: Check | B4: Result | C4: Severity | D4: Interpretation
A5: Forecast assets non-negative | B5: =IF(MIN(Forecast!C5:G5)>=0,"PASS","FAIL") -> PASS | C5: Critical | D5: No negative asset balance
A6: Ending equity non-negative | B6: =IF(MIN(Forecast!C12:G12)>=0,"PASS","FAIL") -> PASS | C6: Critical | D6: Capital remains positive
A7: ROE within model bounds | B7: =IF(AND(MIN(Forecast!C10:G10)>-0.5,MAX(Forecast!C10:G10)<0.5),"PASS","FAIL") -> PASS | C7: Critical | D7: Screens extreme profitability
A8: Discount rate exceeds terminal growth | B8: =IF(Assumptions!E8>Assumptions!E9,"PASS","FAIL") -> PASS | C8: Critical | D8: Required for convergent residual-income terminal value
A9: Historical source coverage | B9: LIMITED | C9: Readiness | D9: Manual/summary sources or missing standalone disclosures remain explicitly limited
A11: Overall gate | B11: =IF(COUNTIF(B5:B9,"FAIL")=0,IF(COUNTIF(B5:B9,"LIMITED")=0,"PASS","PASS WITH LIMITATIONS"),"FAIL") -> PASS WITH LIMITATIONS
A12: Decision use | B12: Source-backed summary / residual-income framework

Sheet Sector_KPIs
A1: Sector KPI framework
A2: A decision-useful model requires sector drivers beyond the three statements.
A4: KPI | B4: Historical | C4: Forecast | D4: Status / source requirement
A5: Loan growth | D5: Input-ready; populate from issuer operating disclosures
A6: Deposit growth | D6: Input-ready; populate from issuer operating disclosures
A7: Net interest margin | D7: Input-ready; populate from issuer operating disclosures
A8: Cost of risk | D8: Input-ready; populate from issuer operating disclosures
A9: NPL ratio | D9: Input-ready; populate from issuer operating disclosures
A10: Coverage ratio | D10: Input-ready; populate from issuer operating disclosures
A11: CET1 / capital ratio | D11: Input-ready; populate from issuer operating disclosures
A12: Liquidity ratio | D12: Input-ready; populate from issuer operating disclosures
A13: ROE | D13: Input-ready; populate from issuer operating disclosures
A14: Tangible book value per share | D14: Input-ready; populate from issuer operating disclosures

Sheet Change_Log
A1: Change log and governance
A2: Version history and model-owner review record.
A4: Date | B4: Version | C4: Author | D4: Change | E4: Evidence | F4: Reviewer status
A5: 2026-07-15 | B5: 1.0 | C5: Codex | D5: Initial institutional model framework and source pack | E5: https://gruposura.com/relacion-con-inversionistas/informes/informe-anual-2025/ | F5: Builder-verified
A6: 2026-07-15 | B6: 1.0 | C6: Codex | D6: Formula, package and visual QA | E6: Checks sheet and preview artifacts | F6: Pending owner investment judgment
A7: 46224 | B7: Elevación statement-grade (patrón Samsung): IS_Hist/CI_Hist/BS_Hist/CF_Hist auditados FY2022A-FY2025A (COP mm, constantes publicadas; FY2021A no abastecido), Checks_TieOut (28 tie-outs + continuidad de caja, tolerancia COP 1,000mm por redondeo del emisor), Sources_Audited (jerarquía FY2023 documentada: dictamen=Informe Anual 2023, detalle=4T sin dictamen), USD_Bridge (FY2023 con tasas del emisor; FY2024-25 gap documentado — sin tasa fabricada), schedules sectoriales Investment_Portfolio/Equity_Method/Segments (Notas 6/10/24, FY2024-25), Assumptions_IS+Forecast_IS (sheets nuevos) IS-level driver-built 5yr Base/Bull/Bear (PARTIAL — BS/CF forecast pendiente). Legacy stubs 00_Cover/Sources/Historical/Assumptions/Forecast/Valuation/Sensitivity/Checks/Sector_KPIs dejados intactos (no se tocaron para no romper su wiring cruzado). Root model intacto; build en the maintainer's archive. | C7: Claude (run 41538014)

Sheet IS_Hist
A1: Grupo de Inversiones Suramericana S.A. — Estado de Resultados Consolidado (auditado)
A2: COP millones. FY2022-23 por EEFF Consolidados FY2023 4T (pp.10-11) con dictamen en Informe Anual 2023 (pp.114-ss); FY2024-25 por EEFF Consolidados-Notas-Dictamen FY2025 4T (pp.8-9, comparativo FY2024 reexpresado por desconsolidación EPS Suramericana). FY2021 no sourced esta pasada.
A4: Line item | B4: FY2021A | C4: FY2022A | D4: FY2023A | E4: FY2024A | F4: FY2025A | G4: Note ref
A5: Ingresos
A6: Primas de seguros | C6: 22133590 | D6: 22055173 | E6: 23916068 | F6: 24160789 | G6: IS p.9(FY25)/p.11(FY23,img)
A7: Primas y servicios de salud | C7: 7567570 | D7: 9466458 | G7: IS p.11(FY23,img) — EPS Suramericana desconsolidada 2024
A8: Primas emitidas | C8: 29701160 | D8: 31521631 | E8: 23916068 | F8: 24160789 | G8: IS subtotal
A9: Primas cedidas en reaseguro | C9: -3956158 | D9: -4736885 | E9: -4180445 | F9: -4502294 | G9: IS
A10: Primas retenidas (netas) | C10: 25745002 | D10: 26784746 | E10: 19735623 | F10: 19658495 | G10: IS subtotal
A11: Reservas netas de producción | C11: -4949853 | D11: -3603764 | E11: -4208631 | F11: -5045098 | G11: IS
A12: Primas retenidas devengadas | C12: 20795149 | D12: 23180982 | E12: 15526992 | F12: 14613397 | G12: IS subtotal
A13: Rendimiento neto inversiones costo amortizado y otros | C13: 1759441 | D13: 2879980 | E13: 3189611 | F13: 4550751 | G13: IS Nota 5/6.1.2, 27
A14: Ganancia (pérdida) neta inversiones a valor razonable | C14: -160989 | D14: 1559616 | E14: 1180325 | F14: 1219546 | G14: IS Nota 5/6.1.2
A15: Ingresos por comisiones | C15: 3481253 | D15: 4809987 | E15: 4629762 | F15: 5059124 | G15: IS Nota 24/25
A16: Prestación de servicios | C16: 282828 | D16: 316251 | E16: 5326816 | F16: 1750772 | G16: IS Nota 25/26
A17: Ganancia por método de participación | C17: 2038764 | D17: 1792706 | E17: 1522597 | F17: 920191 | G17: IS Nota 9/10
A18: Ganancia en venta de inversiones | C18: 101605 | D18: 234164 | G18: IS Nota 5 (FY22-23 caption)
A19: Ganancia realización activos no corrientes mantenidos p/venta | E19: 4017061 | F19: 804 | G19: IS Nota 27 (FY24-25 caption)
A20: Ganancia realización inversiones a valor razonable | E20: 306267 | F20: 107448 | G20: IS Nota 6.1.2 (FY24-25 caption)
A21: Otros ingresos | C21: 887743 | D21: 755521 | E21: 627233 | F21: 484686 | G21: IS Nota 26/27
A22: Total ingresos | C22: 29185794 | D22: 35529207 | E22: 36326664 | F22: 28706719 | G22: IS subtotal (published)
A24: Costos y gastos
A25: Siniestros de seguros | C25: -11270463 | D25: -11003254 | E25: -12242736 | F25: -12266254 | G25: IS
A26: Siniestros y servicios de salud | C26: -7438137 | D26: -9289624 | G26: IS (FY22-23 caption)
A27: Siniestros totales | C27: -18708600 | D27: -20292878 | E27: -12242736 | F27: -12266254 | G27: IS subtotal Nota 6
A28: Reembolso de siniestros | C28: 3621040 | D28: 1898688 | E28: 1342412 | F28: 1532926 | G28: IS Nota 6
A29: Siniestros retenidos | C29: -15087560 | D29: -18394190 | E29: -10900324 | F29: -10733328 | G29: IS subtotal Nota 6
A30: Gastos por comisiones a intermediarios | C30: -3217027 | D30: -3749807 | E30: -3674241 | F30: -3859118 | G30: IS Nota 24/25
A31: Costos y gastos de seguros | C31: -1814645 | D31: -2179354 | E31: -1977250 | F31: -1965832 | G31: IS Nota 6
A32: Costos por prestación de servicios | C32: -388900 | D32: -433552 | E32: -5174080 | F32: -1743955 | G32: IS Nota 25/26
A33: Gastos administrativos | C33: -2037521 | D33: -2430275 | E33: -2379268 | F33: -2679514 | G33: IS Nota 27/28
A34: Beneficios a empleados | C34: -1963865 | D34: -2429889 | E34: -2355512 | F34: -2245715 | G34: IS Nota 15/16
A35: Honorarios | C35: -397866 | D35: -515467 | E35: -816793 | F35: -483479 | G35: IS Nota 28/29
A36: Depreciación y amortización | C36: -541133 | D36: -625109 | E36: -543834 | F36: -570383 | G36: IS Notas 11-13
A37: Otros gastos | C37: -33639 | D37: -123356 | E37: -61012 | F37: -50128 | G37: IS Nota 26/27
A38: Total costos y gastos | C38: -25482156 | D38: -30881009 | E38: -27882314 | F38: -24331452 | G38: IS subtotal (published)
... A43: Intereses y otros | C43: -986102 | D43: -1128275 | E43: -1452007 | F43: -1348764 | G43: IS Nota 29/30
A44: Otros costos financieros | E44: -17577 | G44: IS (FY24 caption only)
A45: Resultado financiero | C45: -982457 | D45: -1046667 | E45: -1636282 | F45: -1383014 | G45: IS subtotal
A46: Ganancia antes de impuestos (operaciones continuas) | C46: 2721181 | D46: 3601531 | E46: 6808068 | F46: 2992253 | G46: IS subtotal
...

Sheet CI_Hist
A1: Grupo de Inversiones Suramericana S.A. — Estado de Resultados Integrales Consolidado (auditado)
A2: COP millones. Misma base de fuentes que IS_Hist.
A4: Line item | B4: FY2021A | C4: FY2022A | D4: FY2023A | E4: FY2024A | F4: FY2025A | G4: Note ref
A5: Ganancia neta del período | C5: 2345341 | D5: 1934977 | E5: 6402006 | F5: 2256175 | G5: CI
A6: Partidas que no se reclasificarán al resultado, neto de impuestos
A7: Ganancia (pérdida) inversiones en instrumentos de patrimonio | C7: -20595 | D7: 15784 | E7: -18617 | F7: 1028 | G7: CI Nota 21/22
A8: Ganancia (pérdida) por revaluación de propiedades y equipo | C8: -46029 | D8: 88374 | E8: -10008 | F8: 73745 | G8: CI Nota 21/22
A9: Nuevas mediciones de planes de beneficios definidos | C9: 6747 | D9: -14256 | E9: 111 | F9: 2489 | G9: CI Nota 21/22
A10: Participación ORI asociadas/negocios conjuntos (no reclasificable) | E10: -212754 | F10: 132950 | G10: CI Nota 22 (FY24-25 caption only)
A11: Total no reclasificará al resultado, neto de impuestos | C11: -59877 | D11: 89902 | E11: -241268 | F11: 210212 | G11: CI subtotal
A12: Partidas que se reclasificarán al resultado, neto de impuestos
A13: (Pérdida) ganancia diferencias de cambio de conversión | C13: 3206935 | D13: -3521646 | E13: 321526 | F13: -678057 | G13: CI Nota 21/22
A14: Ganancia (pérdida) por cobertura de flujo de efectivo | C14: -108109 | D14: -22667 | E14: 18140 | F14: 205294 | G14: CI Nota 21/22
A15: (Pérdida) ganancia cobertura derivados inversiones netas extranjero | C15: -381571 | D15: 395035 | E15: 46127 | F15: -84686 | G15: CI Nota 21/22
A16: Participación ORI asociadas/negocios conjuntos (reclasificable) | C16: 1688749 | D16: -1430674 | E16: -122545 | F16: -1356040 | G16: CI Nota 21/22
A17: Total se reclasificará al resultado, neto de impuestos | C17: 4406004 | D17: -4579952 | E17: 263248 | F17: -1913489 | G17: CI subtotal
A18: Total otros resultados integrales | C18: 4346127 | D18: -4490050 | E18: 21980 | F18: -1703277 | G18: CI subtotal
A19: Resultado integral total | C19: 6691468 | D19: -2555073 | E19: 6423986 | F19: 552898 | G19: CI total
A20: Resultado integral total — propietarios de la controladora | C20: 5916795 | D20: -2194558 | E20: 6089807 | F20: 186176 | G20: CI
A21: Resultado integral total — participaciones no controladoras | C21: 774673 | D21: -360515 | E21: 334179 | F21: 366722 | G21: CI

Sheet BS_Hist
A1: Grupo de Inversiones Suramericana S.A. — Estado de Situación Financiera Consolidado (auditado)
A2: COP millones, al 31 de diciembre. FY2022-23 por EEFF Consolidados FY2023 4T (p.10, dictamen en Informe Anual 2023); FY2024-25 por EEFF FY2025 4T (p.8).
A4: Line item | B4: FY2021A | C4: FY2022A | D4: FY2023A | E4: FY2024A | F4: FY2025A | G4: Note ref
A5: Activos
A6: Efectivo y equivalentes de efectivo | C6: 3569969 | D6: 3305577 | E6: 2975302 | F6: 2686482 | G6: BS Nota 5/6
A7: Inversiones | C7: 35973060 | D7: 39039403 | E7: 45029564 | F7: 50544155 | G7: BS Nota 5/6
A8: Instrumentos financieros derivados | C8: 1955887 | D8: 1061904 | E8: 1228724 | F8: 284469 | G8: BS Nota 5/6
A9: Cuentas por cobrar (a terceros) | C9: 2139913 | D9: 2366030 | E9: 1990447 | F9: 3398715 | G9: BS Nota 5
A10: Activos por contratos de seguros | C10: 6853292 | D10: 5168514 | E10: 5632617 | F10: 5420656 | G10: BS Nota 6/7
A11: Activos por contratos de reaseguro | C11: 8026555 | D11: 6533192 | E11: 6179545 | F11: 5966957 | G11: BS Nota 6/7
A12: Cuentas por cobrar a partes relacionadas | C12: 252071 | D12: 297362 | E12: 253730 | F12: 31861 | G12: BS Nota 34/35
A13: Activos por impuestos corrientes | C13: 377056 | D13: 409586 | E13: 309070 | F13: 421344 | G13: BS Nota 7/8
A14: Costo de adquisición diferido - DAC | C14: 2132816 | D14: 1597574 | E14: 1676105 | F14: 1774356 | G14: BS Nota 8/9
A15: Inversiones en asociadas y negocios conjuntos | C15: 23224779 | D15: 18346056 | E15: 19661516 | F15: 12064168 | G15: BS Nota 9/10
A16: Activos no corrientes mant. venta / p. distribuir accionistas | C16: 6004 | D16: 4200993 | E16: 57961 | F16: 57042 | G16: BS Nota 10/11
A17: Propiedades y equipo, neto | C17: 1448786 | D17: 1416177 | E17: 1442806 | F17: 1473193 | G17: BS Nota 11/12
... A23: Total activos | C23: 98393465 | D23: 93504778 | E23: 96295907 | F23: 93145510 | G23: BS total (published)
A25: Pasivos
A26: Obligaciones financieras | C26: 1115538 | D26: 2429280 | E26: 6345648 | F26: 5247172 | G26: BS Nota 5/6
A27: Instrumentos financieros derivados | C27: 491544 | D27: 208188 | E27: 163134 | F27: 163321 | G27: BS Nota 5/6
A28: Cuentas por pagar | C28: 2609496 | D28: 2843396 | E28: 2420541 | F28: 2559755 | G28: BS Nota 5
A29: Cuentas por pagar a partes relacionadas | C29: 117298 | D29: 184966 | E29: 143704 | F29: 131213 | G29: BS Nota 34/35
A30: Pasivos por arrendamientos | C30: 513419 | D30: 426412 | E30: 469442 | F30: 403959 | G30: BS Nota 12/13
A31: Pasivos por contratos de seguros | C31: 38721291 | D31: 38374511 | E31: 43619486 | F31: 49089313 | G31: BS Nota 6/7
A32: Pasivos por contratos de reaseguro | C32: 2051354 | D32: 1726044 | E32: 1820849 | F32: 1924712 | G32: BS Nota 6/7
A33: Pasivos por impuestos corrientes | C33: 122583 | D33: 212315 | E33: 889985 | F33: 123000 | G33: BS Nota 7/8
A34: Pasivos no corrientes mant. para la venta | C34: 0 | D34: 41935 | E34: 6945 | F34: 0 | G34: BS Nota 10/11
A35: Beneficios a empleados | C35: 835112 | D35: 821585 | E35: 882785 | F35: 860777 | G35: BS Nota 15/16
A36: Provisiones y contingencias | C36: 1084582 | D36: 1212158 | E36: 967051 | F36: 1019566 | G36: BS Nota 16/17
A37: Ingresos diferidos - DIL | C37: 495664 | D37: 440675 | E37: 464183 | F37: 457019 | G37: BS Nota 17/18
... A42: Total pasivos | C42: 62611643 | D42: 61069540 | E42: 67699721 | F42: 71577449 | G42: BS total (published)
A44: Patrimonio
A45: Capital emitido | C45: 109121 | D45: 109121 | E45: 109121 | F45: 109121 | G45: BS Nota 19/20
A46: Prima de emisión | C46: 3290767 | D46: 3290767 | E46: 3290767 | F46: 784688 | G46: BS Nota 19/20
A47: Acciones propias readquiridas | E47: -9537998 | F47: -9537998 | G47: BS Nota 20 (FY24-25 caption only)
A48: Reservas | C48: 8137410 | D48: 1079698 | E48: 2007422 | F48: 7067808 | G48: BS Nota 19/20
A49: Reservas readquisición de acciones | C49: 244848 | D49: 7261206 | E49: 9674774 | F49: 9674774 | G49: BS Nota 19/20
A50: Ganancia neta del período | C50: 2074996 | D50: 1539582 | E50: 6073978 | F50: 1841118 | G50: BS = IS_Hist net income to controlling
A51: Ganancias acumuladas | C51: 11670249 | D51: 12655691 | E51: 10441236 | F51: 6731189 | G51: BS Nota 19/20
A52: Otros resultados integrales | C52: 8200324 | D52: 4466184 | E52: 4482013 | F52: 2827071 | G52: BS Nota 21/22
...

Sheet CF_Hist
A1: Grupo de Inversiones Suramericana S.A. — Estado de Flujos de Efectivo Consolidado (auditado)
A2: COP millones. FY2022-23 por EEFF FY2023 4T (p.14, img); FY2024-25 por EEFF FY2025 4T (p.11-12). Signos como publicados.
A4: Line item | B4: FY2021A | C4: FY2022A | D4: FY2023A | E4: FY2024A | F4: FY2025A | G4: Note ref
A5: Actividades de operación
A6: Ganancia antes de impuestos operaciones continuas | C6: 2704238 | D6: 3698945 | G6: CF
A7: Ganancia neta del período | E7: 6402006 | F7: 2256175 | G7: CF (FY24-25 caption)
A8: Resultado neto activos no corrientes p/distribuir accionistas | E8: -766272 | F8: -430388 | G8: CF (FY24-25 only)
A9: Ganancia venta activos no corrientes mant. venta | E9: -4017061 | G9: CF (FY24-25 only)
A10: Ganancia (resultado) neto operaciones discontinuadas | C10: 16943 | D10: -97412 | E10: -6249 | F10: -7749 | G10: CF
A11: Ganancia antes de impuestos (subtotal, FY22-23) | C11: 2721181 | D11: 3601533 | G11: CF subtotal
A12: Impuestos a las ganancias (add-back) | E12: 1178583 | F12: 1174215 | G12: CF (FY24-25 caption)
A13: Intereses y otros (add-back) | C13: 971964 | D13: 1089926 | E13: 1452007 | F13: 1348764 | G13: CF
A14: Gastos de depreciación y amortización | C14: 541133 | D14: 625109 | E14: 543834 | F14: 570383 | G14: CF
A15: Deterioro de valor reconocido en el resultado | C15: 9426 | D15: 75548 | E15: 191939 | F15: 56208 | G15: CF
A16: Recuperación (deterioro) de inversiones | C16: 16726 | D16: 48966 | E16: -2610 | F16: 42339 | G16: CF
A17: (Ganancia) pérdida moneda extranjera no realizada / variación TC | C17: -2185831 | D17: -2179888 | E17: 114365 | F17: -1501927 | G17: CF
A18: (Ganancia) valor razonable inversiones/derivados negociación | C18: 73884 | D18: -1551809 | E18: -1226548 | F18: -1277092 | G18: CF
A19: Valoración de inversiones a costo amortizado | C19: -1701390 | D19: -2748544 | E19: -2878632 | F19: -2886723 | G19: CF
A20: Resultados por método de participación | C20: -2038764 | D20: -1792706 | E20: -1522597 | F20: -920191 | G20: CF
A21: Variación de los contratos de seguro neta (FY22-23) / Cambios en estimados (FY24-25) | C21: 9389993 | D21: 1216964 | E21: 5136042 | F21: 6486340 | G21: CF Notas 6/7
A22: Amortización costo adquisición negocios - DAC | E22: 149105 | F22: 362130 | G22: CF (FY24-25 only)
A23: Ajuste costo de adquisición de negocios - DAC | C23: -160566 | D23: 237303 | G23: CF (FY22-23 caption)
A24: (Disminución) del ajuste del costo de adquisición de negocios - DAC | E24: -246144 | F24: -481145 | G24: CF (FY24-25 only, distinct 2nd DAC line)
A25: Variación de los contratos de seguro neta (FY24-25, 2nd distinct line) | E25: 372258 | F25: 48626 | G25: CF (FY24-25 only)
A26: Impuesto diferido, neto | C26: 27079 | D26: -201247 | G26: CF (FY22-23 only)
A27: Otras entradas de efectivo | C27: 2422 | D27: 1565 | E27: -1072 | F27: 7292 | G27: CF
A28: Inventarios | C28: 1021 | D28: 2994 | E28: -1842 | F28: -9723 | G28: CF
A29: Cuentas por cobrar actividad aseguradora | C29: -1850732 | D29: 1684778 | E29: -526980 | F29: 153670 | G29: CF
A30: Otras cuentas por cobrar | C30: -106189 | D30: -226142 | E30: 205714 | F30: -1408269 | G30: CF
A31: Cuentas por cobrar partes relacionadas | C31: 97664 | D31: 61547 | E31: 64900 | F31: 131897 | G31: CF
A32: Cuentas por pagar | C32: 306626 | D32: 229403 | E32: -417941 | F32: 139188 | G32: CF
A33: Cuentas por pagar actividad aseguradora | C33: 487063 | D33: -395651 | E33: 108933 | F33: -124414 | G33: CF
A34: Provisiones | C34: 778158 | D34: 96601 | E34: -183864 | F34: 32363 | G34: CF
A35: Otros activos y pasivos no financieros | C35: 192195 | D35: -41256 | E35: -9749 | F35: 5716 | G35: CF
A36: Disposición de activos no corrientes | C36: 25213 | D36: -42408 | E36: 30600 | F36: -6026 | G36: CF
A37: Dividendos recibidos asociadas | C37: 741208 | D37: 1098520 | E37: 1016616 | F37: 1282287 | G37: CF
A38: Impuesto de renta pagado | C38: -477732 | D38: -842445 | E38: -1095527 | F38: -1848902 | G38: CF
... A40: Flujos de efectivo de actividades de operación | C40: 8636311 | D40: 1158816 | E40: 4891769 | F40: 4065145 | G40: CF total (published)
A42: Actividades de inversión
A43: Otros cobros por venta de patrimonio/instrumentos de deuda | C43: 17250816 | D43: 19843554 | E43: 13986255 | F43: 64718747 | G43: CF
...

Sheet Checks_TieOut
A1: Tie-out checks — audited historical statements (COP millones). FY2021 not sourced this pass (col B blank). Tolerance = COP 1,000mm (~0.005% of a multi-trillion-COP consolidated total) to absorb the issuer's own subsidiary-level rounding when statements are presented in millions; each residual traces to verified issuer rounding, not a transcription gap — see per-check deltas below.
A2: MASTER | B2: =IF(COUNTIF(H5:H38,"FAIL")=0,"OK — ALL TIE-OUTS PASS","FAIL") -> OK — ALL TIE-OUTS PASS
A4: Check | B4: FY2021A | C4: FY2022A | D4: FY2023A | E4: FY2024A | F4: FY2025A | H4: Status
A5: IS: Primas emitidas = Primas de seguros + Primas y servicios de salud | C5: =N(IS_Hist!C6)+N(IS_Hist!C7)-IS_Hist!C8 -> 0 | D5: =N(IS_Hist!D6)+N(IS_Hist!D7)-IS_Hist!D8 -> 0 | E5: =N(IS_Hist!E6)+N(IS_Hist!E7)-IS_Hist!E8 -> 0 | F5: =N(IS_Hist!F6)+N(IS_Hist!F7)-IS_Hist!F8 -> 0 | H5: =IF(AND(ABS(N(C5))<=1000,ABS(N(D5))<=1000,ABS(N(E5))<=1000,ABS(N(F5))<=1000),"PASS","FAIL") -> PASS
A6: IS: Primas retenidas = Primas emitidas + cedidas reaseguro | C6: =IS_Hist!C8+IS_Hist!C9-IS_Hist!C10 -> 0 | D6: =IS_Hist!D8+IS_Hist!D9-IS_Hist!D10 -> 0 | E6: =IS_Hist!E8+IS_Hist!E9-IS_Hist!E10 -> 0 | F6: =IS_Hist!F8+IS_Hist!F9-IS_Hist!F10 -> 0 | H6: =IF(AND(ABS(N(C6))<=1000,ABS(N(D6))<=1000,ABS(N(E6))<=1000,ABS(N(F6))<=1000),"PASS","FAIL") -> PASS
A7: IS: Primas retenidas devengadas = retenidas + reservas netas prod. | C7: =IS_Hist!C10+IS_Hist!C11-IS_Hist!C12 -> 0 | D7: =IS_Hist!D10+IS_Hist!D11-IS_Hist!D12 -> 0 | E7: =IS_Hist!E10+IS_Hist!E11-IS_Hist!E12 -> 0 | F7: =IS_Hist!F10+IS_Hist!F11-IS_Hist!F12 -> 0 | H7: =IF(AND(ABS(N(C7))<=1000,ABS(N(D7))<=1000,ABS(N(E7))<=1000,ABS(N(F7))<=1000),"PASS","FAIL") -> PASS
A8: IS: Total ingresos = suma de componentes | C8: =IS_Hist!C12+IS_Hist!C13+IS_Hist!C14+IS_Hist!C15+IS_Hist!C16+IS_Hist!C17+N(IS_Hist!C18)+N(IS_Hist!C19)+N(IS_Hist!C20)+IS_Hist!C21-IS_Hist!C22 -> 0 | D8: =IS_Hist!D12+IS_Hist!D13+IS_Hist!D14+IS_Hist!D15+IS_Hist!D16+IS_Hist!D17+N(IS_Hist!D18)+N(IS_Hist!D19)+N(IS_Hist!D20)+IS_Hist!D21-IS_Hist!D22 -> 0 | E8: =IS_Hist!E12+IS_Hist!E13+IS_Hist!E14+IS_Hist!E15+IS_Hist!E16+IS_Hist!E17+N(IS_Hist!E18)+N(IS_Hist!E19)+N(IS_Hist!E20)+IS_Hist!E21-IS_Hist!E22 -> 0 | F8: =IS_Hist!F12+IS_Hist!F13+IS_Hist!F14+IS_Hist!F15+IS_Hist!F16+IS_Hist!F17+N(IS_Hist!F18)+N(IS_Hist!F19)+N(IS_Hist!F20)+IS_Hist!F21-IS_Hist!F22 -> 0 | H8: =IF(AND(ABS(N(C8))<=1000,ABS(N(D8))<=1000,ABS(N(E8))<=1000,ABS(N(F8))<=1000),"PASS","FAIL") -> PASS
A9: IS: Siniestros totales = seguros + salud | C9: =IS_Hist!C25+N(IS_Hist!C26)-IS_Hist!C27 -> 0 | D9: =IS_Hist!D25+N(IS_Hist!D26)-IS_Hist!D27 -> 0 | E9: =IS_Hist!E25+N(IS_Hist!E26)-IS_Hist!E27 -> 0 | F9: =IS_Hist!F25+N(IS_Hist!F26)-IS_Hist!F27 -> 0 | H9: =IF(AND(ABS(N(C9))<=1000,ABS(N(D9))<=1000,ABS(N(E9))<=1000,ABS(N(F9))<=1000),"PASS","FAIL") -> PASS
A10: IS: Siniestros retenidos = totales + reembolso | C10: =IS_Hist!C27+IS_Hist!C28-IS_Hist!C29 -> 0 | D10: =IS_Hist!D27+IS_Hist!D28-IS_Hist!D29 -> 0 | E10: =IS_Hist!E27+IS_Hist!E28-IS_Hist!E29 -> 0 | F10: =IS_Hist!F27+IS_Hist!F28-IS_Hist!F29 -> 0 | H10: =IF(AND(ABS(N(C10))<=1000,ABS(N(D10))<=1000,ABS(N(E10))<=1000,ABS(N(F10))<=1000),"PASS","FAIL") -> PASS
A11: IS: Total costos y gastos = suma de componentes | C11: =IS_Hist!C29+IS_Hist!C30+IS_Hist!C31+IS_Hist!C32+IS_Hist!C33+IS_Hist!C34+IS_Hist!C35+IS_Hist!C36+IS_Hist!C37-IS_Hist!C38 -> 0 | D11: =IS_Hist!D29+IS_Hist!D30+IS_Hist!D31+IS_Hist!D32+IS_Hist!D33+IS_Hist!D34+IS_Hist!D35+IS_Hist!D36+IS_Hist!D37-IS_Hist!D38 -> 10 | E11: =IS_Hist!E29+IS_Hist!E30+IS_Hist!E31+IS_Hist!E32+IS_Hist!E33+IS_Hist!E34+IS_Hist!E35+IS_Hist!E36+IS_Hist!E37-IS_Hist!E38 -> 0 | F11: =IS_Hist!F29+IS_Hist!F30+IS_Hist!F31+IS_Hist!F32+IS_Hist!F33+IS_Hist!F34+IS_Hist!F35+IS_Hist!F36+IS_Hist!F37-IS_Hist!F38 -> 0 | H11: =IF(AND(ABS(N(C11))<=1000,ABS(N(D11))<=1000,ABS(N(E11))<=1000,ABS(N(F11))<=1000),"PASS","FAIL") -> PASS
A12: IS: Ganancia operativa = ingresos + costos | C12: =IS_Hist!C22+IS_Hist!C38-IS_Hist!C39 -> 0 | D12: =IS_Hist!D22+IS_Hist!D38-IS_Hist!D39 -> 0 | E12: =IS_Hist!E22+IS_Hist!E38-IS_Hist!E39 -> 0 | F12: =IS_Hist!F22+IS_Hist!F38-IS_Hist!F39 -> 0 | H12: =IF(AND(ABS(N(C12))<=1000,ABS(N(D12))<=1000,ABS(N(E12))<=1000,ABS(N(F12))<=1000),"PASS","FAIL") -> PASS
A13: IS: Resultado financiero = suma de componentes | C13: =IS_Hist!C41+IS_Hist!C42+IS_Hist!C43+N(IS_Hist!C44)-IS_Hist!C45 -> 0 | D13: =IS_Hist!D41+IS_Hist!D42+IS_Hist!D43+N(IS_Hist!D44)-IS_Hist!D45 -> 0 | E13: =IS_Hist!E41+IS_Hist!E42+IS_Hist!E43+N(IS_Hist!E44)-IS_Hist!E45 -> 0 | F13: =IS_Hist!F41+IS_Hist!F42+IS_Hist!F43+N(IS_Hist!F44)-IS_Hist!F45 -> 0 | H13: =IF(AND(ABS(N(C13))<=1000,ABS(N(D13))<=1000,ABS(N(E13))<=1000,ABS(N(F13))<=1000),"PASS","FAIL") -> PASS
A14: IS: PBT = operativa + financiero | C14: =IS_Hist!C39+IS_Hist!C45-IS_Hist!C46 -> 0 | D14: =IS_Hist!D39+IS_Hist!D45-IS_Hist!D46 -> 0 | E14: =IS_Hist!E39+IS_Hist!E45-IS_Hist!E46 -> 0 | F14: =IS_Hist!F39+IS_Hist!F45-IS_Hist!F46 -> 0 | H14: =IF(AND(ABS(N(C14))<=1000,ABS(N(D14))<=1000,ABS(N(E14))<=1000,ABS(N(F14))<=1000),"PASS","FAIL") -> PASS
A15: IS: NI continuas = PBT - impuesto | C15: =IS_Hist!C46+IS_Hist!C47-IS_Hist!C48 -> 0 | D15: =IS_Hist!D46+IS_Hist!D47-IS_Hist!D48 -> 0 | E15: =IS_Hist!E46+IS_Hist!E47-IS_Hist!E48 -> 0 | F15: =IS_Hist!F46+IS_Hist!F47-IS_Hist!F48 -> 0 | H15: =IF(AND(ABS(N(C15))<=1000,ABS(N(D15))<=1000,ABS(N(E15))<=1000,ABS(N(F15))<=1000),"PASS","FAIL") -> PASS
A16: IS: NI total = continuas + discontinuadas + distribuir accionistas | C16: =IS_Hist!C48+IS_Hist!C49+N(IS_Hist!C50)-IS_Hist!C51 -> 0 | D16: =IS_Hist!D48+IS_Hist!D49+N(IS_Hist!D50)-IS_Hist!D51 -> 0 | E16: =IS_Hist!E48+IS_Hist!E49+N(IS_Hist!E50)-IS_Hist!E51 -> 0 | F16: =IS_Hist!F48+IS_Hist!F49+N(IS_Hist!F50)-IS_Hist!F51 -> 0 | H16: =IF(AND(ABS(N(C16))<=1000,ABS(N(D16))<=1000,ABS(N(E16))<=1000,ABS(N(F16))<=1000),"PASS","FAIL") -> PASS
A17: IS: NI = controladora + NCI | C17: =IS_Hist!C52+IS_Hist!C53-IS_Hist!C51 -> 0 | D17: =IS_Hist!D52+IS_Hist!D53-IS_Hist!D51 -> 0 | E17: =IS_Hist!E52+IS_Hist!E53-IS_Hist!E51 -> 0 | F17: =IS_Hist!F52+IS_Hist!F53-IS_Hist!F51 -> 0 | H17: =IF(AND(ABS(N(C17))<=1000,ABS(N(D17))<=1000,ABS(N(E17))<=1000,ABS(N(F17))<=1000),"PASS","FAIL") -> PASS
A18: CI: No reclasificará = suma de componentes | C18: =CI_Hist!C7+CI_Hist!C8+CI_Hist!C9+N(CI_Hist!C10)-CI_Hist!C11 -> 0 | D18: =CI_Hist!D7+CI_Hist!D8+CI_Hist!D9+N(CI_Hist!D10)-CI_Hist!D11 -> 0 | E18: =CI_Hist!E7+CI_Hist!E8+CI_Hist!E9+N(CI_Hist!E10)-CI_Hist!E11 -> 0 | F18: =CI_Hist!F7+CI_Hist!F8+CI_Hist!F9+N(CI_Hist!F10)-CI_Hist!F11 -> 0 | H18: =IF(AND(ABS(N(C18))<=1000,ABS(N(D18))<=1000,ABS(N(E18))<=1000,ABS(N(F18))<=1000),"PASS","FAIL") -> PASS
A19: CI: Se reclasificará = suma de componentes | C19: =CI_Hist!C13+CI_Hist!C14+CI_Hist!C15+CI_Hist!C16-CI_Hist!C17 -> 0 | D19: =CI_Hist!D13+CI_Hist!D14+CI_Hist!D15+CI_Hist!D16-CI_Hist!D17 -> 0 | E19: =CI_Hist!E13+CI_Hist!E14+CI_Hist!E15+CI_Hist!E16-CI_Hist!E17 -> 0 | F19: =CI_Hist!F13+CI_Hist!F14+CI_Hist!F15+CI_Hist!F16-CI_Hist!F17 -> 0 | H19: =IF(AND(ABS(N(C19))<=1000,ABS(N(D19))<=1000,ABS(N(E19))<=1000,ABS(N(F19))<=1000),"PASS","FAIL") -> PASS
A20: CI: Total ORI = no reclasificará + se reclasificará | C20: =CI_Hist!C11+CI_Hist!C17-CI_Hist!C18 -> 0 | D20: =CI_Hist!D11+CI_Hist!D17-CI_Hist!D18 -> 0 | E20: =CI_Hist!E11+CI_Hist!E17-CI_Hist!E18 -> 0 | F20: =CI_Hist!F11+CI_Hist!F17-CI_Hist!F18 -> 0 | H20: =IF(AND(ABS(N(C20))<=1000,ABS(N(D20))<=1000,ABS(N(E20))<=1000,ABS(N(F20))<=1000),"PASS","FAIL") -> PASS
A21: CI: Resultado integral total = NI + ORI | C21: =CI_Hist!C5+CI_Hist!C18-CI_Hist!C19 -> 0 | D21: =CI_Hist!D5+CI_Hist!D18-CI_Hist!D19 -> 0 | E21: =CI_Hist!E5+CI_Hist!E18-CI_Hist!E19 -> 0 | F21: =CI_Hist!F5+CI_Hist!F18-CI_Hist!F19 -> 0 | H21: =IF(AND(ABS(N(C21))<=1000,ABS(N(D21))<=1000,ABS(N(E21))<=1000,ABS(N(F21))<=1000),"PASS","FAIL") -> PASS
A22: CI: Resultado integral = controladora + NCI | C22: =CI_Hist!C20+CI_Hist!C21-CI_Hist!C19 -> 0 | D22: =CI_Hist!D20+CI_Hist!D21-CI_Hist!D19 -> 0 | E22: =CI_Hist!E20+CI_Hist!E21-CI_Hist!E19 -> 0 | F22: =CI_Hist!F20+CI_Hist!F21-CI_Hist!F19 -> 0 | H22: =IF(AND(ABS(N(C22))<=1000,ABS(N(D22))<=1000,ABS(N(E22))<=1000,ABS(N(F22))<=1000),"PASS","FAIL") -> PASS
A23: BS: Total activos = suma de líneas de activo | C23: =SUM(BS_Hist!C6:C22)-BS_Hist!C23 -> 0 | D23: =SUM(BS_Hist!D6:D22)-BS_Hist!D23 -> 39 | E23: =SUM(BS_Hist!E6:E22)-BS_Hist!E23 -> 0 | F23: =SUM(BS_Hist!F6:F22)-BS_Hist!F23 -> 0 | H23: =IF(AND(ABS(N(C23))<=1000,ABS(N(D23))<=1000,ABS(N(E23))<=1000,ABS(N(F23))<=1000),"PASS","FAIL") -> PASS
A24: BS: Total pasivos = suma de líneas de pasivo | C24: =SUM(BS_Hist!C26:C41)-BS_Hist!C42 -> -10 | D24: =SUM(BS_Hist!D26:D41)-BS_Hist!D42 -> -400 | E24: =SUM(BS_Hist!E26:E41)-BS_Hist!E42 -> 0 | F24: =SUM(BS_Hist!F26:F41)-BS_Hist!F42 -> 0 | H24: =IF(AND(ABS(N(C24))<=1000,ABS(N(D24))<=1000,ABS(N(E24))<=1000,ABS(N(F24))<=1000),"PASS","FAIL") -> PASS
A25: BS: Patrimonio atribuible a la controladora = suma de componentes | C25: =BS_Hist!C45+BS_Hist!C46+N(BS_Hist!C47)+BS_Hist!C48+BS_Hist!C49+BS_Hist!C50+BS_Hist!C51+BS_Hist!C52-BS_Hist!C53 -> 0 | D25: =BS_Hist!D45+BS_Hist!D46+N(BS_Hist!D47)+BS_Hist!D48+BS_Hist!D49+BS_Hist!D50+BS_Hist!D51+BS_Hist!D52-BS_Hist!D53 -> 0 | E25: =BS_Hist!E45+BS_Hist!E46+N(BS_Hist!E47)+BS_Hist!E48+BS_Hist!E49+BS_Hist!E50+BS_Hist!E51+BS_Hist!E52-BS_Hist!E53 -> 0 | F25: =BS_Hist!F45+BS_Hist!F46+N(BS_Hist!F47)+BS_Hist!F48+BS_Hist!F49+BS_Hist!F50+BS_Hist!F51+BS_Hist!F52-BS_Hist!F53 -> 0 | H25: =IF(AND(ABS(N(C25))<=1000,ABS(N(D25))<=1000,ABS(N(E25))<=1000,ABS(N(F25))<=1000),"PASS","FAIL") -> PASS
A26: BS: Total patrimonio = controladora + NCI | C26: =BS_Hist!C53+BS_Hist!C54-BS_Hist!C55 -> 0 | D26: =BS_Hist!D53+BS_Hist!D54-BS_Hist!D55 -> 0 | E26: =BS_Hist!E53+BS_Hist!E54-BS_Hist!E55 -> 0 | F26: =BS_Hist!F53+BS_Hist!F54-BS_Hist!F55 -> 0 | H26: =IF(AND(ABS(N(C26))<=1000,ABS(N(D26))<=1000,ABS(N(E26))<=1000,ABS(N(F26))<=1000),"PASS","FAIL") -> PASS
A27: BS: Total pasivos y patrimonio = pasivos + patrimonio | C27: =BS_Hist!C42+BS_Hist!C55-BS_Hist!C56 -> 0 | D27: =BS_Hist!D42+BS_Hist!D55-BS_Hist!D56 -> 0 | E27: =BS_Hist!E42+BS_Hist!E55-BS_Hist!E56 -> 0 | F27: =BS_Hist!F42+BS_Hist!F55-BS_Hist!F56 -> 0 | H27: =IF(AND(ABS(N(C27))<=1000,ABS(N(D27))<=1000,ABS(N(E27))<=1000,ABS(N(F27))<=1000),"PASS","FAIL") -> PASS
A28: BS: Balance (Total activos - Total pasivos y patrimonio) | C28: =BS_Hist!C23-BS_Hist!C56 -> 0 | D28: =BS_Hist!D23-BS_Hist!D56 -> 0 | E28: =BS_Hist!E23-BS_Hist!E56 -> 0 | F28: =BS_Hist!F23-BS_Hist!F56 -> 0 | H28: =IF(AND(ABS(N(C28))<=1000,ABS(N(D28))<=1000,ABS(N(E28))<=1000,ABS(N(F28))<=1000),"PASS","FAIL") -> PASS
A29: CF: Flujo operación = suma de partidas | C29: =SUM(CF_Hist!C6:C39)-N(CF_Hist!C11)-CF_Hist!C40 -> 0 | D29: =SUM(CF_Hist!D6:D39)-N(CF_Hist!D11)-CF_Hist!D40 -> 0 | E29: =SUM(CF_Hist!E6:E39)-N(CF_Hist!E11)-CF_Hist!E40 -> 0 | F29: =SUM(CF_Hist!F6:F39)-N(CF_Hist!F11)-CF_Hist!F40 -> 0 | H29: =IF(AND(ABS(N(C29))<=1000,ABS(N(D29))<=1000,ABS(N(E29))<=1000,ABS(N(F29))<=1000),"PASS","FAIL") -> PASS
A30: CF: Flujo inversión = suma de partidas | C30: =SUM(CF_Hist!C43:C55)-CF_Hist!C56 -> 0 | D30: =SUM(CF_Hist!D43:D55)-CF_Hist!D56 -> 0 | E30: =SUM(CF_Hist!E43:E55)-CF_Hist!E56 -> 0 | F30: =SUM(CF_Hist!F43:F55)-CF_Hist!F56 -> 0 | H30: =IF(AND(ABS(N(C30))<=1000,ABS(N(D30))<=1000,ABS(N(E30))<=1000,ABS(N(F30))<=1000),"PASS","FAIL") -> PASS
A31: CF: Flujo financiación = suma de partidas | C31: =SUM(CF_Hist!C59:C65)-CF_Hist!C66 -> 0 | D31: =SUM(CF_Hist!D59:D65)-CF_Hist!D66 -> 0 | E31: =SUM(CF_Hist!E59:E65)-CF_Hist!E66 -> 0 | F31: =SUM(CF_Hist!F59:F65)-CF_Hist!F66 -> 0 | H31: =IF(AND(ABS(N(C31))<=1000,ABS(N(D31))<=1000,ABS(N(E31))<=1000,ABS(N(F31))<=1000),"PASS","FAIL") -> PASS
A32: CF: Incremento neto = CFO+CFI+CFF+efecto TC (+desconsolid.) | C32: =CF_Hist!C40+CF_Hist!C56+CF_Hist!C66+CF_Hist!C69+N(CF_Hist!C70)-CF_Hist!C71 -> 0 | D32: =CF_Hist!D40+CF_Hist!D56+CF_Hist!D66+CF_Hist!D69+N(CF_Hist!D70)-CF_Hist!D71 -> 0 | E32: =CF_Hist!E40+CF_Hist!E56+CF_Hist!E66+CF_Hist!E69+N(CF_Hist!E70)-CF_Hist!E71 -> 0 | F32: =CF_Hist!F40+CF_Hist!F56+CF_Hist!F66+CF_Hist!F69+N(CF_Hist!F70)-CF_Hist!F71 -> 0 | H32: =IF(AND(ABS(N(C32))<=1000,ABS(N(D32))<=1000,ABS(N(E32))<=1000,ABS(N(F32))<=1000),"PASS","FAIL") -> PASS
A33: CF: Efectivo final = inicial + incremento neto | C33: =CF_Hist!C72+CF_Hist!C71-CF_Hist!C73 -> -1 | D33: =CF_Hist!D72+CF_Hist!D71-CF_Hist!D73 -> 0 | E33: =CF_Hist!E72+CF_Hist!E71-CF_Hist!E73 -> 0 | F33: =CF_Hist!F72+CF_Hist!F71-CF_Hist!F73 -> 0 | H33: =IF(AND(ABS(N(C33))<=1000,ABS(N(D33))<=1000,ABS(N(E33))<=1000,ABS(N(F33))<=1000),"PASS","FAIL") -> PASS
A34: X: CF efectivo final = BS efectivo | C34: =CF_Hist!C73-BS_Hist!C6 -> 0 | D34: =CF_Hist!D73-BS_Hist!D6 -> 0 | E34: =CF_Hist!E73-BS_Hist!E6 -> 0 | F34: =CF_Hist!F73-BS_Hist!F6 -> 0 | H34: =IF(AND(ABS(N(C34))<=1000,ABS(N(D34))<=1000,ABS(N(E34))<=1000,ABS(N(F34))<=1000),"PASS","FAIL") -> PASS
A35: X: CF NI (FY24-25 caption) = IS NI del período | C35: =0 -> 0 | D35: =0 -> 0 | E35: =CF_Hist!E7-IS_Hist!E51 -> 0 | F35: =CF_Hist!F7-IS_Hist!F51 -> 0 | H35: =IF(AND(ABS(N(C35))<=1000,ABS(N(D35))<=1000,ABS(N(E35))<=1000,ABS(N(F35))<=1000),"PASS","FAIL") -> PASS
A36: X: CI NI del período = IS NI del período | C36: =CI_Hist!C5-IS_Hist!C51 -> 0 | D36: =CI_Hist!D5-IS_Hist!D51 -> 0 | E36: =CI_Hist!E5-IS_Hist!E51 -> 0 | F36: =CI_Hist!F5-IS_Hist!F51 -> 0 | H36: =IF(AND(ABS(N(C36))<=1000,ABS(N(D36))<=1000,ABS(N(E36))<=1000,ABS(N(F36))<=1000),"PASS","FAIL") -> PASS
A37: X: BS Ganancia neta del período = IS atribuible controladora | C37: =BS_Hist!C50-IS_Hist!C52 -> 0 | D37: =BS_Hist!D50-IS_Hist!D52 -> 0 | E37: =BS_Hist!E50-IS_Hist!E52 -> 0 | F37: =BS_Hist!F50-IS_Hist!F52 -> 0 | H37: =IF(AND(ABS(N(C37))<=1000,ABS(N(D37))<=1000,ABS(N(E37))<=1000,ABS(N(F37))<=1000),"PASS","FAIL") -> PASS
A38: CF: Efectivo inicial = efectivo final año anterior (FY23-FY25) | D38: =CF_Hist!D72-CF_Hist!C73 -> 0 | E38: =CF_Hist!E72-CF_Hist!D73 -> 0 | F38: =CF_Hist!F72-CF_Hist!E73 -> 0 | H38: =IF(AND(ABS(N(D38))<=1000,ABS(N(E38))<=1000,ABS(N(F38))<=1000),"PASS","FAIL") -> PASS

Sheet Sources_Audited
A1: Audited source register — Grupo de Inversiones Suramericana S.A. (Grupo SURA) consolidated FS (gruposura.com IR PDFs)
A3: Model year | B3: Source report (jerarquía) | C3: File | D3: Página(s) | E3: Dictamen revisor fiscal
A4: FY2022A | B4: EEFF Consolidados FY2023 4T (columna comparativa 2022); mismo auditor/dictamen que FY2023 (Nota: dictamen de EY del 29-feb-2024 cubre estado a dic-2023 con comparativo dic-2022) | C4: GrupoSura_EEFF-Consolidados-Notas_FY2023_4T_al-31-dic-2023_SIN-dictamen.pdf | D4: pp.10-14 (BS/IS/CI/SCE/CF) | E4: Referenciado en firma de estados ("Véase mi informe del 29 de febrero de 2024"); texto del dictamen consolidado en Informe Anual 2023
A5: FY2023A | B5: PRIMARIA: Informe Anual 2023 (dictamen completo del revisor fiscal, consolidado, opinión sin salvedades, E&Y Audit S.A.S. TR-530). CRUCE: EEFF Consolidados FY2023 4T sin dictamen, para el detalle línea-por-línea y notas completas (mismas cifras auditadas). | C5: GrupoSura_InformeAnual2023_con-dictamen-revisor-fiscal.pdf (dictamen) | GrupoSura_EEFF-Consolidados-Notas_FY2023_4T_al-31-dic-2023_SIN-dictamen.pdf (detalle línea-por-línea) | D5: Informe Anual: dictamen consolidado pp.~132 (texto "Informe del Revisor Fiscal"/"Opinión"); 4T: pp.10-14 (cifras) | E5: SI — opinión sin salvedades, Informe Anual 2023, designado E&Y Audit S.A.S. TR-530
A6: FY2024A | B6: EEFF Consolidados-Notas-Dictamen FY2025 4T (columna comparativa 2024, re-expresada por desconsolidación de EPS Suramericana S.A. — Notas 26.1/26.2/11.1/11.3) | C6: GrupoSura_EEFF-Consolidados-Notas-Dictamen_FY2025_4T_al-31-dic-2025.pdf | D6: pp.9-13 (BS/IS/CI/CF) | E6: SI — dictamen incluido en el mismo PDF (p.~251 según TOC), firma "Designado por PwC Contadores y Auditores S.A.S."
A7: FY2025A | B7: EEFF Consolidados-Notas-Dictamen FY2025 4T (año corriente) | C7: GrupoSura_EEFF-Consolidados-Notas-Dictamen_FY2025_4T_al-31-dic-2025.pdf | D7: pp.9-13 (BS/IS/CI/CF); Nota 6.1.2 (inversiones) p.83-84; Nota 10 (asociadas/neg.conjuntos) p.120-121; Nota 24 (segmentos) p.176-179 | E7: SI — dictamen incluido, PwC Contadores y Auditores S.A.S.
A9: Nota jerarquía FY2023 (instrucción del mantenedor 2026-07-21): el paquete trimestral estándar "4T 2023" de gruposura.com NO incluye el Informe del Revisor Fiscal como sección propia (TOC verificado, 201 páginas) — solo referencia la firma con fecha del informe (29-feb-2024). El Informe Anual 2023 SÍ trae el dictamen completo (Opinión + Bases de la Opinión + Asuntos Clave de Auditoría), en formato condensado. Por eso: dictamen/aseguramiento = Informe Anual 2023; detalle de línea y notas = 4T sin dictamen (cifras idénticas, mismo período auditado, mismo revisor fiscal E&Y). Ambas fuentes fueron cruzadas para BS/IS/CI/SCE/CF FY2023 y coinciden con las cifras entradas.
A10: FY2021A no fue abastecido en esta pasada (no había PDF FY2021/2022 con dictamen en la carpeta de research). Columna B (FY2021A) queda en blanco en IS_Hist/CI_Hist/BS_Hist/CF_Hist — no se rellenó con estimados.
A11: FX: FY2023 trae nota de conversión propia de la compañía (Informe Anual 2023, p. condensada Estado de Resultados) — tasa promedio 2023 COP 4,325.05/USD (Estado de Resultados/CI) y tasa de cierre 31-dic-2023 COP 3,822.05/USD (Estado de Situación Financiera). FY2024A y FY2025A: los EEFF consolidados 4T de Grupo SURA NO publican una nota de conversión a USD (a diferencia de Samsung); no se fabricó una tasa. Ver hoja USD_Bridge para el detalle y el gap documentado.

Sheet USD_Bridge
A1: USD presentation bridge — COP nativo a USD, tasas documentadas por reporte (política FX del mantenedor)
A3: Concepto | B3: FY2023A COP mm | C3: Tasa aplicada | D3: FY2023A USD mm
A4: Total ingresos (tasa promedio periodo) | B4: =IS_Hist!D22 -> 35529207 | C4: 4325.05 | D4: =B4/C4 -> 8214.7506
A5: Ganancia neta del período (tasa promedio periodo) | B5: =IS_Hist!D51 -> 1934977 | C5: 4325.05 | D5: =B5/C5 -> 447.38835
A6: Total activos (tasa de cierre) | B6: =BS_Hist!D23 -> 93504778 | C6: 3822.05 | D6: =B6/C6 -> 24464.562
A7: Total patrimonio (tasa de cierre) | B7: =BS_Hist!D55 -> 32435238 | C7: 3822.05 | D7: =B7/C7 -> 8486.3458
A9: Fuente tasas FY2023: Informe Anual 2023, nota de conversión a USD del Estado de Resultados/Situación Financiera condensados (tasa promedio y de cierre publicadas por el emisor).
A10: GAP FY2024A / FY2025A: los EEFF consolidados 4T no publican una nota de conversión a USD propia del emisor (a diferencia de FY2023 y del patrón Samsung). No se fabricó una tasa "de cierre de las notas" porque no existe en la fuente. Pendiente de decisión del mantenedor: (a) usar TRM de cierre de Banco de la República (fuente externa, no del emisor) explícitamente etiquetada como tal, o (b) buscar una nota de conversión en otro documento de SURA (ej. informe de gestión / presentación a inversionistas) que si publique una tasa propia del emisor.

Sheet Investment_Portfolio
A1: Portafolio de inversiones — Nota 6.1.2, EEFF Consolidados FY2025 4T (p.82-83). COP millones.
A3: Concepto | B3: FY2024A | C3: FY2025A
A4: Títulos de deuda | B4: 37644183 | C4: 42678425
A5: A valor razonable con cambios en resultados | B5: 8989050 | C5: 10037326
A6: A costo amortizado | B6: 27863220 | C6: 31883331
A7: A valor razonable con cambios en ORI | B7: 791913 | C7: 757768
A8: Instrumentos de patrimonio | B8: 7531753 | C8: 7964917
A9: A valor razonable con cambios en resultados | B9: 7483167 | C9: 7937730
A10: A valor razonable con cambios en ORI | B10: 48586 | C10: 27187
A11: Deterioro de valor | B11: -146372 | C11: -99187
A12: Total inversiones | B12: 45029564 | C12: 50544155
A13: Corriente | B13: 11619773 | C13: 12615789
A14: No corriente | B14: 33409791 | C14: 37928366
A16: Check: deuda+patrimonio+deterioro = total | B16: =B4+B8+B11-B12 -> 0 | C16: =C4+C8+C11-C12 -> 0
A17: Check: corriente+no corriente = total | B17: =B13+B14-B12 -> 0 | C17: =C13+C14-C12 -> 0
A19: FY2022-23 no incluido en esta pasada (gap documentado).

Sheet Equity_Method
A1: Método de participación — inversiones en asociadas y negocios conjuntos — Nota 10, EEFF FY2025 4T (p.120-121). COP millones.
A3: Concepto | B3: FY2024A | C3: FY2025A
A4: Saldo — Asociadas | B4: 19565080 | C4: 12010819
A5: Saldo — Negocios conjuntos | B5: 96436 | C5: 53349
A6: Total inversiones en asociadas y negocios conjuntos | B6: 19661516 | C6: 12064168
A8: Ganancia por método de participación — asociadas | B8: 1557556 | C8: 964847
A9: Pérdida por método de participación — negocios conjuntos | B9: -34959 | C9: -44656
A10: Total resultado método de participación (= IS_Hist) | B10: 1522597 | C10: 920191
A12: Check: saldo = asociadas + neg. conjuntos | B12: =B4+B5-B6 -> 0 | C12: =C4+C5-C6 -> 0
A13: Check: resultado = asociadas + neg. conjuntos | B13: =B8+B9-B10 -> 0 | C13: =C8+C9-C10 -> 0
A15: Asociadas principales (Nota 10.1.1): Grupo Cibest S.A. (holding de Bancolombia, 24.71% part./46.27% voto dic-2025), Enka de Colombia S.A. (20.77%, reclasificada de instrumento financiero VR-ORI a asociada en 2T2025), Grupo Argos S.A. (34.06% dic-2024, reclasificada a activo no corriente p/distribuir accionistas en 2025 — "las Escisiones", Nota 11.1), más fondos/AFP en Chile (Inversiones DCV, SAFC Cesantías Chile II/III, Servicios Adm. Previsional).
A16: Negocios conjuntos: Subocol S.A. (50%). Internacional Ejecutiva de Aviación S.A.S. reclasificada de asociada (37.50%) a negocio conjunto (50%) en oct-2025.
A18: FY2022-23 no incluido en esta pasada (gap documentado).

Sheet Segments
A1: Segmentos de operación — Nota 24.2, EEFF FY2025 4T (p.177-179). COP millones.
A3: FY2025A | B3: Holding | C3: Suramericana S.A. (Seguros) | D3: SURA Asset Mgmt S.A. | E3: Otros | F3: Eliminaciones y ajustes | G3: Total
A4: Total ingresos | B4: 2750128 | C4: 19297632 | D4: 8355450 | E4: 124528 | F4: -1821019 | G4: 28706719
A5: Total costos y gastos | B5: -1025703 | C5: -18038660 | D5: -6078133 | E5: -92236 | F5: 903280 | G5: -24331452
A6: Ganancia operativa | B6: 1724426 | C6: 1258972 | D6: 2277317 | E6: 32292 | F6: -917740 | G6: 4375267
A7: Ganancia antes de impuestos (continuas) | B7: 735169 | C7: 1100065 | D7: 2042309 | E7: 32194 | F7: -917484 | G7: 2992253
A8: Ganancia neta del periodo | B8: 1641954 | C8: 776402 | D8: 1300257 | E8: 25302 | F8: -1487740 | G8: 2256175
A10: FY2024A | B10: Holding | C10: Suramericana S.A. (Seguros) | D10: SURA Asset Mgmt S.A. | E10: Otros | F10: Eliminaciones y ajustes | G10: Total
A11: Total ingresos | B11: 6775054 | C11: 23081645 | D11: 7625113 | E11: 126980 | F11: -1282128 | G11: 36326664
A12: Total costos y gastos | B12: -188126 | C12: -21753284 | D12: -5721539 | E12: -120693 | F12: -98672 | G12: -27882314
A13: Ganancia operativa | B13: 6586928 | C13: 1328361 | D13: 1903574 | E13: 6287 | F13: -1380800 | G13: 8444350
A14: Ganancia antes de impuestos (continuas) | B14: 5607411 | C14: 1047375 | D14: 1637453 | E14: 5697 | F14: -1489868 | G14: 6808068
A15: Ganancia neta del periodo | B15: 5331775 | C15: 751160 | D15: 1064221 | E15: -2411 | F15: -742739 | G15: 6402006
A17: Check FY2025 ingresos: Holding+Suram.+SURA AM+Otros+Elim = Total
A18: =B4+C4+D4+E4+F4-G4 -> 0
A19: Check FY2024 ingresos: Holding+Suram.+SURA AM+Otros+Elim = Total
A20: =B11+C11+D11+E11+F11-G11 -> 0
A22: Segmentos reportables: (a) Holding (matriz, gestión de inversiones), (b) Suramericana S.A. (seguros vida/no-vida/salud), (c) SURA Asset Management S.A. (AFP/fondos), (d) Otros (servicios/comercialización). FY2022-23 no incluido en esta pasada (gap documentado).

Sheet Assumptions_IS
A1: Assumptions_IS — forecast drivers (IS-level, ancladas a FY2025A base). Escenario: 1=Base, 2=Bull, 3=Bear. NOTA: sheet nuevo, independiente del stub legado "Assumptions" (que queda intacto, referenciado por Valuation/Sensitivity/Checks preexistentes).
A3: Escenario activo (1/2/3) | B3: 1
A4: Etiqueta escenario | B4: =CHOOSE(B3,"Base","Bull","Bear") -> Base
A6: Driver | B6: Base | C6: Bull | D6: Bear | E6: Activo (según escenario)
A7: Crecimiento anual — primas retenidas devengadas | B7: 0.06 | C7: 0.09 | D7: 0.02 | E7: =CHOOSE($B$3,B7,C7,D7) -> 0.06
A8: Crecimiento anual — otros ingresos (comisiones+servicios+inversión+método part.) | B8: 0.05 | C8: 0.08 | D8: 0.01 | E8: =CHOOSE($B$3,B8,C8,D8) -> 0.05
A9: Ratio costos y gastos / total ingresos (constante) | B9: 0.848 | C9: 0.83 | D9: 0.875 | E9: =CHOOSE($B$3,B9,C9,D9) -> 0.848
A10: Resultado financiero / total ingresos (constante) | B10: -0.032 | C10: -0.02 | D10: -0.045 | E10: =CHOOSE($B$3,B10,C10,D10) -> -0.032
A11: Tasa impositiva efectiva | B11: 0.35 | C11: 0.33 | D11: 0.38 | E11: =CHOOSE($B$3,B11,C11,D11) -> 0.35
A12: % Ganancia neta atribuible a NCI | B12: 0.18 | C12: 0.16 | D12: 0.2 | E12: =CHOOSE($B$3,B12,C12,D12) -> 0.18
A14: Bases de los drivers: promedio observado FY2022A-FY2025A de la razón costos/ingresos y resultado financiero/ingresos (IS_Hist); crecimiento de primas ajustado por la volatilidad de reclasificaciones 2023-2025 (desconsolidación EPS Suramericana, Escisión Grupo Argos) — Bear castiga el crecimiento por nuevas escisiones/desconsolidaciones, Bull asume estabilización de perímetro.
A15: ALCANCE: forecast a nivel Estado de Resultados solamente (Total ingresos -> Ganancia neta). BS/CF forecast NO construido en esta pasada — marcado PARTIAL (gap documentado en el reporte interno (no publicado)).

Sheet Forecast_IS
A1: Forecast_IS — IS-level (PARTIAL — ver Assumptions_IS!A15) — driver-built, escenario activo: | F1: =Assumptions_IS!B4 -> Base
A3: Línea | B3: FY2026E | C3: FY2027E | D3: FY2028E | E3: FY2029E | F3: FY2030E
A5: Primas retenidas devengadas | B5: =IS_Hist!F12*(1+Assumptions_IS!$E$7) -> 15490201 | C5: =B5*(1+Assumptions_IS!$E$7) -> 16419613 | D5: =C5*(1+Assumptions_IS!$E$7) -> 17404790 | E5: =D5*(1+Assumptions_IS!$E$7) -> 18449077 | F5: =E5*(1+Assumptions_IS!$E$7) -> 19556022
A6: Otros ingresos (resto de líneas de Total ingresos) | B6: =(IS_Hist!F22-IS_Hist!F12)*(1+Assumptions_IS!$E$8) -> 14797988 | C6: =B6*(1+Assumptions_IS!$E$8) -> 15537888 | D6: =C6*(1+Assumptions_IS!$E$8) -> 16314782 | E6: =D6*(1+Assumptions_IS!$E$8) -> 17130521 | F6: =E6*(1+Assumptions_IS!$E$8) -> 17987047
A7: Total ingresos | B7: =B5+B6 -> 30288189 | C7: =C5+C6 -> 31957500 | D7: =D5+D6 -> 33719572 | E7: =E5+E6 -> 35579598 | F7: =F5+F6 -> 37543069
A8: Total costos y gastos (ratio sobre ingresos) | B8: =-B7*Assumptions_IS!$E$9 -> -25684384 | C8: =-C7*Assumptions_IS!$E$9 -> -27099960 | D8: =-D7*Assumptions_IS!$E$9 -> -28594197 | E8: =-E7*Assumptions_IS!$E$9 -> -30171499 | F8: =-F7*Assumptions_IS!$E$9 -> -31836522
A9: Ganancia operativa | B9: =B7+B8 -> 4603804.7 | C9: =C7+C8 -> 4857540.1 | D9: =D7+D8 -> 5125374.9 | E9: =E7+E8 -> 5408098.9 | F9: =F7+F8 -> 5706546.4
A10: Resultado financiero (ratio sobre ingresos) | B10: =B7*Assumptions_IS!$E$10 -> -969222.05 | C10: =C7*Assumptions_IS!$E$10 -> -1022640 | D10: =D7*Assumptions_IS!$E$10 -> -1079026.3 | E10: =E7*Assumptions_IS!$E$10 -> -1138547.1 | F10: =F7*Assumptions_IS!$E$10 -> -1201378.2
A11: Ganancia antes de impuestos | B11: =B9+B10 -> 3634582.7 | C11: =C9+C10 -> 3834900 | D11: =D9+D10 -> 4046348.6 | E11: =E9+E10 -> 4269551.8 | F11: =F9+F10 -> 4505168.2
A12: Impuesto a las ganancias | B12: =-B11*Assumptions_IS!$E$11 -> -1272103.9 | C12: =-C11*Assumptions_IS!$E$11 -> -1342215 | D12: =-D11*Assumptions_IS!$E$11 -> -1416222 | E12: =-E11*Assumptions_IS!$E$11 -> -1494343.1 | F12: =-F11*Assumptions_IS!$E$11 -> -1576808.9
A13: Ganancia neta del período | B13: =B11+B12 -> 2362478.7 | C13: =C11+C12 -> 2492685 | D13: =D11+D12 -> 2630126.6 | E13: =E11+E12 -> 2775208.6 | F13: =F11+F12 -> 2928359.4
A14: Atribuible a la controladora | B14: =B13*(1-Assumptions_IS!$E$12) -> 1937232.6 | C14: =C13*(1-Assumptions_IS!$E$12) -> 2044001.7 | D14: =D13*(1-Assumptions_IS!$E$12) -> 2156703.8 | E14: =E13*(1-Assumptions_IS!$E$12) -> 2275671.1 | F14: =F13*(1-Assumptions_IS!$E$12) -> 2401254.7
A15: Atribuible a NCI | B15: =B13*Assumptions_IS!$E$12 -> 425246.17 | C15: =C13*Assumptions_IS!$E$12 -> 448683.31 | D15: =D13*Assumptions_IS!$E$12 -> 473422.78 | E15: =E13*Assumptions_IS!$E$12 -> 499537.56 | F15: =F13*Assumptions_IS!$E$12 -> 527104.68

Sheet Claude Code Log
A1: Turn # | B1: Date | C1: User Request | D1: Action Taken | E1: Details | F1: Outcome
A2: 1 | B2: 46324.359 | C2: Prepare a public model copy | D2: Remove local paths and private build references; preserve financial formulas and inputs | E2: Agent run with MOG as the tool, checked by guard v1. The guard measured every sheet before and after the run. Changed: Change_Log: 1 cell written, at B7; Sources_Audited: 5 cells written, at C4, C5, C6, C7, A9; USD_Bridge: 2 cells written, at A1, A10; Assumptions_IS: 1 cell written, at A15. Agent: OpenFinmods export | F2: Compare against source and review public copy
