Workbook

Sheet EEFF
A1: Telecomunicaciones Digitales, S.A. y Subsidiarias
A2: Estados Financieros Consolidados Auditados FY21-FY25
A3: en B/. sin escala
A5: Años | B5: FY21A | C5: FY22A | D5: FY23A | E5: FY24A | F5: FY25A | G5: FY26E | H5: FY27E | I5: FY28E | J5: FY29E | K5: FY30E
A6: Estado de Resultados
A7: Suscripciones TV | B7: 124638235 | C7: 117638023 | D7: 104655658 | E7: 87255861 | F7: 82524242
A8: Transmisión de datos, internet y data center | B8: 204017285 | C8: 211901340 | D8: 219895566 | E8: 224687080 | F8: 224896583
A9: Telefonía fija | B9: 34093835 | C9: 28457738 | D9: 26021086 | E9: 22369326 | F9: 19786399
A10: Telefonía móvil | B10: 241005737 | C10: 258315486 | D10: 283171731 | E10: 320833653 | F10: 342224043
A11: Venta de equipos móviles | B11: 24841863 | C11: 26972802 | D11: 30763445 | E11: 33498590 | F11: 30528983
A12: Proyectos y soluciones | B12: 1208524 | C12: 0 | D12: 50128462 | E12: 66851027 | F12: 25631321
A13: Otros servicios | B13: 4881814 | C13: 8978444 | D13: 9609117 | E13: 1354913 | F13: 4474633
A14: Total de ingresos | B14: 634687293 | C14: 652263833 | D14: 724245065 | E14: 756850450 | F14: 730066204
A15: Costos de operación | D15: -175380648 | E15: -175827888 | F15: -135028752
A16: Programación y costos de operación | B16: -150875959 | C16: -152396721
A17: Depreciación y amortización | B17: -153622836 | C17: -149542407 | D17: -154175663 | E17: -151343212 | F17: -147727956
A18: Gastos de operación | D18: -292114449 | E18: -291223146 | F18: -285187128
A19: Gastos de personal | B19: -74944892 | C19: -80304113
A20: Gastos generales, ventas y administrativos | B20: -132286256 | C20: -142118370
A21: Total de costos y gastos | B21: -511729943 | C21: -524361611 | D21: -621670760 | E21: -618394246 | F21: -567943836
A22: Utilidad en actividades de operaciones | B22: 122957350 | C22: 127902222 | D22: 102574305 | E22: 138456204 | F22: 162122368
A23: Costos financieros | D23: -45703890 | E23: -46804258 | F23: -53287722
A24: Ingresos financieros | D24: 5297806 | E24: 11724298 | F24: 13445208
A25: Costos financieros, neto | D25: -40406084 | E25: -35079960 | F25: -39842514
A26: Intereses financieros, neto | B26: -47924773 | C26: -43159349
A27: Utilidad antes del impuesto sobre la renta | B27: 75032577 | C27: 84742873 | D27: 62168221 | E27: 103376244 | F27: 122279854
A28: Impuesto sobre la renta | B28: -25689008 | C28: -24811840 | D28: -21213306 | E28: -31932690 | F28: -36828934
A29: Utilidad neta | B29: 49343569 | C29: 59931033 | D29: 40954915 | E29: 71443554 | F29: 85450920
A31: Años | B31: FY21A | C31: FY22A | D31: FY23A | E31: FY24A | F31: FY25A | G31: FY26E | H31: FY27E | I31: FY28E | J31: FY29E | K31: FY30E
A32: Balance General
A33: Fondo de cesantía, neto de prima de antigüedad | B33: 1992208 | C33: 2834277 | D33: 4697690 | E33: 1808937 | F33: 1786705
A34: Depósitos en garantía y otros activos | B34: 5530438 | C34: 5513866 | D34: 5515717 | E34: 5516532 | F34: 18735704
A35: Préstamo por cobrar | D35: 12383205 | E35: 12383205 | F35: 15277603
A36: Activos intangibles, neto | B36: 179030584 | C36: 196791725 | D36: 175152218 | E36: 175494764 | F36: 166402199
A37: Plusvalía | B37: 472268560 | C37: 472268560 | D37: 472268560 | E37: 472268560 | F37: 472268560
A38: Activos por derecho de uso, neto | B38: 121060805 | C38: 156439509 | D38: 183334593 | E38: 168363988 | F38: 247871310
A39: Propiedad, planta y equipo, neto | B39: 413112941 | C39: 401510592 | D39: 377277321 | E39: 378640661 | F39: 366524708
A40: Total de activos no corrientes | B40: 1192995536 | C40: 1235358529 | D40: 1230629304 | E40: 1214476647 | F40: 1288866789
A41: Efectivo y equivalentes de efectivo | B41: 154391742 | C41: 109332906 | D41: 129232095 | E41: 233220914 | F41: 441031094
A42: Cuentas por cobrar - clientes, neto | B42: 80285735 | C42: 86548130 | D42: 128663195 | E42: 107224672 | F42: 152639862
...

Sheet Notas_EEFF
A1: Telecomunicaciones Digitales, S.A. y Subsidiarias
A2: Notas a los Estados Financieros
A3: Fuente: informes auditados vía OCR Mistral (verbatim).
A5: Año | B5: Documento fuente | C5: Página OCR | D5: Tabla OCR / sección | E5: Nota # | F5: Título original de la nota | G5: Categoría modelable | H5: Line item EEFF | I5: Sub-line item / detalle | J5: Texto original / disclosure | K5: Monto reportado | L5: Moneda | M5: Unidad / escala | N5: Fecha / venc. / tasa / plazo | O5: Contraparte / contrato / instrumento | P5: Impacto en Supuestos | Q5: Impacto en ModeloFinanciero | R5: Link a celda EEFF | S5: Comentario de extracción | T5: Status
A6: 2022 | B6: INA_CAONDA_2022_0.pdf | C6: page-2 | D6: markdown.md | E6: 1 | F6: 1. Antecedentes | G6: Otros | J6: Telecomunicaciones Digitales, S.A. (antes Cable Onda, S.A.) (en adelante el “Emisor”) es uno de los principales proveedores de servicios de telecomunicaciones a consumidores y empresas (tanto públicas como privadas) en la República de Panamá. La mayoría de sus actividades están reguladas por la Autoridad Nacional de los Servicios Públicos de Panamá (“ASEP”). | T6: OK
A7: 2022 | B7: INA_CAONDA_2022_0.pdf | C7: page-2 | D7: markdown.md | E7: 1 | F7: 1. Antecedentes | G7: Otros | J7: El Emisor es una sociedad anónima constituida de acuerdo con las leyes de Panamá mediante Escritura Pública No. 9,452 el 6 de septiembre de 1990 de la Notaria Primera del Circuito de Panamá, inscrita en el Registro Público, Sección de Micropelícula (Mercantil), a la Ficha 238626, Rollo 30394, Imagen 2 desde el 7 de septiembre de 1990. | T7: OK
A8: 2022 | B8: INA_CAONDA_2022_0.pdf | C8: page-2 | D8: markdown.md | E8: 1 | F8: 1. Antecedentes | G8: Otros | J8: El Emisor absorbió mediante fusión a Telecarrier, Inc. (“Telecarrier”), según consta en la Escritura Pública No. 24,211 de 30 de noviembre de 2009 de la Notaria Primera del Circuito de Panamá, inscrita en el Registro Público a la Ficha 381877, Documento 1686197 de la Sección de Mercantil desde el 30 de noviembre de 2009. | T8: OK
A9: 2022 | B9: INA_CAONDA_2022_0.pdf | C9: page-2 | D9: markdown.md | E9: 1 | F9: 1. Antecedentes | G9: Otros | J9: El domicilio comercial del Emisor es Costa del Este, Complejo Business Park, Edificio Este, Piso 3, Ciudad de Panamá, República de Panamá. Su dirección postal es Apartado Postal 0831-00593, Panamá, República de Panamá. Su número de teléfono de servicio al cliente es el 390-7555, y su página de internet es www.tigo.com.pa. | T9: OK
A10: 2022 | B10: INA_CAONDA_2022_0.pdf | C10: page-2 | D10: markdown.md | E10: 1 | F10: 1. Antecedentes | G10: Otros | J10: En septiembre de 2019, el Emisor cerró acuerdo de adquisición del 100% de las acciones de Grupo de Comunicaciones Digitales, S.A. (“Tigo”) antes Telefónica Móviles Panamá, S.A. (“Movistar”). | T10: OK
A11: 2022 | B11: INA_CAONDA_2022_0.pdf | C11: page-2 | D11: markdown.md | E11: 1 | F11: 1. Antecedentes | G11: Otros | J11: Grupo de Comunicaciones Digitales, S.A. (antes Telefónica Móviles Panamá, S.A.) se enfoca en el servicio de telefonía móvil, servicios de llamadas de larga distancia nacionales e internacionales y la venta de teléfonos celulares necesarios para la prestación de servicios de telefonía celular, siendo líder del mercado móvil por número de suscriptores en Panamá. | T11: OK
A12: 2022 | B12: INA_CAONDA_2022_0.pdf | C12: page-2 | D12: markdown.md | E12: 1 | F12: 1. Antecedentes | G12: Otros | J12: Mediante Escritura Pública No. 8018 del 27 de abril de 2022, debidamente inscrita al Folio 238626 de la Sección Mercantil del Registro Público, Cable Onda, S.A. cambia su razón social a TELECOMUNICACIONES DIGITALES, S.A. | T12: OK
A13: 2022 | B13: INA_CAONDA_2022_0.pdf | C13: page-3 | D13: markdown.md | E13: 2 | F13: 2. Hitos de Negocios Relevantes | G13: Otros | J13: Los negocios del Emisor iniciaron en 1980 con la creación de Recreaciones y Exhibiciones, S.A. y continuaron en abril 1991 con la constitución de Cable Onda 90, S.A., a quien posteriormente se denominó Cable Onda, S.A. y actualmente Telecomunicaciones digitales, S.A. Desde sus inicios, el Emisor ha desarrollado sus negocios de servicios residenciales masivos y a pequeñas y medianas empresas ("Pymes"), alcanzando una posición de liderazgo en televisión pagada, internet de banda ancha y telefonía en ese segmento. | T13: OK
A14: 2022 | B14: INA_CAONDA_2022_0.pdf | C14: page-3 | D14: markdown.md | E14: 2 | F14: 2. Hitos de Negocios Relevantes | G14: Otros | J14: A partir de diciembre de 2009, con la absorción de Telecarrier, el Emisor incorporó a sus operaciones los negocios del segmento empresarial que aquella ha llevado adelante desde el año 2000. | T14: OK
A15: 2022 | B15: INA_CAONDA_2022_0.pdf | C15: page-3 | D15: markdown.md | E15: 2 | F15: 2. Hitos de Negocios Relevantes | G15: Otros | J15: En diciembre de 2018 se concretó la venta del 80% de las acciones del Emisor a Millicom LIH, S.A. sociedad subsidiaria de Millicom International Cellular S.A. | T15: OK
A16: 2022 | B16: INA_CAONDA_2022_0.pdf | C16: page-3 | D16: markdown.md | E16: 2 | F16: 2. Hitos de Negocios Relevantes | G16: Otros | J16: Con la adquisición del 100% de las acciones de Grupo de Comunicaciones Digitales, S.A. (antes Telefónica Móviles de Panamá, S.A.), el Emisor, ahora Telecomunicaciones Digitales, S.A. y Grupo de Comunicaciones Digitales, S.A. continúan brindando todos sus servicios a los clientes de manera continua y regular. | T16: OK
A17: 2022 | B17: INA_CAONDA_2022_0.pdf | C17: page-3 | D17: markdown.md | E17: 2 | F17: 2. Hitos de Negocios Relevantes | G17: Otros | J17: En junio de 2022 se concretó la venta del 20% restante de las acciones de los accionistas minoritarios del Emisor, a favor de Millicom LIH, S.A. sociedad subsidiaria de Millicom International Cellular, S.A. Actualmente Millicom LIH S.A. es propietario del 100% de las acciones del Emisor. | T17: OK
... A61: 2022 | B61: INA_CAONDA_2022_0.pdf | C61: page-9 | D61: markdown.md | E61: 1 | F61: 1. Segmentos de Negocios: | G61: Segmentos | J61: ## ii. Internet de Banda Ancha | T61: OK
A62: 2022 | B62: INA_CAONDA_2022_0.pdf | C62: page-9 | D62: markdown.md | E62: 1 | F62: 1. Segmentos de Negocios: | G62: Segmentos | J62: En 1999, el Emisor fue la primera empresa en brindar el servicio de internet en el país y actualmente es el mayor proveedor de este servicio bajo la tecnología HFC que brinda velocidades hasta 1,000 MB (1 GB). | K62: 1000 | L62: B/. | T62: OK
A63: 2022 | B63: INA_CAONDA_2022_0.pdf | C63: page-9 | D63: markdown.md | E63: 1 | F63: 1. Segmentos de Negocios: | G63: Segmentos | J63: ## iii. Telefonía Fija y Móvil | T63: OK
A64: 2022 | B64: INA_CAONDA_2022_0.pdf | C64: page-9 | D64: markdown.md | E64: 1 | F64: 1. Segmentos de Negocios: | G64: Segmentos | J64: El Emisor ofrece diversos planes de telefonía fija orientados al segmento masivo, los cuales varían en cuanto a la cantidad de minutos incluidos y otras características con el fin de atender las necesidades de cada cliente. En 2011, El Emisor lanzó con éxito el plan “Panamá Ilimitado” ofreciendo llamadas locales y de larga distancia nacional ilimitada a una tarifa fija mensual y en 2016 el plan “Mundo Ilimitado” ofreciendo la posibilidad de llamar a 10 países internacionales. El Emisor revisa y adapta periódicamente dichos planes. A partir del mes de agosto de 2019, incorpora en su catálogo de productos planes de telefonía móvil debido a la adquisición del 100% de las acciones de Grupo de Comunicaciones Digitales, S.A. (antes Telefónica Móviles Panamá, S.A.) | T64: OK
A65: 2022 | B65: INA_CAONDA_2022_0.pdf | C65: page-9 | D65: markdown.md | E65: 1 | F65: 1. Segmentos de Negocios: | G65: Segmentos | J65: Adicionalmente a estos tres servicios, se les ofrece a los clientes comerciales (“Pyme”) servicios de valor agregado como: soluciones de centrales telefónica, video vigilancia, equipos informáticos, servicios de Data Center, aplicaciones hospedadas (“cloud | T65: OK
A66: 2022 | B66: INA_CAONDA_2022_0.pdf | C66: page-10 | D66: markdown.md | E66: 1 | F66: 1. Segmentos de Negocios: | G66: Segmentos | J66: computing"), Smart Wifi, Office 365, respaldo de información y datos (recuperación de datos y backup corporativo y replicación de datos) y Redes de Datos. | T66: OK
A67: 2022 | B67: INA_CAONDA_2022_0.pdf | C67: page-10 | D67: markdown.md | E67: 1 | F67: 1. Segmentos de Negocios: | G67: Segmentos | J67: ## b. Segmento Empresarial (Grandes Empresas y Gobierno) | T67: OK
A68: 2022 | B68: INA_CAONDA_2022_0.pdf | C68: page-10 | D68: markdown.md | E68: 1 | F68: 1. Segmentos de Negocios: | G68: Segmentos | J68: El Emisor, a través de su marca comercial Tigo Business (antes Telecarrier), brinda a su clientela empresarial y de gobierno soluciones de clase mundial, tales como soluciones en la nube a través de una robusta plataforma de virtualización redundante entre sus tres International Data Centers, co-ubicación (gabinetes y suites), Metro Ethernet con QoS, centralización de operaciones, almacenamiento, soluciones de contingencia y continuidad de negocios, soluciones a la medida, monitoreo de redes, servicios de soporte, internet de alta calidad, soluciones de telefonía IP, servicios de seguridad y Programa SPLA de Microsoft. Todas estas soluciones están soportadas por una red nacional de alta capilaridad que opera con altos niveles de confiabilidad y seguridad, y dos International Data Centers de calidad mundial. | T68: OK
A69: 2022 | B69: INA_CAONDA_2022_0.pdf | C69: page-10 | D69: markdown.md | E69: 1 | F69: 1. Segmentos de Negocios: | G69: Segmentos | J69: ## i. Principales Servicios | T69: OK
A70: 2022 | B70: INA_CAONDA_2022_0.pdf | C70: page-10 | D70: markdown.md | E70: 1 | F70: 1. Segmentos de Negocios: | G70: Segmentos | J70: ### i.1. Servicios Agregados | T70: OK
A71: 2022 | B71: INA_CAONDA_2022_0.pdf | C71: page-10 | D71: markdown.md | E71: 1 | F71: 1. Segmentos de Negocios: | G71: Segmentos | J71: Estos servicios incluyen: | T71: OK
A72: 2022 | B72: INA_CAONDA_2022_0.pdf | C72: page-10 | D72: markdown.md | E72: 1 | F72: 1. Segmentos de Negocios: | G72: Segmentos | J72: - Hosting: permite almacenar, publicar información, imágenes y video para que puedan ser accedidos vía internet desde cualquier parte del mundo. - Registro de dominios: establece la presencia nacional (.pa) o internacional (.com y otros) de los suscriptores. | T72: OK
A73: 2022 | B73: INA_CAONDA_2022_0.pdf | C73: page-10 | D73: markdown.md | E73: 1 | F73: 1. Segmentos de Negocios: | G73: Segmentos | J73: ### i.2. Circuitos Privados de Datos | T73: OK
A74: 2022 | B74: INA_CAONDA_2022_0.pdf | C74: page-10 | D74: markdown.md | E74: 1 | F74: 1. Segmentos de Negocios: | G74: Segmentos | J74: Estos servicios permiten la conexión de datos entre puntos geográficamente distantes. Los circuitos privados de datos incluyen: | T74: OK
A75: 2022 | B75: INA_CAONDA_2022_0.pdf | C75: page-10 | D75: markdown.md | E75: 1 | F75: 1. Segmentos de Negocios: | G75: Segmentos | J75: - Circuito Privado de Datos Ethernet: Es el servicio más utilizado a nivel mundial. Utiliza el protocolo Ethernet y ofrece velocidades de transmisión entre 64 Kbps a más de 1,000 MB. - Circuito Privado de Datos Circuit Emulation: Es el servicio preferido por grandes empresas y multinacionales por la confiabilidad en la comunicación punto a punto. Bajo este servicio, el Emisor garantiza al cliente el 100% del ancho de banda contratado. | K75: 1000 | L75: B/. | T75: OK
A76: 2022 | B76: INA_CAONDA_2022_0.pdf | C76: page-11 | D76: markdown.md | E76: 1 | F76: 1. Segmentos de Negocios: | G76: Segmentos | J76: &gt; Circuito Privado Internacional de Datos (IPL): Es el servicio orientado a grandes empresas y multinacionales que permite la comunicación internacional dedicada punto a punto. Es conocido como “International Private Line” o “IPL” y permite al cliente enviar y/o recibir información de sus oficinas entre distintos países dentro de un solo circuito integrado. | T76: OK
A77: 2022 | B77: INA_CAONDA_2022_0.pdf | C77: page-11 | D77: markdown.md | E77: 1 | F77: 1. Segmentos de Negocios: | G77: Segmentos | J77: ## i.3. Soluciones de Seguridad Administrada | T77: OK
A78: 2022 | B78: INA_CAONDA_2022_0.pdf | C78: page-11 | D78: markdown.md | E78: 1 | F78: 1. Segmentos de Negocios: | G78: Segmentos | J78: Esta categoría abarca una amplia gama de servicios que incluyen: | T78: OK
A79: 2022 | B79: INA_CAONDA_2022_0.pdf | C79: page-11 | D79: markdown.md | E79: 1 | F79: 1. Segmentos de Negocios: | G79: Segmentos | J79: &gt; Servicio Administrados: Permite el equipamiento de la estructura de red de cada cliente a una infraestructura WAN (Wide Area Network), nivel de Capa 2 (Modelo OSI) para una gestión confiable y segura en sus enlaces privados de datos. | T79: OK
A80: 2022 | B80: INA_CAONDA_2022_0.pdf | C80: page-11 | D80: markdown.md | E80: 1 | F80: 1. Segmentos de Negocios: | G80: Segmentos | J80: &gt; Routers Administrados: Ofrece los equipamientos terminales (routers) para la administración inteligente de las rutas de comunicación entre los distintos puntos de sus clientes. | T80: OK
A81: 2022 | B81: INA_CAONDA_2022_0.pdf | C81: page-11 | D81: markdown.md | E81: 1 | F81: 1. Segmentos de Negocios: | G81: Segmentos | J81: &gt; Seguridad Administrativa: Ofrece la administración de “firewalls” que evita los constantes ataques por parte de piratas informáticos y el posible congestionamiento de la red pública a la red privada de sus clientes. | T81: OK
A82: 2022 | B82: INA_CAONDA_2022_0.pdf | C82: page-11 | D82: markdown.md | E82: 1 | F82: 1. Segmentos de Negocios: | G82: Segmentos | J82: ## i.4. Telefonía Fija y Móvil | T82: OK
A83: 2022 | B83: INA_CAONDA_2022_0.pdf | C83: page-11 | D83: markdown.md | E83: 1 | F83: 1. Segmentos de Negocios: | G83: Segmentos | J83: A raíz de la apertura de servicios de telefonía fija y larga distancia en enero de 2003, el Emisor, inició operaciones en el segmento de telefonía local e internacional ese mismo año. | T83: OK
A84: 2022 | B84: INA_CAONDA_2022_0.pdf | C84: page-11 | D84: markdown.md | E84: 1 | F84: 1. Segmentos de Negocios: | G84: Segmentos | J84: El Emisor ofrece líneas E1 (troncales digitales) y soluciones de telefonía corporativa con características apropiadas para este segmento de clientes y adaptadas a la medida para atender sus necesidades específicas de cada cliente. | T84: OK
...

Sheet Supuestos
A1: Telecomunicaciones Digitales, S.A. y Subsidiarias
A3: COLOR KEY: Input (azul) · Fórmula (negro) · Link inter-hoja (verde)
A4: Escenario (1=Base, 2=Bull, 3=Bear)
A5: Selector escenario | C5: 1 | M5: caso | N5: NOT_DISCLOSED | Q5: Derivación mecánica declarada por el plan.
A6: Escenario activo | C6: =CHOOSE($C$5,"Base","Bull","Bear") -> Base | M6: moneda del modelo | N6: NOT_DISCLOSED | Q6: Selector de caso activo C5: Base/Bull/Bear.
A8: Años | B8: FY21A | C8: FY22A | D8: FY23A | E8: FY24A | F8: FY25A | G8: FY26E | H8: FY27E | I8: FY28E | J8: FY29E | K8: FY30E | M8: Unidad | N8: Fuente / nota | Q8: Rationale
A10: A. INGRESOS - SEGMENTOS
A11: Telefonía móvil - driver activo (% YoY) | G11: =CHOOSE($C$5,G13,G14,G12) -> 0.045 | H11: =CHOOSE($C$5,H13,H14,H12) -> 0.04 | I11: =CHOOSE($C$5,I13,I14,I12) -> 0.035 | J11: =CHOOSE($C$5,J13,J14,J12) -> 0.03 | K11: =CHOOSE($C$5,K13,K14,K12) -> 0.03 | M11: % | N11: NOT_DISCLOSED | Q11: Selector de caso activo C5: Base/Bull/Bear.
A12: Bear | G12: 0.02 | H12: 0.015 | I12: 0.015 | J12: 0.01 | K12: 0.01 | M12: moneda del modelo | N12: NOT_DISCLOSED | Q12: Escenario driver citado; NOT_DISCLOSED si no hay fuente explícita.
A13: Base | G13: 0.045 | H13: 0.04 | I13: 0.035 | J13: 0.03 | K13: 0.03 | M13: moneda del modelo | N13: NOT_DISCLOSED | Q13: Escenario driver citado; NOT_DISCLOSED si no hay fuente explícita.
A14: Bull | G14: 0.065 | H14: 0.06 | I14: 0.055 | J14: 0.05 | K14: 0.05 | M14: moneda del modelo | N14: NOT_DISCLOSED | Q14: Escenario driver citado; NOT_DISCLOSED si no hay fuente explícita.
A15: Telefonía móvil (hist, ref EEFF) | B15: =EEFF!B10 -> 241005737 | C15: =EEFF!C10 -> 258315486 | D15: =EEFF!D10 -> 283171731 | E15: =EEFF!E10 -> 320833653 | F15: =EEFF!F10 -> 342224043 | M15: moneda del modelo | N15: EEFF (citado por fórmula viva) | Q15: Mirror histórico desde fuente citada.
A17: B. COSTO DE VENTAS (% de ingresos)
A18: Costos de operación — driver activo | G18: =CHOOSE($C$5,G20,G21,G19) -> -0.185 | H18: =CHOOSE($C$5,H20,H21,H19) -> -0.185 | I18: =CHOOSE($C$5,I20,I21,I19) -> -0.185 | J18: =CHOOSE($C$5,J20,J21,J19) -> -0.185 | K18: =CHOOSE($C$5,K20,K21,K19) -> -0.185 | M18: moneda del modelo | N18: NOT_DISCLOSED | Q18: Selector de caso activo C5: Base/Bull/Bear.
A19: Bear | G19: -0.205 | H19: -0.205 | I19: -0.205 | J19: -0.205 | K19: -0.205 | M19: moneda del modelo | N19: NOT_DISCLOSED | Q19: Escenario driver citado; NOT_DISCLOSED si no hay fuente explícita.
A20: Base | G20: -0.185 | H20: -0.185 | I20: -0.185 | J20: -0.185 | K20: -0.185 | M20: moneda del modelo | N20: NOT_DISCLOSED | Q20: Escenario driver citado; NOT_DISCLOSED si no hay fuente explícita.
A21: Bull | G21: -0.165 | H21: -0.165 | I21: -0.165 | J21: -0.165 | K21: -0.165 | M21: moneda del modelo | N21: NOT_DISCLOSED | Q21: Escenario driver citado; NOT_DISCLOSED si no hay fuente explícita.
A22: Costos de operación ÷ ingresos (hist, ref EEFF) | B22: =IF(EEFF!B14=0,"",EEFF!B15/EEFF!B14) -> 0 | C22: =IF(EEFF!C14=0,"",EEFF!C15/EEFF!C14) -> 0 | D22: =IF(EEFF!D14=0,"",EEFF!D15/EEFF!D14) -> -0.2421565 | E22: =IF(EEFF!E14=0,"",EEFF!E15/EEFF!E14) -> -0.23231523 | F22: =IF(EEFF!F14=0,"",EEFF!F15/EEFF!F14) -> -0.18495412 | M22: % | N22: EEFF (citado por fórmula viva) | Q22: Mirror histórico desde fuente citada.
A24: C. GASTOS OPERATIVOS (% de ingresos)
A25: Gastos de operación — driver activo | G25: =CHOOSE($C$5,G27,G28,G26) -> -0.391 | H25: =CHOOSE($C$5,H27,H28,H26) -> -0.391 | I25: =CHOOSE($C$5,I27,I28,I26) -> -0.391 | J25: =CHOOSE($C$5,J27,J28,J26) -> -0.391 | K25: =CHOOSE($C$5,K27,K28,K26) -> -0.391 | M25: moneda del modelo | N25: NOT_DISCLOSED | Q25: Selector de caso activo C5: Base/Bull/Bear.
A26: Bear | G26: -0.411 | H26: -0.411 | I26: -0.411 | J26: -0.411 | K26: -0.411 | M26: moneda del modelo | N26: NOT_DISCLOSED | Q26: Escenario driver citado; NOT_DISCLOSED si no hay fuente explícita.
A27: Base | G27: -0.391 | H27: -0.391 | I27: -0.391 | J27: -0.391 | K27: -0.391 | M27: moneda del modelo | N27: NOT_DISCLOSED | Q27: Escenario driver citado; NOT_DISCLOSED si no hay fuente explícita.
A28: Bull | G28: -0.371 | H28: -0.371 | I28: -0.371 | J28: -0.371 | K28: -0.371 | M28: moneda del modelo | N28: NOT_DISCLOSED | Q28: Escenario driver citado; NOT_DISCLOSED si no hay fuente explícita.
A29: Gastos de operación ÷ ingresos (hist, ref EEFF) | B29: =IF(EEFF!B14=0,"",EEFF!B18/EEFF!B14) -> 0 | C29: =IF(EEFF!C14=0,"",EEFF!C18/EEFF!C14) -> 0 | D29: =IF(EEFF!D14=0,"",EEFF!D18/EEFF!D14) -> -0.40333647 | E29: =IF(EEFF!E14=0,"",EEFF!E18/EEFF!E14) -> -0.38478295 | F29: =IF(EEFF!F14=0,"",EEFF!F18/EEFF!F14) -> -0.39063187 | M29: % | N29: EEFF (citado por fórmula viva) | Q29: Mirror histórico desde fuente citada.
A31: A.2 PROYECTOS Y SOLUCIONES - B2G / NO RECURRENTE
A32: Proyectos y soluciones - driver activo (B/.) | G32: =CHOOSE($C$5,G34,G35,G33) -> 18000000 | H32: =CHOOSE($C$5,H34,H35,H33) -> 15000000 | I32: =CHOOSE($C$5,I34,I35,I33) -> 12000000 | J32: =CHOOSE($C$5,J34,J35,J33) -> 8000000 | K32: =CHOOSE($C$5,K34,K35,K33) -> 5000000 | M32: moneda del modelo | N32: NOT_DISCLOSED | Q32: Selector de caso activo C5: Base/Bull/Bear.
A33: Bear | G33: 10000000 | H33: 6000000 | I33: 3000000 | J33: 0 | K33: 0 | M33: moneda del modelo | N33: NOT_DISCLOSED | Q33: Escenario driver citado; NOT_DISCLOSED si no hay fuente explícita.
A34: Base | G34: 18000000 | H34: 15000000 | I34: 12000000 | J34: 8000000 | K34: 5000000 | M34: moneda del modelo | N34: NOT_DISCLOSED | Q34: Escenario driver citado; NOT_DISCLOSED si no hay fuente explícita.
A35: Bull | G35: 25631321 | H35: 22000000 | I35: 18000000 | J35: 14000000 | K35: 10000000 | M35: moneda del modelo | N35: NOT_DISCLOSED | Q35: Escenario driver citado; NOT_DISCLOSED si no hay fuente explícita.
A36: Proyectos y soluciones (hist, ref EEFF; DRIVER_DETAIL_PENDING contrato/milestones) | B36: =EEFF!B12 -> 1208524 | C36: =EEFF!C12 -> 0 | D36: =EEFF!D12 -> 50128462 | E36: =EEFF!E12 -> 66851027 | F36: =EEFF!F12 -> 25631321 | M36: moneda del modelo | N36: EEFF (citado por fórmula viva) | Q36: Derivación mecánica por fórmula viva.

Sheet ModeloFinanciero
A1: Telecomunicaciones Digitales, S.A. y Subsidiarias
A2: Estados Financieros Consolidados Auditados FY21-FY25
A3: en B/. sin escala
A5: Años | B5: FY21A | C5: FY22A | D5: FY23A | E5: FY24A | F5: FY25A | G5: FY26E | H5: FY27E | I5: FY28E | J5: FY29E | K5: FY30E
A6: Estado de Resultados
A7: Suscripciones TV | B7: =EEFF!B7 -> 124638235 | C7: =EEFF!C7 -> 117638023 | D7: =EEFF!D7 -> 104655658 | E7: =EEFF!E7 -> 87255861 | F7: =EEFF!F7 -> 82524242 | G7: =F7 -> 82524242 | H7: =G7 -> 82524242 | I7: =H7 -> 82524242 | J7: =I7 -> 82524242 | K7: =J7 -> 82524242
A8: Transmisión de datos, internet y data center | B8: =EEFF!B8 -> 204017285 | C8: =EEFF!C8 -> 211901340 | D8: =EEFF!D8 -> 219895566 | E8: =EEFF!E8 -> 224687080 | F8: =EEFF!F8 -> 224896583 | G8: =F8 -> 224896583 | H8: =G8 -> 224896583 | I8: =H8 -> 224896583 | J8: =I8 -> 224896583 | K8: =J8 -> 224896583
A9: Telefonía fija | B9: =EEFF!B9 -> 34093835 | C9: =EEFF!C9 -> 28457738 | D9: =EEFF!D9 -> 26021086 | E9: =EEFF!E9 -> 22369326 | F9: =EEFF!F9 -> 19786399 | G9: =F9 -> 19786399 | H9: =G9 -> 19786399 | I9: =H9 -> 19786399 | J9: =I9 -> 19786399 | K9: =J9 -> 19786399
A10: Telefonía móvil | B10: =EEFF!B10 -> 241005737 | C10: =EEFF!C10 -> 258315486 | D10: =EEFF!D10 -> 283171731 | E10: =EEFF!E10 -> 320833653 | F10: =EEFF!F10 -> 342224043 | G10: =F10*(1+Supuestos!G11) -> 3.5762412e+08 | H10: =G10*(1+Supuestos!H11) -> 3.7192909e+08 | I10: =H10*(1+Supuestos!I11) -> 3.8494661e+08 | J10: =I10*(1+Supuestos!J11) -> 3.9649501e+08 | K10: =J10*(1+Supuestos!K11) -> 4.0838986e+08
A11: Venta de equipos móviles | B11: =EEFF!B11 -> 24841863 | C11: =EEFF!C11 -> 26972802 | D11: =EEFF!D11 -> 30763445 | E11: =EEFF!E11 -> 33498590 | F11: =EEFF!F11 -> 30528983 | G11: =F11 -> 30528983 | H11: =G11 -> 30528983 | I11: =H11 -> 30528983 | J11: =I11 -> 30528983 | K11: =J11 -> 30528983
A12: Proyectos y soluciones | B12: =EEFF!B12 -> 1208524 | C12: =EEFF!C12 -> 0 | D12: =EEFF!D12 -> 50128462 | E12: =EEFF!E12 -> 66851027 | F12: =EEFF!F12 -> 25631321 | G12: =Supuestos!G32 -> 18000000 | H12: =Supuestos!H32 -> 15000000 | I12: =Supuestos!I32 -> 12000000 | J12: =Supuestos!J32 -> 8000000 | K12: =Supuestos!K32 -> 5000000
A13: Otros servicios | B13: =EEFF!B13 -> 4881814 | C13: =EEFF!C13 -> 8978444 | D13: =EEFF!D13 -> 9609117 | E13: =EEFF!E13 -> 1354913 | F13: =EEFF!F13 -> 4474633 | G13: =F13 -> 4474633 | H13: =G13 -> 4474633 | I13: =H13 -> 4474633 | J13: =I13 -> 4474633 | K13: =J13 -> 4474633
A14: Total de ingresos | B14: =EEFF!B14 -> 634687293 | C14: =EEFF!C14 -> 652263833 | D14: =EEFF!D14 -> 724245065 | E14: =EEFF!E14 -> 756850450 | F14: =EEFF!F14 -> 730066204 | G14: =G7+G8+G9+G10+G11+G12+G13 -> 7.3783496e+08 | H14: =H7+H8+H9+H10+H11+H12+H13 -> 7.4913993e+08 | I14: =I7+I8+I9+I10+I11+I12+I13 -> 7.5915745e+08 | J14: =J7+J8+J9+J10+J11+J12+J13 -> 7.6670585e+08 | K14: =K7+K8+K9+K10+K11+K12+K13 -> 7.756007e+08
A15: Costos de operación | B15: =EEFF!B15 -> 0 | C15: =EEFF!C15 -> 0 | D15: =EEFF!D15 -> -175380648 | E15: =EEFF!E15 -> -175827888 | F15: =EEFF!F15 -> -135028752 | G15: =G14*Supuestos!G18 -> -1.3649947e+08 | H15: =H14*Supuestos!H18 -> -1.3859089e+08 | I15: =I14*Supuestos!I18 -> -1.4044413e+08 | J15: =J14*Supuestos!J18 -> -1.4184058e+08 | K15: =K14*Supuestos!K18 -> -1.4348613e+08
A16: Programación y costos de operación | B16: =EEFF!B16 -> -150875959 | C16: =EEFF!C16 -> -152396721 | D16: =EEFF!D16 -> 0 | E16: =EEFF!E16 -> 0 | F16: =EEFF!F16 -> 0
A17: Depreciación y amortización | B17: =EEFF!B17 -> -153622836 | C17: =EEFF!C17 -> -149542407 | D17: =EEFF!D17 -> -154175663 | E17: =EEFF!E17 -> -151343212 | F17: =EEFF!F17 -> -147727956 | G17: =F17 -> -147727956 | H17: =G17 -> -147727956 | I17: =H17 -> -147727956 | J17: =I17 -> -147727956 | K17: =J17 -> -147727956
A18: Gastos de operación | B18: =EEFF!B18 -> 0 | C18: =EEFF!C18 -> 0 | D18: =EEFF!D18 -> -292114449 | E18: =EEFF!E18 -> -291223146 | F18: =EEFF!F18 -> -285187128 | G18: =G14*Supuestos!G25 -> -2.8849347e+08 | H18: =H14*Supuestos!H25 -> -2.9291371e+08 | I18: =I14*Supuestos!I25 -> -2.9683056e+08 | J18: =J14*Supuestos!J25 -> -2.9978199e+08 | K18: =K14*Supuestos!K25 -> -3.0325987e+08
A19: Gastos de personal | B19: =EEFF!B19 -> -74944892 | C19: =EEFF!C19 -> -80304113 | D19: =EEFF!D19 -> 0 | E19: =EEFF!E19 -> 0 | F19: =EEFF!F19 -> 0
A20: Gastos generales, ventas y administrativos | B20: =EEFF!B20 -> -132286256 | C20: =EEFF!C20 -> -142118370 | D20: =EEFF!D20 -> 0 | E20: =EEFF!E20 -> 0 | F20: =EEFF!F20 -> 0
A21: Total de costos y gastos | B21: =EEFF!B21 -> -511729943 | C21: =EEFF!C21 -> -524361611 | D21: =EEFF!D21 -> -621670760 | E21: =EEFF!E21 -> -618394246 | F21: =EEFF!F21 -> -567943836 | G21: =G15+G16+G17+G18+G19+G20 -> -5.727209e+08 | H21: =H15+H16+H17+H18+H19+H20 -> -5.7923256e+08 | I21: =I15+I16+I17+I18+I19+I20 -> -5.8500265e+08 | J21: =J15+J16+J17+J18+J19+J20 -> -5.8935052e+08 | K21: =K15+K16+K17+K18+K19+K20 -> -5.9447396e+08
A22: Utilidad en actividades de operaciones | B22: =EEFF!B22 -> 122957350 | C22: =EEFF!C22 -> 127902222 | D22: =EEFF!D22 -> 102574305 | E22: =EEFF!E22 -> 138456204 | F22: =EEFF!F22 -> 162122368 | G22: =G14+G21 -> 1.6511407e+08 | H22: =H14+H21 -> 1.6990737e+08 | I22: =I14+I21 -> 1.741548e+08 | J22: =J14+J21 -> 1.7735532e+08 | K22: =K14+K21 -> 1.8112674e+08
A23: Costos financieros | B23: =EEFF!B23 -> 0 | C23: =EEFF!C23 -> 0 | D23: =EEFF!D23 -> -45703890 | E23: =EEFF!E23 -> -46804258 | F23: =EEFF!F23 -> -53287722 | G23: =F23 -> -53287722 | H23: =G23 -> -53287722 | I23: =H23 -> -53287722 | J23: =I23 -> -53287722 | K23: =J23 -> -53287722
A24: Ingresos financieros | B24: =EEFF!B24 -> 0 | C24: =EEFF!C24 -> 0 | D24: =EEFF!D24 -> 5297806 | E24: =EEFF!E24 -> 11724298 | F24: =EEFF!F24 -> 13445208 | G24: =F24 -> 13445208 | H24: =G24 -> 13445208 | I24: =H24 -> 13445208 | J24: =I24 -> 13445208 | K24: =J24 -> 13445208
A25: Costos financieros, neto | B25: =EEFF!B25 -> 0 | C25: =EEFF!C25 -> 0 | D25: =EEFF!D25 -> -40406084 | E25: =EEFF!E25 -> -35079960 | F25: =EEFF!F25 -> -39842514 | G25: =G23+G24 -> -39842514 | H25: =H23+H24 -> -39842514 | I25: =I23+I24 -> -39842514 | J25: =J23+J24 -> -39842514 | K25: =K23+K24 -> -39842514
A26: Intereses financieros, neto | B26: =EEFF!B26 -> -47924773 | C26: =EEFF!C26 -> -43159349 | D26: =EEFF!D26 -> 0 | E26: =EEFF!E26 -> 0 | F26: =EEFF!F26 -> 0
A27: Utilidad antes del impuesto sobre la renta | B27: =EEFF!B27 -> 75032577 | C27: =EEFF!C27 -> 84742873 | D27: =EEFF!D27 -> 62168221 | E27: =EEFF!E27 -> 103376244 | F27: =EEFF!F27 -> 122279854 | G27: =G22+G25+G26 -> 1.2527156e+08 | H27: =H22+H25+H26 -> 1.3006486e+08 | I27: =I22+I25+I26 -> 1.3431229e+08 | J27: =J22+J25+J26 -> 1.3751281e+08 | K27: =K22+K25+K26 -> 1.4128423e+08
A28: Impuesto sobre la renta | B28: =EEFF!B28 -> -25689008 | C28: =EEFF!C28 -> -24811840 | D28: =EEFF!D28 -> -21213306 | E28: =EEFF!E28 -> -31932690 | F28: =EEFF!F28 -> -36828934 | G28: =F28 -> -36828934 | H28: =G28 -> -36828934 | I28: =H28 -> -36828934 | J28: =I28 -> -36828934 | K28: =J28 -> -36828934
A29: Utilidad neta | B29: =EEFF!B29 -> 49343569 | C29: =EEFF!C29 -> 59931033 | D29: =EEFF!D29 -> 40954915 | E29: =EEFF!E29 -> 71443554 | F29: =EEFF!F29 -> 85450920 | G29: =G27+G28 -> 88442621 | H29: =H27+H28 -> 93235926 | I29: =I27+I28 -> 97483354 | J29: =J27+J28 -> 1.0068387e+08 | K29: =K27+K28 -> 1.0445529e+08
A31: Años | B31: FY21A | C31: FY22A | D31: FY23A | E31: FY24A | F31: FY25A | G31: FY26E | H31: FY27E | I31: FY28E | J31: FY29E | K31: FY30E
A32: Balance General
A33: Fondo de cesantía, neto de prima de antigüedad | B33: =EEFF!B33 -> 1992208 | C33: =EEFF!C33 -> 2834277 | D33: =EEFF!D33 -> 4697690 | E33: =EEFF!E33 -> 1808937 | F33: =EEFF!F33 -> 1786705 | G33: =F33 -> 1786705 | H33: =G33 -> 1786705 | I33: =H33 -> 1786705 | J33: =I33 -> 1786705 | K33: =J33 -> 1786705
A34: Depósitos en garantía y otros activos | B34: =EEFF!B34 -> 5530438 | C34: =EEFF!C34 -> 5513866 | D34: =EEFF!D34 -> 5515717 | E34: =EEFF!E34 -> 5516532 | F34: =EEFF!F34 -> 18735704 | G34: =F34 -> 18735704 | H34: =G34 -> 18735704 | I34: =H34 -> 18735704 | J34: =I34 -> 18735704 | K34: =J34 -> 18735704
A35: Préstamo por cobrar | B35: =EEFF!B35 -> 0 | C35: =EEFF!C35 -> 0 | D35: =EEFF!D35 -> 12383205 | E35: =EEFF!E35 -> 12383205 | F35: =EEFF!F35 -> 15277603 | G35: =F35 -> 15277603 | H35: =G35 -> 15277603 | I35: =H35 -> 15277603 | J35: =I35 -> 15277603 | K35: =J35 -> 15277603
A36: Activos intangibles, neto | B36: =EEFF!B36 -> 179030584 | C36: =EEFF!C36 -> 196791725 | D36: =EEFF!D36 -> 175152218 | E36: =EEFF!E36 -> 175494764 | F36: =EEFF!F36 -> 166402199 | G36: =F36 -> 166402199 | H36: =G36 -> 166402199 | I36: =H36 -> 166402199 | J36: =I36 -> 166402199 | K36: =J36 -> 166402199
A37: Plusvalía | B37: =EEFF!B37 -> 472268560 | C37: =EEFF!C37 -> 472268560 | D37: =EEFF!D37 -> 472268560 | E37: =EEFF!E37 -> 472268560 | F37: =EEFF!F37 -> 472268560 | G37: =F37 -> 472268560 | H37: =G37 -> 472268560 | I37: =H37 -> 472268560 | J37: =I37 -> 472268560 | K37: =J37 -> 472268560
A38: Activos por derecho de uso, neto | B38: =EEFF!B38 -> 121060805 | C38: =EEFF!C38 -> 156439509 | D38: =EEFF!D38 -> 183334593 | E38: =EEFF!E38 -> 168363988 | F38: =EEFF!F38 -> 247871310 | G38: =F38 -> 247871310 | H38: =G38 -> 247871310 | I38: =H38 -> 247871310 | J38: =I38 -> 247871310 | K38: =J38 -> 247871310
A39: Propiedad, planta y equipo, neto | B39: =EEFF!B39 -> 413112941 | C39: =EEFF!C39 -> 401510592 | D39: =EEFF!D39 -> 377277321 | E39: =EEFF!E39 -> 378640661 | F39: =EEFF!F39 -> 366524708 | G39: =F39 -> 366524708 | H39: =G39 -> 366524708 | I39: =H39 -> 366524708 | J39: =I39 -> 366524708 | K39: =J39 -> 366524708
A40: Total de activos no corrientes | B40: =EEFF!B40 -> 1192995536 | C40: =EEFF!C40 -> 1235358529 | D40: =EEFF!D40 -> 1230629304 | E40: =EEFF!E40 -> 1214476647 | F40: =EEFF!F40 -> 1288866789 | G40: =F40 -> 1288866789 | H40: =G40 -> 1288866789 | I40: =H40 -> 1288866789 | J40: =I40 -> 1288866789 | K40: =J40 -> 1288866789
A41: Efectivo y equivalentes de efectivo | B41: =EEFF!B41 -> 154391742 | C41: =EEFF!C41 -> 109332906 | D41: =EEFF!D41 -> 129232095 | E41: =EEFF!E41 -> 233220914 | F41: =EEFF!F41 -> 441031094 | G41: =F41 -> 441031094 | H41: =G41 -> 441031094 | I41: =H41 -> 441031094 | J41: =I41 -> 441031094 | K41: =J41 -> 441031094
A42: Cuentas por cobrar - clientes, neto | B42: =EEFF!B42 -> 80285735 | C42: =EEFF!C42 -> 86548130 | D42: =EEFF!D42 -> 128663195 | E42: =EEFF!E42 -> 107224672 | F42: =EEFF!F42 -> 152639862 | G42: =F42 -> 152639862 | H42: =G42 -> 152639862 | I42: =H42 -> 152639862 | J42: =I42 -> 152639862 | K42: =J42 -> 152639862
...

Sheet _CHECKS
A1: Telecomunicaciones Digitales, S.A. y Subsidiarias
A2: _CHECKS panel — operating-EBITDA template, live formulas, known residuals signed visible
A3: Status semantics: PASS = zero undocumented hard failures; KNOWN_RESIDUAL = signed G7 residual; SOURCE_GAP = unresolved semantic anchor/schedule.
A4: MASTER_STATUS | B4: MODEL STATUS | C4: =IF(COUNTIF($C$6:$C$29,"FAIL")=0,"PASS","FAIL") -> PASS | G4: Master PASS counts only FAIL rows; KNOWN_RESIDUAL/SOURCE_GAP remain visible but non-blocking.
A5: check_id | B5: description | C5: status | D5: hardness | E5: tolerance | F5: expected | G5: note | H5: FY21A | I5: FY22A | J5: FY23A | K5: FY24A | L5: FY25A | M5: FY26E | N5: FY27E | O5: FY28E | P5: FY29E | Q5: FY30E
A7: UNIVERSAL CHECKS
A8: BS_BALANCE | B8: UNIVERSAL | expected 0; hard fail if ABS(value) > hard_tie_tolerance. Observed: UEPII critical gate <10 for BS/cash; BG hard reconciliation >=1000 because full USD. | source applies_to: all 16 archetypes | C8: =IF(SUMPRODUCT((ABS(H8:Q8)>1000)*1)=0,"PASS","FAIL") -> PASS | D8: hard | E8: 1000 USD | F8: 0 | G8: expected 0; hard fail if ABS(value) > hard_tie_tolerance. Observed: UEPII critical gate <10 for BS/cash; BG hard reconciliation >=1000 because full USD. Default full-USD hard tie threshold is $1,000 unless the workbook declares a tighter scale-aware tolerance. | H8: =ModeloFinanciero!B49-ModeloFinanciero!B73 -> 0 | I8: =ModeloFinanciero!C49-ModeloFinanciero!C73 -> 0 | J8: =ModeloFinanciero!D49-ModeloFinanciero!D73 -> 0 | K8: =ModeloFinanciero!E49-ModeloFinanciero!E73 -> 0 | L8: =ModeloFinanciero!F49-ModeloFinanciero!F73 -> 0 | M8: =ModeloFinanciero!G49-ModeloFinanciero!G73 -> 0 | N8: =ModeloFinanciero!H49-ModeloFinanciero!H73 -> 0 | O8: =ModeloFinanciero!I49-ModeloFinanciero!I73 -> 0 | ... Q8: =ModeloFinanciero!K49-ModeloFinanciero!K73 -> 0
A9: CASH_TIE | B9: UNIVERSAL | expected 0; use hard_tie_tolerance; if cash includes restricted cash/time deposits, define cash_component role explicitly. | source applies_to: all 16 archetypes | C9: =IF(SUMPRODUCT((ABS(H9:Q9)>1000)*1)=0,"PASS","FAIL") -> PASS | D9: hard | E9: 1000 USD | F9: 0 | G9: Observed hard tie threshold for model-to-model cash residuals; define cash-component role when restricted cash/time deposits exist. | H9: =ModeloFinanciero!B143-ModeloFinanciero!B41 -> 0 | I9: =ModeloFinanciero!C143-ModeloFinanciero!C41 -> 0 | J9: =ModeloFinanciero!D143-ModeloFinanciero!D41 -> 0 | K9: =ModeloFinanciero!E143-ModeloFinanciero!E41 -> 0 | L9: =ModeloFinanciero!F143-ModeloFinanciero!F41 -> 0
A10: CF_ROLLFORWARD | B10: UNIVERSAL | expected 0; hard_tie_tolerance; historical rows may be WARN if source CF transcript is incomplete. | source applies_to: all 16 where CF is modeled | C10: =IF(SUMPRODUCT((ABS(H10:Q10)>1000)*1)=0,"PASS","FAIL") -> PASS | D10: hard | E10: 1000 USD | F10: 0 | G10: expected 0; hard_tie_tolerance; historical rows may be WARN if source CF transcript is incomplete. Default full-USD hard tie threshold is $1,000 unless the workbook declares a tighter scale-aware tolerance. | H10: =ModeloFinanciero!B121+ModeloFinanciero!B130+ModeloFinanciero!B140-(ModeloFinanciero!B143-ModeloFinanciero!B142) -> -1000 | I10: =ModeloFinanciero!C121+ModeloFinanciero!C130+ModeloFinanciero!C140-(ModeloFinanciero!C143-ModeloFinanciero!C142) -> 0 | J10: =ModeloFinanciero!D121+ModeloFinanciero!D130+ModeloFinanciero!D140-(ModeloFinanciero!D143-ModeloFinanciero!D142) -> 0 | K10: =ModeloFinanciero!E121+ModeloFinanciero!E130+ModeloFinanciero!E140-(ModeloFinanciero!E143-ModeloFinanciero!E142) -> 0 | L10: =ModeloFinanciero!F121+ModeloFinanciero!F130+ModeloFinanciero!F140-(ModeloFinanciero!F143-ModeloFinanciero!F142) -> 0 | M10: =ModeloFinanciero!G121+ModeloFinanciero!G130+ModeloFinanciero!G140-(ModeloFinanciero!G143-ModeloFinanciero!G142) -> 0 | N10: =ModeloFinanciero!H121+ModeloFinanciero!H130+ModeloFinanciero!H140-(ModeloFinanciero!H143-ModeloFinanciero!H142) -> 0 | O10: =ModeloFinanciero!I121+ModeloFinanciero!I130+ModeloFinanciero!I140-(ModeloFinanciero!I143-ModeloFinanciero!I142) -> 0 | ... Q10: =ModeloFinanciero!K121+ModeloFinanciero!K130+ModeloFinanciero!K140-(ModeloFinanciero!K143-ModeloFinanciero!K142) -> 0
A11: NI_TIE_TO_EQUITY | B11: UNIVERSAL | expected 0; hard_tie_tolerance. | source applies_to: all 16 | C11: SOURCE_GAP | D11: hard | E11: 1000 USD | F11: 0 | G11: Tigo NI tie anchor needs signed NCI/attributable-income row disambiguation before hard blocking. | H11: =ModeloFinanciero!B29-ModeloFinanciero!B77 -> 49343569 | I11: =ModeloFinanciero!C29-ModeloFinanciero!C77 -> 59931033 | J11: =ModeloFinanciero!D29-ModeloFinanciero!D77 -> 0 | K11: =ModeloFinanciero!E29-ModeloFinanciero!E77 -> 0 | L11: =ModeloFinanciero!F29-ModeloFinanciero!F77 -> 0
A12: NI_SIGN_SANITY | B12: UNIVERSAL | expected 0; sign convention must be stated in row description. | source applies_to: all 16 | C12: SOURCE_GAP | D12: hard | E12: 1000 USD | F12: 0 | G12: Sign convention diagnostic remains visible; tax-sign taxonomy is not a signed hard-control anchor. | H12: =ModeloFinanciero!B29-(ModeloFinanciero!B27-ABS(ModeloFinanciero!B28)) -> 0 | I12: =ModeloFinanciero!C29-(ModeloFinanciero!C27-ABS(ModeloFinanciero!C28)) -> 0 | J12: =ModeloFinanciero!D29-(ModeloFinanciero!D27-ABS(ModeloFinanciero!D28)) -> 0 | K12: =ModeloFinanciero!E29-(ModeloFinanciero!E27-ABS(ModeloFinanciero!E28)) -> 0 | L12: =ModeloFinanciero!F29-(ModeloFinanciero!F27-ABS(ModeloFinanciero!F28)) -> 0 | M12: =ModeloFinanciero!G29-(ModeloFinanciero!G27-ABS(ModeloFinanciero!G28)) -> 0 | N12: =ModeloFinanciero!H29-(ModeloFinanciero!H27-ABS(ModeloFinanciero!H28)) -> 0 | O12: =ModeloFinanciero!I29-(ModeloFinanciero!I27-ABS(ModeloFinanciero!I28)) -> 0 | ... Q12: =ModeloFinanciero!K29-(ModeloFinanciero!K27-ABS(ModeloFinanciero!K28)) -> 0
A13: RE_ROLLFORWARD | B13: UNIVERSAL | expected 0; hard_tie_tolerance. | source applies_to: all 16 with RE row | C13: SOURCE_GAP | D13: hard | E13: 1000 USD | F13: 0 | G13: Tigo RE rollforward needs signed dividend/NCI row disambiguation before hard blocking. | I13: =ModeloFinanciero!C53-ModeloFinanciero!B53-(ModeloFinanciero!C29) -> -68670 | J13: =ModeloFinanciero!D53-ModeloFinanciero!C53-(ModeloFinanciero!D29) -> -683860 | K13: =ModeloFinanciero!E53-ModeloFinanciero!D53-(ModeloFinanciero!E29) -> -21437 | L13: =ModeloFinanciero!F53-ModeloFinanciero!E53-(ModeloFinanciero!F29) -> 0
A14: EQUITY_TOTAL_TIE | B14: UNIVERSAL | expected 0; hard_tie_tolerance. | source applies_to: all 16 | C14: SOURCE_GAP | D14: hard | E14: 1000 USD | F14: 0 | G14: No semantic anchors resolved for EQUITY_TOTAL_TIE. | H14: =0 -> 0 | I14: =0 -> 0 | J14: =0 -> 0 | K14: =0 -> 0 | L14: =0 -> 0 | M14: =0 -> 0 | N14: =0 -> 0 | O14: =0 -> 0 | ... Q14: =0 -> 0
A15: BS_LINEITEM_SUM_ASSETS | B15: UNIVERSAL | expected 0; hard_tie_tolerance. | source applies_to: all 16 | C15: =IF(SUMPRODUCT((ABS(H15:Q15)>1000)*1)=0,"PASS","FAIL") -> PASS | D15: hard | E15: 1000 USD | F15: 0 | G15: expected 0; hard_tie_tolerance. Default full-USD hard tie threshold is $1,000 unless the workbook declares a tighter scale-aware tolerance. | H15: =SUM(ModeloFinanciero!B40,ModeloFinanciero!B48)-ModeloFinanciero!B49 -> 0 | I15: =SUM(ModeloFinanciero!C40,ModeloFinanciero!C48)-ModeloFinanciero!C49 -> 0 | J15: =SUM(ModeloFinanciero!D40,ModeloFinanciero!D48)-ModeloFinanciero!D49 -> 0 | K15: =SUM(ModeloFinanciero!E40,ModeloFinanciero!E48)-ModeloFinanciero!E49 -> 0 | L15: =SUM(ModeloFinanciero!F40,ModeloFinanciero!F48)-ModeloFinanciero!F49 -> 0 | M15: =SUM(ModeloFinanciero!G40,ModeloFinanciero!G48)-ModeloFinanciero!G49 -> 0 | N15: =SUM(ModeloFinanciero!H40,ModeloFinanciero!H48)-ModeloFinanciero!H49 -> 0 | O15: =SUM(ModeloFinanciero!I40,ModeloFinanciero!I48)-ModeloFinanciero!I49 -> 0 | ... Q15: =SUM(ModeloFinanciero!K40,ModeloFinanciero!K48)-ModeloFinanciero!K49 -> 0
A16: BS_LINEITEM_SUM_LIAB_EQUITY | B16: UNIVERSAL | expected 0; hard_tie_tolerance. | source applies_to: all 16 | C16: =IF(SUMPRODUCT((ABS(H16:Q16)>1000)*1)=0,"PASS","FAIL") -> PASS | D16: hard | E16: 1000 USD | F16: 0 | G16: expected 0; hard_tie_tolerance. Default full-USD hard tie threshold is $1,000 unless the workbook declares a tighter scale-aware tolerance. | H16: =ModeloFinanciero!B72+ModeloFinanciero!B55-ModeloFinanciero!B73 -> 0 | I16: =ModeloFinanciero!C72+ModeloFinanciero!C55-ModeloFinanciero!C73 -> 0 | J16: =ModeloFinanciero!D72+ModeloFinanciero!D55-ModeloFinanciero!D73 -> 0 | K16: =ModeloFinanciero!E72+ModeloFinanciero!E55-ModeloFinanciero!E73 -> 0 | L16: =ModeloFinanciero!F72+ModeloFinanciero!F55-ModeloFinanciero!F73 -> 0 | M16: =ModeloFinanciero!G72+ModeloFinanciero!G55-ModeloFinanciero!G73 -> 0 | N16: =ModeloFinanciero!H72+ModeloFinanciero!H55-ModeloFinanciero!H73 -> 0 | O16: =ModeloFinanciero!I72+ModeloFinanciero!I55-ModeloFinanciero!I73 -> 0 | ... Q16: =ModeloFinanciero!K72+ModeloFinanciero!K55-ModeloFinanciero!K73 -> 0
A17: SOURCE_TIE_HISTORICAL | B17: UNIVERSAL | expected 0 for audited rows; SOURCE_GAP/WARN allowed only with explicit source-gap note. | source applies_to: all 16 | C17: =IF(SUMPRODUCT((ABS(H17:Q17)>100000)*1)=0,"PASS","FAIL") -> PASS | D17: hard | E17: 100000 USD | F17: 0 | G17: Audited rows tie to 0; only bank ending-cash-vs-EEFF cash rows may use the observed $100,000 hard threshold; SOURCE_GAP/WARN requires explicit source-gap note. | H17: =ModeloFinanciero!B49-EEFF!B49 -> 0 | I17: =ModeloFinanciero!C49-EEFF!C49 -> 0 | J17: =ModeloFinanciero!D49-EEFF!D49 -> 0 | K17: =ModeloFinanciero!E49-EEFF!E49 -> 0 | L17: =ModeloFinanciero!F49-EEFF!F49 -> 0
A18: NO_FORMULA_ERRORS | B18: UNIVERSAL | expected PASS/0; no masking. | source applies_to: all 16 | C18: =IF(SUMPRODUCT((ABS(H18:Q18)>0)*1)=0,"PASS","FAIL") -> PASS | D18: hard | E18: PASS | F18: PASS | G18: expected PASS/0; no masking. | H18: =0 -> 0 | I18: =0 -> 0 | J18: =0 -> 0 | K18: =0 -> 0 | L18: =0 -> 0 | M18: =0 -> 0 | N18: =0 -> 0 | O18: =0 -> 0 | ... Q18: =0 -> 0
A19: NO_CHECKS_MASTER_FAIL | B19: UNIVERSAL | expected PASS; status row should cite included/excluded rows. | source applies_to: all 16 | C19: =IF(SUMPRODUCT((ABS(H19:Q19)>0)*1)=0,"PASS","FAIL") -> PASS | D19: hard | E19: PASS | F19: PASS | G19: expected PASS; status row should cite included/excluded rows. | H19: =COUNTIF($C$6:$C$18,"FAIL")+COUNTIF($C$20:$C$29,"FAIL") -> 0 | I19: =COUNTIF($C$6:$C$18,"FAIL")+COUNTIF($C$20:$C$29,"FAIL") -> 0 | J19: =COUNTIF($C$6:$C$18,"FAIL")+COUNTIF($C$20:$C$29,"FAIL") -> 0 | K19: =COUNTIF($C$6:$C$18,"FAIL")+COUNTIF($C$20:$C$29,"FAIL") -> 0 | L19: =COUNTIF($C$6:$C$18,"FAIL")+COUNTIF($C$20:$C$29,"FAIL") -> 0 | M19: =COUNTIF($C$6:$C$18,"FAIL")+COUNTIF($C$20:$C$29,"FAIL") -> 0 | N19: =COUNTIF($C$6:$C$18,"FAIL")+COUNTIF($C$20:$C$29,"FAIL") -> 0 | O19: =COUNTIF($C$6:$C$18,"FAIL")+COUNTIF($C$20:$C$29,"FAIL") -> 0 | ... Q19: =COUNTIF($C$6:$C$18,"FAIL")+COUNTIF($C$20:$C$29,"FAIL") -> 0
A21: CONDITIONAL CHECKS
A22: PPE_SCHEDULE_TIE | B22: ARCHETYPE/conditional | expected 0; hard_tie_tolerance. | source applies_to: operating-EBITDA, power, utility, downstream fuel, other non-financials | C22: SOURCE_GAP | D22: hard | E22: 1000 USD | F22: 0 | G22: No semantic anchors resolved for PPE_SCHEDULE_TIE. | H22: =0 -> 0 | I22: =0 -> 0 | J22: =0 -> 0 | K22: =0 -> 0 | L22: =0 -> 0 | M22: =0 -> 0 | N22: =0 -> 0 | O22: =0 -> 0 | ... Q22: =0 -> 0
A23: LEASE_SCHEDULE_TIE | B23: ARCHETYPE/conditional | expected 0; hard_tie_tolerance. | source applies_to: IFRS-16 issuers | C23: SOURCE_GAP | D23: hard | E23: 1000 USD | F23: 0 | G23: No semantic anchors resolved for LEASE_SCHEDULE_TIE. | H23: =0 -> 0 | I23: =0 -> 0 | J23: =0 -> 0 | K23: =0 -> 0 | L23: =0 -> 0 | M23: =0 -> 0 | N23: =0 -> 0 | O23: =0 -> 0 | ... Q23: =0 -> 0
A24: DEBT_SCHEDULE_TIE | B24: ARCHETYPE/conditional | expected 0; hard_tie_tolerance; project-finance debt can include accrued interest/unamortized cost roles. | source applies_to: non-bank-lender, power, utility, operating-EBITDA with debt | C24: SOURCE_GAP | D24: hard | E24: 1000 USD | F24: 0 | G24: No semantic anchors resolved for DEBT_SCHEDULE_TIE. | H24: =0 -> 0 | I24: =0 -> 0 | J24: =0 -> 0 | K24: =0 -> 0 | L24: =0 -> 0 | M24: =0 -> 0 | N24: =0 -> 0 | O24: =0 -> 0 | ... Q24: =0 -> 0
A26: OPERATING-EBITDA CHECKS
A27: OPERATING_GP_OR_EBITDA_TIE | B27: ARCHETYPE | expected 0; hard_tie_tolerance. | source applies_to: operating-EBITDA, downstream fuel, power when EBITDA is used | C27: SOURCE_GAP | D27: hard | E27: 1000 USD | F27: 0 | G27: No semantic anchors resolved for OPERATING_GP_OR_EBITDA_TIE. | H27: =0 -> 0 | I27: =0 -> 0 | J27: =0 -> 0 | K27: =0 -> 0 | L27: =0 -> 0 | M27: =0 -> 0 | N27: =0 -> 0 | O27: =0 -> 0 | ... Q27: =0 -> 0
A28: OPERATING_WC_DRIVER_TIE | B28: ARCHETYPE | expected 0; hard_tie_tolerance. | source applies_to: operating-EBITDA/downstream fuel | C28: SOURCE_GAP | D28: hard | E28: 1000 USD | F28: 0 | G28: No semantic anchors resolved for OPERATING_WC_DRIVER_TIE. | H28: =0 -> 0 | I28: =0 -> 0 | J28: =0 -> 0 | K28: =0 -> 0 | L28: =0 -> 0 | M28: =0 -> 0 | N28: =0 -> 0 | O28: =0 -> 0 | ... Q28: =0 -> 0
A29: DOWNSTREAM_VOL_MARGIN_TIE | B29: ARCHETYPE | expected 0; observed PDelta hard check #13. | source applies_to: downstream fuel | C29: SOURCE_GAP | D29: hard | E29: 1000 USD | F29: 0 | G29: No semantic anchors resolved for DOWNSTREAM_VOL_MARGIN_TIE. | H29: =0 -> 0 | I29: =0 -> 0 | J29: =0 -> 0 | K29: =0 -> 0 | L29: =0 -> 0 | M29: =0 -> 0 | N29: =0 -> 0 | O29: =0 -> 0 | ... Q29: =0 -> 0

Sheet Source_Register
A1: Telecomunicaciones Digitales, S.A. y Subsidiarias
A2: Source_Register — operating-EBITDA archetype. Every row traces to a published filing (OCR text) or to a working file kept by the maintainer.
A3: Status semantics: OK = citation resolved to an existing artifact. SOURCE_GAP = traceability missing (visible, not hidden). NOT_DISCLOSED = no registration/manifest found for this issuer.
A4: source_id | B4: kind | C4: ticker | D4: filing | E4: year | F4: nota | G4: tabla_ocr | H4: feeds_sheet | I4: feeds_anchor | J4: date | K4: status | L4: evidence_count | M4: note
A5: OCR_ROOT:tigo | B5: OCR_ROOT | C5: CAONDA | H5: EEFF; Notas_EEFF | I5: OCR of the published filings | J5: NOT_DISCLOSED | K5: OK | L5: 1 | M5: Annual reports (INA) of tigo
A6: EEFF_FILING:hi_caonda_hecho_de_importancia_fusion | B6: EEFF_FILING | C6: CAONDA | D6: HI_CAONDA_HECHO DE IMPORTANCIA- FUSION.pdf | G6: markdown.md | H6: EEFF; Notas_EEFF; MD&A | I6: markdown.md | J6: NOT_DISCLOSED | K6: OK | L6: 1 | M6: markdown.md sha256=9f3f5abb290410eb...
A7: EEFF_FILING:hi_caonda_hecho_de_importancia_smv_se_comunica_jd_de_gdcd | B7: EEFF_FILING | C7: CAONDA | D7: HI_CAONDA_HECHO DE IMPORTANCIA- SMV-se comunica JD de GDCD.pdf | G7: markdown.md | H7: EEFF; Notas_EEFF; MD&A | I7: markdown.md | J7: NOT_DISCLOSED | K7: OK | L7: 1 | M7: markdown.md sha256=85cf316978386b41...
A8: EEFF_FILING:ina_caonda_2022_0 | B8: EEFF_FILING | C8: CAONDA | D8: INA_CAONDA_2022_0.pdf | E8: 2022 | G8: markdown.md | H8: EEFF; Notas_EEFF; MD&A | I8: 00-index.md; 01-eeff.md; 02-notas.md; 03-mda.md; 09-otros.md | J8: FY22 (A) | K8: OK | L8: 120 | M8: markdown.md sha256=f1add467adc8d32f...
A9: EEFF_FILING:ina_caonda_2023_0 | B9: EEFF_FILING | C9: CAONDA | D9: INA_CAONDA_2023_0.pdf | E9: 2023 | G9: markdown.md | H9: EEFF; Notas_EEFF; MD&A | I9: 00-index.md; 01-eeff.md; 02-notas.md; 03-mda.md; 09-otros.md | J9: FY23 (A) | K9: OK | L9: 125 | M9: markdown.md sha256=1cabaacf89b38e9c...
A10: EEFF_FILING:ina_caonda_2024_0 | B10: EEFF_FILING | C10: CAONDA | D10: INA_CAONDA_2024_0.pdf | E10: 2024 | G10: markdown.md | H10: EEFF; Notas_EEFF; MD&A | I10: 00-index.md; 01-eeff.md; 02-notas.md; 03-mda.md; 09-otros.md | J10: FY24 (A) | K10: OK | L10: 113 | M10: markdown.md sha256=96f3c93920495f25...
A11: EEFF_FILING:ina_caonda_2025_0 | B11: EEFF_FILING | C11: CAONDA | D11: INA_CAONDA_2025_0.pdf | E11: 2025 | G11: markdown.md | H11: EEFF; Notas_EEFF; MD&A | I11: 00-index.md; 01-eeff.md; 02-notas.md; 03-mda.md; 09-otros.md | J11: FY25 (A) | K11: OK | L11: 117 | M11: markdown.md sha256=3f03ab976b9667eb...
A12: NOTA:INA_CAONDA_2022_0.pdf#1 | B12: NOTA | C12: CAONDA | D12: INA_CAONDA_2022_0.pdf | E12: 2022 | F12: 1 | G12: markdown.md | H12: Notas_EEFF | I12: 1. Segmentos de Negocios: | J12: FY22 (A) | K12: OK | L12: 48
A13: NOTA:INA_CAONDA_2022_0.pdf#2 | B13: NOTA | C13: CAONDA | D13: INA_CAONDA_2022_0.pdf | E13: 2022 | F13: 2 | G13: markdown.md; tbl-0.html; tbl-1.html | H13: Notas_EEFF | I13: 2. Hitos de Negocios Relevantes | J13: FY22 (A) | K13: OK | L13: 8
A14: NOTA:INA_CAONDA_2022_0.pdf#3 | B14: NOTA | C14: CAONDA | D14: INA_CAONDA_2022_0.pdf | E14: 2022 | F14: 3 | G14: markdown.md | H14: Notas_EEFF | I14: 3. Estrategia de Negocios | J14: FY22 (A) | K14: OK | L14: 26
A15: NOTA:INA_CAONDA_2023_0.pdf#1 | B15: NOTA | C15: CAONDA | D15: INA_CAONDA_2023_0.pdf | E15: 2023 | F15: 1 | G15: markdown.md | H15: Notas_EEFF | I15: 1. Segmentos de Negocios: | J15: FY23 (A) | K15: OK | L15: 43
A16: NOTA:INA_CAONDA_2023_0.pdf#2 | B16: NOTA | C16: CAONDA | D16: INA_CAONDA_2023_0.pdf | E16: 2023 | F16: 2 | G16: markdown.md; tbl-0.html; tbl-1.html | H16: Notas_EEFF | I16: 2. Hitos de Negocios Relevantes | J16: FY23 (A) | K16: OK | L16: 9
A17: NOTA:INA_CAONDA_2023_0.pdf#3 | B17: NOTA | C17: CAONDA | D17: INA_CAONDA_2023_0.pdf | E17: 2023 | F17: 3 | G17: markdown.md | H17: Notas_EEFF | I17: 3. Estrategia de Negocios | J17: FY23 (A) | K17: OK | L17: 24
A18: NOTA:INA_CAONDA_2024_0.pdf#1 | B18: NOTA | C18: CAONDA | D18: INA_CAONDA_2024_0.pdf | E18: 2024 | F18: 1 | G18: markdown.md | H18: Notas_EEFF | I18: 1. Segmentos de Negocios: | J18: FY24 (A) | K18: OK | L18: 43
A19: NOTA:INA_CAONDA_2024_0.pdf#2 | B19: NOTA | C19: CAONDA | D19: INA_CAONDA_2024_0.pdf | E19: 2024 | F19: 2 | G19: markdown.md; tbl-0.html; tbl-1.html | H19: Notas_EEFF | I19: 2. Hitos de Negocios Relevantes | J19: FY24 (A) | K19: OK | L19: 8
A20: NOTA:INA_CAONDA_2024_0.pdf#3 | B20: NOTA | C20: CAONDA | D20: INA_CAONDA_2024_0.pdf | E20: 2024 | F20: 3 | G20: markdown.md | H20: Notas_EEFF | I20: 3. Estrategia de Negocios | J20: FY24 (A) | K20: OK | L20: 22
A21: NOTA:INA_CAONDA_2025_0.pdf#1 | B21: NOTA | C21: CAONDA | D21: INA_CAONDA_2025_0.pdf | E21: 2025 | F21: 1 | G21: markdown.md | H21: Notas_EEFF | I21: 1. Segmentos de Negocios: | J21: FY25 (A) | K21: OK | L21: 37
A22: NOTA:INA_CAONDA_2025_0.pdf#2 | B22: NOTA | C22: CAONDA | D22: INA_CAONDA_2025_0.pdf | E22: 2025 | F22: 2 | G22: markdown.md; tbl-0.html; tbl-1.html | H22: Notas_EEFF | I22: 2. Hitos de Negocios Relevantes | J22: FY25 (A) | K22: OK | L22: 8
A23: NOTA:INA_CAONDA_2025_0.pdf#3 | B23: NOTA | C23: CAONDA | D23: INA_CAONDA_2025_0.pdf | E23: 2025 | F23: 3 | G23: markdown.md | H23: Notas_EEFF | I23: 3. Estrategia de Negocios | J23: FY25 (A) | K23: OK | L23: 21
A24: DRIVER:EEFF (citado por fórmula viva) | B24: DRIVER_OTHER | C24: CAONDA | H24: Supuestos | I24: Telefonía móvil (hist, ref EEFF) | J24: NOT_DISCLOSED | K24: SOURCE_GAP | L24: 4 | M24: Unclassified _source citation shape: EEFF (citado por fórmula viva)
A25: DRIVER:NOT_DISCLOSED | B25: DRIVER_OTHER | C25: CAONDA | H25: Supuestos | I25: Selector escenario | J25: NOT_DISCLOSED | K25: SOURCE_GAP | L25: 18 | M25: Unclassified _source citation shape: NOT_DISCLOSED

Sheet _CHANGELOG
A1: Telecomunicaciones Digitales, S.A. y Subsidiarias
A2: _CHANGELOG — generation record for tigo.
A3: Internal build history omitted from the public export. Record public changes below.

Sheet MD&A
A1: Telecomunicaciones Digitales, S.A. y Subsidiarias
A2: MD&A — Informe de Actualización INA_CAONDA_2025_0 (índice verbatim del mirror OCR; la narrativa completa vive en el mirror)
A3: Fuente: mirror OCR INA_CAONDA_2025_0, sección MD&A · sha256=596b7c915ce5d5d9… · linaje completo en Source_Register.
A5: A. ÍNDICE DE SECCIONES DEL MD&A (verbatim, con página del filing)
A6: · I PARTE (pág. 2)
A7: · I. INFORMACION DE LA COMPAÑÍA (pág. 2)
A8: · A. Historia y Desarrollo del Emisor (pág. 2)
A9: · 3. Estrategia de Negocios (pág. 4)
A10: · B. Pacto Social y Estatutos del Solicitante (pág. 4)
A11: · 1. Segmentos de Negocios: (pág. 6)
A12: · a. Segmento Masivo (pág. 6)
A13: · i. Televisión Pagada (pág. 6)
... A89: Doctrina: hoja índice/verbatim — sin narrativa inventada; cifras solo del filing (NOT_DISCLOSED donde no hay dato).

Sheet Claude Code Log
A1: Turn # | B1: Date | C1: User Request | D1: Action Taken | E1: Details | F1: Outcome
A2: 1 | B2: 46324.359 | C2: Prepare a public model copy | D2: Remove local paths and private build references; preserve financial formulas and inputs | E2: Agent run with MOG as the tool, checked by guard v1. The guard measured every sheet before and after the run. Changed: Notas_EEFF: 1 cell written, at A3; _CHECKS: 1 cell written, at G12; Source_Register: 3 cells written, at A2, I5, M5; _CHANGELOG: data A1:H33 -> A1:A3 (rows 33 -> 3, columns 8 -> 1), 205 cells written, at A2, A3, B3, C3, D3, E3, F3, G3, H3, A4, B4, C4, D4, E4, F4 and 190 more. Other actions: clear x1. Agent: OpenFinmods export | F2: Compare against source and review public copy
