Workbook

Sheet 00_Cover
A1: Apple Inc. (AAPL) — 9/10 Re-gated Institutional Model
A2: Owner-prepared submission; independent reviewer reproduction is required before certification
A4: Model snapshot
A5: Legal entity | B5: Apple Inc.
A6: Ticker | B6: AAPL
A7: Latest filing | B7: 2025-09-27 10-K filed 2025-10-31
A8: SEC accession | B8: 0000320193-25-000079
A9: Market price | B9: 327.5
A10: Market as-of | B10: 2026-07-15
A11: Active scenario | B11: =Assumptions!B4 -> Base
A12: DCF value / share | B12: =Valuation!G18 -> 136.40517
A13: Upside / (downside) | B13: =Valuation!G20 -> -0.58349567
A14: Gate decision | B14: =Gate_9of10!B17 -> OWNER READY — INDEPENDENT REVIEW REQUIRED
A16: What changed in the 9/10 re-gate
A17: 1 | B17: Replaced generic Sources sheet with target-cell provenance ledger
A18: 2 | B18: Replaced generic assumptions with company-specific operating drivers
A19: 3 | B19: Scenario selector now changes multiple operating outputs and the DCF
A20: 4 | B20: Debt, liquid assets and share-count valuation bridges are explicit
A21: 5 | B21: Checks are formula-driven; Gate_9of10 states owner evidence and review status
A22: 6 | B22: All original workbook files remain preserved; this is a new derivative output

Sheet Sources
A1: Apple Inc. — Source Provenance Ledger
A2: Every populated hardcoded historical or driver input is mapped to a target cell with period, value, unit, taxonomy/locator, accession and exact URL.
A4: Source ID | B4: Legal Entity | C4: Target Cell | D4: Metric | E4: Period / As-of | F4: Reported Value | G4: Units | H4: Currency | I4: Taxonomy / Locator | J4: Start | K4: End | L4: FY / FP | M4: Form | N4: Filed | O4: Accession | P4: Exact URL | Q4: Retrieved | R4: Source Class | S4: Transform / Mapping | T4: Verification | U4: Limitation / Disposition | V4: Complete?
A5: 1 | B5: Apple Inc. | C5: Historical!B5 | D5: Revenue | E5: 2021A | F5: 365817 | G5: USD millions | H5: USD | I5: us-gaap:RevenueFromContractWithCustomerExcludingAssessedTax | J5: 2020-09-27 | K5: 2021-09-25 | L5: 2023/FY | M5: 10-K | N5: 2023-11-03 | O5: 0000320193-23-000106 | P5: https://www.sec.gov/Archives/edgar/data/320193/000032019323000106/0000320193-23-000106-index.htm | Q5: 2026-07-16 | R5: Primary - SEC filing / Company Facts | S5: USD divided by 1,000,000; sign as presented | T5: Matched legal entity, period, form, filed date, accession and target | U5: None identified | V5: =IF(COUNTA(A5:U5)=21,"OK","MISSING") -> OK
A6: 2 | B6: Apple Inc. | C6: Historical!C5 | D6: Revenue | E6: 2022A | F6: 394328 | G6: USD millions | H6: USD | I6: us-gaap:RevenueFromContractWithCustomerExcludingAssessedTax | J6: 2021-09-26 | K6: 2022-09-24 | L6: 2024/FY | M6: 10-K | N6: 2024-11-01 | O6: 0000320193-24-000123 | P6: https://www.sec.gov/Archives/edgar/data/320193/000032019324000123/0000320193-24-000123-index.htm | Q6: 2026-07-16 | R6: Primary - SEC filing / Company Facts | S6: USD divided by 1,000,000; sign as presented | T6: Matched legal entity, period, form, filed date, accession and target | U6: None identified | V6: =IF(COUNTA(A6:U6)=21,"OK","MISSING") -> OK
A7: 3 | B7: Apple Inc. | C7: Historical!D5 | D7: Revenue | E7: 2023A | F7: 383285 | G7: USD millions | H7: USD | I7: us-gaap:RevenueFromContractWithCustomerExcludingAssessedTax | J7: 2022-09-25 | K7: 2023-09-30 | L7: 2025/FY | M7: 10-K | N7: 2025-10-31 | O7: 0000320193-25-000079 | P7: https://www.sec.gov/Archives/edgar/data/320193/000032019325000079/0000320193-25-000079-index.htm | Q7: 2026-07-16 | R7: Primary - SEC filing / Company Facts | S7: USD divided by 1,000,000; sign as presented | T7: Matched legal entity, period, form, filed date, accession and target | U7: None identified | V7: =IF(COUNTA(A7:U7)=21,"OK","MISSING") -> OK
A8: 4 | B8: Apple Inc. | C8: Historical!E5 | D8: Revenue | E8: 2024A | F8: 391035 | G8: USD millions | H8: USD | I8: us-gaap:RevenueFromContractWithCustomerExcludingAssessedTax | J8: 2023-10-01 | K8: 2024-09-28 | L8: 2025/FY | M8: 10-K | N8: 2025-10-31 | O8: 0000320193-25-000079 | P8: https://www.sec.gov/Archives/edgar/data/320193/000032019325000079/0000320193-25-000079-index.htm | Q8: 2026-07-16 | R8: Primary - SEC filing / Company Facts | S8: USD divided by 1,000,000; sign as presented | T8: Matched legal entity, period, form, filed date, accession and target | U8: None identified | V8: =IF(COUNTA(A8:U8)=21,"OK","MISSING") -> OK
A9: 5 | B9: Apple Inc. | C9: Historical!F5 | D9: Revenue | E9: 2025A | F9: 416161 | G9: USD millions | H9: USD | I9: us-gaap:RevenueFromContractWithCustomerExcludingAssessedTax | J9: 2024-09-29 | K9: 2025-09-27 | L9: 2025/FY | M9: 10-K | N9: 2025-10-31 | O9: 0000320193-25-000079 | P9: https://www.sec.gov/Archives/edgar/data/320193/000032019325000079/0000320193-25-000079-index.htm | Q9: 2026-07-16 | R9: Primary - SEC filing / Company Facts | S9: USD divided by 1,000,000; sign as presented | T9: Matched legal entity, period, form, filed date, accession and target | U9: None identified | V9: =IF(COUNTA(A9:U9)=21,"OK","MISSING") -> OK
A10: 6 | B10: Apple Inc. | C10: Historical!B6 | D10: Gross profit | E10: 2021A | F10: 152836 | G10: USD millions | H10: USD | I10: us-gaap:GrossProfit | J10: 2020-09-27 | K10: 2021-09-25 | L10: 2023/FY | M10: 10-K | N10: 2023-11-03 | O10: 0000320193-23-000106 | P10: https://www.sec.gov/Archives/edgar/data/320193/000032019323000106/0000320193-23-000106-index.htm | Q10: 2026-07-16 | R10: Primary - SEC filing / Company Facts | S10: USD divided by 1,000,000; sign as presented | T10: Matched legal entity, period, form, filed date, accession and target | U10: None identified | V10: =IF(COUNTA(A10:U10)=21,"OK","MISSING") -> OK
A11: 7 | B11: Apple Inc. | C11: Historical!C6 | D11: Gross profit | E11: 2022A | F11: 170782 | G11: USD millions | H11: USD | I11: us-gaap:GrossProfit | J11: 2021-09-26 | K11: 2022-09-24 | L11: 2024/FY | M11: 10-K | N11: 2024-11-01 | O11: 0000320193-24-000123 | P11: https://www.sec.gov/Archives/edgar/data/320193/000032019324000123/0000320193-24-000123-index.htm | Q11: 2026-07-16 | R11: Primary - SEC filing / Company Facts | S11: USD divided by 1,000,000; sign as presented | T11: Matched legal entity, period, form, filed date, accession and target | U11: None identified | V11: =IF(COUNTA(A11:U11)=21,"OK","MISSING") -> OK
A12: 8 | B12: Apple Inc. | C12: Historical!D6 | D12: Gross profit | E12: 2023A | F12: 169148 | G12: USD millions | H12: USD | I12: us-gaap:GrossProfit | J12: 2022-09-25 | K12: 2023-09-30 | L12: 2025/FY | M12: 10-K | N12: 2025-10-31 | O12: 0000320193-25-000079 | P12: https://www.sec.gov/Archives/edgar/data/320193/000032019325000079/0000320193-25-000079-index.htm | Q12: 2026-07-16 | R12: Primary - SEC filing / Company Facts | S12: USD divided by 1,000,000; sign as presented | T12: Matched legal entity, period, form, filed date, accession and target | U12: None identified | V12: =IF(COUNTA(A12:U12)=21,"OK","MISSING") -> OK
A13: 9 | B13: Apple Inc. | C13: Historical!E6 | D13: Gross profit | E13: 2024A | F13: 180683 | G13: USD millions | H13: USD | I13: us-gaap:GrossProfit | J13: 2023-10-01 | K13: 2024-09-28 | L13: 2025/FY | M13: 10-K | N13: 2025-10-31 | O13: 0000320193-25-000079 | P13: https://www.sec.gov/Archives/edgar/data/320193/000032019325000079/0000320193-25-000079-index.htm | Q13: 2026-07-16 | R13: Primary - SEC filing / Company Facts | S13: USD divided by 1,000,000; sign as presented | T13: Matched legal entity, period, form, filed date, accession and target | U13: None identified | V13: =IF(COUNTA(A13:U13)=21,"OK","MISSING") -> OK
A14: 10 | B14: Apple Inc. | C14: Historical!F6 | D14: Gross profit | E14: 2025A | F14: 195201 | G14: USD millions | H14: USD | I14: us-gaap:GrossProfit | J14: 2024-09-29 | K14: 2025-09-27 | L14: 2025/FY | M14: 10-K | N14: 2025-10-31 | O14: 0000320193-25-000079 | P14: https://www.sec.gov/Archives/edgar/data/320193/000032019325000079/0000320193-25-000079-index.htm | Q14: 2026-07-16 | R14: Primary - SEC filing / Company Facts | S14: USD divided by 1,000,000; sign as presented | T14: Matched legal entity, period, form, filed date, accession and target | U14: None identified | V14: =IF(COUNTA(A14:U14)=21,"OK","MISSING") -> OK
A15: 11 | B15: Apple Inc. | C15: Historical!B7 | D15: Operating income / EBIT | E15: 2021A | F15: 108949 | G15: USD millions | H15: USD | I15: us-gaap:OperatingIncomeLoss | J15: 2020-09-27 | K15: 2021-09-25 | L15: 2023/FY | M15: 10-K | N15: 2023-11-03 | O15: 0000320193-23-000106 | P15: https://www.sec.gov/Archives/edgar/data/320193/000032019323000106/0000320193-23-000106-index.htm | Q15: 2026-07-16 | R15: Primary - SEC filing / Company Facts | S15: USD divided by 1,000,000; sign as presented | T15: Matched legal entity, period, form, filed date, accession and target | U15: None identified | V15: =IF(COUNTA(A15:U15)=21,"OK","MISSING") -> OK
A16: 12 | B16: Apple Inc. | C16: Historical!C7 | D16: Operating income / EBIT | E16: 2022A | F16: 119437 | G16: USD millions | H16: USD | I16: us-gaap:OperatingIncomeLoss | J16: 2021-09-26 | K16: 2022-09-24 | L16: 2024/FY | M16: 10-K | N16: 2024-11-01 | O16: 0000320193-24-000123 | P16: https://www.sec.gov/Archives/edgar/data/320193/000032019324000123/0000320193-24-000123-index.htm | Q16: 2026-07-16 | R16: Primary - SEC filing / Company Facts | S16: USD divided by 1,000,000; sign as presented | T16: Matched legal entity, period, form, filed date, accession and target | U16: None identified | V16: =IF(COUNTA(A16:U16)=21,"OK","MISSING") -> OK
... A96: 92 | B96: Apple Inc. | C96: Valuation!G19 | D96: Market close | E96: 2026-07-15 | F96: 327.5 | G96: USD per share | H96: USD | I96: Issuer IR:Historical daily close | J96: N/A - instant | K96: 2026-07-15 | L96: N/A | M96: Market data | N96: 2026-07-15 | O96: N/A - market data | P96: https://investor.apple.com/investor-relations/stock-price/ | Q96: 2026-07-16 | R96: Primary - issuer investor-relations historical stock-price lookup | S96: Closing price as displayed; no FX | T96: Date and close matched on cited historical-price surface | U96: Issuer lookup is interactive; refresh the exact dated close before transaction use | V96: =IF(COUNTA(A96:U96)=21,"OK","MISSING") -> OK
A98: Ledger completeness | G98: =COUNTIF(V5:V96,"OK") -> 92 | H98: 92 | I98: =IF(G98=H98,"OK","REVIEW") -> OK

Sheet Historical
A1: Apple Inc. — Historical Financials
A2: SEC 10-K / Company Facts lineage; USD millions except per-share data and shares
A4: Metric | B4: 2021A | C4: 2022A | D4: 2023A | E4: 2024A | F4: 2025A
A5: Revenue | B5: 365817 | C5: 394328 | D5: 383285 | E5: 391035 | F5: 416161
A6: Gross profit | B6: 152836 | C6: 170782 | D6: 169148 | E6: 180683 | F6: 195201
A7: Operating income / EBIT | B7: 108949 | C7: 119437 | D7: 114301 | E7: 123216 | F7: 133050
A8: Net income | B8: 94680 | C8: 99803 | D8: 96995 | E8: 93736 | F8: 112010
A9: Cash from operations | B9: 104038 | C9: 122151 | D9: 110543 | E9: 118254 | F9: 111482
A10: Capital expenditures | B10: 11085 | C10: 10708 | D10: 10959 | E10: 9447 | F10: 12715
A11: Total assets | B11: 351002 | C11: 352755 | D11: 352583 | E11: 364980 | F11: 359241
A12: Shareholders' equity | B12: 63090 | C12: 50672 | D12: 62146 | E12: 56950 | F12: 73733
A13: Cash and equivalents | B13: 34940 | C13: 23646 | D13: 29965 | E13: 29943 | F13: 35934
A14: Total debt | C14: 110087 | D14: 105103 | E14: 96662 | F14: 90678
A15: Diluted weighted-average shares | B15: 16864.919 | C15: 16325.819 | D15: 15812.547 | E15: 15408.095 | F15: 15004.697
A17: Bridge policy | B17: Latest balance-sheet cash policy
A18: Liquid assets used in DCF | B18: =SUM(B23:B25) -> 132420 | F18: USD millions
A19: Debt used in DCF | B19: =F14 -> 90678 | F19: USD millions
A20: Share count used in DCF | B20: 14776.353 | F20: million shares
A22: Apple liquid-asset bridge | B22: 2025A | C22: Policy | D22: USD m | E22: Source | F22: Status
A23: Cash and equivalents | B23: =F13 -> 35934 | C23: Included | D23: USD m | E23: Historical latest balance | F23: Formula link
A24: Current marketable securities | B24: 18763 | C24: Included | D24: USD m | E24: us-gaap:MarketableSecuritiesCurrent | F24: OK
A25: Non-current marketable securities | B25: 77723 | C25: Included | D25: USD m | E25: us-gaap:MarketableSecuritiesNoncurrent | F25: OK

Sheet Assumptions
A1: Apple Inc. — Scenario Assumptions
A2: Selector drives operating revenues/margins and the DCF; blue/amber cells are editable inputs
A3: Scenario selector (1 Base / 2 Bull / 3 Bear) | B3: 1 | G3: Input
A4: Active scenario | B4: =CHOOSE(B3,"Base","Bull","Bear") -> Base | G4: Formula
A6: Assumption | B6: Units | C6: Base | D6: Bull | E6: Bear | F6: Active | G6: Rationale / evidence
A7: iPhone revenue growth | B7: % | C7: 0.03 | D7: 0.06 | E7: 0 | F7: =CHOOSE($B$3,C7,D7,E7) -> 0.03 | G7: 2025 iPhone revenue USD 209,586m; scenario growth driver
A8: Mac revenue growth | B8: % | C8: 0.04 | D8: 0.08 | E8: 0 | F8: =CHOOSE($B$3,C8,D8,E8) -> 0.04 | G8: 2025 Mac revenue USD 33,708m; scenario growth driver
A9: iPad revenue growth | B9: % | C9: 0.02 | D9: 0.06 | E9: -0.02 | F9: =CHOOSE($B$3,C9,D9,E9) -> 0.02 | G9: 2025 iPad revenue USD 28,023m; scenario growth driver
A10: Wearables revenue growth | B10: % | C10: 0.01 | D10: 0.05 | E10: -0.04 | F10: =CHOOSE($B$3,C10,D10,E10) -> 0.01 | G10: 2025 Wearables revenue USD 35,686m; scenario growth driver
A11: Services revenue growth | B11: % | C11: 0.11 | D11: 0.14 | E11: 0.07 | F11: =CHOOSE($B$3,C11,D11,E11) -> 0.11 | G11: 2025 Services revenue USD 109,158m; scenario growth driver
A12: Products gross margin | B12: % | C12: 0.368 | D12: 0.38 | E12: 0.355 | F12: =CHOOSE($B$3,C12,D12,E12) -> 0.368 | G12: 2025 reported products gross margin 36.8%
A13: Services gross margin | B13: % | C13: 0.754 | D13: 0.77 | E13: 0.72 | F13: =CHOOSE($B$3,C13,D13,E13) -> 0.754 | G13: 2025 reported services gross margin 75.4%
A14: R&D as % revenue | B14: % | C14: 0.083 | D14: 0.078 | E14: 0.09 | F14: =CHOOSE($B$3,C14,D14,E14) -> 0.083 | G14: 2025 R&D USD 34,550m / revenue
A15: SG&A as % revenue | B15: % | C15: 0.066 | D15: 0.062 | E15: 0.07 | F15: =CHOOSE($B$3,C15,D15,E15) -> 0.066 | G15: 2025 SG&A USD 27,601m / revenue
A16: Cash tax rate | B16: % | C16: 0.165 | D16: 0.15 | E16: 0.185 | F16: =CHOOSE($B$3,C16,D16,E16) -> 0.165 | G16: Normalized cash tax rate
A17: D&A as % revenue | B17: % | C17: 0.03 | D17: 0.032 | E17: 0.028 | F17: =CHOOSE($B$3,C17,D17,E17) -> 0.03 | G17: Normalized D&A intensity
A18: Capex as % revenue | B18: % | C18: 0.031 | D18: 0.028 | E18: 0.035 | F18: =CHOOSE($B$3,C18,D18,E18) -> 0.031 | G18: Normalized capex intensity
... A21: Terminal growth | B21: % | C21: 0.025 | D21: 0.03 | E21: 0.02 | F21: =CHOOSE($B$3,C21,D21,E21) -> 0.025 | G21: DCF perpetual-growth scenario

Sheet Forecast
A1: Apple Inc. — Operating Forecast
A2: Scenario-linked driver build; expense and capex anchors are negative model outflows; USD millions
A4: Metric | B4: 2025A | C4: 2026E | D4: 2027E | E4: 2028E | F4: 2029E | G4: 2030E
A5: iPhone revenue | B5: =Sector_KPIs!D5 -> 209586 | C5: =B5*(1+Assumptions!F7) -> 215873.58 | D5: =C5*(1+Assumptions!F7) -> 222349.79 | E5: =D5*(1+Assumptions!F7) -> 229020.28 | F5: =E5*(1+Assumptions!F7) -> 235890.89 | G5: =F5*(1+Assumptions!F7) -> 242967.62
A6: Mac revenue | B6: =Sector_KPIs!D6 -> 33708 | C6: =B6*(1+Assumptions!F8) -> 35056.32 | D6: =C6*(1+Assumptions!F8) -> 36458.573 | E6: =D6*(1+Assumptions!F8) -> 37916.916 | F6: =E6*(1+Assumptions!F8) -> 39433.592 | G6: =F6*(1+Assumptions!F8) -> 41010.936
A7: iPad revenue | B7: =Sector_KPIs!D7 -> 28023 | C7: =B7*(1+Assumptions!F9) -> 28583.46 | D7: =C7*(1+Assumptions!F9) -> 29155.129 | E7: =D7*(1+Assumptions!F9) -> 29738.232 | F7: =E7*(1+Assumptions!F9) -> 30332.996 | G7: =F7*(1+Assumptions!F9) -> 30939.656
A8: Wearables revenue | B8: =Sector_KPIs!D8 -> 35686 | C8: =B8*(1+Assumptions!F10) -> 36042.86 | D8: =C8*(1+Assumptions!F10) -> 36403.289 | E8: =D8*(1+Assumptions!F10) -> 36767.321 | F8: =E8*(1+Assumptions!F10) -> 37134.995 | G8: =F8*(1+Assumptions!F10) -> 37506.345
A9: Services revenue | B9: =Sector_KPIs!D9 -> 109158 | C9: =B9*(1+Assumptions!F11) -> 121165.38 | D9: =C9*(1+Assumptions!F11) -> 134493.57 | E9: =D9*(1+Assumptions!F11) -> 149287.86 | F9: =E9*(1+Assumptions!F11) -> 165709.53 | G9: =F9*(1+Assumptions!F11) -> 183937.58
A10: Total revenue | B10: =SUM(B5:B9) -> 416161 | C10: =SUM(C5:C9) -> 436721.6 | D10: =SUM(D5:D9) -> 458860.35 | E10: =SUM(E5:E9) -> 482730.61 | F10: =SUM(F5:F9) -> 508502 | G10: =SUM(G5:G9) -> 536362.13
A11: Products gross profit | B11: =Sector_KPIs!D11 -> 112887 | C11: =SUM(C5:C8)*Assumptions!F12 -> 116124.69 | D11: =SUM(D5:D8)*Assumptions!F12 -> 119366.97 | E11: =SUM(E5:E8)*Assumptions!F12 -> 122706.93 | F11: =SUM(F5:F8)*Assumptions!F12 -> 126147.63 | G11: =SUM(G5:G8)*Assumptions!F12 -> 129692.24
A12: Services gross profit | B12: =Sector_KPIs!D12 -> 82314 | C12: =C9*Assumptions!F13 -> 91358.697 | D12: =D9*Assumptions!F13 -> 101408.15 | E12: =E9*Assumptions!F13 -> 112563.05 | F12: =F9*Assumptions!F13 -> 124944.99 | G12: =G9*Assumptions!F13 -> 138688.93
A13: Total gross profit | B13: =SUM(B11:B12) -> 195201 | C13: =SUM(C11:C12) -> 207483.39 | D13: =SUM(D11:D12) -> 220775.13 | E13: =SUM(E11:E12) -> 235269.98 | F13: =SUM(F11:F12) -> 251092.62 | G13: =SUM(G11:G12) -> 268381.17
A14: R&D | B14: =-Sector_KPIs!D15 -> -34550 | C14: =-C10*Assumptions!F14 -> -36247.893 | D14: =-D10*Assumptions!F14 -> -38085.409 | E14: =-E10*Assumptions!F14 -> -40066.641 | F14: =-F10*Assumptions!F14 -> -42205.666 | G14: =-G10*Assumptions!F14 -> -44518.057
A15: SG&A | B15: =-Sector_KPIs!D16 -> -27601 | C15: =-C10*Assumptions!F15 -> -28823.626 | D15: =-D10*Assumptions!F15 -> -30284.783 | E15: =-E10*Assumptions!F15 -> -31860.221 | F15: =-F10*Assumptions!F15 -> -33561.132 | G15: =-G10*Assumptions!F15 -> -35399.901
A16: EBIT | B16: =SUM(B13:B15) -> 133050 | C16: =SUM(C13:C15) -> 142411.87 | D16: =SUM(D13:D15) -> 152404.94 | E16: =SUM(E13:E15) -> 163343.12 | F16: =SUM(F13:F15) -> 175325.82 | G16: =SUM(G13:G15) -> 188463.21
A17: Cash taxes | B17: =-B16*Assumptions!C16 -> -21953.25 | C17: =-C16*Assumptions!F16 -> -23497.958 | D17: =-D16*Assumptions!F16 -> -25146.814 | E17: =-E16*Assumptions!F16 -> -26951.615 | F17: =-F16*Assumptions!F16 -> -28928.76 | G17: =-G16*Assumptions!F16 -> -31096.43
A18: NOPAT | B18: =B16+B17 -> 111096.75 | C18: =SUM(C16:C17) -> 118913.91 | D18: =SUM(D16:D17) -> 127258.12 | E18: =SUM(E16:E17) -> 136391.51 | F18: =SUM(F16:F17) -> 146397.06 | G18: =SUM(G16:G17) -> 157366.78
A19: D&A | B19: =Sector_KPIs!D17 -> 11698 | C19: =C10*Assumptions!F17 -> 13101.648 | D19: =D10*Assumptions!F17 -> 13765.81 | E19: =E10*Assumptions!F17 -> 14481.918 | F19: =F10*Assumptions!F17 -> 15255.06 | G19: =G10*Assumptions!F17 -> 16090.864
A20: Capital expenditures | B20: =-Historical!F10 -> -12715 | C20: =-C10*Assumptions!F18 -> -13538.37 | D20: =-D10*Assumptions!F18 -> -14224.671 | E20: =-E10*Assumptions!F18 -> -14964.649 | F20: =-F10*Assumptions!F18 -> -15763.562 | G20: =-G10*Assumptions!F18 -> -16627.226
A21: Change in NWC | B21: =0 -> 0 | C21: =-(C10-B10)*Assumptions!F19 -> -205.606 | D21: =-(D10-C10)*Assumptions!F19 -> -221.3875 | E21: =-(E10-D10)*Assumptions!F19 -> -238.70265 | F21: =-(F10-E10)*Assumptions!F19 -> -257.71388 | G21: =-(G10-F10)*Assumptions!F19 -> -278.60129
A22: FCFF | B22: =SUM(B18:B21) -> 110079.75 | C22: =SUM(C18:C21) -> 118271.58 | D22: =SUM(D18:D21) -> 126577.87 | E22: =SUM(E18:E21) -> 135670.07 | F22: =SUM(F18:F21) -> 145630.84 | G22: =SUM(G18:G21) -> 156551.82

Sheet Valuation
A1: Apple Inc. — DCF Valuation
A2: Unlevered FCFF; liquid-asset and debt bridge policies are explicit
A4: DCF item | B4: Year 1 | C4: Year 2 | D4: Year 3 | E4: Year 4 | F4: Year 5 | G4: Bridge / output
A5: FCFF | B5: =Forecast!C22 -> 118271.58 | C5: =Forecast!D22 -> 126577.87 | D5: =Forecast!E22 -> 135670.07 | E5: =Forecast!F22 -> 145630.84 | F5: =Forecast!G22 -> 156551.82
A6: Discount period | B6: 1 | C6: 2 | D6: 3 | E6: 4 | F6: 5
A7: Discount factor | B7: =1/(1+Assumptions!F20)^B6 -> 0.91324201 | C7: =1/(1+Assumptions!F20)^C6 -> 0.83401097 | D7: =1/(1+Assumptions!F20)^D6 -> 0.76165385 | E7: =1/(1+Assumptions!F20)^E6 -> 0.69557429 | F7: =1/(1+Assumptions!F20)^F6 -> 0.63522767
A8: Present value of FCFF | B8: =B5*B7 -> 108010.58 | C8: =C5*C7 -> 105567.33 | D8: =D5*D7 -> 103333.63 | E8: =E5*E7 -> 101297.07 | F8: =F5*F7 -> 99446.046
A9: Terminal value | F9: =F5*(1+Assumptions!F21)/(Assumptions!F20-Assumptions!F21) -> 2292365.9
A10: PV of terminal value | F10: =F9*F7 -> 1456174.2
A11: Enterprise value | G11: =SUM(B8:F8)+F10 -> 1973828.9
A12: Liquid assets | G12: =Historical!B18 -> 132420
A13: Debt | G13: =Historical!B19 -> 90678
A14: Equity value | G14: =G11+G12-G13 -> 2015570.9
A15: Shares outstanding / diluted policy | G15: =Historical!B20 -> 14776.353
A17: Per-share outputs
A18: DCF value / share | G18: =G14/G15 -> 136.40517
A19: Market price | G19: 327.5
A20: Upside / (downside) | G20: =G18/G19-1 -> -0.58349567
A21: Market as-of | G21: 2026-07-15

Sheet Sensitivity
A1: Apple Inc. — DCF Sensitivity
A2: Implied value per share across WACC and terminal-growth assumptions
A4: WACC / TGR | B4: 0.015 | C4: 0.02 | D4: 0.025 | E4: 0.03 | F4: 0.035
A5: 0.08 | B5: =(SUM(Valuation!B8:F8)+Forecast!G22*(1+B$4)/($A5-B$4)*Valuation!F7+Valuation!G12-Valuation!G13)/Valuation!G15 -> 142.95036 | C5: =(SUM(Valuation!B8:F8)+Forecast!G22*(1+C$4)/($A5-C$4)*Valuation!F7+Valuation!G12-Valuation!G13)/Valuation!G15 -> 152.26893 | D5: =(SUM(Valuation!B8:F8)+Forecast!G22*(1+D$4)/($A5-D$4)*Valuation!F7+Valuation!G12-Valuation!G13)/Valuation!G15 -> 163.28179 | E5: =(SUM(Valuation!B8:F8)+Forecast!G22*(1+E$4)/($A5-E$4)*Valuation!F7+Valuation!G12-Valuation!G13)/Valuation!G15 -> 176.49722 | F5: =(SUM(Valuation!B8:F8)+Forecast!G22*(1+F$4)/($A5-F$4)*Valuation!F7+Valuation!G12-Valuation!G13)/Valuation!G15 -> 192.64941
A6: 0.0875 | B6: =(SUM(Valuation!B8:F8)+Forecast!G22*(1+B$4)/($A6-B$4)*Valuation!F7+Valuation!G12-Valuation!G13)/Valuation!G15 -> 132.07869 | C6: =(SUM(Valuation!B8:F8)+Forecast!G22*(1+C$4)/($A6-C$4)*Valuation!F7+Valuation!G12-Valuation!G13)/Valuation!G15 -> 139.55655 | D6: =(SUM(Valuation!B8:F8)+Forecast!G22*(1+D$4)/($A6-D$4)*Valuation!F7+Valuation!G12-Valuation!G13)/Valuation!G15 -> 148.23088 | E6: =(SUM(Valuation!B8:F8)+Forecast!G22*(1+E$4)/($A6-E$4)*Valuation!F7+Valuation!G12-Valuation!G13)/Valuation!G15 -> 158.41379 | F6: =(SUM(Valuation!B8:F8)+Forecast!G22*(1+F$4)/($A6-F$4)*Valuation!F7+Valuation!G12-Valuation!G13)/Valuation!G15 -> 170.53629
A7: 0.095 | B7: =(SUM(Valuation!B8:F8)+Forecast!G22*(1+B$4)/($A7-B$4)*Valuation!F7+Valuation!G12-Valuation!G13)/Valuation!G15 -> 123.24546 | C7: =(SUM(Valuation!B8:F8)+Forecast!G22*(1+C$4)/($A7-C$4)*Valuation!F7+Valuation!G12-Valuation!G13)/Valuation!G15 -> 129.38666 | D7: =(SUM(Valuation!B8:F8)+Forecast!G22*(1+D$4)/($A7-D$4)*Valuation!F7+Valuation!G12-Valuation!G13)/Valuation!G15 -> 136.40517 | E7: =(SUM(Valuation!B8:F8)+Forecast!G22*(1+E$4)/($A7-E$4)*Valuation!F7+Valuation!G12-Valuation!G13)/Valuation!G15 -> 144.50345 | F7: =(SUM(Valuation!B8:F8)+Forecast!G22*(1+F$4)/($A7-F$4)*Valuation!F7+Valuation!G12-Valuation!G13)/Valuation!G15 -> 153.95145
A8: 0.1025 | B8: =(SUM(Valuation!B8:F8)+Forecast!G22*(1+B$4)/($A8-B$4)*Valuation!F7+Valuation!G12-Valuation!G13)/Valuation!G15 -> 115.92649 | C8: =(SUM(Valuation!B8:F8)+Forecast!G22*(1+C$4)/($A8-C$4)*Valuation!F7+Valuation!G12-Valuation!G13)/Valuation!G15 -> 121.06583 | D8: =(SUM(Valuation!B8:F8)+Forecast!G22*(1+D$4)/($A8-D$4)*Valuation!F7+Valuation!G12-Valuation!G13)/Valuation!G15 -> 126.8683 | E8: =(SUM(Valuation!B8:F8)+Forecast!G22*(1+E$4)/($A8-E$4)*Valuation!F7+Valuation!G12-Valuation!G13)/Valuation!G15 -> 133.47112 | F8: =(SUM(Valuation!B8:F8)+Forecast!G22*(1+F$4)/($A8-F$4)*Valuation!F7+Valuation!G12-Valuation!G13)/Valuation!G15 -> 141.05213
A9: 0.11 | B9: =(SUM(Valuation!B8:F8)+Forecast!G22*(1+B$4)/($A9-B$4)*Valuation!F7+Valuation!G12-Valuation!G13)/Valuation!G15 -> 109.76316 | C9: =(SUM(Valuation!B8:F8)+Forecast!G22*(1+C$4)/($A9-C$4)*Valuation!F7+Valuation!G12-Valuation!G13)/Valuation!G15 -> 114.13181 | D9: =(SUM(Valuation!B8:F8)+Forecast!G22*(1+D$4)/($A9-D$4)*Valuation!F7+Valuation!G12-Valuation!G13)/Valuation!G15 -> 119.01441 | E9: =(SUM(Valuation!B8:F8)+Forecast!G22*(1+E$4)/($A9-E$4)*Valuation!F7+Valuation!G12-Valuation!G13)/Valuation!G15 -> 124.50735 | F9: =(SUM(Valuation!B8:F8)+Forecast!G22*(1+F$4)/($A9-F$4)*Valuation!F7+Valuation!G12-Valuation!G13)/Valuation!G15 -> 130.73267
B11: Central cross-check
B12: Active WACC | C12: =Assumptions!F20 -> 0.095
B13: Active TGR | C13: =Assumptions!F21 -> 0.025
B14: Active DCF value/share | C14: =Valuation!G18 -> 136.40517

Sheet Checks
A1: Apple Inc. — Model Checks
A2: Overall status is formula-driven from assertions; source completeness is linked to the provenance ledger
A4: Assertion | B4: Actual | C4: Expected | D4: Difference | E4: Tolerance | F4: Status | G4: Fix hint
A5: Source ledger complete | B5: =Sources!I98 -> OK | C5: OK | F5: =IF(B5=C5,"OK","REVIEW") -> OK | G5: Complete every mandatory provenance field
A6: Scenario selector valid | B6: =Assumptions!B3 -> 1 | C6: 1 | D6: =IF(AND(B6>=1,B6<=3),0,1) -> 0 | E6: 0 | F6: =IF(D6=E6,"OK","REVIEW") -> OK | G6: Set Assumptions!B3 to 1, 2 or 3
A7: Forecast revenue positive | B7: =Forecast!C10 -> 436721.6 | C7: 0 | D7: =IF(B7>0,0,1) -> 0 | E7: 0 | F7: =IF(D7=E7,"OK","REVIEW") -> OK | G7: Inspect revenue-driver formulas
A8: Five EBIT periods populated | B8: =COUNT(Forecast!C16:G16) -> 5 | C8: 5 | D8: =ABS(B8-C8) -> 0 | E8: 0 | F8: =IF(D8=E8,"OK","REVIEW") -> OK | G8: Inspect margin and opex build
A9: Five FCFF periods populated | B9: =COUNT(Forecast!C22:G22) -> 5 | C9: 5 | D9: =ABS(B9-C9) -> 0 | E9: 0 | F9: =IF(D9=E9,"OK","REVIEW") -> OK | G9: Inspect NOPAT, D&A, capex and NWC
A10: 2025A material forecast-anchor tie | B10: =SUM(ABS(Forecast!B5-Sector_KPIs!D5),ABS(Forecast!B6-Sector_KPIs!D6),ABS(Forecast!B7-Sector_KPIs!D7),ABS(Forecast!B8-Sector_KPIs!D8),ABS(Forecast!B9-Sector_KPIs!D9),ABS(Forecast!B11-Sector_KPIs!D11),ABS(Forecast!B12-Sector_KPIs!D12),ABS(ABS(Forecast!B14)-Sector_KPIs!D15),ABS(ABS(Forecast!B15)-Sector_KPIs!D16),ABS(Forecast!B19-Sector_KPIs!D17),ABS(ABS(Forecast!B20)-Historical!F10)) -> 0 | C10: 0 | D10: =ABS(B10-C10) -> 0 | E10: 0.1 | F10: =IF(D10<=E10,"OK","REVIEW") -> OK | G10: Historical inputs are positive as reported; forecast expense/capex anchors are negative model outflows
A11: DCF equity bridge | B11: =Valuation!G14 -> 2015570.9 | C11: =Valuation!G11+Valuation!G12-Valuation!G13 -> 2015570.9 | D11: =ABS(B11-C11) -> 0 | E11: 0.1 | F11: =IF(D11<=E11,"OK","REVIEW") -> OK | G11: Inspect EV, liquid assets and total debt
A12: DCF per-share identity | B12: =Valuation!G18 -> 136.40517 | C12: =Valuation!G14/Valuation!G15 -> 136.40517 | D12: =ABS(B12-C12) -> 0 | E12: 0.001 | F12: =IF(D12<=E12,"OK","REVIEW") -> OK | G12: Inspect shares bridge
A13: Market price positive and sourced | B13: =Valuation!G19 -> 327.5 | C13: 0 | D13: =IF(B13>0,0,1) -> 0 | E13: 0 | F13: =IF(D13=E13,"OK","REVIEW") -> OK | G13: Update the dated market source row in Sources
A14: Tie-outs históricos y de cobertura (Checks_TieOut) | B14: =COUNTIF(Checks_TieOut!H5:H61,"FAIL") -> 1 | C14: 0 | D14: =ABS(B14-C14) -> 1 | E14: 0 | F14: =IF(D14=E14,"OK","REVIEW") -> REVIEW | G14: Abrir Checks_TieOut y resolver toda fila en FAIL antes de volver a certificar el gate
A15: Overall status | F15: =IF(COUNTIF(F5:F14,"OK")=10,"OK","REVIEW") -> REVIEW

Sheet Sector_KPIs
A1: Apple Inc. — Company Operating Drivers
A2: Company-specific reported driver history; formulas reconcile the model totals to historical revenue where applicable
A4: Metric | B4: 2023A | C4: 2024A | D4: 2025A | E4: Units | F4: Source / locator | G4: Status
A5: iPhone revenue | B5: 200583 | C5: 201183 | D5: 209586 | E5: USD m | F5: 2025 Form 10-K, Net Sales by Reportable Segment and Product | G5: Reported
A6: Mac revenue | B6: 29357 | C6: 29984 | D6: 33708 | E6: USD m | F6: 2025 Form 10-K, product net sales | G6: Reported
A7: iPad revenue | B7: 28300 | C7: 26694 | D7: 28023 | E7: USD m | F7: 2025 Form 10-K, product net sales | G7: Reported
A8: Wearables, Home & Accessories revenue | B8: 39845 | C8: 37005 | D8: 35686 | E8: USD m | F8: 2025 Form 10-K, product net sales | G8: Reported
A9: Services revenue | B9: 85200 | C9: 96169 | D9: 109158 | E9: USD m | F9: 2025 Form 10-K, services net sales | G9: Reported
A10: Revenue total | B10: =SUM(B5:B9) -> 383285 | C10: =SUM(C5:C9) -> 391035 | D10: =SUM(D5:D9) -> 416161 | E10: USD m | F10: Sum of categories | G10: Formula
A11: Products gross profit | B11: 108803 | C11: 109633 | D11: 112887 | E11: USD m | F11: 2025 Form 10-K, products and services performance | G11: Reported
A12: Services gross profit | B12: 60345 | C12: 71050 | D12: 82314 | E12: USD m | F12: 2025 Form 10-K, products and services performance | G12: Reported
A13: Products gross margin | B13: 0.365 | C13: 0.372 | D13: 0.368 | E13: % | F13: 2025 Form 10-K, products and services performance | G13: Reported
A14: Services gross margin | B14: 0.708 | C14: 0.739 | D14: 0.754 | E14: % | F14: 2025 Form 10-K, products and services performance | G14: Reported
A15: R&D | B15: 29915 | C15: 31370 | D15: 34550 | E15: USD m | F15: 2025 Form 10-K, operating expenses | G15: Reported
A16: SG&A | B16: 24932 | C16: 26097 | D16: 27601 | E16: USD m | F16: 2025 Form 10-K, operating expenses | G16: Reported
A17: D&A | D17: 11698 | E17: USD m | F17: us-gaap:DepreciationDepletionAndAmortization | G17: Reported

Sheet Change_Log
A1: Apple Inc. — Change Log
A2: Re-gating work performed without overwriting the prior workbook
A4: Timestamp (UTC) | B4: Scope | C4: Change | D4: Evidence | E4: Prior hash | F4: Preparer | G4: Disposition
A5: Build 2026-07-17T02:33:12.208Z | B5: Source lineage | C5: Added line-item target-cell provenance ledger | D5: Sources + SEC Company Facts / 10-K | E5: 6560d19fbe4cd8919c00bc2f78dfe01eefa7ce0001ba10039ea4da797e7f837a | F5: Codex | G5: Ready for independent review
A6: Build 2026-07-17T02:33:12.208Z | B6: Operating model | C6: Added company-specific revenue and margin drivers | D6: Sector_KPIs, Assumptions, Forecast | E6: 6560d19fbe4cd8919c00bc2f78dfe01eefa7ce0001ba10039ea4da797e7f837a | F6: Codex | G6: Ready for independent review
A7: Build 2026-07-17T02:33:12.208Z | B7: Valuation | C7: Rebuilt FCFF DCF, bridge and sensitivity | D7: Valuation + Sensitivity | E7: 6560d19fbe4cd8919c00bc2f78dfe01eefa7ce0001ba10039ea4da797e7f837a | F7: Codex | G7: Ready for independent review
A8: Build 2026-07-17T02:33:12.208Z | B8: Governance | C8: Added formula-driven checks and Gate_9of10 | D8: Checks + Gate_9of10 | E8: 6560d19fbe4cd8919c00bc2f78dfe01eefa7ce0001ba10039ea4da797e7f837a | F8: Codex | G8: Owner submission only
A9: 46224 | B9: Ola 2 elevation to statement-grade IG: added audited FY2021A-FY2025A IS_Hist/CI_Hist/BS_Hist/CF_Hist/SCE_Hist, Segment_Products (Products/Services schedule), Checks_TieOut (33 tie-outs incl. cross-statement + cash/equity continuity), Sources_Audited, Source_Register. Native currency USD, no FX layer needed. FY2021 SCE roll-forward and FY2021 Products/Services split flagged as sourcing gaps (not in research package). Prior 9of10 sheets left unmodified; Gate_9of10 not re-certified. Root workbook untouched; built via Mog SDK only into the maintainer's archive. | C9: Claude (run 24e4a1f1)
A13: 46224 | B13: Added forecast layer: Fwd_Assumptions (Bear/Base/Bull driver switch, Fwd_Assumptions!B2), Fwd_IS (driver-built IS + simplified capex/D&A/SBC/WC/FCF/capital-return, FY2026E-FY2030E, anchored to FY2025A), Fwd_Summary. PARTIAL scope: no BS/CF forecast tabs, no debt-maturity schedule, no share-price-based buyback share-count solve — flagged in build report as an honest scope limitation, not fabricated detail. | C13: Claude (run 24e4a1f1)
A14: 46248 | B14: Capa de cobertura (2026-08-14): se agregaron Drivers_MDA (drivers de negocio del MD&A y los disclosures, FY2021A-FY2025A: ingresos por categoría de producto, por segmento geográfico, utilidad operativa por segmento con su reconciliación, economía Products vs Services, métricas operativas divulgadas, drivers FX, y declaración explícita de lo que Apple NO divulga) y Market_Package (precio, acciones, market cap, puente a EV, beta, Rf, ERP, costo de deuda, tasa de impuestos, WACC y múltiplos implícitos, cada input con fuente y FECHA). Se agregaron 18 tie-outs nuevos en Checks_TieOut (filas 40-57) y se amplió el rango del gate maestro de H5:H38 a H5:H57 (endurece, no debilita). Cerrada la brecha declarada en Sources_Audited!A11: el split Products/Services de FY2021 se obtuvo del 10-K FY2021. NINGUNA hoja histórica (IS/CI/BS/CF/SCE_Hist, Segment_Products) ni el DCF existente fueron modificados; los hallazgos sobre el puente de deuda y el precio en duro quedan declarados en Market_Package, no corregidos. | C14: Claude Opus 5 (capa de cobertura, piloto de flota)
A15: 46248 | B15: Checks_TieOut, Checks, Market_Package, Drivers_MDA y Change_Log | C15: Corrección de la revisión adversarial de la capa de cobertura. (1) Los checks 51 a 55 eran tautologías algebraicas —restaban cada celda contra su propia definición— y no podían ponerse rojos: se reconstruyeron contra fuente independiente, recomputando desde insumos primarios y desde los subtotales auditados de BS_Hist, más bandas de plausibilidad contra el precio fechado de Valuation!G19 y el conteo de acciones de BS_Hist!F40. (2) Checks_TieOut no gateaba nada: se agregó la fila Checks!A14:G14 (COUNTIF de FAIL sobre Checks_TieOut!H5:H61) y Checks!F15 pasa de 9 a 10 asserts, de modo que Gate_9of10!B18 cae en REVIEW si cae cualquier tie-out. (3) Kd refrescado de 5.27% fechado como texto a 5.20% con serial 2026-08-13, leído de la serie primaria de FRED BAMLC0A2CAAEY; el control de procedencia ahora exige fecha serial y castiga el desfase (Market_Package B90 reescrito y B92 nuevo). (4) Checks nuevos: 58 (Assumptions!C12 y C13 contra Drivers_MDA!F85 y F86), 59 (cruce geográfico por línea), 60 (márgenes brutos reportados contra calculados) y 61 (bandas de plausibilidad para las constantes sin tie). (5) Drivers_MDA!A145 corregido a "coincide en valor, no enlazado", A133 renombrada como ilustrativa de Americas, y bloque 9 nuevo (A150 a A155) declarando exactamente qué NO está mecanizado. (6) Change_Log: se vaciaron las filas 10 a 12 (duplicados idénticos de la 9); la corrección del conteo de tie-outs (34, no 33) vive hoy en la fila 16, en sus columnas correctas | D15: Informe de revisión adversarial 2026-08-14. Pruebas de instrumento con defectos plantados sobre copias en scratchpad: precio 1.00, Rf 99%, BS_Hist!F24 a 1000, BS_Hist!F7 corrupto, Drivers_MDA!F33 a 60000, F87 a 99%, F94 a 1, F96 a 999999, F119 a 999999, permutación de F31 con F32, y D34 devuelto a texto | E15: 11b1dbde2e38ed3654ee5ae5197b23d4c7269c59007f781943ecdc6d2d9ad75a | F15: Claude Opus 5 (corrección de auditoría) | G15: Instrumento probado: cada check tocado cae en FAIL ante su defecto y el gate se pone en REVIEW. El archivo activo queda sano
A16: 46248 | B16: Change_Log fila 9 | C16: CORRECCIÓN: la entrada de la fila 9 dice "33 tie-outs" y la cifra correcta es 34 — el rango original era H5:H38, 34 filas de status, las 34 en PASS. Las filas 10 a 12 eran duplicados idénticos de esa misma entrada y se vaciaron. Esta nota vivía en D9 (columna Evidence); se movió aquí, a la columna Change, según el encabezado A4:G4 | D16: Conteo de filas de status del rango original Checks_TieOut!H5:H38 | F16: Claude (ronda 3, segunda verificación) | G16: Nota de corrección; la fila 9 original se conserva intacta
A17: 46248 | B17: Checks_TieOut (51 a 56), Market_Package (bloque 8 de anclas, control de procedencia, notas), Drivers_MDA (A150:A155), Checks!A14, Gate_9of10!F17, Change_Log | C17: Ronda 3 — cierre de la segunda verificación. (1) Checks 51 a 53 re-anclados a un vintage DISTINTO: el 10-Q Q3 FY2026 (accn 0000320193-26-000020, radicado el 2026-07-31) trae el balance al 2026-06-27 y la columna comparativa al 2025-09-27; ambas vivas como constantes fechadas (B82/B83 y el bloque 8 nuevo, B104/B105). El 52 exige tie exacto de B17 contra B104 y banda de ±15% contra B82; el 53 conserva el puente del papel comercial (H1), exige tie exacto de B21 contra B105 y banda de ±25% contra B83 (la deriva real ya es +17.0%, una banda de ±10% caería en rojo con el libro sano); el 51 recomputa el EV con esas anclas. Se ELIMINARON los términos que la verificación probó redundantes (52 ≡ checks 14+15; 53 término 1 ≡ 17+18; 51 término 1 ≡ 0; 54 término 1 ≡ 0): lo que caza son las bandas y las anclas, no la "reconstrucción". (2) Bandas realistas: acciones de ±10% a ±3% (los buybacks retiran ~3%/año; 15,300 ahora cae en FAIL), precio de ±50% a ±25% (un error de precio dentro de banda es indetectable sin feed vivo — declarado). (3) Frescura ABSOLUTA: B92 suma un término contra HOY()−10; un paquete uniformemente obsoleto (las cuatro fechas en enero) ahora cae en FAIL. (4) El 54 conserva las bandas y gana la guardia del enlace vivo de la tasa efectiva (B37 tecleada en duro cae). (5) Notas de honestidad reescritas (Drivers_MDA A150:A155, checks 51 a 61): el mérito es de las bandas, las anclas de vintage distinto y los ties de suma; lo indetectable queda declarado, no tapado. (6) Tildes corregidas en las 26 celdas señaladas por la verificación. (7) Gate_9of10!F17: nota de que B16/B17 son decorativos (C5:C14 son constantes). Ninguna hoja histórica se tocó | D17: 10-Q Q3 FY2026, balance condensado R4 (EDGAR, accn 0000320193-26-000020); informe de la segunda verificación 2026-08-14; pruebas con defectos plantados sobre copia en scratchpad (tabla en el informe de la ronda 3) | E17: 6adb623eaa77a910e8ed018f057c338e01f2554721f777c5bc3fe3ce53763869 | F17: Claude (ronda 3, segunda verificación) | G17: Instrumento re-probado: los defectos originales siguen cayendo, acciones 15,300 y fechas de enero ahora caen, libro sano 100% PASS

Sheet Gate_9of10
A1: Apple Inc. — Gate 9/10 Owner Submission
A2: Independent review is a separate role; this sheet does not self-certify the workbook
A4: Gate | B4: Weight | C4: Owner status | D4: Blocker class | E4: Exact evidence range | F4: Native / visual evidence | G4: Independent action | H4: Notes
A5: H0 Controlled lineage / package | B5: 5 | C5: PASS | D5: None identified | E5: Change_Log!A4:G8; final .xlsx | F5: Prior hash preserved; OOXML integrity PASS 2026-07-17T02:36:50.230Z | G5: Reproduce lineage and package test | H5: Final JSON carries prior and final hashes
A6: H1 Source fidelity | B6: 20 | C6: PASS | D6: None identified | E6: Sources!A4:V500 | F6: SEC target-cell ledger + formula completeness | G6: Sample and reproduce ledger mappings | H6: Every populated hardcoded historical/driver cell mapped
A7: H2 Historical / formula / schedule mechanics | B7: 15 | C7: PASS | D7: None identified | E7: Historical!A4:F26; Forecast!A4:G30 | F7: Five-year historicals and formula-driven operating build | G7: Reperform historical and forecast ties | H7: Reported values preserved; forecast cells formula-driven
A8: H3 Scenario / sensitivity | B8: 10 | C8: PASS | D8: None identified | E8: Assumptions!A3:G30; Sensitivity!A4:G14 | F8: Base/Bull/Bear selector + dynamic DCF sensitivity | G8: Perturb selector 1/2/3 and reset to 1 | H8: Evidence JSON records exact outputs
A9: H4 Valuation fit / mechanics | B9: 15 | C9: PASS | D9: None identified | E9: Valuation!A4:G21; Historical!A17:F26 | F9: FCFF, bridge and per-share DCF | G9: Reperform DCF and balance-sheet bridge | H9: Debt/liquid asset/share policies explicit
A10: H5 Checks / error state | B10: 8 | C10: PASS | D10: None identified | E10: Checks!A4:G14 | F10: Formula-driven checks OK and zero formula-error matches 2026-07-17T02:33:53.917Z | G10: Reproduce checks and formula-error scan | H10: Final scan repeated after gate promotion
A11: H6 Native recalc / reproducibility | B11: 10 | C11: PASS | D11: None identified | E11: Checks!A4:G14 | F11: LibreOfficeDev 26.8.0.0.alpha0 2c87e51eeaa2b413ff4ae097b2705eea1995d8e5; save/reopen completed 2026-07-17T02:33:53.917Z | G11: Reopen and reproduce in native engine | H11: Final recalc repeated after gate promotion; evidence JSON carries hashes
A12: H7 Post-recalc all-sheet visual QA | B12: 7 | C12: PASS | D12: None identified | E12: internal QA evidence (not published) | F12: All 11 sheets rendered in preflight 2026-07-17T02:33:53.917Z; final render repeated after promotion | G12: Inspect preview manifest | H12: Final JSON carries per-sheet manifest
A13: H8 Material economic upgrade | B13: 5 | C13: PASS | D13: None identified | E13: Sector_KPIs!A4:G40; Assumptions!A6:G30; Forecast!A4:G30 | F13: Company-specific driver and margin build | G13: Challenge economic usefulness | H13: No relabel-only sector shell
A14: H9 Governance / limitations / handoff | B14: 5 | C14: PASS | D14: None identified | E14: Change_Log!A4:G8; Gate_9of10!A4:H26 | F14: Owner/reviewer separation and limitations explicit | G14: Assign independent reviewer | H14: No self-certification; evidence JSON is handoff surface
A16: Owner score | B16: =SUMIF(C5:C14,"PASS",B5:B14) -> 100
A17: Decision | B17: =IF(B16=100,"OWNER READY — INDEPENDENT REVIEW REQUIRED","PENDING OWNER QA") -> OWNER READY — INDEPENDENT REVIEW REQUIRED | F17: NOTA (2026-08-14, ronda 3): B16 y B17 son decorativos — C5:C14 son constantes "PASS" tecleadas, así que el puntaje del owner siempre da 100 y esta decisión nunca cambia sola; en 14 defectos plantados no se movió. La única señal viva de esta hoja es B18 (=Checks!F15). No citar B16/B17 como evidencia de salud. Preexistente: se declara y no se corrige para no tocar un output ya gateado
A18: Overall model status | B18: =Checks!F15 -> REVIEW
A20: Native recalculation / review metadata
A21: Build timestamp UTC | B21: Build 2026-07-17T02:33:12.208Z
A22: Required native engine | B22: LibreOfficeDev 26.8.0.0.alpha0 2c87e51eeaa2b413ff4ae097b2705eea1995d8e5
A23: Final native timestamp | B23: Native preflight 2026-07-17T02:33:53.917Z; final recalc after promotion 2026-07-17T02:36:51.597Z
A24: Visual manifest | B24: internal QA evidence (not published)
A25: Evidence manifest | B25: internal QA evidence (not published)
A26: Independent certification | B26: Not performed by owner-preparer

Sheet IS_Hist
A1: Apple Inc. — Consolidated Statements of Operations (audited, published constants)
A2: USD millions except per-share data and share counts (thousands). FY2021 per FY2021 10-K; FY2022-24 per FY2024 10-K; FY2025 per FY2025 10-K.
A4: Line item | B4: FY2021A | C4: FY2022A | D4: FY2023A | E4: FY2024A | F4: FY2025A | G4: Note ref
A5: Net sales — Products | C5: 316199 | D5: 298085 | E5: 294866 | F5: 307003 | G5: Segment; Rev
A6: Net sales — Services | C6: 78129 | D6: 85200 | E6: 96169 | F6: 109158 | G6: Segment; Rev
A7: Total net sales | B7: 365817 | C7: 394328 | D7: 383285 | E7: 391035 | F7: 416161 | G7: Rev
A8: Cost of sales — Products | C8: 201471 | D8: 189282 | E8: 185233 | F8: 194116 | G8: Segment; Rev
A9: Cost of sales — Services | C9: 22075 | D9: 24855 | E9: 25119 | F9: 26844 | G9: Segment; Rev
A10: Total cost of sales | B10: 212981 | C10: 223546 | D10: 214137 | E10: 210352 | F10: 220960 | G10: IS
A11: Gross margin | B11: 152836 | C11: 170782 | D11: 169148 | E11: 180683 | F11: 195201 | G11: IS
A12: Operating expenses
A13: Research and development | B13: 21914 | C13: 26251 | D13: 29915 | E13: 31370 | F13: 34550 | G13: IS
A14: Selling, general and administrative | B14: 21973 | C14: 25094 | D14: 24932 | E14: 26097 | F14: 27601 | G14: IS
A15: Total operating expenses | B15: 43887 | C15: 51345 | D15: 54847 | E15: 57467 | F15: 62151 | G15: IS
A16: Operating income | B16: 108949 | C16: 119437 | D16: 114301 | E16: 123216 | F16: 133050 | G16: IS
A17: Other income/(expense), net | B17: 258 | C17: -334 | D17: -565 | E17: 269 | F17: -321 | G17: IS
A18: Income before provision for income taxes | B18: 109207 | C18: 119103 | D18: 113736 | E18: 123485 | F18: 132729 | G18: IS
A19: Provision for income taxes | B19: 14527 | C19: 19300 | D19: 16741 | E19: 29749 | F19: 20719 | G19: IS
A20: Net income | B20: 94680 | C20: 99803 | D20: 96995 | E20: 93736 | F20: 112010 | G20: IS
A22: Basic EPS ($/sh) | B22: 5.67 | C22: 6.15 | D22: 6.16 | E22: 6.11 | F22: 7.49 | G22: IS
A23: Diluted EPS ($/sh) | B23: 5.61 | C23: 6.11 | D23: 6.13 | E23: 6.08 | F23: 7.46 | G23: IS
A24: Basic weighted-avg shares (000) | B24: 16701272 | C24: 16215963 | D24: 15744231 | E24: 15343783 | F24: 14948500 | G24: IS
A25: Diluted weighted-avg shares (000) | B25: 16864919 | C25: 16325819 | D25: 15812547 | E25: 15408095 | F25: 15004697 | G25: IS

Sheet CI_Hist
A1: Apple Inc. — Consolidated Statements of Comprehensive Income (audited)
A2: USD millions. FY2021 OCI detail not broken out in this source package (net income only); FY2022-25 per FY2024/FY2025 10-Ks.
A4: Line item | B4: FY2021A | C4: FY2022A | D4: FY2023A | E4: FY2024A | F4: FY2025A | G4: Note ref
A5: Net income | B5: 94680 | C5: 99803 | D5: 96995 | E5: 93736 | F5: 112010
A6: Change in foreign currency translation, net of tax | C6: -1511 | D6: -765 | E6: 395 | F6: -267
A7: Change in fair value of derivative instruments | C7: 3212 | D7: 323 | E7: -832 | F7: 849
A8: Adjustment for net (gains)/losses realized, derivatives | C8: -1074 | D8: -1717 | E8: -1337 | F8: 212
A9: Total unrealized gain/(loss) on derivatives | C9: 2138 | D9: -1394 | E9: -2169 | F9: 637
A10: Change in fair value of marketable debt securities | C10: -12104 | D10: 1563 | E10: 5850 | F10: 817
A11: Adjustment for net (gains)/losses realized, securities | C11: 205 | D11: 253 | E11: 204 | F11: 414
A12: Total unrealized gain/(loss) on marketable debt securities | C12: -11899 | D12: 1816 | E12: 6054 | F12: 1231
A13: Total other comprehensive income/(loss) | C13: -11272 | D13: -343 | E13: 4280 | F13: 1601
A14: Total comprehensive income | C14: 88531 | D14: 96652 | E14: 98016 | F14: 113611

Sheet BS_Hist
A1: Apple Inc. — Consolidated Balance Sheets (audited)
A2: USD millions, as of fiscal year-end (last Saturday of September). Same source basis as IS_Hist.
A4: Line item | B4: FY2021A | C4: FY2022A | D4: FY2023A | E4: FY2024A | F4: FY2025A | G4: Note ref
A5: Current assets
A6: Cash and cash equivalents | B6: 34940 | C6: 23646 | D6: 29965 | E6: 29943 | F6: 35934 | G6: BS
A7: Marketable securities (current) | B7: 27699 | C7: 24658 | D7: 31590 | E7: 35228 | F7: 18763 | G7: BS
A8: Accounts receivable, net | B8: 26278 | C8: 28184 | D8: 29508 | E8: 33410 | F8: 39777 | G8: BS
A9: Vendor non-trade receivables | B9: 25228 | C9: 32748 | D9: 31477 | E9: 32833 | F9: 33180 | G9: BS
A10: Inventories | B10: 6580 | C10: 4946 | D10: 6331 | E10: 7286 | F10: 5718 | G10: BS
A11: Other current assets | B11: 14111 | C11: 21223 | D11: 14695 | E11: 14287 | F11: 14585 | G11: BS
A12: Total current assets | B12: 134836 | C12: 135405 | D12: 143566 | E12: 152987 | F12: 147957 | G12: BS
A13: Non-current assets
A14: Marketable securities (non-current) | B14: 127877 | C14: 120805 | D14: 100544 | E14: 91479 | F14: 77723 | G14: BS
A15: Property, plant and equipment, net | B15: 39440 | C15: 42117 | D15: 43715 | E15: 45680 | F15: 49834 | G15: BS
A16: Other non-current assets | B16: 48849 | C16: 54428 | D16: 64758 | E16: 74834 | F16: 83727 | G16: BS
A17: Total non-current assets | B17: 216166 | C17: 217350 | D17: 209017 | E17: 211993 | F17: 211284 | G17: BS
A18: Total assets | B18: 351002 | C18: 352755 | D18: 352583 | E18: 364980 | F18: 359241 | G18: BS
A20: Current liabilities
A21: Accounts payable | B21: 54763 | C21: 64115 | D21: 62611 | E21: 68960 | F21: 69860 | G21: BS
A22: Other current liabilities | B22: 47493 | C22: 60845 | D22: 58829 | E22: 78304 | F22: 66387 | G22: BS
A23: Deferred revenue | B23: 7612 | C23: 7912 | D23: 8061 | E23: 8249 | F23: 9055 | G23: BS
A24: Commercial paper | B24: 6000 | C24: 9982 | D24: 5985 | E24: 9967 | F24: 7979 | G24: BS
A25: Term debt (current) | B25: 9613 | C25: 11128 | D25: 9822 | E25: 10912 | F25: 12350 | G25: BS
A26: Total current liabilities | B26: 125481 | C26: 153982 | D26: 145308 | E26: 176392 | F26: 165631 | G26: BS
A27: Non-current liabilities
A28: Term debt (non-current) | B28: 109106 | C28: 98959 | D28: 95281 | E28: 85750 | F28: 78328 | G28: BS
A29: Other non-current liabilities | B29: 53325 | C29: 49142 | D29: 49848 | E29: 45888 | F29: 41549 | G29: BS
A30: Total non-current liabilities | B30: 162431 | C30: 148101 | D30: 145129 | E30: 131638 | F30: 119877 | G30: BS
A31: Total liabilities | B31: 287912 | C31: 302083 | D31: 290437 | E31: 308030 | F31: 285508 | G31: BS
A33: Shareholders' equity
A34: Common stock and additional paid-in capital | B34: 57365 | C34: 64849 | D34: 73812 | E34: 83276 | F34: 93568 | G34: BS
A35: Retained earnings/(Accumulated deficit) | B35: 5562 | C35: -3068 | D35: -214 | E35: -19154 | F35: -14264 | G35: BS
A36: Accumulated other comprehensive income/(loss) | B36: 163 | C36: -11109 | D36: -11452 | E36: -7172 | F36: -5571 | G36: BS
A37: Total shareholders' equity | B37: 63090 | C37: 50672 | D37: 62146 | E37: 56950 | F37: 73733 | G37: BS
A38: Total liabilities and shareholders' equity | B38: 351002 | C38: 352755 | D38: 352583 | E38: 364980 | F38: 359241 | G38: BS
A40: Common shares outstanding, period-end (000) | B40: 16426786 | C40: 15943425 | D40: 15550061 | E40: 15116786 | F40: 14773260 | G40: BS

Sheet CF_Hist
A1: Apple Inc. — Consolidated Statements of Cash Flows (audited)
A2: USD millions. Same source basis as IS_Hist. Signs as published (outflows negative).
A4: Line item | B4: FY2021A | C4: FY2022A | D4: FY2023A | E4: FY2024A | F4: FY2025A | G4: Note ref
A5: Cash, cash equiv. and restricted cash, beginning balance | B5: 39789 | C5: 35929 | D5: 24977 | E5: 30737 | F5: 29943 | G5: CF
A6: Operating activities
A7: Net income | B7: 94680 | C7: 99803 | D7: 96995 | E7: 93736 | F7: 112010 | G7: CF
A8: Depreciation and amortization | B8: 11284 | C8: 11104 | D8: 11519 | E8: 11445 | F8: 11698 | G8: CF
A9: Share-based compensation expense | B9: 7906 | C9: 9038 | D9: 10833 | E9: 11688 | F9: 12863 | G9: CF
A10: Other (FY21: derived residual — see Sources_Audited) | B10: -3245 | C10: 1006 | D10: -2227 | E10: -2266 | F10: -89 | G10: CF*
A11: Changes in operating assets and liabilities
A12: Accounts receivable, net | B12: -10125 | C12: -1823 | D12: -1688 | E12: -3788 | F12: -6682 | G12: CF
A13: Vendor non-trade receivables | B13: -3903 | C13: -7520 | D13: 1271 | E13: -1356 | F13: -347 | G13: CF
A14: Inventories | B14: -2642 | C14: 1484 | D14: -1618 | E14: -1046 | F14: 1400 | G14: CF
A15: Other current and non-current assets | B15: -8042 | C15: -6499 | D15: -5684 | E15: -11731 | F15: -9197 | G15: CF
A16: Accounts payable | B16: 12326 | C16: 9448 | D16: -1889 | E16: 6020 | F16: 902 | G16: CF
A17: Other current and non-current liabilities | B17: 5799 | C17: 6110 | D17: 3031 | E17: 15552 | F17: -11076 | G17: CF
A18: Cash generated by operating activities | B18: 104038 | C18: 122151 | D18: 110543 | E18: 118254 | F18: 111482 | G18: CF
A19: Investing activities
A20: Purchases of marketable securities | B20: -109558 | C20: -76923 | D20: -29513 | E20: -48656 | F20: -24407 | G20: CF
A21: Proceeds from maturities of marketable securities | B21: 59023 | C21: 29917 | D21: 39686 | E21: 51211 | F21: 40907 | G21: CF
A22: Proceeds from sales of marketable securities | B22: 47460 | C22: 37446 | D22: 5828 | E22: 11135 | F22: 12890 | G22: CF
A23: Payments for acquisition of property, plant and equipment | B23: -11085 | C23: -10708 | D23: -10959 | E23: -9447 | F23: -12715 | G23: CF
A24: Other (investing) (FY21: derived residual — see Sources_Audited) | B24: -385 | C24: -2086 | D24: -1337 | E24: -1308 | F24: -1480 | G24: CF*
A25: Cash generated by/(used in) investing activities | B25: -14545 | C25: -22354 | D25: 3705 | E25: 2935 | F25: 15195 | G25: CF
A26: Financing activities
A27: Payments for taxes related to net share settlement of equity awards | B27: -6556 | C27: -6223 | D27: -5431 | E27: -5441 | F27: -5960 | G27: CF
A28: Payments for dividends and dividend equivalents | B28: -14467 | C28: -14841 | D28: -15025 | E28: -15234 | F28: -15421 | G28: CF
A29: Repurchases of common stock | B29: -85971 | C29: -89402 | D29: -77550 | E29: -94949 | F29: -90711 | G29: CF
A30: Proceeds from issuance of term debt, net | B30: 20393 | C30: 5465 | D30: 5228 | E30: 0 | F30: 4481 | G30: CF
A31: Repayments of term debt | B31: -8750 | C31: -9543 | D31: -11151 | E31: -9958 | F31: -10932 | G31: CF
A32: Proceeds from/(Repayments of) commercial paper, net | B32: 1022 | C32: 3955 | D32: -3978 | E32: 3960 | F32: -2032 | G32: CF
A33: Other (financing) (FY21: derived residual — see Sources_Audited) | B33: 976 | C33: -160 | D33: -581 | E33: -361 | F33: -111 | G33: CF*
A34: Cash used in financing activities | B34: -93353 | C34: -110749 | D34: -108488 | E34: -121983 | F34: -120686 | G34: CF
A35: Increase/(Decrease) in cash, cash equiv. and restricted cash | B35: -3860 | C35: -10952 | D35: 5760 | E35: -794 | F35: 5991 | G35: CF
A36: Cash, cash equiv. and restricted cash, ending balance | B36: 35929 | C36: 24977 | D36: 30737 | E36: 29943 | F36: 35934 | G36: CF
A38: Cash paid for income taxes, net (supplemental) | B38: 25385 | C38: 19573 | D38: 18679 | E38: 26102 | F38: 43369 | G38: CF

Sheet SCE_Hist
A1: Apple Inc. — Consolidated Statements of Shareholders' Equity (audited, roll-forward)
A2: USD millions. FY2021 roll-forward detail not in this source package (SCE statement for FY2021 not pulled); FY2021 shown as period-end snapshot only. FY2022-25 per FY2024/FY2025 10-Ks (SCE tab / R7).
A4: Line item | B4: FY2021A | C4: FY2022A | D4: FY2023A | E4: FY2024A | F4: FY2025A | G4: Note ref
A5: Beginning balance (start of FY) | C5: 63090 | D5: 50672 | E5: 62146 | F5: 56950
A6: Common stock issued | C6: 1175 | D6: 1346 | E6: 1423 | F6: 1498
A7: Common stock withheld, net share settlement — APIC | C7: -2971 | D7: -3521 | E7: -3993 | F7: -4452
A8: Common stock withheld, net share settlement — Retained earnings | C8: -3454 | D8: -2099 | E8: -1612 | F8: -1655
A9: Share-based compensation (APIC) | C9: 9280 | D9: 11138 | E9: 12034 | F9: 13246
A10: Net income | B10: 94680 | C10: 99803 | D10: 96995 | E10: 93736 | F10: 112010
A11: Dividends and dividend equivalents declared | C11: -14793 | D11: -14996 | E11: -15218 | F11: -15413
A12: Common stock repurchased (retained earnings) | C12: -90186 | D12: -77046 | E12: -95846 | F12: -90052
A13: Other comprehensive income/(loss) | C13: -11272 | D13: -343 | E13: 4280 | F13: 1601
A14: Ending balance (end of FY) | B14: 63090 | C14: 50672 | D14: 62146 | E14: 56950 | F14: 73733
A15: Ending balance (end of FY) | B15: 63090 | C15: 50672 | D15: 62146 | E15: 56950 | F15: 73733
A16: Dividend declared per share ($) | B16: 0.85 | C16: 0.9 | D16: 0.94 | E16: 0.98 | F16: 1.02
A17: Dividend declared per share ($) | B17: 0.85 | C17: 0.9 | D17: 0.94 | E17: 0.98 | F17: 1.02

Sheet Segment_Products
A1: Apple Inc. — Net sales and cost of sales by category (Products / Services)
A2: USD millions. Source: Revenue note, FY2024 10-K (FY22-24) and FY2025 10-K R3 (FY23-25). FY2021 category split not available in this source package.
A4: Metric | B4: FY2021A | C4: FY2022A | D4: FY2023A | E4: FY2024A | F4: FY2025A
A5: Products — Net sales | C5: 316199 | D5: 298085 | E5: 294866 | F5: 307003
A6: Products — Cost of sales | C6: 201471 | D6: 189282 | E6: 185233 | F6: 194116
A7: Products — Gross margin (calc) | B7: =IF(B5="","",B5-B6) | C7: =IF(C5="","",C5-C6) -> 114728 | D7: =IF(D5="","",D5-D6) -> 108803 | E7: =IF(E5="","",E5-E6) -> 109633 | F7: =IF(F5="","",F5-F6) -> 112887
A8: Services — Net sales | C8: 78129 | D8: 85200 | E8: 96169 | F8: 109158
A9: Services — Cost of sales | C9: 22075 | D9: 24855 | E9: 25119 | F9: 26844
A10: Services — Gross margin (calc) | B10: =IF(B8="","",B8-B9) | C10: =IF(C8="","",C8-C9) -> 56054 | D10: =IF(D8="","",D8-D9) -> 60345 | E10: =IF(E8="","",E8-E9) -> 71050 | F10: =IF(F8="","",F8-F9) -> 82314
A11: Products % of total net sales (calc) | B11: =IF(B5="","",B5/IS_Hist!B7) | C11: =IF(C5="","",C5/IS_Hist!C7) -> 0.80186799 | D11: =IF(D5="","",D5/IS_Hist!D7) -> 0.7777111 | E11: =IF(E5="","",E5/IS_Hist!E7) -> 0.75406549 | F11: =IF(F5="","",F5/IS_Hist!F7) -> 0.73770248
A12: Services % of total net sales (calc) | B12: =IF(B8="","",B8/IS_Hist!B7) | C12: =IF(C8="","",C8/IS_Hist!C7) -> 0.19813201 | D12: =IF(D8="","",D8/IS_Hist!D7) -> 0.2222889 | E12: =IF(E8="","",E8/IS_Hist!E7) -> 0.24593451 | F12: =IF(F8="","",F8/IS_Hist!F7) -> 0.26229752

Sheet Checks_TieOut
A1: Tie-out checks — Apple audited historical statements FY2021-FY2025 (USD millions; deltas must be 0, tol 0.5 abs except EPS tol 0.02)
A2: MASTER | B2: =IF(COUNTIF(H5:H61,"FAIL")=0,"OK — ALL TIE-OUTS PASS","FAIL") -> FAIL
A3: Conteo mecanizado | B3: =COUNTIF(H5:H61,"PASS")&" PASS / "&(COUNTIF(H5:H61,"PASS")+COUNTIF(H5:H61,"FAIL"))&" checks" -> 55 PASS / 56 checks
A4: Check | B4: FY2021A | C4: FY2022A | D4: FY2023A | E4: FY2024A | F4: FY2025A | H4: Status | I4: Applicable years
A5: IS: Total net sales = Products + Services | C5: =IS_Hist!C5+IS_Hist!C6-IS_Hist!C7 -> 0 | D5: =IS_Hist!D5+IS_Hist!D6-IS_Hist!D7 -> 0 | E5: =IS_Hist!E5+IS_Hist!E6-IS_Hist!E7 -> 0 | F5: =IS_Hist!F5+IS_Hist!F6-IS_Hist!F7 -> 0 | H5: =IF(AND(ABS(N(C5))<=0.5,ABS(N(D5))<=0.5,ABS(N(E5))<=0.5,ABS(N(F5))<=0.5),"PASS","FAIL") -> PASS | I5: C,D,E,F
A6: IS: Total COGS = Products + Services | C6: =IS_Hist!C8+IS_Hist!C9-IS_Hist!C10 -> 0 | D6: =IS_Hist!D8+IS_Hist!D9-IS_Hist!D10 -> 0 | E6: =IS_Hist!E8+IS_Hist!E9-IS_Hist!E10 -> 0 | F6: =IS_Hist!F8+IS_Hist!F9-IS_Hist!F10 -> 0 | H6: =IF(AND(ABS(N(C6))<=0.5,ABS(N(D6))<=0.5,ABS(N(E6))<=0.5,ABS(N(F6))<=0.5),"PASS","FAIL") -> PASS | I6: C,D,E,F
A7: IS: Gross margin = Sales − COGS | B7: =IS_Hist!B7-IS_Hist!B10-IS_Hist!B11 -> 0 | C7: =IS_Hist!C7-IS_Hist!C10-IS_Hist!C11 -> 0 | D7: =IS_Hist!D7-IS_Hist!D10-IS_Hist!D11 -> 0 | E7: =IS_Hist!E7-IS_Hist!E10-IS_Hist!E11 -> 0 | F7: =IS_Hist!F7-IS_Hist!F10-IS_Hist!F11 -> 0 | H7: =IF(AND(ABS(N(B7))<=0.5,ABS(N(C7))<=0.5,ABS(N(D7))<=0.5,ABS(N(E7))<=0.5,ABS(N(F7))<=0.5),"PASS","FAIL") -> PASS | I7: B,C,D,E,F
A8: IS: Total opex = R&D + SG&A | B8: =IS_Hist!B13+IS_Hist!B14-IS_Hist!B15 -> 0 | C8: =IS_Hist!C13+IS_Hist!C14-IS_Hist!C15 -> 0 | D8: =IS_Hist!D13+IS_Hist!D14-IS_Hist!D15 -> 0 | E8: =IS_Hist!E13+IS_Hist!E14-IS_Hist!E15 -> 0 | F8: =IS_Hist!F13+IS_Hist!F14-IS_Hist!F15 -> 0 | H8: =IF(AND(ABS(N(B8))<=0.5,ABS(N(C8))<=0.5,ABS(N(D8))<=0.5,ABS(N(E8))<=0.5,ABS(N(F8))<=0.5),"PASS","FAIL") -> PASS | I8: B,C,D,E,F
A9: IS: Operating income = Gross margin − Opex | B9: =IS_Hist!B11-IS_Hist!B15-IS_Hist!B16 -> 0 | C9: =IS_Hist!C11-IS_Hist!C15-IS_Hist!C16 -> 0 | D9: =IS_Hist!D11-IS_Hist!D15-IS_Hist!D16 -> 0 | E9: =IS_Hist!E11-IS_Hist!E15-IS_Hist!E16 -> 0 | F9: =IS_Hist!F11-IS_Hist!F15-IS_Hist!F16 -> 0 | H9: =IF(AND(ABS(N(B9))<=0.5,ABS(N(C9))<=0.5,ABS(N(D9))<=0.5,ABS(N(E9))<=0.5,ABS(N(F9))<=0.5),"PASS","FAIL") -> PASS | I9: B,C,D,E,F
A10: IS: PBT = Operating income + Other income/(expense) | B10: =IS_Hist!B16+IS_Hist!B17-IS_Hist!B18 -> 0 | C10: =IS_Hist!C16+IS_Hist!C17-IS_Hist!C18 -> 0 | D10: =IS_Hist!D16+IS_Hist!D17-IS_Hist!D18 -> 0 | E10: =IS_Hist!E16+IS_Hist!E17-IS_Hist!E18 -> 0 | F10: =IS_Hist!F16+IS_Hist!F17-IS_Hist!F18 -> 0 | H10: =IF(AND(ABS(N(B10))<=0.5,ABS(N(C10))<=0.5,ABS(N(D10))<=0.5,ABS(N(E10))<=0.5,ABS(N(F10))<=0.5),"PASS","FAIL") -> PASS | I10: B,C,D,E,F
A11: IS: NI = PBT − tax | B11: =IS_Hist!B18-IS_Hist!B19-IS_Hist!B20 -> 0 | C11: =IS_Hist!C18-IS_Hist!C19-IS_Hist!C20 -> 0 | D11: =IS_Hist!D18-IS_Hist!D19-IS_Hist!D20 -> 0 | E11: =IS_Hist!E18-IS_Hist!E19-IS_Hist!E20 -> 0 | F11: =IS_Hist!F18-IS_Hist!F19-IS_Hist!F20 -> 0 | H11: =IF(AND(ABS(N(B11))<=0.5,ABS(N(C11))<=0.5,ABS(N(D11))<=0.5,ABS(N(E11))<=0.5,ABS(N(F11))<=0.5),"PASS","FAIL") -> PASS | I11: B,C,D,E,F
