Workbook

Sheet EEFF
A1: Grupo ASSA, S. A.
A2: Estados Financieros Consolidados Auditados FY21-FY25
A3: en US$ sin escala
A5: Años | B5: FY21A | C5: FY22A | D5: FY23A | E5: FY24A | F5: FY25A | G5: FY26E | H5: FY27E | I5: FY28E | J5: FY29E | K5: FY30E
A6: Estado de Resultados
A7: — Base regulatoria SSRP / NIIF excepto NIIF 17 (FY2021A–FY2024A, filings propios de cada año)
A8: Primas suscritas, netas de cancelaciones | B8: 657884741 | C8: 698200257 | D8: 817173751 | E8: 841095242
A9: Primas suscritas cedidas a reaseguradores | B9: -356304040 | C9: -361584073 | D9: -435628239 | E9: -426032825
A10: Total de primas netas retenidas | B10: 301580701 | C10: 336616184 | D10: 381545512 | E10: 415062417
A11: Cambio en la provisión bruta para riesgo en curso | B11: -9152442 | C11: 3120015 | D11: -28420469 | E11: -475396
A12: Cambio en la provisión en los negocios de vida a largo plazo sobre pólizas de vida | B12: -10285045 | C12: -12525971 | D12: -12302706 | E12: -10311345
A13: Cambio en la participación de los reaseguradores en la provisión sobre contratos de seguros | B13: 9401319 | C13: -6820962 | D13: 16095063
A14: Total de cambios en las provisiones de los contratos de seguros | B14: -10036168 | C14: -16226918 | D14: -24628112 | E14: -19186523
A15: Primas netas ganadas | B15: 291544533 | C15: 320389266 | D15: 356917400 | E15: 395875894
A16: Reclamos y beneficios incurridos | B16: -238994085 | C16: -327863954 | D16: -238087045 | E16: -248414644
A17: Participación de los reaseguradores en los reclamos y beneficios incurridos | B17: 101363600 | C17: 176570373 | D17: 65656958 | E17: 62663262
A18: Beneficios por reembolsos y rescates | B18: -13646362 | C18: -14629260 | D18: -16826376 | E18: -19666415
A19: Reclamos y beneficios netos incurridos por los asegurados | B19: -151276847 | C19: -165922841 | D19: -189256463 | E19: -205417797
A20: Costo de suscripción y adquisición | B20: -89805859 | C20: -98549869 | D20: -115810518 | E20: -126570429
A21: Provisión para pérdidas crediticias esperadas en primas por cobrar | B21: -143340 | C21: -1327507 | D21: -1113601 | E21: -530722
A22: Primas netas ganadas, después de reclamos, costos de suscripción y provisión para pérdidas crediticias esperadas en primas por cobrar | B22: 50318487 | C22: 54589049 | D22: 50736818 | E22: 63356946
A23: Intereses sobre préstamos | B23: 90113580 | C23: 89349229 | D23: 99791323
A24: Intereses sobre depósitos en bancos | B24: 324360 | C24: 852370 | D24: 1871676
A25: Intereses sobre inversiones en valores | B25: 30270095 | C25: 33792124 | D25: 38203473
A26: Total de ingresos por intereses | B26: 120708035 | C26: 123993723 | D26: 139866472
A27: Gastos por intereses sobre depósitos | B27: -25360968 | C27: -25531810 | D27: -34235136
A28: Gastos por intereses sobre emisiones de deuda y obligaciones | B28: -30177384 | C28: -29003930 | D28: -34426805
A29: Total de gastos por intereses | B29: -55538352 | C29: -54535740 | D29: -68661941 | E29: -1028730
A30: Provisión para pérdidas crediticias esperadas en préstamos | B30: -4291456 | C30: -4626793 | D30: -7316131
A31: Ganancia neta por modificación de préstamos a CA | C31: 515213 | D31: 67054
A32: Resultado neto de intereses, comisiones y provisión para pérdidas crediticias esperadas en préstamos | B32: 60878227 | C32: 65346403 | D32: 63955454 | E32: 35051765
A33: Ingresos por comisiones y servicios financieros | B33: 53282269 | C33: 54586912 | D33: 68685561 | E33: 61243501
A34: Ganancia (Pérdida) en venta de bonos y acciones, neto | B34: 2013784 | C34: -240213 | D34: 63303
A35: Dividendos ganados | B35: 24063694 | C35: 30788100 | D35: 40145969 | E35: 51360184
A36: Ganancia (Pérdida) no realizada de inversiones a valor razonable con cambio en resultado | B36: 6681944 | C36: -14025402 | D36: 5542980
A37: Otros ingresos de operaciones, neto | B37: 9840321 | C37: 5497518 | D37: 3537146 | E37: 4229486
A38: Reversión de (provisión para) pérdidas crediticias esperadas en inversiones | B38: -125836 | C38: -582779 | D38: 1442923
A39: Resultados, neto | B39: 206952890 | C39: 195959588 | D39: 234110154 | E39: 219482630
A40: Gastos de personal | B40: -65378406 | C40: -68691932 | D40: -72370796 | E40: -55716075
A41: Gastos generales y administrativos | B41: -39466922 | C41: -41469305 | D41: -41793696 | E41: -24861432
...

Sheet Supuestos
A1: Grupo ASSA, S. A.
A3: COLOR KEY: Input (azul) · Fórmula (negro) · Link inter-hoja (verde)
A4: Escenario (1=Base, 2=Bull, 3=Bear)
A5: Selector escenario | C5: 1 | M5: caso | N5: NOT_DISCLOSED | Q5: Input de escenario desde fuente citada o NOT_DISCLOSED.
A6: Escenario activo | C6: =CHOOSE($C$5,"Base","Bull","Bear") -> Base | M6: moneda del modelo | N6: NOT_DISCLOSED | Q6: Selector de caso activo C5: Base/Bull/Bear.
A8: Años | B8: FY21A | C8: FY22A | D8: FY23A | E8: FY24A | F8: FY25A | G8: FY26E | H8: FY27E | I8: FY28E | J8: FY29E | K8: FY30E | M8: Unidad | N8: Fuente / nota | Q8: Rationale
A10: A. INGRESOS POR SERVICIOS DE SEGURO (NIIF 17) — CRECIMIENTO (% YoY)
A11: Ingresos por servicios de seguro — driver activo (base NIIF 17) | G11: =CHOOSE($C$5,G13,G14,G12) -> 0.0794 | H11: =CHOOSE($C$5,H13,H14,H12) -> 0.0794 | I11: =CHOOSE($C$5,I13,I14,I12) -> 0.0794 | J11: =CHOOSE($C$5,J13,J14,J12) -> 0.0794 | K11: =CHOOSE($C$5,K13,K14,K12) -> 0.0794 | M11: % | N11: EEFF:Ingresos por servicios de seguro | Q11: Selector de caso activo C5: Base/Bull/Bear.
A12: Bear | G12: 0.0594 | H12: 0.0594 | I12: 0.0594 | J12: 0.0594 | K12: 0.0594 | M12: % | N12: EEFF:Ingresos por servicios de seguro | Q12: Escenario driver citado; NOT_DISCLOSED si no hay fuente explícita.
A13: Base | G13: 0.0794 | H13: 0.0794 | I13: 0.0794 | J13: 0.0794 | K13: 0.0794 | M13: % | N13: EEFF:Ingresos por servicios de seguro | Q13: Escenario driver citado; NOT_DISCLOSED si no hay fuente explícita.
A14: Bull | G14: 0.0994 | H14: 0.0994 | I14: 0.0994 | J14: 0.0994 | K14: 0.0994 | M14: % | N14: EEFF:Ingresos por servicios de seguro | Q14: Escenario driver citado; NOT_DISCLOSED si no hay fuente explícita.
A15: Ingresos por servicios de seguro (hist, ref EEFF) | E15: =EEFF!E50 -> 820306455 | F15: =EEFF!F50 -> 885435473 | M15: moneda del modelo | N15: EEFF:Ingresos por servicios de seguro | Q15: Mirror histórico desde fuente citada.
A16: Ingresos por servicios de seguro YoY histórico (ref EEFF) | F16: =EEFF!F50/EEFF!E50-1 -> 0.079395959 | M16: % | N16: EEFF:Ingresos por servicios de seguro | Q16: Fórmula viva: año actual / año previo - 1.
A18: B. GASTOS POR SERVICIOS DE SEGURO (% de ingresos por servicios, NIIF 17)
A19: Gastos por servicios de seguro — driver activo (ratio negativo) | G19: =CHOOSE($C$5,G21,G22,G20) -> -0.4816 | H19: =CHOOSE($C$5,H21,H22,H20) -> -0.4816 | I19: =CHOOSE($C$5,I21,I22,I20) -> -0.4816 | J19: =CHOOSE($C$5,J21,J22,J20) -> -0.4816 | K19: =CHOOSE($C$5,K21,K22,K20) -> -0.4816 | M19: % | N19: EEFF:Gastos por servicios de seguro | Q19: Selector de caso activo C5: Base/Bull/Bear.
A20: Bear | G20: -0.5016 | H20: -0.5016 | I20: -0.5016 | J20: -0.5016 | K20: -0.5016 | M20: % | N20: EEFF:Gastos por servicios de seguro | Q20: Escenario driver citado; NOT_DISCLOSED si no hay fuente explícita.
A21: Base | G21: -0.4816 | H21: -0.4816 | I21: -0.4816 | J21: -0.4816 | K21: -0.4816 | M21: % | N21: EEFF:Gastos por servicios de seguro | Q21: Escenario driver citado; NOT_DISCLOSED si no hay fuente explícita.
A22: Bull | G22: -0.4616 | H22: -0.4616 | I22: -0.4616 | J22: -0.4616 | K22: -0.4616 | M22: % | N22: EEFF:Gastos por servicios de seguro | Q22: Escenario driver citado; NOT_DISCLOSED si no hay fuente explícita.
A23: Gasto ÷ ingreso (hist; B:D legacy reclamos s/primas, E:F NIIF17 gasto servicio s/ingreso servicio) | B23: =IF(EEFF!B10=0,"",EEFF!B16/EEFF!B10) -> -0.79247142 | C23: =IF(EEFF!C10=0,"",EEFF!C16/EEFF!C10) -> -0.97399938 | D23: =IF(EEFF!D10=0,"",EEFF!D16/EEFF!D10) -> -0.62400693 | E23: =EEFF!E51/EEFF!E50 -> -0.4484638 | F23: =EEFF!F51/EEFF!F50 -> -0.48164584 | M23: % | N23: EEFF:Gastos por servicios de seguro; EEFF:Ingresos por servicios de seguro | Q23: Derivación mecánica por fórmula viva.
A25: C. GASTOS GENERALES (% de ingresos por servicios de seguro, NIIF 17)
A26: Gastos generales y administrativos — driver activo | G26: =CHOOSE($C$5,G28,G29,G27) -> -0.1076 | H26: =CHOOSE($C$5,H28,H29,H27) -> -0.1076 | I26: =CHOOSE($C$5,I28,I29,I27) -> -0.1076 | J26: =CHOOSE($C$5,J28,J29,J27) -> -0.1076 | K26: =CHOOSE($C$5,K28,K29,K27) -> -0.1076 | M26: % | N26: EEFF:Gastos generales y administrativos | Q26: Selector de caso activo C5: Base/Bull/Bear.
A27: Bear | G27: -0.1276 | H27: -0.1276 | I27: -0.1276 | J27: -0.1276 | K27: -0.1276 | M27: % | N27: EEFF:Gastos generales y administrativos | Q27: Escenario driver citado; NOT_DISCLOSED si no hay fuente explícita.
A28: Base | G28: -0.1076 | H28: -0.1076 | I28: -0.1076 | J28: -0.1076 | K28: -0.1076 | M28: % | N28: EEFF:Gastos generales y administrativos | Q28: Escenario driver citado; NOT_DISCLOSED si no hay fuente explícita.
A29: Bull | G29: -0.0876 | H29: -0.0876 | I29: -0.0876 | J29: -0.0876 | K29: -0.0876 | M29: % | N29: EEFF:Gastos generales y administrativos | Q29: Escenario driver citado; NOT_DISCLOSED si no hay fuente explícita.
A30: G&A ÷ ingreso (hist; B:D legacy s/primas retenidas, E:F NIIF17 s/ingreso servicio) | B30: =IF(EEFF!B10=0,"",EEFF!B41/EEFF!B10) -> -0.13086687 | C30: =IF(EEFF!C10=0,"",EEFF!C41/EEFF!C10) -> -0.12319463 | D30: =IF(EEFF!D10=0,"",EEFF!D41/EEFF!D10) -> -0.1095379 | E30: =EEFF!E62/EEFF!E50 -> -0.10875473 | F30: =EEFF!F62/EEFF!F50 -> -0.10760001 | M30: % | N30: EEFF:Gastos generales y administrativos; EEFF:Ingresos por servicios de seguro | Q30: Derivación mecánica por fórmula viva.
A33: D. PRIMAS SUSCRITAS POR RAMO (NETAS DE REASEGURO) — CRECIMIENTO % YoY (NIIF 17; Nota 10.ii del filing 2025, tbl-35)
A34: Histórico 2025 = YoY por ramo con referencia al ledger Notas_EEFF (verde). Proyección = driver por escenario (azul, hardcoded) + selector $C$5. Base = YoY 2025; Bear/Bull = Base ∓ 2 puntos.
A35: Accidentes personales — driver activo (% YoY prima suscrita neta) | G35: =CHOOSE($C$5,G37,G38,G36) -> 0.0277 | H35: =CHOOSE($C$5,H37,H38,H36) -> 0.0277 | I35: =CHOOSE($C$5,I37,I38,I36) -> 0.0277 | J35: =CHOOSE($C$5,J37,J38,J36) -> 0.0277 | K35: =CHOOSE($C$5,K37,K38,K36) -> 0.0277 | M35: % | N35: NOT_DISCLOSED | Q35: Selector de caso activo C5: Base/Bull/Bear.
A36: Bear | G36: 0.0077 | H36: 0.0077 | I36: 0.0077 | J36: 0.0077 | K36: 0.0077 | M36: % | N36: NOT_DISCLOSED | Q36: Escenario driver citado; NOT_DISCLOSED si no hay fuente explícita.
A37: Base | G37: 0.0277 | H37: 0.0277 | I37: 0.0277 | J37: 0.0277 | K37: 0.0277 | M37: % | N37: NOT_DISCLOSED | Q37: Escenario driver citado; NOT_DISCLOSED si no hay fuente explícita.
A38: Bull | G38: 0.0477 | H38: 0.0477 | I38: 0.0477 | J38: 0.0477 | K38: 0.0477 | M38: % | N38: NOT_DISCLOSED | Q38: Escenario driver citado; NOT_DISCLOSED si no hay fuente explícita.
A39: YoY histórico 2025 (ref Notas_EEFF) | F39: =Notas_EEFF!K2716/Notas_EEFF!K2717-1 -> 0.027659405 | M39: % | N39: Notas_EEFF (citado por fórmula viva) | Q39: Fórmula viva: año actual / año previo - 1.
A40: Automóvil — driver activo (% YoY prima suscrita neta) | G40: =CHOOSE($C$5,G42,G43,G41) -> 0.1407 | H40: =CHOOSE($C$5,H42,H43,H41) -> 0.1407 | I40: =CHOOSE($C$5,I42,I43,I41) -> 0.1407 | J40: =CHOOSE($C$5,J42,J43,J41) -> 0.1407 | K40: =CHOOSE($C$5,K42,K43,K41) -> 0.1407 | M40: % | N40: NOT_DISCLOSED | Q40: Selector de caso activo C5: Base/Bull/Bear.
A41: Bear | G41: 0.1207 | H41: 0.1207 | I41: 0.1207 | J41: 0.1207 | K41: 0.1207 | M41: % | N41: NOT_DISCLOSED | Q41: Escenario driver citado; NOT_DISCLOSED si no hay fuente explícita.
A42: Base | G42: 0.1407 | H42: 0.1407 | I42: 0.1407 | J42: 0.1407 | K42: 0.1407 | M42: % | N42: NOT_DISCLOSED | Q42: Escenario driver citado; NOT_DISCLOSED si no hay fuente explícita.
A43: Bull | G43: 0.1607 | H43: 0.1607 | I43: 0.1607 | J43: 0.1607 | K43: 0.1607 | M43: % | N43: NOT_DISCLOSED | Q43: Escenario driver citado; NOT_DISCLOSED si no hay fuente explícita.
A44: YoY histórico 2025 (ref Notas_EEFF) | F44: =Notas_EEFF!K2718/Notas_EEFF!K2719-1 -> 0.1407481 | M44: % | N44: Notas_EEFF (citado por fórmula viva) | Q44: Fórmula viva: año actual / año previo - 1.
A45: Casco — driver activo (% YoY prima suscrita neta) | G45: =CHOOSE($C$5,G47,G48,G46) -> 0.0322 | H45: =CHOOSE($C$5,H47,H48,H46) -> 0.0322 | I45: =CHOOSE($C$5,I47,I48,I46) -> 0.0322 | J45: =CHOOSE($C$5,J47,J48,J46) -> 0.0322 | K45: =CHOOSE($C$5,K47,K48,K46) -> 0.0322 | M45: % | N45: NOT_DISCLOSED | Q45: Selector de caso activo C5: Base/Bull/Bear.
A46: Bear | G46: 0.0122 | H46: 0.0122 | I46: 0.0122 | J46: 0.0122 | K46: 0.0122 | M46: % | N46: NOT_DISCLOSED | Q46: Escenario driver citado; NOT_DISCLOSED si no hay fuente explícita.
A47: Base | G47: 0.0322 | H47: 0.0322 | I47: 0.0322 | J47: 0.0322 | K47: 0.0322 | M47: % | N47: NOT_DISCLOSED | Q47: Escenario driver citado; NOT_DISCLOSED si no hay fuente explícita.
...

Sheet Notas_EEFF
A1: Grupo ASSA, S. A.
A2: Notas a los Estados Financieros
A3: Fuente: informes auditados vía OCR Mistral (verbatim).
A5: Año | B5: Documento fuente | C5: Página OCR | D5: Tabla OCR / sección | E5: Nota # | F5: Título original de la nota | G5: Categoría modelable | H5: Line item EEFF | I5: Sub-line item / detalle | J5: Texto original / disclosure | K5: Monto reportado | L5: Moneda | M5: Unidad / escala | N5: Fecha / venc. / tasa / plazo | O5: Contraparte / contrato / instrumento | P5: Impacto en Supuestos | Q5: Impacto en ModeloFinanciero | R5: Link a celda EEFF | S5: Comentario de extracción | T5: Status
A6: 2021 | B6: INA_ASSA_2021_0.pdf | C6: page-89 | D6: markdown.md | E6: 5 | F6: 5. Saldos y transacciones con partes relacionadas | G6: Partes relacionadas | J6: Los saldos y transacciones con partes relacionadas del Grupo se detallan a continuación: | T6: OK
A7: 2021 | B7: INA_ASSA_2021_0.pdf | C7: page-89 | D7: markdown.md | E7: 5 | F7: 5. Saldos y transacciones con partes relacionadas | G7: Partes relacionadas | J7: (a) Transacciones con personal clave de gerencia | T7: OK
A8: 2021 | B8: INA_ASSA_2021_0.pdf | C8: page-89 | D8: markdown.md | E8: 5 | F8: 5. Saldos y transacciones con partes relacionadas | G8: Partes relacionadas | J8: - Préstamos a directores, personal clave de la gerencia | T8: OK
A9: 2021 | B9: INA_ASSA_2021_0.pdf | C9: page-89 | D9: markdown.md | E9: 5 | F9: 5. Saldos y transacciones con partes relacionadas | G9: Partes relacionadas | J9: Al 31 de diciembre de 2021, el saldo pendiente de los préstamos por cobrar a directores y personal clave de la gerencia asciende a US$674,272 (2020: US$712,613) y están incluidos en los préstamos por cobrar. Estos saldos presentan intereses por cobrar por US$4,732 (2020: US$5,929). | K9: 674272 | L9: B/. | T9: OK
A10: 2021 | B10: INA_ASSA_2021_0.pdf | C10: page-89 | D10: markdown.md | E10: 5 | F10: 5. Saldos y transacciones con partes relacionadas | G10: Partes relacionadas | J10: Durante el año se han registrado ingresos por intereses sobre estos préstamos con directores y personal clave de la gerencia por US$46,590 (2020: US$49,610). | K10: 46590 | L10: B/. | T10: OK
A11: 2021 | B11: INA_ASSA_2021_0.pdf | C11: page-89 | D11: markdown.md | E11: 5 | F11: 5. Saldos y transacciones con partes relacionadas | G11: Partes relacionadas | J11: - Depósitos de directores y personal clave de la gerencia | T11: OK
A12: 2021 | B12: INA_ASSA_2021_0.pdf | C12: page-89 | D12: markdown.md | E12: 5 | F12: 5. Saldos y transacciones con partes relacionadas | G12: Partes relacionadas | J12: Algunos directores y personal clave de la gerencia del Grupo mantienen cuentas corrientes, de ahorro y plazos fijos en las subsidiarias Grupo BDF, S. A. y La Hipotecaria (Holding), Inc. las cuales, al 31 de diciembre de 2021, mantenían un saldo de US$1,553,553 (2020: US$1,936,743) y están incluidas en las cuentas de depósitos de clientes del Grupo. Estos saldos presentan intereses por pagar por US$9,173 (2020: US$9,322). | K12: 1553553 | L12: B/. | T12: OK
A13: 2021 | B13: INA_ASSA_2021_0.pdf | C13: page-90 | D13: markdown.md | E13: 5 | F13: 5. Saldos y transacciones con partes relacionadas | G13: Partes relacionadas | J13: Durante el año, estas subsidiarias registraron gastos por intereses sobre depósitos de directores y personal clave de la gerencia por US$59,809 (2020: US$299,832). | K13: 59809 | L13: B/. | T13: OK
A14: 2021 | B14: INA_ASSA_2021_0.pdf | C14: page-90 | D14: markdown.md | E14: 5 | F14: 5. Saldos y transacciones con partes relacionadas | G14: Partes relacionadas | J14: - Primas suscritas a directores y personal clave de gerencia Dentro del giro normal del negocio, directores y personal clave de gerencia han suscrito pólizas a nombre propio con primas anuales por la suma de US$112,717 (2020: US$113,412) en condiciones similares a las que se pactan con terceros no vinculados al Grupo. | K14: 112717 | L14: B/. | T14: OK
A15: 2021 | B15: INA_ASSA_2021_0.pdf | C15: page-90 | D15: markdown.md | E15: 5 | F15: 5. Saldos y transacciones con partes relacionadas | G15: Partes relacionadas | J15: Al 31 de diciembre de 2021, el saldo de primas por cobrar asciende a US$55,870 (2020: US$51,871) y está incluido en las cuentas por cobrar de asegurados. Otras cuentas por cobrar ascendieron a US$226 (2020: US$271). | K15: 55870 | L15: B/. | T15: OK
A16: 2021 | B16: INA_ASSA_2021_0.pdf | C16: page-90 | D16: markdown.md | E16: 5 | F16: 5. Saldos y transacciones con partes relacionadas | G16: Partes relacionadas | J16: Durante el año, se han pagado reclamos a estas pólizas por US$19,086 (2020: US$10,084). | K16: 19086 | L16: B/. | T16: OK
A17: 2021 | B17: INA_ASSA_2021_0.pdf | C17: page-90 | D17: markdown.md | E17: 5 | F17: 5. Saldos y transacciones con partes relacionadas | G17: Partes relacionadas | J17: - Compensación recibida por el personal clave de gerencia, directores, personal clave de la gerencia: Algunos miembros del personal clave de la gerencia del Grupo participan en programas de opción de compra de acciones y de concesión de acciones ("grants") del Grupo (véase Nota 23). Adicionalmente, algunos de los empleados de las subsidiarias de ASSA Compañía Tenedora, S. A., pueden participar en alguno de estos programas si cumplen con ciertos criterios de antigüedad de servicios, entre otros. | T17: OK
A18: 2021 | B18: INA_ASSA_2021_0.pdf | C18: page-90 | D18: markdown.md | E18: 5 | F18: 5. Saldos y transacciones con partes relacionadas | G18: Partes relacionadas | J18: Las transacciones del personal clave de gerencia y directores están compuestas por dietas, salarios y otras remuneraciones y ascienden a US$9,402,041 (2020: US$10,097,417). | K18: 9402041 | L18: B/. | T18: OK
A19: 2021 | B19: INA_ASSA_2021_0.pdf | C19: page-91 | D19: markdown.md | E19: 5 | F19: 5. Saldos y transacciones con partes relacionadas | G19: Partes relacionadas | J19: (b) Saldos y transacciones con compañías relacionadas y afiliadas Los saldos con las partes relacionadas se detallan de la siguiente manera: | T19: OK
A20: 2021 | B20: INA_ASSA_2021_0.pdf | C20: page-91 | D20: tbl-29.html | E20: 5 | F20: 5. Saldos y transacciones con partes relacionadas | G20: Partes relacionadas | J20: [tbl-29.html](tbl-29.html) | T20: OK
A21: 2021 | B21: INA_ASSA_2021_0.pdf | C21: page-91 | D21: markdown.md | E21: 5 | F21: 5. Saldos y transacciones con partes relacionadas | G21: Partes relacionadas | J21: Ocasionalmente, el Grupo adquiere instrumentos financieros emitidos por partes relacionadas y afiliadas y coloca depósitos en esas compañías, los cuales producen ingresos financieros. | T21: OK
A22: 2021 | B22: INA_ASSA_2021_0.pdf | C22: page-91 | D22: markdown.md | E22: 5 | F22: 5. Saldos y transacciones con partes relacionadas | G22: Partes relacionadas | J22: También el Grupo, dentro del giro normal del negocio, vende productos de seguros de algunas compañías relacionadas, pagando igualmente cualquier reclamo. Los términos y condiciones de estas transacciones no han sido más favorables que aquellos que se pudiera razonablemente esperar que estuvieran disponibles, en transacciones similares, a entidades no relacionadas, sobre la base de libre competencia. | T22: OK
A23: 2021 | B23: INA_ASSA_2021_0.pdf | C23: page-92 | D23: markdown.md | E23: 6 | F23: 6. Efectivo y depósitos en bancos | G23: Working capital | J23: El efectivo y los depósitos en bancos se detallan de la siguiente manera: | T23: OK
A24: 2021 | B24: INA_ASSA_2021_0.pdf | C24: page-92 | D24: tbl-30.html | E24: 6 | F24: 6. Efectivo y depósitos en bancos | G24: Working capital | J24: [tbl-30.html](tbl-30.html) | T24: OK
A25: 2021 | B25: INA_ASSA_2021_0.pdf | C25: page-92 | D25: markdown.md | E25: 6 | F25: 6. Efectivo y depósitos en bancos | G25: Working capital | J25: El efectivo restringido consiste en: | T25: OK
A26: 2021 | B26: INA_ASSA_2021_0.pdf | C26: page-92 | D26: markdown.md | E26: 6 | F26: 6. Efectivo y depósitos en bancos | G26: Working capital | J26: - Encaje legal depositado en el Banco Central de Nicaragua por US$50,335,044 (2020: US$47,940,434) basado en el porcentaje de los depósitos captados de terceros. - Al 31 de diciembre de 2021, no se mantienen depósitos en garantía de operaciones (2020: US$946,803). | K26: 50335044 | L26: B/. | T26: OK
A27: 2021 | B27: INA_ASSA_2021_0.pdf | C27: page-92 | D27: markdown.md | E27: 7 | F27: 7. Cuentas por cobrar de seguros y otras, neto | G27: Cuentas por cobrar | J27: Las cuentas por cobrar de seguros y otras cuentas por cobrar, netas se detallan de la siguiente manera: | T27: OK
A28: 2021 | B28: INA_ASSA_2021_0.pdf | C28: page-92 | D28: tbl-31.html | E28: 7 | F28: 7. Cuentas por cobrar de seguros y otras, neto | G28: Cuentas por cobrar | J28: [tbl-31.html](tbl-31.html) | T28: OK
A29: 2021 | B29: INA_ASSA_2021_0.pdf | C29: page-92 | D29: markdown.md | E29: 7 | F29: 7. Cuentas por cobrar de seguros y otras, neto | G29: Cuentas por cobrar | J29: La legislación panameña relacionada con la recuperación del crédito fiscal por realizar se detalla en la Nota 32 (b). | T29: OK
A30: 2021 | B30: INA_ASSA_2021_0.pdf | C30: page-93 | D30: markdown.md | E30: 7 | F30: 7. Cuentas por cobrar de seguros y otras, neto | G30: Cuentas por cobrar | J30: Los movimientos de la provisión para pérdidas crediticias esperadas en primas por cobrar se detallan de la siguiente forma: | T30: OK
A31: 2021 | B31: INA_ASSA_2021_0.pdf | C31: page-93 | D31: tbl-32.html | E31: 7 | F31: 7. Cuentas por cobrar de seguros y otras, neto | G31: Cuentas por cobrar | J31: [tbl-32.html](tbl-32.html) | T31: OK
A32: 2021 | B32: INA_ASSA_2021_0.pdf | C32: page-93 | D32: markdown.md | E32: 7 | F32: 7. Cuentas por cobrar de seguros y otras, neto | G32: Cuentas por cobrar | J32: (8) Préstamos por cobrar, neto | T32: OK
A33: 2021 | B33: INA_ASSA_2021_0.pdf | C33: page-93 | D33: markdown.md | E33: 7 | F33: 7. Cuentas por cobrar de seguros y otras, neto | G33: Cuentas por cobrar | J33: La composición de la cartera de préstamos netos, distribuidos por actividad económica, se resume a continuación: | T33: OK
A34: 2021 | B34: INA_ASSA_2021_0.pdf | C34: page-93 | D34: tbl-33.html | E34: 7 | F34: 7. Cuentas por cobrar de seguros y otras, neto | G34: Cuentas por cobrar | J34: [tbl-33.html](tbl-33.html) | T34: OK
A35: 2021 | B35: INA_ASSA_2021_0.pdf | C35: page-93 | D35: markdown.md | E35: 7 | F35: 7. Cuentas por cobrar de seguros y otras, neto | G35: Cuentas por cobrar | J35: Al 31 de diciembre de 2021, las tasas de interés anual de los préstamos oscilaban entre 5% y 30% (2020: 5% y 33%) y para tarjetas de crédito entre 13% y 45% (2020: 15% y 45%). | T35: OK
A36: 2021 | B36: INA_ASSA_2021_0.pdf | C36: page-93 | D36: markdown.md | E36: 7 | F36: 7. Cuentas por cobrar de seguros y otras, neto | G36: Cuentas por cobrar | J36: Al 31 de diciembre de 2021, la subsidiaria La Hipotecaria (Holding), Inc. y Subsidiarias, mantenía préstamos hipotecarios para viviendas por US$200,910,697 (2020: US$238,395,359) en garantía de obligaciones contraídas con instituciones financieras y a la fecha no mantienen créditos hipotecarios en garantía de notas comerciales negociables (véase Nota 14). | K36: 200910697 | L36: B/. | T36: OK
A37: 2021 | B37: INA_ASSA_2021_0.pdf | C37: page-94 | D37: markdown.md | E37: 7 | F37: 7. Cuentas por cobrar de seguros y otras, neto | G37: Cuentas por cobrar | J37: Al 31 de diciembre de 2021, la subsidiaria Grupo BDF, S. A. mantenía préstamos por cobrar por US$67,097,026 (2020: US$80,067,689) que garantizan obligaciones con instituciones financieras (véase Nota 14). | K37: 67097026 | L37: B/. | T37: OK
A38: 2021 | B38: INA_ASSA_2021_0.pdf | C38: page-94 | D38: markdown.md | E38: 7 | F38: 7. Cuentas por cobrar de seguros y otras, neto | G38: Cuentas por cobrar | J38: El movimiento de la provisión para pérdidas crediticias esperadas en préstamos se detalla a continuación: | T38: OK
A39: 2021 | B39: INA_ASSA_2021_0.pdf | C39: page-94 | D39: tbl-34.html | E39: 7 | F39: 7. Cuentas por cobrar de seguros y otras, neto | G39: Cuentas por cobrar | J39: [tbl-34.html](tbl-34.html) | T39: OK
A40: 2021 | B40: INA_ASSA_2021_0.pdf | C40: page-94 | D40: markdown.md | E40: 7 | F40: 7. Cuentas por cobrar de seguros y otras, neto | G40: Cuentas por cobrar | J40: Las subsidiarias con operaciones bancarias en Panamá y Nicaragua, requieren establecer reservas regulatorias para préstamos, indistintamente de las provisiones requeridas bajo NIIF. | T40: OK
A41: 2021 | B41: INA_ASSA_2021_0.pdf | C41: page-94 | D41: markdown.md | E41: 7 | F41: 7. Cuentas por cobrar de seguros y otras, neto | G41: Cuentas por cobrar | J41: Al 31 de diciembre de 2021, estas reservas regulatorias acumuladas ascienden a US$17,999,310 (2020: US$18,978,963), las cuales se presentan en el estado consolidado de cambios en el patrimonio como una apropiación de las utilidades no distribuidas disponibles. | K41: 17999310 | L41: B/. | T41: OK
...

Sheet ModeloFinanciero
A1: Grupo ASSA, S. A.
A2: Estados Financieros Consolidados Auditados FY21-FY25
A3: en US$ sin escala
A5: Años | B5: FY21A | C5: FY22A | D5: FY23A | E5: FY24A | F5: FY25A | G5: FY26E | H5: FY27E | I5: FY28E | J5: FY29E | K5: FY30E
A6: Estado de Resultados
A7: Primas suscritas, netas de cancelaciones | B7: =EEFF!B8 -> 657884741 | C7: =EEFF!C8 -> 698200257 | D7: =EEFF!D8 -> 817173751 | F7: =EEFF!F8 -> 0
A8: Primas suscritas cedidas a reaseguradores | B8: =EEFF!B9 -> -356304040 | C8: =EEFF!C9 -> -361584073 | D8: =EEFF!D9 -> -435628239 | F8: =EEFF!F9 -> 0
A9: Total de primas netas retenidas | B9: =EEFF!B10 -> 301580701 | C9: =EEFF!C10 -> 336616184 | D9: =EEFF!D10 -> 381545512 | F9: =EEFF!F10 -> 0 | G9: =G7+G8 -> 0 | H9: =H7+H8 -> 0 | I9: =I7+I8 -> 0 | J9: =J7+J8 -> 0 | K9: =K7+K8 -> 0
A10: Cambio en la provisión bruta para riesgo en curso | B10: =EEFF!B11 -> -9152442 | C10: =EEFF!C11 -> 3120015 | D10: =EEFF!D11 -> -28420469 | F10: =EEFF!F11 -> 0
A11: Cambio en la provisión en los negocios de vida a largo plazo sobre pólizas de vida | B11: =EEFF!B12 -> -10285045 | C11: =EEFF!C12 -> -12525971 | D11: =EEFF!D12 -> -12302706 | F11: =EEFF!F12 -> 0
A12: Cambio en la participación de los reaseguradores en la provisión sobre contratos de seguros | B12: =EEFF!B13 -> 9401319 | C12: =EEFF!C13 -> -6820962 | D12: =EEFF!D13 -> 16095063 | E12: =EEFF!E13 -> 0 | F12: =EEFF!F13 -> 0
A13: Total de cambios en las provisiones de los contratos de seguros | B13: =EEFF!B14 -> -10036168 | C13: =EEFF!C14 -> -16226918 | D13: =EEFF!D14 -> -24628112 | F13: =EEFF!F14 -> 0 | G13: =G10+G11+G12 -> 0 | H13: =H10+H11+H12 -> 0 | I13: =I10+I11+I12 -> 0 | J13: =J10+J11+J12 -> 0 | K13: =K10+K11+K12 -> 0
A14: Primas netas ganadas | B14: =EEFF!B15 -> 291544533 | C14: =EEFF!C15 -> 320389266 | D14: =EEFF!D15 -> 356917400 | F14: =EEFF!F15 -> 0 | G14: =G9+G13 -> 0 | H14: =H9+H13 -> 0 | I14: =I9+I13 -> 0 | J14: =J9+J13 -> 0 | K14: =K9+K13 -> 0
A15: Reclamos y beneficios incurridos | B15: =EEFF!B16 -> -238994085 | C15: =EEFF!C16 -> -327863954 | D15: =EEFF!D16 -> -238087045 | F15: =EEFF!F16 -> 0 | G15: =G9*Supuestos!G19 -> 0 | H15: =H9*Supuestos!H19 -> 0 | I15: =I9*Supuestos!I19 -> 0 | J15: =J9*Supuestos!J19 -> 0 | K15: =K9*Supuestos!K19 -> 0
A16: Participación de los reaseguradores en los reclamos y beneficios incurridos | B16: =EEFF!B17 -> 101363600 | C16: =EEFF!C17 -> 176570373 | D16: =EEFF!D17 -> 65656958 | F16: =EEFF!F17 -> 0
A17: Beneficios por reembolsos y rescates | B17: =EEFF!B18 -> -13646362 | C17: =EEFF!C18 -> -14629260 | D17: =EEFF!D18 -> -16826376 | F17: =EEFF!F18 -> 0
A18: Reclamos y beneficios netos incurridos por los asegurados | B18: =EEFF!B19 -> -151276847 | C18: =EEFF!C19 -> -165922841 | D18: =EEFF!D19 -> -189256463 | F18: =EEFF!F19 -> 0
A19: Costo de suscripción y adquisición | B19: =EEFF!B20 -> -89805859 | C19: =EEFF!C20 -> -98549869 | D19: =EEFF!D20 -> -115810518 | F19: =EEFF!F20 -> 0
A20: Provisión para pérdidas crediticias esperadas en primas por cobrar | B20: =EEFF!B21 -> -143340 | C20: =EEFF!C21 -> -1327507 | D20: =EEFF!D21 -> -1113601 | F20: =EEFF!F21 -> 0
A21: Primas netas ganadas, después de reclamos, costos de suscripción y provisión para pérdidas crediticias esperadas en primas por cobrar | B21: =EEFF!B22 -> 50318487 | C21: =EEFF!C22 -> 54589049 | D21: =EEFF!D22 -> 50736818 | F21: =EEFF!F22 -> 0 | G21: =G15+G16+G17+G18+G19+G20 -> 0 | H21: =H15+H16+H17+H18+H19+H20 -> 0 | I21: =I15+I16+I17+I18+I19+I20 -> 0 | J21: =J15+J16+J17+J18+J19+J20 -> 0 | K21: =K15+K16+K17+K18+K19+K20 -> 0
A22: Intereses sobre préstamos | B22: =EEFF!B23 -> 90113580 | C22: =EEFF!C23 -> 89349229 | D22: =EEFF!D23 -> 99791323 | E22: =EEFF!E23 -> 0 | F22: =EEFF!F23 -> 0
A23: Intereses sobre depósitos en bancos | B23: =EEFF!B24 -> 324360 | C23: =EEFF!C24 -> 852370 | D23: =EEFF!D24 -> 1871676 | E23: =EEFF!E24 -> 0 | F23: =EEFF!F24 -> 0
A24: Intereses sobre inversiones en valores | B24: =EEFF!B25 -> 30270095 | C24: =EEFF!C25 -> 33792124 | D24: =EEFF!D25 -> 38203473 | E24: =EEFF!E25 -> 0 | F24: =EEFF!F25 -> 0
A25: Total de ingresos por intereses | B25: =EEFF!B26 -> 120708035 | C25: =EEFF!C26 -> 123993723 | D25: =EEFF!D26 -> 139866472 | E25: =EEFF!E26 -> 0 | F25: =EEFF!F26 -> 0 | G25: =G22+G23+G24 -> 0 | H25: =H22+H23+H24 -> 0 | I25: =I22+I23+I24 -> 0 | J25: =J22+J23+J24 -> 0 | K25: =K22+K23+K24 -> 0
A26: Gastos por intereses sobre depósitos | B26: =EEFF!B27 -> -25360968 | C26: =EEFF!C27 -> -25531810 | D26: =EEFF!D27 -> -34235136 | E26: =EEFF!E27 -> 0 | F26: =EEFF!F27 -> 0
A27: Gastos por intereses sobre emisiones de deuda y obligaciones | B27: =EEFF!B28 -> -30177384 | C27: =EEFF!C28 -> -29003930 | D27: =EEFF!D28 -> -34426805 | E27: =EEFF!E28 -> 0 | F27: =EEFF!F28 -> 0
A28: Total de gastos por intereses | B28: =EEFF!B29 -> -55538352 | C28: =EEFF!C29 -> -54535740 | D28: =EEFF!D29 -> -68661941 | F28: =EEFF!F29 -> 0 | G28: =G26+G27 -> 0 | H28: =H26+H27 -> 0 | I28: =I26+I27 -> 0 | J28: =J26+J27 -> 0 | K28: =K26+K27 -> 0
A29: Provisión para pérdidas crediticias esperadas en préstamos | B29: =EEFF!B30 -> -4291456 | C29: =EEFF!C30 -> -4626793 | D29: =EEFF!D30 -> -7316131 | E29: =EEFF!E30 -> 0 | F29: =EEFF!F30 -> 0
A30: Ganancia neta por modificación de préstamos a CA | B30: =EEFF!B31 -> 0 | C30: =EEFF!C31 -> 515213 | D30: =EEFF!D31 -> 67054 | E30: =EEFF!E31 -> 0 | F30: =EEFF!F31 -> 0
A31: Resultado neto de intereses, comisiones y provisión para pérdidas crediticias esperadas en préstamos | B31: =EEFF!B32 -> 60878227 | C31: =EEFF!C32 -> 65346403 | D31: =EEFF!D32 -> 63955454 | F31: =EEFF!F32 -> 0 | G31: =G25+G28+G29+G30 -> 0 | H31: =H25+H28+H29+H30 -> 0 | I31: =I25+I28+I29+I30 -> 0 | J31: =J25+J28+J29+J30 -> 0 | K31: =K25+K28+K29+K30 -> 0
A32: Ingresos por comisiones y servicios financieros | B32: =EEFF!B33 -> 53282269 | C32: =EEFF!C33 -> 54586912 | D32: =EEFF!D33 -> 68685561 | F32: =EEFF!F33 -> 0
A33: Ganancia (Pérdida) en venta de bonos y acciones, neto | B33: =EEFF!B34 -> 2013784 | C33: =EEFF!C34 -> -240213 | D33: =EEFF!D34 -> 63303 | E33: =EEFF!E34 -> 0 | F33: =EEFF!F34 -> 0
A34: Dividendos ganados | B34: =EEFF!B35 -> 24063694 | C34: =EEFF!C35 -> 30788100 | D34: =EEFF!D35 -> 40145969 | F34: =EEFF!F35 -> 0
A35: Ganancia (Pérdida) no realizada de inversiones a valor razonable con cambio en resultado | B35: =EEFF!B36 -> 6681944 | C35: =EEFF!C36 -> -14025402 | D35: =EEFF!D36 -> 5542980 | E35: =EEFF!E36 -> 0 | F35: =EEFF!F36 -> 0
A36: Otros ingresos de operaciones, neto | B36: =EEFF!B37 -> 9840321 | C36: =EEFF!C37 -> 5497518 | D36: =EEFF!D37 -> 3537146 | F36: =EEFF!F37 -> 0
A37: Reversión de (provisión para) pérdidas crediticias esperadas en inversiones | B37: =EEFF!B38 -> -125836 | C37: =EEFF!C38 -> -582779 | D37: =EEFF!D38 -> 1442923 | E37: =EEFF!E38 -> 0 | F37: =EEFF!F38 -> 0
A38: Resultados, neto | B38: =EEFF!B39 -> 206952890 | C38: =EEFF!C39 -> 195959588 | D38: =EEFF!D39 -> 234110154 | F38: =EEFF!F39 -> 0 | G38: =G21+G31+G32+G33+G34+G35+G36+G37 -> 0 | H38: =H21+H31+H32+H33+H34+H35+H36+H37 -> 0 | I38: =I21+I31+I32+I33+I34+I35+I36+I37 -> 0 | J38: =J21+J31+J32+J33+J34+J35+J36+J37 -> 0 | K38: =K21+K31+K32+K33+K34+K35+K36+K37 -> 0
A39: Gastos de personal | B39: =EEFF!B40 -> -65378406 | C39: =EEFF!C40 -> -68691932 | D39: =EEFF!D40 -> -72370796 | F39: =EEFF!F40 -> 0
A40: Gastos generales y administrativos | B40: =EEFF!B62 -> 0 | C40: =EEFF!C62 -> 0 | D40: =EEFF!D62 -> 0 | E40: =EEFF!E62 -> -89212204 | F40: =EEFF!F62 -> -95272868 | G40: =G9*Supuestos!G26 -> 0 | H40: =H9*Supuestos!H26 -> 0 | I40: =I9*Supuestos!I26 -> 0 | J40: =J9*Supuestos!J26 -> 0 | K40: =K9*Supuestos!K26 -> 0
A41: Gastos de depreciación de activos fijos y propiedades de inversión | B41: =EEFF!B42 -> -6393929 | C41: =EEFF!C42 -> -7352476 | D41: =EEFF!D42 -> -6753787 | F41: =EEFF!F42 -> 0
...

Sheet Puente_NIIF17
A1: Grupo ASSA, S. A.
A2: Puente_NIIF17 — conciliación del cambio de base contable: base regulatoria SSRP / NIIF excepto NIIF 17 (FY2021A–FY2024A) → Normas NIIF plenas con NIIF 17 (FY2024A re-expresado · FY2025A)
A3: Transición: 1 de enero de 2024 (NIIF 1 primera adopción + NIIF 17; Acuerdo 01-2024 SSRP). El filing 2025A no publica el impacto partida por partida (Nota 5): el efecto se revela en el estado de cambios en el patrimonio.
A4: Fuentes verbatim del mirror OCR: filing 2024A (base vieja) · filing 2025A (re-expresado). Azul = cifra publicada verbatim; negro = conciliación local (esperado 0).
A6: Agregados FY2024A en las dos bases contables | B6: Base SSRP (filing 2024A) | C6: NIIF 17 re-expresado (filing 2025A) | D6: Δ (NIIF 17 − SSRP)
A7: Total de activos | B7: 3280490170 | C7: 3119530651 | D7: =C7-B7 -> -160959519
A8: Total de pasivos | B8: 1903341718 | C8: 1673539425 | D8: =C8-B8 -> -229802293
A9: Total de patrimonio | B9: 1377148452 | C9: 1445991226 | D9: =C9-B9 -> 68842774
A10: Utilidad neta, antes de operación descontinuada | B10: 119425469 | C10: 128434687 | D10: =C10-B10 -> 9009218
A11: Utilidad neta | B11: 115636579 | C11: 124645797 | D11: =C11-B11 -> 9009218
A12: Verificación local: Δ activos − Δ pasivos − Δ patrimonio (esperado 0) | D12: =D7-D8-D9 -> 0
A14: Conciliación del patrimonio — transición al 1 de enero de 2024 | B14: Total de patrimonio (US$)
A15: Saldo al 1 de enero de 2024, previamente reportado | B15: 1217249492
A16: Ajuste por aplicación inicial de la NIIF 17, neto de impuesto | B16: 45319978
A17: Corrección de error no material y otros ajustes | B17: 0
A18: Saldo re-expresado al 1 de enero de 2024 | B18: 1262569470
A19: Verificación local: reportado + ajustes − re-expresado (esperado 0) | B19: =B15+B16+B17-B18 -> 0
A20: Amarre base vieja: Total de patrimonio al 31-dic-2023 (filing 2024A) | B20: 1217249492
A21: Verificación local: amarre base vieja − previamente reportado (esperado 0) | B21: =B20-B15 -> 0
A23: Rodamiento re-expresado del patrimonio FY2024 (NIIF 17) | B23: Total de patrimonio (US$)
A24: Saldo re-expresado al 1 de enero de 2024 (apertura) | B24: =B18 -> 1262569470
A25: Total de resultados integrales re-expresados | B25: 263916500
A26: Reclasificación de reservas y asignaciones | B26: 33
A27: Transacciones con accionistas y cambios en participaciones en subsidiarias | B27: -80494777
A28: Saldo al 31 de diciembre de 2024 (NIIF 17 re-expresado) | B28: 1445991226
A29: Verificación local: apertura + movimientos − cierre (esperado 0) | B29: =B24+B25+B26+B27-B28 -> 0
A31: Nota: el detalle por participación (controladora / no controladora) está en el estado consolidado de cambios en el patrimonio del filing 2025A; este puente concilia la columna Total de patrimonio.
A32: Serie comparable del analista: ver ModeloFinanciero (banderas NOT_COMPARABLE donde la línea no existe en ambas bases).

Sheet Premiums_Claims
A1: Grupo ASSA, S. A.
A2: Premiums_Claims — puente de base contable + prima por ramo + resultado de servicio NIIF 17
A3: Fuente: EEFF (mirror congelado) + mirror OCR ASSA 2025 (tbl-35, Nota concentracion de riesgo de suscripcion). Ver flags[] para vacios de fuente.
A5: Años | B5: FY21A | C5: FY22A | D5: FY23A | E5: FY24A | F5: FY25A | G5: FY26E | H5: FY27E | I5: FY28E | J5: FY29E | K5: FY30E
A7: A. ACCOUNTING_BASIS — puente base legacy (NIIF excepto NIIF 17) -> NIIF 17 re-expresado
A8: Fuente: SSRP diferio NIIF 17 a 1-ene-2025; FY21-FY23 base legacy Panama/NIIF-excepto-NIIF17, FY24-FY25 re-expresadas bajo NIIF 17 (OCR text lines 452-464).
A9: FY26-FY30 forecast se modela 100% en base NIIF 17 (Seccion C); no se produce un forecast de primas legacy — por construccion, ambas bases no pueden mezclarse en el horizonte de proyeccion.
A10: Total de primas netas retenidas — base legacy (ref EEFF, FY21-FY23) | B10: =EEFF!B10 -> 301580701 | C10: =EEFF!C10 -> 336616184 | D10: =EEFF!D10 -> 381545512 | F10: =EEFF!F10 -> 0
A11: Ingresos por servicios de seguro — base NIIF 17 (ref EEFF, FY24-FY25) | B11: =EEFF!B50 -> 0 | C11: =EEFF!C50 -> 0 | D11: =EEFF!D50 -> 0 | E11: =EEFF!E50 -> 820306455 | F11: =EEFF!F50 -> 885435473
A12: CHECK ACCOUNTING_BASIS_SWITCH_TIE (1=bases mezcladas en el mismo ano historico, esperado 0 en B:F) | B12: =IF(AND(B10<>0,B11<>0),1,0) -> 0 | C12: =IF(AND(C10<>0,C11<>0),1,0) -> 0 | D12: =IF(AND(D10<>0,D11<>0),1,0) -> 0 | E12: =IF(AND(E10<>0,E11<>0),1,0) -> 0 | F12: =IF(AND(F10<>0,F11<>0),1,0) -> 0
A14: G:K (forecast) no aplica a este check: no existe fila de primas legacy proyectada (ver nota arriba).
A16: B. PREMIUM_BUILD — prima suscrita neta de reaseguro por ramo (concentracion de riesgo de suscripcion)
A17: Fuente verbatim: INA_ASSA_2025_0.pdf p.96 (prima suscrita neta de reaseguro por ramo, concentracion del riesgo de suscripcion). Solo FY24-FY25 divulgados por ramo; FY21-FY23 NOT_DISCLOSED a nivel de ramo.
A18: BASE_DISTINTA: este total (prima suscrita neta de reaseguro por ramo) NO es la misma base que 'Ingresos por servicios de seguro' NIIF 17 consolidado (Seccion C) — alcance/base distintos (posible sub-segmento de riesgo de suscripcion vs. grupo consolidado, incl. vida en Centroamerica). No se fuerza una conciliacion 1:1 no divulgada.
A19: Accidentes personales | E19: =Notas_EEFF!K2717 -> 84101845 | F19: =Notas_EEFF!K2716 -> 86428052 | G19: =F19*(1+Supuestos!G35) -> 88822109 | H19: =G19*(1+Supuestos!H35) -> 91282481 | I19: =H19*(1+Supuestos!I35) -> 93811006 | J19: =I19*(1+Supuestos!J35) -> 96409571 | K19: =J19*(1+Supuestos!K35) -> 99080116
A20: Automóvil | E20: =Notas_EEFF!K2719 -> 100793260 | F20: =Notas_EEFF!K2718 -> 114979720 | G20: =F20*(1+Supuestos!G40) -> 1.3115737e+08 | H20: =G20*(1+Supuestos!H40) -> 1.4961121e+08 | I20: =H20*(1+Supuestos!I40) -> 1.7066151e+08 | J20: =I20*(1+Supuestos!J40) -> 1.9467358e+08 | K20: =J20*(1+Supuestos!K40) -> 2.2206415e+08
A21: Casco | E21: =Notas_EEFF!K2721 -> 18932539 | F21: =Notas_EEFF!K2720 -> 19542577 | G21: =F21*(1+Supuestos!G45) -> 20171848 | H21: =G21*(1+Supuestos!H45) -> 20821381 | I21: =H21*(1+Supuestos!I45) -> 21491830 | J21: =I21*(1+Supuestos!J45) -> 22183867 | K21: =J21*(1+Supuestos!K45) -> 22898187
A22: Colectivo de vida | E22: =Notas_EEFF!K2723 -> 39159903 | F22: =Notas_EEFF!K2722 -> 41214579 | G22: =F22*(1+Supuestos!G50) -> 43378344 | H22: =G22*(1+Supuestos!H50) -> 45655707 | I22: =H22*(1+Supuestos!I50) -> 48052632 | J22: =I22*(1+Supuestos!J50) -> 50575395 | K22: =J22*(1+Supuestos!K50) -> 53230604
A23: Fianzas | E23: =Notas_EEFF!K2725 -> 5662609 | F23: =Notas_EEFF!K2724 -> 5661627 | G23: =F23*(1+Supuestos!G55) -> 5660494.7 | H23: =G23*(1+Supuestos!H55) -> 5659362.6 | I23: =H23*(1+Supuestos!I55) -> 5658230.7 | J23: =I23*(1+Supuestos!J55) -> 5657099.1 | K23: =J23*(1+Supuestos!K55) -> 5655967.6
A24: Fidelidad | E24: =Notas_EEFF!K2727 -> 5264032 | F24: =Notas_EEFF!K2726 -> 5598664 | G24: =F24*(1+Supuestos!G60) -> 5954739 | H24: =G24*(1+Supuestos!H60) -> 6333460.4 | I24: =H24*(1+Supuestos!I60) -> 6736268.5 | J24: =I24*(1+Supuestos!J60) -> 7164695.2 | K24: =J24*(1+Supuestos!K60) -> 7620369.8
A25: Incendio | E25: =Notas_EEFF!K2729 -> 16624396 | F25: =Notas_EEFF!K2728 -> 16727248 | G25: =F25*(1+Supuestos!G65) -> 16830957 | H25: =G25*(1+Supuestos!H65) -> 16935309 | I25: =H25*(1+Supuestos!I65) -> 17040308 | J25: =I25*(1+Supuestos!J65) -> 17145958 | K25: =J25*(1+Supuestos!K65) -> 17252263
A26: Responsabilidad civil | E26: =Notas_EEFF!K2731 -> 5695830 | F26: =Notas_EEFF!K2730 -> 5774973 | G26: =F26*(1+Supuestos!G70) -> 5855245.1 | H26: =G26*(1+Supuestos!H70) -> 5936633 | I26: =H26*(1+Supuestos!I70) -> 6019152.2 | J26: =I26*(1+Supuestos!J70) -> 6102818.4 | K26: =J26*(1+Supuestos!K70) -> 6187647.6
A27: Riesgos diversos | E27: =Notas_EEFF!K2733 -> 5059301 | F27: =Notas_EEFF!K2732 -> 4979863 | G27: =F27*(1+Supuestos!G75) -> 4901679.2 | H27: =G27*(1+Supuestos!H75) -> 4824722.8 | I27: =H27*(1+Supuestos!I75) -> 4748974.6 | J27: =I27*(1+Supuestos!J75) -> 4674415.7 | K27: =J27*(1+Supuestos!K75) -> 4601027.4
A28: Salud | E28: =Notas_EEFF!K2735 -> 64553128 | F28: =Notas_EEFF!K2734 -> 65224063 | G28: =F28*(1+Supuestos!G80) -> 65902393 | H28: =G28*(1+Supuestos!H80) -> 66587778 | I28: =H28*(1+Supuestos!I80) -> 67280291 | J28: =I28*(1+Supuestos!J80) -> 67980006 | K28: =J28*(1+Supuestos!K80) -> 68686998
A29: Seguros técnicos | E29: =Notas_EEFF!K2737 -> 2816214 | F29: =Notas_EEFF!K2736 -> 2734994 | G29: =F29*(1+Supuestos!G85) -> 2656226.2 | H29: =G29*(1+Supuestos!H85) -> 2579726.9 | I29: =H29*(1+Supuestos!I85) -> 2505430.7 | J29: =I29*(1+Supuestos!J85) -> 2433274.3 | K29: =J29*(1+Supuestos!K85) -> 2363196
A30: Autoexpedibles y otros | E30: =Notas_EEFF!K2739 -> 12790589 | F30: =Notas_EEFF!K2738 -> 12943398 | G30: =F30*(1+Supuestos!G90) -> 13097424 | H30: =G30*(1+Supuestos!H90) -> 13253284 | I30: =H30*(1+Supuestos!I90) -> 13410998 | J30: =I30*(1+Supuestos!J90) -> 13570589 | K30: =J30*(1+Supuestos!K90) -> 13732079
A32: Forecast por ramo = driver de escenario por ramo en Supuestos (sección D) — histórico referencia el ledger Notas_EEFF (Nota 10.ii, tbl-35)
A33: Total prima suscrita neta de reaseguro (Sigma ramos) | B33: =B19+B20+B21+B22+B23+B24+B25+B26+B27+B28+B29+B30 -> 0 | C33: =C19+C20+C21+C22+C23+C24+C25+C26+C27+C28+C29+C30 -> 0 | D33: =D19+D20+D21+D22+D23+D24+D25+D26+D27+D28+D29+D30 -> 0 | E33: =E19+E20+E21+E22+E23+E24+E25+E26+E27+E28+E29+E30 -> 361453646 | F33: =F19+F20+F21+F22+F23+F24+F25+F26+F27+F28+F29+F30 -> 381809758 | G33: =G19+G20+G21+G22+G23+G24+G25+G26+G27+G28+G29+G30 -> 4.0438883e+08 | H33: =H19+H20+H21+H22+H23+H24+H25+H26+H27+H28+H29+H30 -> 4.2948105e+08 | I33: =I19+I20+I21+I22+I23+I24+I25+I26+I27+I28+I29+I30 -> 4.5741663e+08 | ... K33: =K19+K20+K21+K22+K23+K24+K25+K26+K27+K28+K29+K30 -> 5.2337261e+08
A34: Total per filing (verbatim tie, tbl-35) | E34: =Notas_EEFF!K2741 -> 361453646 | F34: =Notas_EEFF!K2740 -> 381809758
A35: CHECK INSURANCE_PREMIUM_DRIVER_TIE (Sigma ramos - total verbatim tbl-35, esperado 0 en FY24/FY25) | E35: =E33-E34 -> 0 | F35: =F33-F34 -> 0
A37: C. INSURANCE_SERVICE_RESULT + CLAIMS_SERVICE_EXPENSE (NIIF 17, EEFF filas 42-52)
A38: Fuente: EEFF (mirror congelado) filas Ingresos/Gastos por servicios de seguro, Resultados netos de contratos de reaseguro, Retorno de las inversiones, Resultado financiero neto (OCR text lines 248-258).
A39: Ingresos por servicios de seguro | B39: =EEFF!B50 -> 0 | C39: =EEFF!C50 -> 0 | D39: =EEFF!D50 -> 0 | E39: =EEFF!E50 -> 820306455 | F39: =EEFF!F50 -> 885435473 | G39: =F39*(1+Supuestos!G11) -> 9.5573905e+08 | H39: =G39*(1+Supuestos!H11) -> 1.0316247e+09 | I39: =H39*(1+Supuestos!I11) -> 1.1135357e+09 | J39: =I39*(1+Supuestos!J11) -> 1.2019505e+09 | K39: =J39*(1+Supuestos!K11) -> 1.2973853e+09
A40: Gastos por servicios de seguro | B40: =EEFF!B51 -> 0 | C40: =EEFF!C51 -> 0 | D40: =EEFF!D51 -> 0 | E40: =EEFF!E51 -> -367877750 | F40: =EEFF!F51 -> -426466314 | G40: =G39*Supuestos!G19 -> -4.6028393e+08 | H40: =H39*Supuestos!H19 -> -4.9683047e+08 | I40: =I39*Supuestos!I19 -> -5.3627881e+08 | J40: =J39*Supuestos!J19 -> -5.7885935e+08 | K40: =K39*Supuestos!K19 -> -6.2482078e+08
A41: Resultados netos de contratos de reaseguro | B41: =EEFF!B52 -> 0 | C41: =EEFF!C52 -> 0 | D41: =EEFF!D52 -> 0 | E41: =EEFF!E52 -> -314823760 | F41: =EEFF!F52 -> -313277206 | G41: =G39*($F$41/$F$39) -> -3.3815142e+08 | H41: =H39*($F$41/$F$39) -> -3.6500064e+08 | I41: =I39*($F$41/$F$39) -> -3.9398169e+08 | J41: =J39*($F$41/$F$39) -> -4.2526384e+08 | K41: =K39*($F$41/$F$39) -> -4.5902978e+08
A42: Resultado del servicio de seguro (computado = suma de las 3 lineas anteriores) | B42: =B39+B40+B41 -> 0 | C42: =C39+C40+C41 -> 0 | D42: =D39+D40+D41 -> 0 | E42: =E39+E40+E41 -> 137604945 | F42: =F39+F40+F41 -> 145691953 | G42: =G39+G40+G41 -> 1.5730371e+08 | H42: =H39+H40+H41 -> 1.6979362e+08 | I42: =I39+I40+I41 -> 1.8327524e+08 | ... K42: =K39+K40+K41 -> 2.1353478e+08
A43: Resultado del servicio de seguro (EEFF, subtotal auditado) | B43: =EEFF!B53 -> 0 | C43: =EEFF!C53 -> 0 | D43: =EEFF!D53 -> 0 | E43: =EEFF!E53 -> 137604945 | F43: =EEFF!F53 -> 145691953
A44: CHECK IFRS17_SERVICE_RESULT_TIE (computado - EEFF subtotal, esperado 0 FY24/FY25) | B44: =B42-B43 -> 0 | C44: =C42-C43 -> 0 | D44: =D42-D43 -> 0 | E44: =E42-E43 -> 0 | F44: =F42-F43 -> 0
A46: Ingresos por interes (metodo interes efectivo) | B46: =EEFF!B54 -> 0 | C46: =EEFF!C54 -> 0 | D46: =EEFF!D54 -> 0 | E46: =EEFF!E54 -> 35258108 | F46: =EEFF!F54 -> 40827249
A47: Otros ingresos por inversiones | B47: =EEFF!B55 -> 0 | C47: =EEFF!C55 -> 0 | D47: =EEFF!D55 -> 0 | E47: =EEFF!E55 -> 55379789 | F47: =EEFF!F55 -> 61865524
...

Sheet Claims_Reserves
A1: Grupo ASSA, S. A.
A2: Claims_Reserves — provisiones legacy + roll-forward NIIF 17 LRC/LIC vida/generales (Nota 20)
A3: Fuente: EEFF (mirror congelado) + mirror OCR ASSA 2025 Nota 20 (tbl-68/69/70/71/72). Ver flags[] para vacios de fuente.
A5: Años | B5: FY21A | C5: FY22A | D5: FY23A | E5: FY24A | F5: FY25A | G5: FY26E | H5: FY27E | I5: FY28E | J5: FY29E | K5: FY30E
A7: A. PROVISIONES LEGACY (stock de fin de periodo, FY21-FY23 — base retirada desde FY24)
A8: Fuente: EEFF (mirror congelado), Balance General. NO existe un roll-forward completo divulgado para la base legacy; el movimiento de P&L ('cambio en la provision') ya esta en Premiums_Claims seccion A filas de cambio en provisiones.
A9: Riesgo en curso | B9: =EEFF!B94 -> 222380820 | C9: =EEFF!C94 -> 222836666 | D9: =EEFF!D94 -> 252044466
A10: Reclamos en trámite | B10: =EEFF!B95 -> 166900068 | C10: =EEFF!C95 -> 262168088 | D10: =EEFF!D95 -> 183640714
A11: Negocios de vida a largo plazo sobre pólizas de vida | B11: =EEFF!B96 -> 271722485 | C11: =EEFF!C96 -> 285566197 | D11: =EEFF!D96 -> 297881412
A12: Total de provisiones sobre contratos de seguros (EEFF subtotal auditado, legacy) | B12: =EEFF!B97 -> 661003373 | C12: =EEFF!C97 -> 770570951 | D12: =EEFF!D97 -> 733566592
A14: N/A FY24-FY30: base legacy retirada; ver seccion B (NIIF 17).
A16: B. NIIF 17 — CONTRATOS DE SEGURO Y REASEGURO POR VIDA/GENERALES (Nota 20, tbl-68/69), FY24-FY25
A17: Fuente verbatim: INA_ASSA_2025_0.pdf p.125 (Nota 20, saldos de contratos de seguro y reaseguro, 31-dic-2025) ; INA_ASSA_2025_0.pdf p.125 (Nota 20, saldos de contratos de seguro y reaseguro, 31-dic-2024). Solo 2 anos divulgados (FY24-FY25); FY21-FY23 y forecast FY26-FY30 no aplican a este detalle NIIF 17.
A18: B.1 Contrato de seguro — grupos con saldos pasivos (LRC = pasivo cobertura restante; LIC = pasivo reclamos incurridos)
A19: LRC vida | E19: 223147540 | F19: 226113118
A20: LRC generales | E20: 117243673 | F20: 118644281
A21: LRC total (seguro) | B21: =B19+B20 -> 0 | C21: =C19+C20 -> 0 | D21: =D19+D20 -> 0 | E21: =E19+E20 -> 340391213 | F21: =F19+F20 -> 344757399 | G21: =G19+G20 -> 0 | H21: =H19+H20 -> 0 | I21: =I19+I20 -> 0 | ... K21: =K19+K20 -> 0
A22: LIC vida | E22: 7461196 | F22: 5533001
A23: LIC generales | E23: 199328472 | F23: 166289061
A24: LIC total (seguro) | B24: =B22+B23 -> 0 | C24: =C22+C23 -> 0 | D24: =D22+D23 -> 0 | E24: =E22+E23 -> 206789668 | F24: =F22+F23 -> 171822062 | G24: =G22+G23 -> 0 | H24: =H22+H23 -> 0 | I24: =I22+I23 -> 0 | ... K24: =K22+K23 -> 0
A25: Total pasivo bruto contratos de seguro (LRC + LIC) | B25: =B21+B24 -> 0 | C25: =C21+C24 -> 0 | D25: =D21+D24 -> 0 | E25: =E21+E24 -> 547180881 | F25: =F21+F24 -> 516579461 | G25: =G21+G24 -> 0 | H25: =H21+H24 -> 0 | I25: =I21+I24 -> 0 | ... K25: =K21+K24 -> 0
A27: B.2 Contrato de seguro — grupos con saldos activos (activo cobertura restante, presentado negativo por convencion del filing)
A28: Activo cobertura restante vida | E28: -1664254 | F28: -1639224
A29: Activo cobertura restante generales | E29: -19446414 | F29: -19392926
A30: Activo cobertura restante total | B30: =B28+B29 -> 0 | C30: =C28+C29 -> 0 | D30: =D28+D29 -> 0 | E30: =E28+E29 -> -21110668 | F30: =F28+F29 -> -21032150 | G30: =G28+G29 -> 0 | H30: =H28+H29 -> 0 | I30: =I28+I29 -> 0 | ... K30: =K28+K29 -> 0
A31: Saldo neto contratos de seguro (pasivo bruto + activo cobertura restante) | B31: =B25+B30 -> 0 | C31: =C25+C30 -> 0 | D31: =D25+D30 -> 0 | E31: =E25+E30 -> 526070213 | F31: =F25+F30 -> 495547311 | G31: =G25+G30 -> 0 | H31: =H25+H30 -> 0 | I31: =I25+I30 -> 0 | ... K31: =K25+K30 -> 0
A33: CHECKS B (contra EEFF / BS)
A34: Provisiones sobre contratos de seguros (EEFF BS, NIIF17) | E34: =EEFF!E107 -> 547180881 | F34: =EEFF!F107 -> 516579461
A35: CHECK RESERVE_LRC_LIC_ROLLFORWARD_TIE / INSURANCE_TECHNICAL_RESERVE_TIE (Total pasivo bruto - EEFF BS, esperado 0) | E35: =E25-E34 -> 0 | F35: =F25-F34 -> 0
A37: B.3 Contrato de reaseguro — cedido (LRC/LIC activos por reaseguro cedido + LRC pasivo por reaseguro)
A38: Activo cobertura restante reaseguro, vida | E38: -20744470 | F38: -19080050
A39: Activo cobertura restante reaseguro, generales | E39: -75653344 | F39: -69470378
A40: Activo cobertura restante reaseguro, total | B40: =B38+B39 -> 0 | C40: =C38+C39 -> 0 | D40: =D38+D39 -> 0 | E40: =E38+E39 -> -96397814 | F40: =F38+F39 -> -88550428 | G40: =G38+G39 -> 0 | H40: =H38+H39 -> 0 | I40: =I38+I39 -> 0 | ... K40: =K38+K39 -> 0
A41: Activo reclamos incurridos reaseguro, vida | E41: -1401285 | F41: -508181
A42: Activo reclamos incurridos reaseguro, generales | E42: -126657059 | F42: -90555844
A43: Activo reclamos incurridos reaseguro, total | B43: =B41+B42 -> 0 | C43: =C41+C42 -> 0 | D43: =D41+D42 -> 0 | E43: =E41+E42 -> -128058344 | F43: =F41+F42 -> -91064025 | G43: =G41+G42 -> 0 | H43: =H41+H42 -> 0 | I43: =I41+I42 -> 0 | ... K43: =K41+K42 -> 0
A44: Activo total contrato de reaseguro (cobertura restante + reclamos incurridos) | B44: =B40+B43 -> 0 | C44: =C40+C43 -> 0 | D44: =D40+D43 -> 0 | E44: =E40+E43 -> -224456158 | F44: =F40+F43 -> -179614453 | G44: =G40+G43 -> 0 | H44: =H40+H43 -> 0 | I44: =I40+I43 -> 0 | ... K44: =K40+K43 -> 0
A45: Pasivo cobertura restante reaseguro, generales (grupos con saldo pasivo) | E45: 36801772 | F45: 35259752
A46: Saldo neto contrato de reaseguro (activo + pasivo cobertura restante) | B46: =B44+B45 -> 0 | C46: =C44+C45 -> 0 | D46: =D44+D45 -> 0 | E46: =E44+E45 -> -187654386 | F46: =F44+F45 -> -144354701 | G46: =G44+G45 -> 0 | H46: =H44+H45 -> 0 | I46: =I44+I45 -> 0 | ... K46: =K44+K45 -> 0
A47: Activos por contratos de reaseguros (EEFF BS) | E47: =EEFF!E81 -> 224456158 | F47: =EEFF!F81 -> 179614453
...

Sheet Reinsurance
A1: Grupo ASSA, S. A.
A2: Reinsurance — política, resultado NIIF 17, cesión legacy y saldos de contratos (Nota 20)
A3: Fuente: EEFF (mirror congelado) + INA_ASSA_2025_0.pdf p.96 (politica de reaseguro: exceso de perdida, stop-loss, facultativo) + Nota 20 (via Claims_Reserves). Bases legacy/NIIF17 explícitas, nunca mezcladas.
A5: Años | B5: FY21A | C5: FY22A | D5: FY23A | E5: FY24A | F5: FY25A | G5: FY26E | H5: FY27E | I5: FY28E | J5: FY29E | K5: FY30E
A7: A. POLÍTICA DE REASEGURO (cualitativa, verbatim del filing)
A8: El Grupo usa reaseguro (incl. exceso de pérdida y stop-loss) para mitigar pérdidas significativas de eventos individuales; reaseguro facultativo por encima de la tolerancia al riesgo.
A9: Fuente: INA_ASSA_2025_0.pdf p.96 (politica de reaseguro: exceso de perdida, stop-loss, facultativo).
A11: B. RESULTADO DE REASEGURO EN P&L — base NIIF 17 (FY24-FY30)
A12: Resultados netos de contratos de reaseguro (ref EEFF; forecast link Premiums_Claims) | E12: =EEFF!E52 -> -314823760 | F12: =EEFF!F52 -> -313277206 | G12: =Premiums_Claims!G41 -> -3.3815142e+08 | H12: =Premiums_Claims!H41 -> -3.6500064e+08 | I12: =Premiums_Claims!I41 -> -3.9398169e+08 | J12: =Premiums_Claims!J41 -> -4.2526384e+08 | K12: =Premiums_Claims!K41 -> -4.5902978e+08
A13: Ingresos financieros netos de contratos de reaseguro (ref EEFF) | E13: =EEFF!E59 -> 959026 | F13: =EEFF!F59 -> 2508685
A14: Ingresos por servicios de seguro (ref EEFF; forecast link Premiums_Claims) | E14: =EEFF!E50 -> 820306455 | F14: =EEFF!F50 -> 885435473 | G14: =Premiums_Claims!G39 -> 9.5573905e+08 | H14: =Premiums_Claims!H39 -> 1.0316247e+09 | I14: =Premiums_Claims!I39 -> 1.1135357e+09 | J14: =Premiums_Claims!J39 -> 1.2019505e+09 | K14: =Premiums_Claims!K39 -> 1.2973853e+09
A15: Ratio resultado de reaseguro ÷ ingresos por servicios (NIIF 17) | E15: =E12/E14 -> -0.38378798 | F15: =F12/F14 -> -0.35381145 | G15: =G12/G14 -> -0.35381145 | H15: =H12/H14 -> -0.35381145 | I15: =I12/I14 -> -0.35381145 | J15: =J12/J14 -> -0.35381145 | K15: =K12/K14 -> -0.35381145
A17: Forecast del resultado de reaseguro = ratio FY25 plano sobre ingresos (RATIO_HELD_FLAT_FY25, ver Premiums_Claims). Ingreso financiero de reaseguro: sin forecast propio (Modelo lo lleva plano FY25, FINCOST_FLAT_CARRY).
A19: C. CESIÓN LEGACY (FY21-FY23 — base retirada desde FY24)
A20: Primas suscritas, netas de cancelaciones (ref EEFF) | B20: =EEFF!B8 -> 657884741 | C20: =EEFF!C8 -> 698200257 | D20: =EEFF!D8 -> 817173751
A21: Primas suscritas cedidas a reaseguradores (ref EEFF) | B21: =EEFF!B9 -> -356304040 | C21: =EEFF!C9 -> -361584073 | D21: =EEFF!D9 -> -435628239
A22: Participación de reaseguradores en reclamos y beneficios incurridos (ref EEFF) | B22: =EEFF!B17 -> 101363600 | C22: =EEFF!C17 -> 176570373 | D22: =EEFF!D17 -> 65656958
A23: Ratio de cesión legacy (=|cedidas| ÷ suscritas, FY21-FY23) | B23: =ABS(B21)/B20 -> 0.54159037 | C23: =ABS(C21)/C20 -> 0.51788018 | D23: =ABS(D21)/D20 -> 0.53309133
A25: N/A FY24-FY30: bajo NIIF 17 la cesión se presenta como resultado neto de contratos de reaseguro (sección B); no se mezclan bases.
A27: D. SALDOS DE CONTRATOS DE REASEGURO — Nota 20 (link a Claims_Reserves, FY24-FY25)
A28: Activo cobertura restante reaseguro, total (Nota 20, convención negativa) | E28: =Claims_Reserves!E40 -> -96397814 | F28: =Claims_Reserves!F40 -> -88550428
A29: Activo reclamos incurridos reaseguro, total | E29: =Claims_Reserves!E43 -> -128058344 | F29: =Claims_Reserves!F43 -> -91064025
A30: Activo total contrato de reaseguro | E30: =Claims_Reserves!E44 -> -224456158 | F30: =Claims_Reserves!F44 -> -179614453
A31: Pasivo cobertura restante reaseguro (grupos con saldo pasivo) | E31: =Claims_Reserves!E45 -> 36801772 | F31: =Claims_Reserves!F45 -> 35259752
A32: Total saldo neto contrato de reaseguro (Nota 20) | E32: =Claims_Reserves!E46 -> -187654386 | F32: =Claims_Reserves!F46 -> -144354701
A33: Activos por contratos de reaseguros (EEFF BS) | E33: =EEFF!E81 -> 224456158 | F33: =EEFF!F81 -> 179614453
A34: Provisiones sobre contratos de reaseguros (EEFF BS) | E34: =EEFF!E108 -> 36801772 | F34: =EEFF!F108 -> 35259752
A35: CHECK REINSURANCE_CONTRACT_BALANCE_TIE (Nota20 neto + (EEFF activo − EEFF pasivo), esperado 0; signos opuestos por convención) | E35: =E32+(E33-E34) -> 0 | F35: =F32+(F33-F34) -> 0
A37: NOT_DISCLOSED (no se inventa)
A38: Programas por reasegurador, comisiones de reaseguro por contrato, retenciones/PML por ramo: NOT_DISCLOSED en el filing.

Sheet Investments
A1: Grupo ASSA, S. A.
A2: Investments — portafolio por categoría (Nota 18) + acciones estratégicas y dividendos
A3: Fuente verbatim: INA_ASSA_2025_0.pdf p.120 (instrumentos financieros por categoria, 31-dic-2025) y tbl-58.md (31-dic-2024) ; INA_ASSA_2025_0.pdf p.121 (acciones estrategicas: valor razonable y dividendos reconocidos, 2025/2024) ; memo liquidez: INA_ASSA_2025_0.pdf (tbl-3: activos liquidos, miles de US$; indicador Activos Liquidos / Total de activos 83.0% FY25).
A5: Años | B5: FY21A | C5: FY22A | D5: FY23A | E5: FY24A | F5: FY25A | G5: FY26E | H5: FY27E | I5: FY28E | J5: FY29E | K5: FY30E
A7: A. PORTAFOLIO POR CATEGORÍA (columna Total de tbl-57/58; FY24-FY25 únicos años divulgados en esta base)
A8: Acciones patrimoniales | E8: 788615179 | F8: 978773593
A9: Fondos de inversión | E9: 56258011 | F9: 52810718
A10: Bonos privados | E10: 436643368 | F10: 493226637
A11: Bonos del gobierno | E11: 83908160 | F11: 100800146
A12: Depósitos a plazo | E12: 197274835 | F12: 211357691
A13: Reportos | E13: 2651825 | F13: 0
A14: Intereses acumulados por cobrar | E14: 5070745 | F14: 5872277
A15: Total instrumentos financieros (Σ categorías) | E15: =E8+E9+E10+E11+E12+E13+E14 -> 1570422123 | F15: =F8+F9+F10+F11+F12+F13+F14 -> 1842841062
A16: Total per filing (verbatim tbl-57/58) | E16: 1570422123 | F16: 1842841062
A17: Instrumentos financieros, neto (EEFF BS) | E17: =EEFF!E79 -> 1570422123 | F17: =EEFF!F79 -> 1842841062
A18: CHECK INVESTMENT_PORTFOLIO_TIE (Σ categorías − verbatim, y verbatim − EEFF BS; esperado 0) | E18: =(E15-E16)+(E16-E17) -> 0 | F18: =(F15-F16)+(F16-F17) -> 0
A19: Mix FY25: acciones patrimoniales ÷ total (memo) | F19: =F8/F15 -> 0.53112209
A21: B. ACCIONES ESTRATÉGICAS — VALOR RAZONABLE (tbl-61)
A22: Grupo Financiero BG, S. A. | E22: 405532999 | F22: 508921589
A23: MHC Holdings LTD | E23: 7524699 | F23: 6019890
A24: Empresa General de Inversiones | E24: 252381387 | F24: 320640492
A25: Copa Holdings, S. A. | E25: 2973814 | F25: 3584782
A26: Corporación de inversiones aéreas, S.A. | E26: 43617053 | F26: 57988044
A27: Entidad privada | E27: 1558012 | F27: 1635334
A28: CM Business Group | E28: 542659 | F28: 1212131
A29: Otras | E29: 15045532 | F29: 10121782
A30: BANPRO | E30: 50760781 | F30: 57924549
A31: Total valor razonable (Σ) | E31: =E22+E23+E24+E25+E26+E27+E28+E29+E30 -> 779936936 | F31: =F22+F23+F24+F25+F26+F27+F28+F29+F30 -> 968048593
A32: Total per filing (verbatim tbl-61; = VRORI acciones patrimoniales tbl-57) | E32: 779936936 | F32: 968048593
A33: CHECK STRATEGIC_EQUITY_FV_TIE (Σ − verbatim, esperado 0) | E33: =E31-E32 -> 0 | F33: =F31-F32 -> 0
A35: C. ACCIONES ESTRATÉGICAS — DIVIDENDOS RECONOCIDOS (tbl-61)
A36: Grupo Financiero BG, S. A. | E36: 19312221 | F36: 20990158
A37: MHC Holdings LTD | E37: 406551 | F37: 323095
A38: Empresa General de Inversiones | E38: 22636186 | F38: 24225072
A39: Copa Holdings, S. A. | E39: 29262 | F39: 0
A40: Corporación de inversiones aéreas, S.A. | E40: 4068000 | F40: 4446783
A41: Entidad privada | E41: 845950 | F41: 73640
A42: CM Business Group | E42: 191150 | F42: 64722
A43: Otras | E43: 1163893 | F43: 673709
A44: BANPRO | E44: 0 | F44: 1017428
...

Sheet Investment_Float
A1: Grupo ASSA, S. A.
A2: Investment_Float — base invertida, yield realizado y forecast de retorno (activos promedio × yield)
A3: Fuente: EEFF (mirror congelado) filas de inversiones/instrumentos y Retorno de las inversiones. Forecast: driver proxy documentado (LIMITED_HISTORY NIIF 17).
A5: Años | B5: FY21A | C5: FY22A | D5: FY23A | E5: FY24A | F5: FY25A | G5: FY26E | H5: FY27E | I5: FY28E | J5: FY29E | K5: FY30E
A7: A. BASE INVERTIDA (fin de período)
