Workbook

Sheet 00_Cover
A1: NEE | 9-of-10 Regated Public-Company Model | B1: NEE | 9-of-10 Regated Public-Company Model | C1: NEE | 9-of-10 Regated Public-Company Model | D1: NEE | 9-of-10 Regated Public-Company Model | E1: NEE | 9-of-10 Regated Public-Company Model | F1: NEE | 9-of-10 Regated Public-Company Model | G1: NEE | 9-of-10 Regated Public-Company Model | H1: NEE | 9-of-10 Regated Public-Company Model
A2: NextEra Energy, Inc. | Regulated utility + renewables / infrastructure | Controlled artifact-tool rebuild; independent certification remains outside owner scope. | B2: NextEra Energy, Inc. | Regulated utility + renewables / infrastructure | Controlled artifact-tool rebuild; independent certification remains outside owner scope. | C2: NextEra Energy, Inc. | Regulated utility + renewables / infrastructure | Controlled artifact-tool rebuild; independent certification remains outside owner scope. | D2: NextEra Energy, Inc. | Regulated utility + renewables / infrastructure | Controlled artifact-tool rebuild; independent certification remains outside owner scope. | E2: NextEra Energy, Inc. | Regulated utility + renewables / infrastructure | Controlled artifact-tool rebuild; independent certification remains outside owner scope. | F2: NextEra Energy, Inc. | Regulated utility + renewables / infrastructure | Controlled artifact-tool rebuild; independent certification remains outside owner scope. | G2: NextEra Energy, Inc. | Regulated utility + renewables / infrastructure | Controlled artifact-tool rebuild; independent certification remains outside owner scope. | H2: NextEra Energy, Inc. | Regulated utility + renewables / infrastructure | Controlled artifact-tool rebuild; independent certification remains outside owner scope.
A4: Company | B4: NextEra Energy, Inc.
A5: Ticker | B5: NEE
A6: Model as of | B6: 2025-12-31
A7: Currency | B7: USD millions unless stated
A8: Forecast horizon | B8: 2026E-2030E
A9: Active case | B9: =Assumptions!B4 -> Base
A10: Overall status | B10: =Checks!B4 -> PASS
A11: Primary valuation | B11: FPL / NEER / Corporate SOTP
A12: Market-price comparison | B12: Omitted — no independently refreshed exact-dated quote in this owner lane
A13: Debt definition | B13: LongTermDebtCurrent + LongTermDebtNoncurrent + CommercialPaper + OtherShortTermBorrowings + FinanceLeaseLiability.
A14: Cash policy | B14: Net debt deducts cash and cash equivalents only; restricted cash and nuclear decommissioning funds are excluded.
A15: Acquisition / perimeter | B15: The model keeps FPL and NEER economics separate and treats Corporate & Other as the residual to consolidated NEE. Filed USD values are not FX-restated.
A16: Known limitation | B16: Primary valuation is a segment SOTP using FPL and NEER earnings because a generic unlevered DCF obscures regulated rate-base, high-capex and financing economics. FCFF is retained only as a cross-check.
A19: Investor view: begin with operating drivers and the debt bridge, then assess valuation only after Checks!B4 passes. Gate_9of10 is owner preflight, not independent certification. | B19: Investor view: begin with operating drivers and the debt bridge, then assess valuation only after Checks!B4 passes. Gate_9of10 is owner preflight, not independent certification. | C19: Investor view: begin with operating drivers and the debt bridge, then assess valuation only after Checks!B4 passes. Gate_9of10 is owner preflight, not independent certification. | D19: Investor view: begin with operating drivers and the debt bridge, then assess valuation only after Checks!B4 passes. Gate_9of10 is owner preflight, not independent certification. | E19: Investor view: begin with operating drivers and the debt bridge, then assess valuation only after Checks!B4 passes. Gate_9of10 is owner preflight, not independent certification. | F19: Investor view: begin with operating drivers and the debt bridge, then assess valuation only after Checks!B4 passes. Gate_9of10 is owner preflight, not independent certification. | G19: Investor view: begin with operating drivers and the debt bridge, then assess valuation only after Checks!B4 passes. Gate_9of10 is owner preflight, not independent certification. | H19: Investor view: begin with operating drivers and the debt bridge, then assess valuation only after Checks!B4 passes. Gate_9of10 is owner preflight, not independent certification.

Sheet Sources
A1: NEE | Source and Transformation Ledger | B1: NEE | Source and Transformation Ledger | C1: NEE | Source and Transformation Ledger | D1: NEE | Source and Transformation Ledger | E1: NEE | Source and Transformation Ledger | F1: NEE | Source and Transformation Ledger | G1: NEE | Source and Transformation Ledger | H1: NEE | Source and Transformation Ledger | I1: NEE | Source and Transformation Ledger | J1: NEE | Source and Transformation Ledger | K1: NEE | Source and Transformation Ledger | L1: NEE | Source and Transformation Ledger | M1: NEE | Source and Transformation Ledger | N1: NEE | Source and Transformation Ledger | O1: NEE | Source and Transformation Ledger | P1: NEE | Source and Transformation Ledger | Q1: NEE | Source and Transformation Ledger
A2: Every material input identifies target, metric, period, filing metadata, retrieval date, exact URL, scale/sign transform and perimeter note. | B2: Every material input identifies target, metric, period, filing metadata, retrieval date, exact URL, scale/sign transform and perimeter note. | C2: Every material input identifies target, metric, period, filing metadata, retrieval date, exact URL, scale/sign transform and perimeter note. | D2: Every material input identifies target, metric, period, filing metadata, retrieval date, exact URL, scale/sign transform and perimeter note. | E2: Every material input identifies target, metric, period, filing metadata, retrieval date, exact URL, scale/sign transform and perimeter note. | F2: Every material input identifies target, metric, period, filing metadata, retrieval date, exact URL, scale/sign transform and perimeter note. | G2: Every material input identifies target, metric, period, filing metadata, retrieval date, exact URL, scale/sign transform and perimeter note. | H2: Every material input identifies target, metric, period, filing metadata, retrieval date, exact URL, scale/sign transform and perimeter note. | I2: Every material input identifies target, metric, period, filing metadata, retrieval date, exact URL, scale/sign transform and perimeter note. | J2: Every material input identifies target, metric, period, filing metadata, retrieval date, exact URL, scale/sign transform and perimeter note. | K2: Every material input identifies target, metric, period, filing metadata, retrieval date, exact URL, scale/sign transform and perimeter note. | L2: Every material input identifies target, metric, period, filing metadata, retrieval date, exact URL, scale/sign transform and perimeter note. | M2: Every material input identifies target, metric, period, filing metadata, retrieval date, exact URL, scale/sign transform and perimeter note. | N2: Every material input identifies target, metric, period, filing metadata, retrieval date, exact URL, scale/sign transform and perimeter note. | O2: Every material input identifies target, metric, period, filing metadata, retrieval date, exact URL, scale/sign transform and perimeter note. | P2: Every material input identifies target, metric, period, filing metadata, retrieval date, exact URL, scale/sign transform and perimeter note. | Q2: Every material input identifies target, metric, period, filing metadata, retrieval date, exact URL, scale/sign transform and perimeter note.
A4: Source ID | B4: Target | C4: Metric | D4: Value | E4: Units | F4: Period start | G4: Period end / as-of | H4: Taxonomy / tag | I4: Form | J4: Filed | K4: Accession | L4: Source title | M4: Source class | N4: Retrieved | O4: Exact URL | P4: Transform | Q4: Notes / perimeter
A5: SRC-001 | B5: Historical!C5 | C5: Revenue | D5: 28114 | E5: USD mm | F5: N/A | G5: 2025-12-31 | H5: Filed statements / debt footnote — fiscal 2023 — row: Revenue | I5: 10-K | J5: 2026-02-13 | K5: 0000753308-26-000015 | L5: NextEra Energy, Inc. 2025 Form 10-K | M5: Primary — SEC filed | N5: 2026-07-16 | O5: https://www.sec.gov/Archives/edgar/data/753308/000075330826000015/nee-20251231.htm | P5: Transcribed from filed table; USD values in millions unless stated | Q5: Direct 10-K value used when a single comparable Company Facts tag was not reliable.
A6: SRC-002 | B6: Historical!D5 | C6: Revenue | D6: 24753 | E6: USD mm | F6: N/A | G6: 2025-12-31 | H6: Filed statements / debt footnote — fiscal 2024 — row: Revenue | I6: 10-K | J6: 2026-02-13 | K6: 0000753308-26-000015 | L6: NextEra Energy, Inc. 2025 Form 10-K | M6: Primary — SEC filed | N6: 2026-07-16 | O6: https://www.sec.gov/Archives/edgar/data/753308/000075330826000015/nee-20251231.htm | P6: Transcribed from filed table; USD values in millions unless stated | Q6: Direct 10-K value used when a single comparable Company Facts tag was not reliable.
A7: SRC-003 | B7: Historical!E5 | C7: Revenue | D7: 27412 | E7: USD mm | F7: N/A | G7: 2025-12-31 | H7: Filed statements / debt footnote — fiscal 2025 — row: Revenue | I7: 10-K | J7: 2026-02-13 | K7: 0000753308-26-000015 | L7: NextEra Energy, Inc. 2025 Form 10-K | M7: Primary — SEC filed | N7: 2026-07-16 | O7: https://www.sec.gov/Archives/edgar/data/753308/000075330826000015/nee-20251231.htm | P7: Transcribed from filed table; USD values in millions unless stated | Q7: Direct 10-K value used when a single comparable Company Facts tag was not reliable.
A8: SRC-004 | B8: Historical!C6 | C8: Operating income (EBIT) | D8: 10237 | E8: USD mm | F8: 2023-01-01 | G8: 2023-12-31 | H8: us-gaap:OperatingIncomeLoss | I8: 10-K | J8: 2026-02-13 | K8: 0000753308-26-000015 | L8: NextEra Energy, Inc. Form 10-K / SEC Company Facts | M8: Primary — SEC filed | N8: 2026-07-16 | O8: https://data.sec.gov/api/xbrl/companyfacts/CIK0000753308.json | P8: Filed USD divided by 1,000,000; sign preserved | Q8: The model keeps FPL and NEER economics separate and treats Corporate & Other as the residual to consolidated NEE. Filed USD values are not FX-restated.
A9: SRC-005 | B9: Historical!D6 | C9: Operating income (EBIT) | D9: 7479 | E9: USD mm | F9: 2024-01-01 | G9: 2024-12-31 | H9: us-gaap:OperatingIncomeLoss | I9: 10-K | J9: 2026-02-13 | K9: 0000753308-26-000015 | L9: NextEra Energy, Inc. Form 10-K / SEC Company Facts | M9: Primary — SEC filed | N9: 2026-07-16 | O9: https://data.sec.gov/api/xbrl/companyfacts/CIK0000753308.json | P9: Filed USD divided by 1,000,000; sign preserved | Q9: The model keeps FPL and NEER economics separate and treats Corporate & Other as the residual to consolidated NEE. Filed USD values are not FX-restated.
A10: SRC-006 | B10: Historical!E6 | C10: Operating income (EBIT) | D10: 8280 | E10: USD mm | F10: 2025-01-01 | G10: 2025-12-31 | H10: us-gaap:OperatingIncomeLoss | I10: 10-K | J10: 2026-02-13 | K10: 0000753308-26-000015 | L10: NextEra Energy, Inc. Form 10-K / SEC Company Facts | M10: Primary — SEC filed | N10: 2026-07-16 | O10: https://data.sec.gov/api/xbrl/companyfacts/CIK0000753308.json | P10: Filed USD divided by 1,000,000; sign preserved | Q10: The model keeps FPL and NEER economics separate and treats Corporate & Other as the residual to consolidated NEE. Filed USD values are not FX-restated.
A11: SRC-007 | B11: Historical!C7 | C11: Net income | D11: 7310 | E11: USD mm | F11: 2023-01-01 | G11: 2023-12-31 | H11: us-gaap:NetIncomeLoss | I11: 10-K | J11: 2026-02-13 | K11: 0000753308-26-000015 | L11: NextEra Energy, Inc. Form 10-K / SEC Company Facts | M11: Primary — SEC filed | N11: 2026-07-16 | O11: https://data.sec.gov/api/xbrl/companyfacts/CIK0000753308.json | P11: Filed USD divided by 1,000,000; sign preserved | Q11: The model keeps FPL and NEER economics separate and treats Corporate & Other as the residual to consolidated NEE. Filed USD values are not FX-restated.
A12: SRC-008 | B12: Historical!D7 | C12: Net income | D12: 6946 | E12: USD mm | F12: 2024-01-01 | G12: 2024-12-31 | H12: us-gaap:NetIncomeLoss | I12: 10-K | J12: 2026-02-13 | K12: 0000753308-26-000015 | L12: NextEra Energy, Inc. Form 10-K / SEC Company Facts | M12: Primary — SEC filed | N12: 2026-07-16 | O12: https://data.sec.gov/api/xbrl/companyfacts/CIK0000753308.json | P12: Filed USD divided by 1,000,000; sign preserved | Q12: The model keeps FPL and NEER economics separate and treats Corporate & Other as the residual to consolidated NEE. Filed USD values are not FX-restated.
A13: SRC-009 | B13: Historical!E7 | C13: Net income | D13: 6835 | E13: USD mm | F13: 2025-01-01 | G13: 2025-12-31 | H13: us-gaap:NetIncomeLoss | I13: 10-K | J13: 2026-02-13 | K13: 0000753308-26-000015 | L13: NextEra Energy, Inc. Form 10-K / SEC Company Facts | M13: Primary — SEC filed | N13: 2026-07-16 | O13: https://data.sec.gov/api/xbrl/companyfacts/CIK0000753308.json | P13: Filed USD divided by 1,000,000; sign preserved | Q13: The model keeps FPL and NEER economics separate and treats Corporate & Other as the residual to consolidated NEE. Filed USD values are not FX-restated.
A14: SRC-010 | B14: Historical!C8 | C14: Cash from operations | D14: 11301 | E14: USD mm | F14: 2023-01-01 | G14: 2023-12-31 | H14: us-gaap:NetCashProvidedByUsedInOperatingActivities | I14: 10-K | J14: 2026-02-13 | K14: 0000753308-26-000015 | L14: NextEra Energy, Inc. Form 10-K / SEC Company Facts | M14: Primary — SEC filed | N14: 2026-07-16 | O14: https://data.sec.gov/api/xbrl/companyfacts/CIK0000753308.json | P14: Filed USD divided by 1,000,000; sign preserved | Q14: The model keeps FPL and NEER economics separate and treats Corporate & Other as the residual to consolidated NEE. Filed USD values are not FX-restated.
A15: SRC-011 | B15: Historical!D8 | C15: Cash from operations | D15: 13260 | E15: USD mm | F15: 2024-01-01 | G15: 2024-12-31 | H15: us-gaap:NetCashProvidedByUsedInOperatingActivities | I15: 10-K | J15: 2026-02-13 | K15: 0000753308-26-000015 | L15: NextEra Energy, Inc. Form 10-K / SEC Company Facts | M15: Primary — SEC filed | N15: 2026-07-16 | O15: https://data.sec.gov/api/xbrl/companyfacts/CIK0000753308.json | P15: Filed USD divided by 1,000,000; sign preserved | Q15: The model keeps FPL and NEER economics separate and treats Corporate & Other as the residual to consolidated NEE. Filed USD values are not FX-restated.
A16: SRC-012 | B16: Historical!E8 | C16: Cash from operations | D16: 12485 | E16: USD mm | F16: 2025-01-01 | G16: 2025-12-31 | H16: us-gaap:NetCashProvidedByUsedInOperatingActivities | I16: 10-K | J16: 2026-02-13 | K16: 0000753308-26-000015 | L16: NextEra Energy, Inc. Form 10-K / SEC Company Facts | M16: Primary — SEC filed | N16: 2026-07-16 | O16: https://data.sec.gov/api/xbrl/companyfacts/CIK0000753308.json | P16: Filed USD divided by 1,000,000; sign preserved | Q16: The model keeps FPL and NEER economics separate and treats Corporate & Other as the residual to consolidated NEE. Filed USD values are not FX-restated.
... A112: SRC-108 | B112: Assumptions!E27 | C112: Capital plan debt-funding share — Bull | D112: 0.45 | E112: % | F112: N/A | G112: N/A | H112: Model assumption | I112: N/A | J112: N/A | K112: N/A | L112: NEE scenario framework | M112: Model judgment | N112: 2026-07-16 | O112: https://www.sec.gov/Archives/edgar/data/753308/000075330826000015/nee-20251231.htm | P112: Scenario calibration | Q112: Financing mix disclosure; diagnostic rather than a cash plug.
A113: SRC-109 | B113: Sector_KPIs!E5:E12 | C113: FPL / NEER segment revenue and net income | D113: See cells | E113: USD mm | F113: N/A | G113: 2025-12-31 | H113: Item 7 MD&A — FPL Results of Operations and NEER Results of Operations tables — rows: Operating revenues / Net income — 2025 column | I113: 10-K | J113: 2026-02-13 | K113: 0000753308-26-000015 | L113: NextEra Energy, Inc. 2025 Form 10-K | M113: Primary — SEC filed | N113: 2026-07-16 | O113: https://www.sec.gov/Archives/edgar/data/753308/000075330826000015/nee-20251231.htm | P113: Transcribed from filed table; USD values in millions unless stated | Q113: The model keeps FPL and NEER economics separate and treats Corporate & Other as the residual to consolidated NEE. Filed USD values are not FX-restated.
A114: SRC-110 | B114: Sector_KPIs!F18:J19 | C114: 2026-2030 FPL and NEER filed capital plan | D114: See cells | E114: USD mm | F114: N/A | G114: 2025-12-31 | H114: Item 7 Liquidity and Capital Resources — Capital Expenditures and Other Investments table — rows: FPL / NEER — columns 2026-2030 | I114: 10-K | J114: 2026-02-13 | K114: 0000753308-26-000015 | L114: NextEra Energy, Inc. 2025 Form 10-K | M114: Primary — SEC filed | N114: 2026-07-16 | O114: https://www.sec.gov/Archives/edgar/data/753308/000075330826000015/nee-20251231.htm | P114: Transcribed from filed table; USD values in millions unless stated | Q114: Base capital plan transcribed from filed 10-K tables.
A115: SRC-111 | B115: Sector_KPIs!E13:E17 | C115: Rate base and capacity additions | D115: See cells | E115: USD mm / MW | F115: N/A | G115: 2025-12-31 | H115: Item 7 MD&A — FPL rate base and NEER operating highlights — rows: average rate base increase / wind / solar / battery storage additions — 2025 | I115: 10-K | J115: 2026-02-13 | K115: 0000753308-26-000015 | L115: NextEra Energy, Inc. 2025 Form 10-K | M115: Primary — SEC filed | N115: 2026-07-16 | O115: https://www.sec.gov/Archives/edgar/data/753308/000075330826000015/nee-20251231.htm | P115: Transcribed from filed table; USD values in millions unless stated | Q115: 2025 operating milestones; backlog addition separately cross-checked to the 2026 proxy.
A116: SRC-112 | B116: Sector_KPIs!E17 | C116: Renewables and storage backlog additions | D116: 13500 | E116: MW | F116: 2025-01-01 | G116: 2025-12-31 | H116: 2026 Proxy — clean energy backlog discussion — 13.5 GW added during 2025 | I116: DEF 14A | J116: 2026 | K116: Company IR proxy PDF | L116: NextEra Energy 2026 Proxy Statement | M116: Primary — company IR | N116: 2026-07-16 | O116: https://www.investor.nexteraenergy.com/~/media/Files/N/NEE-IR/2026%20Proxy.pdf | P116: 13.5 GW multiplied by 1,000 to MW | Q116: Cross-check for NEER growth case; not a standalone revenue input.
A117: SRC-113 | B117: Historical / Valuation | C117: Debt definition | D117: LongTermDebtCurrent + LongTermDebtNoncurrent + CommercialPaper + OtherShortTermBorrowings + FinanceLeaseLiability. | E117: Policy | F117: N/A | G117: 2025-12-31 | H117: Accounting policy | I117: 10-K | J117: 2026-02-13 | K117: 0000753308-26-000015 | L117: NextEra Energy, Inc. 2025 Form 10-K | M117: Primary — SEC filed | N117: 2026-07-16 | O117: https://www.sec.gov/Archives/edgar/data/753308/000075330826000015/nee-20251231.htm | P117: Explicit sum of filed debt components | Q117: Net debt deducts cash and cash equivalents only; restricted cash and nuclear decommissioning funds are excluded.
A118: SRC-114 | B118: Entire model | C118: Acquisition / perimeter note | D118: The model keeps FPL and NEER economics separate and treats Corporate & Other as the residual to consolidated NEE. Filed USD values are not FX-restated. | E118: Policy | F118: N/A | G118: 2025-12-31 | H118: Perimeter policy | I118: 10-K | J118: 2026-02-13 | K118: 0000753308-26-000015 | L118: NextEra Energy, Inc. 2025 Form 10-K | M118: Primary — SEC filed | N118: 2026-07-16 | O118: https://www.sec.gov/Archives/edgar/data/753308/000075330826000015/nee-20251231.htm | P118: No current-FX restatement; filed values preserved | Q118: Primary valuation is a segment SOTP using FPL and NEER earnings because a generic unlevered DCF obscures regulated rate-base, high-capex and financing economics. FCFF is retained only as a cross-check.

Sheet Historical
A1: NEE | Historical Financials | B1: NEE | Historical Financials | C1: NEE | Historical Financials | D1: NEE | Historical Financials | E1: NEE | Historical Financials | F1: NEE | Historical Financials | G1: NEE | Historical Financials | H1: NEE | Historical Financials | I1: NEE | Historical Financials
A2: Filed values and explicit debt bridge. USD in millions except per-share and share-count data. | B2: Filed values and explicit debt bridge. USD in millions except per-share and share-count data. | C2: Filed values and explicit debt bridge. USD in millions except per-share and share-count data. | D2: Filed values and explicit debt bridge. USD in millions except per-share and share-count data. | E2: Filed values and explicit debt bridge. USD in millions except per-share and share-count data. | F2: Filed values and explicit debt bridge. USD in millions except per-share and share-count data. | G2: Filed values and explicit debt bridge. USD in millions except per-share and share-count data. | H2: Filed values and explicit debt bridge. USD in millions except per-share and share-count data. | I2: Filed values and explicit debt bridge. USD in millions except per-share and share-count data.
A4: Metric | B4: Units | C4: 2023A | D4: 2024A | E4: 2025A | F4: Source definition | G4: Source IDs | H4: Policy / transform | I4: Quality
A5: Revenue | B5: USD mm | C5: 28114 | D5: 24753 | E5: 27412 | F5: SEC Company Facts / filed 10-K; Revenues or Revenues or SalesRevenueNet | G5: SRC-001, SRC-002, SRC-003 | H5: Filed USD; no FX restatement; sign preserved. | I5: Filed
A6: Operating income (EBIT) | B6: USD mm | C6: 10237 | D6: 7479 | E6: 8280 | F6: SEC Company Facts / filed 10-K; OperatingIncomeLoss | G6: SRC-004, SRC-005, SRC-006 | H6: Filed USD; no FX restatement; sign preserved. | I6: Filed
A7: Net income | B7: USD mm | C7: 7310 | D7: 6946 | E7: 6835 | F7: SEC Company Facts / filed 10-K; NetIncomeLoss or ProfitLoss | G7: SRC-007, SRC-008, SRC-009 | H7: Filed USD; no FX restatement; sign preserved. | I7: Filed
A8: Cash from operations | B8: USD mm | C8: 11301 | D8: 13260 | E8: 12485 | F8: SEC Company Facts / filed 10-K; NetCashProvidedByUsedInOperatingActivities | G8: SRC-010, SRC-011, SRC-012 | H8: Filed USD; no FX restatement; sign preserved. | I8: Filed
A9: Depreciation & amortization | B9: USD mm | C9: 5879 | D9: 5462 | E9: 6580 | F9: SEC Company Facts / filed 10-K; DepreciationAndAmortization or DepreciationDepletionAndAmortization or DepreciationAndAmortization | G9: SRC-013, SRC-014, SRC-015 | H9: Filed USD; no FX restatement; sign preserved. | I9: Filed
A10: Cash capex / P&E additions | B10: USD mm | C10: 25113 | D10: 24729 | E10: 24606 | F10: SEC Company Facts / filed 10-K; PaymentsToAcquirePropertyPlantAndEquipment or PaymentsForAdditionsToPropertyPlantAndEquipment | G10: SRC-016, SRC-017, SRC-018 | H10: Filed USD; no FX restatement; sign preserved. | I10: Filed
A11: Total assets | B11: USD mm | C11: 177489 | D11: 190144 | E11: 212721 | F11: SEC Company Facts / filed 10-K; Assets | G11: SRC-019, SRC-020, SRC-021 | H11: Filed USD; no FX restatement; sign preserved. | I11: Filed
A12: Stockholders' equity | B12: USD mm | C12: 47468 | D12: 50101 | E12: 54608 | F12: SEC Company Facts / filed 10-K; StockholdersEquity or StockholdersEquityIncludingPortionAttributableToNoncontrollingInterest | G12: SRC-022, SRC-023, SRC-024 | H12: Filed USD; no FX restatement; sign preserved. | I12: Filed
A13: Cash & cash equivalents | B13: USD mm | C13: 2690 | D13: 1487 | E13: 2812 | F13: SEC Company Facts / filed 10-K; CashAndCashEquivalentsAtCarryingValue or CashCashEquivalentsRestrictedCashAndRestrictedCashEquivalents | G13: SRC-025, SRC-026, SRC-027 | H13: Filed USD; no FX restatement; sign preserved. | I13: Filed
A14: Long-term debt | B14: USD mm | C14: 68306 | D14: 80446 | E14: 93056 | F14: SEC Company Facts / filed 10-K; LongTermDebt or LongTermDebtAndCapitalLeaseObligationsIncludingCurrentMaturities | G14: SRC-029, SRC-031, SRC-033 | H14: LongTermDebtCurrent + LongTermDebtNoncurrent + CommercialPaper + OtherShortTermBorrowings + FinanceLeaseLiability. | I14: Filed
A15: Short-term borrowings | B15: USD mm | C15: 4905 | D15: 1887 | E15: 2563 | F15: SEC Company Facts / filed 10-K; ShortTermBorrowings or CommercialPaper | G15: SRC-035, SRC-037, SRC-039 | H15: LongTermDebtCurrent + LongTermDebtNoncurrent + CommercialPaper + OtherShortTermBorrowings + FinanceLeaseLiability. | I15: Filed
A16: Finance lease liability | B16: USD mm | C16: 444 | D16: 840 | E16: 1143 | F16: SEC Company Facts / filed 10-K; FinanceLeaseLiability | G16: SRC-040, SRC-041, SRC-042 | H16: LongTermDebtCurrent + LongTermDebtNoncurrent + CommercialPaper + OtherShortTermBorrowings + FinanceLeaseLiability. | I16: Filed
A17: Diluted weighted-average shares | B17: mm shares | C17: 2030.8 | D17: 2059.2 | E17: 2070.6 | F17: SEC Company Facts / filed 10-K; WeightedAverageNumberOfDilutedSharesOutstanding | G17: SRC-043, SRC-044, SRC-045 | H17: Filed USD; no FX restatement; sign preserved. | I17: Filed
A18: Total debt | B18: USD mm | C18: =C14+C15+C16 -> 73655 | D18: =D14+D15+D16 -> 83173 | E18: =E14+E15+E16 -> 96762 | F18: LongTermDebtCurrent + LongTermDebtNoncurrent + CommercialPaper + OtherShortTermBorrowings + FinanceLeaseLiability. | G18: Formula | H18: LongTermDebtCurrent + LongTermDebtNoncurrent + CommercialPaper + OtherShortTermBorrowings + FinanceLeaseLiability. | I18: Modeled
A19: Net debt | B19: USD mm | C19: =C18-C13 -> 70965 | D19: =D18-D13 -> 81686 | E19: =E18-E13 -> 93950 | F19: Total debt less cash and cash equivalents | G19: Formula | H19: Net debt deducts cash and cash equivalents only; restricted cash and nuclear decommissioning funds are excluded. | I19: Modeled
A21: Debt policy | B21: LongTermDebtCurrent + LongTermDebtNoncurrent + CommercialPaper + OtherShortTermBorrowings + FinanceLeaseLiability.
A22: Cash policy | B22: Net debt deducts cash and cash equivalents only; restricted cash and nuclear decommissioning funds are excluded.
A23: Perimeter | B23: The model keeps FPL and NEER economics separate and treats Corporate & Other as the residual to consolidated NEE. Filed USD values are not FX-restated.

Sheet Assumptions
A1: NEE | Scenario Assumptions | B1: NEE | Scenario Assumptions | C1: NEE | Scenario Assumptions | D1: NEE | Scenario Assumptions | E1: NEE | Scenario Assumptions | F1: NEE | Scenario Assumptions | G1: NEE | Scenario Assumptions
A2: Blue cells are inputs; green cells are links/formulas. Selector 1=Base, 2=Bull, 3=Bear. | B2: Blue cells are inputs; green cells are links/formulas. Selector 1=Base, 2=Bull, 3=Bear. | C2: Blue cells are inputs; green cells are links/formulas. Selector 1=Base, 2=Bull, 3=Bear. | D2: Blue cells are inputs; green cells are links/formulas. Selector 1=Base, 2=Bull, 3=Bear. | E2: Blue cells are inputs; green cells are links/formulas. Selector 1=Base, 2=Bull, 3=Bear. | F2: Blue cells are inputs; green cells are links/formulas. Selector 1=Base, 2=Bull, 3=Bear. | G2: Blue cells are inputs; green cells are links/formulas. Selector 1=Base, 2=Bull, 3=Bear.
A3: Scenario selector | B3: 1
A4: Active case | B4: =CHOOSE(B3,"Base","Bull","Bear") -> Base
A6: Driver | B6: Units | C6: Bear | D6: Base | E6: Bull | F6: Active | G6: Rationale / calibration
A7: FPL revenue growth | B7: % / year | C7: 0.03 | D7: 0.05 | E7: 0.07 | F7: =CHOOSE($B$3,D7,E7,C7) -> 0.05 | G7: Regulated load, rate-base investment and approved rate outcomes.
A8: NEER revenue growth | B8: % / year | C8: 0.02 | D8: 0.06 | E8: 0.1 | F8: =CHOOSE($B$3,D8,E8,C8) -> 0.06 | G8: New wind, solar, storage and transmission investment.
A9: Corporate / eliminations revenue growth | B9: % / year | C9: 0 | D9: 0.02 | E9: 0.04 | F9: =CHOOSE($B$3,D9,E9,C9) -> 0.02 | G9: Residual consolidated revenue assumption.
A10: FPL net income growth | B10: % / year | C10: 0.06 | D10: 0.09 | E10: 0.11 | F10: =CHOOSE($B$3,D10,E10,C10) -> 0.09 | G10: Anchored to $5.5bn 2025 average rate-base growth and the 2026-2030 capital plan.
A11: NEER net income growth | B11: % / year | C11: 0.02 | D11: 0.08 | E11: 0.12 | F11: =CHOOSE($B$3,D11,E11,C11) -> 0.08 | G11: Anchored to new capacity, backlog and capital deployment.
A12: Corporate & Other cost growth | B12: % / year | C12: 0.05 | D12: 0.02 | E12: 0 | F12: =CHOOSE($B$3,D12,E12,C12) -> 0.02 | G12: Corporate/financing cost sensitivity.
A13: FPL capital-plan multiplier | B13: x | C13: 1.1 | D13: 1 | E13: 0.95 | F13: =CHOOSE($B$3,D13,E13,C13) -> 1 | G13: Scenario overlay on the filed 2026-2030 capital plan.
A14: NEER capital-plan multiplier | B14: x | C14: 1.1 | D14: 1 | E14: 0.95 | F14: =CHOOSE($B$3,D14,E14,C14) -> 1 | G14: Scenario overlay on the filed 2026-2030 capital plan.
A15: Consolidated EBIT margin | B15: % | C15: 0.25 | D15: 0.302 | E15: 0.33 | F15: =CHOOSE($B$3,D15,E15,C15) -> 0.302 | G15: FCFF cross-check assumption; not the primary valuation driver.
A16: D&A as % revenue | B16: % | C16: 0.25 | D16: 0.24 | E16: 0.23 | F16: =CHOOSE($B$3,D16,E16,C16) -> 0.24 | G16: Anchored to 2025 SEC D&A / revenue.
A17: Cash tax rate | B17: % | C17: 0.16 | D17: 0.14 | E17: 0.12 | F17: =CHOOSE($B$3,D17,E17,C17) -> 0.14 | G17: Utility/renewables tax-credit-sensitive normalized assumption.
A18: NWC investment / change in revenue | B18: % | C18: 0.02 | D18: 0.01 | E18: 0.005 | F18: =CHOOSE($B$3,D18,E18,C18) -> 0.01 | G18: FCFF cross-check assumption.
... A27: Capital plan debt-funding share | B27: % | C27: 0.65 | D27: 0.55 | E27: 0.45 | F27: =CHOOSE($B$3,D27,E27,C27) -> 0.55 | G27: Financing mix disclosure; diagnostic rather than a cash plug.
A29: Debt definition | B29: LongTermDebtCurrent + LongTermDebtNoncurrent + CommercialPaper + OtherShortTermBorrowings + FinanceLeaseLiability.
A30: Cash policy | B30: Net debt deducts cash and cash equivalents only; restricted cash and nuclear decommissioning funds are excluded.
A31: Known limitation | B31: Primary valuation is a segment SOTP using FPL and NEER earnings because a generic unlevered DCF obscures regulated rate-base, high-capex and financing economics. FCFF is retained only as a cross-check.

Sheet Forecast
A1: NEE | Integrated Forecast | B1: NEE | Integrated Forecast | C1: NEE | Integrated Forecast | D1: NEE | Integrated Forecast | E1: NEE | Integrated Forecast | F1: NEE | Integrated Forecast | G1: NEE | Integrated Forecast
A2: FCFF is a financing-sensitive cross-check only; SOTP is the primary valuation. | B2: FCFF is a financing-sensitive cross-check only; SOTP is the primary valuation. | C2: FCFF is a financing-sensitive cross-check only; SOTP is the primary valuation. | D2: FCFF is a financing-sensitive cross-check only; SOTP is the primary valuation. | E2: FCFF is a financing-sensitive cross-check only; SOTP is the primary valuation. | F2: FCFF is a financing-sensitive cross-check only; SOTP is the primary valuation. | G2: FCFF is a financing-sensitive cross-check only; SOTP is the primary valuation.
A4: Metric | B4: Units | C4: 2026E | D4: 2027E | E4: 2028E | F4: 2029E | G4: 2030E
A5: Revenue | B5: USD mm | C5: =Sector_KPIs!F8 -> 28858.5 | D5: =Sector_KPIs!G8 -> 30382.347 | E5: =Sector_KPIs!H8 -> 31987.719 | F5: =Sector_KPIs!I8 -> 33679.022 | G5: =Sector_KPIs!J8 -> 35460.901
A6: Operating cash earnings proxy | B6: USD mm | C6: =Sector_KPIs!F12 -> 7501.04 | D6: =Sector_KPIs!G12 -> 8226.2564 | E6: =Sector_KPIs!H12 -> 9015.8169 | F6: =Sector_KPIs!I12 -> 9875.3398 | G6: =Sector_KPIs!J12 -> 10810.933
A7: Depreciation & amortization | B7: USD mm | C7: =C5*Assumptions!$F$16 -> 6926.04 | D7: =D5*Assumptions!$F$16 -> 7291.7633 | E7: =E5*Assumptions!$F$16 -> 7677.0526 | F7: =F5*Assumptions!$F$16 -> 8082.9652 | G7: =G5*Assumptions!$F$16 -> 8510.6164
A8: EBIT | B8: USD mm | C8: =C5*Assumptions!$F$15 -> 8715.267 | D8: =D5*Assumptions!$F$15 -> 9175.4688 | E8: =E5*Assumptions!$F$15 -> 9660.2911 | F8: =F5*Assumptions!$F$15 -> 10171.065 | G8: =G5*Assumptions!$F$15 -> 10709.192
A9: Cash taxes | B9: USD mm | C9: =MAX(0,C8*Assumptions!$F$17) -> 1220.1374 | D9: =MAX(0,D8*Assumptions!$F$17) -> 1284.5656 | E9: =MAX(0,E8*Assumptions!$F$17) -> 1352.4408 | F9: =MAX(0,F8*Assumptions!$F$17) -> 1423.949 | G9: =MAX(0,G8*Assumptions!$F$17) -> 1499.2869
A10: NOPAT | B10: USD mm | C10: =C8-C9 -> 7495.1296 | D10: =D8-D9 -> 7890.9032 | E10: =E8-E9 -> 8307.8504 | F10: =F8-F9 -> 8747.1156 | G10: =G8-G9 -> 9209.9053
A11: D&A add-back | B11: USD mm | C11: =C7 -> 6926.04 | D11: =D7 -> 7291.7633 | E11: =E7 -> 7677.0526 | F11: =F7 -> 8082.9652 | G11: =G7 -> 8510.6164
A12: Capital expenditures | B12: USD mm | C12: =Sector_KPIs!F22 -> 27565 | D12: =Sector_KPIs!G22 -> 21600 | E12: =Sector_KPIs!H22 -> 16720 | F12: =Sector_KPIs!I22 -> 14025 | G12: =Sector_KPIs!J22 -> 14275
A13: Change in net working capital | B13: USD mm | C13: =MAX(0,(Sector_KPIs!F8-Sector_KPIs!E8)*Assumptions!$F$18) -> 14.465 | D13: =MAX(0,(Sector_KPIs!G8-Sector_KPIs!F8)*Assumptions!$F$18) -> 15.23847 | E13: =MAX(0,(Sector_KPIs!H8-Sector_KPIs!G8)*Assumptions!$F$18) -> 16.05372 | F13: =MAX(0,(Sector_KPIs!I8-Sector_KPIs!H8)*Assumptions!$F$18) -> 16.913028 | G13: =MAX(0,(Sector_KPIs!J8-Sector_KPIs!I8)*Assumptions!$F$18) -> 17.818796
A14: FCFF | B14: USD mm | C14: =C10+C11-C12-C13 -> -13158.295 | D14: =D10+D11-D12-D13 -> -6432.572 | E14: =E10+E11-E12-E13 -> -751.15077 | F14: =F10+F11-F12-F13 -> 2788.1678 | G14: =G10+G11-G12-G13 -> 3427.7029
A15: FCFF margin | B15: % | C15: =IFERROR(C14/C5,0) -> -0.45595909 | D15: =IFERROR(D14/D5,0) -> -0.21172071 | E15: =IFERROR(E14/E5,0) -> -0.023482474 | F15: =IFERROR(F14/F5,0) -> 0.082786483 | G15: =IFERROR(G14/G5,0) -> 0.096661471
A18: Primary valuation remains FPL/NEER/Corporate SOTP; negative FCFF is expected under the filed capital plan and is not treated as model failure. | B18: Primary valuation remains FPL/NEER/Corporate SOTP; negative FCFF is expected under the filed capital plan and is not treated as model failure. | C18: Primary valuation remains FPL/NEER/Corporate SOTP; negative FCFF is expected under the filed capital plan and is not treated as model failure. | D18: Primary valuation remains FPL/NEER/Corporate SOTP; negative FCFF is expected under the filed capital plan and is not treated as model failure. | E18: Primary valuation remains FPL/NEER/Corporate SOTP; negative FCFF is expected under the filed capital plan and is not treated as model failure. | F18: Primary valuation remains FPL/NEER/Corporate SOTP; negative FCFF is expected under the filed capital plan and is not treated as model failure. | G18: Primary valuation remains FPL/NEER/Corporate SOTP; negative FCFF is expected under the filed capital plan and is not treated as model failure.

Sheet Valuation
A1: NEE | Segment SOTP Valuation | B1: NEE | Segment SOTP Valuation | C1: NEE | Segment SOTP Valuation | D1: NEE | Segment SOTP Valuation | E1: NEE | Segment SOTP Valuation | F1: NEE | Segment SOTP Valuation
A2: Primary method: capitalize 2026E FPL, NEER and Corporate & Other earnings separately; DDM is an equity cross-check. | B2: Primary method: capitalize 2026E FPL, NEER and Corporate & Other earnings separately; DDM is an equity cross-check. | C2: Primary method: capitalize 2026E FPL, NEER and Corporate & Other earnings separately; DDM is an equity cross-check. | D2: Primary method: capitalize 2026E FPL, NEER and Corporate & Other earnings separately; DDM is an equity cross-check. | E2: Primary method: capitalize 2026E FPL, NEER and Corporate & Other earnings separately; DDM is an equity cross-check. | F2: Primary method: capitalize 2026E FPL, NEER and Corporate & Other earnings separately; DDM is an equity cross-check.
A4: Component | B4: 2026E earnings | C4: Active multiple | D4: Equity value | E4: Source / rationale | F4: Quality
A5: FPL | B5: =Sector_KPIs!F9 -> 5463.08 | C5: =Assumptions!$F$19 -> 20 | D5: =B5*C5 -> 109261.6 | E5: Regulated-utility earnings / P-E | F5: Formula
A6: NEER | B6: =Sector_KPIs!F10 -> 3213 | C6: =Assumptions!$F$20 -> 22 | D6: =B6*C6 -> 70686 | E6: Renewables and infrastructure earnings / P-E | F6: Formula
A7: Corporate & Other | B7: =Sector_KPIs!F11 -> -1175.04 | C7: =Assumptions!$F$21 -> 15 | D7: =B7*C7 -> -17625.6 | E7: Corporate / financing residual / P-E | F7: Formula
A9: SOTP equity value | B9: =SUM(D5:D7) -> 162322
A10: 2026E diluted shares | B10: =Sector_KPIs!F23 -> 2080.953
A11: SOTP value / share | B11: =IFERROR(B9/B10,0) -> 78.003684
A12: Market-price comparison | B12: Omitted
A13: Reason | B13: No independently refreshed exact-dated quote was obtained in the controlled owner lane.
A14: 2026E dividend / share | B14: =Sector_KPIs!F24 -> 2.4516
A15: DDM value / share | B15: =IFERROR(B14/(Assumptions!$F$23-Assumptions!$F$24),0) -> 61.29
A16: DDM premium / (discount) to SOTP | B16: =IFERROR(B15/B11-1,0) -> -0.21426788
A29: Valuation date / horizon | B29: Filed FY2025 actuals with an explicit 2026E-2030E forecast; terminal value is measured at 2030E and discounted to the valuation date.
A30: Debt / cash policy | B30: LongTermDebtCurrent + LongTermDebtNoncurrent + CommercialPaper + OtherShortTermBorrowings + FinanceLeaseLiability. Net debt deducts cash and cash equivalents only; restricted cash and nuclear decommissioning funds are excluded.
A31: Share-count basis | B31: 2026E diluted shares roll forward from FY2025 diluted weighted-average shares; 2,083.522 mm shares outstanding at January 31, 2026 is disclosed separately in Sources.

Sheet Sensitivity
A1: NEE | SOTP Sensitivity | B1: NEE | SOTP Sensitivity | C1: NEE | SOTP Sensitivity | D1: NEE | SOTP Sensitivity | E1: NEE | SOTP Sensitivity | F1: NEE | SOTP Sensitivity | G1: NEE | SOTP Sensitivity | H1: NEE | SOTP Sensitivity
A2: Value per share across FPL and NEER forward P/E assumptions; Corporate & Other multiple remains at active case. | B2: Value per share across FPL and NEER forward P/E assumptions; Corporate & Other multiple remains at active case. | C2: Value per share across FPL and NEER forward P/E assumptions; Corporate & Other multiple remains at active case. | D2: Value per share across FPL and NEER forward P/E assumptions; Corporate & Other multiple remains at active case. | E2: Value per share across FPL and NEER forward P/E assumptions; Corporate & Other multiple remains at active case. | F2: Value per share across FPL and NEER forward P/E assumptions; Corporate & Other multiple remains at active case. | G2: Value per share across FPL and NEER forward P/E assumptions; Corporate & Other multiple remains at active case. | H2: Value per share across FPL and NEER forward P/E assumptions; Corporate & Other multiple remains at active case.
A4: NEER P/E → / FPL P/E ↓ | B4: =Assumptions!$F$20+-4 -> 18 | C4: =Assumptions!$F$20+-2 -> 20 | D4: =Assumptions!$F$20+0 -> 22 | E4: =Assumptions!$F$20+2 -> 24 | F4: =Assumptions!$F$20+4 -> 26 | G4: Base value / share | H4: =Valuation!B11 -> 78.003684
A5: =Assumptions!$F$19+-4 -> 16 | B5: =IFERROR((Sector_KPIs!F9*$A5+Sector_KPIs!F10*B$4+Sector_KPIs!F11*Assumptions!$F$21)/Sector_KPIs!F23,0) -> 61.326556 | C5: =IFERROR((Sector_KPIs!F9*$A5+Sector_KPIs!F10*C$4+Sector_KPIs!F11*Assumptions!$F$21)/Sector_KPIs!F23,0) -> 64.414564 | D5: =IFERROR((Sector_KPIs!F9*$A5+Sector_KPIs!F10*D$4+Sector_KPIs!F11*Assumptions!$F$21)/Sector_KPIs!F23,0) -> 67.502572 | E5: =IFERROR((Sector_KPIs!F9*$A5+Sector_KPIs!F10*E$4+Sector_KPIs!F11*Assumptions!$F$21)/Sector_KPIs!F23,0) -> 70.59058 | F5: =IFERROR((Sector_KPIs!F9*$A5+Sector_KPIs!F10*F$4+Sector_KPIs!F11*Assumptions!$F$21)/Sector_KPIs!F23,0) -> 73.678589
A6: =Assumptions!$F$19+-2 -> 18 | B6: =IFERROR((Sector_KPIs!F9*$A6+Sector_KPIs!F10*B$4+Sector_KPIs!F11*Assumptions!$F$21)/Sector_KPIs!F23,0) -> 66.577112 | C6: =IFERROR((Sector_KPIs!F9*$A6+Sector_KPIs!F10*C$4+Sector_KPIs!F11*Assumptions!$F$21)/Sector_KPIs!F23,0) -> 69.66512 | D6: =IFERROR((Sector_KPIs!F9*$A6+Sector_KPIs!F10*D$4+Sector_KPIs!F11*Assumptions!$F$21)/Sector_KPIs!F23,0) -> 72.753128 | E6: =IFERROR((Sector_KPIs!F9*$A6+Sector_KPIs!F10*E$4+Sector_KPIs!F11*Assumptions!$F$21)/Sector_KPIs!F23,0) -> 75.841136 | F6: =IFERROR((Sector_KPIs!F9*$A6+Sector_KPIs!F10*F$4+Sector_KPIs!F11*Assumptions!$F$21)/Sector_KPIs!F23,0) -> 78.929144
A7: =Assumptions!$F$19+0 -> 20 | B7: =IFERROR((Sector_KPIs!F9*$A7+Sector_KPIs!F10*B$4+Sector_KPIs!F11*Assumptions!$F$21)/Sector_KPIs!F23,0) -> 71.827667 | C7: =IFERROR((Sector_KPIs!F9*$A7+Sector_KPIs!F10*C$4+Sector_KPIs!F11*Assumptions!$F$21)/Sector_KPIs!F23,0) -> 74.915676 | D7: =IFERROR((Sector_KPIs!F9*$A7+Sector_KPIs!F10*D$4+Sector_KPIs!F11*Assumptions!$F$21)/Sector_KPIs!F23,0) -> 78.003684 | E7: =IFERROR((Sector_KPIs!F9*$A7+Sector_KPIs!F10*E$4+Sector_KPIs!F11*Assumptions!$F$21)/Sector_KPIs!F23,0) -> 81.091692 | F7: =IFERROR((Sector_KPIs!F9*$A7+Sector_KPIs!F10*F$4+Sector_KPIs!F11*Assumptions!$F$21)/Sector_KPIs!F23,0) -> 84.1797
A8: =Assumptions!$F$19+2 -> 22 | B8: =IFERROR((Sector_KPIs!F9*$A8+Sector_KPIs!F10*B$4+Sector_KPIs!F11*Assumptions!$F$21)/Sector_KPIs!F23,0) -> 77.078223 | C8: =IFERROR((Sector_KPIs!F9*$A8+Sector_KPIs!F10*C$4+Sector_KPIs!F11*Assumptions!$F$21)/Sector_KPIs!F23,0) -> 80.166232 | D8: =IFERROR((Sector_KPIs!F9*$A8+Sector_KPIs!F10*D$4+Sector_KPIs!F11*Assumptions!$F$21)/Sector_KPIs!F23,0) -> 83.25424 | E8: =IFERROR((Sector_KPIs!F9*$A8+Sector_KPIs!F10*E$4+Sector_KPIs!F11*Assumptions!$F$21)/Sector_KPIs!F23,0) -> 86.342248 | F8: =IFERROR((Sector_KPIs!F9*$A8+Sector_KPIs!F10*F$4+Sector_KPIs!F11*Assumptions!$F$21)/Sector_KPIs!F23,0) -> 89.430256
A9: =Assumptions!$F$19+4 -> 24 | B9: =IFERROR((Sector_KPIs!F9*$A9+Sector_KPIs!F10*B$4+Sector_KPIs!F11*Assumptions!$F$21)/Sector_KPIs!F23,0) -> 82.328779 | C9: =IFERROR((Sector_KPIs!F9*$A9+Sector_KPIs!F10*C$4+Sector_KPIs!F11*Assumptions!$F$21)/Sector_KPIs!F23,0) -> 85.416787 | D9: =IFERROR((Sector_KPIs!F9*$A9+Sector_KPIs!F10*D$4+Sector_KPIs!F11*Assumptions!$F$21)/Sector_KPIs!F23,0) -> 88.504796 | E9: =IFERROR((Sector_KPIs!F9*$A9+Sector_KPIs!F10*E$4+Sector_KPIs!F11*Assumptions!$F$21)/Sector_KPIs!F23,0) -> 91.592804 | F9: =IFERROR((Sector_KPIs!F9*$A9+Sector_KPIs!F10*F$4+Sector_KPIs!F11*Assumptions!$F$21)/Sector_KPIs!F23,0) -> 94.680812

Sheet Checks
A1: NEE | Formula-Driven Model Checks | B1: NEE | Formula-Driven Model Checks | C1: NEE | Formula-Driven Model Checks | D1: NEE | Formula-Driven Model Checks | E1: NEE | Formula-Driven Model Checks | F1: NEE | Formula-Driven Model Checks | G1: NEE | Formula-Driven Model Checks | H1: NEE | Formula-Driven Model Checks
A2: Overall status is aggregated from check-row formulas. No check status is hardcoded. | B2: Overall status is aggregated from check-row formulas. No check status is hardcoded. | C2: Overall status is aggregated from check-row formulas. No check status is hardcoded. | D2: Overall status is aggregated from check-row formulas. No check status is hardcoded. | E2: Overall status is aggregated from check-row formulas. No check status is hardcoded. | F2: Overall status is aggregated from check-row formulas. No check status is hardcoded. | G2: Overall status is aggregated from check-row formulas. No check status is hardcoded. | H2: Overall status is aggregated from check-row formulas. No check status is hardcoded.
A3: Model as of | B3: 2025-12-31
A4: Overall model status | B4: =IF(COUNTIF(G7:G16,"<>PASS")=0,"PASS","REMEDIATE") -> PASS
A6: Check ID | B6: Category | C6: Actual | D6: Expected | E6: Difference | F6: Tolerance | G6: Status | H6: Evidence / fix hint
A7: C01 | B7: Source ledger exact URLs | C7: =COUNTBLANK(Sources!O5:O118) -> 0 | D7: 0 | E7: =C7-D7 -> 0 | F7: 0.01 | G7: =IF(ABS(E7)<=F7,"PASS","FAIL") -> PASS | H7: All material rows require an exact URL.
A8: C02 | B8: Source ledger accession field complete | C8: =COUNTBLANK(Sources!K5:K118) -> 0 | D8: 0 | E8: =C8-D8 -> 0 | F8: 0.01 | G8: =IF(ABS(E8)<=F8,"PASS","FAIL") -> PASS | H8: Every source row must carry a filed accession or an explicit N/A.
A9: C03 | B9: Debt bridge | C9: =Historical!E18-SUM(Historical!E14:E16) -> 0 | D9: 0 | E9: =C9-D9 -> 0 | F9: 0.01 | G9: =IF(ABS(E9)<=F9,"PASS","FAIL") -> PASS | H9: LongTermDebtCurrent + LongTermDebtNoncurrent + CommercialPaper + OtherShortTermBorrowings + FinanceLeaseLiability.
A10: C04 | B10: Net debt bridge | C10: =Historical!E19-(Historical!E18-Historical!E13) -> 0 | D10: 0 | E10: =C10-D10 -> 0 | F10: 0.01 | G10: =IF(ABS(E10)<=F10,"PASS","FAIL") -> PASS | H10: Net debt deducts cash and cash equivalents only; restricted cash and nuclear decommissioning funds are excluded.
A11: C05 | B11: Operating model historical revenue tie | C11: =Sector_KPIs!E8-Historical!E5 -> 0 | D11: 0 | E11: =C11-D11 -> 0 | F11: 0.01 | G11: =IF(ABS(E11)<=F11,"PASS","FAIL") -> PASS | H11: 2025 operating schedule revenue must equal filed revenue.
A12: C06 | B12: Forecast operating link | C12: =Forecast!C5-Sector_KPIs!F8 -> 0 | D12: 0 | E12: =C12-D12 -> 0 | F12: 0.01 | G12: =IF(ABS(E12)<=F12,"PASS","FAIL") -> PASS | H12: 2026E revenue must flow from the operating model.
A13: C07 | B13: Scenario selector | C13: =IF(AND(Assumptions!B3>=1,Assumptions!B3<=3),1,0) -> 1 | D13: 1 | E13: =C13-D13 -> 0 | F13: 0.01 | G13: =IF(ABS(E13)<=F13,"PASS","FAIL") -> PASS | H13: Selector must be 1, 2 or 3.
A14: C08 | B14: Share count positive | C14: =IF(Sector_KPIs!F23>0,1,0) -> 1 | D14: 1 | E14: =C14-D14 -> 0 | F14: 0.01 | G14: =IF(ABS(E14)<=F14,"PASS","FAIL") -> PASS | H14: Per-share valuation requires a positive share count.
A15: C09 | B15: Sensitivity center reconciliation | C15: =Sensitivity!D7-Valuation!B11 -> 0 | D15: 0 | E15: =C15-D15 -> 0 | F15: 0.01 | G15: =IF(ABS(E15)<=F15,"PASS","FAIL") -> PASS | H15: Center sensitivity cell must equal the active valuation.
A16: C10 | B16: Valuation finite / non-negative | C16: =IF(AND(ISNUMBER(Valuation!B11),Valuation!B11>=0),1,0) -> 1 | D16: 1 | E16: =C16-D16 -> 0 | F16: 0.01 | G16: =IF(ABS(E16)<=F16,"PASS","FAIL") -> PASS | H16: Primary equity value per share must be finite and non-negative; equity is floored at zero in downside cases.

Sheet Sector_KPIs
A1: NEE | FPL / NEER Segment Operating Model | B1: NEE | FPL / NEER Segment Operating Model | C1: NEE | FPL / NEER Segment Operating Model | D1: NEE | FPL / NEER Segment Operating Model | E1: NEE | FPL / NEER Segment Operating Model | F1: NEE | FPL / NEER Segment Operating Model | G1: NEE | FPL / NEER Segment Operating Model | H1: NEE | FPL / NEER Segment Operating Model | I1: NEE | FPL / NEER Segment Operating Model | J1: NEE | FPL / NEER Segment Operating Model
A2: FPL and NEER remain separate through earnings, capital plan and SOTP valuation; Corporate & Other is an explicit residual. | B2: FPL and NEER remain separate through earnings, capital plan and SOTP valuation; Corporate & Other is an explicit residual. | C2: FPL and NEER remain separate through earnings, capital plan and SOTP valuation; Corporate & Other is an explicit residual. | D2: FPL and NEER remain separate through earnings, capital plan and SOTP valuation; Corporate & Other is an explicit residual. | E2: FPL and NEER remain separate through earnings, capital plan and SOTP valuation; Corporate & Other is an explicit residual. | F2: FPL and NEER remain separate through earnings, capital plan and SOTP valuation; Corporate & Other is an explicit residual. | G2: FPL and NEER remain separate through earnings, capital plan and SOTP valuation; Corporate & Other is an explicit residual. | H2: FPL and NEER remain separate through earnings, capital plan and SOTP valuation; Corporate & Other is an explicit residual. | I2: FPL and NEER remain separate through earnings, capital plan and SOTP valuation; Corporate & Other is an explicit residual. | J2: FPL and NEER remain separate through earnings, capital plan and SOTP valuation; Corporate & Other is an explicit residual.
A4: Metric | B4: Units | C4: 2023A | D4: 2024A | E4: 2025A | F4: 2026E | G4: 2027E | H4: 2028E | I4: 2029E | J4: 2030E
A5: FPL revenue | B5: USD mm | C5: 18365 | D5: 17019 | E5: 18262 | F5: =E5*(1+Assumptions!$F$7) -> 19175.1 | G5: =F5*(1+Assumptions!$F$7) -> 20133.855 | H5: =G5*(1+Assumptions!$F$7) -> 21140.548 | I5: =H5*(1+Assumptions!$F$7) -> 22197.575 | J5: =I5*(1+Assumptions!$F$7) -> 23307.454
A6: NEER revenue | B6: USD mm | C6: 9672 | D6: 7542 | E6: 8760 | F6: =E6*(1+Assumptions!$F$8) -> 9285.6 | G6: =F6*(1+Assumptions!$F$8) -> 9842.736 | H6: =G6*(1+Assumptions!$F$8) -> 10433.3 | I6: =H6*(1+Assumptions!$F$8) -> 11059.298 | J6: =I6*(1+Assumptions!$F$8) -> 11722.856
A7: Corporate & eliminations revenue | B7: USD mm | C7: 77 | D7: 192 | E7: 390 | F7: =E7*(1+Assumptions!$F$9) -> 397.8 | G7: =F7*(1+Assumptions!$F$9) -> 405.756 | H7: =G7*(1+Assumptions!$F$9) -> 413.87112 | I7: =H7*(1+Assumptions!$F$9) -> 422.14854 | J7: =I7*(1+Assumptions!$F$9) -> 430.59151
A8: Consolidated revenue | B8: USD mm | C8: 28114 | D8: 24753 | E8: 27412 | F8: =SUM(F5:F7) -> 28858.5 | G8: =SUM(G5:G7) -> 30382.347 | H8: =SUM(H5:H7) -> 31987.719 | I8: =SUM(I5:I7) -> 33679.022 | J8: =SUM(J5:J7) -> 35460.901
A9: FPL net income | B9: USD mm | C9: 4552 | D9: 4543 | E9: 5012 | F9: =E9*(1+Assumptions!$F$10) -> 5463.08 | G9: =F9*(1+Assumptions!$F$10) -> 5954.7572 | H9: =G9*(1+Assumptions!$F$10) -> 6490.6853 | I9: =H9*(1+Assumptions!$F$10) -> 7074.847 | J9: =I9*(1+Assumptions!$F$10) -> 7711.5833
A10: NEER net income | B10: USD mm | C10: 3558 | D10: 2299 | E10: 2975 | F10: =E10*(1+Assumptions!$F$11) -> 3213 | G10: =F10*(1+Assumptions!$F$11) -> 3470.04 | H10: =G10*(1+Assumptions!$F$11) -> 3747.6432 | I10: =H10*(1+Assumptions!$F$11) -> 4047.4547 | J10: =I10*(1+Assumptions!$F$11) -> 4371.251
A11: Corporate & Other net income | B11: USD mm | C11: -800 | D11: 104 | E11: -1152 | F11: =E11*(1+Assumptions!$F$12) -> -1175.04 | G11: =F11*(1+Assumptions!$F$12) -> -1198.5408 | H11: =G11*(1+Assumptions!$F$12) -> -1222.5116 | I11: =H11*(1+Assumptions!$F$12) -> -1246.9618 | J11: =I11*(1+Assumptions!$F$12) -> -1271.9011
A12: Consolidated net income | B12: USD mm | C12: 7310 | D12: 6946 | E12: 6835 | F12: =SUM(F9:F11) -> 7501.04 | G12: =SUM(G9:G11) -> 8226.2564 | H12: =SUM(H9:H11) -> 9015.8169 | I12: =SUM(I9:I11) -> 9875.3398 | J12: =SUM(J9:J11) -> 10810.933
A13: FPL average rate-base increase | B13: USD mm | E13: 5500
A14: NEER new wind additions | B14: MW | E14: 1604
A15: NEER new solar additions | B15: MW | E15: 2859
A16: NEER new battery-storage additions | B16: MW | E16: 1799
A17: Renewables/storage backlog added | B17: MW | E17: 13500
A18: FPL filed capital plan | B18: USD mm | F18: 11185 | G18: 10870 | H18: 11605 | I18: 12375 | J18: 12595
A19: NEER filed capital plan | B19: USD mm | F19: 16380 | G19: 10730 | H19: 5115 | I19: 1650 | J19: 1680
A20: FPL scenario capex | B20: USD mm | C20: 9400 | D20: 8214 | E20: 8935 | F20: =F18*Assumptions!$F$13 -> 11185 | G20: =G18*Assumptions!$F$13 -> 10870 | H20: =H18*Assumptions!$F$13 -> 11605 | I20: =I18*Assumptions!$F$13 -> 12375 | J20: =J18*Assumptions!$F$13 -> 12595
A21: NEER scenario capex | B21: USD mm | C21: 15652 | D21: 16392 | E21: 15669 | F21: =F19*Assumptions!$F$14 -> 16380 | G21: =G19*Assumptions!$F$14 -> 10730 | H21: =H19*Assumptions!$F$14 -> 5115 | I21: =I19*Assumptions!$F$14 -> 1650 | J21: =J19*Assumptions!$F$14 -> 1680
A22: Total scenario capex | B22: USD mm | C22: 25113 | D22: 24729 | E22: 24606 | F22: =SUM(F20:F21) -> 27565 | G22: =SUM(G20:G21) -> 21600 | H22: =SUM(H20:H21) -> 16720 | I22: =SUM(I20:I21) -> 14025 | J22: =SUM(J20:J21) -> 14275
A23: Diluted weighted-average shares | B23: mm shares | C23: =Historical!C17 -> 2030.8 | D23: =Historical!D17 -> 2059.2 | E23: =Historical!E17 -> 2070.6 | F23: =E23*(1+Assumptions!$F$25) -> 2080.953 | G23: =F23*(1+Assumptions!$F$25) -> 2091.3578 | H23: =G23*(1+Assumptions!$F$25) -> 2101.8146 | I23: =H23*(1+Assumptions!$F$25) -> 2112.3236 | J23: =I23*(1+Assumptions!$F$25) -> 2122.8852
A24: Dividend per share | B24: $ / share | E24: 2.27 | F24: =E24*(1+Assumptions!$F$22) -> 2.4516 | G24: =F24*(1+Assumptions!$F$22) -> 2.647728 | H24: =G24*(1+Assumptions!$F$22) -> 2.8595462 | I24: =H24*(1+Assumptions!$F$22) -> 3.0883099 | J24: =I24*(1+Assumptions!$F$22) -> 3.3353747
A25: Total debt | B25: USD mm | C25: =Historical!C18 -> 73655 | D25: =Historical!D18 -> 83173 | E25: =Historical!E18 -> 96762 | F25: =E25*(1+Assumptions!$F$26) -> 99664.86 | G25: =F25*(1+Assumptions!$F$26) -> 102654.81 | H25: =G25*(1+Assumptions!$F$26) -> 105734.45 | I25: =H25*(1+Assumptions!$F$26) -> 108906.48 | J25: =I25*(1+Assumptions!$F$26) -> 112173.68
A26: EPS | B26: $ / share | C26: =IFERROR(C12/C23,0) -> 3.5995667 | D26: =IFERROR(D12/D23,0) -> 3.3731546 | E26: =IFERROR(E12/E23,0) -> 3.3009756 | F26: =IFERROR(F12/F23,0) -> 3.6046177 | G26: =IFERROR(G12/G23,0) -> 3.9334525 | H26: =IFERROR(H12/H23,0) -> 4.2895397 | I26: =IFERROR(I12/I23,0) -> 4.6751074 | J26: =IFERROR(J12/J23,0) -> 5.092566
A29: Year | B29: FPL NI | C29: NEER NI
A30: 2025A | B30: =E9 -> 5012 | C30: =E10 -> 2975
A31: 2026E | B31: =F9 -> 5463.08 | C31: =F10 -> 3213
A32: 2027E | B32: =G9 -> 5954.7572 | C32: =G10 -> 3470.04
A33: 2028E | B33: =H9 -> 6490.6853 | C33: =H10 -> 3747.6432
A34: 2029E | B34: =I9 -> 7074.847 | C34: =I10 -> 4047.4547
A35: 2030E | B35: =J9 -> 7711.5833 | C35: =J10 -> 4371.251

Sheet Change_Log
A1: NEE | Controlled Change Log | B1: NEE | Controlled Change Log | C1: NEE | Controlled Change Log | D1: NEE | Controlled Change Log | E1: NEE | Controlled Change Log | F1: NEE | Controlled Change Log
A2: Prior workbook is preserved. This output is a new artifact with documented source, model, gate and recalculation changes. | B2: Prior workbook is preserved. This output is a new artifact with documented source, model, gate and recalculation changes. | C2: Prior workbook is preserved. This output is a new artifact with documented source, model, gate and recalculation changes. | D2: Prior workbook is preserved. This output is a new artifact with documented source, model, gate and recalculation changes. | E2: Prior workbook is preserved. This output is a new artifact with documented source, model, gate and recalculation changes. | F2: Prior workbook is preserved. This output is a new artifact with documented source, model, gate and recalculation changes.
A4: Timestamp | B4: Version | C4: Area | D4: Change | E4: Evidence | F4: Owner scope
A5: UTC 2026-07-16T21:40:00Z | B5: 9of10-regated | C5: Preservation | D5: Prior workbook preserved without overwrite. | E5: Original SHA-256: f04dca73907ab65678e52963d37b8de46238695d1a45093a759d0da9c2dec391 | F5: Controlled rebuild
A6: UTC 2026-07-16T21:40:00Z | B6: 9of10-regated | C6: Sources | D6: Replaced generic source list with exact SEC accession, filing URL, taxonomy/tag, period, unit, transform and target-cell ledger. | E6: Sources!A4:Q* | F6: Owner preflight
A7: UTC 2026-07-16T21:40:00Z | B7: 9of10-regated | C7: Debt / cash / shares | D7: Rebuilt total debt from explicit filed components; documented cash/restricted-cash and share-count policies. | E7: Historical!A13:I19 | F7: Owner preflight
A8: UTC 2026-07-16T21:40:00Z | B8: 9of10-regated | C8: Operating model | D8: Separated FPL and NEER revenue, earnings and capital plans. | E8: Sector_KPIs | F8: Owner preflight
A9: UTC 2026-07-16T21:40:00Z | B9: 9of10-regated | C9: Valuation | D9: Established FPL/NEER/Corporate SOTP with DDM cross-check. | E9: Valuation + Sensitivity | F9: Owner preflight
A10: UTC 2026-07-16T21:40:00Z | B10: 9of10-regated | C10: Gate | D10: Added formula-driven Checks and H0-H9 owner-preflight gate; independent certification is explicitly excluded. | E10: Checks + Gate_9of10 | F10: Owner preflight
A11: UTC 2026-07-16T21:40:00Z | B11: 9of10-regated | C11: Output | D11: Authored with artifact-tool; native recalculation and final visual manifest are referenced in Gate_9of10 and support evidence. | E11: NextEra_Energy_9of10_Regated.xlsx | F11: Owner preflight

Sheet Gate_9of10
A1: NEE | H0-H9 Owner Preflight Gate | B1: NEE | H0-H9 Owner Preflight Gate | C1: NEE | H0-H9 Owner Preflight Gate | D1: NEE | H0-H9 Owner Preflight Gate | E1: NEE | H0-H9 Owner Preflight Gate | F1: NEE | H0-H9 Owner Preflight Gate | G1: NEE | H0-H9 Owner Preflight Gate
A2: This sheet records owner preflight readiness. Independent certification is still required and is not self-awarded. | B2: This sheet records owner preflight readiness. Independent certification is still required and is not self-awarded. | C2: This sheet records owner preflight readiness. Independent certification is still required and is not self-awarded. | D2: This sheet records owner preflight readiness. Independent certification is still required and is not self-awarded. | E2: This sheet records owner preflight readiness. Independent certification is still required and is not self-awarded. | F2: This sheet records owner preflight readiness. Independent certification is still required and is not self-awarded. | G2: This sheet records owner preflight readiness. Independent certification is still required and is not self-awarded.
A4: Gate | B4: Control objective | C4: Weight | D4: Status | E4: Evidence range | F4: Owner note | G4: Independent certification
A5: H0 | B5: Controlled lineage and package integrity | C5: 5 | D5: =IF(AND(B23<>"",B24<>"",B25<>""),"PASS","FAIL") -> PASS | E5: Gate_9of10!A23:B28; internal QA evidence (not published) | F5: Original/output paths and original hash recorded; final hash and unzip evidence live beside the immutable reviewed file. | G5: Required
A6: H1 | B6: Source fidelity and provenance | C6: 20 | D6: =IF(AND(Checks!G7="PASS",Checks!G8="PASS"),"PASS","FAIL") -> PASS | E6: Sources!A4:Q*; Historical comments; Assumptions comments | F6: SEC tags/periods/units/accessions/retrieval/targets/transforms. Undated inherited market price removed from outputs. | G6: Required
A7: H2 | B7: Historical, formula and schedule mechanics | C7: 15 | D7: =IF(AND(Checks!G9="PASS",Checks!G10="PASS",Checks!G11="PASS",Checks!G12="PASS"),"PASS","FAIL") -> PASS | E7: Historical!A4:I23; Sector_KPIs!A4:J*; Forecast!A4:G15 | F7: Historical hardcodes and forecast formulas trace without cash/debt plugs. | G7: Required
A8: H3 | B8: Scenario and sensitivity integrity | C8: 10 | D8: =IF(AND(Checks!G13="PASS",Checks!G15="PASS"),"PASS","FAIL") -> PASS | E8: Assumptions!A3:G*; Sensitivity!A4:H9 | F8: Editable selector drives Base/Bull/Bear; sensitivity is formula-backed. | G8: Required
A9: H4 | B9: Valuation fit and mechanics | C9: 15 | D9: =IF(AND(Checks!G14="PASS",Checks!G15="PASS",Checks!G16="PASS"),"PASS","FAIL") -> PASS | E9: Valuation!A4:G31; Sensitivity!A4:H9 | F9: FPL/NEER/Corporate SOTP primary; DDM cross-check; no stale market-price comparison. | G9: Required
A10: H5 | B10: Model checks and error state | C10: 8 | D10: =IF(Checks!B4="PASS","PASS","FAIL") -> PASS | E10: Checks!A3:H16; post manifest formula_error_scan | F10: Transparent Actual/Expected/Difference/Tolerance/Status checks and post-recalc error scan. | G10: Required
A11: H6 | B11: Native recalculation and reproducibility | C11: 10 | D11: =IF(B21<>"","PASS","FAIL") -> PASS | E11: Gate_9of10!A20:B22; support native log; internal QA evidence (not published) | F11: Opened/recalculated/saved/closed in LibreOfficeDev, then reopened by artifact-tool. | G11: Required
A12: H7 | B12: Visual QA after recalculation | C12: 7 | D12: =IF(B22<>"","PASS","FAIL") -> PASS | E12: internal QA evidence (not published) | F12: Every user-facing sheet rendered after native recalculation and tied to final hash. | G12: Required
A13: H8 | B13: Material economic upgrade | C13: 5 | D13: =IF(AND(COUNTA(Change_Log!A5:A20)>=6,COUNTA(Sector_KPIs!F5:J20)>0),"PASS","FAIL") -> PASS | E13: Change_Log!A4:F*; Sector_KPIs; Valuation; Checks | F13: Source, debt, company-specific operating, scenario, valuation and check mechanics were substantively rebuilt. | G13: Required
A14: H9 | B14: Governance, limitations and reviewer handoff | C14: 5 | D14: =IF(AND('00_Cover'!B4<>"",'00_Cover'!B16<>"",COUNTA(Change_Log!A5:A20)>=6),"PASS","FAIL") -> PASS | E14: 00_Cover!A4:H19; Change_Log!A4:F*; Gate_9of10 | F14: Purpose, version, as-of, units, horizon, case, status, limitations and reviewer handoff are explicit. | G14: Required
A16: Weighted score | B16: =SUMPRODUCT(C5:C14,--(D5:D14="PASS")) -> 100
A17: Owner preflight decision | B17: =IF(AND(B16>=90,COUNTIF(D5:D14,"FAIL")=0),"OWNER PRE-FLIGHT 9/10 READY — INDEPENDENT CERTIFICATION REQUIRED","REMEDIATE BEFORE INDEPENDENT CERTIFICATION") -> OWNER PRE-FLIGHT 9/10 READY — INDEPENDENT CERTIFICATION REQUIRED
