Workbook

Sheet EEFF
A1: UEP Penonomé II, S. A.
A2: Estados Financieros Auditados FY21-FY25
A3: en US$ sin escala
A5: Años | B5: FY21A | C5: FY22A | D5: FY23A | E5: FY24A | F5: FY25A | G5: FY26E | H5: FY27E | I5: FY28E | J5: FY29E | K5: FY30E
A6: Estado de Resultado
A7: Ingresos por energía | B7: 42036085 | C7: 40987418 | D7: 54587421 | E7: 42653811 | F7: 42404701
A8: Costos de bienes y servicios | B8: -22857327 | C8: -21858853 | D8: -25573871 | E8: -25736347 | F8: -24413955
A9: Utilidad bruta | B9: 19178758 | C9: 19128565 | D9: 29013550 | E9: 16917464 | F9: 17990746
A10: Gastos administrativos | B10: -3266942 | C10: -3405988 | D10: -4482435 | E10: -3436087 | F10: -3908720
A11: Utilidad operativa | B11: 15911816 | C11: 15722577 | D11: 24531115 | E11: 13481377 | F11: 14082026
A12: Costos financieros, neto | B12: -14126147 | C12: -9881077 | D12: -16142876 | E12: -15193459 | F12: -14336109
A13: Otros ingresos | B13: 34397 | C13: 130429 | D13: 6770 | E13: 1010 | F13: 81975
A14: Pérdida antes del impuesto sobre la renta | B14: 1820066 | C14: 5971929 | D14: 8395009 | E14: -1711072 | F14: -172108
A15: Impuesto sobre la renta | B15: -2683428 | C15: 599370 | D15: -820467 | E15: -681267 | F15: -497187
A16: Pérdida del año | B16: -863362 | C16: 6571299 | D16: 7574542 | E16: -2392339 | F16: -669295
A18: Años | B18: FY21A | C18: FY22A | D18: FY23A | E18: FY24A | F18: FY25A | G18: FY26E | H18: FY27E | I18: FY28E | J18: FY29E | K18: FY30E
A19: Balance General
A20: Efectivo y equivalentes de efectivo | B20: 5485501 | C20: 5490195 | D20: 17396949 | E20: 4118908 | F20: 5197344
A21: Deudores comerciales y otras cuentas por cobrar | B21: 8440721 | C21: 6989164 | D21: 7127866 | E21: 3904545 | F21: 4837614
A22: Deuda por cobrar a parte relacionada | B22: 898932 | C22: 996982 | D22: 1138080 | E22: 1239674 | F22: 1332322
A23: Gastos pagados por adelantado | B23: 1954336 | C23: 4991808 | D23: 1291507 | E23: 1963129 | F23: 860787
A24: Inventario | B24: 38791 | C24: 40685 | D24: 51726 | E24: 71702 | F24: 84203
A25: Total de activos corrientes | B25: 16818281 | C25: 18508834 | D25: 27006128 | E25: 11297958 | F25: 12312270
A26: Planta y equipo, neto | B26: 216209163 | C26: 202848696 | D26: 193996920 | E26: 180311071 | F26: 167298071
A27: Plusvalía | B27: 20000000 | C27: 20000000 | D27: 20000000 | E27: 20000000 | F27: 20000000
A28: Deuda por cobrar a parte relacionada | B28: 21480114 | C28: 20483131 | D28: 19345052 | E28: 18105378 | F28: 16773057
A29: Activos intangibles, neto | B29: 109685 | C29: 105268 | D29: 100851 | E29: 96435 | F29: 92018
A30: Fondo de cesantía | C30: 13934 | D30: 17359 | E30: 21782 | F30: 26510
A31: Total de activos no corrientes | B31: 257798962 | C31: 243451029 | D31: 233460182 | E31: 218534666 | F31: 204189656
A32: Total de activos | B32: 274617243 | C32: 261959863 | D32: 260466310 | E32: 229832624 | F32: 216501926
A33: Bonos por pagar | B33: 14299859 | C33: 15240126 | D33: 16627445 | E33: 17584115 | F33: 18400181
A34: Proveedores y otras cuentas por pagar | B34: 2652919 | C34: 1285733 | D34: 2536737 | E34: 1419947 | F34: 2311149
A35: Pasivos por arrendamiento | B35: 157731 | C35: 192094 | D35: 229888 | E35: 271410 | F35: 316983
A36: Total de pasivos corrientes | B36: 17110509 | C36: 16717953 | D36: 19394070 | E36: 19275472 | F36: 21028313
A37: Pasivos por arrendamiento | B37: 8232437 | C37: 8040342 | D37: 7810454 | E37: 7539044 | F37: 7222062
A38: Impuesto sobre la renta diferido | B38: 1204764 | C38: 605394 | D38: 1425861 | E38: 2107128 | F38: 2604315
A39: Provisiones | B39: 0 | C39: 347922 | D39: 374016 | E39: 402067 | F39: 432222
A40: Bonos por pagar | B40: 234949078 | C40: 224181572 | D40: 211820687 | E40: 198290030 | F40: 183665429
A41: Instrumento financiero derivado | B41: 7625074
A42: Total de pasivos no corrientes | B42: 252011353 | C42: 233175230 | D42: 221431018 | E42: 208338269 | F42: 193924028
...

Sheet Supuestos
A1: UEP Penonomé II, S. A.
A3: COLOR KEY: Input (azul) · Fórmula (negro) · Link inter-hoja (verde)
A4: Escenario (1=Base, 2=Bull, 3=Bear)
A5: Selector escenario | C5: 1 | M5: caso | N5: NOT_DISCLOSED | Q5: Input de escenario desde fuente citada o NOT_DISCLOSED.
A6: Escenario activo | C6: =CHOOSE($C$5,"Base","Bull","Bear") -> Base | M6: moneda del modelo | N6: NOT_DISCLOSED | Q6: Selector de caso activo C5: Base/Bull/Bear.
A8: Años | B8: FY21A | C8: FY22A | D8: FY23A | E8: FY24A | F8: FY25A | G8: FY26E | H8: FY27E | I8: FY28E | J8: FY29E | K8: FY30E | M8: Unidad | N8: Fuente / nota | Q8: Rationale
A10: A. PRODUCCIÓN POR PARQUE (MWh neto = MW × 8.760 h × CF neto; el CF histórico ya embebe wake+AVF)
A11: Factor de planta NETO (CF) — activo | B11: 0.2304 | C11: 0.2028 | D11: 0.2838 | E11: 0.2147 | F11: 0.2243 | G11: =CHOOSE($C$5,G13,G14,G12) -> 0.215 | H11: =CHOOSE($C$5,H13,H14,H12) -> 0.215 | I11: =CHOOSE($C$5,I13,I14,I12) -> 0.215 | J11: =CHOOSE($C$5,J13,J14,J12) -> 0.21 | K11: =CHOOSE($C$5,K13,K14,K12) -> 0.21 | M11: % | N11: a working file kept by the maintainer | Q11: Selector de caso activo C5: Base/Bull/Bear.
A12: Bear | G12: 0.195 | H12: 0.195 | I12: 0.195 | J12: 0.195 | K12: 0.19 | M12: % | N12: a working file kept by the maintainer | Q12: Escenario driver citado; NOT_DISCLOSED si no hay fuente explícita.
A13: Base | G13: 0.215 | H13: 0.215 | I13: 0.215 | J13: 0.21 | K13: 0.21 | M13: % | N13: a working file kept by the maintainer | Q13: Escenario driver citado; NOT_DISCLOSED si no hay fuente explícita.
A14: Bull | G14: 0.245 | H14: 0.245 | I14: 0.245 | J14: 0.24 | K14: 0.24 | M14: % | N14: a working file kept by the maintainer | Q14: Escenario driver citado; NOT_DISCLOSED si no hay fuente explícita.
A15: Disponibilidad (AVF) — memo (ya embebida en CF neto) | B15: 0.9381 | C15: 0.957 | D15: 0.9337 | E15: 0.9366 | F15: 0.9597 | G15: 0.96 | H15: 0.96 | I15: 0.96 | J15: 0.96 | K15: 0.96 | M15: % | N15: a working file kept by the maintainer | Q15: Input de escenario desde fuente citada o NOT_DISCLOSED.
A16: Horas / año | B16: 8760 | C16: 8760 | D16: 8760 | E16: 8784 | F16: 8760 | G16: 8760 | H16: 8760 | I16: 8760 | J16: 8760 | K16: 8760 | M16: horas/año | N16: a working file kept by the maintainer | Q16: Input de escenario desde fuente citada o NOT_DISCLOSED.
A17: Nuevo Chagres — 62.5 MW (wake 12.4%) | G17: =62.5*G16*G11 -> 117712.5 | H17: =62.5*H16*H11 -> 117712.5 | I17: =62.5*I16*I11 -> 117712.5 | J17: =62.5*J16*J11 -> 114975 | K17: =62.5*K16*K11 -> 114975 | M17: MW | N17: a working file kept by the maintainer | Q17: Derivación mecánica por fórmula viva.
A18: Rosa de los Vientos I — 52.5 MW (wake 8.0%) | G18: =52.5*G16*G11 -> 98878.5 | H18: =52.5*H16*H11 -> 98878.5 | I18: =52.5*I16*I11 -> 98878.5 | J18: =52.5*J16*J11 -> 96579 | K18: =52.5*K16*K11 -> 96579 | M18: MW | N18: a working file kept by the maintainer | Q18: Derivación mecánica por fórmula viva.
A19: Rosa de los Vientos II — 50 MW (wake 6.0%) | G19: =50*G16*G11 -> 94170 | H19: =50*H16*H11 -> 94170 | I19: =50*I16*I11 -> 94170 | J19: =50*J16*J11 -> 91980 | K19: =50*K16*K11 -> 91980 | M19: MW | N19: a working file kept by the maintainer | Q19: Derivación mecánica por fórmula viva.
A20: Marañón — 17.5 MW (wake 7.0%) | G20: =17.5*G16*G11 -> 32959.5 | H20: =17.5*H16*H11 -> 32959.5 | I20: =17.5*I16*I11 -> 32959.5 | J20: =17.5*J16*J11 -> 32193 | K20: =17.5*K16*K11 -> 32193 | M20: MW | N20: a working file kept by the maintainer | Q20: Derivación mecánica por fórmula viva.
A21: Portobelo Ballestillas — 32.5 MW (wake 8.0%) | G21: =32.5*G16*G11 -> 61210.5 | H21: =32.5*H16*H11 -> 61210.5 | I21: =32.5*I16*I11 -> 61210.5 | J21: =32.5*J16*J11 -> 59787 | K21: =32.5*K16*K11 -> 59787 | M21: MW | N21: a working file kept by the maintainer | Q21: Derivación mecánica por fórmula viva.
A22: Generación neta total (MWh) | B22: 433950 | C22: 381870 | D22: 534600 | E22: 405420 | F22: 422370 | G22: =G17+G18+G19+G20+G21 -> 404931 | H22: =H17+H18+H19+H20+H21 -> 404931 | I22: =I17+I18+I19+I20+I21 -> 404931 | J22: =J17+J18+J19+J20+J21 -> 395514 | K22: =K17+K18+K19+K20+K21 -> 395514 | M22: MWh | N22: a working file kept by the maintainer | Q22: Suma mecánica del bloque.
A24: B. PRECIOS POR FUENTE ($/MWh)
A25: PPA contratado ($/MWh, 75% fijo + 25% IPC) | G25: 112.359 | H25: 112.921 | I25: 113.485 | J25: 114.053 | K25: 114.623 | M25: MWh | N25: a working file kept by the maintainer | Q25: Input de escenario desde fuente citada o NOT_DISCLOSED.
A26: Spot / merchant ($/MWh) — activo | B26: 74.16 | C26: 148.76 | D26: 112.45 | E26: 133.91 | F26: 66.44 | G26: =CHOOSE($C$5,G28,G29,G27) -> 60 | H26: =CHOOSE($C$5,H28,H29,H27) -> 57 | I26: =CHOOSE($C$5,I28,I29,I27) -> 54 | J26: =CHOOSE($C$5,J28,J29,J27) -> 51 | K26: =CHOOSE($C$5,K28,K29,K27) -> 50 | M26: MWh | N26: a working file kept by the maintainer | Q26: Selector de caso activo C5: Base/Bull/Bear.
A27: Bear | G27: 50 | H27: 47 | I27: 44 | J27: 41 | K27: 40 | M27: moneda del modelo | N27: a working file kept by the maintainer | Q27: Escenario driver citado; NOT_DISCLOSED si no hay fuente explícita.
A28: Base | G28: 60 | H28: 57 | I28: 54 | J28: 51 | K28: 50 | M28: moneda del modelo | N28: a working file kept by the maintainer | Q28: Escenario driver citado; NOT_DISCLOSED si no hay fuente explícita.
A29: Bull | G29: 70 | H29: 67 | I29: 64 | J29: 61 | K29: 60 | M29: moneda del modelo | N29: a working file kept by the maintainer | Q29: Escenario driver citado; NOT_DISCLOSED si no hay fuente explícita.
A30: Reserva Tecnisol ($/MWh) | G30: 73.3 | H30: 73.3 | I30: 73.3 | J30: 73.3 | K30: 73.3 | M30: MWh | N30: a working file kept by the maintainer | Q30: Input de escenario desde fuente citada o NOT_DISCLOSED.
A32: C. VOLUMEN POR CANAL (MWh, con cliffs PPA por parque)
A33: MWh PPA contratado (DISCOs) | B33: 337870 | C33: 299330 | D33: 418780 | E33: 320080 | F33: 347300 | G33: =1*G17+1*G18+1*G20+1*G21 -> 310761 | H33: =1*H17+1*H18+1*H20+1*H21 -> 310761 | I33: =1*I17+1*I18+1*I20+1*I21 -> 310761 | J33: =0.5*J17+0.5*J18+1*J20+1*J21 -> 197757 | K33: =1*K20+1*K21 -> 91980 | M33: MWh | N33: a working file kept by the maintainer | Q33: Derivación mecánica por fórmula viva.
A34: MWh reserva (Tecnisol, Rosa II) | B34: 27870 | C34: 24710 | D34: 43220 | E34: 34000 | F34: 38160 | G34: 34000 | H34: 34000 | I34: 34000 | J34: 34000 | K34: 34000 | M34: MWh | N34: a working file kept by the maintainer | Q34: Input de escenario desde fuente citada o NOT_DISCLOSED.
A35: MWh spot / merchant (residual) | B35: 56140 | C35: 49820 | D35: 61470 | E35: 42710 | F35: 26840 | G35: =MAX(0,G22-G33-G34) -> 60170 | H35: =MAX(0,H22-H33-H34) -> 60170 | I35: =MAX(0,I22-I33-I34) -> 60170 | J35: =MAX(0,J22-J33-J34) -> 163757 | K35: =MAX(0,K22-K33-K34) -> 269534 | M35: MWh | N35: a working file kept by the maintainer | Q35: Derivación mecánica por fórmula viva.
A37: D. INGRESO POR FUENTE ($ = MWh × precio)
A38: Ingreso energía FY25A (auditado, ref EEFF) | B38: =EEFF!B7 -> 42036085 | C38: =EEFF!C7 -> 40987418 | D38: =EEFF!D7 -> 54587421 | E38: =EEFF!E7 -> 42653811 | F38: =EEFF!F7 -> 42404701 | M38: MWh | N38: EEFF:Ingresos por energía | Q38: Mirror histórico desde fuente citada.
A39: Ingreso PPA | G39: =G33*G25 -> 34916795 | H39: =H33*H25 -> 35091443 | I39: =I33*I25 -> 35266712 | J39: =J33*J25 -> 22554779 | K39: =K33*K25 -> 10543024 | M39: moneda del modelo | N39: a working file kept by the maintainer | Q39: Derivación mecánica por fórmula viva.
A40: Ingreso reserva Tecnisol | B40: 1819919 | C40: 1613353 | D40: 2822042 | E40: 2220153 | F40: 2492069 | G40: =G34*G30 -> 2492200 | H40: =H34*H30 -> 2492200 | I40: =I34*I30 -> 2492200 | J40: =J34*J30 -> 2492200 | K40: =K34*K30 -> 2492200 | M40: moneda del modelo | N40: a working file kept by the maintainer | Q40: Derivación mecánica por fórmula viva.
A41: Ingreso spot / merchant | B41: =B35*B26 -> 4163342.4 | C41: =C35*C26 -> 7411223.2 | D41: =D35*D26 -> 6912301.5 | E41: =E35*E26 -> 5719296.1 | F41: =F35*F26 -> 1783249.6 | G41: =G35*G26 -> 3610200 | H41: =H35*H26 -> 3429690 | I41: =I35*I26 -> 3249180 | ... K41: =K35*K26 -> 13476700 | M41: moneda del modelo | N41: a working file kept by the maintainer | Q41: Derivación mecánica por fórmula viva.
A42: Compensación pérdidas transmisión | G42: 700000 | H42: 700000 | I42: 700000 | J42: 700000 | K42: 700000 | M42: moneda del modelo | N42: a working file kept by the maintainer | Q42: Input de escenario desde fuente citada o NOT_DISCLOSED.
A43: (memo) Potencia firme — embebida en PPA $/MWh (no sumada) | G43: 49.5 | H43: 49.5 | I43: 49.5 | J43: 49.5 | K43: 49.5 | M43: MWh | N43: a working file kept by the maintainer | Q43: Derivación mecánica declarada por el plan.
A44: TOTAL INGRESO ENERGÍA | B44: =B38 -> 42036085 | C44: =C38 -> 40987418 | D44: =D38 -> 54587421 | E44: =E38 -> 42653811 | F44: =F38 -> 42404701 | G44: =G39+G40+G41+G42 -> 41719195 | H44: =H39+H40+H41+H42 -> 41713333 | I44: =I39+I40+I41+I42 -> 41708092 | J44: =J39+J40+J41+J42 -> 34098586 | K44: =K39+K40+K41+K42 -> 27211924 | M44: MWh | N44: a working file kept by the maintainer | Q44: Suma mecánica del bloque.
A46: E. O&M Y COSTOS OPERATIVOS ($)
A47: O&M variable ($/MWh) [Goldwind SMA] | B47: =B48/B22 -> 16.803941 | C47: =C48/C22 -> 16.441072 | D47: =D48/D22 -> 14.581163 | E47: =E48/E22 -> 17.057489 | F47: =F48/F22 -> 16.98029 | G47: 17 | H47: 17 | I47: 17 | J47: 17 | K47: 17 | M47: MWh | N47: a working file kept by the maintainer | Q47: Derivación mecánica por fórmula viva.
...

Sheet Notas_EEFF
A1: UEP Penonomé II, S. A.
A2: Notas a los Estados Financieros
A3: Fuente: Estados Financieros Auditados FY21-FY25 (OCR Mistral). Entidad: UEP Penonomé II, S. A. STANDALONE (no Grupo Tecnisol combinado, no Fideicomiso FID-135). Notas verbatim en español. Años: 2025/2024 del informe INA_UEPPSA_2025; 2023 del INA_UEPPSA_2024; 2022 del INA_UEPPSA_2023; 2021 del INA_UEPPSA_2022 (criterio: informe más reciente para años solapados).
A5: Año | B5: Documento fuente | C5: Página OCR | D5: Tabla OCR / sección | E5: Nota # | F5: Título original de la nota | G5: Categoría modelable | H5: Line item EEFF | I5: Sub-line item / detalle | J5: Texto original / disclosure | K5: Monto reportado | L5: Moneda | M5: Unidad / escala | N5: Fecha / venc. / tasa / plazo | O5: Contraparte / contrato / instrumento | P5: Impacto en Supuestos | Q5: Impacto en ModeloFinanciero | R5: Link a celda EEFF | S5: Comentario de extracción | T5: Status
A6: 2025 | B6: INA_UEPPSA_2025_0.pdf | C6: page-36 | D6: markdown.md | E6: 1. Información General | F6: 1. Información General | G6: Otros | I6: Constitución y actividad | J6: UEP Penonomé II, S. A. (la “Compañía”) se constituyó el 18 de enero de 2013 bajo las leyes de la República de Panamá. La Compañía se dedica a la producción de electricidad a través de cinco parques eólicos ubicados en Penonomé, Provincia de Coclé, República de Panamá. | L6: US$ | M6: sin escala | N6: 18 de enero de 2013 | P6: Define el activo: 5 parques eólicos, 215 MW; base del build de generación. | T6: OK
A7: 2025 | B7: INA_UEPPSA_2025_0.pdf | C7: page-36 | D7: markdown.md | E7: 1. Información General | F7: 1. Información General | G7: Partes relacionadas | I7: Controladora última | J7: La última sociedad controladora de UEP Penonomé II, S. A. es Basic Energy Ltd., constituida en las Bahamas. | L7: US$ | M7: sin escala | O7: Basic Energy Ltd. (Bahamas) | T7: OK
A8: 2025 | B8: INA_UEPPSA_2025_0.pdf | C8: page-36 | D8: markdown.md | E8: 1. Información General | F8: 1. Información General | G8: Otros | I8: Licencia ASEP | J8: El regulador local, la Autoridad Nacional de Servicios Públicos (ASEP), aprobó la licencia de generación de electricidad de la Compañía con capacidad de 215 MW (Nota 19). | K8: 215 | L8: US$ | M8: MW | O8: ASEP | P8: Capacidad instalada 215 MW = techo físico de generación. | T8: OK
A9: 2025 | B9: INA_UEPPSA_2025_0.pdf | C9: page-36 | D9: markdown.md | E9: 1. Información General | F9: 1. Información General | G9: Otros | I9: Domicilio | J9: La Compañía está ubicada en Edificio Plaza 58, Piso 9, Calle 58E, Obarrío, República de Panamá, y las turbinas eólicas están ubicadas en Penonomé, Provincia de Coclé, República de Panamá. | L9: US$ | M9: sin escala | T9: OK
A10: 2025 | B10: INA_UEPPSA_2025_0.pdf | C10: page-36 | D10: markdown.md | E10: 1. Información General | F10: 1. Información General | G10: Subsequent events | I10: Aprobación de emisión | J10: Estos estados financieros han sido aprobados para su emisión por el Gerente de Finanzas el 28 de febrero de 2026. | L10: US$ | M10: sin escala | N10: 28 de febrero de 2026 | T10: OK
A11: 2025 | B11: INA_UEPPSA_2025_0.pdf | C11: page-37 | D11: markdown.md | E11: 2. Resumen de las Políticas Contables Materiales | F11: 2. Resumen de las Políticas Contables Materiales | G11: Políticas contables | I11: Base de Preparación | J11: Los estados financieros de la Compañía han sido preparados de acuerdo con las Normas Internacionales de Información Financiera emitidas por la Junta de Normas Internacionales de Contabilidad (IASB, por sus siglas en inglés) (Normas de Contabilidad NIIF). Los estados financieros han sido preparados sobre la base del costo histórico. En los estados financieros de la Compañía no se presenta el Estado de Otro Resultado Integral, debido a que no hay partidas que requieran una presentación separada de este estado. La preparación de los estados financieros en conformidad con las Normas de Contabilidad NIIF requiere el uso de ciertas estimaciones de contabilidad críticas. También requiere que la Administración use su juicio en el proceso de la aplicación de las políticas contables de la Compañía. Las áreas que involucran un alto grado de juicio o complejidad, o áreas donde los supuestos y estimaciones son significativos para los estados financieros, se revelan en la Nota 4. | L11: US$ | M11: sin escala | Q11: NIIF, costo histórico; sin OCI. Base contable del modelo. | T11: OK
A12: 2025 | B12: INA_UEPPSA_2025_0.pdf | C12: page-37 | D12: markdown.md | E12: 2. Resumen de las Políticas Contables Materiales | F12: 2. Resumen de las Políticas Contables Materiales | G12: Políticas contables | I12: Nuevas Normas y Enmiendas Adoptadas por la Compañía (NIC 21) | J12: La Compañía ha aplicado las siguientes modificaciones por primera vez para su período de reporte anual que comienza el 1 de enero de 2025: Falta de Convertibilidad - Modificaciones a la NIC 21, “Efectos de las variaciones en las tasas de cambio de la Moneda Extranjera”... La Compañía determinó que las modificaciones no tuvieron un impacto significativo en sus estados financieros. | L12: US$ | M12: sin escala | N12: vigente 1 enero 2025 | T12: OK
A13: 2025 | B13: INA_UEPPSA_2025_0.pdf | C13: page-37 | D13: markdown.md | E13: 2. Resumen de las Políticas Contables Materiales | F13: 2. Resumen de las Políticas Contables Materiales | G13: Políticas contables | I13: Decisiones del Comité de Interpretaciones de las NIIF (NIC 38; garantías) | J13: En 2025 se emitieron las siguientes decisiones que podrían ser relevantes...: Reconocimiento de Activos Intangibles por Gastos Relacionados con el Clima (NIC 38)... Garantías Emitidas sobre Obligaciones de Otras Entidades... La Compañía determinó que las interpretaciones no tuvieron un impacto significativo en sus estados financieros. | L13: US$ | M13: sin escala | T13: OK
A14: 2025 | B14: INA_UEPPSA_2025_0.pdf | C14: page-38 | D14: markdown.md | E14: 2. Resumen de las Políticas Contables Materiales | F14: 2. Resumen de las Políticas Contables Materiales | G14: Políticas contables | I14: Nuevas Normas no Adoptadas (NIIF 9/7 clasificación y medición) | J14: Se han publicado ciertas nuevas normas contables y modificaciones... que la Compañía no ha adoptado anticipadamente. Modificaciones a la Clasificación y Medición de Instrumentos Financieros - Modificaciones a las NIIF 9 y NIIF 7. ... estarán vigentes para los períodos anuales que comiencen a partir del 1 de enero de 2026, permitiéndose su aplicación anticipada. La administración está evaluando las implicaciones detalladas... | L14: US$ | M14: sin escala | N14: vigente 1 enero 2026 | T14: OK
A15: 2025 | B15: INA_UEPPSA_2025_0.pdf | C15: page-38 | D15: markdown.md | E15: 2. Resumen de las Políticas Contables Materiales | F15: 2. Resumen de las Políticas Contables Materiales | G15: Políticas contables | I15: Nuevas Normas no Adoptadas (NIIF 9/7 electricidad dependiente de la naturaleza) | J15: Contratos que Hacen Referencia a la Electricidad Dependiente de la Naturaleza - Modificaciones a las NIIF 9 y NIIF 7: ... (a) aclaran la aplicación del criterio de “uso propio” a los contratos de electricidad dependiente de la naturaleza; (b) permiten la contabilidad de coberturas si estos contratos se utilizan como instrumentos de cobertura; y (c) añaden nuevos requisitos de información a revelar... estarán vigentes para los periodos anuales que comiencen a partir del 1 de enero de 2026, permitiéndose su aplicación anticipada. | L15: US$ | M15: sin escala | N15: vigente 1 enero 2026 | T15: OK
A16: 2025 | B16: INA_UEPPSA_2025_0.pdf | C16: page-38 | D16: markdown.md | E16: 2. Resumen de las Políticas Contables Materiales | F16: 2. Resumen de las Políticas Contables Materiales | G16: Políticas contables | I16: Nuevas Normas no Adoptadas (NIIF 18) | J16: NIIF 18, “Presentación y revelación en estados financieros”... La NIIF 18 entró en vigor el 1 de enero de 2027 y aún no ha sido adoptada por la Compañía. ... La Compañía informa actualmente a los accionistas sobre una medida de EBITDA ajustado. La Compañía espera que esta medida cumpla con la definición de una medida de rendimiento definida por la administración. | L16: US$ | M16: sin escala | N16: vigente 1 enero 2027 | Q16: La Compañía reporta EBITDA ajustado a accionistas (medida de gestión). | T16: OK
A17: 2025 | B17: INA_UEPPSA_2025_0.pdf | C17: page-40 | D17: markdown.md | E17: 2. Resumen de las Políticas Contables Materiales | F17: 2. Resumen de las Políticas Contables Materiales | G17: Políticas contables | I17: Unidad Monetaria y Moneda Funcional | J17: Los estados financieros están expresados en dólares (US$), unidad monetaria de los Estados Unidos de América, la cual está a la par con el Balboa (B/.), unidad monetaria de la República de Panamá. El dólar (US$) circula y es de libre cambio en la República de Panamá y es la moneda funcional. | L17: US$ | M17: sin escala | Q17: Moneda funcional US$ (=B/. 1:1); sin exposición FX material. | T17: OK
A18: 2025 | B18: INA_UEPPSA_2025_0.pdf | C18: page-40 | D18: markdown.md | E18: 2. Resumen de las Políticas Contables Materiales | F18: 2. Resumen de las Políticas Contables Materiales | G18: Segmentos | I18: Información de Segmento | J18: Las operaciones del negocio de la Compañía están organizadas y manejadas como un solo segmento de negocios que es el de operar las plantas generadoras dentro del entorno económico de generación eléctrica. Adicionalmente, la organización interna y de reporte de la Compañía está predominantemente basada en un solo segmento de negocio. | L18: US$ | M18: sin escala | Q18: Un solo segmento (generación eléctrica) → modelo single-segment. | T18: OK
A19: 2025 | B19: INA_UEPPSA_2025_0.pdf | C19: page-40 | D19: markdown.md | E19: 2. Resumen de las Políticas Contables Materiales | F19: 2. Resumen de las Políticas Contables Materiales | G19: Cuentas por cobrar | I19: Activos Financieros / Deudores Comerciales (ECL NIIF 9 simplificado) | J19: La Compañía clasifica sus activos financieros en la categoría de préstamos y cuentas por cobrar... Los deudores se reconocen inicialmente por el monto de la contraprestación... y posteriormente se miden al costo amortizado utilizando el método de interés efectivo, menos la provisión por deterioro... Se establece una provisión por deterioro de cuentas comerciales por cobrar aplicando el enfoque simplificado de la NIIF 9 para medir las pérdidas crediticias esperadas... | L19: US$ | M19: sin escala | P19: AR a costo amortizado; ECL enfoque simplificado. | T19: OK
A20: 2025 | B20: INA_UEPPSA_2025_0.pdf | C20: page-40 | D20: markdown.md | E20: 2. Resumen de las Políticas Contables Materiales | F20: 2. Resumen de las Políticas Contables Materiales | G20: Working capital | I20: Gastos Pagados por Adelantado | J20: Los gastos pagados por anticipado están relacionados principalmente con anticipos a proveedores, seguros pagados por anticipado y cartas de crédito. ... Los gastos pagados por anticipado y otros activos se registran inicialmente como activos, pero su valor se reconoce a lo largo del tiempo en el estado de resultados. | L20: US$ | M20: sin escala | T20: OK
A21: 2025 | B21: INA_UEPPSA_2025_0.pdf | C21: page-41 | D21: markdown.md | E21: 2. Resumen de las Políticas Contables Materiales | F21: 2. Resumen de las Políticas Contables Materiales | G21: PP&E / capex / depreciación | I21: Planta y Equipo | J21: La planta y equipo se registran al costo, menos la depreciación, amortización acumulada y las pérdidas por deterioro. La depreciación y amortización se calculan con el método de línea recta sobre la vida útil estimada del activo. ... La Compañía cuenta con un programa de mantenimiento... basado en las horas de operación equivalentes (EOH). ... La planta y el equipo incluyen los intereses de los financiamientos que se atribuyen directamente a la construcción de los activos. | L21: US$ | M21: sin escala | P21: Depreciación lineal sobre vida útil; capitaliza intereses de construcción. | T21: OK
A22: 2025 | B22: INA_UEPPSA_2025_0.pdf | C22: page-42 | D22: tbl-13.html | E22: 2. Resumen de las Políticas Contables Materiales | F22: 2. Resumen de las Políticas Contables Materiales | G22: PP&E / capex / depreciación | I22: Tasas de depreciación y amortización | J22: Equipo de transporte | L22: US$ | M22: % | N22: 25% | P22: Tasa de depreciación anual por clase de activo (input del schedule de PP&E). | T22: OK
A23: 2025 | B23: INA_UEPPSA_2025_0.pdf | C23: page-42 | D23: tbl-13.html | E23: 2. Resumen de las Políticas Contables Materiales | F23: 2. Resumen de las Políticas Contables Materiales | G23: PP&E / capex / depreciación | I23: Tasas de depreciación y amortización | J23: Edificios | L23: US$ | M23: % | N23: 2.50% | T23: OK
A24: 2025 | B24: INA_UEPPSA_2025_0.pdf | C24: page-42 | D24: tbl-13.html | E24: 2. Resumen de las Políticas Contables Materiales | F24: 2. Resumen de las Políticas Contables Materiales | G24: PP&E / capex / depreciación | I24: Tasas de depreciación y amortización | J24: Herramientas, equipo menor y otros activos | L24: US$ | M24: % | N24: 25% | T24: OK
A25: 2025 | B25: INA_UEPPSA_2025_0.pdf | C25: page-42 | D25: tbl-13.html | E25: 2. Resumen de las Políticas Contables Materiales | F25: 2. Resumen de las Políticas Contables Materiales | G25: PP&E / capex / depreciación | I25: Tasas de depreciación y amortización | J25: Mobiliario y equipo de oficina | L25: US$ | M25: % | N25: 25% | T25: OK
A26: 2025 | B26: INA_UEPPSA_2025_0.pdf | C26: page-42 | D26: tbl-13.html | E26: 2. Resumen de las Políticas Contables Materiales | F26: 2. Resumen de las Políticas Contables Materiales | G26: PP&E / capex / depreciación | I26: Tasas de depreciación y amortización | J26: Instalaciones de planta y generadores | L26: US$ | M26: % | N26: 5% - 10% | P26: Generadores 5%-10% → vida útil ~10-20 años; driver clave de la depreciación. | T26: OK
A27: 2025 | B27: INA_UEPPSA_2025_0.pdf | C27: page-42 | D27: tbl-13.html | E27: 2. Resumen de las Políticas Contables Materiales | F27: 2. Resumen de las Políticas Contables Materiales | G27: PP&E / capex / depreciación | I27: Tasas de depreciación y amortización | J27: Propiedad arrendada | L27: US$ | M27: % | N27: 5% | T27: OK
A28: 2025 | B28: INA_UEPPSA_2025_0.pdf | C28: page-41 | D28: markdown.md | E28: 2. Resumen de las Políticas Contables Materiales | F28: 2. Resumen de las Políticas Contables Materiales | G28: Inventario | I28: Inventario | J28: Consisten en piezas de repuesto consumibles... Los inventarios se valúan al costo o al valor neto realizable, el que sea menor. ... El costo se determina utilizando el método de costo promedio ponderado. Se establece una provisión para el inventario obsoleto de piezas de repuesto... | L28: US$ | M28: sin escala | P28: Inventario = repuestos; costo promedio ponderado. | T28: OK
A29: 2025 | B29: INA_UEPPSA_2025_0.pdf | C29: page-41 | D29: markdown.md | E29: 2. Resumen de las Políticas Contables Materiales | F29: 2. Resumen de las Políticas Contables Materiales | G29: Políticas contables | I29: Deterioro de Activos de Larga Vida | J29: La planta y equipo y otros activos no corrientes... son revisados por deterioro cuando eventos o cambios en las circunstancias indiquen que el valor en libros puede no ser recuperable. Los activos intangibles que tienen una vida útil indefinida no están sujetos a amortización y se prueban anualmente por deterioro... el monto recuperable es el mayor del valor razonable de un activo menos los costos de disposición y el valor en uso. | L29: US$ | M29: sin escala | T29: OK
A30: 2025 | B30: INA_UEPPSA_2025_0.pdf | C30: page-41 | D30: markdown.md | E30: 2. Resumen de las Políticas Contables Materiales | F30: 2. Resumen de las Políticas Contables Materiales | G30: Deuda / bonos / préstamos / leases | I30: Pasivos por Arrendamiento (NIIF 16) | J30: La Compañía aplica la NIIF 16 Arrendamientos... Al inicio de un arrendamiento, la Compañía reconoce un activo por derecho de uso (ROU) y un pasivo por arrendamiento, medido inicialmente al valor presente de los pagos futuros... Los pagos por arrendamiento se descuentan utilizando la tasa de interés implícita en el arrendamiento, cuando sea fácilmente determinable. | L30: US$ | M30: sin escala | P30: ROU/lease bajo NIIF 16; ver Nota 9 (tasa descuento 7.5%). | T30: OK
A31: 2025 | B31: INA_UEPPSA_2025_0.pdf | C31: page-41 | D31: markdown.md | E31: 2. Resumen de las Políticas Contables Materiales | F31: 2. Resumen de las Políticas Contables Materiales | G31: Intangibles | I31: Activos Intangibles - Servidumbre por Derecho de Paso | J31: Servidumbre por Derecho de Paso: Representa el valor atribuible al derecho de paso de una línea de transmisión de alta tensión por un período de 25 años, en virtud de un contrato a largo plazo con el propietario del terreno y las Compañías. Los activos intangibles se reconocen al costo y posteriormente se miden al costo menos la amortización acumulada... a lo largo de su vida útil estimada de 25 años. | L31: US$ | M31: sin escala | N31: 25 años | P31: Intangible = servidumbre, amortización lineal 25 años. | T31: OK
A32: 2025 | B32: INA_UEPPSA_2025_0.pdf | C32: page-41 | D32: markdown.md | E32: 2. Resumen de las Políticas Contables Materiales | F32: 2. Resumen de las Políticas Contables Materiales | G32: Intangibles | I32: Plusvalía | J32: La plusvalía surge y representa el exceso de la contraprestación transferida... sobre el valor razonable de los activos netos identificables adquiridos. La plusvalía no se amortiza, pero se comprueba su deterioro anualmente... | L32: US$ | M32: sin escala | P32: Plusvalía no se amortiza; test de deterioro anual (Nota 11). | T32: OK
A33: 2025 | B33: INA_UEPPSA_2025_0.pdf | C33: page-41 | D33: markdown.md | E33: 2. Resumen de las Políticas Contables Materiales | F33: 2. Resumen de las Políticas Contables Materiales | G33: Cuentas por pagar | I33: Proveedores y Otras Cuentas por Pagar | J33: Los proveedores y otras cuentas por pagar son obligaciones de pago por bienes o servicios... Se reconocen inicialmente a su valor razonable y posteriormente se miden a costo amortizado utilizando el método del interés efectivo. | L33: US$ | M33: sin escala | T33: OK
A34: 2025 | B34: INA_UEPPSA_2025_0.pdf | C34: page-41 | D34: markdown.md | E34: 2. Resumen de las Políticas Contables Materiales | F34: 2. Resumen de las Políticas Contables Materiales | G34: PP&E / capex / depreciación | I34: Provisión - Obligación de Retiro de Activos (ARO) | J34: La provisión para obligaciones por retiro de activos (ARO) se mide al valor actual de los desembolsos que se espera que sean necesarios para liquidar la obligación... La Compañía ha reconocido obligaciones no corrientes para el desmantelamiento y la retirada de sus activos al final de su vida útil. | L34: US$ | M34: sin escala | P34: ARO de desmantelamiento; ver Provisiones (EEFF) y costo financiero de desmantelamiento. | T34: OK
A35: 2025 | B35: INA_UEPPSA_2025_0.pdf | C35: page-41 | D35: markdown.md | E35: 2. Resumen de las Políticas Contables Materiales | F35: 2. Resumen de las Políticas Contables Materiales | G35: Deuda / bonos / préstamos / leases | I35: Bonos por Pagar | J35: Los bonos por pagar se reconocen inicialmente a su valor razonable, neto de los costos de transacción incurridos. Los bonos por pagar se registran posteriormente a costo amortizado utilizando el método de interés efectivo; se clasifican como pasivos corrientes a menos que la Compañía mantenga el derecho incondicional de diferir el pasivo durante al menos doce meses... | L35: US$ | M35: sin escala | P35: Bonos a costo amortizado (interés efectivo); ver Nota 13. | T35: OK
A36: 2025 | B36: INA_UEPPSA_2025_0.pdf | C36: page-41 | D36: markdown.md | E36: 2. Resumen de las Políticas Contables Materiales | F36: 2. Resumen de las Políticas Contables Materiales | G36: Intereses | I36: Costos Financieros | J36: Los costos financieros generales y específicos directamente atribuidos a la adquisición, construcción o producción de activos calificados... se añaden al costo de dichos activos... Todos los costos financieros se reconocen en el estado del resultado en el período en que se incurren. | L36: US$ | M36: sin escala | T36: OK
A37: 2025 | B37: INA_UEPPSA_2025_0.pdf | C37: page-41 | D37: markdown.md | E37: 2. Resumen de las Políticas Contables Materiales | F37: 2. Resumen de las Políticas Contables Materiales | G37: Impuestos | I37: Impuesto sobre la Renta Corriente y Diferido | J37: El gasto del impuesto sobre la renta para el período comprende del impuesto sobre la renta corriente y diferido... El impuesto sobre la renta diferido se provisiona en su totalidad utilizando el método de pasivo, cuando surgen diferencias temporarias entre las bases fiscales de los activos y pasivos y sus valores en libros... se determina utilizando las tasas impositivas que han sido promulgadas o sustancialmente promulgadas a la fecha del balance general... | L37: US$ | M37: sin escala | P37: ISR corriente + diferido (método de pasivo). Ver Nota 18 (tasa 25%/CAIR). | T37: OK
A38: 2025 | B38: INA_UEPPSA_2025_0.pdf | C38: page-41 | D38: markdown.md | E38: 2. Resumen de las Políticas Contables Materiales | F38: 2. Resumen de las Políticas Contables Materiales | G38: Opex | I38: Beneficio a Empleados | J38: Plan de Beneficios Definidos para Colaboradores (prima de antigüedad e indemnización): La Ley del Trabajo panameña estableció una prima de antigüedad de servicio... equivalente al 1.92% de los salarios pagados en el año... La Ley No. 44 de 12 de agosto de 1995 estableció... la obligación del empleador de constituir un fondo de cesantías... Plan de Contribución Definida: De acuerdo con la Ley No.51 del 27 de diciembre de 2005... La contribución para el año asciende a US$41,351 (2024: US$36,259). | K38: 41351 | L38: US$ | M38: sin escala | N38: prima antigüedad 1.92% | P38: Beneficios laborales (prima antigüedad 1.92%; fondo de cesantía). | T38: OK
A39: 2025 | B39: INA_UEPPSA_2025_0.pdf | C39: page-41 | D39: markdown.md | E39: 2. Resumen de las Políticas Contables Materiales | F39: 2. Resumen de las Políticas Contables Materiales | G39: Capital / patrimonio / dividendos | I39: Patrimonio | J39: El patrimonio está constituido por: Acciones comunes... acciones ordinarias nominativas no endosables de US$1 de valor nominal cada una. Contribución de capital: representa el exceso sobre el valor nominal del valor razonable de la contraprestación recibida... Déficit acumulado: representa las ganancias y pérdidas acumuladas. Se realiza una provisión para dividendos por el monto de cualquier dividendo declarado, debidamente autorizado por la Junta Directiva... | L39: US$ | M39: sin escala | T39: OK
A40: 2025 | B40: INA_UEPPSA_2025_0.pdf | C40: page-41 | D40: markdown.md | E40: 2. Resumen de las Políticas Contables Materiales | F40: 2. Resumen de las Políticas Contables Materiales | G40: Ingresos | I40: Reconocimiento de Ingresos por Energía (NIIF 15) | J40: La Compañía reconoce los ingresos por energía en los períodos en que entrega electricidad. Los precios contratados son facturados según las provisiones aplicables a los contratos de venta de energía y las ventas de mercado ocasional se facturan según los precios actuales del mercado. La unidad de medida de los precios contratados es dólar por megavatio hora ($/MWh). ... Según la NIIF 15, la Compañía reconoció los ingresos de los contratos con clientes en base al modelo de cinco pasos... la Compañía continúa reconociendo ingresos a lo largo del tiempo en lugar de un tiempo determinado. | L40: US$ | M40: $/MWh | P40: Ingreso = energía entregada; PPA + mercado ocasional; precios en $/MWh. | Q40: Driver de ingresos: MWh × $/MWh (contratado vs ocasional). | T40: OK
A41: 2025 | B41: INA_UEPPSA_2025_0.pdf | C41: page-47 | D41: markdown.md | E41: 3. Administración de Riesgos Financieros | F41: 3. Administración de Riesgos Financieros | G41: Riesgo financiero | I41: Factores de Riesgos Financieros | J41: Las actividades de la Compañía la exponen a una variedad de riesgos financieros: riesgo de mercado (incluyendo riesgo de moneda, riesgo de tasa de interés del valor razonable y riesgo de tasa de interés de flujo de efectivo), riesgo de crédito y riesgo de liquidez. La gestión del riesgo financiero es llevada a cabo por el Gerente General y el Director del Departamento de Finanzas bajo la supervisión de la Junta Directiva. | L41: US$ | M41: sin escala | T41: OK
...

Sheet ModeloFinanciero
A1: UEP Penonomé II, S. A.
A2: Estados Financieros Auditados FY21-FY25
A3: en US$ sin escala
A5: Años | B5: FY21A | C5: FY22A | D5: FY23A | E5: FY24A | F5: FY25A | G5: FY26E | H5: FY27E | I5: FY28E | J5: FY29E | K5: FY30E
A6: Estado de Resultado
A7: Ingresos por energía | B7: =EEFF!B7 -> 42036085 | C7: =EEFF!C7 -> 40987418 | D7: =EEFF!D7 -> 54587421 | E7: =EEFF!E7 -> 42653811 | F7: =EEFF!F7 -> 42404701 | G7: =Supuestos!G44 -> 41719195 | H7: =Supuestos!H44 -> 41713333 | I7: =Supuestos!I44 -> 41708092 | J7: =Supuestos!J44 -> 34098586 | K7: =Supuestos!K44 -> 27211924
A8: Costos de bienes y servicios | B8: =EEFF!B8 -> -22857327 | C8: =EEFF!C8 -> -21858853 | D8: =EEFF!D8 -> -25573871 | E8: =EEFF!E8 -> -25736347 | F8: =EEFF!F8 -> -24413955 | G8: =-Supuestos!G54 -> -22731827 | H8: =-Supuestos!H54 -> -22738827 | I8: =-Supuestos!I54 -> -22746827 | J8: =-Supuestos!J54 -> -22594738 | K8: =-Supuestos!K54 -> -22603738
A9: Utilidad bruta | B9: =EEFF!B9 -> 19178758 | C9: =EEFF!C9 -> 19128565 | D9: =EEFF!D9 -> 29013550 | E9: =EEFF!E9 -> 16917464 | F9: =EEFF!F9 -> 17990746 | G9: =G7+G8 -> 18987368 | H9: =H7+H8 -> 18974506 | I9: =I7+I8 -> 18961265 | J9: =J7+J8 -> 11503848 | K9: =K7+K8 -> 4608185.5
A10: Gastos administrativos | B10: =EEFF!B10 -> -3266942 | C10: =EEFF!C10 -> -3405988 | D10: =EEFF!D10 -> -4482435 | E10: =EEFF!E10 -> -3436087 | F10: =EEFF!F10 -> -3908720 | G10: =-Supuestos!G58 -> -3660000 | H10: =-Supuestos!H58 -> -3660000 | I10: =-Supuestos!I58 -> -3660000 | J10: =-Supuestos!J58 -> -3660000 | K10: =-Supuestos!K58 -> -3660000
A11: Utilidad operativa | B11: =EEFF!B11 -> 15911816 | C11: =EEFF!C11 -> 15722577 | D11: =EEFF!D11 -> 24531115 | E11: =EEFF!E11 -> 13481377 | F11: =EEFF!F11 -> 14082026 | G11: =G9+G10 -> 15327368 | H11: =H9+H10 -> 15314506 | I11: =I9+I10 -> 15301265 | J11: =J9+J10 -> 7843848.1 | K11: =K9+K10 -> 948185.54
A12: Costos financieros, neto | B12: =EEFF!B12 -> -14126147 | C12: =EEFF!C12 -> -9881077 | D12: =EEFF!D12 -> -16142876 | E12: =EEFF!E12 -> -15193459 | F12: =EEFF!F12 -> -14336109 | G12: =F12 -> -14336109 | H12: =G12 -> -14336109 | I12: =H12 -> -14336109 | J12: =I12 -> -14336109 | K12: =J12 -> -14336109
A13: Otros ingresos | B13: =EEFF!B13 -> 34397 | C13: =EEFF!C13 -> 130429 | D13: =EEFF!D13 -> 6770 | E13: =EEFF!E13 -> 1010 | F13: =EEFF!F13 -> 81975 | G13: =F13 -> 81975 | H13: =G13 -> 81975 | I13: =H13 -> 81975 | J13: =I13 -> 81975 | K13: =J13 -> 81975
A14: Pérdida antes del impuesto sobre la renta | B14: =EEFF!B14 -> 1820066 | C14: =EEFF!C14 -> 5971929 | D14: =EEFF!D14 -> 8395009 | E14: =EEFF!E14 -> -1711072 | F14: =EEFF!F14 -> -172108 | G14: =G11+G12+G13 -> 1073234.2 | H14: =H11+H12+H13 -> 1060371.9 | I14: =I11+I12+I13 -> 1047131.1 | J14: =J11+J12+J13 -> -6410285.9 | K14: =K11+K12+K13 -> -13305948
A15: Impuesto sobre la renta | B15: =EEFF!B15 -> -2683428 | C15: =EEFF!C15 -> 599370 | D15: =EEFF!D15 -> -820467 | E15: =EEFF!E15 -> -681267 | F15: =EEFF!F15 -> -497187 | G15: =F15 -> -497187 | H15: =G15 -> -497187 | I15: =H15 -> -497187 | J15: =I15 -> -497187 | K15: =J15 -> -497187
A16: Pérdida del año | B16: =EEFF!B16 -> -863362 | C16: =EEFF!C16 -> 6571299 | D16: =EEFF!D16 -> 7574542 | E16: =EEFF!E16 -> -2392339 | F16: =EEFF!F16 -> -669295 | G16: =G14+G15 -> 576047.2 | H16: =H14+H15 -> 563184.88 | I16: =I14+I15 -> 549944.09 | J16: =J14+J15 -> -6907472.9 | K16: =K14+K15 -> -13803135
A18: Años | B18: FY21A | C18: FY22A | D18: FY23A | E18: FY24A | F18: FY25A | G18: FY26E | H18: FY27E | I18: FY28E | J18: FY29E | K18: FY30E
A19: Balance General
A20: Efectivo y equivalentes de efectivo | B20: =EEFF!B20 -> 5485501 | C20: =EEFF!C20 -> 5490195 | D20: =EEFF!D20 -> 17396949 | E20: =EEFF!E20 -> 4118908 | F20: =EEFF!F20 -> 5197344 | G20: =F20 -> 5197344 | H20: =G20 -> 5197344 | I20: =H20 -> 5197344 | J20: =I20 -> 5197344 | K20: =J20 -> 5197344
A21: Deudores comerciales y otras cuentas por cobrar | B21: =EEFF!B21 -> 8440721 | C21: =EEFF!C21 -> 6989164 | D21: =EEFF!D21 -> 7127866 | E21: =EEFF!E21 -> 3904545 | F21: =EEFF!F21 -> 4837614 | G21: =F21 -> 4837614 | H21: =G21 -> 4837614 | I21: =H21 -> 4837614 | J21: =I21 -> 4837614 | K21: =J21 -> 4837614
A22: Deuda por cobrar a parte relacionada | B22: =EEFF!B28 -> 21480114 | C22: =EEFF!C28 -> 20483131 | D22: =EEFF!D28 -> 19345052 | E22: =EEFF!E28 -> 18105378 | F22: =EEFF!F28 -> 16773057 | G22: =F22 -> 16773057 | H22: =G22 -> 16773057 | I22: =H22 -> 16773057 | J22: =I22 -> 16773057 | K22: =J22 -> 16773057
A23: Gastos pagados por adelantado | B23: =EEFF!B23 -> 1954336 | C23: =EEFF!C23 -> 4991808 | D23: =EEFF!D23 -> 1291507 | E23: =EEFF!E23 -> 1963129 | F23: =EEFF!F23 -> 860787 | G23: =F23 -> 860787 | H23: =G23 -> 860787 | I23: =H23 -> 860787 | J23: =I23 -> 860787 | K23: =J23 -> 860787
A24: Inventario | B24: =EEFF!B24 -> 38791 | C24: =EEFF!C24 -> 40685 | D24: =EEFF!D24 -> 51726 | E24: =EEFF!E24 -> 71702 | F24: =EEFF!F24 -> 84203 | G24: =F24 -> 84203 | H24: =G24 -> 84203 | I24: =H24 -> 84203 | J24: =I24 -> 84203 | K24: =J24 -> 84203
A25: Total de activos corrientes | B25: =EEFF!B25 -> 16818281 | C25: =EEFF!C25 -> 18508834 | D25: =EEFF!D25 -> 27006128 | E25: =EEFF!E25 -> 11297958 | F25: =EEFF!F25 -> 12312270 | G25: =F25 -> 12312270 | H25: =G25 -> 12312270 | I25: =H25 -> 12312270 | J25: =I25 -> 12312270 | K25: =J25 -> 12312270
A26: Planta y equipo, neto | B26: =EEFF!B26 -> 216209163 | C26: =EEFF!C26 -> 202848696 | D26: =EEFF!D26 -> 193996920 | E26: =EEFF!E26 -> 180311071 | F26: =EEFF!F26 -> 167298071 | G26: =F26 -> 167298071 | H26: =G26 -> 167298071 | I26: =H26 -> 167298071 | J26: =I26 -> 167298071 | K26: =J26 -> 167298071
A27: Plusvalía | B27: =EEFF!B27 -> 20000000 | C27: =EEFF!C27 -> 20000000 | D27: =EEFF!D27 -> 20000000 | E27: =EEFF!E27 -> 20000000 | F27: =EEFF!F27 -> 20000000 | G27: =F27 -> 20000000 | H27: =G27 -> 20000000 | I27: =H27 -> 20000000 | J27: =I27 -> 20000000 | K27: =J27 -> 20000000
A28: Deuda por cobrar a parte relacionada | B28: =EEFF!B28 -> 21480114 | C28: =EEFF!C28 -> 20483131 | D28: =EEFF!D28 -> 19345052 | E28: =EEFF!E28 -> 18105378 | F28: =EEFF!F28 -> 16773057 | G28: =F28 -> 16773057 | H28: =G28 -> 16773057 | I28: =H28 -> 16773057 | J28: =I28 -> 16773057 | K28: =J28 -> 16773057
A29: Activos intangibles, neto | B29: =EEFF!B29 -> 109685 | C29: =EEFF!C29 -> 105268 | D29: =EEFF!D29 -> 100851 | E29: =EEFF!E29 -> 96435 | F29: =EEFF!F29 -> 92018 | G29: =F29 -> 92018 | H29: =G29 -> 92018 | I29: =H29 -> 92018 | J29: =I29 -> 92018 | K29: =J29 -> 92018
A30: Fondo de cesantía | B30: =EEFF!B30 -> 0 | C30: =EEFF!C30 -> 13934 | D30: =EEFF!D30 -> 17359 | E30: =EEFF!E30 -> 21782 | F30: =EEFF!F30 -> 26510 | G30: =F30 -> 26510 | H30: =G30 -> 26510 | I30: =H30 -> 26510 | J30: =I30 -> 26510 | K30: =J30 -> 26510
A31: Total de activos no corrientes | B31: =EEFF!B31 -> 257798962 | C31: =EEFF!C31 -> 243451029 | D31: =EEFF!D31 -> 233460182 | E31: =EEFF!E31 -> 218534666 | F31: =EEFF!F31 -> 204189656 | G31: =F31 -> 204189656 | H31: =G31 -> 204189656 | I31: =H31 -> 204189656 | J31: =I31 -> 204189656 | K31: =J31 -> 204189656
A32: Total de activos | B32: =EEFF!B32 -> 274617243 | C32: =EEFF!C32 -> 261959863 | D32: =EEFF!D32 -> 260466310 | E32: =EEFF!E32 -> 229832624 | F32: =EEFF!F32 -> 216501926 | G32: =F32 -> 216501926 | H32: =G32 -> 216501926 | I32: =H32 -> 216501926 | J32: =I32 -> 216501926 | K32: =J32 -> 216501926
A33: Bonos por pagar | B33: =EEFF!B40 -> 234949078 | C33: =EEFF!C40 -> 224181572 | D33: =EEFF!D40 -> 211820687 | E33: =EEFF!E40 -> 198290030 | F33: =EEFF!F40 -> 183665429 | G33: =F33 -> 183665429 | H33: =G33 -> 183665429 | I33: =H33 -> 183665429 | J33: =I33 -> 183665429 | K33: =J33 -> 183665429
A34: Proveedores y otras cuentas por pagar | B34: =EEFF!B34 -> 2652919 | C34: =EEFF!C34 -> 1285733 | D34: =EEFF!D34 -> 2536737 | E34: =EEFF!E34 -> 1419947 | F34: =EEFF!F34 -> 2311149 | G34: =F34 -> 2311149 | H34: =G34 -> 2311149 | I34: =H34 -> 2311149 | J34: =I34 -> 2311149 | K34: =J34 -> 2311149
A35: Pasivos por arrendamiento | B35: =EEFF!B37 -> 8232437 | C35: =EEFF!C37 -> 8040342 | D35: =EEFF!D37 -> 7810454 | E35: =EEFF!E37 -> 7539044 | F35: =EEFF!F37 -> 7222062 | G35: =F35 -> 7222062 | H35: =G35 -> 7222062 | I35: =H35 -> 7222062 | J35: =I35 -> 7222062 | K35: =J35 -> 7222062
A36: Total de pasivos corrientes | B36: =EEFF!B36 -> 17110509 | C36: =EEFF!C36 -> 16717953 | D36: =EEFF!D36 -> 19394070 | E36: =EEFF!E36 -> 19275472 | F36: =EEFF!F36 -> 21028313 | G36: =F36 -> 21028313 | H36: =G36 -> 21028313 | I36: =H36 -> 21028313 | J36: =I36 -> 21028313 | K36: =J36 -> 21028313
A37: Pasivos por arrendamiento | B37: =EEFF!B37 -> 8232437 | C37: =EEFF!C37 -> 8040342 | D37: =EEFF!D37 -> 7810454 | E37: =EEFF!E37 -> 7539044 | F37: =EEFF!F37 -> 7222062 | G37: =F37 -> 7222062 | H37: =G37 -> 7222062 | I37: =H37 -> 7222062 | J37: =I37 -> 7222062 | K37: =J37 -> 7222062
A38: Impuesto sobre la renta diferido | B38: =EEFF!B38 -> 1204764 | C38: =EEFF!C38 -> 605394 | D38: =EEFF!D38 -> 1425861 | E38: =EEFF!E38 -> 2107128 | F38: =EEFF!F38 -> 2604315 | G38: =F38 -> 2604315 | H38: =G38 -> 2604315 | I38: =H38 -> 2604315 | J38: =I38 -> 2604315 | K38: =J38 -> 2604315
A39: Provisiones | B39: =EEFF!B39 -> 0 | C39: =EEFF!C39 -> 347922 | D39: =EEFF!D39 -> 374016 | E39: =EEFF!E39 -> 402067 | F39: =EEFF!F39 -> 432222 | G39: =F39 -> 432222 | H39: =G39 -> 432222 | I39: =H39 -> 432222 | J39: =I39 -> 432222 | K39: =J39 -> 432222
A40: Bonos por pagar | B40: =EEFF!B40 -> 234949078 | C40: =EEFF!C40 -> 224181572 | D40: =EEFF!D40 -> 211820687 | E40: =EEFF!E40 -> 198290030 | F40: =EEFF!F40 -> 183665429 | G40: =F40 -> 183665429 | H40: =G40 -> 183665429 | I40: =H40 -> 183665429 | J40: =I40 -> 183665429 | K40: =J40 -> 183665429
A41: Instrumento financiero derivado | B41: =EEFF!B41 -> 7625074 | C41: =EEFF!C41 -> 0 | D41: =EEFF!D41 -> 0 | E41: =EEFF!E41 -> 0 | F41: =EEFF!F41 -> 0
A42: Total de pasivos no corrientes | B42: =EEFF!B42 -> 252011353 | C42: =EEFF!C42 -> 233175230 | D42: =EEFF!D42 -> 221431018 | E42: =EEFF!E42 -> 208338269 | F42: =EEFF!F42 -> 193924028 | G42: =F42 -> 193924028 | H42: =G42 -> 193924028 | I42: =H42 -> 193924028 | J42: =I42 -> 193924028 | K42: =J42 -> 193924028
...

Sheet _CHECKS
A1: UEP Penonomé II, S. A.
A2: _CHECKS panel — power template, live formulas, known residuals signed visible
A3: Status semantics: PASS = zero undocumented hard failures; KNOWN_RESIDUAL = signed G7 residual; SOURCE_GAP = unresolved semantic anchor/schedule.
A4: MASTER_STATUS | B4: MODEL STATUS | C4: =IF(COUNTIF($C$6:$C$37,"FAIL")=0,"PASS","FAIL") -> PASS | G4: Master PASS counts only FAIL rows; KNOWN_RESIDUAL/SOURCE_GAP remain visible but non-blocking.
A5: check_id | B5: description | C5: status | D5: hardness | E5: tolerance | F5: expected | G5: note | H5: FY21A | I5: FY22A | J5: FY23A | K5: FY24A | L5: FY25A | M5: FY26E | N5: FY27E | O5: FY28E | P5: FY29E | Q5: FY30E
A7: UNIVERSAL CHECKS
A8: BS_BALANCE | B8: UNIVERSAL | expected 0; hard fail if ABS(value) > hard_tie_tolerance. Observed: UEPII critical gate <10 for BS/cash; BG hard reconciliation >=1000 because full USD. | source applies_to: all 16 archetypes | C8: =IF(SUMPRODUCT((ABS(H8:Q8)>1000)*1)=0,"PASS","FAIL") -> PASS | D8: hard | E8: 1000 USD | F8: 0 | G8: expected 0; hard fail if ABS(value) > hard_tie_tolerance. Observed: UEPII critical gate <10 for BS/cash; BG hard reconciliation >=1000 because full USD. Default full-USD hard tie threshold is $1,000 unless the workbook declares a tighter scale-aware tolerance. | H8: =ModeloFinanciero!B32-ModeloFinanciero!B49 -> 0 | I8: =ModeloFinanciero!C32-ModeloFinanciero!C49 -> 0 | J8: =ModeloFinanciero!D32-ModeloFinanciero!D49 -> 0 | K8: =ModeloFinanciero!E32-ModeloFinanciero!E49 -> 0 | L8: =ModeloFinanciero!F32-ModeloFinanciero!F49 -> 0 | M8: =ModeloFinanciero!G32-ModeloFinanciero!G49 -> 0 | N8: =ModeloFinanciero!H32-ModeloFinanciero!H49 -> 0 | O8: =ModeloFinanciero!I32-ModeloFinanciero!I49 -> 0 | ... Q8: =ModeloFinanciero!K32-ModeloFinanciero!K49 -> 0
A9: CASH_TIE | B9: UNIVERSAL | expected 0; use hard_tie_tolerance; if cash includes restricted cash/time deposits, define cash_component role explicitly. | source applies_to: all 16 archetypes | C9: =IF(SUMPRODUCT((ABS(H9:Q9)>1000)*1)=0,"PASS","FAIL") -> PASS | D9: hard | E9: 1000 USD | F9: 0 | G9: Observed hard tie threshold for model-to-model cash residuals; define cash-component role when restricted cash/time deposits exist. | H9: =ModeloFinanciero!B81-ModeloFinanciero!B20 -> 0 | I9: =ModeloFinanciero!C81-ModeloFinanciero!C20 -> 0 | J9: =ModeloFinanciero!D81-ModeloFinanciero!D20 -> 0 | K9: =ModeloFinanciero!E81-ModeloFinanciero!E20 -> 0 | L9: =ModeloFinanciero!F81-ModeloFinanciero!F20 -> 0
A10: CF_ROLLFORWARD | B10: UNIVERSAL | expected 0; hard_tie_tolerance; historical rows may be WARN if source CF transcript is incomplete. | source applies_to: all 16 where CF is modeled | C10: =IF(SUMPRODUCT((ABS(H10:Q10)>1000)*1)=0,"PASS","FAIL") -> PASS | D10: hard | E10: 1000 USD | F10: 0 | G10: expected 0; hard_tie_tolerance; historical rows may be WARN if source CF transcript is incomplete. Default full-USD hard tie threshold is $1,000 unless the workbook declares a tighter scale-aware tolerance. | H10: =ModeloFinanciero!B64+ModeloFinanciero!B69+ModeloFinanciero!B78-(ModeloFinanciero!B81-ModeloFinanciero!B80) -> 0 | I10: =ModeloFinanciero!C64+ModeloFinanciero!C69+ModeloFinanciero!C78-(ModeloFinanciero!C81-ModeloFinanciero!C80) -> 0 | J10: =ModeloFinanciero!D64+ModeloFinanciero!D69+ModeloFinanciero!D78-(ModeloFinanciero!D81-ModeloFinanciero!D80) -> 0 | K10: =ModeloFinanciero!E64+ModeloFinanciero!E69+ModeloFinanciero!E78-(ModeloFinanciero!E81-ModeloFinanciero!E80) -> 0 | L10: =ModeloFinanciero!F64+ModeloFinanciero!F69+ModeloFinanciero!F78-(ModeloFinanciero!F81-ModeloFinanciero!F80) -> 0 | M10: =ModeloFinanciero!G64+ModeloFinanciero!G69+ModeloFinanciero!G78-(ModeloFinanciero!G81-ModeloFinanciero!G80) -> 0 | N10: =ModeloFinanciero!H64+ModeloFinanciero!H69+ModeloFinanciero!H78-(ModeloFinanciero!H81-ModeloFinanciero!H80) -> 0 | O10: =ModeloFinanciero!I64+ModeloFinanciero!I69+ModeloFinanciero!I78-(ModeloFinanciero!I81-ModeloFinanciero!I80) -> 0 | ... Q10: =ModeloFinanciero!K64+ModeloFinanciero!K69+ModeloFinanciero!K78-(ModeloFinanciero!K81-ModeloFinanciero!K80) -> 0
A11: NI_TIE_TO_EQUITY | B11: UNIVERSAL | expected 0; hard_tie_tolerance. | source applies_to: all 16 | C11: SOURCE_GAP | D11: hard | E11: 1000 USD | F11: 0 | G11: No semantic anchors resolved for NI_TIE_TO_EQUITY. | H11: =0 -> 0 | I11: =0 -> 0 | J11: =0 -> 0 | K11: =0 -> 0 | L11: =0 -> 0 | M11: =0 -> 0 | N11: =0 -> 0 | O11: =0 -> 0 | ... Q11: =0 -> 0
A12: NI_SIGN_SANITY | B12: UNIVERSAL | expected 0; sign convention must be stated in row description. | source applies_to: all 16 | C12: SOURCE_GAP | D12: hard | E12: 1000 USD | F12: 0 | G12: No semantic anchors resolved for NI_SIGN_SANITY. | H12: =0 -> 0 | I12: =0 -> 0 | J12: =0 -> 0 | K12: =0 -> 0 | L12: =0 -> 0 | M12: =0 -> 0 | N12: =0 -> 0 | O12: =0 -> 0 | ... Q12: =0 -> 0
A13: RE_ROLLFORWARD | B13: UNIVERSAL | expected 0; hard_tie_tolerance. | source applies_to: all 16 with RE row | C13: SOURCE_GAP | D13: hard | E13: 1000 USD | F13: 0 | G13: No semantic anchors resolved for RE_ROLLFORWARD. | H13: =0 -> 0 | I13: =0 -> 0 | J13: =0 -> 0 | K13: =0 -> 0 | L13: =0 -> 0 | M13: =0 -> 0 | N13: =0 -> 0 | O13: =0 -> 0 | ... Q13: =0 -> 0
A14: EQUITY_TOTAL_TIE | B14: UNIVERSAL | expected 0; hard_tie_tolerance. | source applies_to: all 16 | C14: =IF(SUMPRODUCT((ABS(H14:Q14)>1000)*1)=0,"PASS","FAIL") -> PASS | D14: hard | E14: 1000 USD | F14: 0 | G14: expected 0; hard_tie_tolerance. Default full-USD hard tie threshold is $1,000 unless the workbook declares a tighter scale-aware tolerance. | H14: =SUM(ModeloFinanciero!B44,ModeloFinanciero!B45,ModeloFinanciero!B46,ModeloFinanciero!B47)-ModeloFinanciero!B48 -> 0 | I14: =SUM(ModeloFinanciero!C44,ModeloFinanciero!C45,ModeloFinanciero!C46,ModeloFinanciero!C47)-ModeloFinanciero!C48 -> 0 | J14: =SUM(ModeloFinanciero!D44,ModeloFinanciero!D45,ModeloFinanciero!D46,ModeloFinanciero!D47)-ModeloFinanciero!D48 -> 0 | K14: =SUM(ModeloFinanciero!E44,ModeloFinanciero!E45,ModeloFinanciero!E46,ModeloFinanciero!E47)-ModeloFinanciero!E48 -> 0 | L14: =SUM(ModeloFinanciero!F44,ModeloFinanciero!F45,ModeloFinanciero!F46,ModeloFinanciero!F47)-ModeloFinanciero!F48 -> 0 | M14: =SUM(ModeloFinanciero!G44,ModeloFinanciero!G45,ModeloFinanciero!G46,ModeloFinanciero!G47)-ModeloFinanciero!G48 -> 0 | N14: =SUM(ModeloFinanciero!H44,ModeloFinanciero!H45,ModeloFinanciero!H46,ModeloFinanciero!H47)-ModeloFinanciero!H48 -> 0 | O14: =SUM(ModeloFinanciero!I44,ModeloFinanciero!I45,ModeloFinanciero!I46,ModeloFinanciero!I47)-ModeloFinanciero!I48 -> 0 | ... Q14: =SUM(ModeloFinanciero!K44,ModeloFinanciero!K45,ModeloFinanciero!K46,ModeloFinanciero!K47)-ModeloFinanciero!K48 -> 0
A15: BS_LINEITEM_SUM_ASSETS | B15: UNIVERSAL | expected 0; hard_tie_tolerance. | source applies_to: all 16 | C15: =IF(SUMPRODUCT((ABS(H15:Q15)>1000)*1)=0,"PASS","FAIL") -> PASS | D15: hard | E15: 1000 USD | F15: 0 | G15: expected 0; hard_tie_tolerance. Default full-USD hard tie threshold is $1,000 unless the workbook declares a tighter scale-aware tolerance. | H15: =SUM(ModeloFinanciero!B25,ModeloFinanciero!B31)-ModeloFinanciero!B32 -> 0 | I15: =SUM(ModeloFinanciero!C25,ModeloFinanciero!C31)-ModeloFinanciero!C32 -> 0 | J15: =SUM(ModeloFinanciero!D25,ModeloFinanciero!D31)-ModeloFinanciero!D32 -> 0 | K15: =SUM(ModeloFinanciero!E25,ModeloFinanciero!E31)-ModeloFinanciero!E32 -> 0 | L15: =SUM(ModeloFinanciero!F25,ModeloFinanciero!F31)-ModeloFinanciero!F32 -> 0 | M15: =SUM(ModeloFinanciero!G25,ModeloFinanciero!G31)-ModeloFinanciero!G32 -> 0 | N15: =SUM(ModeloFinanciero!H25,ModeloFinanciero!H31)-ModeloFinanciero!H32 -> 0 | O15: =SUM(ModeloFinanciero!I25,ModeloFinanciero!I31)-ModeloFinanciero!I32 -> 0 | ... Q15: =SUM(ModeloFinanciero!K25,ModeloFinanciero!K31)-ModeloFinanciero!K32 -> 0
A16: BS_LINEITEM_SUM_LIAB_EQUITY | B16: UNIVERSAL | expected 0; hard_tie_tolerance. | source applies_to: all 16 | C16: =IF(SUMPRODUCT((ABS(H16:Q16)>1000)*1)=0,"PASS","FAIL") -> PASS | D16: hard | E16: 1000 USD | F16: 0 | G16: expected 0; hard_tie_tolerance. Default full-USD hard tie threshold is $1,000 unless the workbook declares a tighter scale-aware tolerance. | H16: =ModeloFinanciero!B43+ModeloFinanciero!B48-ModeloFinanciero!B49 -> 0 | I16: =ModeloFinanciero!C43+ModeloFinanciero!C48-ModeloFinanciero!C49 -> 0 | J16: =ModeloFinanciero!D43+ModeloFinanciero!D48-ModeloFinanciero!D49 -> 0 | K16: =ModeloFinanciero!E43+ModeloFinanciero!E48-ModeloFinanciero!E49 -> 0 | L16: =ModeloFinanciero!F43+ModeloFinanciero!F48-ModeloFinanciero!F49 -> 0 | M16: =ModeloFinanciero!G43+ModeloFinanciero!G48-ModeloFinanciero!G49 -> 0 | N16: =ModeloFinanciero!H43+ModeloFinanciero!H48-ModeloFinanciero!H49 -> 0 | O16: =ModeloFinanciero!I43+ModeloFinanciero!I48-ModeloFinanciero!I49 -> 0 | ... Q16: =ModeloFinanciero!K43+ModeloFinanciero!K48-ModeloFinanciero!K49 -> 0
A17: SOURCE_TIE_HISTORICAL | B17: UNIVERSAL | expected 0 for audited rows; SOURCE_GAP/WARN allowed only with explicit source-gap note. | source applies_to: all 16 | C17: =IF(SUMPRODUCT((ABS(H17:Q17)>100000)*1)=0,"PASS","FAIL") -> PASS | D17: hard | E17: 100000 USD | F17: 0 | G17: Audited rows tie to 0; only bank ending-cash-vs-EEFF cash rows may use the observed $100,000 hard threshold; SOURCE_GAP/WARN requires explicit source-gap note. | H17: =ModeloFinanciero!B32-EEFF!B32 -> 0 | I17: =ModeloFinanciero!C32-EEFF!C32 -> 0 | J17: =ModeloFinanciero!D32-EEFF!D32 -> 0 | K17: =ModeloFinanciero!E32-EEFF!E32 -> 0 | L17: =ModeloFinanciero!F32-EEFF!F32 -> 0
A18: NO_FORMULA_ERRORS | B18: UNIVERSAL | expected PASS/0; no masking. | source applies_to: all 16 | C18: =IF(SUMPRODUCT((ABS(H18:Q18)>0)*1)=0,"PASS","FAIL") -> PASS | D18: hard | E18: PASS | F18: PASS | G18: expected PASS/0; no masking. | H18: =0 -> 0 | I18: =0 -> 0 | J18: =0 -> 0 | K18: =0 -> 0 | L18: =0 -> 0 | M18: =0 -> 0 | N18: =0 -> 0 | O18: =0 -> 0 | ... Q18: =0 -> 0
A19: NO_CHECKS_MASTER_FAIL | B19: UNIVERSAL | expected PASS; status row should cite included/excluded rows. | source applies_to: all 16 | C19: =IF(SUMPRODUCT((ABS(H19:Q19)>0)*1)=0,"PASS","FAIL") -> PASS | D19: hard | E19: PASS | F19: PASS | G19: expected PASS; status row should cite included/excluded rows. | H19: =COUNTIF($C$6:$C$18,"FAIL")+COUNTIF($C$20:$C$37,"FAIL") -> 0 | I19: =COUNTIF($C$6:$C$18,"FAIL")+COUNTIF($C$20:$C$37,"FAIL") -> 0 | J19: =COUNTIF($C$6:$C$18,"FAIL")+COUNTIF($C$20:$C$37,"FAIL") -> 0 | K19: =COUNTIF($C$6:$C$18,"FAIL")+COUNTIF($C$20:$C$37,"FAIL") -> 0 | L19: =COUNTIF($C$6:$C$18,"FAIL")+COUNTIF($C$20:$C$37,"FAIL") -> 0 | M19: =COUNTIF($C$6:$C$18,"FAIL")+COUNTIF($C$20:$C$37,"FAIL") -> 0 | N19: =COUNTIF($C$6:$C$18,"FAIL")+COUNTIF($C$20:$C$37,"FAIL") -> 0 | O19: =COUNTIF($C$6:$C$18,"FAIL")+COUNTIF($C$20:$C$37,"FAIL") -> 0 | ... Q19: =COUNTIF($C$6:$C$18,"FAIL")+COUNTIF($C$20:$C$37,"FAIL") -> 0
A21: CONDITIONAL CHECKS
A22: PPE_SCHEDULE_TIE | B22: ARCHETYPE/conditional | expected 0; hard_tie_tolerance. | source applies_to: operating-EBITDA, power, utility, downstream fuel, other non-financials | C22: SOURCE_GAP | D22: hard | E22: 1000 USD | F22: 0 | G22: No semantic anchors resolved for PPE_SCHEDULE_TIE. | H22: =0 -> 0 | I22: =0 -> 0 | J22: =0 -> 0 | K22: =0 -> 0 | L22: =0 -> 0 | M22: =0 -> 0 | N22: =0 -> 0 | O22: =0 -> 0 | ... Q22: =0 -> 0
A23: LEASE_SCHEDULE_TIE | B23: ARCHETYPE/conditional | expected 0; hard_tie_tolerance. | source applies_to: IFRS-16 issuers | C23: SOURCE_GAP | D23: hard | E23: 1000 USD | F23: 0 | G23: No semantic anchors resolved for LEASE_SCHEDULE_TIE. | H23: =0 -> 0 | I23: =0 -> 0 | J23: =0 -> 0 | K23: =0 -> 0 | L23: =0 -> 0 | M23: =0 -> 0 | N23: =0 -> 0 | O23: =0 -> 0 | ... Q23: =0 -> 0
A24: DEBT_SCHEDULE_TIE | B24: ARCHETYPE/conditional | expected 0; hard_tie_tolerance; project-finance debt can include accrued interest/unamortized cost roles. | source applies_to: non-bank-lender, power, utility, operating-EBITDA with debt | C24: SOURCE_GAP | D24: hard | E24: 1000 USD | F24: 0 | G24: No semantic anchors resolved for DEBT_SCHEDULE_TIE. | H24: =0 -> 0 | I24: =0 -> 0 | J24: =0 -> 0 | K24: =0 -> 0 | L24: =0 -> 0 | M24: =0 -> 0 | N24: =0 -> 0 | O24: =0 -> 0 | ... Q24: =0 -> 0
A26: POWER CHECKS
