Workbook

Sheet 00_Cover
A1: The Coca-Cola Company (KO) — 9/10 Re-gated Institutional Model
A2: Owner-prepared submission; independent reviewer reproduction is required before certification
A4: Model snapshot
A5: Legal entity | B5: The Coca-Cola Company
A6: Ticker | B6: KO
A7: Latest filing | B7: 2025-12-31 10-K filed 2026-02-20
A8: SEC accession | B8: 0001628280-26-010047
A9: Market price | B9: 82.45
A10: Market as-of | B10: 2026-07-15
A11: Active scenario | B11: =Assumptions!B4 -> Base
A12: DCF value / share | B12: =Valuation!G18 -> 53.269184
A13: Upside / (downside) | B13: =Valuation!G20 -> -0.35392135
A14: Gate decision | B14: =Gate_9of10!B17 -> OWNER READY — INDEPENDENT REVIEW REQUIRED
A15: What changed in the 9/10 re-gate
A16: What changed in the 9/10 re-gate
A17: 1 | B17: Replaced generic Sources sheet with target-cell provenance ledger
A18: 2 | B18: Replaced generic assumptions with company-specific operating drivers
A19: 3 | B19: Scenario selector now changes multiple operating outputs and the DCF
A20: 4 | B20: Debt, liquid assets and share-count valuation bridges are explicit
A21: 5 | B21: Checks are formula-driven; Gate_9of10 states owner evidence and review status
A22: 6 | B22: All original workbook files remain preserved; this is a new derivative output

Sheet Sources
A1: The Coca-Cola Company — Source Provenance Ledger
A2: Every populated hardcoded historical or driver input is mapped to a target cell with period, value, unit, taxonomy/locator, accession and exact URL.
A4: Source ID | B4: Legal Entity | C4: Target Cell | D4: Metric | E4: Period / As-of | F4: Reported Value | G4: Units | H4: Currency | I4: Taxonomy / Locator | J4: Start | K4: End | L4: FY / FP | M4: Form | N4: Filed | O4: Accession | P4: Exact URL | Q4: Retrieved | R4: Source Class | S4: Transform / Mapping | T4: Verification | U4: Limitation / Disposition | V4: Complete?
A5: 1 | B5: The Coca-Cola Company | C5: Historical!B5 | D5: Revenue | E5: 2021A | F5: 38655 | G5: USD millions | H5: USD | I5: us-gaap:Revenues | J5: 2021-01-01 | K5: 2021-12-31 | L5: 2023/FY | M5: 10-K | N5: 2024-02-20 | O5: 0000021344-24-000009 | P5: https://www.sec.gov/Archives/edgar/data/21344/000002134424000009/0000021344-24-000009-index.htm | Q5: 2026-07-16 | R5: Primary - SEC filing / Company Facts | S5: USD divided by 1,000,000; sign as presented | T5: Matched legal entity, period, form, filed date, accession and target | U5: None identified | V5: =IF(COUNTA(A5:U5)=21,"OK","MISSING") -> OK
A6: 2 | B6: The Coca-Cola Company | C6: Historical!C5 | D6: Revenue | E6: 2022A | F6: 43004 | G6: USD millions | H6: USD | I6: us-gaap:Revenues | J6: 2022-01-01 | K6: 2022-12-31 | L6: 2024/FY | M6: 10-K | N6: 2025-02-20 | O6: 0000021344-25-000011 | P6: https://www.sec.gov/Archives/edgar/data/21344/000002134425000011/0000021344-25-000011-index.htm | Q6: 2026-07-16 | R6: Primary - SEC filing / Company Facts | S6: USD divided by 1,000,000; sign as presented | T6: Matched legal entity, period, form, filed date, accession and target | U6: None identified | V6: =IF(COUNTA(A6:U6)=21,"OK","MISSING") -> OK
A7: 3 | B7: The Coca-Cola Company | C7: Historical!D5 | D7: Revenue | E7: 2023A | F7: 45754 | G7: USD millions | H7: USD | I7: us-gaap:Revenues | J7: 2023-01-01 | K7: 2023-12-31 | L7: 2025/FY | M7: 10-K | N7: 2026-02-20 | O7: 0001628280-26-010047 | P7: https://www.sec.gov/Archives/edgar/data/21344/000162828026010047/0001628280-26-010047-index.htm | Q7: 2026-07-16 | R7: Primary - SEC filing / Company Facts | S7: USD divided by 1,000,000; sign as presented | T7: Matched legal entity, period, form, filed date, accession and target | U7: None identified | V7: =IF(COUNTA(A7:U7)=21,"OK","MISSING") -> OK
A8: 4 | B8: The Coca-Cola Company | C8: Historical!E5 | D8: Revenue | E8: 2024A | F8: 47061 | G8: USD millions | H8: USD | I8: us-gaap:Revenues | J8: 2024-01-01 | K8: 2024-12-31 | L8: 2025/FY | M8: 10-K | N8: 2026-02-20 | O8: 0001628280-26-010047 | P8: https://www.sec.gov/Archives/edgar/data/21344/000162828026010047/0001628280-26-010047-index.htm | Q8: 2026-07-16 | R8: Primary - SEC filing / Company Facts | S8: USD divided by 1,000,000; sign as presented | T8: Matched legal entity, period, form, filed date, accession and target | U8: None identified | V8: =IF(COUNTA(A8:U8)=21,"OK","MISSING") -> OK
A9: 5 | B9: The Coca-Cola Company | C9: Historical!F5 | D9: Revenue | E9: 2025A | F9: 47941 | G9: USD millions | H9: USD | I9: us-gaap:Revenues | J9: 2025-01-01 | K9: 2025-12-31 | L9: 2025/FY | M9: 10-K | N9: 2026-02-20 | O9: 0001628280-26-010047 | P9: https://www.sec.gov/Archives/edgar/data/21344/000162828026010047/0001628280-26-010047-index.htm | Q9: 2026-07-16 | R9: Primary - SEC filing / Company Facts | S9: USD divided by 1,000,000; sign as presented | T9: Matched legal entity, period, form, filed date, accession and target | U9: None identified | V9: =IF(COUNTA(A9:U9)=21,"OK","MISSING") -> OK
A10: 6 | B10: The Coca-Cola Company | C10: Historical!B6 | D10: Gross profit | E10: 2021A | F10: 23298 | G10: USD millions | H10: USD | I10: us-gaap:GrossProfit | J10: 2021-01-01 | K10: 2021-12-31 | L10: 2023/FY | M10: 10-K | N10: 2024-02-20 | O10: 0000021344-24-000009 | P10: https://www.sec.gov/Archives/edgar/data/21344/000002134424000009/0000021344-24-000009-index.htm | Q10: 2026-07-16 | R10: Primary - SEC filing / Company Facts | S10: USD divided by 1,000,000; sign as presented | T10: Matched legal entity, period, form, filed date, accession and target | U10: None identified | V10: =IF(COUNTA(A10:U10)=21,"OK","MISSING") -> OK
A11: 7 | B11: The Coca-Cola Company | C11: Historical!C6 | D11: Gross profit | E11: 2022A | F11: 25004 | G11: USD millions | H11: USD | I11: us-gaap:GrossProfit | J11: 2022-01-01 | K11: 2022-12-31 | L11: 2024/FY | M11: 10-K | N11: 2025-02-20 | O11: 0000021344-25-000011 | P11: https://www.sec.gov/Archives/edgar/data/21344/000002134425000011/0000021344-25-000011-index.htm | Q11: 2026-07-16 | R11: Primary - SEC filing / Company Facts | S11: USD divided by 1,000,000; sign as presented | T11: Matched legal entity, period, form, filed date, accession and target | U11: None identified | V11: =IF(COUNTA(A11:U11)=21,"OK","MISSING") -> OK
A12: 8 | B12: The Coca-Cola Company | C12: Historical!D6 | D12: Gross profit | E12: 2023A | F12: 27234 | G12: USD millions | H12: USD | I12: us-gaap:GrossProfit | J12: 2023-01-01 | K12: 2023-12-31 | L12: 2025/FY | M12: 10-K | N12: 2026-02-20 | O12: 0001628280-26-010047 | P12: https://www.sec.gov/Archives/edgar/data/21344/000162828026010047/0001628280-26-010047-index.htm | Q12: 2026-07-16 | R12: Primary - SEC filing / Company Facts | S12: USD divided by 1,000,000; sign as presented | T12: Matched legal entity, period, form, filed date, accession and target | U12: None identified | V12: =IF(COUNTA(A12:U12)=21,"OK","MISSING") -> OK
A13: 9 | B13: The Coca-Cola Company | C13: Historical!E6 | D13: Gross profit | E13: 2024A | F13: 28737 | G13: USD millions | H13: USD | I13: us-gaap:GrossProfit | J13: 2024-01-01 | K13: 2024-12-31 | L13: 2025/FY | M13: 10-K | N13: 2026-02-20 | O13: 0001628280-26-010047 | P13: https://www.sec.gov/Archives/edgar/data/21344/000162828026010047/0001628280-26-010047-index.htm | Q13: 2026-07-16 | R13: Primary - SEC filing / Company Facts | S13: USD divided by 1,000,000; sign as presented | T13: Matched legal entity, period, form, filed date, accession and target | U13: None identified | V13: =IF(COUNTA(A13:U13)=21,"OK","MISSING") -> OK
A14: 10 | B14: The Coca-Cola Company | C14: Historical!F6 | D14: Gross profit | E14: 2025A | F14: 29544 | G14: USD millions | H14: USD | I14: us-gaap:GrossProfit | J14: 2025-01-01 | K14: 2025-12-31 | L14: 2025/FY | M14: 10-K | N14: 2026-02-20 | O14: 0001628280-26-010047 | P14: https://www.sec.gov/Archives/edgar/data/21344/000162828026010047/0001628280-26-010047-index.htm | Q14: 2026-07-16 | R14: Primary - SEC filing / Company Facts | S14: USD divided by 1,000,000; sign as presented | T14: Matched legal entity, period, form, filed date, accession and target | U14: None identified | V14: =IF(COUNTA(A14:U14)=21,"OK","MISSING") -> OK
A15: 11 | B15: The Coca-Cola Company | C15: Historical!B7 | D15: Operating income / EBIT | E15: 2021A | F15: 10308 | G15: USD millions | H15: USD | I15: us-gaap:OperatingIncomeLoss | J15: 2021-01-01 | K15: 2021-12-31 | L15: 2023/FY | M15: 10-K | N15: 2024-02-20 | O15: 0000021344-24-000009 | P15: https://www.sec.gov/Archives/edgar/data/21344/000002134424000009/0000021344-24-000009-index.htm | Q15: 2026-07-16 | R15: Primary - SEC filing / Company Facts | S15: USD divided by 1,000,000; sign as presented | T15: Matched legal entity, period, form, filed date, accession and target | U15: None identified | V15: =IF(COUNTA(A15:U15)=21,"OK","MISSING") -> OK
A16: 12 | B16: The Coca-Cola Company | C16: Historical!C7 | D16: Operating income / EBIT | E16: 2022A | F16: 10909 | G16: USD millions | H16: USD | I16: us-gaap:OperatingIncomeLoss | J16: 2022-01-01 | K16: 2022-12-31 | L16: 2024/FY | M16: 10-K | N16: 2025-02-20 | O16: 0000021344-25-000011 | P16: https://www.sec.gov/Archives/edgar/data/21344/000002134425000011/0000021344-25-000011-index.htm | Q16: 2026-07-16 | R16: Primary - SEC filing / Company Facts | S16: USD divided by 1,000,000; sign as presented | T16: Matched legal entity, period, form, filed date, accession and target | U16: None identified | V16: =IF(COUNTA(A16:U16)=21,"OK","MISSING") -> OK
... A69: 65 | B69: The Coca-Cola Company | C69: Valuation!G19 | D69: Market close | E69: 2026-07-15 | F69: 82.45 | G69: USD per share | H69: USD | I69: Secondary market:Historical daily close | J69: N/A - instant | K69: 2026-07-15 | L69: N/A | M69: Market data | N69: 2026-07-15 | O69: N/A - market data | P69: https://ph.investing.com/equities/coca-cola-co-historical-data | Q69: 2026-07-16 | R69: Secondary - dated market close | S69: Closing price as displayed; no FX | T69: Date and close matched on cited historical-price surface | U69: Secondary market source; refresh before transaction use | V69: =IF(COUNTA(A69:U69)=21,"OK","MISSING") -> OK
A71: Ledger completeness | G71: =COUNTIF(V5:V69,"OK") -> 65 | H71: 65 | I71: =IF(G71=H71,"OK","REVIEW") -> OK

Sheet Historical
A1: The Coca-Cola Company — Historical Financials
A2: SEC 10-K / Company Facts lineage; USD millions except per-share data and shares
A4: Metric | B4: 2021A | C4: 2022A | D4: 2023A | E4: 2024A | F4: 2025A
A5: Revenue | B5: 38655 | C5: 43004 | D5: 45754 | E5: 47061 | F5: 47941
A6: Gross profit | B6: 23298 | C6: 25004 | D6: 27234 | E6: 28737 | F6: 29544
A7: Operating income / EBIT | B7: 10308 | C7: 10909 | D7: 11311 | E7: 9992 | F7: 13762
A8: Net income | B8: 9771 | C8: 9542 | D8: 10714 | E8: 10631 | F8: 13107
A9: Cash from operations | B9: 12625 | C9: 11018 | D9: 11599 | E9: 6805 | F9: 7408
A10: Capital expenditures | B10: 1367 | C10: 1484 | D10: 1852 | E10: 2064 | F10: 2112
A11: Total assets | B11: 94354 | C11: 92763 | D11: 97703 | E11: 100549 | F11: 104816
A12: Shareholders' equity | B12: 22999 | C12: 24105 | D12: 25941 | E12: 24856 | F12: 32169
A13: Cash and equivalents | B13: 9684 | C13: 9519 | D13: 9366 | E13: 10828 | F13: 10270
A14: Total debt | D14: 37507 | E14: 43023 | F14: 43941
A15: Diluted weighted-average shares | B15: 4340 | C15: 4350 | D15: 4339 | E15: 4320 | F15: 4313
A17: Bridge policy | B17: Latest balance-sheet cash policy
A18: Liquid assets used in DCF | B18: =B23 -> 10270 | F18: USD millions
A19: Debt used in DCF | B19: =SUM(B24:B25) -> 43997 | F19: USD millions
A20: Share count used in DCF | B20: 4300.723 | F20: million shares
A22: Coca-Cola valuation bridge | B22: 2025A | C22: Policy | D22: USD m | E22: Source | F22: Status
A23: Cash and equivalents | B23: =F13 -> 10270 | C23: Included | D23: USD m | E23: Historical latest balance | F23: Formula link
A24: Debt including current maturities | B24: =F14 -> 43941 | C24: Included | D24: USD m | E24: Historical latest balance | F24: Formula link
A25: Other short-term borrowings | B25: 56 | C25: Included | D25: USD m | E25: us-gaap:OtherShortTermBorrowings | F25: OK

Sheet Assumptions
A1: The Coca-Cola Company — Scenario Assumptions
A2: Selector drives operating revenues/margins and the DCF; blue/amber cells are editable inputs
A3: Scenario selector (1 Base / 2 Bull / 3 Bear) | B3: 1 | G3: Input
A4: Active scenario | B4: =CHOOSE(B3,"Base","Bull","Bear") -> Base | G4: Formula
A6: Assumption | B6: Units | C6: Base | D6: Bull | E6: Bear | F6: Active | G6: Rationale / evidence
A7: Unit case volume contribution | B7: % | C7: 0.015 | D7: 0.025 | E7: 0 | F7: =CHOOSE($B$3,C7,D7,E7) -> 0.015 | G7: 2025 system unit cases 33.8bn; driver contribution
A8: Price / mix contribution | B8: % | C8: 0.04 | D8: 0.05 | E8: 0.025 | F8: =CHOOSE($B$3,C8,D8,E8) -> 0.04 | G8: 2025 reported price/mix contribution +4%
A9: Foreign-exchange contribution | B9: % | C9: 0 | D9: 0.01 | E9: -0.02 | F9: =CHOOSE($B$3,C9,D9,E9) -> 0 | G9: Scenario FX translation contribution
A10: Structural / acquisition contribution | B10: % | C10: 0 | D10: 0.005 | E10: -0.01 | F10: =CHOOSE($B$3,C10,D10,E10) -> 0 | G10: Scenario portfolio contribution
A11: Operating margin | B11: % | C11: 0.29 | D11: 0.31 | E11: 0.27 | F11: =CHOOSE($B$3,C11,D11,E11) -> 0.29 | G11: Normalized consolidated operating margin
A12: Cash tax rate | B12: % | C12: 0.19 | D12: 0.175 | E12: 0.21 | F12: =CHOOSE($B$3,C12,D12,E12) -> 0.19 | G12: Normalized cash tax rate
A13: D&A as % revenue | B13: % | C13: 0.045 | D13: 0.047 | E13: 0.043 | F13: =CHOOSE($B$3,C13,D13,E13) -> 0.045 | G13: Normalized D&A intensity
A14: Capex as % revenue | B14: % | C14: 0.045 | D14: 0.04 | E14: 0.05 | F14: =CHOOSE($B$3,C14,D14,E14) -> 0.045 | G14: Normalized capex intensity
A15: NWC investment / revenue growth | B15: % | C15: 0.01 | D15: 0.005 | E15: 0.015 | F15: =CHOOSE($B$3,C15,D15,E15) -> 0.01 | G15: FCFF working-capital policy
A16: WACC | B16: % | C16: 0.075 | D16: 0.068 | E16: 0.085 | F16: =CHOOSE($B$3,C16,D16,E16) -> 0.075 | G16: DCF discount-rate scenario
A17: Terminal growth | B17: % | C17: 0.025 | D17: 0.03 | E17: 0.02 | F17: =CHOOSE($B$3,C17,D17,E17) -> 0.025 | G17: DCF perpetual-growth scenario

Sheet Forecast
A1: The Coca-Cola Company — Operating Forecast
A2: Scenario-linked driver build; USD millions except shares and per-share data
A4: Metric | B4: 2025A | C4: 2026E | D4: 2027E | E4: 2028E | F4: 2029E | G4: 2030E
A5: Unit case volume contribution | B5: 0.01 | C5: =Assumptions!F7 -> 0.015 | D5: =Assumptions!F7 -> 0.015 | E5: =Assumptions!F7 -> 0.015 | F5: =Assumptions!F7 -> 0.015 | G5: =Assumptions!F7 -> 0.015
A6: Price / mix contribution | B6: 0.04 | C6: =Assumptions!F8 -> 0.04 | D6: =Assumptions!F8 -> 0.04 | E6: =Assumptions!F8 -> 0.04 | F6: =Assumptions!F8 -> 0.04 | G6: =Assumptions!F8 -> 0.04
A7: FX contribution | B7: -0.02 | C7: =Assumptions!F9 -> 0 | D7: =Assumptions!F9 -> 0 | E7: =Assumptions!F9 -> 0 | F7: =Assumptions!F9 -> 0 | G7: =Assumptions!F9 -> 0
A8: Structural contribution | B8: -0.01 | C8: =Assumptions!F10 -> 0 | D8: =Assumptions!F10 -> 0 | E8: =Assumptions!F10 -> 0 | F8: =Assumptions!F10 -> 0 | G8: =Assumptions!F10 -> 0
A9: Revenue growth | B9: 0.02 | C9: =SUM(C5:C8) -> 0.055 | D9: =SUM(D5:D8) -> 0.055 | E9: =SUM(E5:E8) -> 0.055 | F9: =SUM(F5:F8) -> 0.055 | G9: =SUM(G5:G8) -> 0.055
A10: Revenue | B10: 47941 | C10: =B10*(1+C9) -> 50577.755 | D10: =C10*(1+D9) -> 53359.532 | E10: =D10*(1+E9) -> 56294.306 | F10: =E10*(1+F9) -> 59390.493 | G10: =F10*(1+G9) -> 62656.97
A11: EBIT | B11: 13200 | C11: =C10*Assumptions!F11 -> 14667.549 | D11: =D10*Assumptions!F11 -> 15474.264 | E11: =E10*Assumptions!F11 -> 16325.349 | F11: =F10*Assumptions!F11 -> 17223.243 | G11: =G10*Assumptions!F11 -> 18170.521
A12: Cash taxes | B12: =-B11*Assumptions!F12 -> -2508 | C12: =-C11*Assumptions!F12 -> -2786.8343 | D12: =-D11*Assumptions!F12 -> -2940.1102 | E12: =-E11*Assumptions!F12 -> -3101.8162 | F12: =-F11*Assumptions!F12 -> -3272.4161 | G12: =-G11*Assumptions!F12 -> -3452.399
A13: NOPAT | B13: =SUM(B11:B12) -> 10692 | C13: =SUM(C11:C12) -> 11880.715 | D13: =SUM(D11:D12) -> 12534.154 | E13: =SUM(E11:E12) -> 13223.532 | F13: =SUM(F11:F12) -> 13950.827 | G13: =SUM(G11:G12) -> 14718.122
A14: D&A | B14: 0 | C14: =C10*Assumptions!F13 -> 2275.999 | D14: =D10*Assumptions!F13 -> 2401.1789 | E14: =E10*Assumptions!F13 -> 2533.2438 | F14: =F10*Assumptions!F13 -> 2672.5722 | G14: =G10*Assumptions!F13 -> 2819.5636
A15: Capital expenditures | B15: 0 | C15: =-C10*Assumptions!F14 -> -2275.999 | D15: =-D10*Assumptions!F14 -> -2401.1789 | E15: =-E10*Assumptions!F14 -> -2533.2438 | F15: =-F10*Assumptions!F14 -> -2672.5722 | G15: =-G10*Assumptions!F14 -> -2819.5636
A16: Change in NWC | B16: 0 | C16: =-(C10-B10)*Assumptions!F15 -> -26.36755 | D16: =-(D10-C10)*Assumptions!F15 -> -27.817765 | E16: =-(E10-D10)*Assumptions!F15 -> -29.347742 | F16: =-(F10-E10)*Assumptions!F15 -> -30.961868 | G16: =-(G10-F10)*Assumptions!F15 -> -32.664771
A17: FCFF | B17: 0 | C17: =SUM(C13:C16) -> 11854.347 | D17: =SUM(D13:D16) -> 12506.336 | E17: =SUM(E13:E16) -> 13194.185 | F17: =SUM(F13:F16) -> 13919.865 | G17: =SUM(G13:G16) -> 14685.457

Sheet Valuation
A1: The Coca-Cola Company — DCF Valuation
A2: Unlevered FCFF; liquid-asset and debt bridge policies are explicit
A4: DCF item | B4: Year 1 | C4: Year 2 | D4: Year 3 | E4: Year 4 | F4: Year 5 | G4: Bridge / output
A5: FCFF | B5: =Forecast!C17 -> 11854.347 | C5: =Forecast!D17 -> 12506.336 | D5: =Forecast!E17 -> 13194.185 | E5: =Forecast!F17 -> 13919.865 | F5: =Forecast!G17 -> 14685.457
A6: Discount period | B6: 1 | C6: 2 | D6: 3 | E6: 4 | F6: 5
A7: Discount factor | B7: =1/(1+Assumptions!F16)^B6 -> 0.93023256 | C7: =1/(1+Assumptions!F16)^C6 -> 0.86533261 | D7: =1/(1+Assumptions!F16)^D6 -> 0.80496057 | E7: =1/(1+Assumptions!F16)^E6 -> 0.74880053 | F7: =1/(1+Assumptions!F16)^F6 -> 0.69655863
A8: Present value of FCFF | B8: =B5*B7 -> 11027.3 | C8: =C5*C7 -> 10822.141 | D8: =D5*D7 -> 10620.798 | E8: =E5*E7 -> 10423.202 | F8: =F5*F7 -> 10229.282
A9: Terminal value | F9: =F5*(1+Assumptions!F17)/(Assumptions!F16-Assumptions!F17) -> 301051.88
A10: PV of terminal value | F10: =F9*F7 -> 209700.28
A11: Enterprise value | G11: =SUM(B8:F8)+F10 -> 262823.01
A12: Liquid assets | G12: =Historical!B18 -> 10270
A13: Debt | G13: =Historical!B19 -> 43997
A14: Equity value | G14: =G11+G12-G13 -> 229096.01
A15: Shares outstanding / diluted policy | G15: =Historical!B20 -> 4300.723
A17: Per-share outputs
A18: DCF value / share | G18: =G14/G15 -> 53.269184
A19: Market price | G19: 82.45
A20: Upside / (downside) | G20: =G18/G19-1 -> -0.35392135
A21: Market as-of | G21: 2026-07-15

Sheet Sensitivity
A1: The Coca-Cola Company — DCF Sensitivity
A2: Implied value per share across WACC and terminal-growth assumptions
A4: WACC / TGR | B4: 0.015 | C4: 0.02 | D4: 0.025 | E4: 0.03 | F4: 0.035
A5: 0.065 | B5: =(SUM(Valuation!B8:F8)+Forecast!G17*(1+B$4)/($A5-B$4)*Valuation!F7+Valuation!G12-Valuation!G13)/Valuation!G15 -> 52.793484 | C5: =(SUM(Valuation!B8:F8)+Forecast!G17*(1+C$4)/($A5-C$4)*Valuation!F7+Valuation!G12-Valuation!G13)/Valuation!G15 -> 58.422607 | D5: =(SUM(Valuation!B8:F8)+Forecast!G17*(1+D$4)/($A5-D$4)*Valuation!F7+Valuation!G12-Valuation!G13)/Valuation!G15 -> 65.459012 | E5: =(SUM(Valuation!B8:F8)+Forecast!G17*(1+E$4)/($A5-E$4)*Valuation!F7+Valuation!G12-Valuation!G13)/Valuation!G15 -> 74.505817 | F5: =(SUM(Valuation!B8:F8)+Forecast!G17*(1+F$4)/($A5-F$4)*Valuation!F7+Valuation!G12-Valuation!G13)/Valuation!G15 -> 86.568225
A6: 0.07 | B6: =(SUM(Valuation!B8:F8)+Forecast!G17*(1+B$4)/($A6-B$4)*Valuation!F7+Valuation!G12-Valuation!G13)/Valuation!G15 -> 48.404065 | C6: =(SUM(Valuation!B8:F8)+Forecast!G17*(1+C$4)/($A6-C$4)*Valuation!F7+Valuation!G12-Valuation!G13)/Valuation!G15 -> 53.031334 | D6: =(SUM(Valuation!B8:F8)+Forecast!G17*(1+D$4)/($A6-D$4)*Valuation!F7+Valuation!G12-Valuation!G13)/Valuation!G15 -> 58.686885 | E6: =(SUM(Valuation!B8:F8)+Forecast!G17*(1+E$4)/($A6-E$4)*Valuation!F7+Valuation!G12-Valuation!G13)/Valuation!G15 -> 65.756325 | F6: =(SUM(Valuation!B8:F8)+Forecast!G17*(1+F$4)/($A6-F$4)*Valuation!F7+Valuation!G12-Valuation!G13)/Valuation!G15 -> 74.845604
A7: 0.075 | B7: =(SUM(Valuation!B8:F8)+Forecast!G17*(1+B$4)/($A7-B$4)*Valuation!F7+Valuation!G12-Valuation!G13)/Valuation!G15 -> 44.746216 | C7: =(SUM(Valuation!B8:F8)+Forecast!G17*(1+C$4)/($A7-C$4)*Valuation!F7+Valuation!G12-Valuation!G13)/Valuation!G15 -> 48.620292 | D7: =(SUM(Valuation!B8:F8)+Forecast!G17*(1+D$4)/($A7-D$4)*Valuation!F7+Valuation!G12-Valuation!G13)/Valuation!G15 -> 53.269184 | E7: =(SUM(Valuation!B8:F8)+Forecast!G17*(1+E$4)/($A7-E$4)*Valuation!F7+Valuation!G12-Valuation!G13)/Valuation!G15 -> 58.951164 | F7: =(SUM(Valuation!B8:F8)+Forecast!G17*(1+F$4)/($A7-F$4)*Valuation!F7+Valuation!G12-Valuation!G13)/Valuation!G15 -> 66.053637
A8: 0.08 | B8: =(SUM(Valuation!B8:F8)+Forecast!G17*(1+B$4)/($A8-B$4)*Valuation!F7+Valuation!G12-Valuation!G13)/Valuation!G15 -> 41.651113 | C8: =(SUM(Valuation!B8:F8)+Forecast!G17*(1+C$4)/($A8-C$4)*Valuation!F7+Valuation!G12-Valuation!G13)/Valuation!G15 -> 44.944424 | D8: =(SUM(Valuation!B8:F8)+Forecast!G17*(1+D$4)/($A8-D$4)*Valuation!F7+Valuation!G12-Valuation!G13)/Valuation!G15 -> 48.83652 | E8: =(SUM(Valuation!B8:F8)+Forecast!G17*(1+E$4)/($A8-E$4)*Valuation!F7+Valuation!G12-Valuation!G13)/Valuation!G15 -> 53.507035 | F8: =(SUM(Valuation!B8:F8)+Forecast!G17*(1+F$4)/($A8-F$4)*Valuation!F7+Valuation!G12-Valuation!G13)/Valuation!G15 -> 59.215442
A9: 0.085 | B9: =(SUM(Valuation!B8:F8)+Forecast!G17*(1+B$4)/($A9-B$4)*Valuation!F7+Valuation!G12-Valuation!G13)/Valuation!G15 -> 38.998167 | C9: =(SUM(Valuation!B8:F8)+Forecast!G17*(1+C$4)/($A9-C$4)*Valuation!F7+Valuation!G12-Valuation!G13)/Valuation!G15 -> 41.834074 | D9: =(SUM(Valuation!B8:F8)+Forecast!G17*(1+D$4)/($A9-D$4)*Valuation!F7+Valuation!G12-Valuation!G13)/Valuation!G15 -> 45.142633 | E9: =(SUM(Valuation!B8:F8)+Forecast!G17*(1+E$4)/($A9-E$4)*Valuation!F7+Valuation!G12-Valuation!G13)/Valuation!G15 -> 49.052747 | F9: =(SUM(Valuation!B8:F8)+Forecast!G17*(1+F$4)/($A9-F$4)*Valuation!F7+Valuation!G12-Valuation!G13)/Valuation!G15 -> 53.744885
B11: Central cross-check
B12: Active WACC | C12: =Assumptions!F16 -> 0.075
B13: Active TGR | C13: =Assumptions!F17 -> 0.025
B14: Active DCF value/share | C14: =Valuation!G18 -> 53.269184

Sheet Checks
A1: The Coca-Cola Company — Model Checks
A2: Overall status is formula-driven from assertions; source completeness is linked to the provenance ledger
A4: Assertion | B4: Actual | C4: Expected | D4: Difference | E4: Tolerance | F4: Status | G4: Fix hint
A5: Source ledger complete | B5: =Sources!I71 -> OK | C5: OK | F5: =IF(B5=C5,"OK","REVIEW") -> OK | G5: Complete every mandatory provenance field
A6: Scenario selector valid | B6: =Assumptions!B3 -> 1 | C6: 1 | D6: =IF(AND(B6>=1,B6<=3),0,1) -> 0 | E6: 0 | F6: =IF(D6=E6,"OK","REVIEW") -> OK | G6: Set Assumptions!B3 to 1, 2 or 3
A7: Forecast revenue positive | B7: =Forecast!C10 -> 50577.755 | C7: 0 | D7: =IF(B7>0,0,1) -> 0 | E7: 0 | F7: =IF(D7=E7,"OK","REVIEW") -> OK | G7: Inspect revenue-driver formulas
A8: Five EBIT periods populated | B8: =COUNT(Forecast!C11:G11) -> 5 | C8: 5 | D8: =ABS(B8-C8) -> 0 | E8: 0 | F8: =IF(D8=E8,"OK","REVIEW") -> OK | G8: Inspect margin and opex build
A9: Five FCFF periods populated | B9: =COUNT(Forecast!C17:G17) -> 5 | C9: 5 | D9: =ABS(B9-C9) -> 0 | E9: 0 | F9: =IF(D9=E9,"OK","REVIEW") -> OK | G9: Inspect NOPAT, D&A, capex and NWC
A10: Latest historical capex source present | B10: =COUNT(Historical!F10) -> 1 | C10: 1 | D10: =ABS(B10-C10) -> 0 | E10: 0.1 | F10: =IF(D10<=E10,"OK","REVIEW") -> OK | G10: Historical inputs are positive as reported; forecast expense/capex anchors are negative model outflows
A11: DCF equity bridge | B11: =Valuation!G14 -> 229096.01 | C11: =Valuation!G11+Valuation!G12-Valuation!G13 -> 229096.01 | D11: =ABS(B11-C11) -> 0 | E11: 0.1 | F11: =IF(D11<=E11,"OK","REVIEW") -> OK | G11: Inspect EV, liquid assets and total debt
A12: DCF per-share identity | B12: =Valuation!G18 -> 53.269184 | C12: =Valuation!G14/Valuation!G15 -> 53.269184 | D12: =ABS(B12-C12) -> 0 | E12: 0.001 | F12: =IF(D12<=E12,"OK","REVIEW") -> OK | G12: Inspect shares bridge
A13: Market price positive and sourced | B13: =Valuation!G19 -> 82.45 | C13: 0 | D13: =IF(B13>0,0,1) -> 0 | E13: 0 | F13: =IF(D13=E13,"OK","REVIEW") -> OK | G13: Update the dated market source row in Sources
A15: Overall status | F15: =IF(COUNTIF(F5:F13,"OK")=9,"OK","REVIEW") -> OK

Sheet Sector_KPIs
A1: The Coca-Cola Company — Company Operating Drivers
A2: Company-specific reported driver history; formulas reconcile the model totals to historical revenue where applicable
A4: Metric | B4: 2024A | C4: 2025A | D4: Units | E4: Source / locator | F4: Status | G4: Model use
A5: System unit cases | B5: 33.7 | C5: 33.8 | D5: billion cases | E5: 2025 Form 10-K, operating review | F5: Reported | G5: Volume anchor
A6: Consolidated revenue | B6: 47061 | C6: 47941 | D6: USD m | E6: 2025 Form 10-K | F6: Reported | G6: Revenue anchor
A7: Volume contribution | C7: 0.01 | D7: % | E7: 2025 Form 10-K revenue contribution bridge | F7: Reported | G7: Scenario driver
A8: Price / mix contribution | C8: 0.04 | D8: % | E8: 2025 Form 10-K revenue contribution bridge | F8: Reported | G8: Scenario driver
A9: FX contribution | C9: -0.02 | D9: % | E9: 2025 Form 10-K revenue contribution bridge | F9: Reported | G9: Scenario driver
A10: Acquisition / divestiture contribution | C10: -0.01 | D10: % | E10: 2025 Form 10-K revenue contribution bridge | F10: Reported | G10: Scenario driver
A11: Total reported revenue growth | C11: 0.02 | D11: % | E11: 2025 Form 10-K revenue contribution bridge | F11: Reported | G11: Cross-check

Sheet Change_Log
A1: The Coca-Cola Company — Change Log
A2: Re-gating work performed without overwriting the prior workbook
A4: Timestamp (UTC) | B4: Scope | C4: Change | D4: Evidence | E4: Prior hash | F4: Preparer | G4: Disposition
A5: Build 2026-07-17T02:33:12.208Z | B5: Source lineage | C5: Added line-item target-cell provenance ledger | D5: Sources + SEC Company Facts / 10-K | E5: 2d7d208c175d48f0001dbe569fc7cd0c298f02fd51e1cb5f8d76b241a6261b48 | F5: Codex | G5: Ready for independent review
A6: Build 2026-07-17T02:33:12.208Z | B6: Operating model | C6: Added company-specific revenue and margin drivers | D6: Sector_KPIs, Assumptions, Forecast | E6: 2d7d208c175d48f0001dbe569fc7cd0c298f02fd51e1cb5f8d76b241a6261b48 | F6: Codex | G6: Ready for independent review
A7: Build 2026-07-17T02:33:12.208Z | B7: Valuation | C7: Rebuilt FCFF DCF, bridge and sensitivity | D7: Valuation + Sensitivity | E7: 2d7d208c175d48f0001dbe569fc7cd0c298f02fd51e1cb5f8d76b241a6261b48 | F7: Codex | G7: Ready for independent review
A8: Build 2026-07-17T02:33:12.208Z | B8: Governance | C8: Added formula-driven checks and Gate_9of10 | D8: Checks + Gate_9of10 | E8: 2d7d208c175d48f0001dbe569fc7cd0c298f02fd51e1cb5f8d76b241a6261b48 | F8: Codex | G8: Owner submission only
A9: 46224 | B9: Ola 2 elevation: added IS_Hist/BS_Hist/CF_Hist (full 5-yr FY2021A-FY2025A audited line-item detail, USD mm, R3/R5/R7.htm + companyfacts.json cited), Checks_TieOut (24 cross-statement/subtotal/continuity checks), Sources_Audited (per-block citation + gap register), Forecast_IG (driver-built Base/Bull/Bear FY2026E-FY2030E). Root untouched; v2 saved under the maintainer's archive. Built via Mog SDK only. Known gaps: FY2021-22 CF custom-tag (ko:) line splits and FY2021-22 BS non-current-asset residual ($1,603mm/$1,136mm) — both disclosed and quantified in Sources_Audited, not estimated. | C9: Claude (run 24e4a1f1)
A10: Build 2026-08-14 (UTC) | B10: Capa de cobertura (Ola 1 flota internacional, plantilla del piloto Apple) | C10: Agregadas 2 hojas nuevas: Drivers_MDA (drivers del MD&A FY2021A-FY2025A: volumen, bridge de ingresos, segmentos con quiebre de presentación declarado, concentrado vs producto terminado en dólares por la Nota 3, FX, commodities, working capital con detalle de la Nota 21, dividendos, NOT_AVAILABLE declarados, memo dual-vintage FY2023, puente al motor) y Market_Package (precio 87.42 al 2026-08-13, acciones 4,302.549m del 10-Q Q2 FY2026, EV, WACC fechado 5.88%, múltiplos, LTM al Q2 FY2026, control de procedencia, hallazgos H1-H4). Agregados 21 checks (32-52) en Checks_TieOut más el conteo mecanizado B3. ÚNICA celda preexistente modificada: Checks_TieOut!B2 (rango del MASTER ampliado de H5:H30 a H5:H52 para que los checks nuevos puedan reprobarlo). Todo lo demás es estrictamente aditivo; cero cambios en hojas históricas, Forecast, Valuation, Assumptions o Gate_9of10. | D10: Drivers_MDA!A1:I177; Market_Package!A1:F107; Checks_TieOut!A31:H52; fuentes: 5 10-K locales (pdftotext) + 10-Q Q2 FY2026 descargado de EDGAR (accn 0001628280-26-050503) + Treasury/FRED/Damodaran/stockanalysis con fecha | E10: e5f93ad944a76f3ffa8e7f049359a4ac43155bfb1a66f44b4955c0f992f2b2d2 | F10: Claude (builder de cobertura KO, corrida 2026-08-14) | G10: Aditivo; pendiente revisión independiente

Sheet Gate_9of10
A1: The Coca-Cola Company — Gate 9/10 Owner Submission
A2: Independent review is a separate role; this sheet does not self-certify the workbook
A4: Gate | B4: Weight | C4: Owner status | D4: Blocker class | E4: Exact evidence range | F4: Native / visual evidence | G4: Independent action | H4: Notes
A5: H0 Controlled lineage / package | B5: 5 | C5: PASS | D5: None identified | E5: Change_Log!A4:G8; final .xlsx | F5: Prior hash preserved; OOXML integrity PASS 2026-07-17T02:36:50.241Z | G5: Reproduce lineage and package test | H5: Final JSON carries prior and final hashes
A6: H1 Source fidelity | B6: 20 | C6: PASS | D6: None identified | E6: Sources!A4:V500 | F6: SEC target-cell ledger + formula completeness | G6: Sample and reproduce ledger mappings | H6: Every populated hardcoded historical/driver cell mapped
A7: H2 Historical / formula / schedule mechanics | B7: 15 | C7: PASS | D7: None identified | E7: Historical!A4:F26; Forecast!A4:G30 | F7: Five-year historicals and formula-driven operating build | G7: Reperform historical and forecast ties | H7: Reported values preserved; forecast cells formula-driven
A8: H3 Scenario / sensitivity | B8: 10 | C8: PASS | D8: None identified | E8: Assumptions!A3:G30; Sensitivity!A4:G14 | F8: Base/Bull/Bear selector + dynamic DCF sensitivity | G8: Perturb selector 1/2/3 and reset to 1 | H8: Evidence JSON records exact outputs
A9: H4 Valuation fit / mechanics | B9: 15 | C9: PASS | D9: None identified | E9: Valuation!A4:G21; Historical!A17:F26 | F9: FCFF, bridge and per-share DCF | G9: Reperform DCF and balance-sheet bridge | H9: Debt/liquid asset/share policies explicit
A10: H5 Checks / error state | B10: 8 | C10: PASS | D10: None identified | E10: Checks!A4:G14 | F10: Formula-driven checks OK and zero formula-error matches 2026-07-17T02:33:56.001Z | G10: Reproduce checks and formula-error scan | H10: Final scan repeated after gate promotion
A11: H6 Native recalc / reproducibility | B11: 10 | C11: PASS | D11: None identified | E11: Checks!A4:G14 | F11: LibreOfficeDev 26.8.0.0.alpha0 2c87e51eeaa2b413ff4ae097b2705eea1995d8e5; save/reopen completed 2026-07-17T02:33:56.001Z | G11: Reopen and reproduce in native engine | H11: Final recalc repeated after gate promotion; evidence JSON carries hashes
A12: H7 Post-recalc all-sheet visual QA | B12: 7 | C12: PASS | D12: None identified | E12: internal QA evidence (not published) | F12: All 11 sheets rendered in preflight 2026-07-17T02:33:56.001Z; final render repeated after promotion | G12: Inspect preview manifest | H12: Final JSON carries per-sheet manifest
A13: H8 Material economic upgrade | B13: 5 | C13: PASS | D13: None identified | E13: Sector_KPIs!A4:G40; Assumptions!A6:G30; Forecast!A4:G30 | F13: Company-specific driver and margin build | G13: Challenge economic usefulness | H13: No relabel-only sector shell
A14: H9 Governance / limitations / handoff | B14: 5 | C14: PASS | D14: None identified | E14: Change_Log!A4:G8; Gate_9of10!A4:H26 | F14: Owner/reviewer separation and limitations explicit | G14: Assign independent reviewer | H14: No self-certification; evidence JSON is handoff surface
A16: Owner score | B16: =SUMIF(C5:C14,"PASS",B5:B14) -> 100
A17: Decision | B17: =IF(B16=100,"OWNER READY — INDEPENDENT REVIEW REQUIRED","PENDING OWNER QA") -> OWNER READY — INDEPENDENT REVIEW REQUIRED
A18: Overall model status | B18: =Checks!F15 -> OK
A20: Native recalculation / review metadata
A21: Build timestamp UTC | B21: Build 2026-07-17T02:33:12.208Z
A22: Required native engine | B22: LibreOfficeDev 26.8.0.0.alpha0 2c87e51eeaa2b413ff4ae097b2705eea1995d8e5
A23: Final native timestamp | B23: Native preflight 2026-07-17T02:33:56.001Z; final recalc after promotion 2026-07-17T02:36:52.392Z
A24: Visual manifest | B24: internal QA evidence (not published)
A25: Evidence manifest | B25: internal QA evidence (not published)
A26: Independent certification | B26: Not performed by owner-preparer

Sheet IS_Hist
A1: The Coca-Cola Company — Consolidated Statements of Income (audited), Ola 2
A2: USD millions except per-share data and shares. FY2023-FY2025 per FY2025 10-K (R3.htm); FY2021-FY2022 per SEC companyfacts.json us-gaap tags. All tie-outs in Checks_TieOut.
A4: Line item | B4: FY2021A | C4: FY2022A | D4: FY2023A | E4: FY2024A | F4: FY2025A | H4: Source
A5: Net operating revenues | B5: 38655 | C5: 43004 | D5: 45754 | E5: 47061 | F5: 47941 | H5: R3/us-gaap:Revenues
A6: Cost of goods sold | B6: 15357 | C6: 18000 | D6: 18520 | E6: 18324 | F6: 18397 | H6: R3/us-gaap:CostOfGoodsAndServicesSold
A7: Gross profit | B7: 23298 | C7: 25004 | D7: 27234 | E7: 28737 | F7: 29544 | H7: R3/us-gaap:GrossProfit
A8: Selling, general and administrative expenses | B8: 12144 | C8: 12880 | D8: 13972 | E8: 14582 | F8: 14521 | H8: R3/us-gaap:SellingGeneralAndAdministrativeExpense
A9: Other operating charges | B9: 846 | C9: 1215 | D9: 1951 | E9: 4163 | F9: 1261 | H9: us-gaap:OtherCostAndExpenseOperating (21-22) / R3 (23-25)
A10: Operating income | B10: 10308 | C10: 10909 | D10: 11311 | E10: 9992 | F10: 13762 | H10: R3/us-gaap:OperatingIncomeLoss
A11: Interest income | B11: 276 | C11: 449 | D11: 907 | E11: 988 | F11: 786 | H11: R3/us-gaap:InvestmentIncomeInterest
A12: Interest expense | B12: 1597 | C12: 882 | D12: 1527 | E12: 1656 | F12: 1654 | H12: R3/us-gaap:InterestExpense
A13: Equity income (loss) — net | B13: 1438 | C13: 1472 | D13: 1691 | E13: 1770 | F13: 2031 | H13: R3/us-gaap:IncomeLossFromEquityMethodInvestments
A14: Other income (loss) — net | B14: 2000 | C14: -262 | D14: 570 | E14: 1992 | F14: 1073 | H14: R3/us-gaap:OtherNonoperatingIncomeExpense
A15: Income before income taxes | B15: 12425 | C15: 11686 | D15: 12952 | E15: 13086 | F15: 15998 | H15: R3/us-gaap:IncomeLossFromContinuingOperationsBeforeIncomeTaxes...
A16: Income taxes | B16: 2621 | C16: 2115 | D16: 2249 | E16: 2437 | F16: 2861 | H16: R3/us-gaap:IncomeTaxExpenseBenefit
... A24: Average shares outstanding — diluted (millions) | B24: 4340 | C24: 4350 | D24: 4339 | E24: 4320 | F24: 4313 | H24: R3/us-gaap:WeightedAverageNumberOfDilutedSharesOutstanding

Sheet BS_Hist
A1: The Coca-Cola Company — Consolidated Balance Sheets (audited), Ola 2
A2: USD millions, as of Dec 31. FY2024-FY2025 per FY2025 10-K (R5.htm); FY2021-FY2023 per companyfacts.json. See Sources_Audited for the held-for-sale presentation note and the FY21/22 non-current-asset reconciling residual.
A4: Line item | B4: FY2021A | C4: FY2022A | D4: FY2023A | E4: FY2024A | F4: FY2025A | H4: Source
A5: Current assets
A6: Cash and cash equivalents | B6: 9684 | C6: 9519 | D6: 9366 | E6: 10828 | F6: 10270 | H6: R5/us-gaap:CashAndCashEquivalentsAtCarryingValue
A7: Short-term investments | B7: 1242 | C7: 1043 | D7: 2997 | E7: 2020 | F7: 3602 | H7: us-gaap:OtherShortTermInvestments
A8: Marketable securities | B8: 1699 | C8: 1069 | D8: 1300 | E8: 1723 | F8: 1934 | H8: us-gaap:MarketableSecurities
A9: Trade accounts receivable, net | B9: 3512 | C9: 3487 | D9: 3410 | E9: 3569 | F9: 3038 | H9: us-gaap:AccountsReceivableNetCurrent
A10: Inventories | B10: 3414 | C10: 4233 | D10: 4424 | E10: 4728 | F10: 4425 | H10: us-gaap:InventoryNet
A11: Prepaid expenses and other current assets | B11: 2994 | C11: 3240 | D11: 5235 | E11: 2998 | F11: 2433 | H11: us-gaap:PrepaidExpenseAndOtherAssetsCurrent
A12: Assets held for sale (memo FY21-23; on-subtotal FY24-25) | B12: 674 | C12: 602 | D12: 2094 | E12: 131 | F12: 5342 | H12: us-gaap:AssetsOfDisposalGroupIncludingDiscontinuedOperation
A13: Total current assets (published) | B13: 22545 | C13: 22591 | D13: 26732 | E13: 25997 | F13: 31044 | H13: R5/us-gaap:AssetsCurrent
A14: Non-current assets
A15: Equity method investments | B15: 17598 | C15: 18264 | D15: 19671 | E15: 18087 | F15: 20235 | H15: us-gaap:EquityMethodInvestments
A16: Deferred income tax assets | B16: 2129 | C16: 1746 | D16: 1561 | E16: 1319 | F16: 1206 | H16: us-gaap:DeferredIncomeTaxAssetsNet
A17: Property, plant and equipment — net | B17: 9920 | C17: 9841 | D17: 9236 | E17: 10303 | F17: 9613 | H17: R5/us-gaap:PropertyPlantAndEquipmentNet
A18: Trademarks with indefinite lives | B18: 14465 | C18: 14214 | D18: 14349 | E18: 13301 | F18: 12531 | H18: us-gaap:IndefiniteLivedTrademarks
A19: Goodwill | B19: 19363 | C19: 18782 | D19: 18358 | E19: 18139 | F19: 15491 | H19: R5/us-gaap:Goodwill
A20: Other noncurrent assets | B20: 6731 | C20: 6189 | D20: 7796 | E20: 13403 | F20: 14696 | H20: us-gaap:OtherAssetsNoncurrent
A21: Unallocated non-current assets (reconciling residual — GAP, see Sources_Audited) | B21: 1603 | C21: 1136 | D21: 0 | E21: 0 | F21: 0 | H21: plug = Assets − TotalCA − sum(above NCA lines)
A22: Total non-current assets (published) | B22: 71809 | C22: 70172 | D22: 70971 | E22: 74552 | F22: 73772 | H22: Derived: Assets − Total current assets
A23: Total assets | B23: 94354 | C23: 92763 | D23: 97703 | E23: 100549 | F23: 104816 | H23: R5/us-gaap:Assets
A25: Current liabilities
A26: Accounts payable and accrued expenses | B26: 14619 | C26: 15749 | D26: 15485 | E26: 21712 | F26: 14813 | H26: us-gaap:AccountsPayableAndAccruedLiabilitiesCurrent
A27: Loans and notes payable | B27: 3307 | C27: 2373 | D27: 4557 | E27: 1499 | F27: 1551 | H27: us-gaap:ShortTermBorrowings (21) / NotesAndLoansPayable (22-25)
A28: Current maturities of long-term debt | B28: 1338 | C28: 399 | D28: 1960 | E28: 648 | F28: 1822 | H28: us-gaap:LongTermDebtCurrent (21-22) / LongTermDebtAndCapitalLeaseObligationsCurrent (23-25)
A29: Accrued income taxes | B29: 686 | C29: 1203 | D29: 1569 | E29: 1387 | F29: 525 | H29: us-gaap:AccruedIncomeTaxesCurrent
A30: Liabilities held for sale (memo FY21-23; on-subtotal FY24-25) | B30: 157 | C30: 160 | D30: 719 | E30: 3 | F30: 2570 | H30: us-gaap:LiabilitiesOfDisposalGroupIncludingDiscontinuedOperation
A31: Total current liabilities (published) | B31: 19950 | C31: 19724 | D31: 23571 | E31: 25249 | F31: 21281 | H31: R5/us-gaap:LiabilitiesCurrent
A32: Non-current liabilities
A33: Long-term debt | B33: 38116 | C33: 36377 | D33: 35547 | E33: 42375 | F33: 42119 | H33: us-gaap:LongTermDebtNoncurrent (21-23) / LongTermDebtAndCapitalLeaseObligations (24-25)
A34: Other noncurrent liabilities | B34: 8607 | C34: 7922 | D34: 8466 | E34: 4084 | F34: 4735 | H34: us-gaap:OtherLiabilitiesNoncurrent
A35: Deferred income tax liabilities | B35: 2821 | C35: 2914 | D35: 2639 | E35: 2469 | F35: 2406 | H35: us-gaap:DeferredIncomeTaxLiabilitiesNet
A36: Total non-current liabilities (published) | B36: 49544 | C36: 47213 | D36: 46652 | E36: 48928 | F36: 49260 | H36: Derived: Total liabilities − Total current liabilities
A37: Total liabilities | B37: 69494 | C37: 66937 | D37: 70223 | E37: 74177 | F37: 70541 | H37: Derived: LiabilitiesAndStockholdersEquity − StockholdersEquityIncl.NCI
A39: Shareowners' equity
A40: Common stock, $0.25 par value | B40: 1760 | C40: 1760 | D40: 1760 | E40: 1760 | F40: 1760 | H40: R5/us-gaap:CommonStockValue
A41: Capital surplus | B41: 18116 | C41: 18822 | D41: 19209 | E41: 19801 | F41: 20581 | H41: us-gaap:AdditionalPaidInCapitalCommonStock
A42: Reinvested earnings | B42: 69094 | C42: 71019 | D42: 73782 | E42: 76054 | F42: 80382 | H42: us-gaap:RetainedEarningsAccumulatedDeficit
A43: Accumulated other comprehensive income (loss) | B43: -14330 | C43: -14895 | D43: -14275 | E43: -16843 | F43: -14131 | H43: us-gaap:AccumulatedOtherComprehensiveIncomeLossNetOfTax
...

Sheet CF_Hist
A1: The Coca-Cola Company — Consolidated Statements of Cash Flows (audited), Ola 2
A2: USD millions. FY2023-FY2025 full line detail per FY2025 10-K (R7.htm); FY2021-FY2022 combines 3 custom-tagged (ko:) line items per section into one sized reconciling row (GAP in granularity only — subtotals are exact). See Sources_Audited.
A4: Line item | B4: FY2021A | C4: FY2022A | D4: FY2023A | E4: FY2024A | F4: FY2025A | H4: Source
A5: Operating activities
A6: Consolidated net income | B6: 9804 | C6: 9571 | D6: 10703 | E6: 10649 | F6: 13137 | H6: R7/us-gaap:ProfitLoss (=IS)
A7: Depreciation and amortization | B7: 1452 | C7: 1260 | D7: 1128 | E7: 1075 | F7: 1050 | H7: R7/us-gaap:DepreciationDepletionAndAmortization
A8: Stock-based compensation expense | B8: 337 | C8: 356 | D8: 254 | E8: 286 | F8: 279 | H8: R7/us-gaap:ShareBasedCompensation
A9: Deferred income taxes | B9: 894 | C9: -122 | D9: -2 | E9: -11 | F9: 517 | H9: R7/us-gaap:DeferredIncomeTaxExpenseBenefit
A10: Equity (income) loss — net of dividends | B10: -615 | C10: -838 | D10: -1019 | E10: -802 | F10: -1038 | H10: R7/us-gaap:IncomeLossFromEquityMethodInvestmentsNetOfDividendsOrDistributions (sign flipped)
A11: Foreign currency adjustments | C11: 203 | D11: 175 | E11: -110 | F11: 191 | H11: us-gaap:ForeignCurrencyTransactionGainLossBeforeTax (sign flipped; 21 n/a)
A12: Significant (gains) losses — net | D12: -492 | E12: -1737 | F12: -713 | H12: R7 (23-25 only; custom tag not in companyfacts pull for 21-22)
A13: Other operating charges | B13: 506 | C13: 1086 | D13: 1741 | E13: 4000 | F13: 1052 | H13: R7/us-gaap:OtherOperatingActivitiesCashFlowStatement
A14: Other items | D14: -43 | E14: -311 | F14: 141 | H14: R7 (23-25 only; custom tag not in companyfacts pull for 21-22)
A15: Net change in operating assets and liabilities | B15: 1325 | C15: -605 | D15: -846 | E15: -6234 | F15: -7208 | H15: us-gaap:IncreaseDecreaseInOperatingCapital (sign flipped)
A16: Significant gains/losses + other items, net (GAP reconciling — FY21-22 combined, see note) | B16: -1078 | C16: 107 | H16: plug = published CFO − sum(tagged lines above, incl. FX where available)
A17: Net cash provided by operating activities | B17: 12625 | C17: 11018 | D17: 11599 | E17: 6805 | F17: 7408 | H17: R7/us-gaap:NetCashProvidedByUsedInOperatingActivities
A19: Investing activities
A20: Purchases of investments | D20: -6698 | E20: -5640 | F20: -6160 | H20: R7 (23-25 only)
A21: Proceeds from disposals of investments | D21: 4354 | E21: 6589 | F21: 4665 | H21: R7 (23-25 only)
A22: Acquisitions of businesses, equity method investments and nonmarketable securities | D22: -62 | E22: -315 | F22: -461 | H22: R7 (23-25 only)
A23: Proceeds from disposals of businesses, equity method investments and nonmarketable securities | D23: 430 | E23: 3485 | F23: 3567 | H23: R7 (23-25 only)
A24: Purchases of property, plant and equipment | B24: -1367 | C24: -1484 | D24: -1852 | E24: -2064 | F24: -2112 | H24: R7/us-gaap:PaymentsToAcquirePropertyPlantAndEquipment
A25: Proceeds from disposals of property, plant and equipment | B25: 108 | C25: 75 | D25: 74 | E25: 40 | F25: 13 | H25: R7/us-gaap:ProceedsFromSaleOfPropertyPlantAndEquipment
A26: Collateral (paid) received associated with hedging activities — net | D26: 366 | E26: 235 | F26: 330 | H26: R7 (23-25 only)
A27: Other investing activities | D27: 39 | E27: 194 | F27: 91 | H27: R7 (23-25 only)
A28: Other investing activities, net (GAP reconciling — FY21-22 combined, see note) | B28: -1506 | C28: 646 | H28: plug = published CFI − sum(tagged lines above)
A29: Net cash provided by (used in) investing activities | B29: -2765 | C29: -763 | D29: -3349 | E29: 2524 | F29: -67 | H29: R7/us-gaap:NetCashProvidedByUsedInInvestingActivities
A31: Financing activities
A32: Issuances of loans, notes payable and long-term debt | D32: 6891 | E32: 12061 | F32: 4980 | H32: R7 (23-25 only)
A33: Payments of loans, notes payable and long-term debt | D33: -5034 | E33: -9533 | F33: -4967 | H33: R7 (23-25 only)
A34: Issuances of stock | B34: 702 | C34: 837 | D34: 539 | E34: 747 | F34: 313 | H34: R7/us-gaap:ProceedsFromIssuanceOfCommonStock
A35: Purchases of stock for treasury | B35: -111 | C35: -1418 | D35: -2289 | E35: -1795 | F35: -746 | H35: R7/us-gaap:PaymentsForRepurchaseOfCommonStock
A36: Dividends | B36: -7252 | C36: -7616 | D36: -7952 | E36: -8359 | F36: -8779 | H36: R7/us-gaap:PaymentsOfDividends
A37: Proceeds from noncontrolling interests | D37: 0 | E37: 0 | F37: 1338 | H37: R7/us-gaap:ProceedsFromMinorityShareholders
A38: Other financing activities | B38: -353 | C38: -1095 | D38: -465 | E38: -31 | F38: -279 | H38: R7/us-gaap:ProceedsFromPaymentsForOtherFinancingActivities
A39: Net debt issuances/(repayments), net (GAP reconciling — FY21-22 combined, see note) | B39: 228 | C39: -958 | H39: plug = published CFF − sum(tagged lines above)
A40: Net cash provided by (used in) financing activities | B40: -6786 | C40: -10250 | D40: -8310 | E40: -6910 | F40: -8140 | H40: R7/us-gaap:NetCashProvidedByUsedInFinancingActivities
A42: Cash and cash equivalents (incl. restricted cash)
A43: Effect of exchange rate changes on cash | B43: -159 | C43: -205 | D43: -73 | E43: -623 | F43: 321 | H43: R7/us-gaap:EffectOfExchangeRateOnCash...
A44: Net increase (decrease) in cash, cash equivalents, restricted cash and restricted cash equivalents | B44: 2915 | C44: -200 | D44: -133 | E44: 1796 | F44: -478 | H44: R7/us-gaap:CashCashEquivalentsRestrictedCash...PeriodIncreaseDecrease
...

Sheet Checks_TieOut
A1: Checks_TieOut — Ola 2 statement-grade tie-outs (all deltas must be 0; USD millions)
A2: MASTER | B2: =IF(COUNTIF(H5:H52,"FAIL")=0,"OK — ALL TIE-OUTS PASS","FAIL") -> FAIL
A3: Conteo mecanizado | B3: =COUNTIF(H5:H52,"PASS")&" PASS / "&(COUNTIF(H5:H52,"PASS")+COUNTIF(H5:H52,"FAIL"))&" checks" -> 46 PASS / 47 checks
A4: Check | B4: FY2021A | C4: FY2022A | D4: FY2023A | E4: FY2024A | F4: FY2025A | H4: Status
A5: IS: Gross profit = Revenue − COGS | B5: =IS_Hist!B5-IS_Hist!B6-IS_Hist!B7 -> 0 | C5: =IS_Hist!C5-IS_Hist!C6-IS_Hist!C7 -> 0 | D5: =IS_Hist!D5-IS_Hist!D6-IS_Hist!D7 -> 0 | E5: =IS_Hist!E5-IS_Hist!E6-IS_Hist!E7 -> 0 | F5: =IS_Hist!F5-IS_Hist!F6-IS_Hist!F7 -> 0 | H5: =IF(AND(ABS(N(B5))<=5,ABS(N(C5))<=5,ABS(N(D5))<=5,ABS(N(E5))<=5,ABS(N(F5))<=5),"PASS","FAIL") -> PASS
A6: IS: Operating income = GP − SG&A − Other opg charges | B6: =IS_Hist!B7-IS_Hist!B8-IS_Hist!B9-IS_Hist!B10 -> 0 | C6: =IS_Hist!C7-IS_Hist!C8-IS_Hist!C9-IS_Hist!C10 -> 0 | D6: =IS_Hist!D7-IS_Hist!D8-IS_Hist!D9-IS_Hist!D10 -> 0 | E6: =IS_Hist!E7-IS_Hist!E8-IS_Hist!E9-IS_Hist!E10 -> 0 | F6: =IS_Hist!F7-IS_Hist!F8-IS_Hist!F9-IS_Hist!F10 -> 0 | H6: =IF(AND(ABS(N(B6))<=5,ABS(N(C6))<=5,ABS(N(D6))<=5,ABS(N(E6))<=5,ABS(N(F6))<=5),"PASS","FAIL") -> PASS
A7: IS: Pretax income chain | B7: =IS_Hist!B10+IS_Hist!B11-IS_Hist!B12+IS_Hist!B13+IS_Hist!B14-IS_Hist!B15 -> 0 | C7: =IS_Hist!C10+IS_Hist!C11-IS_Hist!C12+IS_Hist!C13+IS_Hist!C14-IS_Hist!C15 -> 0 | D7: =IS_Hist!D10+IS_Hist!D11-IS_Hist!D12+IS_Hist!D13+IS_Hist!D14-IS_Hist!D15 -> 0 | E7: =IS_Hist!E10+IS_Hist!E11-IS_Hist!E12+IS_Hist!E13+IS_Hist!E14-IS_Hist!E15 -> 0 | F7: =IS_Hist!F10+IS_Hist!F11-IS_Hist!F12+IS_Hist!F13+IS_Hist!F14-IS_Hist!F15 -> 0 | H7: =IF(AND(ABS(N(B7))<=5,ABS(N(C7))<=5,ABS(N(D7))<=5,ABS(N(E7))<=5,ABS(N(F7))<=5),"PASS","FAIL") -> PASS
A8: IS: Consolidated NI = Pretax − tax | B8: =IS_Hist!B15-IS_Hist!B16-IS_Hist!B17 -> 0 | C8: =IS_Hist!C15-IS_Hist!C16-IS_Hist!C17 -> 0 | D8: =IS_Hist!D15-IS_Hist!D16-IS_Hist!D17 -> 0 | E8: =IS_Hist!E15-IS_Hist!E16-IS_Hist!E17 -> 0 | F8: =IS_Hist!F15-IS_Hist!F16-IS_Hist!F17 -> 0 | H8: =IF(AND(ABS(N(B8))<=5,ABS(N(C8))<=5,ABS(N(D8))<=5,ABS(N(E8))<=5,ABS(N(F8))<=5),"PASS","FAIL") -> PASS
A9: IS: NI attributable = Consolidated − NCI | B9: =IS_Hist!B17-IS_Hist!B18-IS_Hist!B19 -> 0 | C9: =IS_Hist!C17-IS_Hist!C18-IS_Hist!C19 -> 0 | D9: =IS_Hist!D17-IS_Hist!D18-IS_Hist!D19 -> 0 | E9: =IS_Hist!E17-IS_Hist!E18-IS_Hist!E19 -> 0 | F9: =IS_Hist!F17-IS_Hist!F18-IS_Hist!F19 -> 0 | H9: =IF(AND(ABS(N(B9))<=5,ABS(N(C9))<=5,ABS(N(D9))<=5,ABS(N(E9))<=5,ABS(N(F9))<=5),"PASS","FAIL") -> PASS
A10: BS: Total current assets (published, FY21-23 excl. AHFS) | B10: =SUM(BS_Hist!B6:B11)-BS_Hist!B13 -> 0 | C10: =SUM(BS_Hist!C6:C11)-BS_Hist!C13 -> 0 | D10: =SUM(BS_Hist!D6:D11)-BS_Hist!D13 -> 0 | E10: =SUM(BS_Hist!E6:E12)-BS_Hist!E13 -> 0 | F10: =SUM(BS_Hist!F6:F12)-BS_Hist!F13 -> 0 | H10: =IF(AND(ABS(N(B10))<=5,ABS(N(C10))<=5,ABS(N(D10))<=5,ABS(N(E10))<=5,ABS(N(F10))<=5),"PASS","FAIL") -> PASS
A11: BS: Total non-current assets (published) = TA − TCA | B11: =BS_Hist!B23-BS_Hist!B13-BS_Hist!B22 -> 0 | C11: =BS_Hist!C23-BS_Hist!C13-BS_Hist!C22 -> 0 | D11: =BS_Hist!D23-BS_Hist!D13-BS_Hist!D22 -> 0 | E11: =BS_Hist!E23-BS_Hist!E13-BS_Hist!E22 -> 0 | F11: =BS_Hist!F23-BS_Hist!F13-BS_Hist!F22 -> 0 | H11: =IF(AND(ABS(N(B11))<=5,ABS(N(C11))<=5,ABS(N(D11))<=5,ABS(N(E11))<=5,ABS(N(F11))<=5),"PASS","FAIL") -> PASS
A12: BS: Non-current asset detail sum = published NCA (incl. residual line) | B12: =SUM(BS_Hist!B15:B21)-BS_Hist!B22 -> 0 | C12: =SUM(BS_Hist!C15:C21)-BS_Hist!C22 -> 0 | D12: =SUM(BS_Hist!D15:D21)-BS_Hist!D22 -> 0 | E12: =SUM(BS_Hist!E15:E21)-BS_Hist!E22 -> 0 | F12: =SUM(BS_Hist!F15:F21)-BS_Hist!F22 -> 0 | H12: =IF(AND(ABS(N(B12))<=5,ABS(N(C12))<=5,ABS(N(D12))<=5,ABS(N(E12))<=5,ABS(N(F12))<=5),"PASS","FAIL") -> PASS
A13: BS: Total assets = TCA + TNCA | B13: =BS_Hist!B13+BS_Hist!B22-BS_Hist!B23 -> 0 | C13: =BS_Hist!C13+BS_Hist!C22-BS_Hist!C23 -> 0 | D13: =BS_Hist!D13+BS_Hist!D22-BS_Hist!D23 -> 0 | E13: =BS_Hist!E13+BS_Hist!E22-BS_Hist!E23 -> 0 | F13: =BS_Hist!F13+BS_Hist!F22-BS_Hist!F23 -> 0 | H13: =IF(AND(ABS(N(B13))<=5,ABS(N(C13))<=5,ABS(N(D13))<=5,ABS(N(E13))<=5,ABS(N(F13))<=5),"PASS","FAIL") -> PASS
A14: BS: Total current liabilities (published, FY21-23 excl. LHFS) | B14: =SUM(BS_Hist!B26:B29)-BS_Hist!B31 -> 0 | C14: =SUM(BS_Hist!C26:C29)-BS_Hist!C31 -> 0 | D14: =SUM(BS_Hist!D26:D29)-BS_Hist!D31 -> 0 | E14: =SUM(BS_Hist!E26:E30)-BS_Hist!E31 -> 0 | F14: =SUM(BS_Hist!F26:F30)-BS_Hist!F31 -> 0 | H14: =IF(AND(ABS(N(B14))<=5,ABS(N(C14))<=5,ABS(N(D14))<=5,ABS(N(E14))<=5,ABS(N(F14))<=5),"PASS","FAIL") -> PASS
A15: BS: Non-current liabilities sum = published NCL | B15: =SUM(BS_Hist!B33:B35)-BS_Hist!B36 -> 0 | C15: =SUM(BS_Hist!C33:C35)-BS_Hist!C36 -> 0 | D15: =SUM(BS_Hist!D33:D35)-BS_Hist!D36 -> 0 | E15: =SUM(BS_Hist!E33:E35)-BS_Hist!E36 -> 0 | F15: =SUM(BS_Hist!F33:F35)-BS_Hist!F36 -> 0 | H15: =IF(AND(ABS(N(B15))<=5,ABS(N(C15))<=5,ABS(N(D15))<=5,ABS(N(E15))<=5,ABS(N(F15))<=5),"PASS","FAIL") -> PASS
A16: BS: Total liabilities = TCL + TNCL | B16: =BS_Hist!B31+BS_Hist!B36-BS_Hist!B37 -> 0 | C16: =BS_Hist!C31+BS_Hist!C36-BS_Hist!C37 -> 0 | D16: =BS_Hist!D31+BS_Hist!D36-BS_Hist!D37 -> 0 | E16: =BS_Hist!E31+BS_Hist!E36-BS_Hist!E37 -> 0 | F16: =BS_Hist!F31+BS_Hist!F36-BS_Hist!F37 -> 0 | H16: =IF(AND(ABS(N(B16))<=5,ABS(N(C16))<=5,ABS(N(D16))<=5,ABS(N(E16))<=5,ABS(N(F16))<=5),"PASS","FAIL") -> PASS
A17: BS: Parent equity sum = published | B17: =SUM(BS_Hist!B40:B44)-BS_Hist!B45 -> 0 | C17: =SUM(BS_Hist!C40:C44)-BS_Hist!C45 -> 0 | D17: =SUM(BS_Hist!D40:D44)-BS_Hist!D45 -> 0 | E17: =SUM(BS_Hist!E40:E44)-BS_Hist!E45 -> 0 | F17: =SUM(BS_Hist!F40:F44)-BS_Hist!F45 -> 0 | H17: =IF(AND(ABS(N(B17))<=5,ABS(N(C17))<=5,ABS(N(D17))<=5,ABS(N(E17))<=5,ABS(N(F17))<=5),"PASS","FAIL") -> PASS
A18: BS: Total equity = parent + NCI | B18: =BS_Hist!B45+BS_Hist!B46-BS_Hist!B47 -> 0 | C18: =BS_Hist!C45+BS_Hist!C46-BS_Hist!C47 -> 0 | D18: =BS_Hist!D45+BS_Hist!D46-BS_Hist!D47 -> 0 | E18: =BS_Hist!E45+BS_Hist!E46-BS_Hist!E47 -> 0 | F18: =BS_Hist!F45+BS_Hist!F46-BS_Hist!F47 -> 0 | H18: =IF(AND(ABS(N(B18))<=5,ABS(N(C18))<=5,ABS(N(D18))<=5,ABS(N(E18))<=5,ABS(N(F18))<=5),"PASS","FAIL") -> PASS
A19: BS: TL&E = TL + TE | B19: =BS_Hist!B37+BS_Hist!B47-BS_Hist!B48 -> 0 | C19: =BS_Hist!C37+BS_Hist!C47-BS_Hist!C48 -> 0 | D19: =BS_Hist!D37+BS_Hist!D47-BS_Hist!D48 -> 0 | E19: =BS_Hist!E37+BS_Hist!E47-BS_Hist!E48 -> 0 | F19: =BS_Hist!F37+BS_Hist!F47-BS_Hist!F48 -> 0 | H19: =IF(AND(ABS(N(B19))<=5,ABS(N(C19))<=5,ABS(N(D19))<=5,ABS(N(E19))<=5,ABS(N(F19))<=5),"PASS","FAIL") -> PASS
A20: BS: Balance (TA − TL&E) | B20: =BS_Hist!B23-BS_Hist!B48 -> 0 | C20: =BS_Hist!C23-BS_Hist!C48 -> 0 | D20: =BS_Hist!D23-BS_Hist!D48 -> 0 | E20: =BS_Hist!E23-BS_Hist!E48 -> 0 | F20: =BS_Hist!F23-BS_Hist!F48 -> 0 | H20: =IF(AND(ABS(N(B20))<=5,ABS(N(C20))<=5,ABS(N(D20))<=5,ABS(N(E20))<=5,ABS(N(F20))<=5),"PASS","FAIL") -> PASS
A21: X: RE rollforward = RE(t-1) + NI attrib − dividends paid (±$5mm decl-vs-paid timing) | B21: =0 -> 0 | C21: =BS_Hist!B42+IS_Hist!C19+CF_Hist!C36-BS_Hist!C42 -> 1 | D21: =BS_Hist!C42+IS_Hist!D19+CF_Hist!D36-BS_Hist!D42 -> -1 | E21: =BS_Hist!D42+IS_Hist!E19+CF_Hist!E36-BS_Hist!E42 -> 0 | F21: =BS_Hist!E42+IS_Hist!F19+CF_Hist!F36-BS_Hist!F42 -> 0 | H21: =IF(AND(ABS(N(B21))<=5,ABS(N(C21))<=5,ABS(N(D21))<=5,ABS(N(E21))<=5,ABS(N(F21))<=5),"PASS","FAIL") -> PASS
A22: CF: Net cash from operations chain (sum of section) | B22: =SUM(CF_Hist!B6:B16)-CF_Hist!B17 -> 0 | C22: =SUM(CF_Hist!C6:C16)-CF_Hist!C17 -> 0 | D22: =SUM(CF_Hist!D6:D16)-CF_Hist!D17 -> 0 | E22: =SUM(CF_Hist!E6:E16)-CF_Hist!E17 -> 0 | F22: =SUM(CF_Hist!F6:F16)-CF_Hist!F17 -> 0 | H22: =IF(AND(ABS(N(B22))<=5,ABS(N(C22))<=5,ABS(N(D22))<=5,ABS(N(E22))<=5,ABS(N(F22))<=5),"PASS","FAIL") -> PASS
A23: CF: Net cash from investing chain (sum of section) | B23: =SUM(CF_Hist!B20:B28)-CF_Hist!B29 -> 0 | C23: =SUM(CF_Hist!C20:C28)-CF_Hist!C29 -> 0 | D23: =SUM(CF_Hist!D20:D28)-CF_Hist!D29 -> 0 | E23: =SUM(CF_Hist!E20:E28)-CF_Hist!E29 -> 0 | F23: =SUM(CF_Hist!F20:F28)-CF_Hist!F29 -> 0 | H23: =IF(AND(ABS(N(B23))<=5,ABS(N(C23))<=5,ABS(N(D23))<=5,ABS(N(E23))<=5,ABS(N(F23))<=5),"PASS","FAIL") -> PASS
A24: CF: Net cash from financing chain (sum of section) | B24: =SUM(CF_Hist!B32:B39)-CF_Hist!B40 -> 0 | C24: =SUM(CF_Hist!C32:C39)-CF_Hist!C40 -> 0 | D24: =SUM(CF_Hist!D32:D39)-CF_Hist!D40 -> 0 | E24: =SUM(CF_Hist!E32:E39)-CF_Hist!E40 -> 0 | F24: =SUM(CF_Hist!F32:F39)-CF_Hist!F40 -> 0 | H24: =IF(AND(ABS(N(B24))<=5,ABS(N(C24))<=5,ABS(N(D24))<=5,ABS(N(E24))<=5,ABS(N(F24))<=5),"PASS","FAIL") -> PASS
A25: CF: Net change (incl. restricted) = CFO+CFI+CFF+FX | B25: =CF_Hist!B17+CF_Hist!B29+CF_Hist!B40+CF_Hist!B43-CF_Hist!B44 -> 0 | C25: =CF_Hist!C17+CF_Hist!C29+CF_Hist!C40+CF_Hist!C43-CF_Hist!C44 -> 0 | D25: =CF_Hist!D17+CF_Hist!D29+CF_Hist!D40+CF_Hist!D43-CF_Hist!D44 -> 0 | E25: =CF_Hist!E17+CF_Hist!E29+CF_Hist!E40+CF_Hist!E43-CF_Hist!E44 -> 0 | F25: =CF_Hist!F17+CF_Hist!F29+CF_Hist!F40+CF_Hist!F43-CF_Hist!F44 -> 0 | H25: =IF(AND(ABS(N(B25))<=5,ABS(N(C25))<=5,ABS(N(D25))<=5,ABS(N(E25))<=5,ABS(N(F25))<=5),"PASS","FAIL") -> PASS
A26: CF: End cash(incl.restr.) = Begin + net change | B26: =CF_Hist!B45+CF_Hist!B44-CF_Hist!B46 -> 0 | C26: =CF_Hist!C45+CF_Hist!C44-CF_Hist!C46 -> 0 | D26: =CF_Hist!D45+CF_Hist!D44-CF_Hist!D46 -> 0 | E26: =CF_Hist!E45+CF_Hist!E44-CF_Hist!E46 -> 0 | F26: =CF_Hist!F45+CF_Hist!F44-CF_Hist!F46 -> 0 | H26: =IF(AND(ABS(N(B26))<=5,ABS(N(C26))<=5,ABS(N(D26))<=5,ABS(N(E26))<=5,ABS(N(F26))<=5),"PASS","FAIL") -> PASS
A27: CF: Beginning cash continuity (t begin = t-1 end), FY22-25 | B27: =0 -> 0 | C27: =CF_Hist!C45-CF_Hist!B46 -> 0 | D27: =CF_Hist!D45-CF_Hist!C46 -> 0 | E27: =CF_Hist!E45-CF_Hist!D46 -> 0 | F27: =CF_Hist!F45-CF_Hist!E46 -> 0 | H27: =IF(AND(ABS(N(B27))<=5,ABS(N(C27))<=5,ABS(N(D27))<=5,ABS(N(E27))<=5,ABS(N(F27))<=5),"PASS","FAIL") -> PASS
A28: X: CF Consolidated NI = IS Consolidated NI | B28: =CF_Hist!B6-IS_Hist!B17 -> 0 | C28: =CF_Hist!C6-IS_Hist!C17 -> 0 | D28: =CF_Hist!D6-IS_Hist!D17 -> 0 | E28: =CF_Hist!E6-IS_Hist!E17 -> 0 | F28: =CF_Hist!F6-IS_Hist!F17 -> 0 | H28: =IF(AND(ABS(N(B28))<=5,ABS(N(C28))<=5,ABS(N(D28))<=5,ABS(N(E28))<=5,ABS(N(F28))<=5),"PASS","FAIL") -> PASS
A29: X: BS cash = CF Hist BS-figure cash (all 5 yrs, direct tag match) | B29: =BS_Hist!B6-CF_Hist!B48 -> 0 | C29: =BS_Hist!C6-CF_Hist!C48 -> 0 | D29: =BS_Hist!D6-CF_Hist!D48 -> 0 | E29: =BS_Hist!E6-CF_Hist!E48 -> 0 | F29: =BS_Hist!F6-CF_Hist!F48 -> 0 | H29: =IF(AND(ABS(N(B29))<=5,ABS(N(C29))<=5,ABS(N(D29))<=5,ABS(N(E29))<=5,ABS(N(F29))<=5),"PASS","FAIL") -> PASS
A30: X: FY23-25 end cash(incl.restr.) = BS cash + memo restricted | B30: =0 -> 0 | C30: =0 -> 0 | D30: =CF_Hist!D46-CF_Hist!D48-CF_Hist!D47 -> 0 | E30: =CF_Hist!E46-CF_Hist!E48-CF_Hist!E47 -> 0 | F30: =CF_Hist!F46-CF_Hist!F48-CF_Hist!F47 -> 0 | H30: =IF(AND(ABS(N(B30))<=5,ABS(N(C30))<=5,ABS(N(D30))<=5,ABS(N(E30))<=5,ABS(N(F30))<=5),"PASS","FAIL") -> PASS
A31: COBERTURA — drivers de negocio (Drivers_MDA) y paquete de mercado (Market_Package), agregados 2026-08-14. Plantilla del piloto Apple con los checks endurecidos post-refutación: cada check compara contra celdas INDEPENDIENTES (otra hoja, otro documento u otro vintage), nunca contra su propia definición.
A32: DRV: Ventas netas a terceros por segmento suman a IS_Hist ventas netas (FY21-22 presentación original con Global Ventures; FY23-25 re-presentada) | B32: =Drivers_MDA!B34 -> 0 | C32: =Drivers_MDA!C34 -> 0 | D32: =Drivers_MDA!D34 -> 0 | E32: =Drivers_MDA!E34 -> 0 | F32: =Drivers_MDA!F34 -> 0 | H32: =IF(AND(ABS(N(B32))<=0.5,ABS(N(C32))<=0.5,ABS(N(D32))<=0.5,ABS(N(E32))<=0.5,ABS(N(F32))<=0.5),"PASS","FAIL") -> PASS
A33: DRV: Utilidad operativa por segmento + Corporate = IS_Hist utilidad operativa (conciliación del emisor reproducida) | B33: =Drivers_MDA!B52 -> 0 | C33: =Drivers_MDA!C52 -> 0 | D33: =Drivers_MDA!D52 -> 0 | E33: =Drivers_MDA!E52 -> 0 | F33: =Drivers_MDA!F52 -> 0 | H33: =IF(AND(ABS(N(B33))<=0.5,ABS(N(C33))<=0.5,ABS(N(D33))<=0.5,ABS(N(E33))<=0.5,ABS(N(F33))<=0.5),"PASS","FAIL") -> PASS
A34: DRV: COGS por segmento (FY23-25, incl. Corporate y eliminaciones) = IS_Hist costo de ventas | D34: =Drivers_MDA!D70 -> 0 | E34: =Drivers_MDA!E70 -> 0 | F34: =Drivers_MDA!F70 -> 0 | H34: =IF(AND(ABS(N(D34))<=0.5,ABS(N(E34))<=0.5,ABS(N(F34))<=0.5),"PASS","FAIL") -> PASS
A35: DRV: bridge de ingresos del MD&A — la suma de componentes coincide con el total reportado (±1.5pp de redondeo a 1%) Y el total reportado coincide con el crecimiento real de IS_Hist (±1.5pp). FY2021 solo el primer término (FY2020 fuera de ventana). F es conteo de incumplimientos | B35: =IF(ABS(Drivers_MDA!B21-Drivers_MDA!B20)>0.015,1,0) -> 0 | C35: =IF(ABS(Drivers_MDA!C21-Drivers_MDA!C20)>0.015,1,0)+IF(ABS(Drivers_MDA!C20-Drivers_MDA!C22)>0.015,1,0) -> 0 | D35: =IF(ABS(Drivers_MDA!D21-Drivers_MDA!D20)>0.015,1,0)+IF(ABS(Drivers_MDA!D20-Drivers_MDA!D22)>0.015,1,0) -> 0 | E35: =IF(ABS(Drivers_MDA!E21-Drivers_MDA!E20)>0.015,1,0)+IF(ABS(Drivers_MDA!E20-Drivers_MDA!E22)>0.015,1,0) -> 0 | F35: =IF(ABS(Drivers_MDA!F21-Drivers_MDA!F20)>0.015,1,0)+IF(ABS(Drivers_MDA!F20-Drivers_MDA!F22)>0.015,1,0) -> 0 | H35: =IF(AND(N(B35)=0,N(C35)=0,N(D35)=0,N(E35)=0,N(F35)=0),"PASS","FAIL") -> PASS
A36: XREF: Sector_KPIs (bridge FY2025 C7:C11, unit cases B5:C5 y ancla de ingresos B6:C6) = Drivers_MDA / IS_Hist — constantes preexistentes de otra hoja contra la serie del filing | F36: =Drivers_MDA!F168+Drivers_MDA!F169+Drivers_MDA!F170 -> 0 | H36: =IF(AND(ABS(N(F36))<=0.0000001),"PASS","FAIL") -> PASS
A37: FCST: anclas del motor — Forecast!B5:B9 = bridge FY2025 reportado del MD&A y Forecast!B10 = IS_Hist!F5 (suma de |deltas| de Drivers_MDA!F162:F167) | F37: =ABS(Drivers_MDA!F162)+ABS(Drivers_MDA!F163)+ABS(Drivers_MDA!F164)+ABS(Drivers_MDA!F165)+ABS(Drivers_MDA!F166)+ABS(Drivers_MDA!F167) -> 0 | H37: =IF(AND(ABS(N(F37))<=0.0000001),"PASS","FAIL") -> PASS
