Workbook

Sheet EEFF
A1: Global Bank Corporation y Subsidiarias
A2: Estados Financieros Auditados FY21-FY25
A3: en B/. sin escala
A5: Años | B5: FY21A | C5: FY22A | D5: FY23A | E5: FY24A | F5: FY25A | G5: FY26E | H5: FY27E | I5: FY28E | J5: FY29E | K5: FY30E
A6: Estado consolidado de ganancia o pérdida
A7: Ingresos por intereses | B7: 436095180 | C7: 419112916 | D7: 454333887 | E7: 503666534 | F7: 523500468
A8: Gasto por intereses | B8: -263333029 | C8: -238053406 | D8: -281836291 | E8: -350182264 | F8: -366248027
A9: Ingresos neto por intereses | B9: 172762151 | C9: 181059510 | D9: 172497596 | E9: 153484270 | F9: 157252441
A10: Comisiones ganadas | B10: 48561754 | C10: 57798314 | D10: 66344055 | E10: 69992300 | F10: 70656110
A11: Gastos por comisiones | B11: -13491941 | C11: -19374865 | D11: -22088949 | E11: -24919428 | F11: -26262774
A12: Ingresos neto por comisiones | B12: 35069813 | C12: 38423449 | D12: 44255106 | E12: 45072872 | F12: 44393336
A13: Ingresos neto por intereses y comisiones, antes de provisión | B13: 207831964 | C13: 219482959 | D13: 216752702 | E13: 198557142 | F13: 201645777
A14: Provisión para préstamos incobrables | B14: 83497811 | C14: 59032479 | D14: 48957742 | E14: 34695854 | F14: 28431911
A15: Reversión de provisión riesgo país | B15: 1206330 | C15: -905789 | D15: 363938 | E15: -326333 | F15: -613051
A16: Reversión de provisión para inversiones | B16: 500143 | C16: 2897059 | D16: 474038 | E16: -60659 | F16: -198747
A17: Total de provisiones | B17: 85204284 | C17: 61023749 | D17: 49795718 | E17: 34308862 | F17: 27620113
A18: Ingresos neto por intereses y comisiones, después de provisión | B18: 122627680 | C18: 158459210 | D18: 166956984 | E18: 164248280 | F18: 174025664
... A33: Ganancia del año | B33: 26593150 | C33: 37263494 | D33: 47505926 | E33: 47832787 | F33: 48262456
A35: Años | B35: FY21A | C35: FY22A | D35: FY23A | E35: FY24A | F35: FY25A | G35: FY26E | H35: FY27E | I35: FY28E | J35: FY29E | K35: FY30E
A36: Estado consolidado de situación financiera
A37: Efectivo y depósitos en banco | B37: 508316487 | C37: 422163231 | D37: 354965856 | E37: 378198724 | F37: 433699566
A38: Valores comprados bajo acuerdos de reventa | B38: 306301 | C38: 285200 | D38: 3547807 | E38: 4956931 | F38: 4997637
A39: Inversiones en valores, neto | B39: 1110163904 | C39: 1079204941 | D39: 1053410069 | E39: 1049326162 | F39: 1136648533
A40: Préstamos, neto | B40: 6007976619 | C40: 6138222161 | D40: 6212554475 | E40: 6315709567 | F40: 6141543608
A41: Propiedades, mobiliario, equipo y mejoras | B41: 195030353 | C41: 197759650 | D41: 190418187 | E41: 191401031 | F41: 192001647
A42: Activos por derechos de uso | B42: 19425507 | C42: 15584822 | D42: 13301035 | E42: 11291589 | F42: 9660940
A43: Activos varios | B43: 482324722 | C43: 547376430 | D43: 584781470 | E43: 569398628 | F43: 584449645
A44: Total de activos | B44: 8323543893 | C44: 8400596435 | D44: 8412978899 | E44: 8520282632 | F44: 8503001576
A45: Depósitos de clientes | B45: 5189459231 | C45: 5178659636 | D45: 5205576287 | E45: 5264634266 | F45: 5715472860
A46: Depósitos de bancos | B46: 44910134 | C46: 64413383 | D46: 82919955 | E46: 80815921 | F46: 16750000
A47: Intereses acumulados por pagar | B47: 40781723 | C47: 32169806 | D47: 33051550 | E47: 36197140 | F47: 40586551
A48: Total de depósitos | B48: 5275151088 | C48: 5275242825 | D48: 5321547792 | E48: 5381647327 | F48: 5772809411
... A52: Bonos corporativos | B52: 1055663563 | C52: 439235300 | D52: 388450729 | E52: 374440557 | F52: 374069381
A53: Bonos subordinados | B53: 7833557
A54: Bonos perpetuos | B54: 160763868 | C54: 177495857 | D54: 177965873 | E54: 178016538 | F54: 177320865
A55: Intereses acumulados por pagar | B55: 14036040 | C55: 13211416 | D55: 25606793 | E55: 25872345 | F55: 23085224
A56: Total de financiamientos | B56: 2121472574 | C56: 2228809260 | D56: 2244910728 | E56: 2270922588 | F56: 1844742611
A57: Pasivos por arrendamientos | B57: 20847797 | C57: 17277420 | D57: 15302729 | E57: 12991713 | F57: 11539789
A58: Pasivos varios | B58: 116353854 | C58: 119112591 | D58: 119464406 | E58: 123345219 | F58: 105129335
A59: Total de pasivos | B59: 7533825313 | C59: 7640442096 | D59: 7701225655 | E59: 7788906847 | F59: 7734221146
...

Sheet Supuestos
A1: Global Bank Corporation y Subsidiarias
A3: COLOR KEY: Input (azul) · Fórmula (negro) · Link inter-hoja (verde)
A4: Escenario (1=Base, 2=Bull, 3=Bear)
A5: Selector escenario | C5: 1 | M5: caso | N5: NOT_DISCLOSED | Q5: Input de escenario desde fuente citada o NOT_DISCLOSED.
A6: Escenario activo | C6: =CHOOSE($C$5,"Base","Bull","Bear") -> Base | M6: moneda del modelo | N6: NOT_DISCLOSED | Q6: Selector de caso activo C5: Base/Bull/Bear.
A8: Años | B8: FY21A | C8: FY22A | D8: FY23A | E8: FY24A | F8: FY25A | G8: FY26E | H8: FY27E | I8: FY28E | J8: FY29E | K8: FY30E | M8: Unidad | N8: Fuente / nota | Q8: Rationale
A10: A. INGRESO POR INTERESES — CRECIMIENTO (% YoY)
A11: Ingresos por intereses — driver activo | G11: =CHOOSE($C$5,G13,G14,G12) -> 0.0394 | H11: =CHOOSE($C$5,H13,H14,H12) -> 0.0394 | I11: =CHOOSE($C$5,I13,I14,I12) -> 0.0394 | J11: =CHOOSE($C$5,J13,J14,J12) -> 0.0394 | K11: =CHOOSE($C$5,K13,K14,K12) -> 0.0394 | M11: % | N11: driver_tree:interest_income_growth | Q11: Selector de caso activo C5: Base/Bull/Bear.
A12: Bear | G12: 0.0194 | H12: 0.0194 | I12: 0.0194 | J12: 0.0194 | K12: 0.0194 | M12: % | N12: driver_tree:interest_income_growth | Q12: Escenario driver citado; NOT_DISCLOSED si no hay fuente explícita.
A13: Base | G13: 0.0394 | H13: 0.0394 | I13: 0.0394 | J13: 0.0394 | K13: 0.0394 | M13: % | N13: driver_tree:interest_income_growth | Q13: Escenario driver citado; NOT_DISCLOSED si no hay fuente explícita.
A14: Bull | G14: 0.0594 | H14: 0.0594 | I14: 0.0594 | J14: 0.0594 | K14: 0.0594 | M14: % | N14: driver_tree:interest_income_growth | Q14: Escenario driver citado; NOT_DISCLOSED si no hay fuente explícita.
A15: Ingresos por intereses (hist, ref EEFF) | B15: =EEFF!B7 -> 436095180 | C15: =EEFF!C7 -> 419112916 | D15: =EEFF!D7 -> 454333887 | E15: =EEFF!E7 -> 503666534 | F15: =EEFF!F7 -> 523500468 | M15: moneda del modelo | N15: EEFF:Ingresos por intereses@row7 | Q15: Mirror histórico desde fuente citada.
A16: Ingresos por intereses YoY histórico (ref EEFF) | C16: =EEFF!C7/EEFF!B7-1 -> -0.038941646 | D16: =EEFF!D7/EEFF!C7-1 -> 0.08403695 | E16: =EEFF!E7/EEFF!D7-1 -> 0.10858236 | F16: =EEFF!F7/EEFF!E7-1 -> 0.039379098 | M16: % | N16: EEFF:Ingresos por intereses@row7 | Q16: Fórmula viva: año actual / año previo - 1.
A18: B. GASTO POR INTERESES (% de ingreso x int.)
A19: Gasto por intereses — driver activo | G19: =CHOOSE($C$5,G21,G22,G20) -> -0.6996 | H19: =CHOOSE($C$5,H21,H22,H20) -> -0.6996 | I19: =CHOOSE($C$5,I21,I22,I20) -> -0.6996 | J19: =CHOOSE($C$5,J21,J22,J20) -> -0.6996 | K19: =CHOOSE($C$5,K21,K22,K20) -> -0.6996 | M19: % | N19: driver_tree:interest_expense_ratio | Q19: Selector de caso activo C5: Base/Bull/Bear.
A20: Bear | G20: -0.6796 | H20: -0.6796 | I20: -0.6796 | J20: -0.6796 | K20: -0.6796 | M20: % | N20: driver_tree:interest_expense_ratio | Q20: Escenario driver citado; NOT_DISCLOSED si no hay fuente explícita.
A21: Base | G21: -0.6996 | H21: -0.6996 | I21: -0.6996 | J21: -0.6996 | K21: -0.6996 | M21: % | N21: driver_tree:interest_expense_ratio | Q21: Escenario driver citado; NOT_DISCLOSED si no hay fuente explícita.
A22: Bull | G22: -0.7196 | H22: -0.7196 | I22: -0.7196 | J22: -0.7196 | K22: -0.7196 | M22: % | N22: driver_tree:interest_expense_ratio | Q22: Escenario driver citado; NOT_DISCLOSED si no hay fuente explícita.
A23: Gasto por intereses ÷ ingresos (hist, ref EEFF) | B23: =EEFF!B8/EEFF!B7 -> -0.60384302 | C23: =EEFF!C8/EEFF!C7 -> -0.56799349 | D23: =EEFF!D8/EEFF!D7 -> -0.62032857 | E23: =EEFF!E8/EEFF!E7 -> -0.69526609 | F23: =EEFF!F8/EEFF!F7 -> -0.69961356 | M23: % | N23: EEFF:Gasto por intereses@row8; EEFF:Ingresos por intereses@row7 | Q23: Mirror histórico desde fuente citada.
A25: C. CARTERA DE PRÉSTAMOS (crecimiento % YoY)
A26: Préstamos, neto (hist, ref EEFF) | B26: =EEFF!B40 -> 6007976619 | C26: =EEFF!C40 -> 6138222161 | D26: =EEFF!D40 -> 6212554475 | E26: =EEFF!E40 -> 6315709567 | F26: =EEFF!F40 -> 6141543608 | M26: moneda del modelo | N26: EEFF:Préstamos, neto@row40 | Q26: Mirror histórico desde fuente citada.
A27: Préstamos, neto YoY histórico (ref EEFF) | C27: =EEFF!C40/EEFF!B40-1 -> 0.02167877 | D27: =EEFF!D40/EEFF!C40-1 -> 0.012109746 | E27: =EEFF!E40/EEFF!D40-1 -> 0.016604296 | F27: =EEFF!F40/EEFF!E40-1 -> -0.027576626 | M27: % | N27: EEFF:Préstamos, neto@row40 | Q27: Fórmula viva: año actual / año previo - 1.
A28: Crecimiento de préstamos netos (% YoY) — driver activo | G28: =CHOOSE($C$5,G30,G31,G29) -> 0.0057 | H28: =CHOOSE($C$5,H30,H31,H29) -> 0.0057 | I28: =CHOOSE($C$5,I30,I31,I29) -> 0.0057 | J28: =CHOOSE($C$5,J30,J31,J29) -> 0.0057 | K28: =CHOOSE($C$5,K30,K31,K29) -> 0.0057 | M28: % | N28: driver_tree:loan_growth; macro_assumptions:gdp_growth_nominal=0.04 | Q28: Selector de caso activo C5: Base/Bull/Bear.
A29: Bear | G29: 0 | H29: 0 | I29: 0 | J29: 0 | K29: 0 | M29: % | N29: driver_tree:loan_growth; macro_assumptions:gdp_growth_nominal=0.04 | Q29: Floor firmado: si base > PIB, bear = PIB; si base <= PIB, bear = 0%; sin tasa negativa.
A30: Base | G30: 0.0057 | H30: 0.0057 | I30: 0.0057 | J30: 0.0057 | K30: 0.0057 | M30: % | N30: driver_tree:loan_growth; macro_assumptions:gdp_growth_nominal=0.04 | Q30: Base = max(promedio histórico, 0%) para volumen de intermediación/cartera.
A31: Bull | G31: 0.0257 | H31: 0.0257 | I31: 0.0257 | J31: 0.0257 | K31: 0.0257 | M31: % | N31: driver_tree:loan_growth; macro_assumptions:gdp_growth_nominal=0.04 | Q31: Bull = base + spread declarado; sin tasa negativa.
A33: D. DEPÓSITOS DE CLIENTES (crecimiento % YoY)
A34: Depósitos de clientes (hist, ref EEFF) | B34: =EEFF!B45 -> 5189459231 | C34: =EEFF!C45 -> 5178659636 | D34: =EEFF!D45 -> 5205576287 | E34: =EEFF!E45 -> 5264634266 | F34: =EEFF!F45 -> 5715472860 | M34: moneda del modelo | N34: EEFF:Depósitos de clientes@row45 | Q34: Mirror histórico desde fuente citada.
A35: Depósitos de clientes YoY histórico (ref EEFF) | C35: =EEFF!C45/EEFF!B45-1 -> -0.0020810637 | D35: =EEFF!D45/EEFF!C45-1 -> 0.0051976096 | E35: =EEFF!E45/EEFF!D45-1 -> 0.011345138 | F35: =EEFF!F45/EEFF!E45-1 -> 0.085635311 | M35: % | N35: EEFF:Depósitos de clientes@row45 | Q35: Fórmula viva: año actual / año previo - 1.
A36: Crecimiento de depósitos de clientes (% YoY) — driver activo | G36: =CHOOSE($C$5,G38,G39,G37) -> 0.025 | H36: =CHOOSE($C$5,H38,H39,H37) -> 0.025 | I36: =CHOOSE($C$5,I38,I39,I37) -> 0.025 | J36: =CHOOSE($C$5,J38,J39,J37) -> 0.025 | K36: =CHOOSE($C$5,K38,K39,K37) -> 0.025 | M36: % | N36: driver_tree:deposit_growth; macro_assumptions:gdp_growth_nominal=0.04 | Q36: Selector de caso activo C5: Base/Bull/Bear.
A37: Bear | G37: 0 | H37: 0 | I37: 0 | J37: 0 | K37: 0 | M37: % | N37: driver_tree:deposit_growth; macro_assumptions:gdp_growth_nominal=0.04 | Q37: Floor firmado: si base > PIB, bear = PIB; si base <= PIB, bear = 0%; sin tasa negativa.
A38: Base | G38: 0.025 | H38: 0.025 | I38: 0.025 | J38: 0.025 | K38: 0.025 | M38: % | N38: driver_tree:deposit_growth; macro_assumptions:gdp_growth_nominal=0.04 | Q38: Base = max(promedio histórico, 0%) para volumen de intermediación/cartera.
A39: Bull | G39: 0.045 | H39: 0.045 | I39: 0.045 | J39: 0.045 | K39: 0.045 | M39: % | N39: driver_tree:deposit_growth; macro_assumptions:gdp_growth_nominal=0.04 | Q39: Bull = base + spread declarado; sin tasa negativa.
A41: E. PROVISIÓN CREDITICIA (tasa sobre préstamos)
A42: Provisión para préstamos incobrables (hist, ref EEFF) | B42: =EEFF!B14 -> 83497811 | C42: =EEFF!C14 -> 59032479 | D42: =EEFF!D14 -> 48957742 | E42: =EEFF!E14 -> 34695854 | F42: =EEFF!F14 -> 28431911 | M42: moneda del modelo | N42: EEFF:Provisión para préstamos incobrables@row14 | Q42: Mirror histórico desde fuente citada.
A43: Provisión / préstamos netos (hist, ref EEFF) | C43: =EEFF!C14/EEFF!B40 -> 0.0098256839 | D43: =EEFF!D14/EEFF!C40 -> 0.007975883 | E43: =EEFF!E14/EEFF!D40 -> 0.0055847967 | F43: =EEFF!F14/EEFF!E40 -> 0.0045017762 | M43: % | N43: EEFF:Provisión para préstamos incobrables@row14; EEFF:Préstamos, neto@row40 | Q43: Mirror histórico desde fuente citada.
A44: Tasa de provisión sobre préstamos BOP — driver activo | G44: =CHOOSE($C$5,G46,G47,G45) -> 0.0045 | H44: =CHOOSE($C$5,H46,H47,H45) -> 0.0045 | I44: =CHOOSE($C$5,I46,I47,I45) -> 0.0045 | J44: =CHOOSE($C$5,J46,J47,J45) -> 0.0045 | K44: =CHOOSE($C$5,K46,K47,K45) -> 0.0045 | M44: % | N44: driver_tree:credit_provision_rate | Q44: Selector de caso activo C5: Base/Bull/Bear.
A45: Bear | G45: 0.006 | H45: 0.006 | I45: 0.006 | J45: 0.006 | K45: 0.006 | M45: % | N45: driver_tree:credit_provision_rate | Q45: Escenario driver citado; NOT_DISCLOSED si no hay fuente explícita.
A46: Base | G46: 0.0045 | H46: 0.0045 | I46: 0.0045 | J46: 0.0045 | K46: 0.0045 | M46: % | N46: driver_tree:credit_provision_rate | Q46: Escenario driver citado; NOT_DISCLOSED si no hay fuente explícita.
A47: Bull | G47: 0.003 | H47: 0.003 | I47: 0.003 | J47: 0.003 | K47: 0.003 | M47: % | N47: driver_tree:credit_provision_rate | Q47: Escenario driver citado; NOT_DISCLOSED si no hay fuente explícita.
...

Sheet Notas_EEFF
A1: Global Bank Corporation y Subsidiarias
A2: Notas a los Estados Financieros
A3: Fuente: informes auditados vía OCR Mistral (verbatim).
A5: Año | B5: Documento fuente | C5: Página OCR | D5: Tabla OCR / sección | E5: Nota # | F5: Título original de la nota | G5: Categoría modelable | H5: Line item EEFF | I5: Sub-line item / detalle | J5: Texto original / disclosure | K5: Monto reportado | L5: Moneda | M5: Unidad / escala | N5: Fecha / venc. / tasa / plazo | O5: Contraparte / contrato / instrumento | P5: Impacto en Supuestos | Q5: Impacto en ModeloFinanciero | R5: Link a celda EEFF | S5: Comentario de extracción | T5: Status
A6: 2021 | B6: INA_GLOBAN_2021_0.pdf | C6: page-104 | D6: markdown.md | E6: 3 | F6: 3. Base de preparación | G6: Políticas contables | J6: ### 3.1 Estado de cumplimiento | T6: OK
A7: 2021 | B7: INA_GLOBAN_2021_0.pdf | C7: page-104 | D7: markdown.md | E7: 3 | F7: 3. Base de preparación | G7: Políticas contables | J7: Los estados financieros consolidados han sido preparados de conformidad con las Normas Internacionales de Información Financiera (NIIF's), emitidas por IASB. | T7: OK
A8: 2021 | B8: INA_GLOBAN_2021_0.pdf | C8: page-104 | D8: markdown.md | E8: 3 | F8: 3. Base de preparación | G8: Políticas contables | J8: - 15 - | T8: OK
A9: 2021 | B9: INA_GLOBAN_2021_0.pdf | C9: page-105 | D9: markdown.md | E9: 3 | F9: 3. Base de preparación | G9: Políticas contables | J9: ## 3.2 Base de preparación | T9: OK
A10: 2021 | B10: INA_GLOBAN_2021_0.pdf | C10: page-105 | D10: markdown.md | E10: 3 | F10: 3. Base de preparación | G10: Políticas contables | J10: Los estados financieros consolidados han sido preparados bajo la base del costo histórico, excepto por las inversiones al valor razonable con cambios en resultados; las inversiones al valor razonable con cambios en otros resultados integrales, los activos o pasivos con coberturas de valor razonable y los instrumentos derivados los cuales se presentan a su valor razonable. | T10: OK
A11: 2021 | B11: INA_GLOBAN_2021_0.pdf | C11: page-105 | D11: markdown.md | E11: 3 | F11: 3. Base de preparación | G11: Políticas contables | J11: El costo histórico generalmente se basa en el valor razonable de la contraprestación entregada a cambio de bienes y servicios. | T11: OK
A12: 2021 | B12: INA_GLOBAN_2021_0.pdf | C12: page-105 | D12: markdown.md | E12: 3 | F12: 3. Base de preparación | G12: Políticas contables | J12: Valor razonable es el precio que se recibiría por vender un activo o pagar para transferir un pasivo en una transacción ordenada entre participantes del mercado en la fecha de valoración, independientemente de si ese precio es observable directamente o estimado utilizando otra técnica de valoración directa. Al estimar el valor razonable de un activo o un pasivo, se tiene en cuenta las características del activo o pasivo si los participantes del mercado toman en cuenta esas características a la hora de fijar el precio del activo o pasivo a la fecha de medición. El valor razonable a efectos de valoración y/o revelación en los estados financieros consolidados se determina de la forma previamente dicha, a excepción de las transacciones de pagos basados en acciones que se encuentran dentro del alcance de la NIIF 2, las operaciones de leasing que están dentro del alcance de la NIIF 16, y mediciones que tienen algunas similitudes con valor razonable, pero que no son valor razonable, tales como el valor neto realizable de la NIC 2 o el valor en uso de la NIC 36. | T12: OK
A13: 2021 | B13: INA_GLOBAN_2021_0.pdf | C13: page-105 | D13: markdown.md | E13: 3 | F13: 3. Base de preparación | G13: Políticas contables | J13: Los estados financieros consolidados han sido preparados por la Administración asumiendo que el Banco continuará operando como un negocio en marcha. El impacto COVID-19 sobre las operaciones del Banco se describen en la Nota 34 de los estados financieros consolidados. | T13: OK
A14: 2021 | B14: INA_GLOBAN_2021_0.pdf | C14: page-105 | D14: markdown.md | E14: 3 | F14: 3. Base de preparación | G14: Políticas contables | J14: ## 3.3 Base de consolidación | T14: OK
A15: 2021 | B15: INA_GLOBAN_2021_0.pdf | C15: page-105 | D15: markdown.md | E15: 3 | F15: 3. Base de preparación | G15: Políticas contables | J15: Los estados financieros consolidados incluyen los del Banco y sus subsidiarias en las que tiene control. El control se obtiene cuando se cumplen todos los criterios a continuación: | T15: OK
A16: 2021 | B16: INA_GLOBAN_2021_0.pdf | C16: page-105 | D16: markdown.md | E16: 3 | F16: 3. Base de preparación | G16: Políticas contables | J16: - Tiene poder sobre la inversión; - Está expuesto, o tiene los derechos, a los rendimientos variables derivados de su participación con dicha entidad, y - Tiene la capacidad de afectar tales rendimientos a través de su poder sobre la entidad en la que invierte. | T16: OK
A17: 2021 | B17: INA_GLOBAN_2021_0.pdf | C17: page-105 | D17: markdown.md | E17: 3 | F17: 3. Base de preparación | G17: Políticas contables | J17: El Banco reevalúa si controla una entidad si los hechos y circunstancias indican que hay cambios en uno o más de los tres elementos de control que se listaron anteriormente. | T17: OK
... A346: 2021 | B346: INA_GLOBAN_2021_0.pdf | C346: page-135 | D346: markdown.md | E346: 4 | F346: 4. Administración de riesgos financieros | G346: Riesgo financiero | J346: ## Depósitos a plazo colocados en bancos | T346: OK
A347: 2021 | B347: INA_GLOBAN_2021_0.pdf | C347: page-135 | D347: markdown.md | E347: 4 | F347: 4. Administración de riesgos financieros | G347: Riesgo financiero | J347: Al 30 de junio de 2021, se mantiene depósitos a plazo en bancos por B/.292,938,297 (2020: B/.312,958,879). Los depósitos a plazo en bancos son mantenidos en instituciones financieras locales y extranjeras. Estas instituciones cuentan con calificaciones locales y/o internacionales, en su mayoría con grado de inversión internacional de al menos BBB- según Fitch Ratings o Standard and Poors, o Baa3 por Moody's. | K347: 292938297 | L347: B/. | T347: OK
A348: 2021 | B348: INA_GLOBAN_2021_0.pdf | C348: page-135 | D348: markdown.md | E348: 4 | F348: 4. Administración de riesgos financieros | G348: Riesgo financiero | J348: - 46 - | T348: OK
A349: 2021 | B349: INA_GLOBAN_2021_0.pdf | C349: page-136 | D349: markdown.md | E349: 4 | F349: 4. Administración de riesgos financieros | G349: Riesgo financiero | J349: ## 4.2.2.4 Concentración del riesgo de crédito | T349: OK
A350: 2021 | B350: INA_GLOBAN_2021_0.pdf | C350: page-136 | D350: markdown.md | E350: 4 | F350: 4. Administración de riesgos financieros | G350: Riesgo financiero | J350: El Banco monitorea la concentración de riesgo de crédito por sector y ubicación geográfica. El análisis de la concentración de los riesgos de crédito a la fecha de los estados financieros consolidados es la siguiente: | T350: OK
A351: 2021 | B351: INA_GLOBAN_2021_0.pdf | C351: page-136 | D351: tbl-85.html | E351: 4 | F351: 4. Administración de riesgos financieros | G351: Riesgo financiero | J351: [tbl-85.html](tbl-85.html) | T351: OK
A352: 2021 | B352: INA_GLOBAN_2021_0.pdf | C352: page-136 | D352: markdown.md | E352: 4 | F352: 4. Administración de riesgos financieros | G352: Riesgo financiero | J352: En la concentración por sector, el rubro de otros préstamos corresponde a facilidades crediticias a entidades bancarias, cooperativas, compañías de seguros, empresas financieras, gobierno, organismos internacionales y organizaciones no gubernamentales. | T352: OK
A353: 2021 | B353: INA_GLOBAN_2021_0.pdf | C353: page-136 | D353: markdown.md | E353: 4 | F353: 4. Administración de riesgos financieros | G353: Riesgo financiero | J353: Las concentraciones geográficas de la cartera de préstamos están basadas, en la ubicación del deudor. En cuanto a la concentración geográfica para las inversiones está basada en el domicilio del emisor de la inversión. | T353: OK
A354: 2021 | B354: INA_GLOBAN_2021_0.pdf | C354: page-136 | D354: markdown.md | E354: 4 | F354: 4. Administración de riesgos financieros | G354: Riesgo financiero | J354: - 47 - | T354: OK
A355: 2021 | B355: INA_GLOBAN_2021_0.pdf | C355: page-137 | D355: markdown.md | E355: 4 | F355: 4. Administración de riesgos financieros | G355: Riesgo financiero | J355: ## 4.3 Riesgo de liquidez o financiamiento | T355: OK
A356: 2021 | B356: INA_GLOBAN_2021_0.pdf | C356: page-137 | D356: markdown.md | E356: 4 | F356: 4. Administración de riesgos financieros | G356: Riesgo financiero | J356: El riesgo de liquidez se define como el riesgo de que el Banco se encuentre dificultades para obtener los fondos para cumplir con sus compromisos u obligaciones a tiempo. | T356: OK
A357: 2021 | B357: INA_GLOBAN_2021_0.pdf | C357: page-137 | D357: markdown.md | E357: 4 | F357: 4. Administración de riesgos financieros | G357: Riesgo financiero | J357: La Regulación Bancaria en Panamá requiere que los bancos de licencia general mantengan en todo momento un saldo mínimo de activos líquidos, según definición en el Acuerdo No. 4-2008 de la Superintendencia de Bancos de Panamá, no inferior al 30% de sus depósitos, sin embargo, producto de las estrictas políticas de liquidez para la cobertura de sus operaciones pasivas, la liquidez del Banco en base a esta norma al 30 de junio de 2021 fue 49.33% (2020: 50.27%). | T357: OK
A358: 2021 | B358: INA_GLOBAN_2021_0.pdf | C358: page-137 | D358: markdown.md | E358: 4 | F358: 4. Administración de riesgos financieros | G358: Riesgo financiero | J358: El riesgo de liquidez ocasionado por el descalce de plazos entre activos y pasivos es medido utilizando el Gap de liquidez o calce financiero. En este análisis se realizan simulaciones y escenarios de "stress" basados en las dificultades que pudieran ocasionar una falta de liquidez, tales como: retiros inesperados de fondos aportados por acreedores o clientes, deterioro de la calidad de la cartera de préstamos, volatilidad de los recursos captados, etc. | T358: OK
A359: 2021 | B359: INA_GLOBAN_2021_0.pdf | C359: page-137 | D359: markdown.md | E359: 4 | F359: 4. Administración de riesgos financieros | G359: Riesgo financiero | J359: A continuación, se detallan los índices de liquidez legal correspondientes al margen de activos líquidos sobre los depósitos recibidos de clientes del Banco a la fecha de los estados financieros consolidados, como sigue: | T359: OK
... A397: 2022 | B397: INA_GLOBAN_2022_0.pdf | C397: page-151 | D397: tbl-96.html | E397: 6 | F397: 6. Saldos y transacciones con partes relacionadas | G397: Partes relacionadas | J397: [tbl-96.html](tbl-96.html) | T397: OK
A398: 2022 | B398: INA_GLOBAN_2022_0.pdf | C398: page-151 | D398: markdown.md | E398: 6 | F398: 6. Saldos y transacciones con partes relacionadas | G398: Partes relacionadas | J398: Al 30 de junio de 2022, los colaterales que garantizan los créditos a partes relacionadas sumaban B/.127,071,808 (2021: B/.114,125,430), los cuales corresponden a garantías inmuebles, muebles y títulos en valores. | K398: 127071808 | L398: B/. | T398: OK
A399: 2022 | B399: INA_GLOBAN_2022_0.pdf | C399: page-151 | D399: markdown.md | E399: 6 | F399: 6. Saldos y transacciones con partes relacionadas | G399: Partes relacionadas | J399: Al 30 de junio de 2022, no hay préstamos con partes relacionadas con indicios de deterioro. Al 30 de junio de 2022, los préstamos con partes relacionadas tienen fecha de vencimiento entre julio 2022 hasta abril 2052 y tasas de interés anual que oscilan entre $2.75\%$ y $7.25\%$ (2021: tienen vencimiento entre julio de 2021 hasta julio de 2051 y tasas de interés anual que oscilan entre $2.75\%$ y $8.00\%$). | K399: 2.75 | L399: B/. | T399: OK
A400: 2022 | B400: INA_GLOBAN_2022_0.pdf | C400: page-152 | D400: tbl-97.html | E400: 7 | F400: 7. Efectivo y equivalentes de efectivo | G400: Working capital | J400: [tbl-97.html](tbl-97.html) | T400: OK
A401: 2022 | B401: INA_GLOBAN_2022_0.pdf | C401: page-152 | D401: markdown.md | E401: 7 | F401: 7. Efectivo y equivalentes de efectivo | G401: Working capital | J401: Al 30 de junio de 2022, existían depósitos a plazo fijo con vencimientos originales mayor a 90 días por B/.2,430,414 (2021: B/.32,599,556). Además, existen depósitos a plazo fijo restringidos por B/.4,227,529 (2021: B/.1,482,735) que garantizan obligaciones financieras. | K401: 2430414 | L401: B/. | T401: OK
A402: 2022 | B402: INA_GLOBAN_2022_0.pdf | C402: page-152 | D402: markdown.md | E402: 8 | F402: 8. Valores comprados bajo acuerdos de reventa | G402: Ingresos | J402: Al 30 de junio de 2022, los valores comprados bajo acuerdos de reventa por B/.285,200 (2021: B/.306,301) con vencimiento en mayo y junio 2023 (2021: con vencimiento en septiembre 2021, mayo 2022 y junio 2022), están garantizados por acciones y bonos de empresas que cotizan en la Bolsa de Valores de Panamá. | K402: 285200 | L402: B/. | T402: OK
A403: 2022 | B403: INA_GLOBAN_2022_0.pdf | C403: page-152 | D403: markdown.md | E403: 9 | F403: 9. Inversiones en valores, neto | G403: Otros | J403: A continuación, el detalle de las inversiones en valores: | T403: OK
A404: 2022 | B404: INA_GLOBAN_2022_0.pdf | C404: page-152 | D404: tbl-98.html | E404: 9 | F404: 9. Inversiones en valores, neto | G404: Otros | J404: [tbl-98.html](tbl-98.html) | T404: OK
A405: 2022 | B405: INA_GLOBAN_2022_0.pdf | C405: page-152 | D405: markdown.md | E405: 9 | F405: 9. Inversiones en valores, neto | G405: Otros | J405: - 66 - | T405: OK
A406: 2022 | B406: INA_GLOBAN_2022_0.pdf | C406: page-153 | D406: markdown.md | E406: 9 | F406: 9. Inversiones en valores, neto | G406: Otros | J406: ## 9.1 Valores al valor razonable con cambios en otros resultados integrales | T406: OK
...

Sheet ModeloFinanciero
A1: Global Bank Corporation y Subsidiarias
A2: Estados Financieros Auditados FY21-FY25
A3: en B/. sin escala
A5: Años | B5: FY21A | C5: FY22A | D5: FY23A | E5: FY24A | F5: FY25A | G5: FY26E | H5: FY27E | I5: FY28E | J5: FY29E | K5: FY30E
A6: Estado consolidado de ganancia o pérdida
A7: Ingresos por intereses | B7: =EEFF!B7 -> 436095180 | C7: =EEFF!C7 -> 419112916 | D7: =EEFF!D7 -> 454333887 | E7: =EEFF!E7 -> 503666534 | F7: =EEFF!F7 -> 523500468 | G7: =F7*(1+Supuestos!G11) -> 5.4412639e+08 | H7: =G7*(1+Supuestos!H11) -> 5.6556497e+08 | I7: =H7*(1+Supuestos!I11) -> 5.8784823e+08 | J7: =I7*(1+Supuestos!J11) -> 6.1100945e+08 | K7: =J7*(1+Supuestos!K11) -> 6.3508322e+08
A8: Gasto por intereses | B8: =EEFF!B8 -> -263333029 | C8: =EEFF!C8 -> -238053406 | D8: =EEFF!D8 -> -281836291 | E8: =EEFF!E8 -> -350182264 | F8: =EEFF!F8 -> -366248027 | G8: =G7*Supuestos!G19 -> -3.8067082e+08 | H8: =H7*Supuestos!H19 -> -3.9566925e+08 | I8: =I7*Supuestos!I19 -> -4.1125862e+08 | J8: =J7*Supuestos!J19 -> -4.2746221e+08 | K8: =K7*Supuestos!K19 -> -4.4430422e+08
A9: Ingresos neto por intereses | B9: =EEFF!B9 -> 172762151 | C9: =EEFF!C9 -> 181059510 | D9: =EEFF!D9 -> 172497596 | E9: =EEFF!E9 -> 153484270 | F9: =EEFF!F9 -> 157252441 | G9: =G7+G8 -> 1.6345557e+08 | H9: =H7+H8 -> 1.6989572e+08 | I9: =I7+I8 -> 1.7658961e+08 | J9: =J7+J8 -> 1.8354724e+08 | K9: =K7+K8 -> 1.90779e+08
A10: Comisiones ganadas | B10: =EEFF!B10 -> 48561754 | C10: =EEFF!C10 -> 57798314 | D10: =EEFF!D10 -> 66344055 | E10: =EEFF!E10 -> 69992300 | F10: =EEFF!F10 -> 70656110 | G10: =F10*(1+Supuestos!G50) -> 71327343 | H10: =G10*(1+Supuestos!H50) -> 72004953 | I10: =H10*(1+Supuestos!I50) -> 72689000 | J10: =I10*(1+Supuestos!J50) -> 73379545 | K10: =J10*(1+Supuestos!K50) -> 74076651
A11: Gastos por comisiones | B11: =EEFF!B11 -> -13491941 | C11: =EEFF!C11 -> -19374865 | D11: =EEFF!D11 -> -22088949 | E11: =EEFF!E11 -> -24919428 | F11: =EEFF!F11 -> -26262774 | G11: =F11 -> -26262774 | H11: =G11 -> -26262774 | I11: =H11 -> -26262774 | J11: =I11 -> -26262774 | K11: =J11 -> -26262774
A12: Ingresos neto por comisiones | B12: =EEFF!B12 -> 35069813 | C12: =EEFF!C12 -> 38423449 | D12: =EEFF!D12 -> 44255106 | E12: =EEFF!E12 -> 45072872 | F12: =EEFF!F12 -> 44393336 | G12: =G10+G11 -> 45064569 | H12: =H10+H11 -> 45742179 | I12: =I10+I11 -> 46426226 | J12: =J10+J11 -> 47116771 | K12: =K10+K11 -> 47813877
A13: Ingresos neto por intereses y comisiones, antes de provisión | B13: =EEFF!B13 -> 207831964 | C13: =EEFF!C13 -> 219482959 | D13: =EEFF!D13 -> 216752702 | E13: =EEFF!E13 -> 198557142 | F13: =EEFF!F13 -> 201645777 | G13: =G9+G12 -> 2.0852014e+08 | H13: =H9+H12 -> 2.1563789e+08 | I13: =I9+I12 -> 2.2301583e+08 | J13: =J9+J12 -> 2.3066401e+08 | K13: =K9+K12 -> 2.3859288e+08
A14: Provisión para préstamos incobrables | B14: =EEFF!B14 -> 83497811 | C14: =EEFF!C14 -> 59032479 | D14: =EEFF!D14 -> 48957742 | E14: =EEFF!E14 -> 34695854 | F14: =EEFF!F14 -> 28431911 | G14: =Supuestos!G44*F40 -> 27636946 | H14: =Supuestos!H44*G40 -> 27794477 | I14: =Supuestos!I44*H40 -> 27952905 | J14: =Supuestos!J44*I40 -> 28112237 | K14: =Supuestos!K44*J40 -> 28272477
A15: Reversión de provisión riesgo país | B15: =EEFF!B15 -> 1206330 | C15: =EEFF!C15 -> -905789 | D15: =EEFF!D15 -> 363938 | E15: =EEFF!E15 -> -326333 | F15: =EEFF!F15 -> -613051 | G15: =F15 -> -613051 | H15: =G15 -> -613051 | I15: =H15 -> -613051 | J15: =I15 -> -613051 | K15: =J15 -> -613051
A16: Reversión de provisión para inversiones | B16: =EEFF!B16 -> 500143 | C16: =EEFF!C16 -> 2897059 | D16: =EEFF!D16 -> 474038 | E16: =EEFF!E16 -> -60659 | F16: =EEFF!F16 -> -198747 | G16: =F16 -> -198747 | H16: =G16 -> -198747 | I16: =H16 -> -198747 | J16: =I16 -> -198747 | K16: =J16 -> -198747
A17: Total de provisiones | B17: =EEFF!B17 -> 85204284 | C17: =EEFF!C17 -> 61023749 | D17: =EEFF!D17 -> 49795718 | E17: =EEFF!E17 -> 34308862 | F17: =EEFF!F17 -> 27620113 | G17: =G14+G15+G16 -> 26825148 | H17: =H14+H15+H16 -> 26982679 | I17: =I14+I15+I16 -> 27141107 | J17: =J14+J15+J16 -> 27300439 | K17: =K14+K15+K16 -> 27460679
A18: Ingresos neto por intereses y comisiones, después de provisión | B18: =EEFF!B18 -> 122627680 | C18: =EEFF!C18 -> 158459210 | D18: =EEFF!D18 -> 166956984 | E18: =EEFF!E18 -> 164248280 | F18: =EEFF!F18 -> 174025664 | G18: =G13-G17 -> 1.8169499e+08 | H18: =H13-H17 -> 1.8865522e+08 | I18: =I13-I17 -> 1.9587473e+08 | J18: =J13-J17 -> 2.0336357e+08 | K18: =K13-K17 -> 2.111322e+08
A19: Otros ingresos | B19: =EEFF!B19 -> 22758298 | C19: =EEFF!C19 -> 13838072 | D19: =EEFF!D19 -> 22011709 | E19: =EEFF!E19 -> 30401234 | F19: =EEFF!F19 -> 21055991 | G19: =F19*(1+Supuestos!G58) -> 21055991 | H19: =G19*(1+Supuestos!H58) -> 21055991 | I19: =H19*(1+Supuestos!I58) -> 21055991 | J19: =I19*(1+Supuestos!J58) -> 21055991 | K19: =J19*(1+Supuestos!K58) -> 21055991
A20: Salarios y otras remuneraciones | B20: =EEFF!B20 -> 57113674 | C20: =EEFF!C20 -> 59798894 | D20: =EEFF!D20 -> 61331282 | E20: =EEFF!E20 -> 63916541 | F20: =EEFF!F20 -> 61774195 | G20: =F20*(1+Supuestos!G66) -> 61508566 | H20: =G20*(1+Supuestos!H66) -> 61244079 | I20: =H20*(1+Supuestos!I66) -> 60980730 | J20: =I20*(1+Supuestos!J66) -> 60718512 | K20: =J20*(1+Supuestos!K66) -> 60457423
A21: Honorarios profesionales | B21: =EEFF!B21 -> 7726797 | C21: =EEFF!C21 -> 9285792 | D21: =EEFF!D21 -> 10360389 | E21: =EEFF!E21 -> 10744135 | F21: =EEFF!F21 -> 10044980 | G21: =F21*(1+Supuestos!G66) -> 10001787 | H21: =G21*(1+Supuestos!H66) -> 9958778.9 | I21: =H21*(1+Supuestos!I66) -> 9915956.2 | J21: =I21*(1+Supuestos!J66) -> 9873317.5 | K21: =J21*(1+Supuestos!K66) -> 9830862.3
A22: Depreciación y amortización | B22: =EEFF!B22 -> 21305412 | C22: =EEFF!C22 -> 20767901 | D22: =EEFF!D22 -> 18258300 | E22: =EEFF!E22 -> 17607972 | F22: =EEFF!F22 -> 17639914 | G22: =F22*(1+Supuestos!G66) -> 17564062 | H22: =G22*(1+Supuestos!H66) -> 17488537 | I22: =H22*(1+Supuestos!I66) -> 17413336 | J22: =I22*(1+Supuestos!J66) -> 17338459 | K22: =J22*(1+Supuestos!K66) -> 17263903
A23: Publicidad y propaganda | B23: =EEFF!B23 -> 2263252 | C23: =EEFF!C23 -> 2575329 | D23: =EEFF!D23 -> 3117156 | E23: =EEFF!E23 -> 3474398 | F23: =EEFF!F23 -> 3701527 | G23: =F23*(1+Supuestos!G66) -> 3685610.4 | H23: =G23*(1+Supuestos!H66) -> 3669762.3 | I23: =H23*(1+Supuestos!I66) -> 3653982.3 | J23: =I23*(1+Supuestos!J66) -> 3638270.2 | K23: =J23*(1+Supuestos!K66) -> 3622625.6
A24: Mantenimiento y reparaciones | B24: =EEFF!B24 -> 9755794 | C24: =EEFF!C24 -> 10603499 | D24: =EEFF!D24 -> 11309827 | E24: =EEFF!E24 -> 11390367 | F24: =EEFF!F24 -> 11351516 | G24: =F24*(1+Supuestos!G66) -> 11302704 | H24: =G24*(1+Supuestos!H66) -> 11254103 | I24: =H24*(1+Supuestos!I66) -> 11205710 | J24: =I24*(1+Supuestos!J66) -> 11157526 | K24: =J24*(1+Supuestos!K66) -> 11109548
A25: Alquileres | B25: =EEFF!B25 -> 2537829 | C25: =EEFF!C25 -> 3306085 | D25: =EEFF!D25 -> 4015359 | E25: =EEFF!E25 -> 5569274 | F25: =EEFF!F25 -> 6446523 | G25: =F25*(1+Supuestos!G66) -> 6418803 | H25: =G25*(1+Supuestos!H66) -> 6391202.1 | I25: =H25*(1+Supuestos!I66) -> 6363719.9 | J25: =I25*(1+Supuestos!J66) -> 6336355.9 | K25: =J25*(1+Supuestos!K66) -> 6309109.6
A26: Impuestos varios | B26: =EEFF!B26 -> 5568403 | C26: =EEFF!C26 -> 6408887 | D26: =EEFF!D26 -> 6222827 | E26: =EEFF!E26 -> 6603103 | F26: =EEFF!F26 -> 8078593 | G26: =F26*(1+Supuestos!G66) -> 8043855.1 | H26: =G26*(1+Supuestos!H66) -> 8009266.5 | I26: =H26*(1+Supuestos!I66) -> 7974826.6 | J26: =I26*(1+Supuestos!J66) -> 7940534.9 | K26: =J26*(1+Supuestos!K66) -> 7906390.6
A27: Otros gastos | B27: =EEFF!B27 -> 21374260 | C27: =EEFF!C27 -> 23868631 | D27: =EEFF!D27 -> 23382723 | E27: =EEFF!E27 -> 26343807 | F27: =EEFF!F27 -> 25980207 | G27: =F27*(1+Supuestos!G66) -> 25868492 | H27: =G27*(1+Supuestos!H66) -> 25757258 | I27: =H27*(1+Supuestos!I66) -> 25646501 | J27: =I27*(1+Supuestos!J66) -> 25536221 | K27: =J27*(1+Supuestos!K66) -> 25426416
A28: Total de otros gastos | B28: =EEFF!B28 -> 127645421 | C28: =EEFF!C28 -> 136615018 | D28: =EEFF!D28 -> 137997863 | E28: =EEFF!E28 -> 145649597 | F28: =EEFF!F28 -> 145017455 | G28: =G20+G21+G22+G23+G24+G25+G26+G27 -> 1.4439388e+08 | H28: =H20+H21+H22+H23+H24+H25+H26+H27 -> 1.4377299e+08 | I28: =I20+I21+I22+I23+I24+I25+I26+I27 -> 1.4315476e+08 | J28: =J20+J21+J22+J23+J24+J25+J26+J27 -> 1.425392e+08 | K28: =K20+K21+K22+K23+K24+K25+K26+K27 -> 1.4192628e+08
A29: Ganancia antes del impuesto sobre la renta | B29: =EEFF!B29 -> 17740557 | C29: =EEFF!C29 -> 35682264 | D29: =EEFF!D29 -> 50970830 | E29: =EEFF!E29 -> 48999917 | F29: =EEFF!F29 -> 50064200 | G29: =G18+G19-G28 -> 58357098 | H29: =H18+H19-H28 -> 65938221 | I29: =I18+I19-I28 -> 73775954 | J29: =J18+J19-J28 -> 81880364 | K29: =K18+K19-K28 -> 90261910
A30: Impuesto sobre la renta - Corriente | B30: =EEFF!B30 -> 3895556 | C30: =EEFF!C30 -> 3667996 | D30: =EEFF!D30 -> 3825471 | E30: =EEFF!E30 -> 4298464 | F30: =EEFF!F30 -> 4236515 | G30: =F30 -> 4236515 | H30: =G30 -> 4236515 | I30: =H30 -> 4236515 | J30: =I30 -> 4236515 | K30: =J30 -> 4236515
A31: Impuesto sobre la renta - Diferido | B31: =EEFF!B31 -> -12748149 | C31: =EEFF!C31 -> -5249226 | D31: =EEFF!D31 -> -360567 | E31: =EEFF!E31 -> -3131334 | F31: =EEFF!F31 -> -2434771 | G31: =F31 -> -2434771 | H31: =G31 -> -2434771 | I31: =H31 -> -2434771 | J31: =I31 -> -2434771 | K31: =J31 -> -2434771
A32: Impuesto sobre la renta | B32: =EEFF!B32 -> -8852593 | C32: =EEFF!C32 -> -1581230 | D32: =EEFF!D32 -> 3464904 | E32: =EEFF!E32 -> 1167130 | F32: =EEFF!F32 -> 1801744 | G32: =G30+G31 -> 1801744 | H32: =H30+H31 -> 1801744 | I32: =I30+I31 -> 1801744 | J32: =J30+J31 -> 1801744 | K32: =K30+K31 -> 1801744
A33: Ganancia del año | B33: =EEFF!B33 -> 26593150 | C33: =EEFF!C33 -> 37263494 | D33: =EEFF!D33 -> 47505926 | E33: =EEFF!E33 -> 47832787 | F33: =EEFF!F33 -> 48262456 | G33: =G29-G32 -> 56555354 | H33: =H29-H32 -> 64136477 | I33: =I29-I32 -> 71974210 | J33: =J29-J32 -> 80078620 | K33: =K29-K32 -> 88460166
A35: Años | B35: FY21A | C35: FY22A | D35: FY23A | E35: FY24A | F35: FY25A | G35: FY26E | H35: FY27E | I35: FY28E | J35: FY29E | K35: FY30E
A36: Estado consolidado de situación financiera
A37: Efectivo y depósitos en banco | B37: =EEFF!B37 -> 508316487 | C37: =EEFF!C37 -> 422163231 | D37: =EEFF!D37 -> 354965856 | E37: =EEFF!E37 -> 378198724 | F37: =EEFF!F37 -> 433699566 | G37: =F37 -> 433699566 | H37: =G37 -> 433699566 | I37: =H37 -> 433699566 | J37: =I37 -> 433699566 | K37: =J37 -> 433699566
A38: Valores comprados bajo acuerdos de reventa | B38: =EEFF!B38 -> 306301 | C38: =EEFF!C38 -> 285200 | D38: =EEFF!D38 -> 3547807 | E38: =EEFF!E38 -> 4956931 | F38: =EEFF!F38 -> 4997637 | G38: =F38 -> 4997637 | H38: =G38 -> 4997637 | I38: =H38 -> 4997637 | J38: =I38 -> 4997637 | K38: =J38 -> 4997637
A39: Inversiones en valores, neto | B39: =EEFF!B39 -> 1110163904 | C39: =EEFF!C39 -> 1079204941 | D39: =EEFF!D39 -> 1053410069 | E39: =EEFF!E39 -> 1049326162 | F39: =EEFF!F39 -> 1136648533 | G39: =F39+MAX(0,G127) -> 1.2270272e+09 | H39: =G39+MAX(0,H127) -> 1.3382799e+09 | I39: =H39+MAX(0,I127) -> 1.4529933e+09 | J39: =I39+MAX(0,J127) -> 1.571258e+09 | K39: =J39+MAX(0,K127) -> 1.6931665e+09
A40: Préstamos, neto | B40: =EEFF!B40 -> 6007976619 | C40: =EEFF!C40 -> 6138222161 | D40: =EEFF!D40 -> 6212554475 | E40: =EEFF!E40 -> 6315709567 | F40: =EEFF!F40 -> 6141543608 | G40: =F40*(1+Supuestos!G28) -> 6.1765504e+09 | H40: =G40*(1+Supuestos!H28) -> 6.2117567e+09 | I40: =H40*(1+Supuestos!I28) -> 6.2471638e+09 | J40: =I40*(1+Supuestos!J28) -> 6.2827726e+09 | K40: =J40*(1+Supuestos!K28) -> 6.3185844e+09
A41: Propiedades, mobiliario, equipo y mejoras | B41: =EEFF!B41 -> 195030353 | C41: =EEFF!C41 -> 197759650 | D41: =EEFF!D41 -> 190418187 | E41: =EEFF!E41 -> 191401031 | F41: =EEFF!F41 -> 192001647 | G41: =F41 -> 192001647 | H41: =G41 -> 192001647 | I41: =H41 -> 192001647 | J41: =I41 -> 192001647 | K41: =J41 -> 192001647
A42: Activos por derechos de uso | B42: =EEFF!B42 -> 19425507 | C42: =EEFF!C42 -> 15584822 | D42: =EEFF!D42 -> 13301035 | E42: =EEFF!E42 -> 11291589 | F42: =EEFF!F42 -> 9660940 | G42: =F42 -> 9660940 | H42: =G42 -> 9660940 | I42: =H42 -> 9660940 | J42: =I42 -> 9660940 | K42: =J42 -> 9660940
...

Sheet Loan_Book
A1: Global Bank Corporation y Subsidiarias
A2: Loan_Book — cartera bruta por producto (driver del activo, R5)
A3: Histórico verbatim Nota 10 del INA_GLOBAN_2025_0.pdf; forecast = crecimiento de cartera de Supuestos (mix constante).
A5: Años | B5: FY24A | C5: FY25A | D5: FY26E | E5: FY27E | F5: FY28E | G5: FY29E | H5: FY30E
A7: A. CARTERA BRUTA POR PRODUCTO
A8: Sector interno - Consumo | B8: 1164047707 | C8: 1218732493 | D8: =C8*(1+Supuestos!G28) -> 1.2256793e+09 | E8: =D8*(1+Supuestos!H28) -> 1.2326656e+09 | F8: =E8*(1+Supuestos!I28) -> 1.2396918e+09 | G8: =F8*(1+Supuestos!J28) -> 1.2467581e+09 | H8: =G8*(1+Supuestos!K28) -> 1.2538646e+09
A9: Sector interno - Comerciales | B9: 1187948076 | C9: 1164209384 | D9: =C9*(1+Supuestos!G28) -> 1.1708454e+09 | E9: =D9*(1+Supuestos!H28) -> 1.1775192e+09 | F9: =E9*(1+Supuestos!I28) -> 1.1842311e+09 | G9: =F9*(1+Supuestos!J28) -> 1.1909812e+09 | H9: =G9*(1+Supuestos!K28) -> 1.1977698e+09
A10: Sector interno - Agropecuario | B10: 339486359 | C10: 309346401 | D10: =C10*(1+Supuestos!G28) -> 3.1110968e+08 | E10: =D10*(1+Supuestos!H28) -> 3.12883e+08 | F10: =E10*(1+Supuestos!I28) -> 3.1466643e+08 | G10: =F10*(1+Supuestos!J28) -> 3.1646003e+08 | H10: =G10*(1+Supuestos!K28) -> 3.1826385e+08
A11: Sector interno - Prendarios | B11: 148156201 | C11: 144449704 | D11: =C11*(1+Supuestos!G28) -> 1.4527307e+08 | E11: =D11*(1+Supuestos!H28) -> 1.4610112e+08 | F11: =E11*(1+Supuestos!I28) -> 1.469339e+08 | G11: =F11*(1+Supuestos!J28) -> 1.4777142e+08 | H11: =G11*(1+Supuestos!K28) -> 1.4861372e+08
A12: Sector interno - Sobregiros | B12: 118731610 | C12: 105641732 | D12: =C12*(1+Supuestos!G28) -> 1.0624389e+08 | E12: =D12*(1+Supuestos!H28) -> 1.0684948e+08 | F12: =E12*(1+Supuestos!I28) -> 1.0745852e+08 | G12: =F12*(1+Supuestos!J28) -> 1.0807104e+08 | H12: =G12*(1+Supuestos!K28) -> 1.0868704e+08
A13: Sector interno - Hipotecarios | B13: 1918375745 | C13: 1840267760 | D13: =C13*(1+Supuestos!G28) -> 1.8507573e+09 | E13: =D13*(1+Supuestos!H28) -> 1.8613066e+09 | F13: =E13*(1+Supuestos!I28) -> 1.8719161e+09 | G13: =F13*(1+Supuestos!J28) -> 1.882586e+09 | H13: =G13*(1+Supuestos!K28) -> 1.8933167e+09
A14: Sector interno - Industriales | B14: 305881168 | C14: 317318291 | D14: =C14*(1+Supuestos!G28) -> 3.1912701e+08 | E14: =D14*(1+Supuestos!H28) -> 3.2094603e+08 | F14: =E14*(1+Supuestos!I28) -> 3.2277542e+08 | G14: =F14*(1+Supuestos!J28) -> 3.2461524e+08 | H14: =G14*(1+Supuestos!K28) -> 3.2646555e+08
A15: Sector interno - Construcción | B15: 401298736 | C15: 391932776 | D15: =C15*(1+Supuestos!G28) -> 3.9416679e+08 | E15: =D15*(1+Supuestos!H28) -> 3.9641354e+08 | F15: =E15*(1+Supuestos!I28) -> 3.986731e+08 | G15: =F15*(1+Supuestos!J28) -> 4.0094554e+08 | H15: =G15*(1+Supuestos!K28) -> 4.0323093e+08
A16: Sector interno - Arrendamientos financieros | B16: 47163874 | C16: 37539795 | D16: =C16*(1+Supuestos!G28) -> 37753772 | E16: =D16*(1+Supuestos!H28) -> 37968968 | F16: =E16*(1+Supuestos!I28) -> 38185391 | G16: =F16*(1+Supuestos!J28) -> 38403048 | H16: =G16*(1+Supuestos!K28) -> 38621946
A17: Sector interno - Facturas descontadas | B17: 304285310 | C17: 183852054 | D17: =C17*(1+Supuestos!G28) -> 1.8490001e+08 | E17: =D17*(1+Supuestos!H28) -> 1.8595394e+08 | F17: =E17*(1+Supuestos!I28) -> 1.8701388e+08 | G17: =F17*(1+Supuestos!J28) -> 1.8807986e+08 | H17: =G17*(1+Supuestos!K28) -> 1.8915191e+08
A18: Sector externo - Comerciales | B18: 282077170 | C18: 335111161 | D18: =C18*(1+Supuestos!G28) -> 3.3702129e+08 | E18: =D18*(1+Supuestos!H28) -> 3.3894232e+08 | F18: =E18*(1+Supuestos!I28) -> 3.4087429e+08 | G18: =F18*(1+Supuestos!J28) -> 3.4281727e+08 | H18: =G18*(1+Supuestos!K28) -> 3.4477133e+08
A19: Sector externo - Agropecuarios | B19: 0 | C19: 9076680 | D19: =C19*(1+Supuestos!G28) -> 9128417.1 | E19: =D19*(1+Supuestos!H28) -> 9180449.1 | F19: =E19*(1+Supuestos!I28) -> 9232777.6 | G19: =F19*(1+Supuestos!J28) -> 9285404.4 | H19: =G19*(1+Supuestos!K28) -> 9338331.3
A20: Sector externo - Industriales | B20: 151560596 | C20: 106246377 | D20: =C20*(1+Supuestos!G28) -> 1.0685198e+08 | E20: =D20*(1+Supuestos!H28) -> 1.0746104e+08 | F20: =E20*(1+Supuestos!I28) -> 1.0807357e+08 | G20: =F20*(1+Supuestos!J28) -> 1.0868958e+08 | H20: =G20*(1+Supuestos!K28) -> 1.0930912e+08
A21: Sector externo - Construcción | B21: 1876711 | C21: 1548623 | D21: =C21*(1+Supuestos!G28) -> 1557450.2 | E21: =D21*(1+Supuestos!H28) -> 1566327.6 | F21: =E21*(1+Supuestos!I28) -> 1575255.7 | G21: =F21*(1+Supuestos!J28) -> 1584234.6 | H21: =G21*(1+Supuestos!K28) -> 1593264.8
A22: Sector externo - Prendarios | B22: 9470022 | C22: 29470022 | D22: =C22*(1+Supuestos!G28) -> 29638001 | E22: =D22*(1+Supuestos!H28) -> 29806938 | F22: =E22*(1+Supuestos!I28) -> 29976837 | G22: =F22*(1+Supuestos!J28) -> 30147705 | H22: =G22*(1+Supuestos!K28) -> 30319547
A23: Sector externo - Sobregiro | B23: 19275275 | C23: 21297833 | D23: =C23*(1+Supuestos!G28) -> 21419231 | E23: =D23*(1+Supuestos!H28) -> 21541320 | F23: =E23*(1+Supuestos!I28) -> 21664106 | G23: =F23*(1+Supuestos!J28) -> 21787591 | H23: =G23*(1+Supuestos!K28) -> 21911780
A24: Total cartera bruta | B24: =B8+B9+B10+B11+B12+B13+B14+B15+B16+B17+B18+B19+B20+B21+B22+B23 -> 6399634560 | C24: =C8+C9+C10+C11+C12+C13+C14+C15+C16+C17+C18+C19+C20+C21+C22+C23 -> 6216041086 | D24: =D8+D9+D10+D11+D12+D13+D14+D15+D16+D17+D18+D19+D20+D21+D22+D23 -> 6.2514725e+09 | E24: =E8+E9+E10+E11+E12+E13+E14+E15+E16+E17+E18+E19+E20+E21+E22+E23 -> 6.2871059e+09 | F24: =F8+F9+F10+F11+F12+F13+F14+F15+F16+F17+F18+F19+F20+F21+F22+F23 -> 6.3229424e+09 | G24: =G8+G9+G10+G11+G12+G13+G14+G15+G16+G17+G18+G19+G20+G21+G22+G23 -> 6.3589832e+09 | H24: =H8+H9+H10+H11+H12+H13+H14+H15+H16+H17+H18+H19+H20+H21+H22+H23 -> 6.3952294e+09
A26: B. TIE-OUT CONTRA MODELOFINANCIERO (check 13)
A27: Cartera bruta según ModeloFinanciero (BS) | B27: =ModeloFinanciero!E40 -> 6315709567 | C27: =ModeloFinanciero!F40 -> 6141543608 | D27: =ModeloFinanciero!G40 -> 6.1765504e+09 | E27: =ModeloFinanciero!H40 -> 6.2117567e+09 | F27: =ModeloFinanciero!I40 -> 6.2471638e+09 | G27: =ModeloFinanciero!J40 -> 6.2827726e+09 | H27: =ModeloFinanciero!K40 -> 6.3185844e+09
A28: CHECK Δ Loan_Book − Modelo (=0 OK) | B28: =B24-B27 -> 83924993 | C28: =C24-C27 -> 74497478 | D28: =D24-D27 -> 74922114 | E28: =E24-E27 -> 75349170 | F28: =F24-F27 -> 75778660 | G28: =G24-G27 -> 76210598 | H28: =H24-H27 -> 76644999
A30: DRIVER_DETAIL_PENDING: yields/crecimiento por producto no divulgados — todos los productos crecen al driver agregado (mix constante).

Sheet Deposits_Funding
A1: Global Bank Corporation y Subsidiarias
A2: Deposits_Funding — depósitos por tipo + financiamientos (el pasivo del spread, R5)
A3: Histórico verbatim Nota 14; forecast = crecimiento de depósitos de Supuestos. Financiamientos = referencias al ModeloFinanciero (el balanceador vive allá, R2).
A5: Años | B5: FY24A | C5: FY25A | D5: FY26E | E5: FY27E | F5: FY28E | G5: FY29E | H5: FY30E
A7: A. DEPÓSITOS POR TIPO (base de la nota)
A8: A la vista | B8: 467235160 | C8: 518103988 | D8: =C8*(1+Supuestos!G36) -> 5.3105659e+08 | E8: =D8*(1+Supuestos!H36) -> 5.44333e+08 | F8: =E8*(1+Supuestos!I36) -> 5.5794133e+08 | G8: =F8*(1+Supuestos!J36) -> 5.7188986e+08 | H8: =G8*(1+Supuestos!K36) -> 5.8618711e+08
A9: Ahorros | B9: 1081312202 | C9: 1147463446 | D9: =C9*(1+Supuestos!G36) -> 1.17615e+09 | E9: =D9*(1+Supuestos!H36) -> 1.2055538e+09 | F9: =E9*(1+Supuestos!I36) -> 1.2356926e+09 | G9: =F9*(1+Supuestos!J36) -> 1.2665849e+09 | H9: =G9*(1+Supuestos!K36) -> 1.2982496e+09
A10: Plazo fijo | B10: 3716086904 | C10: 4049905426 | D10: =C10*(1+Supuestos!G36) -> 4.1511531e+09 | E10: =D10*(1+Supuestos!H36) -> 4.2549319e+09 | F10: =E10*(1+Supuestos!I36) -> 4.3613052e+09 | G10: =F10*(1+Supuestos!J36) -> 4.4703378e+09 | H10: =G10*(1+Supuestos!K36) -> 4.5820963e+09
A11: Total depósitos (base nota) | B11: =B8+B9+B10 -> 5264634266 | C11: =C8+C9+C10 -> 5715472860 | D11: =D8+D9+D10 -> 5.8583597e+09 | E11: =E8+E9+E10 -> 6.0048187e+09 | F11: =F8+F9+F10 -> 6.1549391e+09 | G11: =G8+G9+G10 -> 6.3088126e+09 | H11: =H8+H9+H10 -> 6.4665329e+09
A13: B. CONCILIACIÓN CONTRA MODELOFINANCIERO (check 14)
A14: Total de depósitos según ModeloFinanciero (BS) | B14: =ModeloFinanciero!E48 -> 5381647327 | C14: =ModeloFinanciero!F48 -> 5772809411 | D14: =ModeloFinanciero!G48 -> 5.8981949e+09 | E14: =ModeloFinanciero!H48 -> 6.0446539e+09 | F14: =ModeloFinanciero!I48 -> 6.1947744e+09 | G14: =ModeloFinanciero!J48 -> 6.3486478e+09 | H14: =ModeloFinanciero!K48 -> 6.5063682e+09
A15: Δ conciliación (interbancarios + intereses acumulados, según filing) | B15: =B14-B11 -> 117013061 | C15: =C14-C11 -> 57336551 | D15: =D14-D11 -> 39835224 | E15: =E14-E11 -> 39835224 | F15: =F14-F11 -> 39835224 | G15: =G14-G11 -> 39835224 | H15: =H14-H11 -> 39835224
A17: C. FINANCIAMIENTOS Y COSTO (referencias)
A18: Total de financiamientos (ModeloFinanciero) | B18: =ModeloFinanciero!E56 -> 2270922588 | C18: =ModeloFinanciero!F56 -> 1844742611 | D18: =ModeloFinanciero!G56 -> 1844742611 | E18: =ModeloFinanciero!H56 -> 1844742611 | F18: =ModeloFinanciero!I56 -> 1844742611 | G18: =ModeloFinanciero!J56 -> 1844742611 | H18: =ModeloFinanciero!K56 -> 1844742611
A19: Costo de depósitos — driver activo (Supuestos) | D19: =Supuestos!G19 -> -0.6996 | E19: =Supuestos!H19 -> -0.6996 | F19: =Supuestos!I19 -> -0.6996 | G19: =Supuestos!J19 -> -0.6996 | H19: =Supuestos!K19 -> -0.6996
A20: Costo de financiamientos — driver activo (Supuestos) | D20: =Supuestos!G19 -> -0.6996 | E20: =Supuestos!H19 -> -0.6996 | F20: =Supuestos!I19 -> -0.6996 | G20: =Supuestos!J19 -> -0.6996 | H20: =Supuestos!K19 -> -0.6996

Sheet NIM_Build
A1: Global Bank Corporation y Subsidiarias
A2: NIM_Build — spread y margen de intermediación (R5, bases BOP R4)
A3: Rendimiento y costo desde Supuestos; saldos y NII desde ModeloFinanciero (verde). El IS del modelo ya calcula con estas mismas bases.
A5: Años | B5: FY24A | C5: FY25A | D5: FY26E | E5: FY27E | F5: FY28E | G5: FY29E | H5: FY30E
A7: A. ACTIVO PRODUCTIVO Y RENDIMIENTO
A8: Cartera bruta (BS ModeloFinanciero) | B8: =ModeloFinanciero!E40 -> 6315709567 | C8: =ModeloFinanciero!F40 -> 6141543608 | D8: =ModeloFinanciero!G40 -> 6.1765504e+09 | E8: =ModeloFinanciero!H40 -> 6.2117567e+09 | F8: =ModeloFinanciero!I40 -> 6.2471638e+09 | G8: =ModeloFinanciero!J40 -> 6.2827726e+09 | H8: =ModeloFinanciero!K40 -> 6.3185844e+09
A9: Rendimiento de cartera — driver activo (Supuestos) | D9: =Supuestos!G11 -> 0.0394 | E9: =Supuestos!H11 -> 0.0394 | F9: =Supuestos!I11 -> 0.0394 | G9: =Supuestos!J11 -> 0.0394 | H9: =Supuestos!K11 -> 0.0394
A10: Ingreso por intereses de préstamos (IS ModeloFinanciero) | B10: =ModeloFinanciero!E7 -> 503666534 | C10: =ModeloFinanciero!F7 -> 523500468 | D10: =ModeloFinanciero!G7 -> 5.4412639e+08 | E10: =ModeloFinanciero!H7 -> 5.6556497e+08 | F10: =ModeloFinanciero!I7 -> 5.8784823e+08 | G10: =ModeloFinanciero!J7 -> 6.1100945e+08 | H10: =ModeloFinanciero!K7 -> 6.3508322e+08
A12: B. FONDEO Y COSTO
A13: Total de depósitos (BS ModeloFinanciero) | B13: =ModeloFinanciero!E48 -> 5381647327 | C13: =ModeloFinanciero!F48 -> 5772809411 | D13: =ModeloFinanciero!G48 -> 5.8981949e+09 | E13: =ModeloFinanciero!H48 -> 6.0446539e+09 | F13: =ModeloFinanciero!I48 -> 6.1947744e+09 | G13: =ModeloFinanciero!J48 -> 6.3486478e+09 | H13: =ModeloFinanciero!K48 -> 6.5063682e+09
A14: Total de gastos por intereses (IS ModeloFinanciero) | B14: =ModeloFinanciero!E8 -> -350182264 | C14: =ModeloFinanciero!F8 -> -366248027 | D14: =ModeloFinanciero!G8 -> -3.8067082e+08 | E14: =ModeloFinanciero!H8 -> -3.9566925e+08 | F14: =ModeloFinanciero!I8 -> -4.1125862e+08 | G14: =ModeloFinanciero!J8 -> -4.2746221e+08 | H14: =ModeloFinanciero!K8 -> -4.4430422e+08
A16: C. MARGEN (check 15)
A17: Total ingresos por intereses y comisiones (IS) | B17: =ModeloFinanciero!E7 -> 503666534 | C17: =ModeloFinanciero!F7 -> 523500468 | D17: =ModeloFinanciero!G7 -> 5.4412639e+08 | E17: =ModeloFinanciero!H7 -> 5.6556497e+08 | F17: =ModeloFinanciero!I7 -> 5.8784823e+08 | G17: =ModeloFinanciero!J7 -> 6.1100945e+08 | H17: =ModeloFinanciero!K7 -> 6.3508322e+08
A18: NII calculado (ingresos − gastos) | B18: =B17-B14 -> 853848798 | C18: =C17-C14 -> 889748495 | D18: =D17-D14 -> 9.2479721e+08 | E18: =E17-E14 -> 9.6123422e+08 | F18: =F17-F14 -> 9.9910684e+08 | G18: =G17-G14 -> 1.0384717e+09 | H18: =H17-H14 -> 1.0793874e+09
A19: NII según ModeloFinanciero | B19: =ModeloFinanciero!E9 -> 153484270 | C19: =ModeloFinanciero!F9 -> 157252441 | D19: =ModeloFinanciero!G9 -> 1.6345557e+08 | E19: =ModeloFinanciero!H9 -> 1.6989572e+08 | F19: =ModeloFinanciero!I9 -> 1.7658961e+08 | G19: =ModeloFinanciero!J9 -> 1.8354724e+08 | H19: =ModeloFinanciero!K9 -> 1.90779e+08
A20: CHECK Δ NII (=0 OK) | B20: =B18-B19 -> 700364528 | C20: =C18-C19 -> 732496054 | D20: =D18-D19 -> 7.6134164e+08 | E20: =E18-E19 -> 7.913385e+08 | F20: =F18-F19 -> 8.2251724e+08 | G20: =G18-G19 -> 8.5492442e+08 | H20: =H18-H19 -> 8.8860844e+08
A21: NIM sobre cartera promedio (proxy: NII ÷ ((BOP+EOP)/2)) | C21: =C18/((B8+C8)/2) -> 0.14284826 | D21: =D18/((C8+D8)/2) -> 0.15015265 | E21: =E18/((D8+E8)/2) -> 0.15518411 | F21: =F18/((E8+F8)/2) -> 0.16038418 | G21: =G18/((F8+G8)/2) -> 0.16575849 | H21: =H18/((G8+H8)/2) -> 0.17131289

Sheet Credit_Quality
A1: Global Bank Corporation y Subsidiarias
A2: Credit_Quality — ECL NIIF 9 por etapas + clasificación SBP
A3: Histórico verbatim Nota 4.2.1 / 4.2.2.1; la reserva total forecast rueda en el ModeloFinanciero (reserva += provisión, sin castigos divulgados).
A5: Años | B5: FY24A | C5: FY25A | D5: FY26E | E5: FY27E | F5: FY28E | G5: FY29E | H5: FY30E
A7: A. RESERVA ECL POR ETAPA (NIIF 9)
A8: Etapa 1 — Etapa 1 | B8: 20286686 | C8: 24717338
A9: Etapa 2 — Etapa 2 | B9: 65496659 | C9: 66747588
A10: Etapa 3 — Etapa 3 | B10: 139643182 | C10: 121855764
A11: Reserva total (Σ etapas) | B11: =B8+B9+B10 -> 225426527 | C11: =C8+C9+C10 -> 213320690
A13: NOT_PROJECTED: el mix por etapa no se proyecta (sin base divulgada); el total forecast referencia el roll-forward del BS.
A15: B. PROVISIÓN Y TASA (checks 16-17)
A16: Provisión del año (IS ModeloFinanciero) | B16: =ModeloFinanciero!E14 -> 34695854 | C16: =ModeloFinanciero!F14 -> 28431911 | D16: =ModeloFinanciero!G14 -> 27636946 | E16: =ModeloFinanciero!H14 -> 27794477 | F16: =ModeloFinanciero!I14 -> 27952905 | G16: =ModeloFinanciero!J14 -> 28112237 | H16: =ModeloFinanciero!K14 -> 28272477
A17: Tasa de provisión — driver activo (Supuestos) | D17: =Supuestos!G44 -> 0.0045 | E17: =Supuestos!H44 -> 0.0045 | F17: =Supuestos!I44 -> 0.0045 | G17: =Supuestos!J44 -> 0.0045 | H17: =Supuestos!K44 -> 0.0045
A18: Reserva según BS ModeloFinanciero
A19: CHECK Δ reserva Credit_Quality − BS (=0 OK) | B19: =B11-B18 -> 225426527 | C19: =C11-C18 -> 213320690 | D19: =D11-D18 -> 0 | E19: =E11-E18 -> 0 | F19: =F11-F18 -> 0 | G19: =G11-G18 -> 0 | H19: =H11-H18 -> 0
A21: C. CLASIFICACIÓN REGULATORIA SBP (memo)
A23: BASE_DISTINTA: cifras en la base/unidad del filing (no re-escaladas); no comparables 1:1 con la reserva consolidada — no se computa cobertura cruzada.

Sheet Capital_Adequacy
A1: Global Bank Corporation y Subsidiarias
A2: Capital_Adequacy — CET1/AT1/RWA y el candado del dividendo (R3/R6/R8)
A3: Histórico verbatim Nota 4.7 (Administración de capital) — Nota 33 (Aspectos regulatorios y reserva de capital) aporta el detalle de la reserva dinámica SBP; forecast: CET1 += utilidad retenida (Modelo × (1−payout local source-backed)); RWA ∝ cartera (proxy, flaggeado).
A5: Años | B5: FY24A | C5: FY25A | D5: FY26E | E5: FY27E | F5: FY28E | G5: FY29E | H5: FY30E
A7: A. STACK DE CAPITAL REGULATORIO
A8: CET1 — capital primario ordinario | B8: 598988872 | C8: 640607500 | D8: =C8+ModeloFinanciero!G33*(1-D23) -> 6.4459228e+08 | E8: =D8+ModeloFinanciero!H33*(1-E23) -> 6.491112e+08 | F8: =E8+ModeloFinanciero!I33*(1-F23) -> 6.5418236e+08 | G8: =F8+ModeloFinanciero!J33*(1-G23) -> 6.5982454e+08 | H8: =G8+ModeloFinanciero!K33*(1-H23) -> 6.6605727e+08
A9: AT1 — capital primario adicional (bonos perpetuos) | B9: 178016538 | C9: 177320865 | D9: =C9 -> 177320865 | E9: =D9 -> 177320865 | F9: =E9 -> 177320865 | G9: =F9 -> 177320865 | H9: =G9 -> 177320865
A10: Tier 1 (CET1 + AT1) | B10: =B8+B9 -> 777005410 | C10: =C8+C9 -> 817928365 | D10: =D8+D9 -> 8.2191314e+08 | E10: =E8+E9 -> 8.2643207e+08 | F10: =F8+F9 -> 8.3150323e+08 | G10: =G8+G9 -> 8.3714541e+08 | H10: =H8+H9 -> 8.4337813e+08
A11: Capital total (sin Tier 2 divulgado) | B11: =B10 -> 777005410 | C11: =C10 -> 817928365 | D11: =D10 -> 8.2191314e+08 | E11: =E10 -> 8.2643207e+08 | F11: =F10 -> 8.3150323e+08 | G11: =G10 -> 8.3714541e+08 | H11: =H10 -> 8.4337813e+08
A13: B. ACTIVOS PONDERADOS POR RIESGO
A14: RWA total | B14: 5659919316 | C14: 5680419094 | D14: =C14*(1+Supuestos!G28) -> 5.7127975e+09 | E14: =D14*(1+Supuestos!H28) -> 5.7453604e+09 | F14: =E14*(1+Supuestos!I28) -> 5.778109e+09 | G14: =F14*(1+Supuestos!J28) -> 5.8110442e+09 | H14: =G14*(1+Supuestos!K28) -> 5.8441672e+09
A16: RWA_PROXY_LOAN_GROWTH: RWA forecast crece al driver de cartera (mix de ponderaciones constante); componentes solo histórico.
A18: C. FORECAST DE CAPITAL (válvula R3)
A19: Fuente payout: EEFF "Estado consolidado de flujos de efectivo" / "Dividendos pagados acciones comunes" ÷ EEFF "Estado consolidado de ganancia o pérdida" / "Ganancia del año"; promedio FY21A-FY25A.
A20: Dividendos pagados (positivo para payout, ref EEFF) | B20: =ABS(EEFF!E114) -> 35336599 | C20: =ABS(EEFF!F114) -> 25134617
A21: Utilidad neta / ganancia del año (ref EEFF) | B21: =EEFF!E33 -> 47832787 | C21: =EEFF!F33 -> 48262456
A22: Payout histórico revelado (dividendos ÷ utilidad neta) | B22: =B20/B21 -> 0.73875267 | C22: =C20/C21 -> 0.52079026
A23: Payout promedio histórico revelado (92.95%; driver local W3-HF) | D23: =AVERAGE(ABS(EEFF!B114)/EEFF!B33,ABS(EEFF!C114)/EEFF!C33,ABS(EEFF!D114)/EEFF!D33,ABS(EEFF!E114)/EEFF!E33,ABS(EEFF!F114)/EEFF!F33) -> 0.92954201 | E23: =AVERAGE(ABS(EEFF!B114)/EEFF!B33,ABS(EEFF!C114)/EEFF!C33,ABS(EEFF!D114)/EEFF!D33,ABS(EEFF!E114)/EEFF!E33,ABS(EEFF!F114)/EEFF!F33) -> 0.92954201 | F23: =AVERAGE(ABS(EEFF!B114)/EEFF!B33,ABS(EEFF!C114)/EEFF!C33,ABS(EEFF!D114)/EEFF!D33,ABS(EEFF!E114)/EEFF!E33,ABS(EEFF!F114)/EEFF!F33) -> 0.92954201 | G23: =AVERAGE(ABS(EEFF!B114)/EEFF!B33,ABS(EEFF!C114)/EEFF!C33,ABS(EEFF!D114)/EEFF!D33,ABS(EEFF!E114)/EEFF!E33,ABS(EEFF!F114)/EEFF!F33) -> 0.92954201 | H23: =AVERAGE(ABS(EEFF!B114)/EEFF!B33,ABS(EEFF!C114)/EEFF!C33,ABS(EEFF!D114)/EEFF!D33,ABS(EEFF!E114)/EEFF!E33,ABS(EEFF!F114)/EEFF!F33) -> 0.92954201
A24: Índice de capital total (computado, = capital ÷ RWA) | B24: =B11/B14 -> 0.13728206 | C24: =C11/C14 -> 0.14399085 | D24: =D11/D14 -> 0.14387227 | E24: =E11/E14 -> 0.14384338 | F24: =F11/F14 -> 0.14390577 | G24: =G11/G14 -> 0.1440611 | H24: =H11/H14 -> 0.14431109
A25: Índice divulgado (Nota, R8 tie disclosed-vs-computed) | B25: 0.1373 | C25: 0.144
A26: CHECK Δ computado − divulgado (≈0, redondeo bp) | B26: =B24-B25 -> -1.7935253e-05 | C26: =C24-C25 -> -9.1515318e-06
A27: Mínimo SBP capital total (phase-in jul-2026: 10.50%) | D27: 0.105 | E27: 0.105 | F27: 0.105 | G27: 0.105 | H27: 0.105
A28: Holgura sobre el mínimo (checks 19-21) | D28: =D24-D27 -> 0.03887227 | E28: =E24-E27 -> 0.038843381 | F28: =F24-F27 -> 0.038905771 | G28: =G24-G27 -> 0.039061098 | H28: =H24-H27 -> 0.03931109

Sheet Liquidity
A1: Global Bank Corporation y Subsidiarias
A2: Liquidity — índice legal SBP e índice interno de gestión
A3: Histórico verbatim Nota 4.3 (Riesgo de liquidez o financiamiento). Dos métricas DISTINTAS: legal (Acuerdo 4-2008, mínimo 30%) vs interna de gestión — no conflar.
A5: Años | B5: FY24A | C5: FY25A | D5: FY26E | E5: FY27E | F5: FY28E | G5: FY29E | H5: FY30E
A7: A. ÍNDICE DE LIQUIDEZ LEGAL (SBP, Acuerdo 4-2008)
A8: Índice legal reportado | B8: 0.3659 | C8: 0.4233
A9: Mínimo regulatorio | B9: 0.3 | C9: 0.3
A10: Holgura sobre el mínimo (check 22) | B10: =B8-B9 -> 0.0659 | C10: =C8-C9 -> 0.1233
A12: B. ÍNDICE INTERNO DE GESTIÓN (si divulgado)
A13: NOT_DISCLOSED: sin índice interno separado en este filing.
A15: LIQUIDITY_FORECAST_PENDING: proyectar liquidez exige el detalle ALM de vencimientos (fase posterior); no se inventan ratios forward.

Sheet _CHECKS
A1: Global Bank Corporation y Subsidiarias
A2: _CHECKS panel — bank template, live formulas, known residuals signed visible
A3: Status semantics: PASS = zero undocumented hard failures; KNOWN_RESIDUAL = signed G7 residual; SOURCE_GAP = unresolved semantic anchor/schedule.
A4: MASTER_STATUS | B4: MODEL STATUS | C4: =IF(COUNTIF($C$6:$C$31,"FAIL")=0,"PASS","FAIL") -> PASS | G4: Master PASS counts only FAIL rows; KNOWN_RESIDUAL/SOURCE_GAP remain visible but non-blocking.
A5: check_id | B5: description | C5: status | D5: hardness | E5: tolerance | F5: expected | G5: note | H5: FY21A | I5: FY22A | J5: FY23A | K5: FY24A | L5: FY25A | M5: FY26E | N5: FY27E | O5: FY28E | P5: FY29E | Q5: FY30E
A7: UNIVERSAL CHECKS
