Workbook

Sheet Claude Log
A1: Turn # | B1: Date | C1: User Request | D1: Action Taken | E1: Details | F1: Outcome
A2: 1 | B2: 2026-10-27 | C2: Fill up the blank cells in the selected drivers block (Assumptions!A52:K76). | D2: Filled history (2019A-2025A) on the Active rows and the 2026E column for price per ad, other revenue, Reality Labs and DAP. | E2: History links to Revenue_Hist rows 27, 28, 30 and growth of rows 8 and 10 (2019A blank: no prior year). 2026E Base/Bull/Bear derived from Interim_Bridge and the Q4 guidance inputs (J:L rows 10, 13, 14); DAP 2026E = Sep 2026 / Dec 2025 average. Active row = CHOOSE on $B$5. Formats: 0.00%, italic, green for cross-sheet links. Neighbouring cells still show 0.0%, not touched. | F2: Assumptions!I61 equals Revenue_Build!C8 (12.65%). Rows 77+ (cash costs, legal charges) were outside the selection and not reviewed.
A3: 2 | B3: 2026-10-27 | C3: Asked to fill the rest of the drivers block (Assumptions!A52:K111). | D3: Filled history on Active rows 81, 91, 101, 111 (2019A-2025A), H96, H106 and 2026E Base/Bull/Bear + Active for cash costs, legal charges, RL operating loss and DPS growth. | E3: Cash costs = (total costs - D&A) / revenue, legal charges not stripped from history (none tagged in the workbook). Capex = -(PP&E purchases + finance-lease principal). Tax = provision / pre-tax. Buybacks = repurchases / (CFO - capex - dividends - RSU tax). 2026E: cash costs from guidance J:L rows 10-11 less legal and D&A; legal = Interim_Bridge!D13; RL = 9M + Q4 scenario; DPS = I39 vs 2025A. Tax and buybacks 2026E left blank (label says 2027E onward; 2026E set by bridge inputs). | F3: Base 2026E cash costs 53.63% (ties to note 53.6%); RL Base (18,500). Open: legal history B:H, RL history B:G, DPS 2024A growth not in workbook.

Sheet 00_Cover
A1: Meta Platforms, Inc. (Facebook, Inc. until 28 October 2021) | Financial model: statements as filed, 10-year forecast, valuation and credit
A3: What this workbook holds
A4: Every line of the five audited statements in each Form 10-K for fiscal 2019 to fiscal 2025.
A5: The statements: income, comprehensive income, balance sheet, stockholders' equity, cash flows.
A6: The nine months to 30 September 2025 and 2026 come from the Q3 Form 10-Q. These are not audited.
A7: Forecast 2026E-2035E with Base, Bull and Bear (switch: Assumptions!C5); valuation (DCF, FCFE, reverse DCF, comps, sum of the parts); credit metrics.
A8: How to read it
A9: Each period comes from the filing that first reported it. A later recast is listed on the Recasts sheet, not applied.
A10: Units: USD millions, except per-share amounts (USD) and share counts (millions).
A11: Signs follow the filing. A number in parentheses in the filing is negative here.
A12: A dash means the filing shows a dash or zero. An empty cell means the filing does not show that line for that period.
A13: If a filing changed only the wording of a line, the line keeps one row. Column O shows the earlier wording.
... A17: Source of every number: the inline XBRL of the filing on SEC EDGAR (CIK 0001326801).
A19: Master check (all checks on the Checks sheet) | D19: =Checks!C4 -> OK
A21: Filing | B21: Form | C21: Period end | D21: Filed | E21: Accession number | F21: Columns taken from it | G21: Link
A22: Form 10-K for fiscal 2019 | B22: 10-K | C22: 43830 | D22: 43860 | E22: 0001326801-20-000013 | F22: 2019A | G22: https://www.sec.gov/Archives/edgar/data/1326801/000132680120000013/fb-12312019x10k.htm
A23: Form 10-K for fiscal 2020 | B23: 10-K | C23: 44196 | D23: 44224 | E23: 0001326801-21-000014 | F23: 2020A | G23: https://www.sec.gov/Archives/edgar/data/1326801/000132680121000014/fb-20201231.htm
A24: Form 10-K for fiscal 2021 | B24: 10-K | C24: 44561 | D24: 44595 | E24: 0001326801-22-000018 | F24: 2021A | G24: https://www.sec.gov/Archives/edgar/data/1326801/000132680122000018/fb-20211231.htm
A25: Form 10-K for fiscal 2022 | B25: 10-K | C25: 44926 | D25: 44959 | E25: 0001326801-23-000013 | F25: 2022A | G25: https://www.sec.gov/Archives/edgar/data/1326801/000132680123000013/meta-20221231.htm
A26: Form 10-K for fiscal 2023 | B26: 10-K | C26: 45291 | D26: 45324 | E26: 0001326801-24-000012 | F26: 2023A | G26: https://www.sec.gov/Archives/edgar/data/1326801/000132680124000012/meta-20231231.htm
A27: Form 10-K for fiscal 2024 | B27: 10-K | C27: 45657 | D27: 45687 | E27: 0001326801-25-000017 | F27: 2024A | G27: https://www.sec.gov/Archives/edgar/data/1326801/000132680125000017/meta-20241231.htm
A28: Form 10-K for fiscal 2025 | B28: 10-K | C28: 46022 | D28: 46051 | E28: 0001628280-26-003942 | F28: 2025A | G28: https://www.sec.gov/Archives/edgar/data/1326801/000162828026003942/meta-20251231.htm
A29: Form 10-Q for the quarter ended 2025-09-30 | B29: 10-Q | C29: 45930 | D29: 45960 | E29: 0001628280-25-047240 | F29: 9M 2025A, Sep 2025A | G29: https://www.sec.gov/Archives/edgar/data/1326801/000162828025047240/meta-20250930.htm
A30: Form 10-Q for the quarter ended 2026-09-30 | B30: 10-Q | C30: 46295 | D30: 46317 | E30: 0001628280-26-066773 | F30: 9M 2026A, Sep 2026A | G30: https://www.sec.gov/Archives/edgar/data/1326801/000162828026066773/meta-20260930.htm
A32: Sheets | B32: What it shows
A33: IS_Hist | B33: Consolidated statements of income
A34: CI_Hist | B34: Consolidated statements of comprehensive income
A35: BS_Hist | B35: Consolidated balance sheets, with the parenthetical share data
A36: CF_Hist | B36: Consolidated statements of cash flows, with supplemental data
A37: SCE_Hist | B37: Consolidated statements of stockholders' equity, as a roll-forward per component
A38: Revenue_Hist | B38: Revenue by source, segment and region (audited notes), Meta's reported drivers, and ratios
A39: Assumptions | B39: Every forecast input: Base, Bull and Bear rows, the active row and the scenario switch (C5)
A40: Interim_Bridge | B40: 2026E = nine months actual (10-Q) + fourth quarter from guidance
A41: Revenue_Build | B41: Advertising = ads shown x price per ad; other revenue; Reality Labs
A42: Schedules | B42: Capex and depreciation by vintage, working capital, debt, cash, equity and shares
A43: Forecast_3Stmt | B43: Integrated income statement, balance sheet and cash flow, 2025A-2035E
... A54: Claude Code Log | B54: Log of every scripted change to this workbook
A56: Model outputs (active scenario)
A57: Active scenario | D57: =Assumptions!B6 -> Base
A58: Share price, 26 Oct 2026 (USD) | D58: =Market_Package!B8 -> 630.56
...

Sheet IS_Hist
A1: Meta Platforms, Inc. | Consolidated Statements of Income
A2: USD millions, except per-share amounts (USD) and share counts (millions). Each period as first reported in its own filing.
B3: Audited (Form 10-K) | I3: Unaudited (Form 10-Q)
A4: Fiscal year ends 31 December | B4: 2019A | C4: 2020A | D4: 2021A | E4: 2022A | F4: 2023A | G4: 2024A | H4: 2025A | I4: 9M 2025A | J4: 9M 2026A | M4: Comentarios FG | N4: XBRL concept (latest filing) | O4: Earlier wording of this line
A6: Revenue | B6: 70697 | C6: 85965 | D6: 117929 | E6: 116609 | F6: 134902 | G6: 164501 | H6: 200966 | I6: 141073 | J6: 181712 | N6: RevenueFromContractWithCustomerExcludingAssessedTax
A8: Costs and expenses:
A9: Cost of revenue | B9: 12770 | C9: 16692 | D9: 22649 | E9: 25249 | F9: 25959 | G9: 30161 | H9: 36175 | I9: 25269 | J9: 34917 | N9: CostOfRevenue
A10: Research and development | B10: 13600 | C10: 18447 | D10: 24655 | E10: 35338 | F10: 38483 | G10: 43873 | H10: 57372 | I10: 40237 | J10: 59409 | N10: ResearchAndDevelopmentExpense
A11: Marketing and sales | B11: 9876 | C11: 11591 | D11: 14043 | E11: 15262 | F11: 12301 | G11: 11347 | H11: 11991 | I11: 8581 | J11: 9672 | N11: SellingAndMarketingExpense
A12: General and administrative | B12: 10465 | C12: 6564 | D12: 9829 | E12: 11816 | F12: 11408 | G12: 9740 | H12: 12152 | I12: 8455 | J12: 23079 | N12: GeneralAndAdministrativeExpense
A13: Total costs and expenses | B13: 46711 | C13: 53294 | D13: 71176 | E13: 87665 | F13: 88151 | G13: 95121 | H13: 117690 | I13: 82542 | J13: 127077 | N13: CostsAndExpenses
A15: Income from operations | B15: 23986 | C15: 32671 | D15: 46753 | E15: 28944 | F15: 46751 | G15: 69380 | H15: 83276 | I15: 58531 | J15: 54635 | N15: OperatingIncomeLoss
A17: Interest and other income, net | B17: 826 | C17: 509 | D17: 531 | E17: -125 | F17: 677 | G17: 1283 | H17: 2656 | I17: 2047 | J17: -1126 | N17: NonoperatingIncomeExpense | O17: Interest and other income (expense), net
A18: Income before provision for income taxes | B18: 24812 | C18: 33180 | D18: 47284 | E18: 28819 | F18: 47428 | G18: 70663 | H18: 85932 | I18: 60578 | J18: 53509 | N18: IncomeLossFromContinuingOperationsBeforeIncomeTaxesExtraordinaryItemsNoncontrollingInterest | O18: Income before income taxes
A20: Provision for income taxes | B20: 6327 | C20: 4034 | D20: 7914 | E20: 5619 | F20: 8330 | G20: 8303 | H20: 25474 | I20: 22888 | J20: 1028 | N20: IncomeTaxExpenseBenefit
A21: Net income | B21: 18485 | C21: 29146 | D21: 39370 | E21: 23200 | F21: 39098 | G21: 62360 | H21: 60458 | I21: 37690 | J21: 52481 | N21: NetIncomeLoss
A23: Less: Net income attributable to participating securities | B23: 0 | C23: 0 | N23: UndistributedEarningsLossAllocatedToParticipatingSecuritiesBasic
A24: Net income attributable to Class A and Class B common stockholders | B24: 18485 | C24: 29146 | N24: NetIncomeLossAvailableToCommonStockholdersBasic
A26: Earnings per share: | O26: Earnings per share attributable to Class A and Class B common stockholders:
A27: Basic | B27: 6.48 | C27: 10.22 | D27: 13.99 | E27: 8.63 | F27: 15.19 | G27: 24.61 | H27: 23.98 | I27: 14.96 | J27: 20.64 | N27: EarningsPerShareBasic
A28: Diluted | B28: 6.43 | C28: 10.09 | D28: 13.77 | E28: 8.59 | F28: 14.87 | G28: 23.86 | H28: 23.49 | I28: 14.62 | J28: 20.44 | N28: EarningsPerShareDiluted
A30: Weighted-average shares used to compute earnings per share: | O30: Weighted-average shares used to compute earnings per share attributable to Class A and Class B common stockholders:
A31: Basic | B31: 2854 | C31: 2851 | D31: 2815 | E31: 2687 | F31: 2574 | G31: 2534 | H31: 2521 | I31: 2520 | J31: 2543 | N31: WeightedAverageNumberOfSharesOutstandingBasic
A32: Diluted | B32: 2876 | C32: 2888 | D32: 2859 | E32: 2702 | F32: 2629 | G32: 2614 | H32: 2574 | I32: 2578 | J32: 2568 | N32: WeightedAverageNumberOfDilutedSharesOutstanding
A34: Share-based compensation expense included in costs and expenses:
A35: Cost of revenue | B35: 377 | C35: 447 | D35: 577 | E35: 768 | N35: AllocatedShareBasedCompensationExpense
A36: Research and development | B36: 3488 | C36: 4918 | D36: 7106 | E36: 9361 | N36: AllocatedShareBasedCompensationExpense
A37: Marketing and sales | B37: 569 | C37: 691 | D37: 837 | E37: 1004 | N37: AllocatedShareBasedCompensationExpense
A38: General and administrative | B38: 402 | C38: 480 | D38: 644 | E38: 859 | N38: AllocatedShareBasedCompensationExpense
A39: Total share-based compensation expense | B39: 4836 | C39: 6536 | D39: 9164 | E39: 11992 | N39: AllocatedShareBasedCompensationExpense
A41: Checks (each should be zero)
A42: Costs and expenses add to the total | B42: =B9+B10+B11+B12-B13 -> 0 | C42: =C9+C10+C11+C12-C13 -> 0 | D42: =D9+D10+D11+D12-D13 -> 0 | E42: =E9+E10+E11+E12-E13 -> 0 | F42: =F9+F10+F11+F12-F13 -> 0 | G42: =G9+G10+G11+G12-G13 -> 0 | H42: =H9+H10+H11+H12-H13 -> 0 | I42: =I9+I10+I11+I12-I13 -> 0 | J42: =J9+J10+J11+J12-J13 -> 0
A43: Revenue less total costs equals income from operations | B43: =B6-B13-B15 -> 0 | C43: =C6-C13-C15 -> 0 | D43: =D6-D13-D15 -> 0 | E43: =E6-E13-E15 -> 0 | F43: =F6-F13-F15 -> 0 | G43: =G6-G13-G15 -> 0 | H43: =H6-H13-H15 -> 0 | I43: =I6-I13-I15 -> 0 | J43: =J6-J13-J15 -> 0
A44: Operating income plus other income equals pre-tax income | B44: =B15+B17-B18 -> 0 | C44: =C15+C17-C18 -> 0 | D44: =D15+D17-D18 -> 0 | E44: =E15+E17-E18 -> 0 | F44: =F15+F17-F18 -> 0 | G44: =G15+G17-G18 -> 0 | H44: =H15+H17-H18 -> 0 | I44: =I15+I17-I18 -> 0 | J44: =J15+J17-J18 -> 0
A45: Pre-tax income less tax equals net income | B45: =B18-B20-B21 -> 0 | C45: =C18-C20-C21 -> 0 | D45: =D18-D20-D21 -> 0 | E45: =E18-E20-E21 -> 0 | F45: =F18-F20-F21 -> 0 | G45: =G18-G20-G21 -> 0 | H45: =H18-H20-H21 -> 0 | I45: =I18-I20-I21 -> 0 | J45: =J18-J20-J21 -> 0
A46: Net income less participating securities equals net income to common | B46: =B21+B23-B24 -> 0 | C46: =C21+C23-C24 -> 0
A47: Share-based compensation by function adds to the total | B47: =B35+B36+B37+B38-B39 -> 0 | C47: =C35+C36+C37+C38-C39 -> 0 | D47: =D35+D36+D37+D38-D39 -> 0 | E47: =E35+E36+E37+E38-E39 -> 0
A48: Net income equals the cash flow statement | B48: =B21-CF_Hist!B7 -> 0 | C48: =C21-CF_Hist!C7 -> 0 | D48: =D21-CF_Hist!D7 -> 0 | E48: =E21-CF_Hist!E7 -> 0 | F48: =F21-CF_Hist!F7 -> 0 | G48: =G21-CF_Hist!G7 -> 0 | H48: =H21-CF_Hist!H7 -> 0 | I48: =I21-CF_Hist!I7 -> 0 | J48: =J21-CF_Hist!J7 -> 0
A49: Net income equals the comprehensive income statement | B49: =B21-CI_Hist!B6 -> 0 | C49: =C21-CI_Hist!C6 -> 0 | D49: =D21-CI_Hist!D6 -> 0 | E49: =E21-CI_Hist!E6 -> 0 | F49: =F21-CI_Hist!F6 -> 0 | G49: =G21-CI_Hist!G6 -> 0 | H49: =H21-CI_Hist!H6 -> 0 | I49: =I21-CI_Hist!I6 -> 0 | J49: =J21-CI_Hist!J6 -> 0
A50: Net income equals the retained earnings roll-forward | B50: =B21-SCE_Hist!B49 -> 0 | C50: =C21-SCE_Hist!C49 -> 0 | D50: =D21-SCE_Hist!D49 -> 0 | E50: =E21-SCE_Hist!E49 -> 0 | F50: =F21-SCE_Hist!F49 -> 0 | G50: =G21-SCE_Hist!G49 -> 0 | H50: =H21-SCE_Hist!H49 -> 0 | I50: =I21-SCE_Hist!I49 -> 0 | J50: =J21-SCE_Hist!J49 -> 0

Sheet CI_Hist
A1: Meta Platforms, Inc. | Consolidated Statements of Comprehensive Income
A2: USD millions, except per-share amounts (USD) and share counts (millions). Each period as first reported in its own filing.
B3: Audited (Form 10-K) | I3: Unaudited (Form 10-Q)
A4: Fiscal year ends 31 December | B4: 2019A | C4: 2020A | D4: 2021A | E4: 2022A | F4: 2023A | G4: 2024A | H4: 2025A | I4: 9M 2025A | J4: 9M 2026A | M4: Comentarios FG | N4: XBRL concept (latest filing) | O4: Earlier wording of this line
A6: Net income | B6: 18485 | C6: 29146 | D6: 39370 | E6: 23200 | F6: 39098 | G6: 62360 | H6: 60458 | I6: 37690 | J6: 52481 | N6: NetIncomeLoss
A8: Other comprehensive income (loss):
A9: Change in foreign currency translation adjustment, net of tax | B9: -151 | C9: 1056 | D9: -1116 | E9: -1184 | F9: 618 | G9: -1413 | H9: 2693 | I9: 2598 | J9: -638 | N9: OtherComprehensiveIncomeLossForeignCurrencyTransactionAndTranslationAdjustmentNetOfTax
A10: Change in unrealized gain (loss) on available-for-sale investments and other, net of tax | B10: 422 | C10: 360 | D10: -504 | E10: -1653 | F10: 757 | G10: 471 | H10: 675 | I10: 658 | J10: -833 | N10: OtherComprehensiveIncomeLossAvailableForSaleSecuritiesAdjustmentAndOtherNetofTax, OtherComprehensiveIncomeLossAvailableForSaleSecuritiesAdjustmentAndOtherNetofTax, OtherComprehensiveIncomeUnrealizedHoldingGainLossOnSecuritiesArisingDuringPeriodNetOfTax | O10: Change in unrealized gain/loss on available-for-sale investments and other, net of tax
A11: Comprehensive income | B11: 18756 | C11: 30562 | D11: 37750 | E11: 20363 | F11: 40473 | G11: 61418 | H11: 63826 | I11: 40946 | J11: 51010 | N11: ComprehensiveIncomeNetOfTax
A13: Checks (each should be zero)
A14: Net income plus other comprehensive income equals comprehensive income | B14: =B6+B9+B10-B11 -> 0 | C14: =C6+C9+C10-C11 -> 0 | D14: =D6+D9+D10-D11 -> 0 | E14: =E6+E9+E10-E11 -> 0 | F14: =F6+F9+F10-F11 -> 0 | G14: =G6+G9+G10-G11 -> 0 | H14: =H6+H9+H10-H11 -> 0 | I14: =I6+I9+I10-I11 -> 0 | J14: =J6+J9+J10-J11 -> 0
A15: Other comprehensive income equals the equity roll-forward | B15: =B9+B10-SCE_Hist!B44 -> 0 | C15: =C9+C10-SCE_Hist!C44 -> 0 | D15: =D9+D10-SCE_Hist!D44 -> 0 | E15: =E9+E10-SCE_Hist!E44 -> 0 | F15: =F9+F10-SCE_Hist!F44 -> 0 | G15: =G9+G10-SCE_Hist!G44 -> 0 | H15: =H9+H10-SCE_Hist!H44 -> 0 | I15: =I9+I10-SCE_Hist!I44 -> 0 | J15: =J9+J10-SCE_Hist!J44 -> 0

Sheet BS_Hist
A1: Meta Platforms, Inc. | Consolidated Balance Sheets
A2: USD millions, except per-share amounts (USD) and share counts (millions). Each period as first reported in its own filing.
B3: Audited (Form 10-K) | I3: Unaudited (Form 10-Q)
A4: Fiscal year ends 31 December | B4: 2019A | C4: 2020A | D4: 2021A | E4: 2022A | F4: 2023A | G4: 2024A | H4: 2025A | I4: Sep 2025A | J4: Sep 2026A | M4: Comentarios FG | N4: XBRL concept (latest filing) | O4: Earlier wording of this line
A6: Assets | J6: =+J7+J48 -> 127746
J7: =+J10+J9-H10+H9 -> 72603
A8: Current assets: | J8: =+(J10+J9)/(H10+H9) -> 1.0105035
A9: Cash and cash equivalents | B9: 19079 | C9: 17576 | D9: 16601 | E9: 14681 | F9: 41862 | G9: 43889 | H9: 35873 | I9: 10187 | J9: 11222 | N9: CashAndCashEquivalentsAtCarryingValue
A10: Marketable securities | B10: 35776 | C10: 44378 | D10: 31397 | E10: 26057 | F10: 23541 | G10: 33926 | H10: 45719 | I10: 34261 | J10: 71227 | N10: AvailableForSaleSecuritiesDebtSecuritiesCurrent, MarketableSecuritiesCurrent
A11: Accounts receivable, net | B11: 9518 | C11: 11335 | D11: 14039 | E11: 13466 | F11: 16169 | G11: 16994 | H11: 19769 | I11: 17297 | J11: 22716 | N11: AccountsReceivableNetCurrent | O11: Accounts receivable, net of allowances of $114 million and $92 million as of December 31, 2020 and 2019, respectively | Accounts receivable, net of allowances of $206 and $229 as of December 31, 2019 and December 31, 2018, respectively
A12: Prepaid expenses and other current assets | B12: 1852 | C12: 2381 | D12: 4629 | E12: 5345 | F12: 3793 | G12: 5236 | H12: 7361 | I12: 11373 | J12: 14735 | N12: PrepaidExpenseAndOtherAssetsCurrent
A13: Total current assets | B13: 66225 | C13: 75670 | D13: 66666 | E13: 59549 | F13: 85365 | G13: 100045 | H13: 108722 | I13: 73118 | J13: 119900 | N13: AssetsCurrent
J14: =+(J16)/(H16) -> 1.4354989
A15: Non-marketable equity investments | C15: 6234 | D15: 6775 | E15: 6201 | F15: 6141 | G15: 6070 | H15: 27524 | I15: 25074 | J15: 32624 | N15: NonmarketableEquitySecuritiesCarryingValue, NonmarketableEquitySecuritiesCarryingValue, EquitySecuritiesWithoutReadilyDeterminableFairValueAmount | O15: Non-marketable equity securities | Equity investments
A16: Property and equipment, net | B16: 35323 | C16: 45633 | D16: 57809 | E16: 79518 | F16: 96587 | G16: 121346 | H16: 176400 | I16: 160270 | J16: 253222 | N16: PropertyPlantAndEquipmentAndFinanceLeaseRightofUseAssetAfterAccumulatedDepreciationAndAmortization, PropertyPlantAndEquipmentAndFinanceLeaseRightOfUseAssetAfterAccumulatedDepreciationAndAmortization
A17: Operating lease right-of-use assets | B17: 9460 | C17: 9348 | D17: 12155 | E17: 12673 | F17: 13294 | G17: 14922 | H17: 20404 | I17: 17372 | J17: 26576 | N17: OperatingLeaseRightOfUseAsset | O17: Operating lease right-of-use assets, net
A18: Intangible assets, net | B18: 894 | C18: 623 | D18: 634 | E18: 897 | F18: 788 | N18: IntangibleAssetsNetExcludingGoodwill
A19: Goodwill | B19: 18715 | C19: 19050 | D19: 19197 | E19: 20306 | F19: 20654 | G19: 20654 | H19: 24534 | I19: 21158 | J19: 23421 | N19: Goodwill
A20: Other assets | B20: 2759 | C20: 2758 | D20: 2751 | E20: 6583 | F20: 6794 | G20: 13017 | H20: 8437 | I20: 6852 | J20: 23093 | N20: OtherAssetsNoncurrent
A21: Total assets | B21: 133376 | C21: 159316 | D21: 165987 | E21: 185727 | F21: 229623 | G21: 276054 | H21: 366021 | I21: 303844 | J21: 478836 | N21: Assets
H22: =+H21/B21-1 -> 1.7442793
A23: Liabilities and stockholders' equity
A25: Current liabilities:
A26: Accounts payable | B26: 1363 | C26: 1331 | D26: 4083 | E26: 4990 | F26: 4849 | G26: 7687 | H26: 8894 | I26: 7798 | J26: 19097 | N26: AccountsPayableCurrent, AccountsPayableTradeCurrent
A27: Partners payable | B27: 886 | C27: 1093 | D27: 1052 | E27: 1117 | F27: 863 | N27: AccountsPayableOtherCurrent, AccountsPayableTradeCurrent
A28: Operating lease liabilities, current | B28: 800 | C28: 1023 | D28: 1127 | E28: 1367 | F28: 1623 | G28: 1942 | H28: 2213 | I28: 2113 | J28: 2522 | N28: OperatingLeaseLiabilityCurrent
A29: Accrued expenses and other current liabilities | B29: 11735 | C29: 11152 | D29: 14312 | E29: 19552 | F29: 24625 | G29: 23967 | H29: 30729 | I29: 27047 | J29: 41392 | N29: AccruedLiabilitiesCurrent
A30: Deferred revenue and deposits | B30: 269 | C30: 382 | D30: 561 | N30: ContractWithCustomerLiabilityAndUnusedDeposits, ContractWithCustomerLiabilityCurrent
A31: Total current liabilities | B31: 15053 | C31: 14981 | D31: 21135 | E31: 27026 | F31: 31960 | G31: 33596 | H31: 41836 | I31: 36958 | J31: 63011 | N31: LiabilitiesCurrent
A33: Operating lease liabilities, non-current | B33: 9524 | C33: 9631 | D33: 12746 | E33: 15301 | F33: 17226 | G33: 18292 | H33: 22940 | I33: 20113 | J33: 28651 | N33: OperatingLeaseLiabilityNoncurrent
A34: Long-term debt | E34: 9923 | F34: 18385 | G34: 28826 | H34: 58744 | I34: 28834 | J34: 80922 | N34: LongTermDebtNoncurrent
A35: Long-term income taxes | G35: 9987 | H35: 21005 | I35: 11738 | J35: 20521 | N35: AccruedIncomeTaxesNoncurrent
A36: Other liabilities | B36: 7745 | C36: 6414 | D36: 7227 | E36: 7764 | F36: 8884 | G36: 2716 | H36: 4253 | I36: 12135 | J36: 13345 | N36: OtherLiabilitiesNoncurrent
A37: Total liabilities | B37: 32322 | C37: 31026 | D37: 41108 | E37: 60014 | F37: 76455 | G37: 93417 | H37: 148778 | I37: 109778 | J37: 206450 | N37: Liabilities
J38: =+J37-H37 -> 57672
A39: Commitments and contingencies
A41: Stockholders' equity:
A42: Common stock and additional paid-in capital, $0.000006 par value | J42: 108244 | N42: CommonStocksIncludingAdditionalPaidInCapital | O42: Common stock and additional paid-in capital, $0.000006 par value; 5,000 million Class A shares authorized, 2,214 million and 2,187 million shares issued and outstanding, as of September 30, 2026 and December 31, 2025, respectively; 4,141 million Class B shares authorized, 342 million and 343 million shares issued and outstanding, as of September 30, 2026 and December 31, 2025, respectively
A43: Common stock, $0.000006 par value | B43: 0 | C43: 0 | D43: 0 | E43: 0 | F43: 0 | G43: 0 | H43: 0 | I43: 0 | N43: CommonStockValue | O43: Common stock, $0.000006 par value; 5,000 million Class A shares authorized, 2,187 million and 2,190 million shares issued and outstanding, as of December 31, 2025 and 2024, respectively; 4,141 million Class B shares authorized, 343 million and 344 million shares issued and outstanding, as of December 31, 2025 and 2024, respectively | Common stock, $0.000006 par value; 5,000 million Class A shares authorized, 2,190 million and 2,211 million shares issued and outstanding, as of December 31, 2024 and 2023, respectively; 4,141 million Class B shares authorized, 344 million and 350 million shares issued and outstanding, as of December 31, 2024 and 2023, respectively | Common stock, $0.000006 par value; 5,000 million Class A shares authorized, 2,211 million and 2,247 million shares issued and outstanding, as of December 31, 2023 and 2022, respectively; 4,141 million Class B shares authorized, 350 million and 367 million shares issued and outstanding, as of December 31, 2023 and 2022, respectively | Common stock, $0.000006 par value; 5,000 million Class A shares authorized, 2,247 million and 2,328 million shares issued and outstanding, as of December 31, 2022 and 2021, respectively; 4,141 million Class B shares authorized, 367 million and 413 million shares issued and outstanding, as of December 31, 2022 and 2021, respectively | Common stock, $0.000006 par value; 5,000 million Class A shares authorized, 2,328 million and 2,406 million shares issued and outstanding, as of December 31, 2021 and 2020, respectively; 4,141 million Class B shares authorized, 413 million and 443 million shares issued and outstanding, as of December 31, 2021 and 2020, respectively | Common stock, $0.000006 par value; 5,000 million Class A shares authorized, 2,406 million and 2,407 million shares issued and outstanding, as of December 31, 2020 and 2019, respectively; 4,141 million Class B shares authorized, 443 million and 445 million shares issued and outstanding, as of December 31, 2020 and 2019, respectively | Common stock, $0.000006 par value; 5,000 million Class A shares authorized, 2,407 million and 2,385 million shares issued and outstanding, as of December 31, 2019 and December 31, 2018, respectively; 4,141 million Class B shares authorized, 445 million and 469 million shares issued and outstanding, as of December 31, 2019 and December 31, 2018, respectively. | Common stock, $0.000006 par value; 5,000 million Class A shares authorized, 2,178 million and 2,190 million shares issued and outstanding, as of September 30, 2025 and December 31, 2024, respectively; 4,141 million Class B shares authorized, 343 million and 344 million shares issued and outstanding, as of September 30, 2025 and December 31, 2024, respectively
A44: Additional paid-in capital | B44: 45851 | C44: 50018 | D44: 55811 | E44: 64444 | F44: 73253 | G44: 83228 | H44: 95793 | I44: 92330 | N44: AdditionalPaidInCapital
...

Sheet CF_Hist
A1: Meta Platforms, Inc. | Consolidated Statements of Cash Flows
A2: USD millions, except per-share amounts (USD) and share counts (millions). Each period as first reported in its own filing.
B3: Audited (Form 10-K) | I3: Unaudited (Form 10-Q)
A4: Fiscal year ends 31 December | B4: 2019A | C4: 2020A | D4: 2021A | E4: 2022A | F4: 2023A | G4: 2024A | H4: 2025A | I4: 9M 2025A | J4: 9M 2026A | M4: Comentarios FG | N4: XBRL concept (latest filing) | O4: Earlier wording of this line
A6: Cash flows from operating activities
A7: Net income | B7: 18485 | C7: 29146 | D7: 39370 | E7: 23200 | F7: 39098 | G7: 62360 | H7: 60458 | I7: 37690 | J7: 52481 | N7: NetIncomeLoss
A9: Adjustments to reconcile net income to net cash provided by operating activities:
A10: Depreciation and amortization | B10: 5741 | C10: 6862 | D10: 7967 | E10: 8686 | F10: 11178 | G10: 15498 | H10: 18616 | I10: 13205 | J10: 19509 | N10: DepreciationDepletionAndAmortization
A11: Share-based compensation | B11: 4836 | C11: 6536 | D11: 9164 | E11: 11992 | F11: 14027 | G11: 16690 | H11: 20427 | I11: 14537 | J11: 21053 | N11: ShareBasedCompensation
A12: Deferred income taxes | B12: -37 | C12: -1192 | D12: 609 | E12: -3286 | F12: 131 | G12: -4738 | H12: 18738 | I12: 17704 | J12: 3685 | N12: DeferredIncomeTaxExpenseBenefit, DeferredIncomeTaxesAndTaxCredits
A13: Unrealized gain on marketable equity securities | I13: -548 | N13: EquitySecuritiesFvNiUnrealizedGainLoss
A14: Unrealized (gain) loss on equity investments | H14: -1138 | J14: 1204 | N14: UnrealizedGainLossOnMarketableAndNonmarketableEquityInvestments | O14: Unrealized (gain) and loss on equity investments
A15: Impairment charges for facilities consolidation | E15: 2218 | F15: 2432 | G15: 383 | H15: 0 | N15: ImpairmentOfLongLivedAssetsHeldForUse, RestructuringCharges | O15: Impairment charges for facilities consolidation, net | Impairment charges for leases and leasehold improvements
A16: Data center assets abandonment | E16: 1341 | F16: -224 | G16: 0 | N16: RestructuringCharges | O16: Abandonment charges for data center assets
A17: Fair value adjustments for non-marketable securities | E17: 463 | N17: EquitySecuritiesFvNiGainLoss
A18: Other | B18: 39 | C18: 118 | D18: -127 | E18: 178 | F18: 635 | G18: 87 | H18: -416 | I18: -453 | J18: -402 | N18: OtherNoncashIncomeExpense
A20: Changes in assets and liabilities:
A21: Accounts receivable | B21: -1961 | C21: -1512 | D21: -3110 | E21: 231 | F21: -2399 | G21: -1485 | H21: -1815 | I21: 660 | J21: -3272 | N21: IncreaseDecreaseInAccountsReceivable
A22: Prepaid expenses and other current assets | B22: 47 | C22: 135 | D22: -1750 | E22: 162 | F22: 559 | G22: -698 | H22: -89 | I22: -348 | J22: -4166 | N22: IncreaseDecreaseInPrepaidDeferredExpenseAndOtherAssets
A23: Other assets | B23: 41 | C23: -34 | D23: -349 | E23: -106 | F23: -80 | G23: -270 | H23: -481 | I23: -209 | J23: -4973 | N23: IncreaseDecreaseInOtherOperatingAssets
A24: Accounts payable | B24: 113 | C24: -17 | D24: 1436 | E24: 210 | F24: 51 | G24: 373 | H24: -14 | I24: -637 | J24: 1242 | N24: IncreaseDecreaseInAccountsPayableTrade
A25: Partners payable | B25: 348 | C25: 178 | D25: -12 | E25: 90 | F25: -271 | N25: IncreaseDecreaseInOtherAccountsPayable
A26: Accrued expenses and other current liabilities | B26: 7300 | C26: -1054 | D26: 3357 | E26: 4210 | F26: 5352 | G26: 323 | H26: 1077 | I26: -2883 | J26: 7602 | N26: IncreaseDecreaseInAccruedLiabilities
A27: Deferred revenue and deposits | B27: 123 | C27: 108 | D27: 187 | N27: IncreaseDecreaseInContractWithCustomerLiability
A28: Other liabilities | B28: 1239 | C28: -527 | D28: 941 | E28: 886 | F28: 624 | G28: 2805 | H28: 437 | I28: 868 | J28: 2910 | N28: IncreaseDecreaseInOtherNoncurrentLiabilities
A29: Net cash provided by operating activities | B29: 36314 | C29: 38747 | D29: 57683 | E29: 50475 | F29: 71113 | G29: 91328 | H29: 115800 | I29: 79586 | J29: 96873 | N29: NetCashProvidedByUsedInOperatingActivities
A31: Cash flows from investing activities
A32: Purchases of property and equipment | B32: -15102 | C32: -15115 | D32: -18567 | E32: -31431 | F32: -27266 | G32: -37256 | H32: -69691 | I32: -48308 | J32: -83055 | N32: PaymentsToAcquirePropertyPlantAndEquipment | O32: Purchases of property and equipment, net
A33: Proceeds relating to property and equipment | E33: 245 | F33: 221 | N33: ProceedsFromSaleOfPropertyPlantAndEquipment
A34: Purchases of marketable securities | B34: -23910 | C34: -33930 | D34: -30407 | E34: -9626 | F34: -2982 | G34: -25542 | H34: -36929 | I34: -22349 | J34: -117467 | N34: PaymentsToAcquireAvailableForSaleSecuritiesDebt, PaymentsToAcquireMarketableSecurities | O34: Purchases of marketable debt securities
A35: Sales of marketable debt securities | B35: 9565 | C35: 11787 | D35: 31671 | E35: 11083 | N35: ProceedsFromSaleOfAvailableForSaleSecuritiesDebt | O35: Sales of marketable securities
A36: Maturities of marketable debt securities | B36: 10152 | C36: 13984 | D36: 10915 | E36: 2075 | N36: ProceedsFromMaturitiesPrepaymentsAndCallsOfAvailableForSaleSecurities | O36: Maturities of marketable securities
A37: Sales and maturities of marketable securities | F37: 6184 | G37: 15789 | H37: 26874 | I37: 23761 | J37: 88837 | N37: ProceedsFromSaleAndMaturityOfAvailableForSaleSecurities, ProceedsFromSaleAndMaturityOfMarketableSecurities | O37: Sales and maturities of marketable debt securities
A38: Payments for held-for-sale assets | H38: -2432 | I38: -1797 | J38: -1612 | N38: PaymentsForHeldForSaleAssets
A39: Proceeds from Venture distribution | H39: 2554 | J39: 1037 | N39: ProceedsFromOneTimeVentureDistribution, EquityMethodInvestmentDividendsOrDistributions | O39: Proceeds from data center venture distribution
A40: Purchases of non-marketable equity investments | C40: -6361 | D40: -47 | E40: -5 | H40: -18330 | I40: -18260 | J40: -2544 | N40: PaymentsForEquitySecuritiesWithoutReadilyDeterminableFairValue, PaymentsForEquitySecuritiesWithoutReadilyDeterminableFairValue | O40: Purchases of non-marketable equity securities | Purchases of equity investments | Payments for non-marketable equity investments
A41: Acquisitions of businesses and intangible assets | B41: -508 | C41: -388 | D41: -851 | E41: -1312 | F41: -629 | G41: -270 | H41: -4231 | I41: -815 | J41: -584 | N41: PaymentsToAcquireBusinessesNetOfCashAcquiredAndPurchasesOfIntangibleAndOtherAssets, PaymentsToAcquireBusinessesNetOfCashAcquiredAndPurchasesOfIntangibleAndOtherAssets | O41: Acquisitions of businesses, net of cash acquired, and purchases of intangible assets
A42: Other investing activities | B42: -61 | C42: -36 | D42: -284 | E42: 1 | F42: -23 | G42: 129 | H42: 182 | I42: -48 | J42: 1079 | N42: PaymentsForProceedsFromOtherInvestingActivities | O42: Other investing activities, net
A43: Net cash used in investing activities | B43: -19864 | C43: -30059 | D43: -7570 | E43: -28970 | F43: -24495 | G43: -47150 | H43: -102003 | I43: -67816 | J43: -114309 | N43: NetCashProvidedByUsedInInvestingActivities
A45: Cash flows from financing activities
...

Sheet SCE_Hist
A1: Meta Platforms, Inc. | Consolidated Statements of Stockholders' Equity (roll-forward by component)
A2: USD millions; shares in millions. Each column of the filed statement is shown here as one block, years across.
B3: Audited (Form 10-K) | I3: Unaudited (Form 10-Q)
A4: Fiscal year ends 31 December | B4: 2019A | C4: 2020A | D4: 2021A | E4: 2022A | F4: 2023A | G4: 2024A | H4: 2025A | I4: 9M 2025A | J4: 9M 2026A | M4: Comentarios FG | N4: XBRL concept (latest filing) | O4: Earlier wording of this line
A6: Total stockholders' equity
A7: Balance at beginning of period | B7: 84127 | C7: 101054 | D7: 128290 | E7: 124879 | F7: 125713 | G7: 153168 | H7: 182637 | I7: 182637 | J7: 217243
A8: Net income | B8: 18485 | C8: 29146 | D8: 39370 | E8: 23200 | F8: 39098 | G8: 62360 | H8: 60458 | I8: 37690 | J8: 52481
A9: Other comprehensive income (loss) | B9: 271 | C9: 1416 | D9: -1620 | E9: -2837 | F9: 1375 | G9: -942 | H9: 3368 | I9: 3256 | J9: -1471 | O9: Other comprehensive income | Other comprehensive loss
A10: Issuance of common stock for cash upon exercise of stock options | B10: 15
A11: Issuance of common stock for settlement of RSUs | B11: 0 | C11: 0 | D11: 0
A12: Issuance of common stock | H12: 450 | I12: 450
A13: Shares withheld related to net share settlement | B13: -2581 | C13: -3564 | D13: -5515 | E13: -3595 | F13: -7012 | G13: -13770 | H13: -18400 | I13: -14128 | J13: -12768 | O13: Shares withheld related to net share settlement and other
A14: Share-based compensation | B14: 4836 | C14: 6536 | D14: 9164 | E14: 11992 | F14: 14027 | G14: 16690 | H14: 20427 | I14: 14537 | J14: 21053
A15: Share repurchases | B15: -4099 | C15: -6298 | D15: -44810 | E15: -27926 | F15: -20033 | G15: -29754 | H15: -26264 | I15: -26319
A16: Dividends and dividend equivalents declared | G16: -5121 | H16: -5421 | I16: -4052 | J16: -4152 | O16: Dividends and dividend equivalents declared ($2.00 per share)
A17: Other | G17: 6 | H17: -12 | I17: -5
A18: Balance at end of period | B18: 101054 | C18: 128290 | D18: 124879 | E18: 125713 | F18: 153168 | G18: 182637 | H18: 217243 | I18: 194066 | J18: 272386
A20: Class A and Class B common stock: shares (millions)
A21: Balance at beginning of period | B21: 2854 | C21: 2852 | D21: 2849 | E21: 2741 | F21: 2614 | G21: 2561 | H21: 2534 | I21: 2534 | J21: 2530
A22: Issuance of common stock for cash upon exercise of stock options | B22: 1
A23: Issuance of common stock for settlement of RSUs | B23: 32 | C23: 38 | D23: 45
A24: Issuance of common stock | E24: 54 | F24: 65 | G24: 65 | H24: 63 | I24: 47 | J24: 47
A25: Shares withheld related to net share settlement | B25: -13 | C25: -14 | D25: -17 | E25: -20 | F25: -26 | G25: -27 | H25: -27 | I25: -20 | J25: -21 | O25: Shares withheld related to net share settlement and other
A26: Share repurchases | B26: -22 | C26: -27 | D26: -136 | E26: -161 | F26: -92 | G26: -65 | H26: -40 | I26: -40
A27: Balance at end of period | B27: 2852 | C27: 2849 | D27: 2741 | E27: 2614 | F27: 2561 | G27: 2534 | H27: 2530 | I27: 2521 | J27: 2556
A29: Class A and Class B common stock: par value
A30: Balance at beginning of period | B30: 0 | C30: 0 | D30: 0 | E30: 0 | F30: 0 | G30: 0 | H30: 0 | I30: 0
A31: Balance at end of period | B31: 0 | C31: 0 | D31: 0 | E31: 0 | F31: 0 | G31: 0 | H31: 0 | I31: 0
A33: Additional paid-in capital
A34: Balance at beginning of period | B34: 42906 | C34: 45851 | D34: 50018 | E34: 55811 | F34: 64444 | G34: 73253 | H34: 83228 | I34: 83228 | J34: 95793
A35: Issuance of common stock for cash upon exercise of stock options | B35: 15
A36: Issuance of common stock | H36: 450 | I36: 450
A37: Shares withheld related to net share settlement | B37: -1906 | C37: -2369 | D37: -3371 | E37: -3359 | F37: -5218 | G37: -6721 | H37: -8312 | I37: -5880 | J37: -8602 | O37: Shares withheld related to net share settlement and other
A38: Share-based compensation | B38: 4836 | C38: 6536 | D38: 9164 | E38: 11992 | F38: 14027 | G38: 16690 | H38: 20427 | I38: 14537 | J38: 21053
A39: Other | G39: 6 | I39: -5
A40: Balance at end of period | B40: 45851 | C40: 50018 | D40: 55811 | E40: 64444 | F40: 73253 | G40: 83228 | H40: 95793 | I40: 92330 | J40: 108244 | O40: 9M 2026A: the Q3 2026 10-Q shows common stock and additional paid-in capital as one column; that column is shown here (par value is USD 0).
A42: Accumulated other comprehensive income (loss)
A43: Balance at beginning of period | B43: -760 | C43: -489 | D43: 927 | E43: -693 | F43: -3530 | G43: -2155 | H43: -3097 | I43: -3097 | J43: 271
A44: Other comprehensive income (loss) | B44: 271 | C44: 1416 | D44: -1620 | E44: -2837 | F44: 1375 | G44: -942 | H44: 3368 | I44: 3256 | J44: -1471 | O44: Other comprehensive income | Other comprehensive loss
A45: Balance at end of period | B45: -489 | C45: 927 | D45: -693 | E45: -3530 | F45: -2155 | G45: -3097 | H45: 271 | I45: 159 | J45: -1200
...

Sheet Revenue_Hist
A1: Meta Platforms, Inc. | Revenue: sources, segments, regions and drivers
A2: USD millions unless the row says otherwise. Each number comes from the filing that first reported it. Sections A and B: audited notes. Section C: management's discussion, not audited. Section D: formulas.
B3: Form 10-K | I3: Form 10-Q
A4: Fiscal year ends 31 December | B4: 2019A | C4: 2020A | D4: 2021A | E4: 2022A | F4: 2023A | G4: 2024A | H4: 2025A | I4: 9M 2025A | J4: 9M 2026A | M4: Comentarios FG | N4: Where in the filing | O4: Note
A6: A. Revenue by source and by segment (audited note)
A7: Advertising | B7: 69655 | C7: 84169 | D7: 114934 | E7: 113642 | F7: 131948 | G7: 160633 | H7: 196175 | I7: 138037 | J7: 177449 | N7: Notes: Revenue (by source and by segment)
A8: Other revenue | B8: 541 | C8: 657 | D8: 721 | E8: 808 | F8: 1058 | G8: 1722 | H8: 2584 | I8: 1784 | J8: 2987 | N8: Notes: Revenue (by source and by segment) | O8: 2019A and 2020A first reported in the 2021 10-K, the first 10-K with two segments. Mainly business messaging and Meta Verified.
A9: Family of Apps | B9: 70196 | C9: 84826 | D9: 115655 | E9: 114450 | F9: 133006 | G9: 162355 | H9: 198759 | I9: 139821 | J9: 180436 | N9: Notes: Revenue (by source and by segment) | O9: 2019A and 2020A first reported in the 2021 10-K, the first 10-K with two segments.
A10: Reality Labs | B10: 501 | C10: 1139 | D10: 2274 | E10: 2159 | F10: 1896 | G10: 2146 | H10: 2207 | I10: 1252 | J10: 1276 | N10: Notes: Revenue (by source and by segment) | O10: 2019A and 2020A first reported in the 2021 10-K, the first 10-K with two segments. Hardware, software and content.
A11: Total revenue | B11: 70697 | C11: 85965 | D11: 117929 | E11: 116609 | F11: 134902 | G11: 164501 | H11: 200966 | I11: 141073 | J11: 181712 | N11: Notes: Revenue (by source and by segment)
A13: Memo: other revenue as reported before the segment split | B13: 1042 | C13: 1796 | N13: Notes: Revenue (by source and by segment) | O13: The 2019 and 2020 10-Ks show one other-revenue line that includes Reality Labs. The 2021 10-K split it (see Recasts).
A14: Memo: total revenue per the income statement | B14: =IS_Hist!B6 -> 70697 | C14: =IS_Hist!C6 -> 85965 | D14: =IS_Hist!D6 -> 117929 | E14: =IS_Hist!E6 -> 116609 | F14: =IS_Hist!F6 -> 134902 | G14: =IS_Hist!G6 -> 164501 | H14: =IS_Hist!H6 -> 200966 | I14: =IS_Hist!I6 -> 141073 | J14: =IS_Hist!J6 -> 181712
A16: B. Revenue by region, by the customer's address (audited note) | O16: Region = the address of the customer (the advertiser), not the place of the user.
A17: United States and Canada | B17: 32206 | C17: 38433 | D17: 51541 | E17: 50150 | F17: 52888 | G17: 63207 | H17: 78866 | I17: 55031 | J17: 71346 | N17: Notes: Revenue (by geography)
A18: Europe | B18: 16826 | C18: 20349 | D18: 29057 | E18: 26681 | F18: 31210 | G18: 38361 | H18: 46569 | I18: 32315 | J18: 41272 | N18: Notes: Revenue (by geography) | O18: Includes Russia and Turkey.
A19: Asia-Pacific | B19: 15406 | C19: 19848 | D19: 26739 | E19: 27760 | F19: 36154 | G19: 45009 | H19: 53817 | I19: 38401 | J19: 48511 | N19: Notes: Revenue (by geography)
A20: Rest of World | B20: 6259 | C20: 7335 | D20: 10592 | E20: 12018 | F20: 14650 | G20: 17924 | H20: 21714 | I20: 15326 | J20: 20583 | N20: Notes: Revenue (by geography) | O20: Africa, Latin America and the Middle East.
A21: Total revenue | B21: 70697 | C21: 85965 | D21: 117929 | E21: 116609 | F21: 134902 | G21: 164501 | H21: 200966 | I21: 141073 | J21: 181712 | N21: Notes: Revenue (by geography)
A23: Memo: United States | B23: 30230 | C23: 36250 | D23: 48380 | E23: 47200 | F23: 49780 | G23: 59730 | H23: 74780 | N23: Notes: Revenue (footnote to the geography table) | O23: Given in USD billions with two decimals. The 10-Qs do not give it.
A24: Memo: China (customers based in China) | D24: 7590 | E24: 7400 | F24: 13690 | G24: 18350 | N24: Notes: Revenue (footnote to the geography table) | O24: Given in USD billions with two decimals. First given in the 2023 10-K, for 2021A to 2023A. The 2025 10-K does not give it.
A26: C. Drivers reported by Meta (management's discussion, not audited) | O26: The sentence behind each number: evidence/driver_sentences.tsv in the run folder 2026-10-26_meta-pestana-ingresos.
A27: Ad impressions delivered: change on a year earlier | B27: 0.33 | C27: 0.34 | D27: 0.1 | E27: 0.18 | F27: 0.28 | G27: 0.11 | H27: 0.12 | I27: 0.1 | J27: 0.14 | N27: Management's discussion: results of operations, revenue | O27: Meta gives whole percents. 9M columns: the nine months against the same nine months a year earlier.
A28: Average price per ad: change on a year earlier | B28: -0.05 | C28: -0.1 | D28: 0.24 | E28: -0.16 | F28: -0.09 | G28: 0.1 | H28: 0.09 | I28: 0.1 | J28: 0.13 | N28: Management's discussion: results of operations, revenue | O28: Meta gives whole percents.
A29: Daily active people, DAP (billions) | B29: 2.26 | C29: 2.6 | D29: 2.82 | E29: 2.96 | F29: 3.19 | G29: 3.35 | H29: 3.58 | I29: 3.54 | J29: 3.64 | N29: Management's discussion: key user metrics | O29: Average for December in the 10-K columns; average for September in the 10-Q columns.
A30: Daily active people: change on a year earlier | B30: 0.11 | C30: 0.15 | D30: 0.08 | E30: 0.05 | F30: 0.08 | G30: 0.05 | H30: 0.07 | I30: 0.08 | J30: 0.03 | N30: Management's discussion: key user metrics
A31: Facebook daily active users, DAU (billions) | B31: 1.66 | C31: 1.84 | D31: 1.93 | E31: 2 | F31: 2.11 | N31: Management's discussion: key user metrics | O31: Average for December. Facebook only. Meta stopped this metric after 2023.
A32: Average revenue per person, ARPP (USD): definition to 2023 | B32: 25.57 | C32: 27.51 | D32: 33.68 | E32: 31.79 | F32: 34.72 | N32: Management's discussion: monetization metrics | O32: Total revenue divided by monthly active people; sum of four quarters.
A33: Average revenue per person, ARPP (USD): definition from 2024 | G33: 49.63 | H33: 57.03 | N33: Management's discussion: monetization metrics | O33: Family of Apps revenue divided by daily active people; sum of four quarters. The 2024 10-K recast the 2023 quarters; their sum is 43.15 (not typed here).
A34: Facebook average revenue per user, ARPU (USD) | B34: 29.25 | C34: 32.03 | D34: 40.96 | E34: 39.63 | F34: 44.6 | N34: Management's discussion: monetization metrics | O34: Facebook only; sum of four quarters. Meta stopped this metric after 2023.
A35: Effect of exchange rates on revenue | B35: -1670 | C35: -120 | D35: 1640 | E35: -5960 | F35: 374 | G35: -874 | H35: -418 | I35: -906 | J35: 2320 | N35: Management's discussion: foreign exchange impact on revenue | O35: Revenue less revenue at the prior year's exchange rates. Meta says 'higher' or 'lower' in words; the sign is ours: negative = the dollar cut revenue.
A37: D. Calculated here (formulas, not in the filings)
A38: Revenue: growth on the prior period | C38: =C11/B11-1 -> 0.2159639 | D38: =D11/C11-1 -> 0.37182574 | E38: =E11/D11-1 -> -0.011193176 | F38: =F11/E11-1 -> 0.15687468 | G38: =G11/F11-1 -> 0.21941113 | H38: =H11/G11-1 -> 0.22167038 | J38: =J11/I11-1 -> 0.28807072
A39: Advertising revenue: growth on the prior period | C39: =C7/B7-1 -> 0.20836982 | D39: =D7/C7-1 -> 0.36551462 | E39: =E7/D7-1 -> -0.011241234 | F39: =F7/E7-1 -> 0.16108481 | G39: =G7/F7-1 -> 0.21739625 | H39: =H7/G7-1 -> 0.22126213 | J39: =J7/I7-1 -> 0.28551765
A40: Ads shown x price per ad: implied advertising growth | B40: =(1+B27)*(1+B28)-1 -> 0.2635 | C40: =(1+C27)*(1+C28)-1 -> 0.206 | D40: =(1+D27)*(1+D28)-1 -> 0.364 | E40: =(1+E27)*(1+E28)-1 -> -0.0088 | F40: =(1+F27)*(1+F28)-1 -> 0.1648 | G40: =(1+G27)*(1+G28)-1 -> 0.221 | H40: =(1+H27)*(1+H28)-1 -> 0.2208 | I40: =(1+I27)*(1+I28)-1 -> 0.21 | J40: =(1+J27)*(1+J28)-1 -> 0.2882 | O40: (1 + change in ads shown) x (1 + change in price per ad) - 1.
A41: Gap: implied less actual advertising growth | C41: =C40-C39 -> -0.0023698227 | D41: =D40-D39 -> -0.0015146194 | E41: =E40-E39 -> 0.0024412341 | F41: =F40-F39 -> 0.0037151898 | G41: =G40-G39 -> 0.003603753 | H41: =H40-H39 -> -0.00046213169 | J41: =J40-J39 -> 0.0026823489 | O41: Not a check. Meta rounds both changes to whole percents, so a gap up to about 1 point is normal.
A42: Revenue: growth at the prior year's exchange rates | C42: =(C11-C35)/B11-1 -> 0.21766129 | D42: =(D11-D35)/C11-1 -> 0.35274821 | E42: =(E11-E35)/D11-1 -> 0.039345708 | F42: =(F11-F35)/E11-1 -> 0.15366738 | G42: =(G11-G35)/F11-1 -> 0.22588991 | H42: =(H11-H35)/G11-1 -> 0.2242114 | J42: =(J11-J35)/I11-1 -> 0.27162533 | O42: (Revenue - exchange-rate effect) / prior-period revenue - 1.
A43: Advertising: share of revenue | B43: =B7/B11 -> 0.98526104 | C43: =C7/C11 -> 0.97910778 | D43: =D7/D11 -> 0.97460336 | E43: =E7/E11 -> 0.97455599 | F43: =F7/F11 -> 0.97810262 | G43: =G7/G11 -> 0.97648647 | H43: =H7/H11 -> 0.97616015 | I43: =I7/I11 -> 0.97847923 | J43: =J7/J11 -> 0.9765398
A44: Reality Labs: share of revenue | B44: =B10/B11 -> 0.0070865808 | C44: =C10/C11 -> 0.013249578 | D44: =D10/D11 -> 0.019282789 | E44: =E10/E11 -> 0.018514866 | F44: =F10/F11 -> 0.014054647 | G44: =G10/G11 -> 0.013045513 | H44: =H10/H11 -> 0.010981957 | I44: =I10/I11 -> 0.0088748378 | J44: =J10/J11 -> 0.0070221009
A46: Index, 2019A = 1.00 (full years only) | O46: Each index compounds the yearly changes from 2019A.
A47: Ads shown | B47: =1 -> 1 | C47: =B47*(1+C27) -> 1.34 | D47: =C47*(1+D27) -> 1.474 | E47: =D47*(1+E27) -> 1.73932 | F47: =E47*(1+F27) -> 2.2263296 | G47: =F47*(1+G27) -> 2.4712259 | H47: =G47*(1+H27) -> 2.767773
...

Sheet Assumptions
A1: Meta Platforms, Inc. | Assumptions and scenarios | F1: 15
A2: Blue cells are inputs. Each driver has Base, Bull and Bear rows; the Active row follows the switch in C5. USD millions unless stated.
H3: Actual | I3: Forecast
A4: Fiscal year ends 31 December | B4: 2019 | C4: =+B4+1 -> 2020 | D4: =+C4+1 -> 2021 | E4: =+D4+1 -> 2022 | F4: =+E4+1 -> 2023 | G4: =+F4+1 -> 2024 | H4: =+G4+1 -> 2025 | I4: =+H4+1 -> 2026 | J4: =+I4+1 -> 2027 | ... R4: =+Q4+1 -> 2035 | S4: Comentarios FG | T4: Source / derivation
A5: Scenario switch: 1 = Base, 2 = Bull, 3 = Bear | B5: 1 | T5: Same convention as the house templates (Supuestos!C5).
A6: Active scenario | B6: =CHOOSE(B5,"Base","Bull","Bear") -> Base
A8: A. 2026E bridge and valuation inputs (one value per scenario)
I9: Active | J9: Base | K9: Bull | L9: Bear
A10: Q4 2026E revenue (USD m) | I10: =CHOOSE($B$5,J10,K10,L10) -> 74500 | J10: 74500 | K10: 76000 | L10: 73000 | T10: Guidance USD 73-76 bn (Q3 2026 earnings, 21 Oct 2026): midpoint, top, bottom.
A11: FY2026E total costs and expenses (USD m) | I11: =CHOOSE($B$5,J11,K11,L11) -> 177000 | J11: 177000 | K11: 175000 | L11: 179000 | T11: Guidance USD 175-179 bn including the legal charge (Q3 2026 earnings call).
A12: Q4 2026E effective tax rate | I12: =CHOOSE($B$5,J12,K12,L12) -> 0.16 | J12: 0.16 | K12: 0.15 | L12: 0.17 | T12: Guidance 15-17% (Q3 2026 earnings call).
A13: Q4 2026E other revenue: growth on Q4 2025 | I13: =CHOOSE($B$5,J13,K13,L13) -> 0.6 | J13: 0.6 | K13: 0.7 | L13: 0.5 | T13: 9M 2026 +67% (10-Q).
A14: Q4 2026E Reality Labs revenue (USD m) | I14: =CHOOSE($B$5,J14,K14,L14) -> 955 | J14: 955 | K14: 1050 | L14: 900 | T14: Q4 2025 = 955 (FY2025 less 9M 2025). Base flat (9M 2026 +2%).
A15: Q4 2026E Reality Labs operating loss (USD m) | I15: =CHOOSE($B$5,J15,K15,L15) -> -5725 | J15: -5725 | K15: -5225 | L15: -6225 | T15: FY2026 loss guidance USD 18-19 bn less 9M loss 12,775.
A16: Terminal growth (after 2035E) | I16: =CHOOSE($B$5,J16,K16,L16) -> 0.03 | J16: 0.03 | K16: 0.035 | L16: 0.025 | T16: Below the 10-year Treasury yield (5.00%); near long-run nominal GDP. Analyst input.
A17: Terminal return on new invested capital | I17: =CHOOSE($B$5,J17,K17,L17) -> 0.2 | J17: 0.2 | K17: 0.3 | L17: 0.12 | T17: Reinvestment = growth / ROIC (Damodaran). Meta's pre-AI ROIC was about 30%. Analyst input.
A18: Exit EV / EBITDA multiple (2035E) | I18: =CHOOSE($B$5,J18,K18,L18) -> 10 | J18: 10 | K18: 12 | L18: 7 | T18: Cross-check only. LTM EV/EBITDA today about 14x-16x; a 2035 exit sees lower growth. Analyst input.
A19: Terminal return on equity (FCFE method) | I19: =CHOOSE($B$5,J19,K19,L19) -> 0.25 | J19: 0.25 | K19: 0.3 | L19: 0.15 | T19: Reinvestment of equity = growth / ROE. Analyst input.
A21: B. Inputs that do not change with the scenario
A22: Q4 2026E interest and other income, net (USD m) | I22: -200 | T22: Interest income on about USD 82 bn of cash at 3.5% less interest on USD 84 bn of notes at 4.8%, per quarter.
A23: Q4 2026E interest expense on the notes (USD m) | I23: 1000 | T23: USD 84 bn x 4.8% / 4.
A24: Q4 2026E depreciation and amortization (USD m) | I24: 8200 | T24: Q3 2026 depreciation 6,810 grows about 15% a quarter, plus about 340 of amortization (10-Q).
A25: Q4 2026E share-based compensation (USD m) | I25: 7000 | T25: 9M 2026: 21,053 (10-Q), so about 7,000 a quarter.
A26: Q4 2026E taxes paid on RSU net share settlement (USD m) | I26: 4250 | T26: 9M 2026: 12,768 (10-Q), so about 4,250 a quarter.
A27: Q4 2026E dividends paid (USD m) | I27: 1360 | T27: Q3 2026 payments USD 1.36 bn (press release).
A28: Q4 2026E new debt issued (USD m) | I28: 0 | T28: No issue announced after 30 Sep 2026.
A29: Q4 2026E share buybacks (USD m) | I29: 0 | T29: No buybacks in 9M 2026 (10-Q).
A30: 9M 2026 legal charges in costs (USD m) | I30: 11890 | T30: Multistate attorneys general agreement charges (10-Q, G&A discussion).
A31: Interest income yield on cash and marketable securities | I31: 0.035 | T31: Between the 2025 realized yield (about 2.7%) and the 3-month bill (4.22%, Treasury, 26 Oct 2026). Analyst input.
A32: Interest rate on debt (on beginning balance) | I32: 0.048 | T32: Coupons 3.50%-6.45% (10-Q Note 9); new issues near 5.3%-6.5%. Analyst input.
A33: Minimum cash and marketable securities: % of revenue | I33: 0.25 | T33: Meta held 34% of LTM revenue at 30 Sep 2026; S&P expects a neutral net debt position. Analyst policy input.
... A45: Sensitivity: capex scale versus the scenario path | I45: 0 | T45: Keep at 0. The Sensitivity sheet moves it.
A46: Accounts receivable: % of revenue | I46: =BS_Hist!H11/IS_Hist!H6 -> 0.098369874 | T46: 2025A ratio, held flat (link to the audited balance sheet).
A47: Prepaid expenses and other current assets: % of revenue | I47: =BS_Hist!H12/IS_Hist!H6 -> 0.036628086 | T47: 2025A ratio, held flat (link to the audited balance sheet).
A48: Accounts payable: % of revenue | I48: =BS_Hist!H26/IS_Hist!H6 -> 0.044256242 | T48: 2025A ratio, held flat (link to the audited balance sheet).
A49: Accrued expenses and other current liabilities: % of revenue | I49: =BS_Hist!H29/IS_Hist!H6 -> 0.15290646 | T49: 2025A ratio, held flat (link to the audited balance sheet).
A51: C. Drivers by year (Base, Bull, Bear and the active row)
A52: Ad impressions delivered: growth on a year earlier | T52: 2026E: 9M 2026 +14%, Q3 +10% (10-Q), so about 13% for the year. Later years fade with people growth (DAP +3% in Sep 2026) and ad load. Analyst input.
A53: Base | I53: 0.13 | J53: 0.1 | K53: 0.09 | L53: 0.08 | M53: 0.07 | N53: 0.06 | O53: 0.05 | P53: 0.04 | Q53: 0.035 | R53: 0.03
A54: Bull | I54: 0.14 | J54: 0.11 | K54: 0.1 | L54: 0.09 | M54: 0.08 | N54: 0.07 | O54: 0.06 | P54: 0.05 | Q54: 0.04 | R54: 0.035
...

Sheet Interim_Bridge
A1: Meta Platforms, Inc. | 2026E bridge: nine months actual plus fourth quarter estimate
A2: 9M columns link to the 10-Q sheets; Q4 2026E comes from guidance and inputs on Assumptions. USD millions.
A4: Line | B4: 9M 2026A | C4: Q4 2026E | D4: FY2026E | E4: 9M 2025A | F4: Q4 2025A | G4: FY2025A | H4: Comentarios FG | I4: Source / derivation
A6: Revenue
A7: Advertising | B7: =Revenue_Hist!J7 -> 177449 | C7: =C10-C8-C9 -> 72265 | D7: =B7+C7 -> 249714 | E7: =Revenue_Hist!I7 -> 138037 | F7: =G7-E7 -> 58138 | G7: =Revenue_Hist!H7 -> 196175 | I7: Q4 2026E = Q4 revenue guidance less other revenue and Reality Labs.
A8: Other revenue | B8: =Revenue_Hist!J8 -> 2987 | C8: =F8*(1+Assumptions!$I$13) -> 1280 | D8: =B8+C8 -> 4267 | E8: =Revenue_Hist!I8 -> 1784 | F8: =G8-E8 -> 800 | G8: =Revenue_Hist!H8 -> 2584
A9: Reality Labs | B9: =Revenue_Hist!J10 -> 1276 | C9: =Assumptions!$I$14 -> 955 | D9: =B9+C9 -> 2231 | E9: =Revenue_Hist!I10 -> 1252 | F9: =G9-E9 -> 955 | G9: =Revenue_Hist!H10 -> 2207
A10: Total revenue | B10: =IS_Hist!J6 -> 181712 | C10: =Assumptions!$I$10 -> 74500 | D10: =B10+C10 -> 256212 | E10: =IS_Hist!I6 -> 141073 | F10: =G10-E10 -> 59893 | G10: =IS_Hist!H6 -> 200966 | I10: Q4 guidance USD 73-76 bn.
A12: Total costs and expenses | B12: =IS_Hist!J13 -> 127077 | C12: =Assumptions!$I$11-B12 -> 49923 | D12: =B12+C12 -> 177000 | E12: =IS_Hist!I13 -> 82542 | F12: =G12-E12 -> 35148 | G12: =IS_Hist!H13 -> 117690 | I12: Q4 2026E = FY2026 guidance (USD 175-179 bn) less 9M actual.
A13: of which legal charges outside the run-rate | B13: =Assumptions!$I$30 -> 11890 | C13: 0 | D13: =B13+C13 -> 11890 | E13: 0 | F13: =G13-E13 -> 0 | G13: 0 | I13: Attorneys general agreement, 10-Q.
A14: Income from operations | B14: =B10-B12 -> 54635 | C14: =C10-C12 -> 24577 | D14: =B14+C14 -> 79212 | E14: =E10-E12 -> 58531 | F14: =G14-E14 -> 24745 | G14: =G10-G12 -> 83276
A15: Reality Labs income (loss) from operations | B15: -12775 | C15: =Assumptions!$I$15 -> -5725 | D15: =B15+C15 -> -18500 | E15: -13171 | F15: =G15-E15 -> -6022 | G15: -19193 | I15: 10-Q and 10-K segment notes (XBRL OperatingIncomeLoss, RealityLabsMember).
A16: Family of Apps income from operations | B16: =B14-B15 -> 67410 | C16: =C14-C15 -> 30302 | D16: =B16+C16 -> 97712 | E16: =E14-E15 -> 71702 | F16: =G16-E16 -> 30767 | G16: =G14-G15 -> 102469
A17: Depreciation and amortization | B17: =CF_Hist!J10 -> 19509 | C17: =Assumptions!$I$24 -> 8200 | D17: =B17+C17 -> 27709 | E17: =CF_Hist!I10 -> 13205 | F17: =G17-E17 -> 5411 | G17: =CF_Hist!H10 -> 18616
A18: EBITDA (income from operations + D&A) | B18: =B14+B17 -> 74144 | C18: =C14+C17 -> 32777 | D18: =B18+C18 -> 106921 | E18: =E14+E17 -> 71736 | F18: =G18-E18 -> 30156 | G18: =G14+G17 -> 101892
A19: Interest and other income, net | B19: =IS_Hist!J17 -> -1126 | C19: =Assumptions!$I$22 -> -200 | D19: =B19+C19 -> -1326 | E19: =IS_Hist!I17 -> 2047 | F19: =G19-E19 -> 609 | G19: =IS_Hist!H17 -> 2656
A20: memo: interest expense on the notes | B20: 2170 | C20: =Assumptions!$I$23 -> 1000 | D20: =B20+C20 -> 3170 | E20: 668 | F20: =G20-E20 -> 422 | G20: 1090 | I20: 10-Q Note 9 and 10-K Note 9 (net of capitalized interest).
A21: Income before provision for income taxes | B21: =B14+B19 -> 53509 | C21: =C14+C19 -> 24377 | D21: =B21+C21 -> 77886 | E21: =E14+E19 -> 60578 | F21: =G21-E21 -> 25354 | G21: =G14+G19 -> 85932
A22: Provision for income taxes | B22: =IS_Hist!J20 -> 1028 | C22: =C21*Assumptions!$I$12 -> 3900.32 | D22: =B22+C22 -> 4928.32 | E22: =IS_Hist!I20 -> 22888 | F22: =G22-E22 -> 2586 | G22: =IS_Hist!H20 -> 25474 | I22: 9M 2026 includes an 8.03 bn CAMT tax benefit; 9M 2025 a 15.93 bn charge (10-Q).
A23: Net income | B23: =B21-B22 -> 52481 | C23: =C21-C22 -> 20476.68 | D23: =B23+C23 -> 72957.68 | E23: =E21-E22 -> 37690 | F23: =G23-E23 -> 22768 | G23: =G21-G22 -> 60458
A25: Cash flow items
A26: Net cash provided by operating activities (memo) | B26: =CF_Hist!J29 -> 96873 | E26: =CF_Hist!I29 -> 79586 | F26: =G26-E26 -> 36214 | G26: =CF_Hist!H29 -> 115800
A27: Share-based compensation | B27: =CF_Hist!J11 -> 21053 | C27: =Assumptions!$I$25 -> 7000 | D27: =B27+C27 -> 28053 | E27: =CF_Hist!I11 -> 14537 | F27: =G27-E27 -> 5890 | G27: =CF_Hist!H11 -> 20427
A28: Capital expenditures incl. finance-lease principal | B28: =-(CF_Hist!J32+CF_Hist!J50) -> 85824 | C28: =Assumptions!I91-B28 -> 54176 | D28: =B28+C28 -> 140000 | E28: =-(CF_Hist!I32+CF_Hist!I50) -> 50078 | F28: =G28-E28 -> 22137 | G28: =-(CF_Hist!H32+CF_Hist!H50) -> 72215 | I28: Meta's definition: purchases of property and equipment plus principal payments on finance leases. FY2026E = guidance (Assumptions).
A29: Dividends paid | B29: =-CF_Hist!J48 -> 4060 | C29: =Assumptions!$I$27 -> 1360 | D29: =B29+C29 -> 5420 | E29: =-CF_Hist!I48 -> 3986 | F29: =G29-E29 -> 1338 | G29: =-CF_Hist!H48 -> 5324
A30: Share buybacks | B30: =-CF_Hist!J47 -> 0 | C30: =Assumptions!$I$29 -> 0 | D30: =B30+C30 -> 0 | E30: =-CF_Hist!I47 -> 26248 | F30: =G30-E30 -> 0 | G30: =-CF_Hist!H47 -> 26248
A31: Taxes paid on RSU net share settlement | B31: =-CF_Hist!J46 -> 12768 | C31: =Assumptions!$I$26 -> 4250 | D31: =B31+C31 -> 17018 | E31: =-CF_Hist!I46 -> 14128 | F31: =G31-E31 -> 4272 | G31: =-CF_Hist!H46 -> 18400
A32: Proceeds from new long-term debt | B32: =CF_Hist!J49 -> 24910 | C32: =Assumptions!$I$28 -> 0 | D32: =B32+C32 -> 24910 | E32: =CF_Hist!I49 -> 0 | F32: =G32-E32 -> 29906 | G32: =CF_Hist!H49 -> 29906
A34: Revenue growth on the same period a year earlier | B34: =B10/E10-1 -> 0.28807072 | C34: =C10/F10-1 -> 0.24388493 | D34: =D10/G10-1 -> 0.27490222
A36: Checks (each should be zero)
A37: Segments add to total revenue | B37: =ROUND(B7+B8+B9-B10,2) -> 0 | C37: =ROUND(C7+C8+C9-C10,2) -> 0 | D37: =ROUND(D7+D8+D9-D10,2) -> 0 | E37: =ROUND(E7+E8+E9-E10,2) -> 0 | F37: =ROUND(F7+F8+F9-F10,2) -> 0 | G37: =ROUND(G7+G8+G9-G10,2) -> 0
A38: Income from operations ties to the income statement | B38: =ROUND(B14-IS_Hist!J15,2) -> 0 | E38: =ROUND(E14-IS_Hist!I15,2) -> 0 | G38: =ROUND(G14-IS_Hist!H15,2) -> 0
A39: Net income ties to the income statement | B39: =ROUND(B23-IS_Hist!J21,2) -> 0 | E39: =ROUND(E23-IS_Hist!I21,2) -> 0 | G39: =ROUND(G23-IS_Hist!H21,2) -> 0
A40: FY2026E costs equal the guidance input | D40: =ROUND(D12-Assumptions!$I$11,2) -> 0

Sheet Revenue_Build
A1: Meta Platforms, Inc. | Revenue build: ads shown x price per ad
A2: Advertising revenue grows with the number of ads shown and the average price per ad, the two numbers Meta reports each year.
B3: Actual | C3: Forecast
A4: Fiscal year ends 31 December | B4: 2025A | C4: 2026E | D4: 2027E | E4: 2028E | F4: 2029E | G4: 2030E | H4: 2031E | I4: 2032E | J4: 2033E | K4: 2034E | L4: 2035E | M4: Comentarios FG | N4: Source / derivation
A6: Advertising
A7: Ad impressions: growth | C7: =Assumptions!I56 -> 0.13 | D7: =Assumptions!J56 -> 0.1 | E7: =Assumptions!K56 -> 0.09 | F7: =Assumptions!L56 -> 0.08 | G7: =Assumptions!M56 -> 0.07 | H7: =Assumptions!N56 -> 0.06 | I7: =Assumptions!O56 -> 0.05 | J7: =Assumptions!P56 -> 0.04 | ... L7: =Assumptions!R56 -> 0.03
A8: Average price per ad: growth (2026E derived) | C8: =(1+C10)/(1+C7)-1 -> 0.126473 | D8: =Assumptions!J61+Assumptions!$I$44 -> 0.08 | E8: =Assumptions!K61+Assumptions!$I$44 -> 0.07 | F8: =Assumptions!L61+Assumptions!$I$44 -> 0.06 | G8: =Assumptions!M61+Assumptions!$I$44 -> 0.05 | H8: =Assumptions!N61+Assumptions!$I$44 -> 0.04 | I8: =Assumptions!O61+Assumptions!$I$44 -> 0.04 | J8: =Assumptions!P61+Assumptions!$I$44 -> 0.035 | K8: =Assumptions!Q61+Assumptions!$I$44 -> 0.03 | L8: =Assumptions!R61+Assumptions!$I$44 -> 0.025 | N8: 2026E: (1 + ad revenue growth) / (1 + impressions growth) - 1. Later years: Assumptions plus the sensitivity shift.
