Workbook

Sheet 00_Cover
A1: Taiwan Semiconductor Manufacturing Company Limited — Regated institutional model
A2: Native-currency, source-ledgered semiconductor model | 2026-07-16 | owner-ready, independent certification pending
A4: Model identifier | B4: TSMC_9of10_Regated
A5: Ticker / CIK | B5: TSM / 0001046179
A6: Reporting currency / scale | B6: TWD / TWD millions
A7: Latest historical period | B7: FY2025A
A8: Forecast horizon | B8: Five fiscal years
A9: Valuation method | B9: Unlevered DCF to USD traded-security value
A10: Scenario control | B10: Assumptions!B3 — 1 Base / 2 Bull / 3 Bear
A11: Source gate | B11: Formula-driven exact claim ledger
A12: Native recalculation | B12: LibreOffice 26.2.4.2; two isolated-profile passes + reopen
A13: Architecture | B13: Prior ten-sheet order preserved; Gate_9of10 appended last
A14: Decision status | B14: READY FOR INDEPENDENT 9/10 REVIEW — not self-certified
A16: Use sequence: Sources → Historical → Assumptions → Forecast → Valuation → Sensitivity → Checks → Gate_9of10. Forecasts are estimates. Historical values remain in native currency; only the final security bridge uses dated FX and ADR ratio.

Sheet Sources
A1: Claim-level source and provenance ledger
A2: Every historical hardcode and external valuation input carries exact identity, period, value, locator, accession/URL, target, transform and review status.
A4: Source ID | B4: Legal entity / identifier | C4: Metric / line item | D4: Value | E4: Unit | F4: Period / as-of | G4: Source / class | H4: Taxonomy / claim locator | I4: Form | J4: Filed | K4: Accession | L4: Target cell | M4: Scale / FX / sign transform | N4: Exact official URL | O4: Retrieved | P4: Preparer | Q4: Verification | R4: Limitation / disposition
A5: TSMC-S001 | B5: Taiwan Semiconductor Manufacturing Company Limited | TSM | CIK 0001046179 | C5: Revenue | D5: 1587415 | E5: TWDm | F5: 2021-12-31 | G5: 20-F / Official regulator filing / XBRL | H5: ifrs-full:RevenueFromContractsWithCustomers | I5: 20-F | J5: 2024-04-18 | K5: 0001193125-24-099840 | L5: Historical!B5 | M5: TWD / 1e6; sign preserved | N5: https://www.sec.gov/Archives/edgar/data/1046179/000119312524099840/0001193125-24-099840-index.html | O5: 2026-07-16 | P5: Codex / semiconductor cluster | Q5: VERIFIED | R5: None
A6: TSMC-S002 | B6: Taiwan Semiconductor Manufacturing Company Limited | TSM | CIK 0001046179 | C6: Revenue | D6: 2263891.3 | E6: TWDm | F6: 2022-12-31 | G6: 20-F / Official regulator filing / XBRL | H6: ifrs-full:RevenueFromContractsWithCustomers | I6: 20-F | J6: 2025-04-17 | K6: 0001193125-25-083423 | L6: Historical!C5 | M6: TWD / 1e6; sign preserved | N6: https://www.sec.gov/Archives/edgar/data/1046179/000119312525083423/0001193125-25-083423-index.html | O6: 2026-07-16 | P6: Codex / semiconductor cluster | Q6: VERIFIED | R6: None
A7: TSMC-S003 | B7: Taiwan Semiconductor Manufacturing Company Limited | TSM | CIK 0001046179 | C7: Revenue | D7: 2161735.8 | E7: TWDm | F7: 2023-12-31 | G7: 20-F / Official regulator filing / XBRL | H7: ifrs-full:RevenueFromContractsWithCustomers | I7: 20-F | J7: 2025-04-17 | K7: 0001193125-25-083423 | L7: Historical!D5 | M7: TWD / 1e6; sign preserved | N7: https://www.sec.gov/Archives/edgar/data/1046179/000119312525083423/0001193125-25-083423-index.html | O7: 2026-07-16 | P7: Codex / semiconductor cluster | Q7: VERIFIED | R7: None
A8: TSMC-S004 | B8: Taiwan Semiconductor Manufacturing Company Limited | TSM | CIK 0001046179 | C8: Revenue | D8: 2894307.7 | E8: TWDm | F8: 2024-12-31 | G8: 20-F / Official regulator filing / XBRL | H8: ifrs-full:RevenueFromContractsWithCustomers | I8: 20-F | J8: 2025-04-17 | K8: 0001193125-25-083423 | L8: Historical!E5 | M8: TWD / 1e6; sign preserved | N8: https://www.sec.gov/Archives/edgar/data/1046179/000119312525083423/0001193125-25-083423-index.html | O8: 2026-07-16 | P8: Codex / semiconductor cluster | Q8: VERIFIED | R8: None
A9: TSMC-S005 | B9: Taiwan Semiconductor Manufacturing Company Limited | TSM | CIK 0001046179 | C9: Revenue | D9: 3809054.3 | E9: TWDm | F9: 2025-12-31 | G9: 20-F / Official regulator filing / XBRL | H9: ifrs-full:RevenueFromContractsWithCustomers; context c-1 | I9: 20-F | J9: 2026-04-16 | K9: 0001628280-26-025362 | L9: Historical!F5 | M9: TWD / 1e6; sign preserved | N9: https://www.sec.gov/Archives/edgar/data/1046179/000162828026025362/tsm-20251231.htm | O9: 2026-07-16 | P9: Codex / semiconductor cluster | Q9: VERIFIED | R9: None
A10: TSMC-S006 | B10: Taiwan Semiconductor Manufacturing Company Limited | TSM | CIK 0001046179 | C10: Gross profit | D10: 819537.3 | E10: TWDm | F10: 2021-12-31 | G10: 20-F / Official regulator filing / XBRL | H10: ifrs-full:GrossProfit | I10: 20-F | J10: 2024-04-18 | K10: 0001193125-24-099840 | L10: Historical!B7 | M10: TWD / 1e6; sign preserved | N10: https://www.sec.gov/Archives/edgar/data/1046179/000119312524099840/0001193125-24-099840-index.html | O10: 2026-07-16 | P10: Codex / semiconductor cluster | Q10: VERIFIED | R10: None
A11: TSMC-S007 | B11: Taiwan Semiconductor Manufacturing Company Limited | TSM | CIK 0001046179 | C11: Gross profit | D11: 1348354.8 | E11: TWDm | F11: 2022-12-31 | G11: 20-F / Official regulator filing / XBRL | H11: ifrs-full:GrossProfit | I11: 20-F | J11: 2025-04-17 | K11: 0001193125-25-083423 | L11: Historical!C7 | M11: TWD / 1e6; sign preserved | N11: https://www.sec.gov/Archives/edgar/data/1046179/000119312525083423/0001193125-25-083423-index.html | O11: 2026-07-16 | P11: Codex / semiconductor cluster | Q11: VERIFIED | R11: None
A12: TSMC-S008 | B12: Taiwan Semiconductor Manufacturing Company Limited | TSM | CIK 0001046179 | C12: Gross profit | D12: 1175110.6 | E12: TWDm | F12: 2023-12-31 | G12: 20-F / Official regulator filing / XBRL | H12: ifrs-full:GrossProfit | I12: 20-F | J12: 2025-04-17 | K12: 0001193125-25-083423 | L12: Historical!D7 | M12: TWD / 1e6; sign preserved | N12: https://www.sec.gov/Archives/edgar/data/1046179/000119312525083423/0001193125-25-083423-index.html | O12: 2026-07-16 | P12: Codex / semiconductor cluster | Q12: VERIFIED | R12: None
A13: TSMC-S009 | B13: Taiwan Semiconductor Manufacturing Company Limited | TSM | CIK 0001046179 | C13: Gross profit | D13: 1624353.6 | E13: TWDm | F13: 2024-12-31 | G13: 20-F / Official regulator filing / XBRL | H13: ifrs-full:GrossProfit | I13: 20-F | J13: 2025-04-17 | K13: 0001193125-25-083423 | L13: Historical!E7 | M13: TWD / 1e6; sign preserved | N13: https://www.sec.gov/Archives/edgar/data/1046179/000119312525083423/0001193125-25-083423-index.html | O13: 2026-07-16 | P13: Codex / semiconductor cluster | Q13: VERIFIED | R13: None
A14: TSMC-S010 | B14: Taiwan Semiconductor Manufacturing Company Limited | TSM | CIK 0001046179 | C14: Gross profit | D14: 2281294 | E14: TWDm | F14: 2025-12-31 | G14: 20-F / Official regulator filing / XBRL | H14: ifrs-full:GrossProfit; context c-1 | I14: 20-F | J14: 2026-04-16 | K14: 0001628280-26-025362 | L14: Historical!F7 | M14: TWD / 1e6; sign preserved | N14: https://www.sec.gov/Archives/edgar/data/1046179/000162828026025362/tsm-20251231.htm | O14: 2026-07-16 | P14: Codex / semiconductor cluster | Q14: VERIFIED | R14: None
A15: TSMC-S011 | B15: Taiwan Semiconductor Manufacturing Company Limited | TSM | CIK 0001046179 | C15: Operating income | D15: 649980.9 | E15: TWDm | F15: 2021-12-31 | G15: 20-F / Official regulator filing / XBRL | H15: ifrs-full:ProfitLossFromOperatingActivities | I15: 20-F | J15: 2024-04-18 | K15: 0001193125-24-099840 | L15: Historical!B9 | M15: TWD / 1e6; sign preserved | N15: https://www.sec.gov/Archives/edgar/data/1046179/000119312524099840/0001193125-24-099840-index.html | O15: 2026-07-16 | P15: Codex / semiconductor cluster | Q15: VERIFIED | R15: None
A16: TSMC-S012 | B16: Taiwan Semiconductor Manufacturing Company Limited | TSM | CIK 0001046179 | C16: Operating income | D16: 1121278.9 | E16: TWDm | F16: 2022-12-31 | G16: 20-F / Official regulator filing / XBRL | H16: ifrs-full:ProfitLossFromOperatingActivities | I16: 20-F | J16: 2025-04-17 | K16: 0001193125-25-083423 | L16: Historical!C9 | M16: TWD / 1e6; sign preserved | N16: https://www.sec.gov/Archives/edgar/data/1046179/000119312525083423/0001193125-25-083423-index.html | O16: 2026-07-16 | P16: Codex / semiconductor cluster | Q16: VERIFIED | R16: None
... A107: TSMC-S103 | B107: Taiwan Semiconductor Manufacturing Company Limited | TSM | CIK 0001046179 | C107: Terminal growth | D107: 0.04 | E107: model input | F107: Forecast horizon | G107: Model input / Forecast assumption / model input | H107: Base/Bull/Bear estimate | I107: Model input | J107: 2026-07-16 | K107: n/a | L107: Assumptions!B21:D21 | M107: blue model input | N107: https://www.sec.gov/Archives/edgar/data/1046179/000162828026025362/tsm-20251231.htm | O107: 2026-07-16 | P107: Codex / semiconductor cluster | Q107: VERIFIED | R107: Not a reported fact
A110: Ola 2 elevation (run 24e4a1f1): see Sources_Audited tab for the real, independently-sourced claim ledger (20-F R-files + companyfacts.json). This legacy tab and its COUNTIF-based "VERIFIED" flags are retained unmodified per no-weaken-checks policy but are self-referential (they check label presence in this own tab, not an external source) -- do not rely on them as the audit trail going forward.

Sheet Historical
A1: Historical financials
A2: TWD millions; native reported history. Percent rows are formula-derived.
A4: Metric | B4: FY2021A | C4: FY2022A | D4: FY2023A | E4: FY2024A | F4: FY2025A | G4: Unit | H4: Source coverage
A5: Revenue | B5: 1587415 | C5: 2263891.3 | D5: 2161735.8 | E5: 2894307.7 | F5: 3809054.3 | G5: TWD millions | H5: =IF(COUNTIF(Sources!$C$5:$C$107,"Revenue")>=1,"VERIFIED","CHECK") -> VERIFIED
A6: Growth | C6: =IF(B5<>0,C5/B5-1,0) -> 0.42614962 | D6: =IF(C5<>0,D5/C5-1,0) -> -0.045123854 | E6: =IF(D5<>0,E5/D5-1,0) -> 0.33888133 | F6: =IF(E5<>0,F5/E5-1,0) -> 0.31605023 | G6: % | H6: Formula-derived
A7: Gross profit | B7: 819537.3 | C7: 1348354.8 | D7: 1175110.6 | E7: 1624353.6 | F7: 2281294 | G7: TWD millions | H7: =IF(COUNTIF(Sources!$C$5:$C$107,"Gross profit")>=1,"VERIFIED","CHECK") -> VERIFIED
A8: Gross margin | B8: =IF(B5<>0,B7/B5,0) -> 0.51627161 | C8: =IF(C5<>0,C7/C5,0) -> 0.59559167 | D8: =IF(D5<>0,D7/D5,0) -> 0.54359585 | E8: =IF(E5<>0,E7/E5,0) -> 0.56122354 | F8: =IF(F5<>0,F7/F5,0) -> 0.59891349 | G8: % | H8: Formula-derived
A9: Operating income | B9: 649980.9 | C9: 1121278.9 | D9: 921465.6 | E9: 1322053 | F9: 1936091.7 | G9: TWD millions | H9: =IF(COUNTIF(Sources!$C$5:$C$107,"Operating income")>=1,"VERIFIED","CHECK") -> VERIFIED
A10: Operating margin | B10: =IF(B5<>0,B9/B5,0) -> 0.40945871 | C10: =IF(C5<>0,C9/C5,0) -> 0.49528831 | D10: =IF(D5<>0,D9/D5,0) -> 0.4262619 | E10: =IF(E5<>0,E9/E5,0) -> 0.45677693 | F10: =IF(F5<>0,F9/F5,0) -> 0.50828672 | G10: % | H10: Formula-derived
A11: Net income attributable / consolidated | B11: 592359.2 | C11: 992923.4 | D11: 851740 | E11: 1158380.2 | F11: 1697604 | G11: TWD millions | H11: =IF(COUNTIF(Sources!$C$5:$C$107,"Net income attributable / consolidated")>=1,"VERIFIED","CHECK") -> VERIFIED
A12: Cash flow from operations | B12: 1112160.7 | C12: 1610599.2 | D12: 1241967.3 | E12: 1826177.1 | F12: 2274975.6 | G12: TWD millions | H12: =IF(COUNTIF(Sources!$C$5:$C$107,"Cash flow from operations")>=1,"VERIFIED","CHECK") -> VERIFIED
A13: Capital expenditure | B13: 839195.7 | C13: 1082672.1 | D13: 949816.8 | E13: 956006.5 | F13: 1272410.5 | G13: TWD millions | H13: =IF(COUNTIF(Sources!$C$5:$C$107,"Capital expenditure")>=1,"VERIFIED","CHECK") -> VERIFIED
A14: Research and development | B14: 124734.8 | C14: 163262.2 | D14: 182370.2 | E14: 204181.8 | F14: 246427.2 | G14: TWD millions | H14: =IF(COUNTIF(Sources!$C$5:$C$107,"Research and development")>=1,"VERIFIED","CHECK") -> VERIFIED
A15: Total assets | B15: 3725302.2 | C15: 4964459.1 | D15: 5532196.6 | E15: 6691764.7 | F15: 7932842.5 | G15: TWD millions | H15: =IF(COUNTIF(Sources!$C$5:$C$107,"Total assets")>=1,"VERIFIED","CHECK") -> VERIFIED
A16: Total liabilities | B16: 1573619.7 | C16: 2046626.7 | D16: 2078330.1 | E16: 2412493.1 | F16: 2536623.3 | G16: TWD millions | H16: =IF(COUNTIF(Sources!$C$5:$C$107,"Total liabilities")>=1,"VERIFIED","CHECK") -> VERIFIED
A17: Equity attributable / stockholders' equity | B17: 2149259.8 | C17: 2903019.7 | D17: 3429522.4 | E17: 4244266.5 | F17: 5355038.7 | G17: TWD millions | H17: =IF(COUNTIF(Sources!$C$5:$C$107,"Equity attributable / stockholders' equity")>=1,"VERIFIED","CHECK") -> VERIFIED
A18: Cash and cash equivalents | B18: 1064990.2 | C18: 1342814.1 | D18: 1465427.8 | E18: 2127627 | F18: 2767856.4 | G18: TWD millions | H18: =IF(COUNTIF(Sources!$C$5:$C$107,"Cash and cash equivalents")>=1,"VERIFIED","CHECK") -> VERIFIED
A19: Interest-bearing debt | B19: 617946.4 | C19: 858410.3 | D19: 927576.1 | E19: 1018286.8 | F19: 1032987.7 | G19: TWD millions | H19: =IF(AND(COUNTIF(Sources!$C$5:$C$107,"Debt component: CurrentPortionOfLongtermBorrowings")>=1,COUNTIF(Sources!$C$5:$C$107,"Debt component: NoncurrentPortionOfNoncurrentBondsIssued")>=1,COUNTIF(Sources!$C$5:$C$107,"Debt component: LongtermBorrowings")>=1),"VERIFIED","CHECK") -> VERIFIED
A20: Diluted weighted-average shares | B20: 25930.3 | C20: 25929.4 | D20: 25929.3 | E20: 25929.7 | F20: 25930.6 | G20: millions of shares | H20: =IF(COUNTIF(Sources!$C$5:$C$107,"Diluted weighted-average shares")>=1,"VERIFIED","CHECK") -> VERIFIED

Sheet Assumptions
A1: Scenario assumptions
A2: Blue = input; green = selected formula. Selector 1 Base / 2 Bull / 3 Bear. TWD stays native through DCF.
A3: Scenario selector | B3: 1
A4: Driver | B4: Base | C4: Bull | D4: Bear | E4: Active | F4: Classification / rationale
A5: Wafer shipment growth — Y1 | B5: 0.1 | C5: 0.14 | D5: 0.04 | E5: =CHOOSE($B$3,B5,C5,D5) -> 0.1 | F5: Company-specific revenue driver estimate
A6: Wafer shipment growth — Y5 | B6: 0.06 | C6: 0.09 | D6: 0.03 | E6: =CHOOSE($B$3,B6,C6,D6) -> 0.06 | F6: Company-specific revenue driver estimate
A7: Blended revenue / wafer growth — Y1 | B7: 0.08 | C7: 0.12 | D7: 0.03 | E7: =CHOOSE($B$3,B7,C7,D7) -> 0.08 | F7: Company-specific revenue driver estimate
A8: Blended revenue / wafer growth — Y5 | B8: 0.04 | C8: 0.07 | D8: 0.01 | E8: =CHOOSE($B$3,B8,C8,D8) -> 0.04 | F8: Company-specific revenue driver estimate
A9: Advanced-node mix annual change — Y1 | B9: 0.035 | C9: 0.045 | D9: 0.02 | E9: =CHOOSE($B$3,B9,C9,D9) -> 0.035 | F9: Company-specific revenue driver estimate
A10: Advanced-node mix annual change — Y5 | B10: 0.02 | C10: 0.03 | D10: 0.01 | E10: =CHOOSE($B$3,B10,C10,D10) -> 0.02 | F10: Company-specific revenue driver estimate
A11: Gross margin — Y1 | B11: 0.605 | C11: 0.62 | D11: 0.575 | E11: =CHOOSE($B$3,B11,C11,D11) -> 0.605 | F11: Operating / FCFF estimate
A12: Gross margin — Y5 | B12: 0.615 | C12: 0.64 | D12: 0.58 | E12: =CHOOSE($B$3,B12,C12,D12) -> 0.615 | F12: Operating / FCFF estimate
A13: R&D / revenue | B13: 0.065 | C13: 0.062 | D13: 0.07 | E13: =CHOOSE($B$3,B13,C13,D13) -> 0.065 | F13: Operating / FCFF estimate
A14: Other operating expense / revenue | B14: 0.026 | C14: 0.023 | D14: 0.03 | E14: =CHOOSE($B$3,B14,C14,D14) -> 0.026 | F14: Operating / FCFF estimate
A15: Cash tax rate | B15: 0.15 | C15: 0.14 | D15: 0.17 | E15: =CHOOSE($B$3,B15,C15,D15) -> 0.15 | F15: Operating / FCFF estimate
A16: D&A / revenue | B16: 0.18 | C16: 0.19 | D16: 0.17 | E16: =CHOOSE($B$3,B16,C16,D16) -> 0.18 | F16: Operating / FCFF estimate
... A24: Current traded-security price (USD) | B24: 419.48 | C24: 419.48 | D24: 419.48 | E24: =CHOOSE($B$3,B24,C24,D24) -> 419.48 | F24: Dated market / structural bridge

Sheet Forecast
A1: Company-specific operating forecast
A2: TWD millions; sector operating drivers build revenue bottom-up.
A4: Metric | B4: FY2025A | C4: FY2026E | D4: FY2027E | E4: FY2028E | F4: FY2029E | G4: FY2030E
A5: Wafer shipments (m 12-inch eq.) | B5: 15 | C5: =B5*(1+Assumptions!$E$5) -> 16.5 | D5: =C5*(1+Assumptions!$E$5+(Assumptions!$E$6-Assumptions!$E$5)*1/4) -> 17.985 | E5: =D5*(1+Assumptions!$E$5+(Assumptions!$E$6-Assumptions!$E$5)*2/4) -> 19.4238 | F5: =E5*(1+Assumptions!$E$5+(Assumptions!$E$6-Assumptions!$E$5)*3/4) -> 20.783466 | G5: =F5*(1+Assumptions!$E$5+(Assumptions!$E$6-Assumptions!$E$5)*4/4) -> 22.030474
A6: Blended revenue / wafer (TWD thousands) | B6: 253936.95 | C6: =B6*(1+Assumptions!$E$7) -> 274251.91 | D6: =C6*(1+Assumptions!$E$7+(Assumptions!$E$8-Assumptions!$E$7)*1/4) -> 293449.54 | E6: =D6*(1+Assumptions!$E$7+(Assumptions!$E$8-Assumptions!$E$7)*2/4) -> 311056.52 | F6: =E6*(1+Assumptions!$E$7+(Assumptions!$E$8-Assumptions!$E$7)*3/4) -> 326609.34 | G6: =F6*(1+Assumptions!$E$7+(Assumptions!$E$8-Assumptions!$E$7)*4/4) -> 339673.72
A7: Advanced technologies mix | B7: 0.74 | C7: =MIN(0.95,B7+Assumptions!$E$9) -> 0.775 | D7: =MIN(0.95,C7+Assumptions!$E$9+(Assumptions!$E$10-Assumptions!$E$9)*1/4) -> 0.80625 | E7: =MIN(0.95,D7+Assumptions!$E$9+(Assumptions!$E$10-Assumptions!$E$9)*2/4) -> 0.83375 | F7: =MIN(0.95,E7+Assumptions!$E$9+(Assumptions!$E$10-Assumptions!$E$9)*3/4) -> 0.8575 | G7: =MIN(0.95,F7+Assumptions!$E$9+(Assumptions!$E$10-Assumptions!$E$9)*4/4) -> 0.8775
A8: Total revenue | B8: =B5*B6 -> 3809054.3 | C8: =C5*C6 -> 4525156.5 | D8: =D5*D6 -> 5277690 | E8: =E5*E6 -> 6041899.6 | F8: =F5*F6 -> 6788074.1 | G8: =G5*G6 -> 7483172.9
A9: Revenue growth | B9: =Historical!F6 -> 0.31605023 | C9: =IF(B8<>0,C8/B8-1,0) -> 0.188 | D9: =IF(C8<>0,D8/C8-1,0) -> 0.1663 | E9: =IF(D8<>0,E8/D8-1,0) -> 0.1448 | F9: =IF(E8<>0,F8/E8-1,0) -> 0.1235 | G9: =IF(F8<>0,G8/F8-1,0) -> 0.1024
A10: Gross margin | B10: =Historical!F8 -> 0.59891349 | C10: =Assumptions!$E$11 -> 0.605 | D10: =Assumptions!$E$11+(Assumptions!$E$12-Assumptions!$E$11)*1/4 -> 0.6075 | E10: =Assumptions!$E$11+(Assumptions!$E$12-Assumptions!$E$11)*2/4 -> 0.61 | F10: =Assumptions!$E$11+(Assumptions!$E$12-Assumptions!$E$11)*3/4 -> 0.6125 | G10: =Assumptions!$E$11+(Assumptions!$E$12-Assumptions!$E$11)*4/4 -> 0.615
A11: Gross profit | B11: =B8*B10 -> 2281294 | C11: =C8*C10 -> 2737719.7 | D11: =D8*D10 -> 3206196.7 | E11: =E8*E10 -> 3685558.7 | F11: =F8*F10 -> 4157695.4 | G11: =G8*G10 -> 4602151.4
A12: R&D / revenue | B12: =IF(B8<>0,Historical!F14/B8,0) -> 0.064695113 | C12: =Assumptions!$E$13 -> 0.065 | D12: =Assumptions!$E$13 -> 0.065 | E12: =Assumptions!$E$13 -> 0.065 | F12: =Assumptions!$E$13 -> 0.065 | G12: =Assumptions!$E$13 -> 0.065
A13: R&D | B13: =Historical!F14 -> 246427.2 | C13: =C8*C12 -> 294135.17 | D13: =D8*D12 -> 343049.85 | E13: =E8*E12 -> 392723.47 | F13: =F8*F12 -> 441224.82 | G13: =G8*G12 -> 486406.24
A14: Other operating expense / revenue | B14: =IF(B8<>0,(B11-Historical!F9-B13)/B8,0) -> 0.02593166 | C14: =Assumptions!$E$14 -> 0.026 | D14: =Assumptions!$E$14 -> 0.026 | E14: =Assumptions!$E$14 -> 0.026 | F14: =Assumptions!$E$14 -> 0.026 | G14: =Assumptions!$E$14 -> 0.026
A15: Other operating expense | B15: =B8*B14 -> 98775.1 | C15: =C8*C14 -> 117654.07 | D15: =D8*D14 -> 137219.94 | E15: =E8*E14 -> 157089.39 | F15: =F8*F14 -> 176489.93 | G15: =G8*G14 -> 194562.5
A16: Operating income | B16: =B11-B13-B15 -> 1936091.7 | C16: =C11-C13-C15 -> 2325930.4 | D16: =D11-D13-D15 -> 2725926.9 | E16: =E11-E13-E15 -> 3135745.9 | F16: =F11-F13-F15 -> 3539980.7 | G16: =G11-G13-G15 -> 3921182.6
A17: Operating margin | B17: =IF(B8<>0,B16/B8,0) -> 0.50828672 | C17: =IF(C8<>0,C16/C8,0) -> 0.514 | D17: =IF(D8<>0,D16/D8,0) -> 0.5165 | E17: =IF(E8<>0,E16/E8,0) -> 0.519 | F17: =IF(F8<>0,F16/F8,0) -> 0.5215 | G17: =IF(G8<>0,G16/G8,0) -> 0.524
A18: Cash tax rate | B18: =Assumptions!E15 -> 0.15 | C18: =Assumptions!$E$15 -> 0.15 | D18: =Assumptions!$E$15 -> 0.15 | E18: =Assumptions!$E$15 -> 0.15 | F18: =Assumptions!$E$15 -> 0.15 | G18: =Assumptions!$E$15 -> 0.15
A19: NOPAT | B19: =B16*(1-B18) -> 1645677.9 | C19: =C16*(1-C18) -> 1977040.9 | D19: =D16*(1-D18) -> 2317037.9 | E19: =E16*(1-E18) -> 2665384 | F19: =F16*(1-F18) -> 3008983.6 | G19: =G16*(1-G18) -> 3333005.2
A20: D&A / revenue | B20: =Assumptions!E16 -> 0.18 | C20: =Assumptions!$E$16 -> 0.18 | D20: =Assumptions!$E$16 -> 0.18 | E20: =Assumptions!$E$16 -> 0.18 | F20: =Assumptions!$E$16 -> 0.18 | G20: =Assumptions!$E$16 -> 0.18
A21: D&A | B21: =B8*B20 -> 685629.77 | C21: =C8*C20 -> 814528.17 | D21: =D8*D20 -> 949984.21 | E21: =E8*E20 -> 1087541.9 | F21: =F8*F20 -> 1221853.3 | G21: =G8*G20 -> 1346971.1
A22: Capex / revenue | B22: =IF(B8<>0,Historical!F13/B8,0) -> 0.33404893 | C22: =Assumptions!$E$17 -> 0.33 | D22: =Assumptions!$E$17+(Assumptions!$E$18-Assumptions!$E$17)*1/4 -> 0.315 | E22: =Assumptions!$E$17+(Assumptions!$E$18-Assumptions!$E$17)*2/4 -> 0.3 | F22: =Assumptions!$E$17+(Assumptions!$E$18-Assumptions!$E$17)*3/4 -> 0.285 | G22: =Assumptions!$E$17+(Assumptions!$E$18-Assumptions!$E$17)*4/4 -> 0.27
A23: Capital expenditure | B23: =Historical!F13 -> 1272410.5 | C23: =C8*C22 -> 1493301.6 | D23: =D8*D22 -> 1662472.4 | E23: =E8*E22 -> 1812569.9 | F23: =F8*F22 -> 1934601.1 | G23: =G8*G22 -> 2020456.7
A24: Change in NWC | B24: 0 | C24: =MAX(0,(C8-B8)*Assumptions!$E$19) -> 17902.555 | D24: =MAX(0,(D8-C8)*Assumptions!$E$19) -> 18813.338 | E24: =MAX(0,(E8-D8)*Assumptions!$E$19) -> 19105.238 | F24: =MAX(0,(F8-E8)*Assumptions!$E$19) -> 18654.365 | G24: =MAX(0,(G8-F8)*Assumptions!$E$19) -> 17377.47
A25: FCFF | B25: =B19+B21-B23-B24 -> 1058897.2 | C25: =C19+C21-C23-C24 -> 1280364.8 | D25: =D19+D21-D23-D24 -> 1585736.4 | E25: =E19+E21-E23-E24 -> 1921250.8 | F25: =F19+F21-F23-F24 -> 2277581.4 | G25: =G19+G21-G23-G24 -> 2642142.2
A26: Cash / liquidity | B26: 2767856.4 | C26: =$B$26 -> 2767856.4 | D26: =$B$26 -> 2767856.4 | E26: =$B$26 -> 2767856.4 | F26: =$B$26 -> 2767856.4 | G26: =$B$26 -> 2767856.4
A27: Interest-bearing debt | B27: 1032987.7 | C27: =$B$27 -> 1032987.7 | D27: =$B$27 -> 1032987.7 | E27: =$B$27 -> 1032987.7 | F27: =$B$27 -> 1032987.7 | G27: =$B$27 -> 1032987.7
A28: Diluted shares | B28: 25930.6 | C28: =$B$28 -> 25930.6 | D28: =$B$28 -> 25930.6 | E28: =$B$28 -> 25930.6 | F28: =$B$28 -> 25930.6 | G28: =$B$28 -> 25930.6

Sheet Valuation
A1: Discounted cash flow valuation
A2: TWD millions; DCF stays native through equity value. Final line converts to the USD traded security.
A4: Metric | B4: Year 1 | C4: Year 2 | D4: Year 3 | E4: Year 4 | F4: Year 5 | G4: Output
A5: FCFF | B5: =Forecast!C25 -> 1280364.8 | C5: =Forecast!D25 -> 1585736.4 | D5: =Forecast!E25 -> 1921250.8 | E5: =Forecast!F25 -> 2277581.4 | F5: =Forecast!G25 -> 2642142.2
A6: Discount factor | B6: =1/(1+Assumptions!$E$20)^1 -> 0.91743119 | C6: =1/(1+Assumptions!$E$20)^2 -> 0.84167999 | D6: =1/(1+Assumptions!$E$20)^3 -> 0.77218348 | E6: =1/(1+Assumptions!$E$20)^4 -> 0.70842521 | F6: =1/(1+Assumptions!$E$20)^5 -> 0.64993139
A7: PV of FCFF | B7: =B5*B6 -> 1174646.6 | C7: =C5*C6 -> 1334682.6 | D7: =D5*D6 -> 1483558.1 | E7: =E5*E6 -> 1613496.1 | F7: =F5*F6 -> 1717211.1
A9: Output | B9: Value
A10: PV explicit FCFF | B10: =SUM(B7:F7) -> 7323594.6
A11: Terminal value | B11: =IF(Assumptions!$E$20>Assumptions!$E$21,F5*(1+Assumptions!$E$21)/(Assumptions!$E$20-Assumptions!$E$21),0) -> 54956558
A12: PV terminal value | B12: =B11*F6 -> 35717992
A13: Enterprise value | B13: =B10+B12 -> 43041586
A14: Cash / liquidity | B14: =Forecast!B26 -> 2767856.4
A15: Interest-bearing debt | B15: =Forecast!B27 -> 1032987.7
A16: Equity value | B16: =B13+B14-B15 -> 44776455
A17: Diluted shares (mm) | B17: =Forecast!B28 -> 25930.6
A18: Implied TWD / ordinary share | B18: =IF(B17>0,B16/B17,0) -> 1726.7805
A19: FX conversion input | B19: =Assumptions!E22 -> 32.21
A20: Ordinary shares per traded security | B20: =Assumptions!E23 -> 5
A21: Implied USD / traded security | B21: =B18/Assumptions!$E$22*Assumptions!$E$23 -> 268.05038
A22: Current traded-security price (USD) | B22: =Assumptions!E24 -> 419.48
A23: Upside / (downside) | B23: =IF(B22>0,B21/B22-1,0) -> -0.36099367

Sheet Sensitivity
A1: DCF sensitivity — implied USD / traded security
A2: Dynamic per-share matrix; center is active WACC / terminal growth.
A4: Terminal growth / WACC | B4: =Assumptions!$E$20+-0.02 -> 0.07 | C4: =Assumptions!$E$20+-0.01 -> 0.08 | D4: =Assumptions!$E$20+0 -> 0.09 | E4: =Assumptions!$E$20+0.01 -> 0.1 | F4: =Assumptions!$E$20+0.02 -> 0.11
A5: =Assumptions!$E$21+-0.01 -> 0.03 | B5: =((Valuation!$B$5/(1+B$4)^1+Valuation!$C$5/(1+B$4)^2+Valuation!$D$5/(1+B$4)^3+Valuation!$E$5/(1+B$4)^4+Valuation!$F$5/(1+B$4)^5+IF(B$4>$A5,Valuation!$F$5*(1+$A5)/(B$4-$A5)/(1+B$4)^5,0)+Valuation!$B$14-Valuation!$B$15)/Valuation!$B$17)/Assumptions!$E$22*Assumptions!$E$23 -> 347.29774 | C5: =((Valuation!$B$5/(1+C$4)^1+Valuation!$C$5/(1+C$4)^2+Valuation!$D$5/(1+C$4)^3+Valuation!$E$5/(1+C$4)^4+Valuation!$F$5/(1+C$4)^5+IF(C$4>$A5,Valuation!$F$5*(1+$A5)/(C$4-$A5)/(1+C$4)^5,0)+Valuation!$B$14-Valuation!$B$15)/Valuation!$B$17)/Assumptions!$E$22*Assumptions!$E$23 -> 277.29196 | D5: =((Valuation!$B$5/(1+D$4)^1+Valuation!$C$5/(1+D$4)^2+Valuation!$D$5/(1+D$4)^3+Valuation!$E$5/(1+D$4)^4+Valuation!$F$5/(1+D$4)^5+IF(D$4>$A5,Valuation!$F$5*(1+$A5)/(D$4-$A5)/(1+D$4)^5,0)+Valuation!$B$14-Valuation!$B$15)/Valuation!$B$17)/Assumptions!$E$22*Assumptions!$E$23 -> 230.69994 | E5: =((Valuation!$B$5/(1+E$4)^1+Valuation!$C$5/(1+E$4)^2+Valuation!$D$5/(1+E$4)^3+Valuation!$E$5/(1+E$4)^4+Valuation!$F$5/(1+E$4)^5+IF(E$4>$A5,Valuation!$F$5*(1+$A5)/(E$4-$A5)/(1+E$4)^5,0)+Valuation!$B$14-Valuation!$B$15)/Valuation!$B$17)/Assumptions!$E$22*Assumptions!$E$23 -> 197.48407 | F5: =((Valuation!$B$5/(1+F$4)^1+Valuation!$C$5/(1+F$4)^2+Valuation!$D$5/(1+F$4)^3+Valuation!$E$5/(1+F$4)^4+Valuation!$F$5/(1+F$4)^5+IF(F$4>$A5,Valuation!$F$5*(1+$A5)/(F$4-$A5)/(1+F$4)^5,0)+Valuation!$B$14-Valuation!$B$15)/Valuation!$B$17)/Assumptions!$E$22*Assumptions!$E$23 -> 172.6257
A6: =Assumptions!$E$21+-0.005 -> 0.035 | B6: =((Valuation!$B$5/(1+B$4)^1+Valuation!$C$5/(1+B$4)^2+Valuation!$D$5/(1+B$4)^3+Valuation!$E$5/(1+B$4)^4+Valuation!$F$5/(1+B$4)^5+IF(B$4>$A6,Valuation!$F$5*(1+$A6)/(B$4-$A6)/(1+B$4)^5,0)+Valuation!$B$14-Valuation!$B$15)/Valuation!$B$17)/Assumptions!$E$22*Assumptions!$E$23 -> 390.39302 | C6: =((Valuation!$B$5/(1+C$4)^1+Valuation!$C$5/(1+C$4)^2+Valuation!$D$5/(1+C$4)^3+Valuation!$E$5/(1+C$4)^4+Valuation!$F$5/(1+C$4)^5+IF(C$4>$A6,Valuation!$F$5*(1+$A6)/(C$4-$A6)/(1+C$4)^5,0)+Valuation!$B$14-Valuation!$B$15)/Valuation!$B$17)/Assumptions!$E$22*Assumptions!$E$23 -> 303.12737 | D6: =((Valuation!$B$5/(1+D$4)^1+Valuation!$C$5/(1+D$4)^2+Valuation!$D$5/(1+D$4)^3+Valuation!$E$5/(1+D$4)^4+Valuation!$F$5/(1+D$4)^5+IF(D$4>$A6,Valuation!$F$5*(1+$A6)/(D$4-$A6)/(1+D$4)^5,0)+Valuation!$B$14-Valuation!$B$15)/Valuation!$B$17)/Assumptions!$E$22*Assumptions!$E$23 -> 247.67741 | E6: =((Valuation!$B$5/(1+E$4)^1+Valuation!$C$5/(1+E$4)^2+Valuation!$D$5/(1+E$4)^3+Valuation!$E$5/(1+E$4)^4+Valuation!$F$5/(1+E$4)^5+IF(E$4>$A6,Valuation!$F$5*(1+$A6)/(E$4-$A6)/(1+E$4)^5,0)+Valuation!$B$14-Valuation!$B$15)/Valuation!$B$17)/Assumptions!$E$22*Assumptions!$E$23 -> 209.35571 | F6: =((Valuation!$B$5/(1+F$4)^1+Valuation!$C$5/(1+F$4)^2+Valuation!$D$5/(1+F$4)^3+Valuation!$E$5/(1+F$4)^4+Valuation!$F$5/(1+F$4)^5+IF(F$4>$A6,Valuation!$F$5*(1+$A6)/(F$4-$A6)/(1+F$4)^5,0)+Valuation!$B$14-Valuation!$B$15)/Valuation!$B$17)/Assumptions!$E$22*Assumptions!$E$23 -> 181.30829
A7: =Assumptions!$E$21+0 -> 0.04 | B7: =((Valuation!$B$5/(1+B$4)^1+Valuation!$C$5/(1+B$4)^2+Valuation!$D$5/(1+B$4)^3+Valuation!$E$5/(1+B$4)^4+Valuation!$F$5/(1+B$4)^5+IF(B$4>$A7,Valuation!$F$5*(1+$A7)/(B$4-$A7)/(1+B$4)^5,0)+Valuation!$B$14-Valuation!$B$15)/Valuation!$B$17)/Assumptions!$E$22*Assumptions!$E$23 -> 447.8534 | C7: =((Valuation!$B$5/(1+C$4)^1+Valuation!$C$5/(1+C$4)^2+Valuation!$D$5/(1+C$4)^3+Valuation!$E$5/(1+C$4)^4+Valuation!$F$5/(1+C$4)^5+IF(C$4>$A7,Valuation!$F$5*(1+$A7)/(C$4-$A7)/(1+C$4)^5,0)+Valuation!$B$14-Valuation!$B$15)/Valuation!$B$17)/Assumptions!$E$22*Assumptions!$E$23 -> 335.42163 | D7: =((Valuation!$B$5/(1+D$4)^1+Valuation!$C$5/(1+D$4)^2+Valuation!$D$5/(1+D$4)^3+Valuation!$E$5/(1+D$4)^4+Valuation!$F$5/(1+D$4)^5+IF(D$4>$A7,Valuation!$F$5*(1+$A7)/(D$4-$A7)/(1+D$4)^5,0)+Valuation!$B$14-Valuation!$B$15)/Valuation!$B$17)/Assumptions!$E$22*Assumptions!$E$23 -> 268.05038 | E7: =((Valuation!$B$5/(1+E$4)^1+Valuation!$C$5/(1+E$4)^2+Valuation!$D$5/(1+E$4)^3+Valuation!$E$5/(1+E$4)^4+Valuation!$F$5/(1+E$4)^5+IF(E$4>$A7,Valuation!$F$5*(1+$A7)/(E$4-$A7)/(1+E$4)^5,0)+Valuation!$B$14-Valuation!$B$15)/Valuation!$B$17)/Assumptions!$E$22*Assumptions!$E$23 -> 223.20596 | F7: =((Valuation!$B$5/(1+F$4)^1+Valuation!$C$5/(1+F$4)^2+Valuation!$D$5/(1+F$4)^3+Valuation!$E$5/(1+F$4)^4+Valuation!$F$5/(1+F$4)^5+IF(F$4>$A7,Valuation!$F$5*(1+$A7)/(F$4-$A7)/(1+F$4)^5,0)+Valuation!$B$14-Valuation!$B$15)/Valuation!$B$17)/Assumptions!$E$22*Assumptions!$E$23 -> 191.23127
A8: =Assumptions!$E$21+0.005 -> 0.045 | B8: =((Valuation!$B$5/(1+B$4)^1+Valuation!$C$5/(1+B$4)^2+Valuation!$D$5/(1+B$4)^3+Valuation!$E$5/(1+B$4)^4+Valuation!$F$5/(1+B$4)^5+IF(B$4>$A8,Valuation!$F$5*(1+$A8)/(B$4-$A8)/(1+B$4)^5,0)+Valuation!$B$14-Valuation!$B$15)/Valuation!$B$17)/Assumptions!$E$22*Assumptions!$E$23 -> 528.29793 | C8: =((Valuation!$B$5/(1+C$4)^1+Valuation!$C$5/(1+C$4)^2+Valuation!$D$5/(1+C$4)^3+Valuation!$E$5/(1+C$4)^4+Valuation!$F$5/(1+C$4)^5+IF(C$4>$A8,Valuation!$F$5*(1+$A8)/(C$4-$A8)/(1+C$4)^5,0)+Valuation!$B$14-Valuation!$B$15)/Valuation!$B$17)/Assumptions!$E$22*Assumptions!$E$23 -> 376.94282 | D8: =((Valuation!$B$5/(1+D$4)^1+Valuation!$C$5/(1+D$4)^2+Valuation!$D$5/(1+D$4)^3+Valuation!$E$5/(1+D$4)^4+Valuation!$F$5/(1+D$4)^5+IF(D$4>$A8,Valuation!$F$5*(1+$A8)/(D$4-$A8)/(1+D$4)^5,0)+Valuation!$B$14-Valuation!$B$15)/Valuation!$B$17)/Assumptions!$E$22*Assumptions!$E$23 -> 292.95067 | E8: =((Valuation!$B$5/(1+E$4)^1+Valuation!$C$5/(1+E$4)^2+Valuation!$D$5/(1+E$4)^3+Valuation!$E$5/(1+E$4)^4+Valuation!$F$5/(1+E$4)^5+IF(E$4>$A8,Valuation!$F$5*(1+$A8)/(E$4-$A8)/(1+E$4)^5,0)+Valuation!$B$14-Valuation!$B$15)/Valuation!$B$17)/Assumptions!$E$22*Assumptions!$E$23 -> 239.57444 | F8: =((Valuation!$B$5/(1+F$4)^1+Valuation!$C$5/(1+F$4)^2+Valuation!$D$5/(1+F$4)^3+Valuation!$E$5/(1+F$4)^4+Valuation!$F$5/(1+F$4)^5+IF(F$4>$A8,Valuation!$F$5*(1+$A8)/(F$4-$A8)/(1+F$4)^5,0)+Valuation!$B$14-Valuation!$B$15)/Valuation!$B$17)/Assumptions!$E$22*Assumptions!$E$23 -> 202.68085
A9: =Assumptions!$E$21+0.01 -> 0.05 | B9: =((Valuation!$B$5/(1+B$4)^1+Valuation!$C$5/(1+B$4)^2+Valuation!$D$5/(1+B$4)^3+Valuation!$E$5/(1+B$4)^4+Valuation!$F$5/(1+B$4)^5+IF(B$4>$A9,Valuation!$F$5*(1+$A9)/(B$4-$A9)/(1+B$4)^5,0)+Valuation!$B$14-Valuation!$B$15)/Valuation!$B$17)/Assumptions!$E$22*Assumptions!$E$23 -> 648.96473 | C9: =((Valuation!$B$5/(1+C$4)^1+Valuation!$C$5/(1+C$4)^2+Valuation!$D$5/(1+C$4)^3+Valuation!$E$5/(1+C$4)^4+Valuation!$F$5/(1+C$4)^5+IF(C$4>$A9,Valuation!$F$5*(1+$A9)/(C$4-$A9)/(1+C$4)^5,0)+Valuation!$B$14-Valuation!$B$15)/Valuation!$B$17)/Assumptions!$E$22*Assumptions!$E$23 -> 432.30442 | D9: =((Valuation!$B$5/(1+D$4)^1+Valuation!$C$5/(1+D$4)^2+Valuation!$D$5/(1+D$4)^3+Valuation!$E$5/(1+D$4)^4+Valuation!$F$5/(1+D$4)^5+IF(D$4>$A9,Valuation!$F$5*(1+$A9)/(D$4-$A9)/(1+D$4)^5,0)+Valuation!$B$14-Valuation!$B$15)/Valuation!$B$17)/Assumptions!$E$22*Assumptions!$E$23 -> 324.07603 | E9: =((Valuation!$B$5/(1+E$4)^1+Valuation!$C$5/(1+E$4)^2+Valuation!$D$5/(1+E$4)^3+Valuation!$E$5/(1+E$4)^4+Valuation!$F$5/(1+E$4)^5+IF(E$4>$A9,Valuation!$F$5*(1+$A9)/(E$4-$A9)/(1+E$4)^5,0)+Valuation!$B$14-Valuation!$B$15)/Valuation!$B$17)/Assumptions!$E$22*Assumptions!$E$23 -> 259.21661 | F9: =((Valuation!$B$5/(1+F$4)^1+Valuation!$C$5/(1+F$4)^2+Valuation!$D$5/(1+F$4)^3+Valuation!$E$5/(1+F$4)^4+Valuation!$F$5/(1+F$4)^5+IF(F$4>$A9,Valuation!$F$5*(1+$A9)/(F$4-$A9)/(1+F$4)^5,0)+Valuation!$B$14-Valuation!$B$15)/Valuation!$B$17)/Assumptions!$E$22*Assumptions!$E$23 -> 216.03869

Sheet Checks
A1: Formula-driven model checks
A2: Critical checks must pass after native recalculation/reopen; source coverage is computed, never hardcoded.
A4: Assertion | B4: Actual | C4: Expected | D4: Difference | E4: Tolerance | F4: Status | G4: Severity | H4: Fix hint
A5: Source records verified | B5: =COUNTIF(Sources!$Q$5:$Q$107,"VERIFIED") -> 103 | C5: =COUNTA(Sources!$A$5:$A$107) -> 103 | D5: =B5-C5 -> 0 | E5: 0 | F5: =IF(AND(D5=0,C5>0),"PASS","FAIL") -> PASS | G5: Critical | H5: Complete missing ledger rows
A6: Historical source coverage | B6: =COUNTIF(Historical!$H$5:$H$20,"CHECK") -> 0 | C6: 0 | D6: =B6-C6 -> 0 | E6: 0 | F6: =IF(ABS(D6)<=E6,"PASS","FAIL") -> PASS | G6: Critical | H6: Resolve metric-to-source mapping
A7: Revenue driver tie | B7: =Forecast!G8 -> 7483172.9 | C7: =Forecast!G5*Forecast!G6 -> 7483172.9 | D7: =B7-C7 -> 0 | E7: 0.1 | F7: =IF(ABS(D7)<=E7,"PASS","FAIL") -> PASS | G7: Critical | H7: Repair bottom-up formula
A8: Operating income tie | B8: =Forecast!G16 -> 3921182.6 | C8: =Forecast!G11-Forecast!G13-Forecast!G15 -> 3921182.6 | D8: =B8-C8 -> 0 | E8: 0.1 | F8: =IF(ABS(D8)<=E8,"PASS","FAIL") -> PASS | G8: Critical | H8: Repair operating formula
A9: FCFF tie | B9: =Forecast!G25 -> 2642142.2 | C9: =Forecast!G19+Forecast!G21-Forecast!G23-Forecast!G24 -> 2642142.2 | D9: =B9-C9 -> 0 | E9: 0.1 | F9: =IF(ABS(D9)<=E9,"PASS","FAIL") -> PASS | G9: Critical | H9: Repair FCFF formula
A10: WACC exceeds terminal growth | B10: =Assumptions!E20 -> 0.09 | C10: =Assumptions!E21 -> 0.04 | D10: =B10-C10 -> 0.05 | E10: 0 | F10: =IF(D10>E10,"PASS","FAIL") -> PASS | G10: Critical | H10: Adjust WACC / g
A11: Valuation bridge | B11: =Valuation!B16 -> 44776455 | C11: =Valuation!B13+Valuation!B14-Valuation!B15 -> 44776455 | D11: =B11-C11 -> 0 | E11: 0.1 | F11: =IF(ABS(D11)<=E11,"PASS","FAIL") -> PASS | G11: Critical | H11: Repair bridge
A12: Sensitivity center tie | B12: =Sensitivity!D7 -> 268.05038 | C12: =Valuation!B21 -> 268.05038 | D12: =B12-C12 -> 0 | E12: 0.1 | F12: =IF(ABS(D12)<=E12,"PASS","FAIL") -> PASS | G12: Critical | H12: Repair matrix
A13: Scenario selector valid | B13: =Assumptions!B3 -> 1 | C13: 1 | D13: =IF(OR(B13=1,B13=2,B13=3),0,1) -> 0 | E13: 0 | F13: =IF(D13=0,"PASS","FAIL") -> PASS | G13: Critical | H13: Reset 1/2/3
A14: Forecast revenue non-negative | B14: =MIN(Forecast!C8:G8) -> 4525156.5 | C14: 0 | D14: =B14-C14 -> 4525156.5 | E14: 0 | F14: =IF(D14>=0,"PASS","FAIL") -> PASS | G14: Critical | H14: Review drivers
A15: Cash and debt non-negative | B15: =MIN(Forecast!B26:G27) -> 1032987.7 | C15: 0 | D15: =B15-C15 -> 1032987.7 | E15: 0 | F15: =IF(D15>=0,"PASS","FAIL") -> PASS | G15: Critical | H15: Review balances
A16: Traded-security price positive | B16: =Valuation!B21 -> 268.05038 | C16: 0 | D16: =B16-C16 -> 268.05038 | E16: 0 | F16: =IF(D16>0,"PASS","FAIL") -> PASS | G16: Critical | H16: Review FX / ADR bridge
A17: Semantic KPI links | B17: 8 | C17: 8 | D17: =B17-C17 -> 0 | E17: 0 | F17: =IF(AND(ABS(Sector_KPIs!D5-Forecast!G5)<0.1,ISTEXT(Sector_KPIs!D6),ABS(Sector_KPIs!D7-Forecast!G7)<0.000001,ISTEXT(Sector_KPIs!D8),ABS(Sector_KPIs!D9-Forecast!G6)<0.1,ABS(Sector_KPIs!D10-Forecast!G10)<0.000001,ABS(Sector_KPIs!D11-Forecast!G12)<0.000001,ISTEXT(Sector_KPIs!D12)),"PASS","FAIL") -> PASS | G17: Critical | H17: Repair company-specific KPI links
A18: KPI unit / range sanity | B18: =1 -> 1 | C18: =1 -> 1 | D18: =B18-C18 -> 0 | E18: 0 | F18: =IF(AND(Sector_KPIs!B5>0,Sector_KPIs!B6>0,Sector_KPIs!B7>=0,Sector_KPIs!B7<=1,Sector_KPIs!B8>=0,Sector_KPIs!B8<=1,Sector_KPIs!B9>10000,Sector_KPIs!B9<1000000,Sector_KPIs!B10>=0,Sector_KPIs!B10<=1,Sector_KPIs!B11>=0,Sector_KPIs!B11<=1,Sector_KPIs!B12=1,Sector_KPIs!D5>0,Sector_KPIs!D7>=0,Sector_KPIs!D7<=1,Sector_KPIs!D9>10000,Sector_KPIs!D9<1000000,Sector_KPIs!D10>=0,Sector_KPIs!D10<=1,Sector_KPIs!D11>=0,Sector_KPIs!D11<=1),"PASS","FAIL") -> PASS | G18: Critical | H18: Repair units or economic ranges
A19: Source target-cell link coverage | B19: =COUNTA(Sources!$L$5:$L$107) -> 103 | C19: =COUNTA(Sources!$A$5:$A$107) -> 103 | D19: =B19-C19 -> 0 | E19: 0 | F19: =IF(ABS(D19)<=E19,"PASS","FAIL") -> PASS | G19: Critical | H19: Add exact sheet-and-cell targets
A20: Source unit completeness | B20: =COUNTBLANK(Sources!$E$5:$E$107) -> 0 | C20: 0 | D20: =B20-C20 -> 0 | E20: 0 | F20: =IF(ABS(D20)<=E20,"PASS","FAIL") -> PASS | G20: Critical | H20: Populate source units
A21: Exact source URL completeness | B21: =COUNTA(Sources!$N$5:$N$107) -> 103 | C21: =COUNTA(Sources!$A$5:$A$107) -> 103 | D21: =B21-C21 -> 0 | E21: 0 | F21: =IF(ABS(D21)<=E21,"PASS","FAIL") -> PASS | G21: Critical | H21: Use exact primary-source URLs
A23: Overall gate | B23: =IF(COUNTIF(F5:F21,"FAIL")=0,"PASS","FAIL") -> PASS
A24: Decision use | B24: Owner-ready only after independent review

Sheet Sector_KPIs
A1: Semiconductor operating KPI framework
A2: Reported sector drivers plus formula-linked active outputs; no generic blanks.
A4: KPI | B4: Reported latest | C4: Unit | D4: Forecast / active output | E4: Source / method | F4: Status
A5: Wafer shipments | B5: 15 | C5: m 12-inch equivalent | D5: =Forecast!G5 -> 22.030474 | E5: Official FY2025 annual report | F5: =IF(COUNTIF(Sources!$L$5:$L$107,"Sector_KPIs!B5")>=1,"VERIFIED","CHECK") -> VERIFIED
A6: Annual capacity | B6: 17 | C6: m 12-inch equivalent | D6: ="Context only / reported capacity" -> Context only / reported capacity | E6: Official FY2025 annual report; more than 17m | F6: =IF(COUNTIF(Sources!$L$5:$L$107,"Sector_KPIs!B6")>=1,"VERIFIED","CHECK") -> VERIFIED
A7: Advanced technologies mix | B7: 0.74 | C7: % wafer revenue | D7: =Forecast!G7 -> 0.8775 | E7: 7nm and below | F7: =IF(COUNTIF(Sources!$L$5:$L$107,"Sector_KPIs!B7")>=1,"VERIFIED","CHECK") -> VERIFIED
A8: 3nm mix | B8: 0.24 | C8: % wafer revenue | D8: ="Context only / reported node mix" -> Context only / reported node mix | E8: Official FY2025 annual report | F8: =IF(COUNTIF(Sources!$L$5:$L$107,"Sector_KPIs!B8")>=1,"VERIFIED","CHECK") -> VERIFIED
A9: Blended revenue / wafer | B9: =IF(B5<>0,Historical!F5/B5,0) -> 253936.95 | C9: TWD / wafer | D9: =Forecast!G6 -> 339673.72 | E9: Formula-derived: TWDm revenue divided by million wafers | F9: =IF(COUNTIF(Sources!$L$5:$L$107,"Sector_KPIs!B9")>=1,"VERIFIED","CHECK") -> VERIFIED
A10: Gross margin | B10: =Historical!F8 -> 0.59891349 | C10: % | D10: =Forecast!G10 -> 0.615 | E10: SEC FY2025 20-F / formula-derived | F10: =IF(COUNTIF(Sources!$L$5:$L$107,"Sector_KPIs!B10")>=1,"VERIFIED","CHECK") -> VERIFIED
A11: R&D intensity | B11: =IF(Historical!F5<>0,Historical!F14/Historical!F5,0) -> 0.064695113 | C11: % | D11: =Forecast!G12 -> 0.065 | E11: SEC FY2025 20-F / formula-derived | F11: =IF(COUNTIF(Sources!$L$5:$L$107,"Sector_KPIs!B11")>=1,"VERIFIED","CHECK") -> VERIFIED
A12: 2nm high-volume manufacturing | B12: 1 | C12: milestone | D12: ="Context only / reported milestone" -> Context only / reported milestone | E12: Q4 FY2025 commencement | F12: =IF(COUNTIF(Sources!$L$5:$L$107,"Sector_KPIs!B12")>=1,"VERIFIED","CHECK") -> VERIFIED

Sheet Change_Log
A1: Change log and governance
A2: Controlled rebuild; prior workbook preserved unchanged.
A4: Date | B4: Version | C4: Author | D4: Change | E4: Evidence | F4: Reviewer status | G4: Disposition
A5: 2026-07-16 | B5: 2.0 | C5: Codex | D5: Preserved prior ten sheets; appended Gate_9of10 | E5: Prior SHA-256 dbde913bb4c66e4f95db6e558a5f2d365555e8274a0e46127715a0ba22f5e655 | F5: Builder verified | G5: No overwrite
A6: 2026-07-16 | B6: 2.0 | C6: Codex | D6: Native-currency exact-source history | E6: Sources + Historical | F6: Builder verified | G6: Independent review pending
A7: 2026-07-16 | B7: 2.0 | C7: Codex | D7: Company-specific forecast, DCF, sensitivity and checks | E7: Forecast + Valuation + Checks | F7: Builder verified | G7: Independent review pending
A8: 2026-07-16 | B8: 2.0 | C8: Codex | D8: Native recalc/reopen and full-sheet QA | E8: internal QA evidence (not published) | F8: Post-LO evidence | G8: Independent review pending
A9: 2026-07-16 | B9: 2.1 | C9: Codex | D9: Repaired KPI semantics, exact source targets, unit/range/link gates and TSMC H1/H2/H5 | E9: Sector_KPIs + Sources + Checks + Gate_9of10 | F9: High-effort repair; independent review pending | G9: Frozen only after native recalc and hash-bound QA
A11: 46224 | B11: Ola 2 IG elevation: added IS_Hist/BS_Hist/CF_Hist/USD_Hist (TWD native, FY2021A-FY2025A; full line detail FY2023-25 or FY2024-25 per 20-F R-files, summary aggregates FY2021-22/23 per companyfacts.json, gaps documented not estimated), Sources_Audited (real claim ledger), Checks_TieOut (26 real cross-checks against independently entered source constants, replacing self-referential label-lookup checks), Forecast_v2 (5yr driver-built Base/Bull/Bear off FY2025A). Legacy Checks/Sources/Gate_9of10/Forecast/Historical/Valuation left unmodified (no check weakened, no sheet deleted). Root workbook untouched; built via Mog SDK only. | C11: Claude (run 24e4a1f1)
A13: 46248 | B13: 2.2-cobertura | C13: Claude Opus 5 (capa de cobertura, Ola 1 de la flota internacional) | D13: Capa de cobertura 2026-08-14, patron del piloto Apple (post-refutacion): se agregaron las hojas Drivers_MDA (drivers del MD&A del Form 20-F FY2021A-FY2025A: ingresos por plataforma, geografia y producto con ties duros al IS auditado; wafer revenue por nodo en absolutos con tie al wafer revenue; embarques, capacidad y utilizacion implicita; concentracion de clientes; FX promedio; empleados; capex y expansion global Arizona/Kumamoto/Dresde; bloque geopolitico cualitativo; NOT_AVAILABLE declarados; puente a Forecast_v2) y Market_Package (precio ADS, acciones, market cap, spot TWD/USD, puente a EV, Rf/ERP/beta/Kd/tasa efectiva, WACC fechado, multiplos FY2025A, control de procedencia mecanizado, hallazgos H1-H4 y limitaciones L1-L6). 17 tie-outs nuevos en Checks_TieOut (filas 29-45) + conteo mecanizado en B3; el rango del gate maestro B2 paso de H5:H27 a H5:H45 (endurece, no debilita). UNICA celda preexistente modificada: Checks_TieOut!B2. Ninguna hoja historica ni el DCF fueron tocados; hallazgos declarados, no corregidos. Construido solo con Mog SDK. | E13: SHA-256 previo 3f12d5027a534e51f36614ca43079082b83495893e2900cfd7baddc6dbe8f18b; respaldo pre-cobertura en scratchpad de la corrida. Fuentes: 20-F FY2022 accn 0001193125-23-107214, FY2023 accn 0001193125-24-099840, FY2024 accn 0001193125-25-083423, FY2025 accn 0001628280-26-025362 (PDFs locales tsmc/, pdftotext -layout); mercado: stockanalysis.com, tradingeconomics.com, treasury.gov, Damodaran -- cada input fechado en Market_Package col D. | F13: Builder verificado; refutacion independiente pendiente | G13: Aditivo. Los 23 checks originales quedan intactos y en PASS; master ampliado a 40 checks

Sheet Gate_9of10
A1: 9-of-10 gate evidence
A2: Owner evidence register aligned exactly to the governing independent rubric; PASS means ready for review, not self-certification.
A4: Gate | B4: Weight | C4: Earned | D4: Status | E4: Exact workbook / external evidence | F4: Blocker class | G4: Notes
A5: H0 Controlled lineage / package | B5: 5 | C5: =IF(D5="PASS",B5,0) -> 5 | D5: PASS | E5: Change_Log!A5:G5; internal QA evidence (not published) | F5: Lineage | G5: Prior file preserved; 10-sheet order + Gate_9of10
A6: H1 Source fidelity | B6: 20 | C6: =IF(D6="PASS",B6,0) -> 20 | D6: =IF(AND(Checks!F5="PASS",Checks!F6="PASS",COUNTIF(Checks!F19:F21,"FAIL")=0),"PASS","FAIL") -> PASS | E6: Sources!A4:R; Checks!A5:F6; Checks!A19:F21 | F6: Source | G6: Claim-level exact-source ledger
A7: H2 Historical / formula / schedule mechanics | B7: 15 | C7: =IF(D7="PASS",B7,0) -> 15 | D7: =IF(AND(COUNTIF(Historical!H5:H20,"CHECK")=0,COUNTIF(Checks!F7:F9,"FAIL")=0,Checks!F17="PASS",Checks!F18="PASS"),"PASS","FAIL") -> PASS | E7: Historical!A4:H20; Forecast!A5:G28; Sector_KPIs!A4:F12; Checks!A7:F9; Checks!A17:F18 | F7: Mechanics | G7: Native history and formula-driven operating schedule
A8: H3 Scenario / sensitivity | B8: 10 | C8: =IF(D8="PASS",B8,0) -> 10 | D8: =IF(AND(Checks!F12="PASS",Checks!F13="PASS"),"PASS","FAIL") -> PASS | E8: Assumptions!B3:E24; Sensitivity!A4:F9; Checks!A12:F13 | F8: Scenario | G8: B/B/B perturb-reset evidence in support JSON
A9: H4 Valuation fit / mechanics | B9: 15 | C9: =IF(D9="PASS",B9,0) -> 15 | D9: =IF(AND(Checks!F10="PASS",Checks!F11="PASS",Checks!F12="PASS",Valuation!B21>0),"PASS","FAIL") -> PASS | E9: Valuation!A4:G23; Checks!A10:F12 | F9: Valuation | G9: Native-currency DCF and dated security bridge
A10: H5 Checks / error state | B10: 8 | C10: =IF(D10="PASS",B10,0) -> 8 | D10: =IF(Checks!B23="PASS","PASS","FAIL") -> PASS | E10: Checks!A4:H23; internal QA evidence (not published) | F10: Checks | G10: All critical checks and post-recalc error scan
A11: H6 Native recalc / reproducibility | B11: 10 | C11: =IF(D11="PASS",B11,0) -> 10 | D11: PASS | E11: internal QA evidence (not published) | native LibreOffice x2 + reopen | F11: Recalc | G11: Two unique LibreOffice profiles; evidence bound to final SHA-256
A12: H7 Post-recalc visual QA | B12: 7 | C12: =IF(D12="PASS",B12,0) -> 7 | D12: PASS | E12: internal QA evidence (not published) | F12: Visual | G12: Every final sheet rendered and reviewed
A13: H8 Economic upgrade | B13: 5 | C13: =IF(D13="PASS",B13,0) -> 5 | D13: =IF(AND(Forecast!G8>0,COUNTIF(Sector_KPIs!F5:F12,"VERIFIED")=8,Checks!F17="PASS",Checks!F18="PASS"),"PASS","FAIL") -> PASS | E13: Forecast!A5:G28; Sector_KPIs!A4:F | F13: Economics | G13: Company-specific semiconductor operating build
A14: H9 Governance / handoff | B14: 5 | C14: =IF(D14="PASS",B14,0) -> 5 | D14: PASS | E14: 00_Cover!A14:B18; Change_Log!A4:G8; Gate_9of10!A16:B18 | F14: Governance | G14: Independent certification remains pending
A16: Owner score | B16: =SUM(C5:C14) -> 100
A17: Decision | B17: =IF(AND(B16>=90,COUNTIF(D5:D14,"FAIL")=0),"READY FOR INDEPENDENT 9/10 REVIEW","OWNER DEMOTION / REMEDIATE") -> READY FOR INDEPENDENT 9/10 REVIEW
A18: Independent certification | B18: PENDING

Sheet IS_Hist
A1: TSMC -- Consolidated Statements of Profit or Loss (audited, IFRS)
A2: TWD millions. FY2023A-FY2025A per FY2025 20-F R4 (full line detail). FY2021A-FY2022A per SEC EDGAR companyfacts.json ifrs-full tags (as originally reported comparative figures) -- opex/non-op detail for those two years not in this package, left blank rather than estimated.
A4: Line item | B4: FY2021A | C4: FY2022A | D4: FY2023A | E4: FY2024A | F4: FY2025A | H4: Note/Tag ref
A5: Net revenue | B5: 1587415 | C5: 2263891.3 | D5: 2161735.8 | E5: 2894307.7 | F5: 3809054.3 | H5: R4 / ifrs-full:Revenue
A6: Cost of revenue | B6: 767877.7 | C6: 915536.5 | D6: 986625.2 | E6: 1269954.1 | F6: 1527760.3 | H6: R4 / ifrs-full:CostOfSales
A7: Gross profit | B7: 819537.3 | C7: 1348354.8 | D7: 1175110.6 | E7: 1624353.6 | F7: 2281294 | H7: R4 / ifrs-full:GrossProfit
A8: Operating expenses
A9: Research and development | D9: 182370.2 | E9: 204181.8 | F9: 246427.2 | H9: R4 (FY23-25 only)
A10: General and administrative | D10: 60872.8 | E10: 83745 | F10: 82304.3 | H10: R4 (FY23-25 only)
A11: Marketing | D11: 10590.7 | E11: 13143.6 | F11: 16918.1 | H11: R4 (FY23-25 only)
A12: Total operating expenses | D12: 253833.7 | E12: 301070.4 | F12: 345649.6 | H12: R4 (FY23-25 only)
A13: Other operating income and expenses, net | D13: 188.7 | E13: -1230.2 | F13: 447.3 | H13: R4 (FY23-25 only)
A14: Income from operations | D14: 921465.6 | E14: 1322053 | F14: 1936091.7 | H14: R4 (FY23-25 only; FY21-22 not separately disclosed in companyfacts)
A15: Non-operating income and expenses
A16: Share of profits of associates | D16: 4800.2 | E16: 4880.7 | F16: 5488.5 | H16: R4 (FY23-25 only)
A17: Interest income | D17: 60293.9 | E17: 87213.4 | F17: 105739.1 | H17: R4 (FY23-25 only)
A18: Other income | D18: 480 | E18: 566.9 | F18: 591.7 | H18: R4 (FY23-25 only)
A19: Foreign exchange gain (loss), net | D19: -2685.4 | E19: 10000.8 | F19: 13831.3 | H19: R4 (FY23-25 only)
A20: Finance costs | D20: -11999.4 | E20: -10495.4 | F20: -12370.4 | H20: R4 (FY23-25 only)
A21: Other gains and losses, net | D21: 6961.6 | E21: -8379.4 | F21: -7717.2 | H21: R4 (FY23-25 only)
A22: Total non-operating income and expenses | D22: 57850.9 | E22: 83787 | F22: 105563 | H22: R4 (FY23-25 only)
A23: Income before income tax | B23: 663036 | C23: 1144072.2 | D23: 979316.5 | E23: 1405840 | F23: 2041654.7 | H23: R4 / ifrs-full:ProfitLossBeforeTax
A24: Income tax expense | B24: 70155.4 | C24: 150777.5 | D24: 128288.8 | E24: 248316.1 | F24: 346529.8 | H24: R4 / ifrs-full:IncomeTaxExpenseContinuingOperations
A25: Net income | B25: 592880.6 | C25: 993294.7 | D25: 851027.7 | E25: 1157523.9 | F25: 1695124.9 | H25: R4 / ifrs-full:ProfitLoss
A26: Net income attributable to:
A27: Owners of the parent (EPS numerator) | D27: 851740 | E27: 1158380.2 | F27: 1697604 | H27: R139 EPS Details (FY23-25 only)
A28: Non-controlling interests | D28: -712.3 | E28: -856.3 | F28: -2479.1 | H28: derived: NI - parent (FY23-25 only)
A30: Earnings per share - basic (TWD) | D30: 32.85 | E30: 44.68 | F30: 65.47 | H30: R139
A31: Earnings per share - diluted (TWD) | D31: 32.85 | E31: 44.67 | F31: 65.47 | H31: R139

Sheet BS_Hist
A1: TSMC -- Consolidated Statements of Financial Position (audited, IFRS)
A2: TWD millions, as of Dec 31. FY2024A-FY2025A per FY2025 20-F R3 (full line detail). FY2021A-FY2023A summary aggregates only per companyfacts.json.
A4: Line item | B4: FY2021A | C4: FY2022A | D4: FY2023A | E4: FY2024A | F4: FY2025A | H4: Note/Tag ref
A5: CURRENT ASSETS
A6: Cash and cash equivalents | B6: 1064990.2 | C6: 1342814.1 | D6: 1465427.8 | E6: 2127627 | F6: 2767856.4 | H6: R3 (FY24-25) / ifrs-full:CashAndCashEquivalents (FY21-23)
A7: Financial assets at FVTPL | E7: 207.7 | F7: 100.2 | H7: R3 (FY24-25 only)
A8: Financial assets at FVOCI | E8: 192202.7 | F8: 175692.7 | H8: R3 (FY24-25 only)
A9: Financial assets at amortized cost | E9: 101971.3 | F9: 124945.5 | H9: R3 (FY24-25 only)
A10: Hedging financial assets | E10: 11 | F10: 0 | H10: R3 (FY24-25 only)
A11: Notes and accounts receivable, net | E11: 270683.2 | F11: 279051.6 | H11: R3 (FY24-25 only)
A12: Receivables from related parties | E12: 1404.5 | F12: 2739.5 | H12: R3 (FY24-25 only)
A13: Other receivables from related parties | E13: 0.2 | F13: 268.1 | H13: R3 (FY24-25 only)
A14: Inventories | B14: 193102.3 | C14: 221149.1 | D14: 250997.1 | E14: 287868.8 | F14: 288109.5 | H14: R3 (FY24-25) / ifrs-full:Inventories (FY21-23)
A15: Other financial assets | E15: 63138.3 | F15: 59702.9 | H15: R3 (FY24-25 only)
A16: Other current assets | E16: 43237.4 | F16: 118664.4 | H16: R3 (FY24-25 only)
A17: Total current assets | B17: 1607072.9 | C17: 2052896.7 | D17: 2194032.9 | E17: 3088352.1 | F17: 3817130.8 | H17: R3 (FY24-25) / ifrs-full:CurrentAssets (FY21-23)
A18: NONCURRENT ASSETS
A19: Financial assets at FVTPL (noncurrent) | E19: 15199.8 | F19: 15032.1 | H19: R3 (FY24-25 only)
A20: Financial assets at FVOCI (noncurrent) | E20: 7822.9 | F20: 8797.2 | H20: R3 (FY24-25 only)
A21: Financial assets at amortized cost (noncurrent) | E21: 88596.5 | F21: 110507.8 | H21: R3 (FY24-25 only)
A22: Investments accounted for using equity method | E22: 37247.8 | F22: 37851.9 | H22: R3 (FY24-25 only)
A23: Property, plant and equipment | B23: 1975118.7 | C23: 2693837 | D23: 3064475 | E23: 3234980.1 | F23: 3691840.9 | H23: R3 (FY24-25) / ifrs-full:PropertyPlantAndEquipment (FY21-23)
A24: Right-of-use assets | E24: 40128.4 | F24: 43918.9 | H24: R3 (FY24-25 only)
A25: Intangible assets | E25: 26282.5 | F25: 24952.6 | H25: R3 (FY24-25 only)
A26: Deferred income tax assets | E26: 65943.3 | F26: 62940.3 | H26: R3 (FY24-25 only)
A27: Refundable deposits | E27: 5495.9 | F27: 4242.6 | H27: R3 (FY24-25 only)
A28: Other noncurrent assets | E28: 81715.4 | F28: 115627.4 | H28: R3 (FY24-25 only)
A29: Total noncurrent assets | B29: 2118229.3 | C29: 2911562.4 | D29: 3338163.7 | E29: 3603412.6 | F29: 4115711.7 | H29: R3 (FY24-25) / ifrs-full:NoncurrentAssets (FY21-23)
A30: TOTAL ASSETS | B30: 3725302.2 | C30: 4964459.1 | D30: 5532196.6 | E30: 6691764.7 | F30: 7932842.5 | H30: R3 (FY24-25) / ifrs-full:Assets (FY21-23)
A32: CURRENT LIABILITIES
A33: Financial liabilities at FVTPL | E33: 466.5 | F33: 3083.9 | H33: R3 (FY24-25 only)
A34: Hedging financial liabilities | E34: 0 | F34: 0.8 | H34: R3 (FY24-25 only)
A35: Accounts payable | E35: 72800.6 | F35: 82551.6 | H35: R3 (FY24-25 only)
A36: Payables to related parties | E36: 1426 | F36: 1778.7 | H36: R3 (FY24-25 only)
A37: Salary and bonus payable | E37: 47451.5 | F37: 63872.9 | H37: R3 (FY24-25 only)
A38: Accrued profit sharing bonus to employees & directors | E38: 70871.2 | F38: 103355.3 | H38: R3 (FY24-25 only)
A39: Payables to contractors and equipment suppliers | E39: 192635.2 | F39: 177730.3 | H39: R3 (FY24-25 only)
A40: Cash dividends payable | E40: 220418.8 | F40: 285258.1 | H40: R3 (FY24-25 only)
A41: Income tax payable | E41: 191569.4 | F41: 266732.6 | H41: R3 (FY24-25 only)
A42: Long-term liabilities - current portion | E42: 59857.9 | F42: 136925.7 | H42: R3 (FY24-25 only)
...

Sheet CF_Hist
A1: TSMC -- Consolidated Statements of Cash Flows (audited, IFRS)
A2: TWD millions. FY2023A-FY2025A per FY2025 20-F R6 (line items netted into logical groups per line-item column H). FY2021A-FY2022A summary per companyfacts.json; FX effect for those years is an implied residual (documented).
A4: Line item | B4: FY2021A | C4: FY2022A | D4: FY2023A | E4: FY2024A | F4: FY2025A | H4: Note/Tag ref
A5: OPERATING ACTIVITIES
A6: Income before income tax | D6: 979316.5 | E6: 1405840 | F6: 2041654.7 | H6: R6 (FY23-25 only)
A7: Depreciation expense | D7: 522932.7 | E7: 653610.5 | F7: 679684 | H7: R6 (FY23-25 only)
A8: Amortization expense | D8: 9258.2 | E8: 9186.1 | F8: 8412.4 | H8: R6 (FY23-25 only)
A9: Other operating adjustments (net) | D9: -52813 | E9: -72170.3 | F9: -90466 | H9: R6 (FY23-25 only; ECL/finance costs/associates/interest income/SBC/disposal & impairment/FX/dividend income/other, netted)
A10: Changes in operating assets and liabilities (net) | D10: -56852 | E10: 13350.9 | F10: -96752 | H10: R6 (FY23-25 only)
A11: Cash generated from operations | D11: 1401842.4 | E11: 2009817.2 | F11: 2542533.1 | H11: R6 (FY23-25 only)
A12: Income taxes paid | D12: -159875.1 | E12: -183640.1 | F12: -267557.5 | H12: R6 (FY23-25 only)
A13: Net cash generated by operating activities | B13: 1112160.7 | C13: 1610599.2 | D13: 1241967.3 | E13: 1826177.1 | F13: 2274975.6 | H13: R6 (FY23-25) / ifrs-full:CashFlowsFromUsedInOperatingActivities (FY21-22)
A14: INVESTING ACTIVITIES
A15: Acquisitions of property, plant and equipment | D15: -949816.8 | E15: -956006.5 | F15: -1272410.5 | H15: R6 (FY23-25 only)
A16: Acquisitions of intangible assets | D16: -5518.4 | E16: -8875.7 | F16: -10146.9 | H16: R6 (FY23-25 only)
A17: Acquisitions of financial instruments (FVTPL/FVOCI/amortized cost/hedging) | D17: -226282 | E17: -244361.5 | F17: -256003.5 | H17: R6 (FY23-25 only)
A18: Proceeds from disposal/redemption of financial instruments | D18: 170304.4 | E18: 186035.4 | F18: 218256 | H18: R6 (FY23-25 only)
A19: Proceeds from disposal of PP&E / intangible assets | D19: 707 | E19: 951.8 | F19: 797 | H19: R6 (FY23-25 only)
A20: Interest received | D20: 55887.2 | E20: 76434.1 | F20: 98954.7 | H20: R6 (FY23-25 only)
A21: Proceeds from government grants | D21: 47545.9 | E21: 75164.3 | F21: 76258.8 | H21: R6 (FY23-25 only)
A22: Dividends received (other + equity-method) | D22: 3521.6 | E22: 3507 | F22: 3939.6 | H22: R6 (FY23-25 only)
A23: Other investing activities (net) | D23: -2469.5 | E23: 2308.3 | F23: -4038.6 | H23: R6 (FY23-25 only; refundable deposits, derivative de-recognition, other)
A24: Net cash used in investing activities | B24: -836365.8 | C24: -1190928.3 | D24: -906120.6 | E24: -864842.8 | F24: -1144393.4 | H24: R6 (FY23-25) / ifrs-full:CashFlowsFromUsedInInvestingActivities (FY21-22)
A25: FINANCING ACTIVITIES
A26: Proceeds from issuance of bonds | D26: 85700 | E26: 34300 | F26: 86900 | H26: R6 (FY23-25 only)
A27: Repayment of bonds | D27: -18100 | E27: -7000 | F27: -54310 | H27: R6 (FY23-25 only)
A28: Proceeds from long-term bank loans | D28: 2450 | E28: 30897 | F28: 10658.4 | H28: R6 (FY23-25 only)
A29: Repayment of long-term bank loans | D29: -1756.9 | E29: -2295.6 | F29: -2710 | H29: R6 (FY23-25 only)
A30: Interest paid | D30: -17359 | E30: -18751.2 | F30: -19128.8 | H30: R6 (FY23-25 only)
A31: Cash dividends paid | D31: -291721.9 | E31: -363055.2 | F31: -466779.2 | H31: R6 (FY23-25 only)
A32: Increase in non-controlling interests | D32: 11048.8 | E32: 12177.6 | F32: 8295.4 | H32: R6 (FY23-25 only)
A33: Other financing activities (net) | D33: 24844.8 | E33: -32574.6 | F33: -3270.4 | H33: R6 (FY23-25 only; hedging bank-loan liabilities, transaction costs, treasury stock, leases, guarantee deposits, donations; FY2024 carries a TWD 1.0mm source-rounding residual vs the published total)
A34: Net cash used in financing activities | B34: 136608.5 | C34: -200244 | D34: -204894.2 | E34: -346301 | F34: -440344.6 | H34: R6 (FY23-25) / ifrs-full:CashFlowsFromUsedInFinancingActivities (FY21-22)
A35: Effect of exchange rate changes on cash | B35: -7583.8 | C35: 58397 | D35: -8338.8 | E35: 47165.9 | F35: -50008.2 | H35: R6 (FY23-25 only); FY21-22 = implied residual, not separately published
A36: Net increase (decrease) in cash | B36: 404819.6 | C36: 277823.9 | D36: 122613.7 | E36: 662199.2 | F36: 640229.4 | H36: R6 (FY23-25) / ifrs-full:IncreaseDecreaseInCashAndCashEquivalents (FY21-22)
A37: Cash and cash equivalents, beginning of year | B37: 660170.6 | C37: 1064990.2 | D37: 1342814.1 | E37: 1465427.8 | F37: 2127627 | H37: BS prior year / companyfacts
A38: Cash and cash equivalents, end of year | B38: 1064990.2 | C38: 1342814.1 | D38: 1465427.8 | E38: 2127627 | F38: 2767856.4 | H38: R6 (FY23-25) / ifrs-full:CashAndCashEquivalents

Sheet USD_Hist
A1: TSMC -- USD convenience translation (Note 9, FY2025A only)
A2: Source-documented USD amounts exist only for FY2025A (Note 9, "U.S. Dollar Amounts"); no independently sourced rate for FY2021A-FY2024A in this filing, so those columns are intentionally blank (not backed into from a modeled rate).
A4: Line item | B4: FY2021A | C4: FY2022A | D4: FY2023A | E4: FY2024A | F4: FY2025A | H4: Note/Tag ref
A5: Note 9 convenience translation rate (TWD per USD) | F5: 31.37 | H5: R4/R3/R6 Note 9 (implied from as-filed USD col)
A7: Net revenue (USD mm) | F7: 121423.5 | H7: R4 Note 9 column
A8: Gross profit (USD mm) | F8: 72722.2 | H8: R4 Note 9 column
A9: Income from operations (USD mm) | F9: 61717.9 | H9: R4 Note 9 column
A10: Net income (USD mm) | F10: 54036.5 | H10: R4 Note 9 column
A12: Total assets (USD mm) | F12: 252879.9 | H12: R3 Note 9 column
A13: Total liabilities (USD mm) | F13: 80861.4 | H13: R3 Note 9 column
A14: Total equity (USD mm) | F14: 172018.5 | H14: R3 Note 9 column
A16: Net cash generated by operating activities (USD mm) | F16: 72520.7 | H16: R6 Note 9 column
A17: Net cash used in investing activities (USD mm) | F17: -36480.5 | H17: R6 Note 9 column
A18: Net cash used in financing activities (USD mm) | F18: -14037.1 | H18: R6 Note 9 column

Sheet Checks_TieOut
A1: Real tie-out checks -- audited historical statements vs independently entered source constants (TWD millions). Supersedes the self-referential label-lookup "checks" on the legacy Checks/Gate_9of10 tabs (left in place, not weakened).
A2: MASTER | B2: =IF(COUNTIF(H5:H45,"FAIL")=0,"OK -- ALL TIE-OUTS PASS","FAIL") -> FAIL
A3: Conteo mecanizado | B3: =COUNTIF(H5:H45,"PASS")&" PASS / "&(COUNTIF(H5:H45,"PASS")+COUNTIF(H5:H45,"FAIL"))&" checks" -> 39 PASS / 40 checks
A4: Check | B4: FY2021A | C4: FY2022A | D4: FY2023A | E4: FY2024A | F4: FY2025A | H4: Status
A5: IS: Gross profit = Revenue - COGS | B5: =IS_Hist!B5-IS_Hist!B6-IS_Hist!B7 -> 0 | C5: =IS_Hist!C5-IS_Hist!C6-IS_Hist!C7 -> 0 | D5: =IS_Hist!D5-IS_Hist!D6-IS_Hist!D7 -> 0 | E5: =IS_Hist!E5-IS_Hist!E6-IS_Hist!E7 -> 0 | F5: =IS_Hist!F5-IS_Hist!F6-IS_Hist!F7 -> 0 | H5: =IF(AND(ABS(N(B5))<=0.6,ABS(N(C5))<=0.6,ABS(N(D5))<=0.6,ABS(N(E5))<=0.6,ABS(N(F5))<=0.6),"PASS","FAIL") -> PASS
A6: IS: Net income = PBT - tax | B6: =IS_Hist!B23-IS_Hist!B24-IS_Hist!B25 -> 0 | C6: =IS_Hist!C23-IS_Hist!C24-IS_Hist!C25 -> 0 | D6: =IS_Hist!D23-IS_Hist!D24-IS_Hist!D25 -> 0 | E6: =IS_Hist!E23-IS_Hist!E24-IS_Hist!E25 -> 0 | F6: =IS_Hist!F23-IS_Hist!F24-IS_Hist!F25 -> 0 | H6: =IF(AND(ABS(N(B6))<=0.6,ABS(N(C6))<=0.6,ABS(N(D6))<=0.6,ABS(N(E6))<=0.6,ABS(N(F6))<=0.6),"PASS","FAIL") -> PASS
