Workbook

Sheet 00_Cover
A1: Grupo Cibest / Bancolombia — Controlled Bank Model | B1: Grupo Cibest / Bancolombia — Controlled Bank Model | C1: Grupo Cibest / Bancolombia — Controlled Bank Model | D1: Grupo Cibest / Bancolombia — Controlled Bank Model | E1: Grupo Cibest / Bancolombia — Controlled Bank Model | F1: Grupo Cibest / Bancolombia — Controlled Bank Model | G1: Grupo Cibest / Bancolombia — Controlled Bank Model | H1: Grupo Cibest / Bancolombia — Controlled Bank Model
A2: COP billions unless stated | 2025A base | 2026E–2030E forecast | Controlled 9/10 re-gate | B2: COP billions unless stated | 2025A base | 2026E–2030E forecast | Controlled 9/10 re-gate | C2: COP billions unless stated | 2025A base | 2026E–2030E forecast | Controlled 9/10 re-gate | D2: COP billions unless stated | 2025A base | 2026E–2030E forecast | Controlled 9/10 re-gate | E2: COP billions unless stated | 2025A base | 2026E–2030E forecast | Controlled 9/10 re-gate | F2: COP billions unless stated | 2025A base | 2026E–2030E forecast | Controlled 9/10 re-gate | G2: COP billions unless stated | 2025A base | 2026E–2030E forecast | Controlled 9/10 re-gate | H2: COP billions unless stated | 2025A base | 2026E–2030E forecast | Controlled 9/10 re-gate
A4: Model field | B4: Value
A5: Legal entity / perimeter | B5: Grupo Cibest S.A. consolidated; Bancolombia predecessor periods are not silently stitched
A6: Ticker / CIK | B6: CIB | current CIK 0002058897 | predecessor CIK 0001071371
A7: Archetype | B7: Bank / financial holding company; loan, funding, credit, capital and payout schedules
A8: Valuation | B8: Residual income primary; dividend discount cross-check; deposits are operating funding, not debt
A9: Currency / units | B9: COP billions; no current-FX restatement of historical periods
A10: Historical perimeter | B10: 2024A and 2025A shown on 4Q25 pro-forma including Banistmo basis for comparability
A11: Forecast horizon | B11: 2026E–2030E
A12: Active scenario | B12: =Assumptions!E3 -> Base
A13: Model status | B13: =Checks!B15 -> PASS
A14: Valuation as-of | B14: 2025-12-31; intrinsic value only, no unsourced market price
A15: Primary filing | B15: Grupo Cibest 2025 Form 20-F, accession 0002058897-26-000125
A16: Operating evidence | B16: Grupo Cibest 4Q25 Form 6-K, accession 0002058897-26-000013
A17: Main limitation | B17: Banistmo sale/perimeter transition and adjusted 2025 earnings require explicit pro-forma treatment
A18: Independent certification | B18: Pending independent-gate reproduction; owner evidence is not self-certification
A19: Controlled output | B19: Bancolombia_9of10_Regated.xlsx
A20: Original preserved | B20: Bancolombia_Institutional_Model.xlsx
A22: Use this controlled workbook only after the Checks sheet reads PASS. Historical values are hardcoded sourced facts. Blue-font cells are editable assumptions. Green-font formulas link across sheets. The active scenario must be returned to Base after testing. | B22: Use this controlled workbook only after the Checks sheet reads PASS. Historical values are hardcoded sourced facts. Blue-font cells are editable assumptions. Green-font formulas link across sheets. The active scenario must be returned to Base after testing. | C22: Use this controlled workbook only after the Checks sheet reads PASS. Historical values are hardcoded sourced facts. Blue-font cells are editable assumptions. Green-font formulas link across sheets. The active scenario must be returned to Base after testing. | D22: Use this controlled workbook only after the Checks sheet reads PASS. Historical values are hardcoded sourced facts. Blue-font cells are editable assumptions. Green-font formulas link across sheets. The active scenario must be returned to Base after testing. | E22: Use this controlled workbook only after the Checks sheet reads PASS. Historical values are hardcoded sourced facts. Blue-font cells are editable assumptions. Green-font formulas link across sheets. The active scenario must be returned to Base after testing. | F22: Use this controlled workbook only after the Checks sheet reads PASS. Historical values are hardcoded sourced facts. Blue-font cells are editable assumptions. Green-font formulas link across sheets. The active scenario must be returned to Base after testing. | G22: Use this controlled workbook only after the Checks sheet reads PASS. Historical values are hardcoded sourced facts. Blue-font cells are editable assumptions. Green-font formulas link across sheets. The active scenario must be returned to Base after testing. | H22: Use this controlled workbook only after the Checks sheet reads PASS. Historical values are hardcoded sourced facts. Blue-font cells are editable assumptions. Green-font formulas link across sheets. The active scenario must be returned to Base after testing.
A23: Use this controlled workbook only after the Checks sheet reads PASS. Historical values are hardcoded sourced facts. Blue-font cells are editable assumptions. Green-font formulas link across sheets. The active scenario must be returned to Base after testing. | B23: Use this controlled workbook only after the Checks sheet reads PASS. Historical values are hardcoded sourced facts. Blue-font cells are editable assumptions. Green-font formulas link across sheets. The active scenario must be returned to Base after testing. | C23: Use this controlled workbook only after the Checks sheet reads PASS. Historical values are hardcoded sourced facts. Blue-font cells are editable assumptions. Green-font formulas link across sheets. The active scenario must be returned to Base after testing. | D23: Use this controlled workbook only after the Checks sheet reads PASS. Historical values are hardcoded sourced facts. Blue-font cells are editable assumptions. Green-font formulas link across sheets. The active scenario must be returned to Base after testing. | E23: Use this controlled workbook only after the Checks sheet reads PASS. Historical values are hardcoded sourced facts. Blue-font cells are editable assumptions. Green-font formulas link across sheets. The active scenario must be returned to Base after testing. | F23: Use this controlled workbook only after the Checks sheet reads PASS. Historical values are hardcoded sourced facts. Blue-font cells are editable assumptions. Green-font formulas link across sheets. The active scenario must be returned to Base after testing. | G23: Use this controlled workbook only after the Checks sheet reads PASS. Historical values are hardcoded sourced facts. Blue-font cells are editable assumptions. Green-font formulas link across sheets. The active scenario must be returned to Base after testing. | H23: Use this controlled workbook only after the Checks sheet reads PASS. Historical values are hardcoded sourced facts. Blue-font cells are editable assumptions. Green-font formulas link across sheets. The active scenario must be returned to Base after testing.
A24: Use this controlled workbook only after the Checks sheet reads PASS. Historical values are hardcoded sourced facts. Blue-font cells are editable assumptions. Green-font formulas link across sheets. The active scenario must be returned to Base after testing. | B24: Use this controlled workbook only after the Checks sheet reads PASS. Historical values are hardcoded sourced facts. Blue-font cells are editable assumptions. Green-font formulas link across sheets. The active scenario must be returned to Base after testing. | C24: Use this controlled workbook only after the Checks sheet reads PASS. Historical values are hardcoded sourced facts. Blue-font cells are editable assumptions. Green-font formulas link across sheets. The active scenario must be returned to Base after testing. | D24: Use this controlled workbook only after the Checks sheet reads PASS. Historical values are hardcoded sourced facts. Blue-font cells are editable assumptions. Green-font formulas link across sheets. The active scenario must be returned to Base after testing. | E24: Use this controlled workbook only after the Checks sheet reads PASS. Historical values are hardcoded sourced facts. Blue-font cells are editable assumptions. Green-font formulas link across sheets. The active scenario must be returned to Base after testing. | F24: Use this controlled workbook only after the Checks sheet reads PASS. Historical values are hardcoded sourced facts. Blue-font cells are editable assumptions. Green-font formulas link across sheets. The active scenario must be returned to Base after testing. | G24: Use this controlled workbook only after the Checks sheet reads PASS. Historical values are hardcoded sourced facts. Blue-font cells are editable assumptions. Green-font formulas link across sheets. The active scenario must be returned to Base after testing. | H24: Use this controlled workbook only after the Checks sheet reads PASS. Historical values are hardcoded sourced facts. Blue-font cells are editable assumptions. Green-font formulas link across sheets. The active scenario must be returned to Base after testing.
A25: Use this controlled workbook only after the Checks sheet reads PASS. Historical values are hardcoded sourced facts. Blue-font cells are editable assumptions. Green-font formulas link across sheets. The active scenario must be returned to Base after testing. | B25: Use this controlled workbook only after the Checks sheet reads PASS. Historical values are hardcoded sourced facts. Blue-font cells are editable assumptions. Green-font formulas link across sheets. The active scenario must be returned to Base after testing. | C25: Use this controlled workbook only after the Checks sheet reads PASS. Historical values are hardcoded sourced facts. Blue-font cells are editable assumptions. Green-font formulas link across sheets. The active scenario must be returned to Base after testing. | D25: Use this controlled workbook only after the Checks sheet reads PASS. Historical values are hardcoded sourced facts. Blue-font cells are editable assumptions. Green-font formulas link across sheets. The active scenario must be returned to Base after testing. | E25: Use this controlled workbook only after the Checks sheet reads PASS. Historical values are hardcoded sourced facts. Blue-font cells are editable assumptions. Green-font formulas link across sheets. The active scenario must be returned to Base after testing. | F25: Use this controlled workbook only after the Checks sheet reads PASS. Historical values are hardcoded sourced facts. Blue-font cells are editable assumptions. Green-font formulas link across sheets. The active scenario must be returned to Base after testing. | G25: Use this controlled workbook only after the Checks sheet reads PASS. Historical values are hardcoded sourced facts. Blue-font cells are editable assumptions. Green-font formulas link across sheets. The active scenario must be returned to Base after testing. | H25: Use this controlled workbook only after the Checks sheet reads PASS. Historical values are hardcoded sourced facts. Blue-font cells are editable assumptions. Green-font formulas link across sheets. The active scenario must be returned to Base after testing.

Sheet Sources
A1: Claim-level source ledger | B1: Claim-level source ledger | C1: Claim-level source ledger | D1: Claim-level source ledger | E1: Claim-level source ledger | F1: Claim-level source ledger | G1: Claim-level source ledger | H1: Claim-level source ledger | I1: Claim-level source ledger | J1: Claim-level source ledger | K1: Claim-level source ledger | L1: Claim-level source ledger | M1: Claim-level source ledger | N1: Claim-level source ledger | O1: Claim-level source ledger | P1: Claim-level source ledger
A2: Each material historical input maps metric, value, period, unit, exact filing, accession, target cell and transformation. | B2: Each material historical input maps metric, value, period, unit, exact filing, accession, target cell and transformation. | C2: Each material historical input maps metric, value, period, unit, exact filing, accession, target cell and transformation. | D2: Each material historical input maps metric, value, period, unit, exact filing, accession, target cell and transformation. | E2: Each material historical input maps metric, value, period, unit, exact filing, accession, target cell and transformation. | F2: Each material historical input maps metric, value, period, unit, exact filing, accession, target cell and transformation. | G2: Each material historical input maps metric, value, period, unit, exact filing, accession, target cell and transformation. | H2: Each material historical input maps metric, value, period, unit, exact filing, accession, target cell and transformation. | I2: Each material historical input maps metric, value, period, unit, exact filing, accession, target cell and transformation. | J2: Each material historical input maps metric, value, period, unit, exact filing, accession, target cell and transformation. | K2: Each material historical input maps metric, value, period, unit, exact filing, accession, target cell and transformation. | L2: Each material historical input maps metric, value, period, unit, exact filing, accession, target cell and transformation. | M2: Each material historical input maps metric, value, period, unit, exact filing, accession, target cell and transformation. | N2: Each material historical input maps metric, value, period, unit, exact filing, accession, target cell and transformation. | O2: Each material historical input maps metric, value, period, unit, exact filing, accession, target cell and transformation. | P2: Each material historical input maps metric, value, period, unit, exact filing, accession, target cell and transformation.
A4: Source ID | B4: Legal entity | C4: Metric | D4: Reported value | E4: Unit | F4: Period | G4: Basis | H4: Taxonomy / exact locator | I4: Form | J4: Filed / published | K4: Accession | L4: Exact official URL | M4: Workbook target | N4: Scale / FX / sign / perimeter transformation | O4: Class | P4: Status
A5: BC24-ASSETS | B5: Grupo Cibest / Bancolombia predecessor | C5: Total assets | D5: 372215.38 | E5: COP bn | F5: 2024-12-31 | G5: 4Q25 pro-forma incl. Banistmo | H5: 4Q25 6-K consolidated statement; ifrs-full:Assets | I5: 6-K | J5: 2026-02-23 | K5: 0002058897-26-000013 | L5: https://www.sec.gov/Archives/edgar/data/2058897/000205889726000013/grupocibestsa6-kpr4q25.htm | M5: Historical!B5 | N5: COP million / 1,000; no FX; comparative pro-forma perimeter | O5: Primary filing | P5: =IF(AND(C5<>"",D5<>"",E5<>"",F5<>"",H5<>"",I5<>"",J5<>"",K5<>"",L5<>"",M5<>"",N5<>"",O5<>""),"PASS","FAIL") -> PASS
A6: BC25-ASSETS | B6: Grupo Cibest S.A. | C6: Total assets | D6: 384657.72 | E6: COP bn | F6: 2025-12-31 | G6: 4Q25 pro-forma incl. Banistmo | H6: 4Q25 6-K consolidated statement; ifrs-full:Assets | I6: 6-K | J6: 2026-02-23 | K6: 0002058897-26-000013 | L6: https://www.sec.gov/Archives/edgar/data/2058897/000205889726000013/grupocibestsa6-kpr4q25.htm | M6: Historical!C5 | N6: COP million / 1,000; no FX; pro-forma incl. Banistmo | O6: Primary filing | P6: =IF(AND(C6<>"",D6<>"",E6<>"",F6<>"",H6<>"",I6<>"",J6<>"",K6<>"",L6<>"",M6<>"",N6<>"",O6<>""),"PASS","FAIL") -> PASS
A7: BC24-LOANS | B7: Grupo Cibest / Bancolombia predecessor | C7: Gross loans | D7: 279453.91 | E7: COP bn | F7: 2024-12-31 | G7: 4Q25 pro-forma incl. Banistmo | H7: 4Q25 6-K loan portfolio table; ifrs-full:LoansAndAdvancesToCustomers | I7: 6-K | J7: 2026-02-23 | K7: 0002058897-26-000013 | L7: https://www.sec.gov/Archives/edgar/data/2058897/000205889726000013/grupocibestsa6-kpr4q25.htm | M7: Historical!B6 | N7: COP million / 1,000; gross; no FX; comparative pro-forma perimeter | O7: Primary filing | P7: =IF(AND(C7<>"",D7<>"",E7<>"",F7<>"",H7<>"",I7<>"",J7<>"",K7<>"",L7<>"",M7<>"",N7<>"",O7<>""),"PASS","FAIL") -> PASS
A8: BC25-LOANS | B8: Grupo Cibest S.A. | C8: Gross loans | D8: 285207.4 | E8: COP bn | F8: 2025-12-31 | G8: 4Q25 pro-forma incl. Banistmo | H8: 4Q25 6-K total loan portfolio table; ifrs-full:LoansAndAdvancesToCustomers | I8: 6-K | J8: 2026-02-23 | K8: 0002058897-26-000013 | L8: https://www.sec.gov/Archives/edgar/data/2058897/000205889726000013/grupocibestsa6-kpr4q25.htm | M8: Historical!C6 | N8: COP million / 1,000; gross; no FX; pro-forma incl. Banistmo | O8: Primary filing | P8: =IF(AND(C8<>"",D8<>"",E8<>"",F8<>"",H8<>"",I8<>"",J8<>"",K8<>"",L8<>"",M8<>"",N8<>"",O8<>""),"PASS","FAIL") -> PASS
A9: BC24-DEPOSITS | B9: Grupo Cibest / Bancolombia predecessor | C9: Customer deposits | D9: 279059.4 | E9: COP bn | F9: 2024-12-31 | G9: 4Q25 pro-forma incl. Banistmo | H9: 4Q25 6-K consolidated statement; ifrs-full:DepositsFromCustomers | I9: 6-K | J9: 2026-02-23 | K9: 0002058897-26-000013 | L9: https://www.sec.gov/Archives/edgar/data/2058897/000205889726000013/grupocibestsa6-kpr4q25.htm | M9: Historical!B7 | N9: COP million / 1,000; no FX; comparative pro-forma perimeter | O9: Primary filing | P9: =IF(AND(C9<>"",D9<>"",E9<>"",F9<>"",H9<>"",I9<>"",J9<>"",K9<>"",L9<>"",M9<>"",N9<>"",O9<>""),"PASS","FAIL") -> PASS
A10: BC25-DEPOSITS | B10: Grupo Cibest S.A. | C10: Customer deposits | D10: 291707.47 | E10: COP bn | F10: 2025-12-31 | G10: 4Q25 pro-forma incl. Banistmo | H10: 4Q25 6-K consolidated statement; ifrs-full:DepositsFromCustomers | I10: 6-K | J10: 2026-02-23 | K10: 0002058897-26-000013 | L10: https://www.sec.gov/Archives/edgar/data/2058897/000205889726000013/grupocibestsa6-kpr4q25.htm | M10: Historical!C7 | N10: COP million / 1,000; no FX; pro-forma incl. Banistmo | O10: Primary filing | P10: =IF(AND(C10<>"",D10<>"",E10<>"",F10<>"",H10<>"",I10<>"",J10<>"",K10<>"",L10<>"",M10<>"",N10<>"",O10<>""),"PASS","FAIL") -> PASS
A11: BC24-EQUITY | B11: Grupo Cibest / Bancolombia predecessor | C11: Equity attributable to parent | D11: 43542.468 | E11: COP bn | F11: 2024-12-31 | G11: 4Q25 pro-forma incl. Banistmo | H11: 4Q25 6-K consolidated statement; ifrs-full:EquityAttributableToOwnersOfParent | I11: 6-K | J11: 2026-02-23 | K11: 0002058897-26-000013 | L11: https://www.sec.gov/Archives/edgar/data/2058897/000205889726000013/grupocibestsa6-kpr4q25.htm | M11: Historical!B8 | N11: COP million / 1,000; no FX; comparative pro-forma perimeter | O11: Primary filing | P11: =IF(AND(C11<>"",D11<>"",E11<>"",F11<>"",H11<>"",I11<>"",J11<>"",K11<>"",L11<>"",M11<>"",N11<>"",O11<>""),"PASS","FAIL") -> PASS
A12: BC25-EQUITY | B12: Grupo Cibest S.A. | C12: Equity attributable to parent | D12: 43092.745 | E12: COP bn | F12: 2025-12-31 | G12: 4Q25 pro-forma incl. Banistmo | H12: 4Q25 6-K consolidated statement; ifrs-full:EquityAttributableToOwnersOfParent | I12: 6-K | J12: 2026-02-23 | K12: 0002058897-26-000013 | L12: https://www.sec.gov/Archives/edgar/data/2058897/000205889726000013/grupocibestsa6-kpr4q25.htm | M12: Historical!C8 | N12: COP million / 1,000; no FX; pro-forma incl. Banistmo | O12: Primary filing | P12: =IF(AND(C12<>"",D12<>"",E12<>"",F12<>"",H12<>"",I12<>"",J12<>"",K12<>"",L12<>"",M12<>"",N12<>"",O12<>""),"PASS","FAIL") -> PASS
A13: BC24-NI | B13: Bancolombia S.A. predecessor | C13: Net income attributable | D13: 6267.744 | E13: COP bn | F13: FY2024 | G13: Reported | H13: 2024 annual management report / 20-F discussion; ifrs-full:ProfitLossAttributableToOwnersOfParent | I13: 20-F / 6-K | J13: 2025-03-28 / 2025-04-07 | K13: 0001071371-25-000053 / 0001071371-25-000062 | L13: https://www.sec.gov/Archives/edgar/data/1071371/000107137125000062/ex991-annualreportofbancol.htm | M13: Historical!B9 | N13: COP million / 1,000; no FX; predecessor legal entity disclosed | O13: Primary filing | P13: =IF(AND(C13<>"",D13<>"",E13<>"",F13<>"",H13<>"",I13<>"",J13<>"",K13<>"",L13<>"",M13<>"",N13<>"",O13<>""),"PASS","FAIL") -> PASS
A14: BC25-ADJNI | B14: Grupo Cibest S.A. | C14: Adjusted net income ex-Banistmo sale | D14: 7276.23 | E14: COP bn | F14: FY2025 | G14: Management adjusted continuing basis | H14: 4Q25 6-K income statement discussion; issuer non-GAAP, no taxonomy tag | I14: 6-K | J14: 2026-02-23 | K14: 0002058897-26-000013 | L14: https://www.sec.gov/Archives/edgar/data/2058897/000205889726000013/grupocibestsa6-kpr4q25.htm | M14: Historical!C9 | N14: COP million / 1,000; excludes COP 3.4tn goodwill impairment from Banistmo sale | O14: Primary filing / adjusted | P14: =IF(AND(C14<>"",D14<>"",E14<>"",F14<>"",H14<>"",I14<>"",J14<>"",K14<>"",L14<>"",M14<>"",N14<>"",O14<>""),"PASS","FAIL") -> PASS
A15: BC25-REPNI | B15: Grupo Cibest S.A. | C15: Reported net income | D15: 3821 | E15: COP bn | F15: FY2025 | G15: Reported | H15: 4Q25 6-K income statement discussion; ifrs-full:ProfitLossAttributableToOwnersOfParent | I15: 6-K | J15: 2026-02-23 | K15: 0002058897-26-000013 | L15: https://www.sec.gov/Archives/edgar/data/2058897/000205889726000013/grupocibestsa6-kpr4q25.htm | M15: Historical!C10 | N15: COP million / 1,000; no FX; includes Banistmo goodwill impairment | O15: Primary filing | P15: =IF(AND(C15<>"",D15<>"",E15<>"",F15<>"",H15<>"",I15<>"",J15<>"",K15<>"",L15<>"",M15<>"",N15<>"",O15<>""),"PASS","FAIL") -> PASS
A16: BC24-NIM | B16: Grupo Cibest / Bancolombia predecessor | C16: Quarterly annualized consolidated NIM | D16: 0.0599 | E16: % | F16: 4Q2024 | G16: Comparable 4Q | H16: 4Q25 6-K NIM table; issuer operating ratio | I16: 6-K | J16: 2026-02-23 | K16: 0002058897-26-000013 | L16: https://www.sec.gov/Archives/edgar/data/2058897/000205889726000013/grupocibestsa6-kpr4q25.htm | M16: Historical!B11 | N16: Direct ratio; no FX; comparative pro-forma disclosure | O16: Primary filing | P16: =IF(AND(C16<>"",D16<>"",E16<>"",F16<>"",H16<>"",I16<>"",J16<>"",K16<>"",L16<>"",M16<>"",N16<>"",O16<>""),"PASS","FAIL") -> PASS
... A27: BC25-SHARES | B27: Grupo Cibest S.A. | C27: Reported EPS used to derive equivalent shares | D27: 4045 | E27: COP/share | F27: FY2025 | G27: Reported EPS; derived share count | H27: 2025 20-F Item 5: COP 3,821bn attributable net income and COP 4,045 EPS | I27: 20-F | J27: 2026-04-08 | K27: 0002058897-26-000125 | L27: https://www.sec.gov/Archives/edgar/data/2058897/000205889726000125/cib-20251231.htm | M27: Historical!B19:C19; Assumptions!B18:E18; Valuation!G24:G25 | N27: COP 3,821bn x 1,000 / COP 4,045 per share = 944.623mm equivalent shares; rounded only for display | O27: Primary filing / derived | P27: =IF(AND(C27<>"",D27<>"",E27<>"",F27<>"",H27<>"",I27<>"",J27<>"",K27<>"",L27<>"",M27<>"",N27<>"",O27<>""),"PASS","FAIL") -> PASS
A28: Completeness | O28: =COUNTIF(P5:P27,"PASS") -> 23 | P28: =IF(O28=23,"PASS","FAIL") -> PASS

Sheet Historical
A1: Historical bank economics | B1: Historical bank economics | C1: Historical bank economics | D1: Historical bank economics | E1: Historical bank economics | F1: Historical bank economics | G1: Historical bank economics | H1: Historical bank economics
A2: COP billions except ratios and shares. 2024A/2025A use explicit pro-forma perimeter notes; no current FX across history. | B2: COP billions except ratios and shares. 2024A/2025A use explicit pro-forma perimeter notes; no current FX across history. | C2: COP billions except ratios and shares. 2024A/2025A use explicit pro-forma perimeter notes; no current FX across history. | D2: COP billions except ratios and shares. 2024A/2025A use explicit pro-forma perimeter notes; no current FX across history. | E2: COP billions except ratios and shares. 2024A/2025A use explicit pro-forma perimeter notes; no current FX across history. | F2: COP billions except ratios and shares. 2024A/2025A use explicit pro-forma perimeter notes; no current FX across history. | G2: COP billions except ratios and shares. 2024A/2025A use explicit pro-forma perimeter notes; no current FX across history. | H2: COP billions except ratios and shares. 2024A/2025A use explicit pro-forma perimeter notes; no current FX across history.
A4: Metric | B4: 2024A | C4: 2025A | D4: Unit | E4: Source ID | F4: Exact locator / tag | G4: Perimeter / transformation | H4: Quality
A5: Total assets | B5: 372215.38 | C5: 384657.72 | D5: COP bn | E5: BC24/25-ASSETS | F5: 4Q25 6-K statement / ifrs-full:Assets | G5: Pro-forma including Banistmo | H5: Primary filing
A6: Gross loans | B6: 279453.91 | C6: 285207.4 | D6: COP bn | E6: BC24/25-LOANS | F6: 4Q25 6-K loan table | G6: Gross; pro-forma including Banistmo | H6: Primary filing
A7: Customer deposits | B7: 279059.4 | C7: 291707.47 | D7: COP bn | E7: BC24/25-DEPOSITS | F7: 4Q25 6-K statement | G7: Operating funding; not corporate debt | H7: Primary filing
A8: Equity attributable to parent | B8: 43542.468 | C8: 43092.745 | D8: COP bn | E8: BC24/25-EQUITY | F8: 4Q25 6-K statement | G8: Parent attributable; no FX | H8: Primary filing
A9: Adjusted net income | B9: 6267.744 | C9: 7276.23 | D9: COP bn | E9: BC24-NI / BC25-ADJNI | F9: 20-F / 4Q25 6-K discussion | G9: 2025 excludes Banistmo sale goodwill impairment | H9: Primary / adjusted
A10: Reported net income | B10: 6267.744 | C10: 3821 | D10: COP bn | E10: BC24-NI / BC25-REPNI | F10: 20-F / 4Q25 6-K discussion | G10: 2025 includes Banistmo goodwill impairment | H10: Primary filing
A11: Quarterly annualized consolidated NIM | B11: 0.0599 | C11: 0.0616 | D11: % | E11: BC24/25-NIM | F11: 4Q25 6-K NIM table / discussion | G11: Comparable 4Q ratios; not full-year average | H11: Primary filing
A12: Cost of risk | C12: 0.0159 | D12: % | E12: BC25-COR | F12: 4Q25 6-K asset quality discussion | G12: LTM 2025 | H12: Primary filing
A13: 30-day past-due loans / gross loans | B13: 0.0465 | C13: 0.0357 | D13: % | E13: BC24/25-PDL | F13: 4Q25 6-K asset quality table | G13: 2024 ratio derived from reported numerator/denominator | H13: Primary / derived
A14: 30-day PDL coverage | B14: 1.2427 | C14: 1.3441 | D14: % | E14: BC24/25-COVER | F14: 4Q25 6-K / 2025 20-F | G14: Direct ratios | H14: Primary filing
A15: Basic/core solvency | B15: 0.1195 | C15: 0.1222 | D15: % | E15: BC24/25-CORE | F15: 4Q25 6-K solvency table | G15: 2024 pro-forma; 2025 reported | H15: Primary filing
A16: Total solvency | B16: 0.1475 | C16: 0.144 | D16: % | E16: BC24/25-CORE | F16: 4Q25 6-K solvency table | G16: 2024 pro-forma; 2025 reported | H16: Primary filing
A17: Technical equity | C17: 29431.196 | D17: COP bn | E17: BC25-CAP | F17: 4Q25 6-K solvency table | G17: Regulatory capital measure | H17: Primary filing
A18: Implied capital requirement denominator | C18: =C17/C15 -> 240844.48 | D18: COP bn | E18: BC25-CAP | F18: Technical equity / core solvency | G18: Formula-derived denominator for forecast capital roll-forward | H18: Derived
A19: Diluted / equivalent shares | B19: 944.62299 | C19: 944.62299 | D19: mm shares | E19: BC25-SHARES | F19: 2025 20-F Item 5: COP 3,821bn attributable NI / COP 4,045 EPS | G19: 2025 equivalent share count derived from official NI and EPS; held constant for 2024 cross-check | H19: Primary filing / derived

Sheet Assumptions
A1: Assumptions and scenarios | B1: Assumptions and scenarios | C1: Assumptions and scenarios | D1: Assumptions and scenarios | E1: Assumptions and scenarios | F1: Assumptions and scenarios
A2: Blue-font cells are editable inputs. Selector: 1 = Base, 2 = Bull, 3 = Bear. Active results are formula cells, not drivers. | B2: Blue-font cells are editable inputs. Selector: 1 = Base, 2 = Bull, 3 = Bear. Active results are formula cells, not drivers. | C2: Blue-font cells are editable inputs. Selector: 1 = Base, 2 = Bull, 3 = Bear. Active results are formula cells, not drivers. | D2: Blue-font cells are editable inputs. Selector: 1 = Base, 2 = Bull, 3 = Bear. Active results are formula cells, not drivers. | E2: Blue-font cells are editable inputs. Selector: 1 = Base, 2 = Bull, 3 = Bear. Active results are formula cells, not drivers. | F2: Blue-font cells are editable inputs. Selector: 1 = Base, 2 = Bull, 3 = Bear. Active results are formula cells, not drivers.
A3: Scenario selector | B3: 1 | E3: =CHOOSE(B3,"Base","Bull","Bear") -> Base | F3: Return to 1 after perturbation testing
A5: Metric | B5: Base | C5: Bull | D5: Bear | E5: Active | F5: Rationale / source / ownership
A6: Loan growth | B6: 0.06 | C6: 0.08 | D6: 0.03 | E6: =CHOOSE($B$3,B6,C6,D6) -> 0.06 | F6: Model input; anchored to 2025 pro-forma loan growth and 2026 recovery
A7: Deposit growth | B7: 0.07 | C7: 0.09 | D7: 0.04 | E7: =CHOOSE($B$3,B7,C7,D7) -> 0.07 | F7: Model input; preserves deposits as operating funding
A8: Net interest margin | B8: 0.062 | C8: 0.065 | D8: 0.057 | E8: =CHOOSE($B$3,B8,C8,D8) -> 0.062 | F8: Model input; anchored to 4Q25 consolidated NIM 6.16%
A9: Cost of risk | B9: 0.017 | C9: 0.013 | D9: 0.024 | E9: =CHOOSE($B$3,B9,C9,D9) -> 0.017 | F9: Model input; anchored to 2025 LTM 1.59% with downside stress
A10: Fee + other income / avg assets | B10: 0.027 | C10: 0.029 | D10: 0.024 | E10: =CHOOSE($B$3,B10,C10,D10) -> 0.027 | F10: Model input; bank non-interest income proxy
A11: Operating expense / avg assets | B11: 0.034 | C11: 0.032 | D11: 0.037 | E11: =CHOOSE($B$3,B11,C11,D11) -> 0.034 | F11: Model input; explicit operating-efficiency driver
A12: Tax rate | B12: 0.3 | C12: 0.29 | D12: 0.31 | E12: =CHOOSE($B$3,B12,C12,D12) -> 0.3 | F12: Model input; normalized effective tax
A13: Dividend payout target | B13: 0.5 | C13: 0.45 | D13: 0.6 | E13: =CHOOSE($B$3,B13,C13,D13) -> 0.5 | F13: Policy-aware input; 2025 20-F states statutory minimum distribution framework
A14: Core capital eligible / parent equity | B14: 0.683 | C14: 0.683 | D14: 0.683 | E14: =CHOOSE($B$3,B14,C14,D14) -> 0.683 | F14: Derived from 2025 technical equity / parent equity
A15: Minimum core solvency | B15: 0.115 | C15: 0.115 | D15: 0.115 | E15: =CHOOSE($B$3,B15,C15,D15) -> 0.115 | F15: Model governance floor below 2025 reported 12.22%
A16: Cost of equity | B16: 0.13 | C16: 0.12 | D16: 0.145 | E16: =CHOOSE($B$3,B16,C16,D16) -> 0.13 | F16: Valuation input; nominal COP required return
A17: Terminal growth | B17: 0.05 | C17: 0.06 | D17: 0.035 | E17: =CHOOSE($B$3,B17,C17,D17) -> 0.05 | F17: Valuation input; nominal COP long-run growth
... A21: 30-day coverage target | B21: 1.35 | C21: 1.45 | D21: 1.2 | E21: =CHOOSE($B$3,B21,C21,D21) -> 1.35 | F21: Model input; anchored to 2025 reported 134.41%
A23: Scenario ownership: cases change operating drivers, capital/payout mechanics and residual-income valuation through formulas. No scenario changes only the headline valuation. The capital schedule can constrain dividends to protect the visible solvency floor. | B23: Scenario ownership: cases change operating drivers, capital/payout mechanics and residual-income valuation through formulas. No scenario changes only the headline valuation. The capital schedule can constrain dividends to protect the visible solvency floor. | C23: Scenario ownership: cases change operating drivers, capital/payout mechanics and residual-income valuation through formulas. No scenario changes only the headline valuation. The capital schedule can constrain dividends to protect the visible solvency floor. | D23: Scenario ownership: cases change operating drivers, capital/payout mechanics and residual-income valuation through formulas. No scenario changes only the headline valuation. The capital schedule can constrain dividends to protect the visible solvency floor. | E23: Scenario ownership: cases change operating drivers, capital/payout mechanics and residual-income valuation through formulas. No scenario changes only the headline valuation. The capital schedule can constrain dividends to protect the visible solvency floor. | F23: Scenario ownership: cases change operating drivers, capital/payout mechanics and residual-income valuation through formulas. No scenario changes only the headline valuation. The capital schedule can constrain dividends to protect the visible solvency floor.
A24: Scenario ownership: cases change operating drivers, capital/payout mechanics and residual-income valuation through formulas. No scenario changes only the headline valuation. The capital schedule can constrain dividends to protect the visible solvency floor. | B24: Scenario ownership: cases change operating drivers, capital/payout mechanics and residual-income valuation through formulas. No scenario changes only the headline valuation. The capital schedule can constrain dividends to protect the visible solvency floor. | C24: Scenario ownership: cases change operating drivers, capital/payout mechanics and residual-income valuation through formulas. No scenario changes only the headline valuation. The capital schedule can constrain dividends to protect the visible solvency floor. | D24: Scenario ownership: cases change operating drivers, capital/payout mechanics and residual-income valuation through formulas. No scenario changes only the headline valuation. The capital schedule can constrain dividends to protect the visible solvency floor. | E24: Scenario ownership: cases change operating drivers, capital/payout mechanics and residual-income valuation through formulas. No scenario changes only the headline valuation. The capital schedule can constrain dividends to protect the visible solvency floor. | F24: Scenario ownership: cases change operating drivers, capital/payout mechanics and residual-income valuation through formulas. No scenario changes only the headline valuation. The capital schedule can constrain dividends to protect the visible solvency floor.

Sheet Forecast
A1: Forecast summary | B1: Forecast summary | C1: Forecast summary | D1: Forecast summary | E1: Forecast summary | F1: Forecast summary | G1: Forecast summary | H1: Forecast summary
A2: Formula-linked summary of bank driver, earnings, capital and payout schedules. The Sector_KPIs sheet contains the detailed mechanics. | B2: Formula-linked summary of bank driver, earnings, capital and payout schedules. The Sector_KPIs sheet contains the detailed mechanics. | C2: Formula-linked summary of bank driver, earnings, capital and payout schedules. The Sector_KPIs sheet contains the detailed mechanics. | D2: Formula-linked summary of bank driver, earnings, capital and payout schedules. The Sector_KPIs sheet contains the detailed mechanics. | E2: Formula-linked summary of bank driver, earnings, capital and payout schedules. The Sector_KPIs sheet contains the detailed mechanics. | F2: Formula-linked summary of bank driver, earnings, capital and payout schedules. The Sector_KPIs sheet contains the detailed mechanics. | G2: Formula-linked summary of bank driver, earnings, capital and payout schedules. The Sector_KPIs sheet contains the detailed mechanics. | H2: Formula-linked summary of bank driver, earnings, capital and payout schedules. The Sector_KPIs sheet contains the detailed mechanics.
A4: Metric | B4: 2025A | C4: 2026E | D4: 2027E | E4: 2028E | F4: 2029E | G4: 2030E | H4: Decision use
A5: Gross loans | B5: =Sector_KPIs!B5 -> 285207.4 | C5: =Sector_KPIs!C5 -> 302319.84 | D5: =Sector_KPIs!D5 -> 320459.03 | E5: =Sector_KPIs!E5 -> 339686.57 | F5: =Sector_KPIs!F5 -> 360067.77 | G5: =Sector_KPIs!G5 -> 381671.83 | H5: Balance-sheet growth
A6: Loan growth | B6: =Sector_KPIs!B6 -> 0.020588333 | C6: =Sector_KPIs!C6 -> 0.06 | D6: =Sector_KPIs!D6 -> 0.06 | E6: =Sector_KPIs!E6 -> 0.06 | F6: =Sector_KPIs!F6 -> 0.06 | G6: =Sector_KPIs!G6 -> 0.06 | H6: Scenario propagation
A7: Customer deposits | B7: =Sector_KPIs!B7 -> 291707.47 | C7: =Sector_KPIs!C7 -> 312127 | D7: =Sector_KPIs!D7 -> 333975.89 | E7: =Sector_KPIs!E7 -> 357354.2 | F7: =Sector_KPIs!F7 -> 382368.99 | G7: =Sector_KPIs!G7 -> 409134.82 | H7: Operating funding
A8: Deposit growth | B8: =Sector_KPIs!B8 -> 0.045323945 | C8: =Sector_KPIs!C8 -> 0.07 | D8: =Sector_KPIs!D8 -> 0.07 | E8: =Sector_KPIs!E8 -> 0.07 | F8: =Sector_KPIs!F8 -> 0.07 | G8: =Sector_KPIs!G8 -> 0.07 | H8: Funding growth
A9: Net interest income | B9: =Sector_KPIs!B11 -> 17568.776 | C9: =Sector_KPIs!C11 -> 18213.344 | D9: =Sector_KPIs!D11 -> 19306.145 | E9: =Sector_KPIs!E11 -> 20464.514 | F9: =Sector_KPIs!F11 -> 21692.385 | G9: =Sector_KPIs!G11 -> 22993.928 | H9: Core earnings
A10: Credit provisions | B10: =Sector_KPIs!B13 -> 4534.7976 | C10: =Sector_KPIs!C13 -> 4993.9815 | D10: =Sector_KPIs!D13 -> 5293.6204 | E10: =Sector_KPIs!E13 -> 5611.2377 | F10: =Sector_KPIs!F13 -> 5947.9119 | G10: =Sector_KPIs!G13 -> 6304.7866 | H10: Credit cycle
A11: Net income | B11: =Sector_KPIs!B19 -> 7276.23 | C11: =Sector_KPIs!C19 -> 7309.8305 | D11: =Sector_KPIs!D19 -> 7743.561 | E11: =Sector_KPIs!E19 -> 8203.0117 | F11: =Sector_KPIs!F19 -> 8689.7067 | G11: =Sector_KPIs!G19 -> 9205.2605 | H11: Equity return
A12: ROE | B12: =Sector_KPIs!B29 -> 0 | C12: =Sector_KPIs!C29 -> 0.16272924 | D12: =Sector_KPIs!D29 -> 0.15905909 | E12: =Sector_KPIs!E29 -> 0.15574296 | F12: =Sector_KPIs!F29 -> 0.15273671 | G12: =Sector_KPIs!G29 -> 0.15000315 | H12: Profitability
A13: Dividends | B13: =Sector_KPIs!B25 -> 0 | C13: =Sector_KPIs!C25 -> 3654.9152 | D13: =Sector_KPIs!D25 -> 3871.7805 | E13: =Sector_KPIs!E25 -> 4101.5058 | F13: =Sector_KPIs!F25 -> 4344.8533 | G13: =Sector_KPIs!G25 -> 4602.6302 | H13: Payout subject to capital
A14: Ending parent equity | B14: =Sector_KPIs!B26 -> 43092.745 | C14: =Sector_KPIs!C26 -> 46747.66 | D14: =Sector_KPIs!D26 -> 50619.441 | E14: =Sector_KPIs!E26 -> 54720.947 | F14: =Sector_KPIs!F26 -> 59065.8 | G14: =Sector_KPIs!G26 -> 63668.43 | H14: Book value / valuation
A15: Core solvency | B15: =Sector_KPIs!B28 -> 0.1222 | C15: =Sector_KPIs!C28 -> 0.12506564 | D15: =Sector_KPIs!D28 -> 0.12775844 | E15: =Sector_KPIs!E28 -> 0.13029268 | F15: =Sector_KPIs!F28 -> 0.1326773 | G15: =Sector_KPIs!G28 -> 0.13492077 | H15: Capital guardrail
A16: 30-day PDL ratio | B16: =Sector_KPIs!B30 -> 0.0357 | C16: =Sector_KPIs!C30 -> 0.034 | D16: =Sector_KPIs!D30 -> 0.034 | E16: =Sector_KPIs!E30 -> 0.034 | F16: =Sector_KPIs!F30 -> 0.034 | G16: =Sector_KPIs!G30 -> 0.034 | H16: Asset quality

Sheet Valuation
A1: Bank-appropriate equity valuation | B1: Bank-appropriate equity valuation | C1: Bank-appropriate equity valuation | D1: Bank-appropriate equity valuation | E1: Bank-appropriate equity valuation | F1: Bank-appropriate equity valuation | G1: Bank-appropriate equity valuation
A2: Residual income is primary; DDM is a cross-check. No enterprise-value bridge treats deposits as corporate debt. | B2: Residual income is primary; DDM is a cross-check. No enterprise-value bridge treats deposits as corporate debt. | C2: Residual income is primary; DDM is a cross-check. No enterprise-value bridge treats deposits as corporate debt. | D2: Residual income is primary; DDM is a cross-check. No enterprise-value bridge treats deposits as corporate debt. | E2: Residual income is primary; DDM is a cross-check. No enterprise-value bridge treats deposits as corporate debt. | F2: Residual income is primary; DDM is a cross-check. No enterprise-value bridge treats deposits as corporate debt. | G2: Residual income is primary; DDM is a cross-check. No enterprise-value bridge treats deposits as corporate debt.
A4: Residual income | B4: 2026E | C4: 2027E | D4: 2028E | E4: 2029E | F4: 2030E | G4: Output
A5: Beginning book value | B5: =Historical!C8 -> 43092.745 | C5: =Sector_KPIs!C26 -> 46747.66 | D5: =Sector_KPIs!D26 -> 50619.441 | E5: =Sector_KPIs!E26 -> 54720.947 | F5: =Sector_KPIs!F26 -> 59065.8
A6: Net income | B6: =Sector_KPIs!C19 -> 7309.8305 | C6: =Sector_KPIs!D19 -> 7743.561 | D6: =Sector_KPIs!E19 -> 8203.0117 | E6: =Sector_KPIs!F19 -> 8689.7067 | F6: =Sector_KPIs!G19 -> 9205.2605
A7: ROE | B7: =B6/B5 -> 0.16963019 | C7: =C6/C5 -> 0.16564596 | D7: =D6/D5 -> 0.16205259 | E7: =E6/E5 -> 0.15880037 | F7: =F6/F5 -> 0.15584755
A8: Cost of equity | B8: =Assumptions!$E$16 -> 0.13 | C8: =Assumptions!$E$16 -> 0.13 | D8: =Assumptions!$E$16 -> 0.13 | E8: =Assumptions!$E$16 -> 0.13 | F8: =Assumptions!$E$16 -> 0.13
A9: Equity charge | B9: =B5*B8 -> 5602.0569 | C9: =C5*C8 -> 6077.1958 | D9: =D5*D8 -> 6580.5273 | E9: =E5*E8 -> 7113.7231 | F9: =F5*F8 -> 7678.554
A10: Residual income | B10: =B6-B9 -> 1707.7736 | C10: =C6-C9 -> 1666.3652 | D10: =D6-D9 -> 1622.4844 | E10: =E6-E9 -> 1575.9836 | F10: =F6-F9 -> 1526.7065
A11: Discount factor | B11: =1/(1+B8)^1 -> 0.88495575 | C11: =1/(1+C8)^2 -> 0.78314668 | D11: =1/(1+D8)^3 -> 0.69305016 | E11: =1/(1+E8)^4 -> 0.61331873 | F11: =1/(1+F8)^5 -> 0.54275994
A12: PV residual income | B12: =B10*B11 -> 1511.3041 | C12: =C10*C11 -> 1305.0084 | D12: =D10*D11 -> 1124.4631 | E12: =E10*E11 -> 966.58026 | F12: =F10*F11 -> 828.63513
A14: Terminal mechanics
A15: Terminal growth | F15: =Assumptions!E17 -> 0.05
A16: Terminal residual income | F16: =F10*(1+F15) -> 1603.0418
A17: Terminal value / PV | E17: =F16/(F8-F15) -> 20038.023 | F17: =E17*F11 -> 10875.836
A19: Residual-income output | G19: Value
A20: Current book value | G20: =Historical!C8 -> 43092.745
A21: PV explicit residual income | G21: =SUM(B12:F12) -> 5735.9909
A22: PV terminal residual income | G22: =F17 -> 10875.836
A23: Implied equity value | G23: =SUM(G20:G22) -> 59704.572
A24: Equivalent shares (mm) | G24: =Assumptions!E18 -> 944.62299
A25: Implied value per share (COP) | G25: =G23*1000/G24 -> 63204.657
A27: Dividend discount cross-check | B27: 2026E | C27: 2027E | D27: 2028E | E27: 2029E | F27: 2030E | G27: Value
A28: Dividends | B28: =Sector_KPIs!C25 -> 3654.9152 | C28: =Sector_KPIs!D25 -> 3871.7805 | D28: =Sector_KPIs!E25 -> 4101.5058 | E28: =Sector_KPIs!F25 -> 4344.8533 | F28: =Sector_KPIs!G25 -> 4602.6302
A29: PV dividends | B29: =B28*B11 -> 3234.4383 | C29: =C28*C11 -> 3032.1721 | D29: =D28*D11 -> 2842.5493 | E29: =E28*E11 -> 2664.7799 | F29: =F28*F11 -> 2498.1233
A30: Terminal dividend value | F30: =F28*(1+Assumptions!E17)/(Assumptions!E16-Assumptions!E17) -> 60409.522
A31: DDM equity value | G31: =SUM(B29:F29)+F30*F11 -> 47059.931

Sheet Sensitivity
A1: Residual-income sensitivity | B1: Residual-income sensitivity | C1: Residual-income sensitivity | D1: Residual-income sensitivity | E1: Residual-income sensitivity | F1: Residual-income sensitivity
A2: Dynamic equity-value sensitivity to cost of equity and terminal growth. Active-case reconstruction is used by Checks. | B2: Dynamic equity-value sensitivity to cost of equity and terminal growth. Active-case reconstruction is used by Checks. | C2: Dynamic equity-value sensitivity to cost of equity and terminal growth. Active-case reconstruction is used by Checks. | D2: Dynamic equity-value sensitivity to cost of equity and terminal growth. Active-case reconstruction is used by Checks. | E2: Dynamic equity-value sensitivity to cost of equity and terminal growth. Active-case reconstruction is used by Checks. | F2: Dynamic equity-value sensitivity to cost of equity and terminal growth. Active-case reconstruction is used by Checks.
A4: g / CoE | B4: 0.11 | C4: 0.12 | D4: 0.13 | E4: 0.14 | F4: 0.15
A5: 0.03 | B5: =IF(B$4<=$A5,"N/M",Historical!C8+((Sector_KPIs!C19-Historical!C8*B$4)/(1+B$4)^1)+((Sector_KPIs!D19-Sector_KPIs!C26*B$4)/(1+B$4)^2)+((Sector_KPIs!E19-Sector_KPIs!D26*B$4)/(1+B$4)^3)+((Sector_KPIs!F19-Sector_KPIs!E26*B$4)/(1+B$4)^4)+((Sector_KPIs!G19-Sector_KPIs!F26*B$4)/(1+B$4)^5)+(((Sector_KPIs!G19-Sector_KPIs!F26*B$4)*(1+$A5)/(B$4-$A5))/(1+B$4)^5)) -> 73502.916 | C5: =IF(C$4<=$A5,"N/M",Historical!C8+((Sector_KPIs!C19-Historical!C8*C$4)/(1+C$4)^1)+((Sector_KPIs!D19-Sector_KPIs!C26*C$4)/(1+C$4)^2)+((Sector_KPIs!E19-Sector_KPIs!D26*C$4)/(1+C$4)^3)+((Sector_KPIs!F19-Sector_KPIs!E26*C$4)/(1+C$4)^4)+((Sector_KPIs!G19-Sector_KPIs!F26*C$4)/(1+C$4)^5)+(((Sector_KPIs!G19-Sector_KPIs!F26*C$4)*(1+$A5)/(C$4-$A5))/(1+C$4)^5)) -> 64519.236 | D5: =IF(D$4<=$A5,"N/M",Historical!C8+((Sector_KPIs!C19-Historical!C8*D$4)/(1+D$4)^1)+((Sector_KPIs!D19-Sector_KPIs!C26*D$4)/(1+D$4)^2)+((Sector_KPIs!E19-Sector_KPIs!D26*D$4)/(1+D$4)^3)+((Sector_KPIs!F19-Sector_KPIs!E26*D$4)/(1+D$4)^4)+((Sector_KPIs!G19-Sector_KPIs!F26*D$4)/(1+D$4)^5)+(((Sector_KPIs!G19-Sector_KPIs!F26*D$4)*(1+$A5)/(D$4-$A5))/(1+D$4)^5)) -> 57363.678 | E5: =IF(E$4<=$A5,"N/M",Historical!C8+((Sector_KPIs!C19-Historical!C8*E$4)/(1+E$4)^1)+((Sector_KPIs!D19-Sector_KPIs!C26*E$4)/(1+E$4)^2)+((Sector_KPIs!E19-Sector_KPIs!D26*E$4)/(1+E$4)^3)+((Sector_KPIs!F19-Sector_KPIs!E26*E$4)/(1+E$4)^4)+((Sector_KPIs!G19-Sector_KPIs!F26*E$4)/(1+E$4)^5)+(((Sector_KPIs!G19-Sector_KPIs!F26*E$4)*(1+$A5)/(E$4-$A5))/(1+E$4)^5)) -> 51536.198 | F5: =IF(F$4<=$A5,"N/M",Historical!C8+((Sector_KPIs!C19-Historical!C8*F$4)/(1+F$4)^1)+((Sector_KPIs!D19-Sector_KPIs!C26*F$4)/(1+F$4)^2)+((Sector_KPIs!E19-Sector_KPIs!D26*F$4)/(1+F$4)^3)+((Sector_KPIs!F19-Sector_KPIs!E26*F$4)/(1+F$4)^4)+((Sector_KPIs!G19-Sector_KPIs!F26*F$4)/(1+F$4)^5)+(((Sector_KPIs!G19-Sector_KPIs!F26*F$4)*(1+$A5)/(F$4-$A5))/(1+F$4)^5)) -> 46703.514
A6: 0.04 | B6: =IF(B$4<=$A6,"N/M",Historical!C8+((Sector_KPIs!C19-Historical!C8*B$4)/(1+B$4)^1)+((Sector_KPIs!D19-Sector_KPIs!C26*B$4)/(1+B$4)^2)+((Sector_KPIs!E19-Sector_KPIs!D26*B$4)/(1+B$4)^3)+((Sector_KPIs!F19-Sector_KPIs!E26*B$4)/(1+B$4)^4)+((Sector_KPIs!G19-Sector_KPIs!F26*B$4)/(1+B$4)^5)+(((Sector_KPIs!G19-Sector_KPIs!F26*B$4)*(1+$A6)/(B$4-$A6))/(1+B$4)^5)) -> 76688.378 | C6: =IF(C$4<=$A6,"N/M",Historical!C8+((Sector_KPIs!C19-Historical!C8*C$4)/(1+C$4)^1)+((Sector_KPIs!D19-Sector_KPIs!C26*C$4)/(1+C$4)^2)+((Sector_KPIs!E19-Sector_KPIs!D26*C$4)/(1+C$4)^3)+((Sector_KPIs!F19-Sector_KPIs!E26*C$4)/(1+C$4)^4)+((Sector_KPIs!G19-Sector_KPIs!F26*C$4)/(1+C$4)^5)+(((Sector_KPIs!G19-Sector_KPIs!F26*C$4)*(1+$A6)/(C$4-$A6))/(1+C$4)^5)) -> 66388.157 | D6: =IF(D$4<=$A6,"N/M",Historical!C8+((Sector_KPIs!C19-Historical!C8*D$4)/(1+D$4)^1)+((Sector_KPIs!D19-Sector_KPIs!C26*D$4)/(1+D$4)^2)+((Sector_KPIs!E19-Sector_KPIs!D26*D$4)/(1+D$4)^3)+((Sector_KPIs!F19-Sector_KPIs!E26*D$4)/(1+D$4)^4)+((Sector_KPIs!G19-Sector_KPIs!F26*D$4)/(1+D$4)^5)+(((Sector_KPIs!G19-Sector_KPIs!F26*D$4)*(1+$A6)/(D$4-$A6))/(1+D$4)^5)) -> 58404.075 | E6: =IF(E$4<=$A6,"N/M",Historical!C8+((Sector_KPIs!C19-Historical!C8*E$4)/(1+E$4)^1)+((Sector_KPIs!D19-Sector_KPIs!C26*E$4)/(1+E$4)^2)+((Sector_KPIs!E19-Sector_KPIs!D26*E$4)/(1+E$4)^3)+((Sector_KPIs!F19-Sector_KPIs!E26*E$4)/(1+E$4)^4)+((Sector_KPIs!G19-Sector_KPIs!F26*E$4)/(1+E$4)^5)+(((Sector_KPIs!G19-Sector_KPIs!F26*E$4)*(1+$A6)/(E$4-$A6))/(1+E$4)^5)) -> 52040.031 | F6: =IF(F$4<=$A6,"N/M",Historical!C8+((Sector_KPIs!C19-Historical!C8*F$4)/(1+F$4)^1)+((Sector_KPIs!D19-Sector_KPIs!C26*F$4)/(1+F$4)^2)+((Sector_KPIs!E19-Sector_KPIs!D26*F$4)/(1+F$4)^3)+((Sector_KPIs!F19-Sector_KPIs!E26*F$4)/(1+F$4)^4)+((Sector_KPIs!G19-Sector_KPIs!F26*F$4)/(1+F$4)^5)+(((Sector_KPIs!G19-Sector_KPIs!F26*F$4)*(1+$A6)/(F$4-$A6))/(1+F$4)^5)) -> 46853.119
A7: 0.05 | B7: =IF(B$4<=$A7,"N/M",Historical!C8+((Sector_KPIs!C19-Historical!C8*B$4)/(1+B$4)^1)+((Sector_KPIs!D19-Sector_KPIs!C26*B$4)/(1+B$4)^2)+((Sector_KPIs!E19-Sector_KPIs!D26*B$4)/(1+B$4)^3)+((Sector_KPIs!F19-Sector_KPIs!E26*B$4)/(1+B$4)^4)+((Sector_KPIs!G19-Sector_KPIs!F26*B$4)/(1+B$4)^5)+(((Sector_KPIs!G19-Sector_KPIs!F26*B$4)*(1+$A7)/(B$4-$A7))/(1+B$4)^5)) -> 80935.659 | C7: =IF(C$4<=$A7,"N/M",Historical!C8+((Sector_KPIs!C19-Historical!C8*C$4)/(1+C$4)^1)+((Sector_KPIs!D19-Sector_KPIs!C26*C$4)/(1+C$4)^2)+((Sector_KPIs!E19-Sector_KPIs!D26*C$4)/(1+C$4)^3)+((Sector_KPIs!F19-Sector_KPIs!E26*C$4)/(1+C$4)^4)+((Sector_KPIs!G19-Sector_KPIs!F26*C$4)/(1+C$4)^5)+(((Sector_KPIs!G19-Sector_KPIs!F26*C$4)*(1+$A7)/(C$4-$A7))/(1+C$4)^5)) -> 68791.056 | D7: =IF(D$4<=$A7,"N/M",Historical!C8+((Sector_KPIs!C19-Historical!C8*D$4)/(1+D$4)^1)+((Sector_KPIs!D19-Sector_KPIs!C26*D$4)/(1+D$4)^2)+((Sector_KPIs!E19-Sector_KPIs!D26*D$4)/(1+D$4)^3)+((Sector_KPIs!F19-Sector_KPIs!E26*D$4)/(1+D$4)^4)+((Sector_KPIs!G19-Sector_KPIs!F26*D$4)/(1+D$4)^5)+(((Sector_KPIs!G19-Sector_KPIs!F26*D$4)*(1+$A7)/(D$4-$A7))/(1+D$4)^5)) -> 59704.572 | E7: =IF(E$4<=$A7,"N/M",Historical!C8+((Sector_KPIs!C19-Historical!C8*E$4)/(1+E$4)^1)+((Sector_KPIs!D19-Sector_KPIs!C26*E$4)/(1+E$4)^2)+((Sector_KPIs!E19-Sector_KPIs!D26*E$4)/(1+E$4)^3)+((Sector_KPIs!F19-Sector_KPIs!E26*E$4)/(1+E$4)^4)+((Sector_KPIs!G19-Sector_KPIs!F26*E$4)/(1+E$4)^5)+(((Sector_KPIs!G19-Sector_KPIs!F26*E$4)*(1+$A7)/(E$4-$A7))/(1+E$4)^5)) -> 52655.826 | F7: =IF(F$4<=$A7,"N/M",Historical!C8+((Sector_KPIs!C19-Historical!C8*F$4)/(1+F$4)^1)+((Sector_KPIs!D19-Sector_KPIs!C26*F$4)/(1+F$4)^2)+((Sector_KPIs!E19-Sector_KPIs!D26*F$4)/(1+F$4)^3)+((Sector_KPIs!F19-Sector_KPIs!E26*F$4)/(1+F$4)^4)+((Sector_KPIs!G19-Sector_KPIs!F26*F$4)/(1+F$4)^5)+(((Sector_KPIs!G19-Sector_KPIs!F26*F$4)*(1+$A7)/(F$4-$A7))/(1+F$4)^5)) -> 47032.644
A8: 0.06 | B8: =IF(B$4<=$A8,"N/M",Historical!C8+((Sector_KPIs!C19-Historical!C8*B$4)/(1+B$4)^1)+((Sector_KPIs!D19-Sector_KPIs!C26*B$4)/(1+B$4)^2)+((Sector_KPIs!E19-Sector_KPIs!D26*B$4)/(1+B$4)^3)+((Sector_KPIs!F19-Sector_KPIs!E26*B$4)/(1+B$4)^4)+((Sector_KPIs!G19-Sector_KPIs!F26*B$4)/(1+B$4)^5)+(((Sector_KPIs!G19-Sector_KPIs!F26*B$4)*(1+$A8)/(B$4-$A8))/(1+B$4)^5)) -> 86881.854 | C8: =IF(C$4<=$A8,"N/M",Historical!C8+((Sector_KPIs!C19-Historical!C8*C$4)/(1+C$4)^1)+((Sector_KPIs!D19-Sector_KPIs!C26*C$4)/(1+C$4)^2)+((Sector_KPIs!E19-Sector_KPIs!D26*C$4)/(1+C$4)^3)+((Sector_KPIs!F19-Sector_KPIs!E26*C$4)/(1+C$4)^4)+((Sector_KPIs!G19-Sector_KPIs!F26*C$4)/(1+C$4)^5)+(((Sector_KPIs!G19-Sector_KPIs!F26*C$4)*(1+$A8)/(C$4-$A8))/(1+C$4)^5)) -> 71994.921 | D8: =IF(D$4<=$A8,"N/M",Historical!C8+((Sector_KPIs!C19-Historical!C8*D$4)/(1+D$4)^1)+((Sector_KPIs!D19-Sector_KPIs!C26*D$4)/(1+D$4)^2)+((Sector_KPIs!E19-Sector_KPIs!D26*D$4)/(1+D$4)^3)+((Sector_KPIs!F19-Sector_KPIs!E26*D$4)/(1+D$4)^4)+((Sector_KPIs!G19-Sector_KPIs!F26*D$4)/(1+D$4)^5)+(((Sector_KPIs!G19-Sector_KPIs!F26*D$4)*(1+$A8)/(D$4-$A8))/(1+D$4)^5)) -> 61376.639 | E8: =IF(E$4<=$A8,"N/M",Historical!C8+((Sector_KPIs!C19-Historical!C8*E$4)/(1+E$4)^1)+((Sector_KPIs!D19-Sector_KPIs!C26*E$4)/(1+E$4)^2)+((Sector_KPIs!E19-Sector_KPIs!D26*E$4)/(1+E$4)^3)+((Sector_KPIs!F19-Sector_KPIs!E26*E$4)/(1+E$4)^4)+((Sector_KPIs!G19-Sector_KPIs!F26*E$4)/(1+E$4)^5)+(((Sector_KPIs!G19-Sector_KPIs!F26*E$4)*(1+$A8)/(E$4-$A8))/(1+E$4)^5)) -> 53425.57 | F8: =IF(F$4<=$A8,"N/M",Historical!C8+((Sector_KPIs!C19-Historical!C8*F$4)/(1+F$4)^1)+((Sector_KPIs!D19-Sector_KPIs!C26*F$4)/(1+F$4)^2)+((Sector_KPIs!E19-Sector_KPIs!D26*F$4)/(1+F$4)^3)+((Sector_KPIs!F19-Sector_KPIs!E26*F$4)/(1+F$4)^4)+((Sector_KPIs!G19-Sector_KPIs!F26*F$4)/(1+F$4)^5)+(((Sector_KPIs!G19-Sector_KPIs!F26*F$4)*(1+$A8)/(F$4-$A8))/(1+F$4)^5)) -> 47252.065
A9: 0.07 | B9: =IF(B$4<=$A9,"N/M",Historical!C8+((Sector_KPIs!C19-Historical!C8*B$4)/(1+B$4)^1)+((Sector_KPIs!D19-Sector_KPIs!C26*B$4)/(1+B$4)^2)+((Sector_KPIs!E19-Sector_KPIs!D26*B$4)/(1+B$4)^3)+((Sector_KPIs!F19-Sector_KPIs!E26*B$4)/(1+B$4)^4)+((Sector_KPIs!G19-Sector_KPIs!F26*B$4)/(1+B$4)^5)+(((Sector_KPIs!G19-Sector_KPIs!F26*B$4)*(1+$A9)/(B$4-$A9))/(1+B$4)^5)) -> 95801.145 | C9: =IF(C$4<=$A9,"N/M",Historical!C8+((Sector_KPIs!C19-Historical!C8*C$4)/(1+C$4)^1)+((Sector_KPIs!D19-Sector_KPIs!C26*C$4)/(1+C$4)^2)+((Sector_KPIs!E19-Sector_KPIs!D26*C$4)/(1+C$4)^3)+((Sector_KPIs!F19-Sector_KPIs!E26*C$4)/(1+C$4)^4)+((Sector_KPIs!G19-Sector_KPIs!F26*C$4)/(1+C$4)^5)+(((Sector_KPIs!G19-Sector_KPIs!F26*C$4)*(1+$A9)/(C$4-$A9))/(1+C$4)^5)) -> 76480.333 | D9: =IF(D$4<=$A9,"N/M",Historical!C8+((Sector_KPIs!C19-Historical!C8*D$4)/(1+D$4)^1)+((Sector_KPIs!D19-Sector_KPIs!C26*D$4)/(1+D$4)^2)+((Sector_KPIs!E19-Sector_KPIs!D26*D$4)/(1+D$4)^3)+((Sector_KPIs!F19-Sector_KPIs!E26*D$4)/(1+D$4)^4)+((Sector_KPIs!G19-Sector_KPIs!F26*D$4)/(1+D$4)^5)+(((Sector_KPIs!G19-Sector_KPIs!F26*D$4)*(1+$A9)/(D$4-$A9))/(1+D$4)^5)) -> 63606.062 | E9: =IF(E$4<=$A9,"N/M",Historical!C8+((Sector_KPIs!C19-Historical!C8*E$4)/(1+E$4)^1)+((Sector_KPIs!D19-Sector_KPIs!C26*E$4)/(1+E$4)^2)+((Sector_KPIs!E19-Sector_KPIs!D26*E$4)/(1+E$4)^3)+((Sector_KPIs!F19-Sector_KPIs!E26*E$4)/(1+E$4)^4)+((Sector_KPIs!G19-Sector_KPIs!F26*E$4)/(1+E$4)^5)+(((Sector_KPIs!G19-Sector_KPIs!F26*E$4)*(1+$A9)/(E$4-$A9))/(1+E$4)^5)) -> 54415.242 | F9: =IF(F$4<=$A9,"N/M",Historical!C8+((Sector_KPIs!C19-Historical!C8*F$4)/(1+F$4)^1)+((Sector_KPIs!D19-Sector_KPIs!C26*F$4)/(1+F$4)^2)+((Sector_KPIs!E19-Sector_KPIs!D26*F$4)/(1+F$4)^3)+((Sector_KPIs!F19-Sector_KPIs!E26*F$4)/(1+F$4)^4)+((Sector_KPIs!G19-Sector_KPIs!F26*F$4)/(1+F$4)^5)+(((Sector_KPIs!G19-Sector_KPIs!F26*F$4)*(1+$A9)/(F$4-$A9))/(1+F$4)^5)) -> 47526.34
A11: Active-case reconstruction | B11: Value | C11: Valuation output | D11: Difference | E11: Tolerance | F11: Status
A12: Dynamic RI sensitivity reconstruction | B12: =Historical!C8+((Sector_KPIs!C19-Historical!C8*Assumptions!E16)/(1+Assumptions!E16)^1)+((Sector_KPIs!D19-Sector_KPIs!C26*Assumptions!E16)/(1+Assumptions!E16)^2)+((Sector_KPIs!E19-Sector_KPIs!D26*Assumptions!E16)/(1+Assumptions!E16)^3)+((Sector_KPIs!F19-Sector_KPIs!E26*Assumptions!E16)/(1+Assumptions!E16)^4)+((Sector_KPIs!G19-Sector_KPIs!F26*Assumptions!E16)/(1+Assumptions!E16)^5)+(((Sector_KPIs!G19-Sector_KPIs!F26*Assumptions!E16)*(1+Assumptions!E17)/(Assumptions!E16-Assumptions!E17))/(1+Assumptions!E16)^5) -> 59704.572 | C12: =Valuation!G23 -> 59704.572 | D12: =B12-C12 -> 0 | E12: 0.1 | F12: =IF(ABS(D12)<=E12,"PASS","FAIL") -> PASS
A14: Central Base case is CoE 13.0% / g 5.0%. Bull/Bear selector tests also change loans, NII, net income and the valuation output. The active-case reconstruction remains exact under all three cases. | B14: Central Base case is CoE 13.0% / g 5.0%. Bull/Bear selector tests also change loans, NII, net income and the valuation output. The active-case reconstruction remains exact under all three cases. | C14: Central Base case is CoE 13.0% / g 5.0%. Bull/Bear selector tests also change loans, NII, net income and the valuation output. The active-case reconstruction remains exact under all three cases. | D14: Central Base case is CoE 13.0% / g 5.0%. Bull/Bear selector tests also change loans, NII, net income and the valuation output. The active-case reconstruction remains exact under all three cases. | E14: Central Base case is CoE 13.0% / g 5.0%. Bull/Bear selector tests also change loans, NII, net income and the valuation output. The active-case reconstruction remains exact under all three cases. | F14: Central Base case is CoE 13.0% / g 5.0%. Bull/Bear selector tests also change loans, NII, net income and the valuation output. The active-case reconstruction remains exact under all three cases.
A15: Central Base case is CoE 13.0% / g 5.0%. Bull/Bear selector tests also change loans, NII, net income and the valuation output. The active-case reconstruction remains exact under all three cases. | B15: Central Base case is CoE 13.0% / g 5.0%. Bull/Bear selector tests also change loans, NII, net income and the valuation output. The active-case reconstruction remains exact under all three cases. | C15: Central Base case is CoE 13.0% / g 5.0%. Bull/Bear selector tests also change loans, NII, net income and the valuation output. The active-case reconstruction remains exact under all three cases. | D15: Central Base case is CoE 13.0% / g 5.0%. Bull/Bear selector tests also change loans, NII, net income and the valuation output. The active-case reconstruction remains exact under all three cases. | E15: Central Base case is CoE 13.0% / g 5.0%. Bull/Bear selector tests also change loans, NII, net income and the valuation output. The active-case reconstruction remains exact under all three cases. | F15: Central Base case is CoE 13.0% / g 5.0%. Bull/Bear selector tests also change loans, NII, net income and the valuation output. The active-case reconstruction remains exact under all three cases.

Sheet Checks
A1: Formula-driven model checks | B1: Formula-driven model checks | C1: Formula-driven model checks | D1: Formula-driven model checks | E1: Formula-driven model checks | F1: Formula-driven model checks | G1: Formula-driven model checks | H1: Formula-driven model checks
A2: Each assertion exposes Actual, Expected, Difference, Tolerance, Status and a fix location. Overall status aggregates component checks. | B2: Each assertion exposes Actual, Expected, Difference, Tolerance, Status and a fix location. Overall status aggregates component checks. | C2: Each assertion exposes Actual, Expected, Difference, Tolerance, Status and a fix location. Overall status aggregates component checks. | D2: Each assertion exposes Actual, Expected, Difference, Tolerance, Status and a fix location. Overall status aggregates component checks. | E2: Each assertion exposes Actual, Expected, Difference, Tolerance, Status and a fix location. Overall status aggregates component checks. | F2: Each assertion exposes Actual, Expected, Difference, Tolerance, Status and a fix location. Overall status aggregates component checks. | G2: Each assertion exposes Actual, Expected, Difference, Tolerance, Status and a fix location. Overall status aggregates component checks. | H2: Each assertion exposes Actual, Expected, Difference, Tolerance, Status and a fix location. Overall status aggregates component checks.
A4: Check | B4: Actual | C4: Expected | D4: Difference | E4: Tolerance | F4: Status | G4: Severity | H4: Location / fix hint
A5: Source ledger completeness | B5: =Sources!O28 -> 23 | C5: 23 | D5: =B5-C5 -> 0 | E5: 0 | F5: =IF(ABS(D5)<=E5,"PASS","FAIL") -> PASS | G5: Critical | H5: Sources!A4:P28; populate every mandatory field
A6: Gross loans do not exceed total assets | B6: =Historical!C6 -> 285207.4 | C6: =Historical!C5 -> 384657.72 | D6: =C6-B6 -> 99450.32 | E6: 0 | F6: =IF(D6>=E6,"PASS","FAIL") -> PASS | G6: Critical | H6: Historical!C5:C6; verify source units and perimeter
A7: Loan growth formula | B7: =Sector_KPIs!C6 -> 0.06 | C7: =Assumptions!E6 -> 0.06 | D7: =B7-C7 -> 0 | E7: 1e-06 | F7: =IF(ABS(D7)<=E7,"PASS","FAIL") -> PASS | G7: Critical | H7: Sector_KPIs!C5:C6 / Assumptions!E6
A8: Net interest income mechanics | B8: =Sector_KPIs!C11 -> 18213.344 | C8: =Sector_KPIs!C9*Sector_KPIs!C10 -> 18213.344 | D8: =B8-C8 -> 0 | E8: 0.1 | F8: =IF(ABS(D8)<=E8,"PASS","FAIL") -> PASS | G8: Critical | H8: Sector_KPIs!C9:C11
A9: Equity roll-forward | B9: =Sector_KPIs!C26 -> 46747.66 | C9: =Sector_KPIs!B26+Sector_KPIs!C19-Sector_KPIs!C25 -> 46747.66 | D9: =B9-C9 -> 0 | E9: 0.1 | F9: =IF(ABS(D9)<=E9,"PASS","FAIL") -> PASS | G9: Critical | H9: Sector_KPIs!B19:C26
A10: Core solvency above floor | B10: =Sector_KPIs!C28 -> 0.12506564 | C10: =Sector_KPIs!C23 -> 0.115 | D10: =B10-C10 -> 0.010065641 | E10: 0 | F10: =IF(D10>=E10,"PASS","FAIL") -> PASS | G10: Critical | H10: Sector_KPIs!C21:C28 / payout constraint
A11: CoE exceeds terminal growth | B11: =Assumptions!E16 -> 0.13 | C11: =Assumptions!E17 -> 0.05 | D11: =B11-C11 -> 0.08 | E11: 0.01 | F11: =IF(D11>E11,"PASS","FAIL") -> PASS | G11: Critical | H11: Assumptions!E16:E17
A12: Dynamic sensitivity ties valuation | B12: =Sensitivity!B12 -> 59704.572 | C12: =Sensitivity!C12 -> 59704.572 | D12: =B12-C12 -> 0 | E12: =Sensitivity!E12 -> 0.1 | F12: =IF(ABS(D12)<=E12,"PASS","FAIL") -> PASS | G12: Critical | H12: Sensitivity!A11:F12 / Valuation!G23
A13: Scenario selector valid | B13: =Assumptions!B3 -> 1 | C13: 1 | D13: =IF(OR(B13=1,B13=2,B13=3),0,1) -> 0 | E13: 0 | F13: =IF(D13=E13,"PASS","FAIL") -> PASS | G13: Critical | H13: Assumptions!B3; return to Base = 1
A14: No capital-forced negative dividend | B14: =MIN(Sector_KPIs!C25:G25) -> 3654.9152 | C14: 0 | D14: =B14-C14 -> 3654.9152 | E14: 0 | F14: =IF(D14>=E14,"PASS","FAIL") -> PASS | G14: Critical | H14: Sector_KPIs!C24:G25
A15: Overall model status | B15: =IF(COUNTIF(F5:F14,"PASS")=10,"PASS","FAIL") -> PASS | H15: All critical checks must pass

Sheet Sector_KPIs
A1: Bank drivers, credit, capital and payout schedule | B1: Bank drivers, credit, capital and payout schedule | C1: Bank drivers, credit, capital and payout schedule | D1: Bank drivers, credit, capital and payout schedule | E1: Bank drivers, credit, capital and payout schedule | F1: Bank drivers, credit, capital and payout schedule | G1: Bank drivers, credit, capital and payout schedule | H1: Bank drivers, credit, capital and payout schedule
