Workbook

Sheet EEFF
A1: Empresa de Distribución Eléctrica Metro-Oeste, S. A.
A2: Estados Financieros Auditados FY24-FY25 (año fiscal al 31 de diciembre)
A3: en B/. sin escala
A5: Años | B5: FY21A | C5: FY22A | D5: FY23A | E5: FY24A | F5: FY25A | G5: FY26E | H5: FY27E | I5: FY28E | J5: FY29E | K5: FY30E
A6: Estado de Resultados
A7: Ingresos por actividades ordinarias | E7: 872479782 | F7: 910833173
A8: Aprovisionamientos | E8: -615692748 | F8: -661106024
A9: Reparaciones y conservación | E9: -21731420 | F9: -19594455
A10: Depreciación y amortización | E10: -48347878 | F10: -53346452
A11: Total de ganancia bruta por actividades ordinarias | E11: 186707736 | F11: 176786242
A12: Gastos de personal | E12: -9105171 | F12: -10322383
A13: Otros gastos | E13: -45818642 | F13: -43618338
A14: Resultado de las actividades de operaciones | E14: 131783923 | F14: 122845521
A15: Gastos financieros | E15: -76941269 | F15: -73951611
A16: Ingresos financieros | E16: 4648031 | F16: 6411378
A17: Pérdida neta en tipos de cambio de moneda extranjera | E17: -318727 | F17: -995436
A18: Utilidad antes del impuesto sobre la renta | E18: 59171958 | F18: 54309852
... A22: Resultados integrales del año | E22: 39807058 | F22: 36942971
A24: Años | B24: FY21A | C24: FY22A | D24: FY23A | E24: FY24A | F24: FY25A | G24: FY26E | H24: FY27E | I24: FY28E | J24: FY29E | K24: FY30E
A25: Balance General
A26: Inmovilizados materiales | E26: 1102383248 | F26: 1229864857
A27: Otros activos no corrientes | E27: 6636716 | F27: 7488557
A28: Activos intangibles | E28: 1435537 | F28: 1231687
A29: Activos por derecho de uso | E29: 310903 | F29: 5557215
A30: Total de activos no corrientes | E30: 1110766404 | F30: 1244142316
A31: Clientes y otras cuentas por cobrar | E31: 295555709 | F31: 247443512
A32: Efectivo | E32: 62979274 | F32: 207018868
A33: Otros activos corrientes | E33: 2493427 | F33: 4814532
A34: Total de activos corrientes | E34: 361028410 | F34: 459276912
A35: Total de activos | E35: 1471794814 | F35: 1703419228
A36: Deuda financiera a largo plazo | E36: 504216550 | F36: 827072790
A37: Bonos por pagar a largo plazo | E37: 0 | F37: 123843760
... A52: Total de pasivos y patrimonio | E52: 1471794814 | F52: 1703419228
A54: Años | B54: FY21A | C54: FY22A | D54: FY23A | E54: FY24A | F54: FY25A | G54: FY26E | H54: FY27E | I54: FY28E | J54: FY29E | K54: FY30E
A55: Estado de Flujos de Efectivo
A56: Utilidad neta | E56: 39800939 | F56: 37173332
A57: Gastos financieros | E57: 76941269 | F57: 73951611
A58: Ingresos financieros | E58: -4648031 | F58: -6411378
A59: Ingresos por subvención de capital | E59: -1778843 | F59: -2663029
A60: Depreciación de inmovilizados materiales | E60: 46727986 | F60: 51526696
...

Sheet Notas_EEFF
A1: Empresa de Distribución Eléctrica Metro-Oeste, S. A.
A2: Notas a los Estados Financieros
A3: Fuente: informes auditados vía OCR Mistral (verbatim).
A5: Año | B5: Documento fuente | C5: Página OCR | D5: Tabla OCR / sección | E5: Nota # | F5: Título original de la nota | G5: Categoría modelable | H5: Line item EEFF | I5: Sub-line item / detalle | J5: Texto original / disclosure | K5: Monto reportado | L5: Moneda | M5: Unidad / escala | N5: Fecha / venc. / tasa / plazo | O5: Contraparte / contrato / instrumento | P5: Impacto en Supuestos | Q5: Impacto en ModeloFinanciero | R5: Link a celda EEFF | S5: Comentario de extracción | T5: Status
A6: 2025 | B6: INA_EDEMET_2025_0.pdf | C6: page-107 | D6: tbl-83.html | E6: 5 | F6: 5. Saldos y Transacciones con Partes Relacionadas. continuación | G6: Partes relacionadas | J6: [tbl-83.html](tbl-83.html)(tbl-82.html)(tbl-82.html) | T6: OK
A7: 2025 | B7: INA_EDEMET_2025_0.pdf | C7: page-107 | D7: markdown.md | E7: 5 | F7: 5. Saldos y Transacciones con Partes Relacionadas. continuación | G7: Partes relacionadas | J7: Los saldos y transacciones con partes relacionadas incluyen los mantenidos con el Gobierno de Panamá (el “Gobierno”) y entidades autónomas. El Gobierno, accionista de la Compañía en un 47,86% (ver Nota 1), tiene participación e influencia significativa en las entidades de generación y distribución eléctrica mixtas de Panamá. En el caso de la entidad de transmisión, el Gobierno mantiene el 100% de control de las entidades que prestan este servicio, como lo es la Empresa de Transmisión Eléctrica, S. A. (ETESA). Dado a que el Gobierno tiene participación en las tres distribuidoras y en algunas generadoras eléctricas del país, el ingreso por venta de energía por montos importantes es efectuado a dichas entidades. | T7: OK
A8: 2025 | B8: INA_EDEMET_2025_0.pdf | C8: page-107 | D8: markdown.md | E8: 6 | F8: 6. Inmovilizados Materiales | G8: Otros | J8: A continuación, se presenta la composición de los inmovilizados materiales: | T8: OK
A9: 2025 | B9: INA_EDEMET_2025_0.pdf | C9: page-107 | D9: tbl-83.html | E9: 6 | F9: 6. Inmovilizados Materiales | G9: Otros | J9: [tbl-83.html](tbl-83.html) | T9: OK
A10: 2025 | B10: INA_EDEMET_2025_0.pdf | C10: page-108 | D10: markdown.md | E10: 6 | F10: 6. Inmovilizados Materiales | G10: Otros | J10: # **Empresa de Distribución Eléctrica Chiriquí, S. A.** (Entidad 51% Propiedad de Distribuidora Eléctrica del Caribe, S. A.) | T10: OK
A11: 2025 | B11: INA_EDEMET_2025_0.pdf | C11: page-108 | D11: markdown.md | E11: 6 | F11: 6. Inmovilizados Materiales | G11: Otros | J11: # **Notas a los Estados Financieros** | T11: OK
A12: 2025 | B12: INA_EDEMET_2025_0.pdf | C12: page-108 | D12: markdown.md | E12: 6 | F12: 6. Inmovilizados Materiales, continuación | G12: Otros | J12: El movimiento del inmovilizado material en explotación se presenta a continuación: | T12: OK
A13: 2025 | B13: INA_EDEMET_2025_0.pdf | C13: page-108 | D13: tbl-84.html | E13: 6 | F13: 6. Inmovilizados Materiales, continuación | G13: Otros | J13: [tbl-84.html](tbl-84.html)(tbl-84.html) | T13: OK
A14: 2025 | B14: INA_EDEMET_2025_0.pdf | C14: page-109 | D14: markdown.md | E14: 6 | F14: 6. Inmovilizados Materiales, continuación | G14: Otros | J14: # **Notas a los Estados Financieros**--- | T14: OK
A15: 2025 | B15: INA_EDEMET_2025_0.pdf | C15: page-109 | D15: markdown.md | E15: 6 | F15: 6. Inmovilizados Materiales, continuación | G15: Otros | J15: La Compañía tiene formalizadas pólizas de seguros para cubrir los posibles riesgos a que están sujetos los diversos elementos de su inmovilizado material, así como las posibles reclamaciones que se le puedan presentar por el ejercicio de su actividad, entendiendo que dichas pólizas cubren de manera suficiente los riesgos a los que están sometidos. | T15: OK
A16: 2025 | B16: INA_EDEMET_2025_0.pdf | C16: page-109 | D16: markdown.md | E16: 6 | F16: 6. Inmovilizados Materiales, continuación | G16: Otros | J16: Los materiales de almacén de consumo se detallan a continuación: | T16: OK
A17: 2025 | B17: INA_EDEMET_2025_0.pdf | C17: page-109 | D17: tbl-86.html | E17: 6 | F17: 6. Inmovilizados Materiales, continuación | G17: Otros | J17: [tbl-86.html](tbl-86.html)(tbl-85.html)(tbl-85.html) | T17: OK
... A19: 2025 | B19: INA_EDEMET_2025_0.pdf | C19: page-109 | D19: markdown.md | E19: 6 | F19: 6. Inmovilizados Materiales, continuación | G19: Otros | J19: La Compañía ha contratado a operadores logísticos, otorgando así la administración de sus inventarios a terceros, que incluye la recepción, descarga, almacenamiento, control del inventario, siendo de esta forma ellos responsables de todos los materiales pertenecientes a la Compañía y que fueron depositados para su custodia. | T19: OK
A20: 2025 | B20: INA_EDEMET_2025_0.pdf | C20: page-109 | D20: markdown.md | E20: 6 | F20: 6. Inmovilizados Materiales, continuación | G20: Otros | J20: Los costos capitalizados también incluyen los gastos de personal relacionados directamente con las obras en curso. Los importes capitalizados por estos conceptos que se excluyen de la cuenta de resultados ascienden a B/.1,166,699 (2024: B/.1,333,108) (véase Nota 17). | K20: 1166699 | L20: B/. | T20: OK
A21: 2025 | B21: INA_EDEMET_2025_0.pdf | C21: page-109 | D21: markdown.md | E21: 6 | F21: 6. Inmovilizados Materiales, continuación | G21: Otros | J21: Para efectos de conciliación con el estado de flujos de efectivo, las adquisiciones de inmovilizados materiales presentadas como flujos de efectivos de actividades de inversiones se presentan netas del cambio neto de materiales de almacén del año, como se detalla a continuación: | T21: OK
A22: 2025 | B22: INA_EDEMET_2025_0.pdf | C22: page-109 | D22: tbl-86.html | E22: 6 | F22: 6. Inmovilizados Materiales, continuación | G22: Otros | J22: [tbl-86.html](tbl-86.html) | T22: OK
A23: 2025 | B23: INA_EDEMET_2025_0.pdf | C23: page-109 | D23: markdown.md | E23: 6 | F23: 6. Inmovilizados Materiales, continuación | G23: Otros | J23: Al 31 de diciembre de 2025, la Compañía mantiene compromisos para la ejecución de inversiones por un monto de B/.17,537,249, concentrados específicamente en calidad y expansión de la red eléctrica. | K23: 17537249 | L23: B/. | T23: OK
A24: 2025 | B24: INA_EDEMET_2025_0.pdf | C24: page-110 | D24: markdown.md | E24: 7 | F24: 7. Otros Activos | G24: Otros | J24: A continuación, se presenta el detalle de los otros activos: | T24: OK
A25: 2025 | B25: INA_EDEMET_2025_0.pdf | C25: page-110 | D25: tbl-88.html | E25: 7 | F25: 7. Otros Activos | G25: Otros | J25: [tbl-88.html](tbl-88.html)(tbl-87.html)(tbl-87.html) | T25: OK
A26: 2025 | B26: INA_EDEMET_2025_0.pdf | C26: page-110 | D26: markdown.md | E26: 8 | F26: 8. Clientes y Otras Cuentas por Cobrar | G26: Cuentas por cobrar | J26: Los saldos por cobrar a clientes y otras cuentas por cobrar se detallan a continuación: | T26: OK
A27: 2025 | B27: INA_EDEMET_2025_0.pdf | C27: page-110 | D27: tbl-88.html | E27: 8 | F27: 8. Clientes y Otras Cuentas por Cobrar | G27: Cuentas por cobrar | J27: [tbl-88.html](tbl-88.html) | T27: OK
A28: 2025 | B28: INA_EDEMET_2025_0.pdf | C28: page-110 | D28: markdown.md | E28: 8 | F28: 8. Clientes y Otras Cuentas por Cobrar | G28: Cuentas por cobrar | J28: # **Cuentas por Cobrar a Clientes** | T28: OK
A29: 2025 | B29: INA_EDEMET_2025_0.pdf | C29: page-110 | D29: markdown.md | E29: 8 | F29: 8. Clientes y Otras Cuentas por Cobrar | G29: Cuentas por cobrar | J29: Las cuentas por cobrar a clientes comprenden cantidades por cobrar por el monto de la facturación de la energía suministrada. El período promedio de crédito es de 30 días, contados a partir de la fecha de la facturación de energía. | T29: OK
A30: 2025 | B30: INA_EDEMET_2025_0.pdf | C30: page-110 | D30: markdown.md | E30: 8 | F30: 8. Clientes y Otras Cuentas por Cobrar | G30: Cuentas por cobrar | J30: La Compañía mantiene una reserva para pérdidas crediticias esperadas de las cuentas por cobrar comerciales, calculada con un modelo simplificado. El cálculo de esta provisión corresponde a un reconocimiento de las pérdidas crediticias esperadas que proyecta la probabilidad de incumplimiento (no pago) en un lapso de un año. | T30: OK
A31: 2025 | B31: INA_EDEMET_2025_0.pdf | C31: page-111 | D31: markdown.md | E31: 8 | F31: 8. Clientes y Otras Cuentas por Cobrar | G31: Cuentas por cobrar | J31: # **Empresa de Distribución Eléctrica Chiriquí, S. A.** (Entidad 51% Propiedad de Distribuidora Eléctrica del Caribe, S. A.) | T31: OK
A32: 2025 | B32: INA_EDEMET_2025_0.pdf | C32: page-111 | D32: markdown.md | E32: 8 | F32: 8. Clientes y Otras Cuentas por Cobrar | G32: Cuentas por cobrar | J32: # **Notas a los Estados Financieros** | T32: OK
A33: 2025 | B33: INA_EDEMET_2025_0.pdf | C33: page-111 | D33: markdown.md | E33: 8 | F33: 8. Clientes y Otras Cuentas por Cobrar, continuación | G33: Cuentas por cobrar | J33: A cada obligación se le asigna una probabilidad individual de no pago que se calcula a partir de un modelo de probabilidad que involucra variables del producto y de su comportamiento de pago. El modelo calcula un porcentaje de pérdida histórica por tipo de mora, la cual se relaciona con un dato macroeconómico buscando una correlación para proyectar un comportamiento según la mejor estimación del crecimiento económico del país. | T33: OK
A34: 2025 | B34: INA_EDEMET_2025_0.pdf | C34: page-111 | D34: markdown.md | E34: 8 | F34: 8. Clientes y Otras Cuentas por Cobrar, continuación | G34: Cuentas por cobrar | J34: La proyección se aplicará al producto de los promedios de desplazamiento por rango de cartera según la mora histórica, la cual refleja la evolución del comportamiento de los saldos de la cartera de clientes y permite establecer los porcentajes de pérdida sobre hechos históricos. | T34: OK
A35: 2025 | B35: INA_EDEMET_2025_0.pdf | C35: page-111 | D35: markdown.md | E35: 8 | F35: 8. Clientes y Otras Cuentas por Cobrar, continuación | G35: Cuentas por cobrar | J35: El movimiento de la reserva para pérdidas crediticias esperadas se presenta a continuación: | T35: OK
... A45: 2025 | B45: INA_EDEMET_2025_0.pdf | C45: page-113 | D45: markdown.md | E45: 8 | F45: 8. Clientes y Otras Cuentas por Cobrar, continuación | G45: Cuentas por cobrar | J45: Las cuentas por cobrar a gobierno y entidades autónomas incluyen subsidios otorgados por el Gobierno al Fondo de Compensación Energética (FACE), Fondo de Estabilización Tarifaria (FET) y Fondo Tarifario de Occidente (FTO). Los subsidios registrados corresponden a lo acordado en la Ley No.15 de febrero de 2001 que establece el régimen y procedimiento a los que se sujetarán los subsidios destinados a los clientes del servicio público de electricidad, cuyo consumo califica como consumo básico o de subsistencia, y en el cual la administración y aplicación está a cargo de la Compañía, para la cual la Compañía efectúa una retención a algunos clientes y a su vez le concede un descuento a aquellos clientes sujetos al subsidio de acuerdo a lo que define la Ley como clientes de consumo básico o de subsistencias. | T45: OK
A46: 2025 | B46: INA_EDEMET_2025_0.pdf | C46: page-113 | D46: markdown.md | E46: 8 | F46: 8. Clientes y Otras Cuentas por Cobrar, continuación | G46: Cuentas por cobrar | J46: Durante el 2025, la Compañía recibió el pago de subsidios de parte de la Empresa de Transmisión Eléctrica, S.A. por un importe total de B/.83,095,239 (2024: B/.49,571,213). | K46: 83095239 | L46: B/. | T46: OK
A47: 2025 | B47: INA_EDEMET_2025_0.pdf | C47: page-113 | D47: markdown.md | E47: 8 | F47: 8. Clientes y Otras Cuentas por Cobrar, continuación | G47: Cuentas por cobrar | J47: Los saldos correspondientes a los reembolsos tarifarios del FACE y del FET que no hayan sido compensados en su totalidad por el Estado a través de ETESA, podrán ser incorporados en las actualizaciones semestrales, de acuerdo con lo dispuesto en el régimen tarifario vigente y sus modificaciones. | T47: OK
A48: 2025 | B48: INA_EDEMET_2025_0.pdf | C48: page-113 | D48: markdown.md | E48: 8 | F48: 8. Clientes y Otras Cuentas por Cobrar, continuación | G48: Cuentas por cobrar | J48: # **Activos Regulatorios** | T48: OK
A49: 2025 | B49: INA_EDEMET_2025_0.pdf | C49: page-113 | D49: markdown.md | E49: 8 | F49: 8. Clientes y Otras Cuentas por Cobrar, continuación | G49: Cuentas por cobrar | J49: Según se establece en el marco regulatorio vigente y dado que los costos estimados de abastecimientos reconocidos en la tarifa fueron diferentes a los costos reales del año 2025, la Compañía mantiene activos regulatorios por B/.10,797,318 (2024: B/.10,313,941), producto de desvíos tarifarios por B/.14,595,699 (2024: B/.9,772,664), menos recuperaciones en tarifa por B/.14,112,322 (2024: B/.14,190,532), según lo establecido en el régimen tarifario. | K49: 10797318 | L49: B/. | T49: OK
A50: 2025 | B50: INA_EDEMET_2025_0.pdf | C50: page-113 | D50: markdown.md | E50: 8 | F50: 8. Clientes y Otras Cuentas por Cobrar, continuación | G50: Cuentas por cobrar | J50: A continuación, el resumen de los movimientos de los desvíos tarifarios por costos de abastecimiento: | T50: OK
A51: 2025 | B51: INA_EDEMET_2025_0.pdf | C51: page-113 | D51: tbl-92.html | E51: 8 | F51: 8. Clientes y Otras Cuentas por Cobrar, continuación | G51: Cuentas por cobrar | J51: [tbl-92.html](tbl-92.html)(tbl-92.html) | T51: OK
...

Sheet Supuestos
A1: Empresa de Distribución Eléctrica Metro-Oeste, S. A.
A3: COLOR KEY: Input (azul) · Fórmula (negro) · Link inter-hoja (verde)
A4: Escenario (1=Base, 2=Bull, 3=Bear)
A5: Selector escenario | C5: 1 | M5: caso | N5: NOT_DISCLOSED | Q5: Input de escenario desde fuente citada o NOT_DISCLOSED.
A6: Escenario activo | C6: =CHOOSE($C$5,"Base","Bull","Bear") -> Base | M6: moneda del modelo | N6: NOT_DISCLOSED | Q6: Selector de caso activo C5: Base/Bull/Bear.
A8: Años | B8: FY21A | C8: FY22A | D8: FY23A | E8: FY24A | F8: FY25A | G8: FY26E | H8: FY27E | I8: FY28E | J8: FY29E | K8: FY30E | M8: Unidad | N8: Fuente / nota | Q8: Rationale
A10: A. INGRESOS — CRECIMIENTO (% YoY)
A11: Ingresos por actividades ordinarias — driver activo | G11: =CHOOSE($C$5,G13,G14,G12) -> 0.044 | H11: =CHOOSE($C$5,H13,H14,H12) -> 0.044 | I11: =CHOOSE($C$5,I13,I14,I12) -> 0.044 | J11: =CHOOSE($C$5,J13,J14,J12) -> 0.044 | K11: =CHOOSE($C$5,K13,K14,K12) -> 0.044 | M11: % | N11: EEFF:Ingresos por actividades ordinarias | Q11: Selector de caso activo C5: Base/Bull/Bear.
A12: Bear | G12: 0.024 | H12: 0.024 | I12: 0.024 | J12: 0.024 | K12: 0.024 | M12: % | N12: EEFF:Ingresos por actividades ordinarias | Q12: Escenario driver citado; NOT_DISCLOSED si no hay fuente explícita.
A13: Base | G13: 0.044 | H13: 0.044 | I13: 0.044 | J13: 0.044 | K13: 0.044 | M13: % | N13: EEFF:Ingresos por actividades ordinarias | Q13: Escenario driver citado; NOT_DISCLOSED si no hay fuente explícita.
A14: Bull | G14: 0.064 | H14: 0.064 | I14: 0.064 | J14: 0.064 | K14: 0.064 | M14: % | N14: EEFF:Ingresos por actividades ordinarias | Q14: Escenario driver citado; NOT_DISCLOSED si no hay fuente explícita.
A15: Ingresos por actividades ordinarias (hist, ref EEFF) | E15: =EEFF!E7 -> 872479782 | F15: =EEFF!F7 -> 910833173 | M15: moneda del modelo | N15: EEFF:Ingresos por actividades ordinarias | Q15: Mirror histórico desde fuente citada.
A16: Ingresos por actividades ordinarias YoY histórico (ref EEFF) | F16: =EEFF!F7/EEFF!E7-1 -> 0.04395906 | M16: % | N16: EEFF:Ingresos por actividades ordinarias | Q16: Fórmula viva: año actual / año previo - 1.
A18: B. APROVISIONAMIENTOS (% de ingresos)
A19: Aprovisionamientos — driver activo | G19: =CHOOSE($C$5,G21,G22,G20) -> -0.726 | H19: =CHOOSE($C$5,H21,H22,H20) -> -0.726 | I19: =CHOOSE($C$5,I21,I22,I20) -> -0.726 | J19: =CHOOSE($C$5,J21,J22,J20) -> -0.726 | K19: =CHOOSE($C$5,K21,K22,K20) -> -0.726 | M19: % | N19: EEFF:Aprovisionamientos | Q19: Selector de caso activo C5: Base/Bull/Bear.
A20: Bear | G20: -0.746 | H20: -0.746 | I20: -0.746 | J20: -0.746 | K20: -0.746 | M20: % | N20: EEFF:Aprovisionamientos | Q20: Escenario driver citado; NOT_DISCLOSED si no hay fuente explícita.
A21: Base | G21: -0.726 | H21: -0.726 | I21: -0.726 | J21: -0.726 | K21: -0.726 | M21: % | N21: EEFF:Aprovisionamientos | Q21: Escenario driver citado; NOT_DISCLOSED si no hay fuente explícita.
A22: Bull | G22: -0.706 | H22: -0.706 | I22: -0.706 | J22: -0.706 | K22: -0.706 | M22: % | N22: EEFF:Aprovisionamientos | Q22: Escenario driver citado; NOT_DISCLOSED si no hay fuente explícita.
A23: Aprovisionamientos ÷ Ingresos por actividades ordinarias (hist, ref EEFF) | E23: =IF(EEFF!E7=0,"",EEFF!E8/EEFF!E7) -> -0.70568139 | F23: =IF(EEFF!F7=0,"",EEFF!F8/EEFF!F7) -> -0.72582559 | M23: % | N23: EEFF:Aprovisionamientos / EEFF:Ingresos por actividades ordinarias | Q23: Mirror histórico desde fuente citada.
A25: C. REPARACIONES Y CONSERVACIÓN (% de ingresos)
A26: Reparaciones y conservación — driver activo | G26: =CHOOSE($C$5,G28,G29,G27) -> -0.022 | H26: =CHOOSE($C$5,H28,H29,H27) -> -0.022 | I26: =CHOOSE($C$5,I28,I29,I27) -> -0.022 | J26: =CHOOSE($C$5,J28,J29,J27) -> -0.022 | K26: =CHOOSE($C$5,K28,K29,K27) -> -0.022 | M26: % | N26: EEFF:Reparaciones y conservación | Q26: Selector de caso activo C5: Base/Bull/Bear.
A27: Bear | G27: -0.042 | H27: -0.042 | I27: -0.042 | J27: -0.042 | K27: -0.042 | M27: % | N27: EEFF:Reparaciones y conservación | Q27: Escenario driver citado; NOT_DISCLOSED si no hay fuente explícita.
A28: Base | G28: -0.022 | H28: -0.022 | I28: -0.022 | J28: -0.022 | K28: -0.022 | M28: % | N28: EEFF:Reparaciones y conservación | Q28: Escenario driver citado; NOT_DISCLOSED si no hay fuente explícita.
A29: Bull | G29: -0.002 | H29: -0.002 | I29: -0.002 | J29: -0.002 | K29: -0.002 | M29: % | N29: EEFF:Reparaciones y conservación | Q29: Escenario driver citado; NOT_DISCLOSED si no hay fuente explícita.
A30: Reparaciones y conservación ÷ Ingresos por actividades ordinarias (hist, ref EEFF) | E30: =IF(EEFF!E7=0,"",EEFF!E9/EEFF!E7) -> -0.024907649 | F30: =IF(EEFF!F7=0,"",EEFF!F9/EEFF!F7) -> -0.021512672 | M30: % | N30: EEFF:Reparaciones y conservación / EEFF:Ingresos por actividades ordinarias | Q30: Mirror histórico desde fuente citada.
A32: D. GASTOS DE PERSONAL (% de ingresos)
A33: Gastos de personal — driver activo | G33: =CHOOSE($C$5,G35,G36,G34) -> -0.011 | H33: =CHOOSE($C$5,H35,H36,H34) -> -0.011 | I33: =CHOOSE($C$5,I35,I36,I34) -> -0.011 | J33: =CHOOSE($C$5,J35,J36,J34) -> -0.011 | K33: =CHOOSE($C$5,K35,K36,K34) -> -0.011 | M33: % | N33: EEFF:Gastos de personal | Q33: Selector de caso activo C5: Base/Bull/Bear.
A34: Bear | G34: -0.031 | H34: -0.031 | I34: -0.031 | J34: -0.031 | K34: -0.031 | M34: % | N34: EEFF:Gastos de personal | Q34: Escenario driver citado; NOT_DISCLOSED si no hay fuente explícita.
A35: Base | G35: -0.011 | H35: -0.011 | I35: -0.011 | J35: -0.011 | K35: -0.011 | M35: % | N35: EEFF:Gastos de personal | Q35: Escenario driver citado; NOT_DISCLOSED si no hay fuente explícita.
A36: Bull | G36: 0.009 | H36: 0.009 | I36: 0.009 | J36: 0.009 | K36: 0.009 | M36: % | N36: EEFF:Gastos de personal | Q36: Escenario driver citado; NOT_DISCLOSED si no hay fuente explícita.
A37: Gastos de personal ÷ Ingresos por actividades ordinarias (hist, ref EEFF) | E37: =IF(EEFF!E7=0,"",EEFF!E12/EEFF!E7) -> -0.010435968 | F37: =IF(EEFF!F7=0,"",EEFF!F12/EEFF!F7) -> -0.011332902 | M37: % | N37: EEFF:Gastos de personal / EEFF:Ingresos por actividades ordinarias | Q37: Mirror histórico desde fuente citada.
A39: E. OTROS GASTOS (% de ingresos)
A40: Otros gastos — driver activo | G40: =CHOOSE($C$5,G42,G43,G41) -> -0.048 | H40: =CHOOSE($C$5,H42,H43,H41) -> -0.048 | I40: =CHOOSE($C$5,I42,I43,I41) -> -0.048 | J40: =CHOOSE($C$5,J42,J43,J41) -> -0.048 | K40: =CHOOSE($C$5,K42,K43,K41) -> -0.048 | M40: % | N40: EEFF:Otros gastos | Q40: Selector de caso activo C5: Base/Bull/Bear.
A41: Bear | G41: -0.068 | H41: -0.068 | I41: -0.068 | J41: -0.068 | K41: -0.068 | M41: % | N41: EEFF:Otros gastos | Q41: Escenario driver citado; NOT_DISCLOSED si no hay fuente explícita.
A42: Base | G42: -0.048 | H42: -0.048 | I42: -0.048 | J42: -0.048 | K42: -0.048 | M42: % | N42: EEFF:Otros gastos | Q42: Escenario driver citado; NOT_DISCLOSED si no hay fuente explícita.
A43: Bull | G43: -0.028 | H43: -0.028 | I43: -0.028 | J43: -0.028 | K43: -0.028 | M43: % | N43: EEFF:Otros gastos | Q43: Escenario driver citado; NOT_DISCLOSED si no hay fuente explícita.
A44: Otros gastos ÷ Ingresos por actividades ordinarias (hist, ref EEFF) | E44: =IF(EEFF!E7=0,"",EEFF!E13/EEFF!E7) -> -0.05251542 | F44: =IF(EEFF!F7=0,"",EEFF!F13/EEFF!F7) -> -0.047888394 | M44: % | N44: EEFF:Otros gastos / EEFF:Ingresos por actividades ordinarias | Q44: Mirror histórico desde fuente citada.
A46: F. TASA EFECTIVA DE IMPUESTO (% de UAI)
A47: Impuesto sobre la renta — driver activo | G47: =CHOOSE($C$5,G49,G50,G48) -> -0.316 | H47: =CHOOSE($C$5,H49,H50,H48) -> -0.316 | I47: =CHOOSE($C$5,I49,I50,I48) -> -0.316 | J47: =CHOOSE($C$5,J49,J50,J48) -> -0.316 | K47: =CHOOSE($C$5,K49,K50,K48) -> -0.316 | M47: % | N47: EEFF:Impuesto sobre la renta | Q47: Selector de caso activo C5: Base/Bull/Bear.
A48: Bear | G48: -0.316 | H48: -0.316 | I48: -0.316 | J48: -0.316 | K48: -0.316 | M48: % | N48: EEFF:Impuesto sobre la renta | Q48: Escenario driver citado; NOT_DISCLOSED si no hay fuente explícita.
...

Sheet ModeloFinanciero
A1: Empresa de Distribución Eléctrica Metro-Oeste, S. A.
A2: Estados Financieros Auditados FY24-FY25 (año fiscal al 31 de diciembre)
A3: en B/. sin escala
A5: Años | B5: FY21A | C5: FY22A | D5: FY23A | E5: FY24A | F5: FY25A | G5: FY26E | H5: FY27E | I5: FY28E | J5: FY29E | K5: FY30E
A6: Estado de Resultados
A7: Ingresos por actividades ordinarias | E7: =EEFF!E7 -> 872479782 | F7: =EEFF!F7 -> 910833173 | G7: =F7*(1+Supuestos!G11) -> 9.5090983e+08 | H7: =G7*(1+Supuestos!H11) -> 9.9274987e+08 | I7: =H7*(1+Supuestos!I11) -> 1.0364309e+09 | J7: =I7*(1+Supuestos!J11) -> 1.0820338e+09 | K7: =J7*(1+Supuestos!K11) -> 1.1296433e+09
A8: Aprovisionamientos | E8: =EEFF!E8 -> -615692748 | F8: =EEFF!F8 -> -661106024 | G8: =G7*Supuestos!G19 -> -6.9036054e+08 | H8: =H7*Supuestos!H19 -> -7.207364e+08 | I8: =I7*Supuestos!I19 -> -7.524488e+08 | J8: =J7*Supuestos!J19 -> -7.8555655e+08 | K8: =K7*Supuestos!K19 -> -8.2012104e+08
A9: Reparaciones y conservación | E9: =EEFF!E9 -> -21731420 | F9: =EEFF!F9 -> -19594455 | G9: =G7*Supuestos!G26 -> -20920016 | H9: =H7*Supuestos!H26 -> -21840497 | I9: =I7*Supuestos!I26 -> -22801479 | J9: =J7*Supuestos!J26 -> -23804744 | K9: =K7*Supuestos!K26 -> -24852153
A10: Depreciación y amortización | E10: =EEFF!E10 -> -48347878 | F10: =EEFF!F10 -> -53346452 | G10: =-(G60+G61+G62) -> -53346452 | H10: =-(H60+H61+H62) -> -53346452 | I10: =-(I60+I61+I62) -> -53346452 | J10: =-(J60+J61+J62) -> -53346452 | K10: =-(K60+K61+K62) -> -53346452
A11: Total de ganancia bruta por actividades ordinarias | E11: =EEFF!E11 -> 186707736 | F11: =EEFF!F11 -> 176786242 | G11: =G7+G8+G9+G10 -> 1.8628283e+08 | H11: =H7+H8+H9+H10 -> 1.9682651e+08 | I11: =I7+I8+I9+I10 -> 2.0783412e+08 | J11: =J7+J8+J9+J10 -> 2.1932607e+08 | K11: =K7+K8+K9+K10 -> 2.3132366e+08
A12: Gastos de personal | E12: =EEFF!E12 -> -9105171 | F12: =EEFF!F12 -> -10322383 | G12: =G7*Supuestos!G33 -> -10460008 | H12: =H7*Supuestos!H33 -> -10920249 | I12: =I7*Supuestos!I33 -> -11400739 | J12: =J7*Supuestos!J33 -> -11902372 | K12: =K7*Supuestos!K33 -> -12426076
A13: Otros gastos | E13: =EEFF!E13 -> -45818642 | F13: =EEFF!F13 -> -43618338 | G13: =G7*Supuestos!G40 -> -45643672 | H13: =H7*Supuestos!H40 -> -47651994 | I13: =I7*Supuestos!I40 -> -49748681 | J13: =J7*Supuestos!J40 -> -51937623 | K13: =K7*Supuestos!K40 -> -54222879
A14: Resultado de las actividades de operaciones | E14: =EEFF!E14 -> 131783923 | F14: =EEFF!F14 -> 122845521 | G14: =G11+G12+G13 -> 1.3017915e+08 | H14: =H11+H12+H13 -> 1.3825427e+08 | I14: =I11+I12+I13 -> 1.466847e+08 | J14: =J11+J12+J13 -> 1.5548607e+08 | K14: =K11+K12+K13 -> 1.6467471e+08
A15: Gastos financieros | E15: =EEFF!E15 -> -76941269 | F15: =EEFF!F15 -> -73951611 | G15: =F15 -> -73951611 | H15: =G15 -> -73951611 | I15: =H15 -> -73951611 | J15: =I15 -> -73951611 | K15: =J15 -> -73951611
A16: Ingresos financieros | E16: =EEFF!E16 -> 4648031 | F16: =EEFF!F16 -> 6411378 | G16: =F16 -> 6411378 | H16: =G16 -> 6411378 | I16: =H16 -> 6411378 | J16: =I16 -> 6411378 | K16: =J16 -> 6411378
A17: Pérdida neta en tipos de cambio de moneda extranjera | E17: =EEFF!E17 -> -318727 | F17: =EEFF!F17 -> -995436 | G17: =F17 -> -995436 | H17: =G17 -> -995436 | I17: =H17 -> -995436 | J17: =I17 -> -995436 | K17: =J17 -> -995436
A18: Utilidad antes del impuesto sobre la renta | E18: =EEFF!E18 -> 59171958 | F18: =EEFF!F18 -> 54309852 | G18: =G14+G15+G16+G17 -> 61643477 | H18: =H14+H15+H16+H17 -> 69718603 | I18: =I14+I15+I16+I17 -> 78149035 | J18: =J14+J15+J16+J17 -> 86950406 | K18: =K14+K15+K16+K17 -> 96139037
A19: Impuesto sobre la renta | E19: =EEFF!E19 -> -19371019 | F19: =EEFF!F19 -> -17136520 | G19: =G18*Supuestos!G47 -> -19479339 | H19: =H18*Supuestos!H47 -> -22031079 | I19: =I18*Supuestos!I47 -> -24695095 | J19: =J18*Supuestos!J47 -> -27476328 | K19: =K18*Supuestos!K47 -> -30379936
A20: Utilidad neta | E20: =EEFF!E20 -> 39800939 | F20: =EEFF!F20 -> 37173332 | G20: =G18+G19 -> 42164138 | H20: =H18+H19 -> 47687524 | I20: =I18+I19 -> 53453940 | J20: =J18+J19 -> 59474078 | K20: =K18+K19 -> 65759101
A21: Ganancia (pérdida) actuarial sobre las obligaciones por beneficios post-empleo | E21: =EEFF!E21 -> 6119 | F21: =EEFF!F21 -> -230361 | G21: =F21 -> -230361 | H21: =G21 -> -230361 | I21: =H21 -> -230361 | J21: =I21 -> -230361 | K21: =J21 -> -230361
A22: Resultados integrales del año | E22: =EEFF!E22 -> 39807058 | F22: =EEFF!F22 -> 36942971 | G22: =G20+G21 -> 41933777 | H22: =H20+H21 -> 47457163 | I22: =I20+I21 -> 53223579 | J22: =J20+J21 -> 59243717 | K22: =K20+K21 -> 65528740
A24: Años | B24: FY21A | C24: FY22A | D24: FY23A | E24: FY24A | F24: FY25A | G24: FY26E | H24: FY27E | I24: FY28E | J24: FY29E | K24: FY30E
A25: Balance General
A26: Inmovilizados materiales | E26: =EEFF!E26 -> 1102383248 | F26: =EEFF!F26 -> 1229864857 | G26: =F26 -> 1229864857 | H26: =G26 -> 1229864857 | I26: =H26 -> 1229864857 | J26: =I26 -> 1229864857 | K26: =J26 -> 1229864857
A27: Otros activos no corrientes | E27: =EEFF!E27 -> 6636716 | F27: =EEFF!F27 -> 7488557 | G27: =F27 -> 7488557 | H27: =G27 -> 7488557 | I27: =H27 -> 7488557 | J27: =I27 -> 7488557 | K27: =J27 -> 7488557
A28: Activos intangibles | E28: =EEFF!E28 -> 1435537 | F28: =EEFF!F28 -> 1231687 | G28: =F28 -> 1231687 | H28: =G28 -> 1231687 | I28: =H28 -> 1231687 | J28: =I28 -> 1231687 | K28: =J28 -> 1231687
A29: Activos por derecho de uso | E29: =EEFF!E29 -> 310903 | F29: =EEFF!F29 -> 5557215 | G29: =F29 -> 5557215 | H29: =G29 -> 5557215 | I29: =H29 -> 5557215 | J29: =I29 -> 5557215 | K29: =J29 -> 5557215
A30: Total de activos no corrientes | E30: =EEFF!E30 -> 1110766404 | F30: =EEFF!F30 -> 1244142316 | G30: =F30 -> 1244142316 | H30: =G30 -> 1244142316 | I30: =H30 -> 1244142316 | J30: =I30 -> 1244142316 | K30: =J30 -> 1244142316
A31: Clientes y otras cuentas por cobrar | E31: =EEFF!E31 -> 295555709 | F31: =EEFF!F31 -> 247443512 | G31: =F31 -> 247443512 | H31: =G31 -> 247443512 | I31: =H31 -> 247443512 | J31: =I31 -> 247443512 | K31: =J31 -> 247443512
A32: Efectivo | E32: =EEFF!E32 -> 62979274 | F32: =EEFF!F32 -> 207018868 | G32: =F32 -> 207018868 | H32: =G32 -> 207018868 | I32: =H32 -> 207018868 | J32: =I32 -> 207018868 | K32: =J32 -> 207018868
A33: Otros activos corrientes | E33: =EEFF!E33 -> 2493427 | F33: =EEFF!F33 -> 4814532 | G33: =F33 -> 4814532 | H33: =G33 -> 4814532 | I33: =H33 -> 4814532 | J33: =I33 -> 4814532 | K33: =J33 -> 4814532
A34: Total de activos corrientes | E34: =EEFF!E34 -> 361028410 | F34: =EEFF!F34 -> 459276912 | G34: =F34 -> 459276912 | H34: =G34 -> 459276912 | I34: =H34 -> 459276912 | J34: =I34 -> 459276912 | K34: =J34 -> 459276912
A35: Total de activos | E35: =EEFF!E35 -> 1471794814 | F35: =EEFF!F35 -> 1703419228 | G35: =F35 -> 1703419228 | H35: =G35 -> 1703419228 | I35: =H35 -> 1703419228 | J35: =I35 -> 1703419228 | K35: =J35 -> 1703419228
A36: Deuda financiera a largo plazo | E36: =EEFF!E36 -> 504216550 | F36: =EEFF!F36 -> 827072790 | G36: =F36 -> 827072790 | H36: =G36 -> 827072790 | I36: =H36 -> 827072790 | J36: =I36 -> 827072790 | K36: =J36 -> 827072790
A37: Bonos por pagar a largo plazo | E37: =EEFF!E37 -> 0 | F37: =EEFF!F37 -> 123843760 | G37: =F37 -> 123843760 | H37: =G37 -> 123843760 | I37: =H37 -> 123843760 | J37: =I37 -> 123843760 | K37: =J37 -> 123843760
... A52: Total de pasivos y patrimonio | E52: =EEFF!E52 -> 1471794814 | F52: =EEFF!F52 -> 1703419228 | G52: =F52 -> 1703419228 | H52: =G52 -> 1703419228 | I52: =H52 -> 1703419228 | J52: =I52 -> 1703419228 | K52: =J52 -> 1703419228
A54: Años | B54: FY21A | C54: FY22A | D54: FY23A | E54: FY24A | F54: FY25A | G54: FY26E | H54: FY27E | I54: FY28E | J54: FY29E | K54: FY30E
A55: Estado de Flujos de Efectivo
A56: Utilidad neta | E56: =EEFF!E56 -> 39800939 | F56: =EEFF!F56 -> 37173332 | G56: =F56 -> 37173332 | H56: =G56 -> 37173332 | I56: =H56 -> 37173332 | J56: =I56 -> 37173332 | K56: =J56 -> 37173332
A57: Gastos financieros | E57: =EEFF!E57 -> 76941269 | F57: =EEFF!F57 -> 73951611 | G57: =F57 -> 73951611 | H57: =G57 -> 73951611 | I57: =H57 -> 73951611 | J57: =I57 -> 73951611 | K57: =J57 -> 73951611
...

Sheet PP&E_Schedule
A1: Empresa de Distribución Eléctrica Metro-Oeste, S. A.
A2: PP&E_Schedule — propiedad, planta y equipo (saldo + capex − depreciación ± bajas, tie EEFF)
A3: Balance: EEFF/ModeloFinanciero (PP&E neto). Movimientos: Estado de Flujos de Efectivo, líneas explícitamente identificadas — sin desglose de notas (nota de PP&E no extraída aún) las líneas no reveladas se marcan NOT_DISCLOSED, nunca se estiman.
A5: Años | B5: FY21A | C5: FY22A | D5: FY23A | E5: FY24A | F5: FY25A | G5: FY26E | H5: FY27E | I5: FY28E | J5: FY29E | K5: FY30E
A7: A. SALDO PP&E, NETO (balance)
A8: PP&E, neto (referencia EEFF/ModeloFinanciero) | B8: =ModeloFinanciero!B26 -> 0 | C8: =ModeloFinanciero!C26 -> 0 | D8: =ModeloFinanciero!D26 -> 0 | E8: =EEFF!E26 -> 1102383248 | F8: =EEFF!F26 -> 1229864857 | G8: =ModeloFinanciero!G26 -> 1229864857 | H8: =ModeloFinanciero!H26 -> 1229864857 | I8: =ModeloFinanciero!I26 -> 1229864857 | J8: =ModeloFinanciero!J26 -> 1229864857 | K8: =ModeloFinanciero!K26 -> 1229864857
A10: B. MOVIMIENTOS (Estado de Flujos de Efectivo)
A11: Saldo inicial (PP&E neto EOP año anterior) | C11: =B8 -> 0 | D11: =C8 -> 0 | E11: =D8 -> 0 | F11: =E8 -> 1102383248 | G11: =F8 -> 1229864857 | H11: =G8 -> 1229864857 | I11: =H8 -> 1229864857 | J11: =I8 -> 1229864857 | K11: =J8 -> 1229864857
A12: (+) Capex / adquisición de PP&E | B12: =ModeloFinanciero!B76 -> 0 | C12: =ModeloFinanciero!C76 -> 0 | D12: =ModeloFinanciero!D76 -> 0 | E12: =EEFF!E76 -> -121066785 | F12: =EEFF!F76 -> -179149611 | G12: =ModeloFinanciero!G76 -> -179149611 | H12: =ModeloFinanciero!H76 -> -179149611 | I12: =ModeloFinanciero!I76 -> -179149611 | J12: =ModeloFinanciero!J76 -> -179149611 | K12: =ModeloFinanciero!K76 -> -179149611
A13: (−) Depreciación de PP&E | B13: =ModeloFinanciero!B60 -> 0 | C13: =ModeloFinanciero!C60 -> 0 | D13: =ModeloFinanciero!D60 -> 0 | E13: =EEFF!E60 -> 46727986 | F13: =EEFF!F60 -> 51526696 | G13: =ModeloFinanciero!G60 -> 51526696 | H13: =ModeloFinanciero!H60 -> 51526696 | I13: =ModeloFinanciero!I60 -> 51526696 | J13: =ModeloFinanciero!J60 -> 51526696 | K13: =ModeloFinanciero!K60 -> 51526696
A15: BAJAS_A_VALOR_EN_LIBROS_NOT_DISCLOSED: el filing no divulga el valor en libros de los activos dados de baja (solo producto de venta / pérdida P&L); el roll-forward no resta bajas — el residual, si existe, absorbe ese componente no divulgado.
A17: Saldo final computado (inicial + capex − depreciación; N/A en el primer año, sin saldo inicial) | C17: =C11-C12-C13 -> 0 | D17: =D11-D12-D13 -> 0 | E17: =E11-E12-E13 -> 74338799 | F17: =F11-F12-F13 -> 1230006163 | G17: =G11-G12-G13 -> 1357487772 | H17: =H11-H12-H13 -> 1357487772 | I17: =I11-I12-I13 -> 1357487772 | J17: =J11-J12-J13 -> 1357487772 | K17: =K11-K12-K13 -> 1357487772
A19: C. TIE-OUT
A20: CHECK Δ saldo final computado − PP&E balance (residual = capex/depreciación/bajas no desglosadas) | C20: =C17-C8 -> 0 | D20: =D17-D8 -> 0 | E20: =E17-E8 -> -1028044449 | F20: =F17-F8 -> 141306 | G20: =G17-G8 -> 127622915 | H20: =H17-H8 -> 127622915 | I20: =I17-I8 -> 127622915 | J20: =J17-J8 -> 127622915 | K20: =K17-K8 -> 127622915

Sheet Intangibles
A1: Empresa de Distribución Eléctrica Metro-Oeste, S. A.
A2: Intangibles — activos intangibles amortizables + plusvalía (memo)
A3: Balance: EEFF/ModeloFinanciero (intangibles neto). Movimientos: Flujo de Efectivo. Plusvalía (si existe) se presenta aparte — no amortiza bajo NIIF, solo deterioro (no computado sin nota).
A5: Años | B5: FY21A | C5: FY22A | D5: FY23A | E5: FY24A | F5: FY25A | G5: FY26E | H5: FY27E | I5: FY28E | J5: FY29E | K5: FY30E
A7: A. INTANGIBLES AMORTIZABLES
A8: Intangibles, neto (referencia EEFF/ModeloFinanciero) | B8: =ModeloFinanciero!B28 -> 0 | C8: =ModeloFinanciero!C28 -> 0 | D8: =ModeloFinanciero!D28 -> 0 | E8: =EEFF!E28 -> 1435537 | F8: =EEFF!F28 -> 1231687 | G8: =ModeloFinanciero!G28 -> 1231687 | H8: =ModeloFinanciero!H28 -> 1231687 | I8: =ModeloFinanciero!I28 -> 1231687 | J8: =ModeloFinanciero!J28 -> 1231687 | K8: =ModeloFinanciero!K28 -> 1231687
A10: Saldo inicial (intangibles neto EOP año anterior) | C10: =B8 -> 0 | D10: =C8 -> 0 | E10: =D8 -> 0 | F10: =E8 -> 1435537 | G10: =F8 -> 1231687 | H10: =G8 -> 1231687 | I10: =H8 -> 1231687 | J10: =I8 -> 1231687 | K10: =J8 -> 1231687
A11: (+) Adquisición de activos intangibles | B11: =ModeloFinanciero!B77 -> 0 | C11: =ModeloFinanciero!C77 -> 0 | D11: =ModeloFinanciero!D77 -> 0 | E11: =EEFF!E77 -> -604998 | F11: =EEFF!F77 -> -608529 | G11: =ModeloFinanciero!G77 -> -608529 | H11: =ModeloFinanciero!H77 -> -608529 | I11: =ModeloFinanciero!I77 -> -608529 | J11: =ModeloFinanciero!J77 -> -608529 | K11: =ModeloFinanciero!K77 -> -608529
A12: (−) Amortización de intangibles | B12: =ModeloFinanciero!B62 -> 0 | C12: =ModeloFinanciero!C62 -> 0 | D12: =ModeloFinanciero!D62 -> 0 | E12: =EEFF!E62 -> 1191479 | F12: =EEFF!F62 -> 812379 | G12: =ModeloFinanciero!G62 -> 812379 | H12: =ModeloFinanciero!H62 -> 812379 | I12: =ModeloFinanciero!I62 -> 812379 | J12: =ModeloFinanciero!J62 -> 812379 | K12: =ModeloFinanciero!K62 -> 812379
A13: Saldo final computado (inicial + adiciones − amortización; N/A en el primer año) | C13: =C10-C11-C12 -> 0 | D13: =D10-D11-D12 -> 0 | E13: =E10-E11-E12 -> -586481 | F13: =F10-F11-F12 -> 1231687 | G13: =G10-G11-G12 -> 1027837 | H13: =H10-H11-H12 -> 1027837 | I13: =I10-I11-I12 -> 1027837 | J13: =J10-J11-J12 -> 1027837 | K13: =K10-K11-K12 -> 1027837
A15: B. TIE-OUT
A16: CHECK Δ saldo final computado − intangibles balance (residual = bajas/otros no desglosados) | C16: =C13-C8 -> 0 | D16: =D13-D8 -> 0 | E16: =E13-E8 -> -2022018 | F16: =F13-F8 -> 0 | G16: =G13-G8 -> -203850 | H16: =H13-H8 -> -203850 | I16: =I13-I8 -> -203850 | J16: =J13-J8 -> -203850 | K16: =K13-K8 -> -203850

Sheet ROU_Lease_Schedule
A1: Empresa de Distribución Eléctrica Metro-Oeste, S. A.
A2: ROU_Lease_Schedule — activo por derecho de uso + pasivo por arrendamiento (NIIF 16)
A3: Balance: EEFF/ModeloFinanciero. Movimientos: Flujo de Efectivo. Nuevos arrendamientos reconocidos (no-cash) NOT_DISCLOSED salvo nota específica — no se estiman.
A5: Años | B5: FY21A | C5: FY22A | D5: FY23A | E5: FY24A | F5: FY25A | G5: FY26E | H5: FY27E | I5: FY28E | J5: FY29E | K5: FY30E
A7: A. ACTIVO POR DERECHO DE USO
A8: Activo por derecho de uso, neto (referencia EEFF/ModeloFinanciero) | B8: =ModeloFinanciero!B29 -> 0 | C8: =ModeloFinanciero!C29 -> 0 | D8: =ModeloFinanciero!D29 -> 0 | E8: =EEFF!E29 -> 310903 | F8: =EEFF!F29 -> 5557215 | G8: =ModeloFinanciero!G29 -> 5557215 | H8: =ModeloFinanciero!H29 -> 5557215 | I8: =ModeloFinanciero!I29 -> 5557215 | J8: =ModeloFinanciero!J29 -> 5557215 | K8: =ModeloFinanciero!K29 -> 5557215
A10: Saldo inicial (ROU neto EOP año anterior) | C10: =B8 -> 0 | D10: =C8 -> 0 | E10: =D8 -> 0 | F10: =E8 -> 310903 | G10: =F8 -> 5557215 | H10: =G8 -> 5557215 | I10: =H8 -> 5557215 | J10: =I8 -> 5557215 | K10: =J8 -> 5557215
A12: NOT_DISCLOSED: nuevos arrendamientos reconocidos (adición no-cash) no identificables en el Flujo de Efectivo.
A13: (−) Depreciación/amortización del activo por derecho de uso | B13: =ModeloFinanciero!B61 -> 0 | C13: =ModeloFinanciero!C61 -> 0 | D13: =ModeloFinanciero!D61 -> 0 | E13: =EEFF!E61 -> 428415 | F13: =EEFF!F61 -> 1007377 | G13: =ModeloFinanciero!G61 -> 1007377 | H13: =ModeloFinanciero!H61 -> 1007377 | I13: =ModeloFinanciero!I61 -> 1007377 | J13: =ModeloFinanciero!J61 -> 1007377 | K13: =ModeloFinanciero!K61 -> 1007377
A14: Saldo final computado (inicial − depreciación − disposiciones; sin adiciones no divulgadas; N/A en el primer año) | C14: =C10-C13 -> 0 | D14: =D10-D13 -> 0 | E14: =E10-E13 -> -428415 | F14: =F10-F13 -> -696474 | G14: =G10-G13 -> 4549838 | H14: =H10-H13 -> 4549838 | I14: =I10-I13 -> 4549838 | J14: =J10-J13 -> 4549838 | K14: =K10-K13 -> 4549838
A15: CHECK Δ ROU computado − ROU balance (residual = adiciones no divulgadas) | C15: =C14-C8 -> 0 | D15: =D14-D8 -> 0 | E15: =E14-E8 -> -739318 | F15: =F14-F8 -> -6253689 | G15: =G14-G8 -> -1007377 | H15: =H14-H8 -> -1007377 | I15: =I14-I8 -> -1007377 | J15: =J14-J8 -> -1007377 | K15: =K14-K8 -> -1007377
A17: B. PASIVO POR ARRENDAMIENTO
A18: Pasivo por arrendamiento — no corriente | B18: =ModeloFinanciero!B40 -> 0 | C18: =ModeloFinanciero!C40 -> 0 | D18: =ModeloFinanciero!D40 -> 0 | E18: =EEFF!E40 -> 153995 | F18: =EEFF!F40 -> 5038023 | G18: =ModeloFinanciero!G40 -> 5038023 | H18: =ModeloFinanciero!H40 -> 5038023 | I18: =ModeloFinanciero!I40 -> 5038023 | J18: =ModeloFinanciero!J40 -> 5038023 | K18: =ModeloFinanciero!K40 -> 5038023
A19: Pasivo por arrendamiento — corriente | B19: =ModeloFinanciero!B48 -> 0 | C19: =ModeloFinanciero!C48 -> 0 | D19: =ModeloFinanciero!D48 -> 0 | E19: =EEFF!E48 -> 254137 | F19: =EEFF!F48 -> 698172 | G19: =ModeloFinanciero!G48 -> 698172 | H19: =ModeloFinanciero!H48 -> 698172 | I19: =ModeloFinanciero!I48 -> 698172 | J19: =ModeloFinanciero!J48 -> 698172 | K19: =ModeloFinanciero!K48 -> 698172
A20: Total pasivo por arrendamiento | B20: =B18+B19 -> 0 | C20: =C18+C19 -> 0 | D20: =D18+D19 -> 0 | E20: =E18+E19 -> 408132 | F20: =F18+F19 -> 5736195 | G20: =G18+G19 -> 5736195 | H20: =H18+H19 -> 5736195 | I20: =I18+I19 -> 5736195 | ... K20: =K18+K19 -> 5736195
A22: Saldo inicial (pasivo total EOP año anterior) | C22: =B20 -> 0 | D22: =C20 -> 0 | E22: =D20 -> 0 | F22: =E20 -> 408132 | G22: =F20 -> 5736195 | H22: =G20 -> 5736195 | I22: =H20 -> 5736195 | J22: =I20 -> 5736195 | K22: =J20 -> 5736195
A24: NOT_DISCLOSED: nuevos arrendamientos reconocidos (adición de pasivo no-cash) no identificables en el Flujo de Efectivo.
A25: NOT_DISCLOSED: sin línea de pago de arrendamientos identificable en el Flujo de Efectivo.
A26: Saldo final computado (inicial − pagos de principal; sin adiciones no divulgadas; N/A en el primer año) | C26: =C22 -> 0 | D26: =D22 -> 0 | E26: =E22 -> 0 | F26: =F22 -> 408132 | G26: =G22 -> 5736195 | H26: =H22 -> 5736195 | I26: =I22 -> 5736195 | J26: =J22 -> 5736195 | K26: =K22 -> 5736195
A27: CHECK Δ pasivo computado − pasivo balance (residual = adiciones no divulgadas) | C27: =C26-C20 -> 0 | D27: =D26-D20 -> 0 | E27: =E26-E20 -> -408132 | F27: =F26-F20 -> -5328063 | G27: =G26-G20 -> 0 | H27: =H26-H20 -> 0 | I27: =I26-I20 -> 0 | J27: =J26-J20 -> 0 | K27: =K26-K20 -> 0
A29: C. MEMO (informativo, no es un CHECK)
A30: Activo ROU − Pasivo por arrendamiento (delta esperado por incentivos/prepagos; no es un error) | B30: =B8-B20 -> 0 | C30: =C8-C20 -> 0 | D30: =D8-D20 -> 0 | E30: =E8-E20 -> -97229 | F30: =F8-F20 -> -178980 | G30: =G8-G20 -> -178980 | H30: =H8-H20 -> -178980 | I30: =I8-I20 -> -178980 | ... K30: =K8-K20 -> -178980

Sheet Debt_Schedule
A1: Empresa de Distribución Eléctrica Metro-Oeste, S. A.
A2: Debt_Schedule — deuda financiera (saldo + draws − amortización; tie balance e intereses P&L)
A3: Balance: EEFF/ModeloFinanciero (deuda corriente + no corriente, excl. arrendamientos → ver ROU_Lease_Schedule). Movimientos e intereses: Flujo de Efectivo / Estado de Resultados.
A5: Años | B5: FY21A | C5: FY22A | D5: FY23A | E5: FY24A | F5: FY25A | G5: FY26E | H5: FY27E | I5: FY28E | J5: FY29E | K5: FY30E
A7: A. SALDO DE DEUDA (balance)
A8: Deuda financiera — no corriente | B8: =SUM(ModeloFinanciero!B36,ModeloFinanciero!B37) -> 0 | C8: =SUM(ModeloFinanciero!C36,ModeloFinanciero!C37) -> 0 | D8: =SUM(ModeloFinanciero!D36,ModeloFinanciero!D37) -> 0 | E8: =SUM(EEFF!E36,EEFF!E37) -> 504216550 | F8: =SUM(EEFF!F36,EEFF!F37) -> 950916550 | G8: =SUM(ModeloFinanciero!G36,ModeloFinanciero!G37) -> 950916550 | H8: =SUM(ModeloFinanciero!H36,ModeloFinanciero!H37) -> 950916550 | I8: =SUM(ModeloFinanciero!I36,ModeloFinanciero!I37) -> 950916550 | J8: =SUM(ModeloFinanciero!J36,ModeloFinanciero!J37) -> 950916550 | K8: =SUM(ModeloFinanciero!K36,ModeloFinanciero!K37) -> 950916550
A9: Deuda financiera — corriente | B9: =SUM(ModeloFinanciero!B42,ModeloFinanciero!B43) -> 0 | C9: =SUM(ModeloFinanciero!C42,ModeloFinanciero!C43) -> 0 | D9: =SUM(ModeloFinanciero!D42,ModeloFinanciero!D43) -> 0 | E9: =SUM(EEFF!E42,EEFF!E43) -> 429069814 | F9: =SUM(EEFF!F42,EEFF!F43) -> 145761703 | G9: =SUM(ModeloFinanciero!G42,ModeloFinanciero!G43) -> 145761703 | H9: =SUM(ModeloFinanciero!H42,ModeloFinanciero!H43) -> 145761703 | I9: =SUM(ModeloFinanciero!I42,ModeloFinanciero!I43) -> 145761703 | J9: =SUM(ModeloFinanciero!J42,ModeloFinanciero!J43) -> 145761703 | K9: =SUM(ModeloFinanciero!K42,ModeloFinanciero!K43) -> 145761703
A10: Total deuda financiera | B10: =B8+B9 -> 0 | C10: =C8+C9 -> 0 | D10: =D8+D9 -> 0 | E10: =E8+E9 -> 933286364 | F10: =F8+F9 -> 1096678253 | G10: =G8+G9 -> 1096678253 | H10: =H8+H9 -> 1096678253 | I10: =I8+I9 -> 1096678253 | ... K10: =K8+K9 -> 1096678253
A12: B. MOVIMIENTOS (Estado de Flujos de Efectivo)
A13: Saldo inicial (deuda total EOP año anterior) | C13: =B10 -> 0 | D13: =C10 -> 0 | E13: =D10 -> 0 | F13: =E10 -> 933286364 | G13: =F10 -> 1096678253 | H13: =G10 -> 1096678253 | I13: =H10 -> 1096678253 | J13: =I10 -> 1096678253 | K13: =J10 -> 1096678253
A14: (+) Desembolsos / producto de nueva deuda | B14: =ModeloFinanciero!B81 -> 0 | C14: =ModeloFinanciero!C81 -> 0 | D14: =ModeloFinanciero!D81 -> 0 | E14: =EEFF!E81 -> 589173940 | F14: =EEFF!F81 -> 535436240 | G14: =ModeloFinanciero!G81 -> 535436240 | H14: =ModeloFinanciero!H81 -> 535436240 | I14: =ModeloFinanciero!I81 -> 535436240 | J14: =ModeloFinanciero!J81 -> 535436240 | K14: =ModeloFinanciero!K81 -> 535436240
A15: (−) Abonos / cancelaciones de deuda | B15: =ModeloFinanciero!B80 -> 0 | C15: =ModeloFinanciero!C80 -> 0 | D15: =ModeloFinanciero!D80 -> 0 | E15: =EEFF!E80 -> -469071611 | F15: =EEFF!F80 -> -495046445 | G15: =ModeloFinanciero!G80 -> -495046445 | H15: =ModeloFinanciero!H80 -> -495046445 | I15: =ModeloFinanciero!I80 -> -495046445 | J15: =ModeloFinanciero!J80 -> -495046445 | K15: =ModeloFinanciero!K80 -> -495046445
A16: Saldo final computado (inicial + desembolsos − abonos; N/A en el primer año) | C16: =C13+C14+C15 -> 0 | D16: =D13+D14+D15 -> 0 | E16: =E13+E14+E15 -> 120102329 | F16: =F13+F14+F15 -> 973676159 | G16: =G13+G14+G15 -> 1137068048 | H16: =H13+H14+H15 -> 1137068048 | I16: =I13+I14+I15 -> 1137068048 | J16: =J13+J14+J15 -> 1137068048 | K16: =K13+K14+K15 -> 1137068048
A18: C. TIE-OUT E INTERESES (P&L)
A19: CHECK Δ deuda computada − deuda balance (residual = costos de emisión/FX/reclasificaciones no desglosadas) | C19: =C16-C10 -> 0 | D19: =D16-D10 -> 0 | E19: =E16-E10 -> -813184035 | F19: =F16-F10 -> -123002094 | G19: =G16-G10 -> 40389795 | H19: =H16-H10 -> 40389795 | I19: =I16-I10 -> 40389795 | J19: =J16-J10 -> 40389795 | K19: =K16-K10 -> 40389795
A20: Intereses financieros del período (ABS, Estado de Resultados) | B20: =ABS(ModeloFinanciero!B15) -> 0 | C20: =ABS(ModeloFinanciero!C15) -> 0 | D20: =ABS(ModeloFinanciero!D15) -> 0 | E20: =ABS(EEFF!E15) -> 76941269 | F20: =ABS(EEFF!F15) -> 73951611 | G20: =ABS(ModeloFinanciero!G15) -> 73951611 | H20: =ABS(ModeloFinanciero!H15) -> 73951611 | I20: =ABS(ModeloFinanciero!I15) -> 73951611 | J20: =ABS(ModeloFinanciero!J15) -> 73951611 | K20: =ABS(ModeloFinanciero!K15) -> 73951611
A21: Tasa de interés efectiva (memo: intereses ÷ deuda promedio BOP/EOP; N/A en el primer año) | C21: =IF((C13+C10)=0,"",C20/((C13+C10)/2)) | D21: =IF((D13+D10)=0,"",D20/((D13+D10)/2)) | E21: =E20/((E13+E10)/2) -> 0.16488245 | F21: =F20/((F13+F10)/2) -> 0.07286 | G21: =G20/((G13+G10)/2) -> 0.067432368 | H21: =H20/((H13+H10)/2) -> 0.067432368 | I21: =I20/((I13+I10)/2) -> 0.067432368 | J21: =J20/((J13+J10)/2) -> 0.067432368 | K21: =K20/((K13+K10)/2) -> 0.067432368

Sheet _CHECKS
A1: Empresa de Distribución Eléctrica Metro-Oeste, S. A.
A2: _CHECKS panel — utility template, live formulas, known residuals signed visible
A3: Status semantics: PASS = zero undocumented hard failures; KNOWN_RESIDUAL = signed G7 residual; SOURCE_GAP = unresolved semantic anchor/schedule.
A4: MASTER_STATUS | B4: MODEL STATUS | C4: =IF(COUNTIF($C$6:$C$32,"FAIL")=0,"PASS","FAIL") -> PASS | G4: Master PASS counts only FAIL rows; KNOWN_RESIDUAL/SOURCE_GAP remain visible but non-blocking.
A5: check_id | B5: description | C5: status | D5: hardness | E5: tolerance | F5: expected | G5: note | H5: FY21A | I5: FY22A | J5: FY23A | K5: FY24A | L5: FY25A | M5: FY26E | N5: FY27E | O5: FY28E | P5: FY29E | Q5: FY30E
A7: UNIVERSAL CHECKS
A8: BS_BALANCE | B8: UNIVERSAL | expected 0; hard fail if ABS(value) > hard_tie_tolerance. Observed: UEPII critical gate <10 for BS/cash; BG hard reconciliation >=1000 because full USD. | source applies_to: all 16 archetypes | C8: =IF(SUMPRODUCT((ABS(H8:Q8)>1000)*1)=0,"PASS","FAIL") -> PASS | D8: hard | E8: 1000 USD | F8: 0 | G8: expected 0; hard fail if ABS(value) > hard_tie_tolerance. Observed: UEPII critical gate <10 for BS/cash; BG hard reconciliation >=1000 because full USD. Default full-USD hard tie threshold is $1,000 unless the workbook declares a tighter scale-aware tolerance. | H8: =ModeloFinanciero!B35-ModeloFinanciero!B52 -> 0 | I8: =ModeloFinanciero!C35-ModeloFinanciero!C52 -> 0 | J8: =ModeloFinanciero!D35-ModeloFinanciero!D52 -> 0 | K8: =ModeloFinanciero!E35-ModeloFinanciero!E52 -> 0 | L8: =ModeloFinanciero!F35-ModeloFinanciero!F52 -> 0 | M8: =ModeloFinanciero!G35-ModeloFinanciero!G52 -> 0 | N8: =ModeloFinanciero!H35-ModeloFinanciero!H52 -> 0 | O8: =ModeloFinanciero!I35-ModeloFinanciero!I52 -> 0 | ... Q8: =ModeloFinanciero!K35-ModeloFinanciero!K52 -> 0
A9: CASH_TIE | B9: UNIVERSAL | expected 0; use hard_tie_tolerance; if cash includes restricted cash/time deposits, define cash_component role explicitly. | source applies_to: all 16 archetypes | C9: =IF(SUMPRODUCT((ABS(H9:Q9)>1000)*1)=0,"PASS","FAIL") -> PASS | D9: hard | E9: 1000 USD | F9: 0 | G9: Observed hard tie threshold for model-to-model cash residuals; define cash-component role when restricted cash/time deposits exist. | H9: =ModeloFinanciero!B91-ModeloFinanciero!B32 -> 0 | I9: =ModeloFinanciero!C91-ModeloFinanciero!C32 -> 0 | J9: =ModeloFinanciero!D91-ModeloFinanciero!D32 -> 0 | K9: =ModeloFinanciero!E91-ModeloFinanciero!E32 -> 0 | L9: =ModeloFinanciero!F91-ModeloFinanciero!F32 -> 0
A10: CF_ROLLFORWARD | B10: UNIVERSAL | expected 0; hard_tie_tolerance; historical rows may be WARN if source CF transcript is incomplete. | source applies_to: all 16 where CF is modeled | C10: =IF(SUMPRODUCT((ABS(H10:Q10)>1000)*1)=0,"PASS","FAIL") -> PASS | D10: hard | E10: 1000 USD | F10: 0 | G10: expected 0; hard_tie_tolerance; historical rows may be WARN if source CF transcript is incomplete. Default full-USD hard tie threshold is $1,000 unless the workbook declares a tighter scale-aware tolerance. | H10: =ModeloFinanciero!B75+ModeloFinanciero!B79+ModeloFinanciero!B88-(ModeloFinanciero!B91-ModeloFinanciero!B90) -> 0 | I10: =ModeloFinanciero!C75+ModeloFinanciero!C79+ModeloFinanciero!C88-(ModeloFinanciero!C91-ModeloFinanciero!C90) -> 0 | J10: =ModeloFinanciero!D75+ModeloFinanciero!D79+ModeloFinanciero!D88-(ModeloFinanciero!D91-ModeloFinanciero!D90) -> 0 | K10: =ModeloFinanciero!E75+ModeloFinanciero!E79+ModeloFinanciero!E88-(ModeloFinanciero!E91-ModeloFinanciero!E90) -> 0 | L10: =ModeloFinanciero!F75+ModeloFinanciero!F79+ModeloFinanciero!F88-(ModeloFinanciero!F91-ModeloFinanciero!F90) -> 0 | M10: =ModeloFinanciero!G75+ModeloFinanciero!G79+ModeloFinanciero!G88-(ModeloFinanciero!G91-ModeloFinanciero!G90) -> 0 | N10: =ModeloFinanciero!H75+ModeloFinanciero!H79+ModeloFinanciero!H88-(ModeloFinanciero!H91-ModeloFinanciero!H90) -> 0 | O10: =ModeloFinanciero!I75+ModeloFinanciero!I79+ModeloFinanciero!I88-(ModeloFinanciero!I91-ModeloFinanciero!I90) -> 0 | ... Q10: =ModeloFinanciero!K75+ModeloFinanciero!K79+ModeloFinanciero!K88-(ModeloFinanciero!K91-ModeloFinanciero!K90) -> 0
A11: NI_TIE_TO_EQUITY | B11: UNIVERSAL | expected 0; hard_tie_tolerance. | source applies_to: all 16 | C11: =IF(SUMPRODUCT((ABS(H11:Q11)>1000)*1)=0,"PASS","FAIL") -> PASS | D11: hard | E11: 1000 USD | F11: 0 | G11: expected 0; hard_tie_tolerance. Default full-USD hard tie threshold is $1,000 unless the workbook declares a tighter scale-aware tolerance. | H11: =ModeloFinanciero!B20-ModeloFinanciero!B56 -> 0 | I11: =ModeloFinanciero!C20-ModeloFinanciero!C56 -> 0 | J11: =ModeloFinanciero!D20-ModeloFinanciero!D56 -> 0 | K11: =ModeloFinanciero!E20-ModeloFinanciero!E56 -> 0 | L11: =ModeloFinanciero!F20-ModeloFinanciero!F56 -> 0
A12: NI_SIGN_SANITY | B12: UNIVERSAL | expected 0; sign convention must be stated in row description. | source applies_to: all 16 | C12: SOURCE_GAP | D12: hard | E12: 1000 USD | F12: 0 | G12: Sign convention diagnostic remains visible; tax-sign taxonomy is not a signed hard-control anchor. | H12: =ModeloFinanciero!B20-(ModeloFinanciero!B18-ABS(ModeloFinanciero!B19)) -> 0 | I12: =ModeloFinanciero!C20-(ModeloFinanciero!C18-ABS(ModeloFinanciero!C19)) -> 0 | J12: =ModeloFinanciero!D20-(ModeloFinanciero!D18-ABS(ModeloFinanciero!D19)) -> 0 | K12: =ModeloFinanciero!E20-(ModeloFinanciero!E18-ABS(ModeloFinanciero!E19)) -> 0 | L12: =ModeloFinanciero!F20-(ModeloFinanciero!F18-ABS(ModeloFinanciero!F19)) -> 0 | M12: =ModeloFinanciero!G20-(ModeloFinanciero!G18-ABS(ModeloFinanciero!G19)) -> 0 | N12: =ModeloFinanciero!H20-(ModeloFinanciero!H18-ABS(ModeloFinanciero!H19)) -> 0 | O12: =ModeloFinanciero!I20-(ModeloFinanciero!I18-ABS(ModeloFinanciero!I19)) -> 0 | ... Q12: =ModeloFinanciero!K20-(ModeloFinanciero!K18-ABS(ModeloFinanciero!K19)) -> 0
A13: RE_ROLLFORWARD | B13: UNIVERSAL | expected 0; hard_tie_tolerance. | source applies_to: all 16 with RE row | C13: SOURCE_GAP | D13: hard | E13: 1000 USD | F13: 0 | G13: No semantic anchors resolved for RE_ROLLFORWARD. | H13: =0 -> 0 | I13: =0 -> 0 | J13: =0 -> 0 | K13: =0 -> 0 | L13: =0 -> 0 | M13: =0 -> 0 | N13: =0 -> 0 | O13: =0 -> 0 | ... Q13: =0 -> 0
A14: EQUITY_TOTAL_TIE | B14: UNIVERSAL | expected 0; hard_tie_tolerance. | source applies_to: all 16 | C14: SOURCE_GAP | D14: hard | E14: 1000 USD | F14: 0 | G14: No semantic anchors resolved for EQUITY_TOTAL_TIE. | H14: =0 -> 0 | I14: =0 -> 0 | J14: =0 -> 0 | K14: =0 -> 0 | L14: =0 -> 0 | M14: =0 -> 0 | N14: =0 -> 0 | O14: =0 -> 0 | ... Q14: =0 -> 0
A15: BS_LINEITEM_SUM_ASSETS | B15: UNIVERSAL | expected 0; hard_tie_tolerance. | source applies_to: all 16 | C15: =IF(SUMPRODUCT((ABS(H15:Q15)>1000)*1)=0,"PASS","FAIL") -> PASS | D15: hard | E15: 1000 USD | F15: 0 | G15: expected 0; hard_tie_tolerance. Default full-USD hard tie threshold is $1,000 unless the workbook declares a tighter scale-aware tolerance. | H15: =SUM(ModeloFinanciero!B30,ModeloFinanciero!B34)-ModeloFinanciero!B35 -> 0 | I15: =SUM(ModeloFinanciero!C30,ModeloFinanciero!C34)-ModeloFinanciero!C35 -> 0 | J15: =SUM(ModeloFinanciero!D30,ModeloFinanciero!D34)-ModeloFinanciero!D35 -> 0 | K15: =SUM(ModeloFinanciero!E30,ModeloFinanciero!E34)-ModeloFinanciero!E35 -> 0 | L15: =SUM(ModeloFinanciero!F30,ModeloFinanciero!F34)-ModeloFinanciero!F35 -> 0 | M15: =SUM(ModeloFinanciero!G30,ModeloFinanciero!G34)-ModeloFinanciero!G35 -> 0 | N15: =SUM(ModeloFinanciero!H30,ModeloFinanciero!H34)-ModeloFinanciero!H35 -> 0 | O15: =SUM(ModeloFinanciero!I30,ModeloFinanciero!I34)-ModeloFinanciero!I35 -> 0 | ... Q15: =SUM(ModeloFinanciero!K30,ModeloFinanciero!K34)-ModeloFinanciero!K35 -> 0
A16: BS_LINEITEM_SUM_LIAB_EQUITY | B16: UNIVERSAL | expected 0; hard_tie_tolerance. | source applies_to: all 16 | C16: SOURCE_GAP | D16: hard | E16: 1000 USD | F16: 0 | G16: No semantic anchors resolved for BS_LINEITEM_SUM_LIAB_EQUITY. | H16: =0 -> 0 | I16: =0 -> 0 | J16: =0 -> 0 | K16: =0 -> 0 | L16: =0 -> 0 | M16: =0 -> 0 | N16: =0 -> 0 | O16: =0 -> 0 | ... Q16: =0 -> 0
A17: SOURCE_TIE_HISTORICAL | B17: UNIVERSAL | expected 0 for audited rows; SOURCE_GAP/WARN allowed only with explicit source-gap note. | source applies_to: all 16 | C17: =IF(SUMPRODUCT((ABS(H17:Q17)>100000)*1)=0,"PASS","FAIL") -> PASS | D17: hard | E17: 100000 USD | F17: 0 | G17: Audited rows tie to 0; only bank ending-cash-vs-EEFF cash rows may use the observed $100,000 hard threshold; SOURCE_GAP/WARN requires explicit source-gap note. | H17: =ModeloFinanciero!B35-EEFF!B35 -> 0 | I17: =ModeloFinanciero!C35-EEFF!C35 -> 0 | J17: =ModeloFinanciero!D35-EEFF!D35 -> 0 | K17: =ModeloFinanciero!E35-EEFF!E35 -> 0 | L17: =ModeloFinanciero!F35-EEFF!F35 -> 0
A18: NO_FORMULA_ERRORS | B18: UNIVERSAL | expected PASS/0; no masking. | source applies_to: all 16 | C18: =IF(SUMPRODUCT((ABS(H18:Q18)>0)*1)=0,"PASS","FAIL") -> PASS | D18: hard | E18: PASS | F18: PASS | G18: expected PASS/0; no masking. | H18: =0 -> 0 | I18: =0 -> 0 | J18: =0 -> 0 | K18: =0 -> 0 | L18: =0 -> 0 | M18: =0 -> 0 | N18: =0 -> 0 | O18: =0 -> 0 | ... Q18: =0 -> 0
A19: NO_CHECKS_MASTER_FAIL | B19: UNIVERSAL | expected PASS; status row should cite included/excluded rows. | source applies_to: all 16 | C19: =IF(SUMPRODUCT((ABS(H19:Q19)>0)*1)=0,"PASS","FAIL") -> PASS | D19: hard | E19: PASS | F19: PASS | G19: expected PASS; status row should cite included/excluded rows. | H19: =COUNTIF($C$6:$C$18,"FAIL")+COUNTIF($C$20:$C$32,"FAIL") -> 0 | I19: =COUNTIF($C$6:$C$18,"FAIL")+COUNTIF($C$20:$C$32,"FAIL") -> 0 | J19: =COUNTIF($C$6:$C$18,"FAIL")+COUNTIF($C$20:$C$32,"FAIL") -> 0 | K19: =COUNTIF($C$6:$C$18,"FAIL")+COUNTIF($C$20:$C$32,"FAIL") -> 0 | L19: =COUNTIF($C$6:$C$18,"FAIL")+COUNTIF($C$20:$C$32,"FAIL") -> 0 | M19: =COUNTIF($C$6:$C$18,"FAIL")+COUNTIF($C$20:$C$32,"FAIL") -> 0 | N19: =COUNTIF($C$6:$C$18,"FAIL")+COUNTIF($C$20:$C$32,"FAIL") -> 0 | O19: =COUNTIF($C$6:$C$18,"FAIL")+COUNTIF($C$20:$C$32,"FAIL") -> 0 | ... Q19: =COUNTIF($C$6:$C$18,"FAIL")+COUNTIF($C$20:$C$32,"FAIL") -> 0
A21: CONDITIONAL CHECKS
A22: PPE_SCHEDULE_TIE | B22: ARCHETYPE/conditional | expected 0; hard_tie_tolerance. | source applies_to: operating-EBITDA, power, utility, downstream fuel, other non-financials | C22: SOURCE_GAP | D22: hard | E22: 1000 USD | F22: 0 | G22: Roll-forward residual is live from PP&E_Schedule; components marked NOT_DISCLOSED keep this report-only until a hard-control policy is signed. | H22: ='PP&E_Schedule'!B20 -> 0 | I22: ='PP&E_Schedule'!C20 -> 0 | J22: ='PP&E_Schedule'!D20 -> 0 | K22: ='PP&E_Schedule'!E20 -> -1028044449 | L22: ='PP&E_Schedule'!F20 -> 141306 | M22: ='PP&E_Schedule'!G20 -> 127622915 | N22: ='PP&E_Schedule'!H20 -> 127622915 | O22: ='PP&E_Schedule'!I20 -> 127622915 | ... Q22: ='PP&E_Schedule'!K20 -> 127622915
A23: LEASE_SCHEDULE_TIE | B23: ARCHETYPE/conditional | expected 0; hard_tie_tolerance. | source applies_to: IFRS-16 issuers | C23: SOURCE_GAP | D23: hard | E23: 1000 USD | F23: 0 | G23: Roll-forward residual is live from ROU_Lease_Schedule; components marked NOT_DISCLOSED keep this report-only until a hard-control policy is signed. | H23: =ROU_Lease_Schedule!B27 -> 0 | I23: =ROU_Lease_Schedule!C27 -> 0 | J23: =ROU_Lease_Schedule!D27 -> 0 | K23: =ROU_Lease_Schedule!E27 -> -408132 | L23: =ROU_Lease_Schedule!F27 -> -5328063 | M23: =ROU_Lease_Schedule!G27 -> 0 | N23: =ROU_Lease_Schedule!H27 -> 0 | O23: =ROU_Lease_Schedule!I27 -> 0 | ... Q23: =ROU_Lease_Schedule!K27 -> 0
A24: DEBT_SCHEDULE_TIE | B24: ARCHETYPE/conditional | expected 0; hard_tie_tolerance; project-finance debt can include accrued interest/unamortized cost roles. | source applies_to: non-bank-lender, power, utility, operating-EBITDA with debt | C24: SOURCE_GAP | D24: hard | E24: 1000 USD | F24: 0 | G24: Roll-forward residual is live from Debt_Schedule; components marked NOT_DISCLOSED keep this report-only until a hard-control policy is signed. | H24: =Debt_Schedule!B19 -> 0 | I24: =Debt_Schedule!C19 -> 0 | J24: =Debt_Schedule!D19 -> 0 | K24: =Debt_Schedule!E19 -> -813184035 | L24: =Debt_Schedule!F19 -> -123002094 | M24: =Debt_Schedule!G19 -> 40389795 | N24: =Debt_Schedule!H19 -> 40389795 | O24: =Debt_Schedule!I19 -> 40389795 | ... Q24: =Debt_Schedule!K19 -> 40389795
A26: UTILITY CHECKS
A27: POWER_REVENUE_BUILD_TIE | B27: ARCHETYPE | expected 0; hard_tie_tolerance. | source applies_to: power, utility | C27: SOURCE_GAP | D27: hard | E27: 1000 USD | F27: 0 | G27: No semantic anchors resolved for POWER_REVENUE_BUILD_TIE. | H27: =0 -> 0 | I27: =0 -> 0 | J27: =0 -> 0 | K27: =0 -> 0 | L27: =0 -> 0 | M27: =0 -> 0 | N27: =0 -> 0 | O27: =0 -> 0 | ... Q27: =0 -> 0
