Workbook

Sheet 00_Cover
A1: Cerebras Systems Inc. (Nasdaq: CBRS) | Financial model: statements as filed, backlog-driven forecast 2026E-2035E, valuation and credit
A2: Built 27 Oct 2026 from the final prospectus (424B4, 13 May 2026) and the Q1 and Q2 2026 Forms 10-Q (latest statements: 30 Jun 2026).
A4: What this workbook holds
A5: Every line of the statements: FY2024 and FY2025 (audited, 424B4), six months to 30 June 2025 and 2026 (Q2 10-Q), ten quarters to Q2 2026 (a column waits for Q3 2026).
A6: Revenue by type, timing and region, customers, costs by function, the backlog and its conversion, the cap table with every class and warrant.
A7: Forecast H2 2026E and 2027E-2035E by revenue type (hardware, contracted backlog, renewals, option, other cloud, pass-through); Base, Bull and Bear (switch: Assumptions!C5).
A8: Three statements that balance every year; loan, lease and credit schedule; DCF; value per share against the price of US$119.31 (27 Oct 2026).
A9: How to read it
A10: Units: USD millions (filed thousands / 1,000), except per-share amounts (USD) and share counts (stated on each sheet).
A11: Signs follow the filing. A '—' is the filing's dash and a '*' the filing's 'below 10%': kept as text, read as nil by the model.
A12: Blue numbers are typed from a filing or are inputs. Black numbers are formulas. Green numbers link to another sheet.
A13: Column M on the year sheets is for your comments. Column N shows the source or the derivation.
A14: The thin vertical line separates actual and forecast columns.
A16: Master check (all checks on the Checks sheet) | C16: =Checks!C4 -> OK
A18: Key outputs (active scenario unless stated) | C18: Value
A19: Active scenario | C19: =Assumptions!$C$6 -> Base
A20: Share price, 27 Oct 2026 (USD) | C20: =Market_Package!B10 -> 119.31
A21: DCF value per share, perpetuity (USD) | C21: =DCF!C40 -> 45.940695
A22: Against the price | C22: =DCF!C42 -> -0.61494682
A23: Base value per share (captured, USD) | C23: =Scenario_Summary!D21 -> 45.940695
A24: Bull value per share (captured, USD) | C24: =Scenario_Summary!E21 -> 100.01525
A25: Bear value per share (captured, USD) | C25: =Scenario_Summary!F21 -> 15.52138
A26: Comparables value per share, trailing EV / LTM revenue median (USD) | C26: =Comparables!E27 -> 67.451939
A27: Probability-weighted DCF value, Bear 25% / Base 50% / Bull 25% (USD) | C27: =Valuation!C45 -> 51.854506
A28: Revenue 2026E (USD m) | C28: =Forecast_3Stmt!C13 -> 1193.6715
A29: Revenue 2030E (USD m) | C29: =Forecast_3Stmt!G13 -> 6879.9866
A30: Backlog at 30 Jun 2026 (USD m) | C30: =Backlog!B7 -> 25400
A31: Diluted shares (millions) | C31: =Cap_Table!B30 -> 286.11752
A33: Sheet | B33: What it shows
A34: IS_Hist | B34: Statements of operations as filed, with tie-out checks
A35: CI_Hist | B35: Statements of comprehensive income (loss) as filed
A36: BS_Hist | B36: Balance sheets as filed (31 Dec 2024 and 2025, the 10-Q recast of 31 Dec 2025, 31 Mar 2026, 30 Jun 2026)
A37: CF_Hist | B37: Statements of cash flows as filed
A38: SCE_Hist | B38: Statements of preferred stock and stockholders' equity as filed
A39: Quarterly_Hist | B39: Ten quarters to Q2 2026, stock pay, the IPO catch-up; Q3 2026 column waiting
A40: Revenue_Hist | B40: Revenue by timing and region, customers, depreciation and stock pay by function, costs before them, other income, OpenAI facts
A41: Backlog | B41: Backlog at 30 Jun 2026 and its conversion by the filed windows; renewals; OpenAI option; warrant amortization
A42: Cap_Table | B42: Shares by class, options, RSUs, PRSUs, OpenAI and AWS warrants; diluted count; stock pay of awards in the count
A43: Assumptions | B43: Every forecast input: Base, Bull, Bear and the switch (C5)
A44: Interim_Bridge | B44: 2026E = six months actual + second-half estimate
...

Sheet IS_Hist
A1: Cerebras Systems Inc. (Nasdaq: CBRS) | Consolidated statements of operations, as filed
A2: USD millions (filed in thousands / 1,000), except per-share amounts (USD) and share counts (thousands). FY2024-FY2025 audited (424B4 p. F-5); six-month periods unaudited (Q2 10-Q p. 7). A '—' is the filing's dash.
A4: Fiscal year ends 31 December | B4: FY2024A | C4: FY2025A | D4: 6M 2025A | E4: 6M 2026A | M4: Comentarios FG | N4: Source / derivation
A6: Revenue
A7: Hardware | B7: 211.965 | C7: 358.44 | D7: 139.969 | E7: 164.712 | N7: 424B4 p. F-5 (FY); Q2 10-Q p. 7 (6M)
A8: Cloud and other services | B8: 78.287 | C8: 151.551 | D8: 62.865 | E8: 208.804 | N8: 424B4 p. F-5 (FY); Q2 10-Q p. 7 (6M)
A9: Total revenue | B9: 290.252 | C9: 509.991 | D9: 202.834 | E9: 373.516 | N9: 424B4 p. F-5 (FY); Q2 10-Q p. 7 (6M)
A11: Cost of revenue
A12: Hardware | B12: 137.31 | C12: 204.746 | D12: 95.059 | E12: 118.072 | N12: 424B4 p. F-5 (FY); Q2 10-Q p. 7 (6M)
A13: Cloud and other services | B13: 30.204 | C13: 106.174 | D13: 34.072 | E13: 143.709 | N13: 424B4 p. F-5 (FY); Q2 10-Q p. 7 (6M)
A14: Total cost of revenue | B14: 167.514 | C14: 310.92 | D14: 129.131 | E14: 261.781 | N14: 424B4 p. F-5 (FY); Q2 10-Q p. 7 (6M)
A15: Gross profit | B15: 122.738 | C15: 199.071 | D15: 73.703 | E15: 111.735 | N15: 424B4 p. F-5 (FY); Q2 10-Q p. 7 (6M)
A17: Operating expenses
A18: Research and development | B18: 158.234 | C18: 243.319 | D18: 113.519 | E18: 395.646 | N18: 424B4 p. F-5 (FY); Q2 10-Q p. 7 (6M)
A19: Sales and marketing | B19: 20.98 | C19: 70.645 | D19: 28.554 | E19: 101.67 | N19: 424B4 p. F-5 (FY); Q2 10-Q p. 7 (6M)
A20: General and administrative | B20: 44.962 | C20: 30.969 | D20: 17.282 | E20: 106.689 | N20: 424B4 p. F-5 (FY); Q2 10-Q p. 7 (6M)
A21: Total operating expenses | B21: 224.176 | C21: 344.933 | D21: 159.355 | E21: 604.005 | N21: 424B4 p. F-5 (FY); Q2 10-Q p. 7 (6M)
A22: Loss from operations | B22: -101.438 | C22: -145.862 | D22: -85.652 | E22: -492.27 | N22: 424B4 p. F-5 (FY); Q2 10-Q p. 7 (6M)
A23: Other income (expense), net | B23: -378.237 | C23: 390.746 | D23: 374.644 | E23: 29.507 | N23: 424B4 p. F-5 (FY); Q2 10-Q p. 7 (6M)
A24: Income (loss) before income taxes | B24: -479.675 | C24: 244.884 | D24: 288.992 | E24: -462.763 | N24: 424B4 p. F-5 (FY); Q2 10-Q p. 7 (6M)
A25: Income tax expense | B25: 1.927 | C25: 7.057 | D25: 3.347 | E25: 1.771 | N25: 424B4 p. F-5 (FY); Q2 10-Q p. 7 (6M)
A26: Net income (loss) | B26: -481.602 | C26: 237.827 | D26: 285.645 | E26: -464.534 | N26: 424B4 p. F-5 (FY); Q2 10-Q p. 7 (6M)
A27: Less: net income attributable to participating securities | B27: — | C27: 149.952 | N27: 424B4 p. F-5 (FY); Q2 10-Q p. 7 (6M); caption not in the filing for 6M 2025A, 6M 2026A (blank)
A28: Less: deemed dividend on issuance of Series F-1 preferred stock | B28: 3.182 | C28: — | N28: 424B4 p. F-5 (FY); Q2 10-Q p. 7 (6M); caption not in the filing for 6M 2025A, 6M 2026A (blank)
A29: Net income (loss) attributable to common shareholders: basic | B29: -484.784 | C29: 87.875 | D29: 110.58 | E29: -464.534 | N29: 424B4 p. F-5 (FY); Q2 10-Q p. 7 (6M)
A30: Net income (loss) attributable to common shareholders: diluted | D30: 285.645 | E30: -464.534 | N30: 424B4 p. F-5 (FY); Q2 10-Q p. 7 (6M); caption not in the filing for FY2024A, FY2025A (blank)
A31: Net income (loss) per share attributable to common shareholders: basic (USD) | B31: -9.9 | C31: 1.64 | D31: 2.11 | E31: -4.34 | N31: 424B4 p. F-5 (FY); Q2 10-Q p. 7 (6M)
A32: Net income (loss) per share attributable to common shareholders: diluted (USD) | B32: -9.9 | C32: 1.38 | D32: 1.76 | E32: -4.34 | N32: 424B4 p. F-5 (FY); Q2 10-Q p. 7 (6M)
A33: Weighted average shares: basic (thousands) | B33: 48972 | C33: 53616 | D33: 52363 | E33: 107132 | N33: 424B4 p. F-5 (FY); Q2 10-Q p. 7 (6M)
A34: Weighted average shares: diluted (thousands) | B34: 48972 | C34: 171821 | D34: 162276 | E34: 107132 | N34: 424B4 p. F-5 (FY); Q2 10-Q p. 7 (6M)
A36: Checks: recomputed less filed (zero passes)
A37: Total revenue | B37: =SUM(B7,B8)-B9 -> 0 | C37: =SUM(C7,C8)-C9 -> 0 | D37: =SUM(D7,D8)-D9 -> 0 | E37: =SUM(E7,E8)-E9 -> 0
A38: Total cost of revenue | B38: =SUM(B12,B13)-B14 -> 0 | C38: =SUM(C12,C13)-C14 -> 0 | D38: =SUM(D12,D13)-D14 -> 0 | E38: =SUM(E12,E13)-E14 -> 0
A39: Gross profit | B39: =B9-B14-B15 -> 0 | C39: =C9-C14-C15 -> 0 | D39: =D9-D14-D15 -> 0 | E39: =E9-E14-E15 -> 0
A40: Total operating expenses | B40: =SUM(B18,B19,B20)-B21 -> 0 | C40: =SUM(C18,C19,C20)-C21 -> 0 | D40: =SUM(D18,D19,D20)-D21 -> 0 | E40: =SUM(E18,E19,E20)-E21 -> 0
A41: Loss from operations | B41: =B15-B21-B22 -> 0 | C41: =C15-C21-C22 -> 0 | D41: =D15-D21-D22 -> 0 | E41: =E15-E21-E22 -> 0
A42: Income (loss) before income taxes | B42: =B22+B23-B24 -> 0 | C42: =C22+C23-C24 -> 0 | D42: =D22+D23-D24 -> 0 | E42: =E22+E23-E24 -> 0
A43: Net income (loss) | B43: =B24-B25-B26 -> 0 | C43: =C24-C25-C26 -> 0 | D43: =D24-D25-D26 -> 0 | E43: =E24-E25-E26 -> 0
A44: Net income attributable to common shareholders, FY | B44: =B26-SUM(B27,B28)-B29 -> 0 | C44: =C26-SUM(C27,C28)-C29 -> 0
A45: Basic earnings per share (rounded to cents) | B45: =ROUND(B29*1000/B33,2)-B31 -> 0 | C45: =ROUND(C29*1000/C33,2)-C31 -> 0 | D45: =ROUND(D29*1000/D33,2)-D31 -> 0 | E45: =ROUND(E29*1000/E33,2)-E31 -> 0

Sheet CI_Hist
A1: Cerebras Systems Inc. (Nasdaq: CBRS) | Consolidated statements of comprehensive income (loss), as filed
A2: USD millions (filed in thousands / 1,000). 424B4 p. F-6 (FY); Q2 10-Q p. 8 (6M).
A4: Fiscal year ends 31 December | B4: FY2024A | C4: FY2025A | D4: 6M 2025A | E4: 6M 2026A | M4: Comentarios FG | N4: Source / derivation
A6: Net income (loss) | B6: -481.602 | C6: 237.827 | D6: 285.645 | E6: -464.534 | N6: 424B4 p. F-6 (FY); Q2 10-Q p. 8 (6M)
A7: Change in foreign currency translation adjustments, net of tax | B7: -0.304 | C7: -0.521 | D7: 0.912 | E7: 0.638 | N7: 424B4 p. F-6 (FY); Q2 10-Q p. 8 (6M)
A9: Available-for-sale investments:
A10: Change in net unrealized gain (loss) on debt securities, net of tax | B10: -0.579 | C10: 1.602 | D10: -0.807 | E10: 3.828 | N10: 424B4 p. F-6 (FY); Q2 10-Q p. 8 (6M)
A11: Comprehensive income (loss) | B11: -482.485 | C11: 238.908 | D11: 285.75 | E11: -460.068 | N11: 424B4 p. F-6 (FY); Q2 10-Q p. 8 (6M)
A13: Checks (zero passes)
A14: Comprehensive income (loss) | B14: =B6+B7+B10-B11 -> 0 | C14: =C6+C7+C10-C11 -> 0 | D14: =D6+D7+D10-D11 -> 0 | E14: =E6+E7+E10-E11 -> 0
A15: Net income equals the statement of operations | B15: =B6-IS_Hist!B26 -> 0 | C15: =C6-IS_Hist!C26 -> 0 | D15: =D6-IS_Hist!D26 -> 0 | E15: =E6-IS_Hist!E26 -> 0

Sheet BS_Hist
A1: Cerebras Systems Inc. (Nasdaq: CBRS) | Consolidated balance sheets, as filed
A2: USD millions (filed in thousands / 1,000). 31 Dec audited (424B4 p. F-4). The Q2 10-Q recasts 31 Dec 2025 (column D): customer warrants, lease and deferred revenue lines split out; totals unchanged. 31 Mar 2026 Q1 10-Q p. 5; 30 Jun 2026 Q2 10-Q p. 6.
A4: Fiscal year ends 31 December | B4: Dec 2024A | C4: Dec 2025A | D4: Dec 2025A recast | E4: Mar 2026A | F4: Jun 2026A | M4: Comentarios FG | N4: Source / derivation
A6: Current assets:
A7: Cash and cash equivalents | B7: 220.208 | C7: 701.706 | D7: 701.706 | E7: 1716.016 | F7: 6742.157 | N7: B-C 424B4 p. F-4; D and F Q2 10-Q p. 6; E Q1 10-Q p. 5
A8: Restricted cash | B8: 361.757 | C8: 228.672 | D8: 228.672 | E8: 1029.098 | F8: 684.68 | N8: B-C 424B4 p. F-4; D and F Q2 10-Q p. 6; E Q1 10-Q p. 5
A9: Investments | B9: 116.943 | C9: 406.531 | D9: 406.531 | E9: 515.605 | F9: 1179.39 | N9: B-C 424B4 p. F-4; D and F Q2 10-Q p. 6; E Q1 10-Q p. 5
A10: Accounts receivable, net | B10: 137.436 | C10: 50.423 | D10: 50.423 | E10: 62.631 | F10: 123.361 | N10: B-C 424B4 p. F-4; D and F Q2 10-Q p. 6; E Q1 10-Q p. 5
A11: Inventories | B11: 174.492 | C11: 63.626 | D11: 63.626 | E11: 89.04 | F11: 32.666 | N11: B-C 424B4 p. F-4; D and F Q2 10-Q p. 6; E Q1 10-Q p. 5
A12: Customer warrants | D12: 60.906 | E12: 90.701 | F12: 167.762 | N12: B-C 424B4 p. F-4; D and F Q2 10-Q p. 6; E Q1 10-Q p. 5; caption not in the filing for Dec 2024A, Dec 2025A (blank)
A13: Prepaid expenses and other current assets | B13: 19.643 | C13: 92.688 | D13: 31.782 | E13: 77.87 | F13: 191.698 | N13: B-C 424B4 p. F-4; D and F Q2 10-Q p. 6; E Q1 10-Q p. 5
A14: Total current assets | B14: 1030.479 | C14: 1543.646 | D14: 1543.646 | E14: 3580.961 | F14: 9121.714 | N14: B-C 424B4 p. F-4; D and F Q2 10-Q p. 6; E Q1 10-Q p. 5
A15: Property and equipment, net | B15: 43.174 | C15: 437.396 | D15: 437.396 | E15: 572.439 | F15: 986.808 | N15: B-C 424B4 p. F-4; D and F Q2 10-Q p. 6; E Q1 10-Q p. 5
A16: Customer warrants, net of current portion | D16: 91.447 | E16: 425.355 | F16: 960.635 | N16: B-C 424B4 p. F-4; D and F Q2 10-Q p. 6; E Q1 10-Q p. 5; caption not in the filing for Dec 2024A, Dec 2025A (blank)
A17: Operating lease right-of-use assets | B17: 36.571 | C17: 248.95 | D17: 248.95 | E17: 353.303 | F17: 528.275 | N17: B-C 424B4 p. F-4; D and F Q2 10-Q p. 6; E Q1 10-Q p. 5
A18: Other non-current assets | B18: 2.514 | C18: 96.045 | D18: 4.598 | E18: 16.32 | F18: 30.44 | N18: B-C 424B4 p. F-4; D and F Q2 10-Q p. 6; E Q1 10-Q p. 5
A19: Total assets | B19: 1112.738 | C19: 2326.037 | D19: 2326.037 | E19: 4948.378 | F19: 11627.872 | N19: B-C 424B4 p. F-4; D and F Q2 10-Q p. 6; E Q1 10-Q p. 5
A21: Current liabilities:
A22: Accounts payable | B22: 25.63 | C22: 48.63 | D22: 48.63 | E22: 50.336 | F22: 88.313 | N22: B-C 424B4 p. F-4; D and F Q2 10-Q p. 6; E Q1 10-Q p. 5
A23: Deferred revenue, current | B23: 38.537 | C23: 131.049 | D23: 131.049 | E23: 149.918 | F23: 173.735 | N23: B-C 424B4 p. F-4; D and F Q2 10-Q p. 6; E Q1 10-Q p. 5
A24: Operating lease liability, current | D24: 45.865 | E24: 66.218 | F24: 88.422 | N24: B-C 424B4 p. F-4; D and F Q2 10-Q p. 6; E Q1 10-Q p. 5; caption not in the filing for Dec 2024A, Dec 2025A (blank)
A25: Customer deposits | B25: 640.317 | C25: 354.46 | D25: 354.46 | E25: 368.426 | F25: 242.672 | N25: B-C 424B4 p. F-4; D and F Q2 10-Q p. 6; E Q1 10-Q p. 5
A26: Forward contract liability | B26: 363.336 | C26: — | N26: B-C 424B4 p. F-4; D and F Q2 10-Q p. 6; E Q1 10-Q p. 5; caption not in the filing for Dec 2025A recast, Mar 2026A, Jun 2026A (blank)
A27: Working capital loan | D27: — | E27: 621.306 | F27: 736.036 | N27: B-C 424B4 p. F-4; D and F Q2 10-Q p. 6; E Q1 10-Q p. 5; caption not in the filing for Dec 2024A, Dec 2025A (blank)
A28: Accrued and other current liabilities | B28: 110.315 | C28: 185.401 | D28: 139.536 | E28: 171.042 | F28: 236.91 | N28: B-C 424B4 p. F-4; D and F Q2 10-Q p. 6; E Q1 10-Q p. 5
A29: Total current liabilities | B29: 1178.135 | C29: 719.54 | D29: 719.54 | E29: 1427.246 | F29: 1566.088 | N29: B-C 424B4 p. F-4; D and F Q2 10-Q p. 6; E Q1 10-Q p. 5
A30: Deferred revenue, net of current portion | D30: 35.847 | E30: 94.344 | F30: 244.529 | N30: B-C 424B4 p. F-4; D and F Q2 10-Q p. 6; E Q1 10-Q p. 5; caption not in the filing for Dec 2024A, Dec 2025A (blank)
A31: Operating lease liability, net of current portion | B31: 27.37 | C31: 215.957 | D31: 215.957 | E31: 312.474 | F31: 480.405 | N31: B-C 424B4 p. F-4; D and F Q2 10-Q p. 6; E Q1 10-Q p. 5
A32: Working capital loan, net of current portion | D32: — | E32: 361.617 | F32: 182.208 | N32: B-C 424B4 p. F-4; D and F Q2 10-Q p. 6; E Q1 10-Q p. 5; caption not in the filing for Dec 2024A, Dec 2025A (blank)
A33: Other non-current liabilities | B33: 23.958 | C33: 35.847 | N33: B-C 424B4 p. F-4; D and F Q2 10-Q p. 6; E Q1 10-Q p. 5; caption not in the filing for Dec 2025A recast, Mar 2026A, Jun 2026A (blank)
A34: Total liabilities | B34: 1229.463 | C34: 971.344 | D34: 971.344 | E34: 2195.681 | F34: 2473.23 | N34: B-C 424B4 p. F-4; D and F Q2 10-Q p. 6; E Q1 10-Q p. 5
A35: Redeemable convertible preferred stock | B35: 850.066 | C35: 1933.348 | D35: 1933.348 | E35: 2947.379 | F35: — | N35: B-C 424B4 p. F-4; D and F Q2 10-Q p. 6; E Q1 10-Q p. 5
A37: Stockholders' equity (deficit)
A38: Class A common stock | B38: 0.001 | C38: 0.001 | D38: 0.001 | E38: 0.001 | F38: 0.001 | N38: B-C 424B4 p. F-4; D and F Q2 10-Q p. 6; E Q1 10-Q p. 5
A39: Class B common stock | F39: 0.001 | N39: B-C 424B4 p. F-4; D and F Q2 10-Q p. 6; E Q1 10-Q p. 5; caption not in the filing for Dec 2024A, Dec 2025A, Dec 2025A recast, Mar 2026A (blank)
A40: Class N common stock | B40: — | C40: — | D40: — | E40: — | F40: — | N40: B-C 424B4 p. F-4; D and F Q2 10-Q p. 6; E Q1 10-Q p. 5
A41: Treasury stock, at cost | B41: -0.088 | C41: -21.456 | D41: -21.456 | E41: -21.456 | F41: -21.456 | N41: B-C 424B4 p. F-4; D and F Q2 10-Q p. 6; E Q1 10-Q p. 5
A42: Additional paid-in capital | B42: 176.233 | C42: 346.829 | D42: 346.829 | E42: 742.713 | F42: 10540.193 | N42: B-C 424B4 p. F-4; D and F Q2 10-Q p. 6; E Q1 10-Q p. 5
A43: Accumulated other comprehensive income | B43: 0.22 | C43: 1.301 | D43: 1.301 | E43: 3.396 | F43: 5.767 | N43: B-C 424B4 p. F-4; D and F Q2 10-Q p. 6; E Q1 10-Q p. 5
A44: Accumulated deficit | B44: -1143.157 | C44: -905.33 | D44: -905.33 | E44: -919.336 | F44: -1369.864 | N44: B-C 424B4 p. F-4; D and F Q2 10-Q p. 6; E Q1 10-Q p. 5
...

Sheet CF_Hist
A1: Cerebras Systems Inc. (Nasdaq: CBRS) | Consolidated statements of cash flows, as filed
A2: USD millions (filed in thousands / 1,000). 424B4 p. F-8 (FY, audited); Q2 10-Q p. 11 (6M, unaudited). Cash includes restricted cash.
A4: Fiscal year ends 31 December | B4: FY2024A | C4: FY2025A | D4: 6M 2025A | E4: 6M 2026A | M4: Comentarios FG | N4: Source / derivation
A6: Cash flows from operating activities:
A7: Net income (loss) | B7: -481.602 | C7: 237.827 | D7: 285.645 | E7: -464.534 | N7: 424B4 p. F-8 (FY); Q2 10-Q p. 11 (6M)
A8: Depreciation and amortization | B8: 11.537 | C8: 34.454 | D8: 9.315 | E8: 42.551 | N8: 424B4 p. F-8 (FY); Q2 10-Q p. 11 (6M)
A9: Stock-based compensation | B9: 58.564 | C9: 49.767 | D9: 22.435 | E9: 386.601 | N9: 424B4 p. F-8 (FY); Q2 10-Q p. 11 (6M)
A10: Amortization of customer warrants | D10: — | E10: 46.315 | N10: 424B4 p. F-8 (FY); Q2 10-Q p. 11 (6M); caption not in the filing for FY2024A, FY2025A (blank)
A11: Non-cash lease expense | B11: 7.607 | C11: 22.673 | D11: 5.872 | E11: 39.104 | N11: 424B4 p. F-8 (FY); Q2 10-Q p. 11 (6M)
A12: Non-cash interest expense | D12: — | E12: 38.602 | N12: 424B4 p. F-8 (FY); Q2 10-Q p. 11 (6M); caption not in the filing for FY2024A, FY2025A (blank)
A13: Provision for product warranties | B13: 12.525 | C13: 20.969 | D13: 9 | E13: 8.43 | N13: 424B4 p. F-8 (FY); Q2 10-Q p. 11 (6M)
A14: Change in fair value (extinguishment) of forward contract liability | B14: 401.264 | C14: -363.336 | D14: -363.336 | E14: — | N14: 424B4 p. F-8 (FY); Q2 10-Q p. 11 (6M)
A15: Other | B15: -1.388 | C15: 3.235 | D15: -0.835 | E15: -2.11 | N15: 424B4 p. F-8 (FY); Q2 10-Q p. 11 (6M)
A17: Changes in operating assets and liabilities:
A18: Accounts receivable | B18: -130.672 | C18: 87.012 | D18: 125.508 | E18: -72.938 | N18: 424B4 p. F-8 (FY); Q2 10-Q p. 11 (6M)
A19: Inventories | B19: -144.969 | C19: 63.307 | D19: 74.929 | E19: 31.116 | N19: 424B4 p. F-8 (FY); Q2 10-Q p. 11 (6M)
A20: Prepaid expenses and other assets | B20: -17.051 | C20: -13.867 | D20: -3.003 | E20: -182.311 | N20: 424B4 p. F-8 (FY); Q2 10-Q p. 11 (6M)
A21: Accounts payable | B21: 9.01 | C21: 21.151 | D21: 6.314 | E21: 0.565 | N21: 424B4 p. F-8 (FY); Q2 10-Q p. 11 (6M)
A22: Deferred revenue | B22: 38.196 | C22: 109.474 | D22: 16.525 | E22: 126.44 | N22: 424B4 p. F-8 (FY); Q2 10-Q p. 11 (6M)
A23: Customer deposits | B23: 640.317 | C23: -285.857 | D23: -320.558 | E23: -111.788 | N23: 424B4 p. F-8 (FY); Q2 10-Q p. 11 (6M)
A24: Other liabilities | B24: 48.64 | C24: 3.141 | D24: 8.346 | E24: 66.469 | N24: 424B4 p. F-8 (FY); Q2 10-Q p. 11 (6M)
A25: Net cash flows provided by (used in) operating activities | B25: 451.978 | C25: -10.05 | D25: -123.843 | E25: -47.488 | N25: 424B4 p. F-8 (FY); Q2 10-Q p. 11 (6M)
A27: Cash flows from investing activities:
A28: Purchases of property and equipment | B28: -23.435 | C28: -382.739 | D28: -185.094 | E28: -548.873 | N28: 424B4 p. F-8 (FY); Q2 10-Q p. 11 (6M)
A29: Purchases of investments | B29: -302.898 | C29: -525.414 | D29: -20.175 | E29: -1275.515 | N29: 424B4 p. F-8 (FY); Q2 10-Q p. 11 (6M)
A30: Maturities and sales of investments | B30: 309.548 | C30: 240.577 | D30: 117.973 | E30: 514.455 | N30: 424B4 p. F-8 (FY); Q2 10-Q p. 11 (6M)
A31: Net cash flows used in investing activities | B31: -16.785 | C31: -667.576 | D31: -87.296 | E31: -1309.933 | N31: 424B4 p. F-8 (FY); Q2 10-Q p. 11 (6M)
A33: Cash flows from financing activities:
A34: Proceeds from initial public offering, net of underwriting discounts and commissions | D34: — | E34: 6232.511 | N34: 424B4 p. F-8 (FY); Q2 10-Q p. 11 (6M); caption not in the filing for FY2024A, FY2025A (blank)
A35: Proceeds from sale of shares of redeemable convertible preferred stock (2026: Series H) | B35: 85 | C35: 1100 | D35: — | E35: 1014.249 | N35: 424B4 p. F-8 (FY); Q2 10-Q p. 11 (6M)
A36: Costs incurred in connection with the sale of preferred stock | B36: -0.102 | C36: -16.718 | D36: — | E36: -0.218 | N36: 424B4 p. F-8 (FY); Q2 10-Q p. 11 (6M)
A37: Proceeds from Working Capital Loan | D37: — | E37: 1004.571 | N37: 424B4 p. F-8 (FY); Q2 10-Q p. 11 (6M); caption not in the filing for FY2024A, FY2025A (blank)
A38: Proceeds from exercise of stock options | B38: 27.752 | C38: 17.299 | D38: 5.176 | E38: 20.221 | N38: 424B4 p. F-8 (FY); Q2 10-Q p. 11 (6M)
A39: Proceeds from issuance of shares of Class N common stock | D39: — | E39: 15.036 | N39: 424B4 p. F-8 (FY); Q2 10-Q p. 11 (6M); caption not in the filing for FY2024A, FY2025A (blank)
A40: Fees paid for revolving credit facility | D40: — | E40: -3.801 | N40: 424B4 p. F-8 (FY); Q2 10-Q p. 11 (6M); caption not in the filing for FY2024A, FY2025A (blank)
A41: Repurchases of early exercised stock options | B41: -0.028 | C41: -0.028 | D41: -0.028 | E41: — | N41: 424B4 p. F-8 (FY); Q2 10-Q p. 11 (6M)
A42: Cancellation and settlement of stock options in connection with the Tender Offer | B42: — | C42: -49.32 | N42: 424B4 p. F-8 (FY); Q2 10-Q p. 11 (6M); caption not in the filing for 6M 2025A, 6M 2026A (blank)
A43: Repurchase of common stock | B43: — | C43: -21.368 | N43: 424B4 p. F-8 (FY); Q2 10-Q p. 11 (6M); caption not in the filing for 6M 2025A, 6M 2026A (blank)
A44: Tax withheld related to RSU settlement | B44: — | C44: -2.95 | N44: 424B4 p. F-8 (FY); Q2 10-Q p. 11 (6M); caption not in the filing for 6M 2025A, 6M 2026A (blank)
A45: Tax withholding from tender offer and initial public offering | D45: — | E45: -416.66 | N45: 424B4 p. F-8 (FY); Q2 10-Q p. 11 (6M); caption not in the filing for FY2024A, FY2025A (blank)
...

Sheet SCE_Hist
A1: Cerebras Systems Inc. (Nasdaq: CBRS) | Statements of redeemable convertible preferred stock and stockholders' equity (deficit), as filed
A2: Amounts USD millions (filed thousands / 1,000); share counts in thousands as filed. 2024-2025: 424B4 p. F-7; Q1 and Q2 2026: Q2 10-Q p. 10.
A4: Line | B4: Preferred: shares (k) | C4: Preferred: amount | D4: Common: shares (k) | E4: Common: amount | F4: Additional paid-in capital | G4: Treasury: shares (k) | H4: Treasury: amount | I4: Accumulated other comprehensive income | J4: Accumulated deficit | K4: Total stockholders' equity (deficit) | M4: Comentarios FG | N4: Source / derivation
A6: Fiscal years 2024 and 2025 (audited)
A7: Balance as of December 31, 2023 | B7: 77033 | C7: 722.78 | D7: 45362 | E7: — | F7: 101.578 | G7: -300 | H7: -0.088 | I7: 1.103 | J7: -661.555 | K7: -558.962 | N7: 424B4 p. F-7
A8: Issuance of shares of Series F-1 redeemable convertible preferred stock, net of issuance costs | B8: 5798 | C8: 84.898 | D8: — | E8: — | F8: — | G8: — | H8: — | I8: — | J8: — | K8: — | N8: 424B4 p. F-7
A9: Settlement of Series F-1 redeemable convertible preferred stock forward contract liability | B9: — | C9: 37.928 | D9: — | E9: — | F9: — | G9: — | H9: — | I9: — | J9: — | K9: — | N9: 424B4 p. F-7
A10: Deemed dividend on issuance of Series F-1 redeemable convertible preferred stock | B10: — | C10: 3.182 | D10: — | E10: — | F10: -3.182 | G10: — | H10: — | I10: — | J10: — | K10: -3.182 | N10: 424B4 p. F-7
A11: Issuance of shares of Series E redeemable convertible preferred stock upon exercise of warrant | B11: 68 | C11: 1.278 | D11: — | E11: — | F11: — | G11: — | H11: — | I11: — | J11: — | K11: — | N11: 424B4 p. F-7
A12: Shares issued upon exercise of stock options, net of repurchases of early exercised stock options | B12: — | C12: — | D12: 8011 | E12: 0.001 | F12: 17.667 | G12: — | H12: — | I12: — | J12: — | K12: 17.668 | N12: 424B4 p. F-7
A13: Vesting of early exercised stock options | B13: — | C13: — | D13: — | E13: — | F13: 1.733 | G13: — | H13: — | I13: — | J13: — | K13: 1.733 | N13: 424B4 p. F-7
A14: Stock-based compensation expense | B14: — | C14: — | D14: — | E14: — | F14: 57.525 | G14: — | H14: — | I14: — | J14: — | K14: 57.525 | N14: 424B4 p. F-7
A15: Conversion of stock-based liability classified awards to stock-based equity classified awards | B15: — | C15: — | D15: — | E15: — | F15: 0.912 | G15: — | H15: — | I15: — | J15: — | K15: 0.912 | N15: 424B4 p. F-7
A16: Foreign currency translation adjustments, net of tax | B16: — | C16: — | D16: — | E16: — | F16: — | G16: — | H16: — | I16: -0.304 | J16: — | K16: -0.304 | N16: 424B4 p. F-7
A17: Change in net unrealized loss on debt securities, net of tax | B17: — | C17: — | D17: — | E17: — | F17: — | G17: — | H17: — | I17: -0.579 | J17: — | K17: -0.579 | N17: 424B4 p. F-7
A18: Net loss | B18: — | C18: — | D18: — | E18: — | F18: — | G18: — | H18: — | I18: — | J18: -481.602 | K18: -481.602 | N18: 424B4 p. F-7
A19: Balance as of December 31, 2024 | B19: 82899 | C19: 850.066 | D19: 53373 | E19: 0.001 | F19: 176.233 | G19: -300 | H19: -0.088 | I19: 0.22 | J19: -1143.157 | K19: -966.791 | N19: 424B4 p. F-7
A20: Issuance of shares of Series G redeemable convertible preferred stock, net of issuance costs | B20: 30360 | C20: 1083.282 | D20: — | E20: — | F20: — | G20: — | H20: — | I20: — | J20: — | K20: — | N20: 424B4 p. F-7
A21: Customer warrants issued | B21: — | C21: — | D21: — | E21: — | F21: 152.353 | G21: — | H21: — | I21: — | J21: — | K21: 152.353 | N21: 424B4 p. F-7
A22: Cancellation and settlement of stock options in connection with the Tender Offer | B22: — | C22: — | D22: — | E22: — | F22: -49.32 | G22: — | H22: — | I22: — | J22: — | K22: -49.32 | N22: 424B4 p. F-7
A23: Repurchase of common stock | B23: — | C23: — | D23: — | E23: — | F23: — | G23: -590 | H23: -21.368 | I23: — | J23: — | K23: -21.368 | N23: 424B4 p. F-7
A24: Shares issued upon acceleration of RSUs vesting and exercise of stock options, net of repurchases and withholding taxes | B24: — | C24: — | D24: 4623 | E24: — | F24: 17.169 | G24: — | H24: — | I24: — | J24: — | K24: 17.169 | N24: 424B4 p. F-7
A25: Tax withheld related to RSU settlement | B25: — | C25: — | D25: -89 | E25: — | F25: -2.95 | G25: — | H25: — | I25: — | J25: — | K25: -2.95 | N25: 424B4 p. F-7
A26: Vesting of early exercised stock options | B26: — | C26: — | D26: — | E26: — | F26: 3.449 | G26: — | H26: — | I26: — | J26: — | K26: 3.449 | N26: 424B4 p. F-7
A27: Stock-based compensation expense | B27: — | C27: — | D27: — | E27: — | F27: 48.857 | G27: — | H27: — | I27: — | J27: — | K27: 48.857 | N27: 424B4 p. F-7
A28: Conversion of stock-based liability classified awards to stock-based equity classified awards | B28: — | C28: — | D28: — | E28: — | F28: 1.038 | G28: — | H28: — | I28: — | J28: — | K28: 1.038 | N28: 424B4 p. F-7
A29: Foreign currency translation adjustments, net of tax | B29: — | C29: — | D29: — | E29: — | F29: — | G29: — | H29: — | I29: -0.521 | J29: — | K29: -0.521 | N29: 424B4 p. F-7
A30: Change in net unrealized loss on debt securities, net of tax | B30: — | C30: — | D30: — | E30: — | F30: — | G30: — | H30: — | I30: 1.602 | J30: — | K30: 1.602 | N30: 424B4 p. F-7
A31: Net income | B31: — | C31: — | D31: — | E31: — | F31: — | G31: — | H31: — | I31: — | J31: 237.827 | K31: 237.827 | N31: 424B4 p. F-7
A32: Balance as of December 31, 2025 | B32: 113259 | C32: 1933.348 | D32: 57907 | E32: 0.001 | F32: 346.829 | G32: -890 | H32: -21.456 | I32: 1.301 | J32: -905.33 | K32: -578.655 | N32: 424B4 p. F-7
A34: Six months ended 30 June 2026 (unaudited)
A35: Balance as of December 31, 2025 | B35: 113259 | C35: 1933.348 | D35: 57907 | E35: 0.001 | F35: 346.829 | G35: -890 | H35: -21.456 | I35: 1.301 | J35: -905.33 | K35: -578.655 | N35: Q2 10-Q p. 10
A36: Issuance of shares of Series H redeemable convertible preferred stock, net of issuance costs | B36: 11394 | C36: 1014.031 | D36: — | E36: — | F36: — | G36: — | H36: — | I36: — | J36: — | K36: — | N36: Q2 10-Q p. 10
A37: Customer warrants issued | B37: — | C37: — | D37: — | E37: — | F37: 365.755 | G37: — | H37: — | I37: — | J37: — | K37: 365.755 | N37: Q2 10-Q p. 10
A38: Issuance of shares of Class N common stock | B38: — | C38: — | D38: 2026 | E38: — | F38: 15.019 | G38: — | H38: — | I38: — | J38: — | K38: 15.019 | N38: Q2 10-Q p. 10
A39: Class A common shares issued upon exercise of stock options | B39: — | C39: — | D39: 1085 | E39: — | F39: 5.177 | G39: — | H39: — | I39: — | J39: — | K39: 5.177 | N39: Q2 10-Q p. 10
A40: Tax withholding from tender offer | B40: — | C40: — | D40: — | E40: — | F40: -0.623 | G40: — | H40: — | I40: — | J40: — | K40: -0.623 | N40: Q2 10-Q p. 10
A41: Vesting of early exercised stock options | B41: — | C41: — | D41: — | E41: — | F41: 0.809 | G41: — | H41: — | I41: — | J41: — | K41: 0.809 | N41: Q2 10-Q p. 10
A42: Stock-based compensation expense | B42: — | C42: — | D42: — | E42: — | F42: 9.418 | G42: — | H42: — | I42: — | J42: — | K42: 9.418 | N42: Q2 10-Q p. 10
A43: Conversion of stock-based liability classified awards to stock-based equity classified awards | B43: — | C43: — | D43: — | E43: — | F43: 0.329 | G43: — | H43: — | I43: — | J43: — | K43: 0.329 | N43: Q2 10-Q p. 10
...

Sheet Quarterly_Hist
A1: Cerebras Systems Inc. (Nasdaq: CBRS) | Quarterly results, as filed
A2: USD millions (filed thousands / 1,000). Unaudited. Q1 2024-Q4 2025: 424B4 p. 104 (operations and stock pay tables). Q1 2025 and Q1 2026: Q1 10-Q p. 6; Q2 2025 and Q2 2026: Q2 10-Q p. 7. Column L waits for the Q3 2026 10-Q (due November 2026).
A4: Three months ended | B4: Q1 2024A | C4: Q2 2024A | D4: Q3 2024A | E4: Q4 2024A | F4: Q1 2025A | G4: Q2 2025A | H4: Q3 2025A | I4: Q4 2025A | J4: Q1 2026A | K4: Q2 2026A | L4: Q3 2026A | M4: Comentarios FG | N4: Source / derivation
A6: Revenue
A7: Hardware | B7: 49.411 | C7: 54.858 | D7: 50.28 | E7: 57.416 | F7: 69.674 | G7: 70.295 | H7: 96.794 | I7: 121.677 | J7: 110.593 | K7: 54.119 | N7: 424B4 p. 104; 2026: Q1 10-Q p. 6, Q2 10-Q p. 7
A8: Cloud and other services | B8: 17.22 | C8: 14.913 | D8: 22.039 | E8: 24.115 | F8: 29.838 | G8: 33.027 | H8: 38.92 | I8: 49.766 | J8: 82.813 | K8: 125.991 | N8: 424B4 p. 104; 2026: Q1 10-Q p. 6, Q2 10-Q p. 7
A9: Total revenue | B9: 66.631 | C9: 69.771 | D9: 72.319 | E9: 81.531 | F9: 99.512 | G9: 103.322 | H9: 135.714 | I9: 171.443 | J9: 193.406 | K9: 180.11 | N9: 424B4 p. 104; 2026: Q1 10-Q p. 6, Q2 10-Q p. 7
A11: Cost of revenue
A12: Hardware | B12: 33.619 | C12: 32.823 | D12: 34.143 | E12: 36.725 | F12: 48.41 | G12: 46.649 | H12: 47.969 | I12: 61.718 | J12: 64.931 | K12: 53.141 | N12: 424B4 p. 104; 2026: Q1 10-Q p. 6, Q2 10-Q p. 7
A13: Cloud and other services | B13: 7.873 | C13: 6.068 | D13: 6.169 | E13: 10.094 | F13: 9.498 | G13: 24.574 | H13: 32.61 | I13: 39.492 | J13: 42.299 | K13: 101.41 | N13: 424B4 p. 104; 2026: Q1 10-Q p. 6, Q2 10-Q p. 7
A14: Total cost of revenue | B14: 41.492 | C14: 38.891 | D14: 40.312 | E14: 46.819 | F14: 57.908 | G14: 71.223 | H14: 80.579 | I14: 101.21 | J14: 107.23 | K14: 154.551 | N14: 424B4 p. 104; 2026: Q1 10-Q p. 6, Q2 10-Q p. 7
A15: Gross profit | B15: 25.139 | C15: 30.88 | D15: 32.007 | E15: 34.712 | F15: 41.604 | G15: 32.099 | H15: 55.135 | I15: 70.233 | J15: 86.176 | K15: 25.559 | N15: 424B4 p. 104; 2026: Q1 10-Q p. 6, Q2 10-Q p. 7
A17: Operating expenses (by function only in the 10-Q quarters; the 424B4 table gives the total)
A18: Research and development | F18: 52.751 | G18: 60.768 | J18: 75.495 | K18: 320.151 | N18: Q1 10-Q p. 6; Q2 10-Q p. 7
A19: Sales and marketing | F19: 10.326 | G19: 18.228 | J19: 14.701 | K19: 86.969 | N19: Q1 10-Q p. 6; Q2 10-Q p. 7
A20: General and administrative | F20: 6.997 | G20: 10.285 | J20: 11.017 | K20: 95.672 | N20: Q1 10-Q p. 6; Q2 10-Q p. 7
A21: Total operating expenses | B21: 43.19 | C21: 54.64 | D21: 51.384 | E21: 74.962 | F21: 70.074 | G21: 89.281 | H21: 81.604 | I21: 103.974 | J21: 101.213 | K21: 502.792 | N21: 424B4 p. 104; 2026: Q1 10-Q p. 6, Q2 10-Q p. 7
A22: Loss from operations | B22: -18.051 | C22: -23.76 | D22: -19.377 | E22: -40.25 | F22: -28.47 | G22: -57.182 | H22: -26.469 | I22: -33.741 | J22: -15.037 | K22: -477.233 | N22: 424B4 p. 104; 2026: Q1 10-Q p. 6, Q2 10-Q p. 7
A23: Other income, net | F23: 6.286 | G23: 368.358 | J23: 2.528 | K23: 26.979 | N23: Q1 10-Q p. 6; Q2 10-Q p. 7
A24: Income (loss) before income taxes | F24: -22.184 | G24: 311.176 | J24: -12.509 | K24: -450.254 | N24: Q1 10-Q p. 6; Q2 10-Q p. 7
A25: Income tax expense | F25: 1.683 | G25: 1.664 | J25: 1.497 | K25: 0.274 | N25: Q1 10-Q p. 6; Q2 10-Q p. 7
A26: Net income (loss) | B26: -15.75 | C26: -50.855 | D26: -309.341 | E26: -105.656 | F26: -23.867 | G26: 309.512 | H26: -22.201 | I26: -25.617 | J26: -14.006 | K26: -450.528 | N26: 424B4 p. 104; 2026: Q1 10-Q p. 6, Q2 10-Q p. 7
A28: Stock-based compensation and depreciation
A29: Stock pay in cost of revenue | B29: 0.189 | C29: 0.231 | D29: 0.237 | E29: 0.264 | F29: 0.326 | G29: 0.187 | H29: 0.161 | I29: 0.153 | J29: 0.95 | K29: 15.353 | N29: 424B4 p. 104; 2026: Q1 10-Q p. 20, Q2 10-Q p. 26
A30: Stock pay in operating expenses | B30: 9.237 | C30: 22.672 | D30: 16.591 | E30: 9.143 | F30: 8.828 | G30: 13.094 | H30: 11.185 | I30: 15.833 | J30: =J31-J29 -> 8.643 | K30: =K31-K29 -> 361.655 | N30: 2026: total less cost of revenue (the 10-Q gives functions, not this subtotal).
A31: Total stock-based compensation | B31: 9.426 | C31: 22.903 | D31: 16.828 | E31: 9.407 | F31: 9.154 | G31: 13.281 | H31: 11.346 | I31: 15.986 | J31: 9.593 | K31: 377.008 | N31: 424B4 p. 104; 2026: Q1 10-Q p. 20, Q2 10-Q p. 26
A32: Depreciation expense | F32: 3.911 | G32: 5.6 | J32: 18.175 | K32: 24.377 | N32: Q1 10-Q p. 17; Q2 10-Q p. 20
A33: of which in cost of revenue | F33: 1.6 | G33: 1.601 | J33: 9.871 | K33: 18.482 | N33: Q1 10-Q p. 17; Q2 10-Q p. 20
A35: The IPO stock pay catch-up in Q2 2026 (the 10-Q does not split it)
A36: Q2 2026: RSU expense | K36: 332.92 | N36: Q2 10-Q p. 26, expense by security type.
A37: Q2 2026: PRSU expense (CEO and CTO) | K37: 34.223 | N37: Q2 10-Q p. 26-27.
A38: Cumulative RSU charge the 424B4 expected at the IPO | K38: 370.9 | N38: 424B4 p. 100: 'we expect to record a cumulative stock-based compensation expense of $370.9 million' in the quarter to 30 Jun 2026.
A39: Q2 2026 stock pay less the 424B4 catch-up estimate (derived) | K39: =K31-K38 -> 6.108 | N39: An estimate of the Q2 run rate. The catch-up actually booked is not disclosed; the forecast run rate is a separate input (Assumptions).
A41: Cash flow by quarter: Q1 as filed in each 10-Q; Q2 = six months less Q1 (derived) | N41: Q1-Q4 2024 and Q3-Q4 2025 cannot be derived: the 424B4 gives annual cash flows only and no 10-Q covers those quarters; only H2 2025 = FY2025 - 6M 2025 (memo).
A42: Net income (loss) | F42: -23.867 | G42: =N(CF_Hist!D7)-N(F42) -> 309.512 | J42: -14.006 | K42: =N(CF_Hist!E7)-N(J42) -> -450.528 | N42: F, J: Q1 10-Q p. 9; G, K: six months (CF_Hist) less Q1
A43: Depreciation and amortization | F43: 3.911 | G43: =N(CF_Hist!D8)-N(F43) -> 5.404 | J43: 18.175 | K43: =N(CF_Hist!E8)-N(J43) -> 24.376 | N43: F, J: Q1 10-Q p. 9; G, K: six months (CF_Hist) less Q1
A44: Stock-based compensation | F44: 9.154 | G44: =N(CF_Hist!D9)-N(F44) -> 13.281 | J44: 9.593 | K44: =N(CF_Hist!E9)-N(J44) -> 377.008 | N44: F, J: Q1 10-Q p. 9; G, K: six months (CF_Hist) less Q1
A45: Amortization of customer warrants | F45: — | G45: =N(CF_Hist!D10)-N(F45) -> 0 | J45: 2.053 | K45: =N(CF_Hist!E10)-N(J45) -> 44.262 | N45: F, J: Q1 10-Q p. 9; G, K: six months (CF_Hist) less Q1
A46: Non-cash interest expense | F46: — | G46: =N(CF_Hist!D12)-N(F46) -> 0 | J46: 18.949 | K46: =N(CF_Hist!E12)-N(J46) -> 19.653 | N46: F, J: Q1 10-Q p. 9; G, K: six months (CF_Hist) less Q1
A47: Non-cash lease expense | F47: 2.912 | G47: =N(CF_Hist!D11)-N(F47) -> 2.96 | J47: 15.775 | K47: =N(CF_Hist!E11)-N(J47) -> 23.329 | N47: F, J: Q1 10-Q p. 9; G, K: six months (CF_Hist) less Q1
...

Sheet Revenue_Hist
A1: Cerebras Systems Inc. (Nasdaq: CBRS) | Revenue, customers, costs by function and other notes, as filed
A2: USD millions (filed thousands / 1,000) unless stated. 424B4 notes (FY2024, FY2025) and Q2 10-Q notes (6M 2025, 6M 2026).
A4: Fiscal year ends 31 December | B4: FY2024A | C4: FY2025A | D4: 6M 2025A | E4: 6M 2026A | M4: Comentarios FG | N4: Source / derivation
A6: A. Revenue by timing of recognition (424B4 Note 3; Q2 10-Q Note 3)
A7: Hardware revenue recognized at a point in time | B7: 211.965 | C7: 358.44 | D7: 139.969 | E7: 164.712 | N7: 424B4 p. F-18; Q2 10-Q p. 14
A8: Cloud and other services revenue recognized at a point in time | B8: 0.628 | C8: 2.194 | D8: 0.851 | E8: 0.987 | N8: 424B4 p. F-18; Q2 10-Q p. 14
A9: Cloud and other services revenue recognized over time | B9: 77.659 | C9: 149.357 | D9: 62.014 | E9: 207.817 | N9: 424B4 p. F-18; Q2 10-Q p. 14
A10: Total revenue | B10: 290.252 | C10: 509.991 | D10: 202.834 | E10: 373.516 | N10: 424B4 p. F-18; Q2 10-Q p. 14
A12: B. Revenue by billing location of the customer
A13: United States | B13: 282.685 | C13: 187.643 | D13: 105.096 | E13: 154.071 | N13: 424B4 p. F-20; Q2 10-Q p. 16
A14: Europe, Middle East, and Africa | B14: 7.567 | C14: 322.231 | D14: 97.643 | E14: 218.921 | N14: 424B4 p. F-20; Q2 10-Q p. 16
A15: Other | B15: — | C15: 0.117 | D15: 0.095 | E15: 0.524 | N15: 424B4 p. F-20; Q2 10-Q p. 16
A16: Total revenue | B16: 290.252 | C16: 509.991 | D16: 202.834 | E16: 373.516 | N16: 424B4 p. F-20; Q2 10-Q p. 16
A17: Europe, Middle East and Africa: % of revenue | B17: =N(B14)/B16 -> 0.026070449 | C17: =N(C14)/C16 -> 0.63183664 | D17: =N(D14)/D16 -> 0.48139365 | E17: =N(E14)/E16 -> 0.58610876
A19: C. Customers above 10% of revenue ('*' = below 10%, kept as filed; letters change meaning between reports)
A20: Customer A (424B4: MBZUAI; Q2 10-Q: MBZUAI) | B20: * | C20: 0.62 | D20: 0.47 | E20: 0.49 | N20: 424B4 p. F-19 names A as MBZUAI (62% of FY2025); Q2 10-Q p. 15 (34% of Q2 2026, 49% of 6M 2026).
A21: Customer B (424B4: G42) | B21: 0.85 | C21: 0.24 | N21: 424B4 p. F-19: G42 24.0% of FY2025 and 85.0% of FY2024.
A22: Customer B (Q2 10-Q; unnamed) | D22: * | E22: 0.2 | N22: Q2 10-Q p. 15: unnamed. OpenAI revenue was US$56.8m in Q2 2026 = 32% of revenue, so B is probably OpenAI (an inference, not a filed fact).
A23: Customer C (Q2 10-Q; unnamed) | D23: * | E23: * | N23: Q2 10-Q p. 15: 10% of Q2 2026.
A24: Customer D (Q2 10-Q: G42) | D24: 0.41 | E24: 0.1 | N24: Q2 10-Q p. 15: G42 9% of Q2 2026 (below 10%, '*'), 10% of 6M 2026, 41% of 6M 2025.
A25: Q2 2026 alone: A 34%, B 32%, C 10%; G42 9% (Q2 10-Q p. 15)
A27: D. Depreciation by function (424B4 p. F-25; Q2 10-Q p. 20)
A28: Cost of revenue | B28: 3.15 | C28: 12.699 | D28: 3.201 | E28: 28.353 | N28: 424B4 p. F-25
A29: Research and development | B29: 6.536 | C29: 14.513 | D29: 4.55 | E29: 11.568 | N29: 424B4 p. F-25
A30: Sales and marketing | B30: 1.095 | C30: 7.186 | D30: 1.544 | E30: 1.639 | N30: 424B4 p. F-25
A31: General and administrative | B31: 0.756 | C31: 0.056 | D31: 0.02 | E31: 0.991 | N31: 424B4 p. F-25
A32: Total depreciation expense | B32: 11.537 | C32: 34.454 | D32: 9.315 | E32: 42.551 | N32: 424B4 p. F-25
A34: E. Stock-based compensation by function (424B4 p. F-34; Q2 10-Q p. 26)
A35: Cost of revenue | B35: 0.921 | C35: 0.827 | D35: 0.513 | E35: 16.303 | N35: 424B4 p. F-34; Q2 10-Q p. 26
A36: Research and development | B36: 41.397 | C36: 32.154 | D36: 15.013 | E36: 227.846 | N36: 424B4 p. F-34; Q2 10-Q p. 26
A37: Sales and marketing | B37: 8.723 | C37: 9.95 | D37: 3.482 | E37: 72.847 | N37: 424B4 p. F-34; Q2 10-Q p. 26
A38: General and administrative | B38: 7.523 | C38: 6.836 | D38: 3.427 | E38: 69.605 | N38: 424B4 p. F-34; Q2 10-Q p. 26
A39: Total stock-based compensation expense | B39: 58.564 | C39: 49.767 | D39: 22.435 | E39: 386.601 | N39: 424B4 p. F-34; Q2 10-Q p. 26
A41: F. Costs before depreciation and stock pay (derived; feeds the forecast) | N41: Allocation convention (mine): depreciation in cost of revenue goes to cloud (data center systems); stock pay in cost of revenue is split by each line's share of cost of revenue.
A42: Hardware cost of revenue before depreciation and stock pay | B42: =N(IS_Hist!B12)-B35*N(IS_Hist!B12)/N(IS_Hist!B14) -> 136.55506 | C42: =N(IS_Hist!C12)-C35*N(IS_Hist!C12)/N(IS_Hist!C14) -> 204.20141 | D42: =N(IS_Hist!D12)-D35*N(IS_Hist!D12)/N(IS_Hist!D14) -> 94.681358 | E42: =N(IS_Hist!E12)-E35*N(IS_Hist!E12)/N(IS_Hist!E14) -> 110.7188
A43: Cloud cost of revenue before depreciation and stock pay | B43: =N(IS_Hist!B13)-B28-B35*N(IS_Hist!B13)/N(IS_Hist!B14) -> 26.887937 | C43: =N(IS_Hist!C13)-C28-C35*N(IS_Hist!C13)/N(IS_Hist!C14) -> 93.192593 | D43: =N(IS_Hist!D13)-D28-D35*N(IS_Hist!D13)/N(IS_Hist!D14) -> 30.735642 | E43: =N(IS_Hist!E13)-E28-E35*N(IS_Hist!E13)/N(IS_Hist!E14) -> 106.4062
A44: Cost of revenue before depreciation and stock pay | B44: =B42+B43 -> 163.443 | C44: =C42+C43 -> 297.394 | D44: =D42+D43 -> 125.417 | E44: =E42+E43 -> 217.125
A45: Hardware gross margin before depreciation and stock pay | B45: =1-B42/N(IS_Hist!B7) -> 0.35576598 | C45: =1-C42/N(IS_Hist!C7) -> 0.43030519 | D45: =1-D42/N(IS_Hist!D7) -> 0.3235548 | E45: =1-E42/N(IS_Hist!E7) -> 0.32780368
A46: Cloud gross margin before depreciation and stock pay | B46: =1-B43/N(IS_Hist!B8) -> 0.65654659 | C46: =1-C43/N(IS_Hist!C8) -> 0.38507438 | D46: =1-D43/N(IS_Hist!D8) -> 0.51108499 | E46: =1-E43/N(IS_Hist!E8) -> 0.49040153
A47: Gross margin as reported | B47: =N(IS_Hist!B15)/N(IS_Hist!B9) -> 0.42286703 | C47: =N(IS_Hist!C15)/N(IS_Hist!C9) -> 0.39034218 | D47: =N(IS_Hist!D15)/N(IS_Hist!D9) -> 0.3633661 | E47: =N(IS_Hist!E15)/N(IS_Hist!E9) -> 0.29914381
...

Sheet Backlog
A1: Cerebras Systems Inc. (Nasdaq: CBRS) | Backlog (remaining performance obligations) and its conversion into revenue
A2: USD millions. Column B = 30 Jun 2026; C = H2 2026E; D-L = fiscal years. The filing gives the share of backlog in three windows; how each window spreads over the years is my convention (blue cells).
B3: Actual | C3: Forecast
A4: Period | B4: Jun 2026A | C4: H2 2026E | D4: 2027E | E4: 2028E | F4: 2029E | G4: 2030E | H4: 2031E | I4: 2032E | J4: 2033E | K4: 2034E | L4: 2035E | M4: Comentarios FG | N4: Source / derivation
A6: A. What the filings say
A7: Backlog (remaining performance obligations), 30 Jun 2026 | B7: 25400 | N7: Q2 10-Q p. 15: 'was $25.4 billion as of June 30, 2026. A significant amount of the balance was attributable to ... the MRA with OpenAI.'
A8: Share recognized in the 24 months to 30 Jun 2028 | B8: 0.22 | N8: Q2 10-Q p. 15: 'approximately 22%'
A9: Share recognized in months 25 to 48 (Jul 2028 - Jun 2030) | B9: 0.43 | N9: Q2 10-Q p. 15: '43% between months 25 and 48'
A10: Share recognized after June 2030 (derived) | B10: =1-B8-B9 -> 0.35 | N10: Q2 10-Q p. 15: "the remaining balance thereafter"
A11: Backlog stated gross of the customer warrant reduction: 1 = gross (used), 2 = net | B11: 1 | N11: The filings do not say. Q2 10-Q p. 15: backlog "includes deferred revenue and amounts that are expected to be invoiced"; 424B4 p. 96: "the gross revenue amount without contra-revenue is what the customer is invoiced and pays in cash"; the warrants are a separate asset recognized "as a reduction of revenue in proportion to the related revenue recognized" (Q2 10-Q p. 24). So gross: reported backlog revenue = schedule less warrant amortization; cash = schedule.
A12: Memo: backlog at 31 Dec 2025 | B12: 24600 | N12: 424B4 p. F-19: US$24.6bn; 15% in the 24 months to Dec 2027, 43% in months 25-48.
A13: Memo: backlog growth in six months (derived) | B13: =B7/B12-1 -> 0.032520325
A14: OpenAI Committed Capacity (MW) | B14: 750 | N14: 424B4 p. 91 and Q2 10-Q p. 15: 750 MW, deployed in tranches 2026-2028; each tranche runs 3-4 years, extendable to 5.
A15: Memo: OpenAI deal value announced ('more than') | B15: 20000 | N15: 424B4 p. v: 'a multi-year deal with OpenAI valued at more than $20 billion dollars'.
A16: OpenAI Additional Capacity option (MW) | B16: 1250 | N16: 424B4 p. 91: option on 1.25 GW more, deployed by the end of 2030 (up to 2.0 GW in total).
A18: B. Conversion schedule (convention: how each filed window spreads over the periods)
A19: Window 1 (22%): share in each period | C19: 0.1 | D19: 0.4 | E19: 0.5 | N19: Ramp: tranches deploy 2026-2028, so H2 2026 is small. Convention.
A20: Window 2 (43%): share in each period | E20: 0.25 | F20: 0.5 | G20: 0.25 | N20: Even over H2 2028, 2029 and H1 2030. Convention.
A21: Window 3 (35%): share in each period | G21: 0.15 | H21: 0.3 | I21: 0.3 | J21: 0.25 | N21: H2 2030 to 2033: the last tranches (deployed by 2028) run up to five years. Convention.
A22: Backlog revenue at full realization | C22: =$B$7*($B$8*N(C19)+$B$9*N(C20)+$B$10*N(C21)) -> 558.8 | D22: =$B$7*($B$8*N(D19)+$B$9*N(D20)+$B$10*N(D21)) -> 2235.2 | E22: =$B$7*($B$8*N(E19)+$B$9*N(E20)+$B$10*N(E21)) -> 5524.5 | F22: =$B$7*($B$8*N(F19)+$B$9*N(F20)+$B$10*N(F21)) -> 5461 | G22: =$B$7*($B$8*N(G19)+$B$9*N(G20)+$B$10*N(G21)) -> 4064 | H22: =$B$7*($B$8*N(H19)+$B$9*N(H20)+$B$10*N(H21)) -> 2667 | I22: =$B$7*($B$8*N(I19)+$B$9*N(I20)+$B$10*N(I21)) -> 2667 | J22: =$B$7*($B$8*N(J19)+$B$9*N(J20)+$B$10*N(J21)) -> 2222.5 | ... L22: =$B$7*($B$8*N(L19)+$B$9*N(L20)+$B$10*N(L21)) -> 0
A23: Revenue from the 30 Jun 2026 backlog (x realization) | C23: =C22*Assumptions!$C$19-IF($B$11=1,C35+C46,0) -> 512.21554 | D23: =D22*Assumptions!$C$19-IF($B$11=1,D35+D46,0) -> 2048.8622 | E23: =E22*Assumptions!$C$19-IF($B$11=1,E35+E46,0) -> 5063.9491 | F23: =F22*Assumptions!$C$19-IF($B$11=1,F35+F46,0) -> 5005.7428 | G23: =G22*Assumptions!$C$19-IF($B$11=1,G35+G46,0) -> 3725.2039 | H23: =H22*Assumptions!$C$19-IF($B$11=1,H35+H46,0) -> 2444.6651 | I23: =I22*Assumptions!$C$19-IF($B$11=1,I35+I46,0) -> 2591.3916 | J23: =J22*Assumptions!$C$19-IF($B$11=1,J35+J46,0) -> 2159.493 | ... L23: =L22*Assumptions!$C$19-IF($B$11=1,L35+L46,0) -> 0 | N23: Reported revenue: schedule x realization, less the warrant amortization when the backlog is gross (row 'basis'). Cash billed = schedule x realization.
A25: C. Renewals and the OpenAI option
A26: Renewals of expired backlog capacity | C26: 0 | D26: =C26*(1+Assumptions!$C$22)+Assumptions!$C$20*MAX(0,C23-D23) -> 0 | E26: =D26*(1+Assumptions!$C$22)+Assumptions!$C$20*MAX(0,D23-E23) -> 0 | F26: =E26*(1+Assumptions!$C$22)+Assumptions!$C$20*MAX(0,E23-F23) -> 46.565049 | G26: =F26*(1+Assumptions!$C$22)+Assumptions!$C$20*MAX(0,F23-G23) -> 1072.3931 | H26: =G26*(1+Assumptions!$C$22)+Assumptions!$C$20*MAX(0,G23-H23) -> 2128.996 | I26: =H26*(1+Assumptions!$C$22)+Assumptions!$C$20*MAX(0,H23-I23) -> 2192.8658 | J26: =I26*(1+Assumptions!$C$22)+Assumptions!$C$20*MAX(0,I23-J23) -> 2604.1707 | K26: =J26*(1+Assumptions!$C$22)+Assumptions!$C$20*MAX(0,J23-K23) -> 4409.8902 | L26: =K26*(1+Assumptions!$C$22)+Assumptions!$C$20*MAX(0,K23-L23) -> 4542.1869 | N26: Each year: renewal rate x the fall in backlog revenue; renewed revenue then grows at the terminal growth rate.
A27: Revenue per GW-year implied by the committed contract (derived) | B27: =B7/(B14/1000)/Assumptions!$C$40 -> 8466.6667 | N27: Backlog / 0.75 GW / average term. A rough price; the backlog also holds other customers.
A28: Option capacity in service (share of the exercised GW) | F28: 0.25 | G28: 0.75 | H28: 1 | I28: 1 | J28: 1 | K28: 1 | L28: 1 | N28: Deployed by the end of 2030 (424B4 p. 91). Convention.
A29: Additional Capacity option: billed revenue (gross) | C29: =$B$16/1000*Assumptions!$C$21*$B$27*N(C28) -> 0 | D29: =$B$16/1000*Assumptions!$C$21*$B$27*N(D28) -> 0 | E29: =$B$16/1000*Assumptions!$C$21*$B$27*N(E28) -> 0 | F29: =$B$16/1000*Assumptions!$C$21*$B$27*N(F28) -> 0 | G29: =$B$16/1000*Assumptions!$C$21*$B$27*N(G28) -> 0 | H29: =$B$16/1000*Assumptions!$C$21*$B$27*N(H28) -> 0 | I29: =$B$16/1000*Assumptions!$C$21*$B$27*N(I28) -> 0 | J29: =$B$16/1000*Assumptions!$C$21*$B$27*N(J28) -> 0 | ... L29: =$B$16/1000*Assumptions!$C$21*$B$27*N(L28) -> 0
A30: Revenue from the Additional Capacity option (reported: gross less its warrant amortization) | C30: =C29-IF($B$11=1,C48,0) -> 0 | D30: =D29-IF($B$11=1,D48,0) -> 0 | E30: =E29-IF($B$11=1,E48,0) -> 0 | F30: =F29-IF($B$11=1,F48,0) -> 0 | G30: =G29-IF($B$11=1,G48,0) -> 0 | H30: =H29-IF($B$11=1,H48,0) -> 0 | I30: =I29-IF($B$11=1,I48,0) -> 0 | J30: =J29-IF($B$11=1,J48,0) -> 0 | ... L30: =L29-IF($B$11=1,L48,0) -> 0
A31: Pass-through data center revenue (at cost) | C31: =C22*Assumptions!$C$19*Assumptions!$C$27 -> 27.94 | D31: =D22*Assumptions!$C$19*Assumptions!$C$27 -> 111.76 | E31: =E22*Assumptions!$C$19*Assumptions!$C$27 -> 276.225 | F31: =F22*Assumptions!$C$19*Assumptions!$C$27 -> 273.05 | G31: =G22*Assumptions!$C$19*Assumptions!$C$27 -> 203.2 | H31: =H22*Assumptions!$C$19*Assumptions!$C$27 -> 133.35 | I31: =I22*Assumptions!$C$19*Assumptions!$C$27 -> 133.35 | J31: =J22*Assumptions!$C$19*Assumptions!$C$27 -> 111.125 | ... L31: =L22*Assumptions!$C$19*Assumptions!$C$27 -> 0
A33: D. Customer warrant asset: amortization as a reduction of revenue (non-cash)
A34: Customer warrant asset, 30 Jun 2026 | B34: =BS_Hist!F51 -> 1128.397 | N34: Q2 10-Q p. 25: amortized 'in proportion to the related revenue' through October 2031.
A35: Amortization (in proportion to backlog revenue, H2 2026E-2031E) | C35: =$B$34*C22/SUM($C$22:$H$22) -> 30.742705 | D35: =$B$34*D22/SUM($C$22:$H$22) -> 122.97082 | E35: =$B$34*E22/SUM($C$22:$H$22) -> 303.93356 | F35: =$B$34*F22/SUM($C$22:$H$22) -> 300.44007 | G35: =$B$34*G22/SUM($C$22:$H$22) -> 223.58331 | H35: =$B$34*H22/SUM($C$22:$H$22) -> 146.72654 | I35: 0 | J35: 0 | K35: 0 | L35: 0 | N35: Inside reported revenue (non-cash). New warrant tranches that vest later are not modelled; their shares are in the diluted count.
A36: Customer warrant asset, end of period | B36: =B34 -> 1128.397 | C36: =B36-C35 -> 1097.6543 | D36: =C36-D35 -> 974.68348 | E36: =D36-E35 -> 670.74992 | F36: =E36-F35 -> 370.30985 | G36: =F36-G35 -> 146.72654 | H36: =G36-H35 -> 0 | I36: =H36-I35 -> 0 | J36: =I36-J35 -> 0 | ... L36: =K36-L35 -> 0
A38: E. Unvested OpenAI warrant tranches (23.4m shares): vesting and contra-revenue
A39: Shares that vest on committed delivery dates of capacity (millions) | B39: 23.411518 | N39: 424B4 p. 86: "23,411,518 shares in the aggregate will vest in multiple tranches on certain committed delivery dates of compute capacity pursuant to the MRA, including ... the Additional Capacity"; full vesting "only if OpenAI exercises all options ... a total of 2GW".
A40: Capacity those shares cover: committed + option (MW) | B40: =B14+B16 -> 2000
A41: Shares per MW (convention: pro rata to capacity; the filing gives no split) | B41: =B39/B40 -> 0.011705759
A42: Shares tied to the Committed Capacity (750 MW) | B42: =B41*B14 -> 8.7793193 | N42: Probable of vesting (Q2 10-Q p. 24): in the diluted count in every scenario.
A43: Shares tied to the Additional Capacity option (1.25 GW) | B43: =B41*B16 -> 14.632199 | N43: Q2 10-Q p. 24: 'not considered probable'; in the count only for the share of the option exercised (Bull 50%).
A44: Grant-date fair value per OpenAI warrant share (USD) | B44: 82.02 | N44: Q2 10-Q p. 24: 'classified as an equity instrument, and the grant date fair value was $82.02 per share'; an asset is booked on vesting (10.03m vested shares = US$822.9m in 6M 2026) and recognized 'as a reduction of revenue in proportion to the related revenue'.
A45: Warrant value of the committed tranches (US$m) | B45: =B42*B44 -> 720.07976
...

Sheet Cap_Table
A1: Cerebras Systems Inc. (Nasdaq: CBRS) | Shares outstanding, dilutive securities and the diluted count (treasury method)
A2: Shares in millions. Basic shares from the Q2 10-Q cover (5 Aug 2026, the latest count). Dilutive securities at 30 Jun 2026 (Q2 10-Q p. 17) unless stated.
A4: Item | B4: Value | C4: Price (USD) | D4: Comentarios FG | E4: Source / derivation
A6: A. Common stock outstanding, 5 Aug 2026 (Q2 10-Q cover, p. 1)
A7: Class A common stock | B7: 112.24711 | E7: 112,247,109 shares
A8: Class B common stock (20 votes a share) | B8: 111.60142 | E8: 111,601,424 shares
A9: Class N common stock (non-voting) | B9: 13.715508 | E9: 13,715,508 shares; includes 10,033,508 OpenAI warrant shares exercised in July 2026
A10: Common shares outstanding | B10: =B7+B8+B9 -> 237.56404
A11: Memo: Class N shares at 30 Jun 2026 (balance sheet caption) | B11: 3.682 | E11: Q2 10-Q p. 6: 3,682,000 shares
A12: OpenAI warrant: shares vested in January 2026 | B12: 4.459337 | E12: Q2 10-Q p. 24
A13: OpenAI warrant: shares vested in June 2026 | B13: 5.574171 | E13: Q2 10-Q p. 24
A14: OpenAI warrant: shares exercised in July 2026 | B14: 10.033508 | E14: Q2 10-Q p. 29
A16: B. Dilutive securities (treasury method at the market price)
A17: Market price used for the treasury method (USD) | C17: =Market_Package!B10 -> 119.31 | E17: Convention: the market price, not the DCF value (avoids a circular count).
A18: Options to purchase common stock (30 Jun 2026) | B18: 23.797 | C18: 4.97 | E18: Count: Q2 10-Q p. 17. Weighted average exercise price US$4.97 at 31 Dec 2025 (424B4 p. F-32), the latest price the filings give.
A19: Options, net shares (treasury method) | B19: =B18*MAX(0,1-C18/C17) -> 22.805708
A20: Unvested RSUs (no exercise price) | B20: 16.532 | E20: Q2 10-Q p. 17
A21: CEO and CTO PRSUs (vest at US$75bn, US$150bn, US$250bn market value) | B21: 9 | E21: Q2 10-Q p. 17, p. 26
A22: Include the PRSUs (1 = yes, 0 = no) | B22: 0 | E22: 0: thresholds far above today's value (about US$28bn basic). Their expense stays a cost in the forecast instead (no double count).
A23: OpenAI warrant: total shares (exercise price US$0.00001) | B23: 33.445026 | E23: Q2 10-Q p. 24; equity-classified.
A24: OpenAI warrant: shares not yet vested (derived) | B24: =B23-B12-B13 -> 23.411518 | E24: Vest with capacity delivered, Additional Capacity bought and value or payment thresholds (Q2 10-Q p. 24).
A25: of which tied to the Committed Capacity: in the count | B25: =Backlog!B42 -> 8.7793193 | E25: Backlog E: pro rata to capacity (convention).
A26: of which tied to the Additional Capacity option: in the count x share exercised | B26: =Backlog!B43*Assumptions!$C$21 -> 0 | E26: Bull 50% exercised; Base and Bear 0%. Changes with the scenario switch.
A27: AWS warrant (exercise price US$100.00) | B27: 2.696678 | C27: 100 | E27: Q2 10-Q p. 25: 269,668 vested at issue; the rest vest on AWS payment thresholds; expires 19 Jun 2033.
A28: AWS warrant, net shares (treasury method) | B28: =B27*MAX(0,1-C27/C17) -> 0.43645002
A29: Memo: early exercised shares subject to repurchase | B29: 0.574 | E29: Q2 10-Q p. 17; already legally issued, so not added.
A30: Diluted shares (millions) | B30: =B10+B19+B20+B21*B22+B25+B26+B28 -> 286.11752 | E30: Method: basic (5 Aug 2026) + options and AWS warrant by the treasury method + RSUs + OpenAI tranches whose trigger occurs in the active scenario.
A32: C. Stock pay of awards already in the diluted count (feeds Schedules E)
A33: Unrecognized RSU expense, 31 Dec 2025 | B33: 343.5 | E33: 424B4 p. F-34 (latest disclosed; the 10-Qs give no total)
A34: Unrecognized option expense, 31 Dec 2025 | B34: 33.2 | E34: 424B4 p. F-33
A35: CEO and CTO RSUs granted in Q1 2026 (grant-date value) | B35: 101.6 | E35: Q2 10-Q p. 26
A36: Less: RSU expense recognized in 6M 2026 | B36: 332.92 | E36: Q2 10-Q p. 26
A37: Less: option expense recognized in 6M 2026 | B37: 18.579 | E37: Q2 10-Q p. 26
A38: Remaining expense of awards in the diluted count, 30 Jun 2026 (estimate) | B38: =MAX(0,B33+B34+B35-B36-B37) -> 126.801 | E38: A floor: RSUs granted to others in 2026 are not disclosed. This part is non-cash in the DCF because its shares are counted.
A39: Amortization period (years) | B39: 2.91 | E39: 424B4 p. F-34: weighted-average period for RSUs
A40: Memo: PRSU grant-date value (expense stays a cost; shares excluded) | B40: 531.2 | E40: Q2 10-Q p. 27; US$34.2m recognized in Q2 2026
A42: D. The IPO (424B4 and Q2 10-Q)
A43: IPO price per Class A share (USD) | C43: 185 | E43: 424B4 cover; completed 15 May 2026 (Q2 10-Q).
A44: Underwriting discount per share (USD) | C44: 4.3475 | E44: 424B4 cover
A45: Shares sold, including the full 4.5m over-allotment | B45: 34.5 | E45: Q2 10-Q: underwriters exercised their option in full
...

Sheet Assumptions
A1: Cerebras Systems Inc. (Nasdaq: CBRS) | Assumptions and scenarios
A2: Blue cells are inputs. Each driver has Base, Bull and Bear rows; the Active row follows the switch in C5. Black cells in section B derive from the filings. USD millions unless stated.
B3: Actual | C3: Forecast
A4: Fiscal year ends 31 December | B4: 2025A | C4: 2026E | D4: 2027E | E4: 2028E | F4: 2029E | G4: 2030E | H4: 2031E | I4: 2032E | J4: 2033E | K4: 2034E | L4: 2035E | M4: Comentarios FG | N4: Source / derivation
A5: Scenario switch: 1 = Base, 2 = Bull, 3 = Bear | C5: 1 | N5: Same convention as the house templates (Supuestos!C5).
A6: Active scenario | C6: =CHOOSE(C5,"Base","Bull","Bear") -> Base
A8: A. Second half of 2026, backlog and valuation inputs (one value per scenario)
C9: Active | D9: Base | E9: Bull | F9: Bear
A10: H2 2026E hardware revenue | C10: =CHOOSE($C$5,D10,E10,F10) -> 130 | D10: 130 | E10: 160 | F10: 100 | N10: H1 2026 164.7 (Q1 110.6, Q2 54.1; Q2 10-Q p. 7). Q2 carries US$28.0m of warrant cost. Analyst input.
A11: H2 2026E other cloud and inference revenue (not in the backlog) | C11: =CHOOSE($C$5,D11,E11,F11) -> 150 | D11: 150 | E11: 180 | F11: 120 | N11: H1 2026 cloud 208.8 less OpenAI 74.4 = 134.4 (Revenue_Hist). Analyst input.
A12: H2 2026E hardware gross margin before depreciation and stock pay | C12: =CHOOSE($C$5,D12,E12,F12) -> 0.36 | D12: 0.36 | E12: 0.4 | F12: 0.3 | N12: H1 2026 32.8%; Q2 2026 41.7% before the warrant cost (Revenue_Hist). Analyst input.
A13: H2 2026E cloud gross margin before depreciation and stock pay | C13: =CHOOSE($C$5,D13,E13,F13) -> 0.4 | D13: 0.4 | E13: 0.45 | F13: 0.33 | N13: H1 2026 49.0%, Q2 2026 42.2%; new data center leases start before their revenue (US$1.5bn signed in Q2, Q2 10-Q p. 28). Analyst input.
A14: H2 2026E research and development, excluding stock pay and depreciation | C14: =CHOOSE($C$5,D14,E14,F14) -> 210 | D14: 210 | E14: 200 | F14: 230 | N14: H1 2026 156.2; Q2 92.9 (Revenue_Hist). Analyst input.
A15: H2 2026E sales and marketing, excluding stock pay and depreciation | C15: =CHOOSE($C$5,D15,E15,F15) -> 40 | D15: 40 | E15: 38 | F15: 45 | N15: H1 2026 27.2 (Revenue_Hist). Analyst input.
A16: H2 2026E general and administrative, excluding stock pay and depreciation | C16: =CHOOSE($C$5,D16,E16,F16) -> 50 | D16: 50 | E16: 48 | F16: 55 | N16: H1 2026 36.1, incl. IPO payroll tax (Revenue_Hist). Analyst input.
A17: H2 2026E stock-based compensation (run rate, no IPO catch-up) | C17: =CHOOSE($C$5,D17,E17,F17) -> 180 | D17: 180 | E17: 160 | F17: 220 | N17: Disclosed balances amortizing: RSUs US$193.0m over 1.56 years and options US$33.2m over 1.78 years (424B4 pp. 100, F-33), PRSUs US$531.2m over 3.4-5.9 years, CEO/CTO RSUs US$101.6m (Q2 10-Q pp. 26-27), plus new grants. Analyst input.
A18: H2 2026E capital expenditures | C18: =CHOOSE($C$5,D18,E18,F18) -> 900 | D18: 900 | E18: 1100 | F18: 700 | N18: H1 2026 548.9 (Q1 132.0, Q2 416.9); construction in progress 604.0 at 30 Jun 2026 (Q2 10-Q). Analyst input.
A19: Backlog realization: share of the 30 Jun 2026 backlog that becomes revenue | C19: =CHOOSE($C$5,D19,E19,F19) -> 1 | D19: 1 | E19: 1 | F19: 0.85 | N19: Contracted, take-or-pay (424B4); Bear allows for slippage or renegotiation with one customer that holds most of it. Analyst input.
