Workbook

Sheet 00_Cover
A1: SK hynix Inc. — Institutional Financial Model
A2: Memory semiconductors / AI infrastructure | USD millions | As of 2026-07-15
A4: Model field | B4: Value
A5: Ticker / identifier | B5: KRX: 000660
A6: Model archetype | B6: Operating company / DCF
A7: Decision readiness | B7: Official-results operating model
A8: Reporting currency | B8: KRW
A9: Model currency | B9: USD millions
A10: Market-data date | B10: Not applicable
A11: Current market price | B11: Not available
A12: Primary source | B12: https://news.skhynix.com/sk-hynix-announces-fy25-financial-results/
A13: Key limitation | B13: This is the Korean memory company the request described. KRW trillion disclosures translated to USD at the current FX snapshot.
A15: Institutional-grade means auditable sources, explicit assumptions, formula-driven forecasts, valuation, sensitivities, checks and governance. It does not mean that missing private-company disclosures have been invented.

Sheet Sources
A1: Sources and data lineage
A2: Every hardcode is mapped to a source, date, currency and transformation.
A4: Source ID | B4: Use | C4: URL / reference | D4: As of | E4: Source currency | F4: Transformation | G4: Limitation | H4: Status
A5: S1 | B5: Historical financials | C5: https://news.skhynix.com/sk-hynix-announces-fy25-financial-results/ | D5: Latest annual filing/results | E5: KRW | F5: Converted at current snapshot FX (KRW to USD = 0.00067253) | G5: This is the Korean memory company the request described. KRW trillion disclosures translated to USD at the current FX snapshot. | H5: Official-results operating model
A6: S2 | B6: Market price | C6: Not applicable | D6: 2026-07-15 | E6: N/A | F6: Dated market input; not a historical financial source | G6: Market prices move after the as-of date | H6: Not loaded
A7: S3 | B7: FX snapshot | C7: Yahoo Finance KRW/USD chart snapshot | D7: 2026-07-15 | E7: KRW | F7: KRW per USD, inverted | G7: Current FX used across historical years for comparability; not historical spot | H7: Loaded
A8: S4 | B8: Forecast assumptions | C8: Model Assumptions sheet | D8: 2026-07-15 | E8: USD | F8: User-editable scenario inputs | G8: Forecasts are estimates, not reported facts | H8: Model input

Sheet Historical
A1: Historical financials
A2: USD millions; blanks are intentional when the cited source did not support a defensible value.
A4: Metric | B4: 2021A | C4: 2022A | D4: 2023A | E4: 2024A | F4: 2025A | G4: Source tag / note | H4: Quality
A5: Revenue | E5: 44516.854 | F5: 65334.181 | G5: Issuer results / manual source mapping | H5: Source-backed / see note
A6: Gross profit | G6: Issuer results / manual source mapping | H6: Missing / not inferred
A7: Operating income / EBIT | E7: 15782.49 | F7: 31747.707 | G7: Issuer results / manual source mapping | H7: Source-backed / see note
A8: Net income | E8: 13314.032 | F8: 28883.8 | G8: Issuer results / manual source mapping | H8: Source-backed / see note
A9: Cash from operations | G9: Issuer results / manual source mapping | H9: Missing / not inferred
A10: Capital expenditure | G10: Issuer results / manual source mapping | H10: Missing / not inferred
A11: Assets | G11: Issuer results / manual source mapping | H11: Missing / not inferred
A12: Liabilities | G12: Issuer results / manual source mapping | H12: Missing / not inferred
A13: Equity | G13: Issuer results / manual source mapping | H13: Missing / not inferred
A14: Cash | G14: Issuer results / manual source mapping | H14: Missing / not inferred
A15: Debt | G15: Issuer results / manual source mapping | H15: Missing / not inferred
A16: Diluted shares (mm) | G16: Issuer results / manual source mapping | H16: Missing / not inferred

Sheet Assumptions
A1: Assumptions and scenarios
A2: Blue-font cells are user inputs. Scenario selector: 1 = Base, 2 = Bull, 3 = Bear.
A3: Scenario selector | B3: 1
A4: Metric | B4: Bear | C4: Base | D4: Bull | E4: Active | F4: Rationale / source
A5: Revenue growth | B5: 0.22 | C5: 0.25 | D5: 0.28 | E5: =CHOOSE($B$3,C5,D5,B5) -> 0.25 | F5: Historical trend / sector anchor
A6: EBIT margin | B6: 0.45592798 | C6: 0.48592798 | D6: 0.51592798 | E6: =CHOOSE($B$3,C6,D6,B6) -> 0.48592798 | F6: Latest reported operating margin or explicit assumption
A7: Cash tax rate | B7: 0.25 | C7: 0.22 | D7: 0.19 | E7: =CHOOSE($B$3,C7,D7,B7) -> 0.22 | F7: Normalized cash-tax assumption
A8: D&A / revenue | B8: 0.03 | C8: 0.04 | D8: 0.05 | E8: =CHOOSE($B$3,C8,D8,B8) -> 0.04 | F8: Sector-neutral default when source facts are unavailable
A9: Capex / revenue | B9: 0.06 | C9: 0.045 | D9: 0.035 | E9: =CHOOSE($B$3,C9,D9,B9) -> 0.045 | F9: Capital intensity assumption
A10: NWC investment / incremental revenue | B10: 0.025 | C10: 0.015 | D10: 0.005 | E10: =CHOOSE($B$3,C10,D10,B10) -> 0.015 | F10: Working-capital intensity
A11: WACC | B11: 0.11 | C11: 0.09 | D11: 0.075 | E11: =CHOOSE($B$3,C11,D11,B11) -> 0.09 | F11: USD discount-rate assumption
A12: Terminal growth | B12: 0.015 | C12: 0.025 | D12: 0.035 | E12: =CHOOSE($B$3,C12,D12,B12) -> 0.025 | F12: Long-run nominal USD growth

Sheet Forecast
A1: Forecast model
A2: Formula-driven five-year projection in USD millions.
A4: Metric | B4: 2025A | C4: 2026E | D4: 2027E | E4: 2028E | F4: 2029E | G4: 2030E
A5: Revenue | B5: 65334.181 | C5: =B5*(1+Assumptions!$E$5) -> 81667.726 | D5: =C5*(1+Assumptions!$E$5) -> 102084.66 | E5: =D5*(1+Assumptions!$E$5) -> 127605.82 | F5: =E5*(1+Assumptions!$E$5) -> 159507.28 | G5: =F5*(1+Assumptions!$E$5) -> 199384.1
A6: Growth | C6: =IF(B5<>0,C5/B5-1,0) -> 0.25 | D6: =IF(C5<>0,D5/C5-1,0) -> 0.25 | E6: =IF(D5<>0,E5/D5-1,0) -> 0.25 | F6: =IF(E5<>0,F5/E5-1,0) -> 0.25 | G6: =IF(F5<>0,G5/F5-1,0) -> 0.25
A7: EBIT margin | B7: 0.48592798 | C7: =Assumptions!$E$6 -> 0.48592798 | D7: =Assumptions!$E$6 -> 0.48592798 | E7: =Assumptions!$E$6 -> 0.48592798 | F7: =Assumptions!$E$6 -> 0.48592798 | G7: =Assumptions!$E$6 -> 0.48592798
A8: EBIT | B8: 31747.707 | C8: =C5*C7 -> 39684.633 | D8: =D5*D7 -> 49605.792 | E8: =E5*E7 -> 62007.24 | F8: =F5*F7 -> 77509.049 | G8: =G5*G7 -> 96886.312
A9: Cash tax rate | C9: =Assumptions!$E$7 -> 0.22 | D9: =Assumptions!$E$7 -> 0.22 | E9: =Assumptions!$E$7 -> 0.22 | F9: =Assumptions!$E$7 -> 0.22 | G9: =Assumptions!$E$7 -> 0.22
A10: NOPAT | C10: =C8*(1-C9) -> 30954.014 | D10: =D8*(1-D9) -> 38692.518 | E10: =E8*(1-E9) -> 48365.647 | F10: =F8*(1-F9) -> 60457.059 | G10: =G8*(1-G9) -> 75571.323
A11: D&A | C11: =C5*Assumptions!$E$8 -> 3266.709 | D11: =D5*Assumptions!$E$8 -> 4083.3863 | E11: =E5*Assumptions!$E$8 -> 5104.2329 | F11: =F5*Assumptions!$E$8 -> 6380.2911 | G11: =G5*Assumptions!$E$8 -> 7975.3639
A12: Capital expenditure | C12: =-C5*Assumptions!$E$9 -> -3675.0477 | D12: =-D5*Assumptions!$E$9 -> -4593.8096 | E12: =-E5*Assumptions!$E$9 -> -5742.262 | F12: =-F5*Assumptions!$E$9 -> -7177.8275 | G12: =-G5*Assumptions!$E$9 -> -8972.2843
A13: Change in NWC | C13: =-(C5-B5)*Assumptions!$E$10 -> -245.00318 | D13: =-(D5-C5)*Assumptions!$E$10 -> -306.25397 | E13: =-(E5-D5)*Assumptions!$E$10 -> -382.81747 | F13: =-(F5-E5)*Assumptions!$E$10 -> -478.52183 | G13: =-(G5-F5)*Assumptions!$E$10 -> -598.15229
A14: FCFF | C14: =C10+C11+C12+C13 -> 30300.672 | D14: =D10+D11+D12+D13 -> 37875.84 | E14: =E10+E11+E12+E13 -> 47344.8 | F14: =F10+F11+F12+F13 -> 59181 | G14: =G10+G11+G12+G13 -> 73976.25
A15: Cash | B15: 0 | C15: =$B$15 -> 0 | D15: =$B$15 -> 0 | E15: =$B$15 -> 0 | F15: =$B$15 -> 0 | G15: =$B$15 -> 0
A16: Debt | B16: 0 | C16: =$B$16 -> 0 | D16: =$B$16 -> 0 | E16: =$B$16 -> 0 | F16: =$B$16 -> 0 | G16: =$B$16 -> 0

Sheet Valuation
A1: Discounted cash flow valuation
A2: Valuation is formula-driven and scenario-sensitive; private-company outputs are enterprise-value ranges only.
A4: Metric | B4: Year 1 | C4: Year 2 | D4: Year 3 | E4: Year 4 | F4: Year 5 | G4: Total / output
A5: FCFF | B5: =Forecast!C14 -> 30300.672 | C5: =Forecast!D14 -> 37875.84 | D5: =Forecast!E14 -> 47344.8 | E5: =Forecast!F14 -> 59181 | F5: =Forecast!G14 -> 73976.25
A6: Discount factor | B6: =1/(1+Assumptions!$E$11)^1 -> 0.91743119 | C6: =1/(1+Assumptions!$E$11)^2 -> 0.84167999 | D6: =1/(1+Assumptions!$E$11)^3 -> 0.77218348 | E6: =1/(1+Assumptions!$E$11)^4 -> 0.70842521 | F6: =1/(1+Assumptions!$E$11)^5 -> 0.64993139
A7: PV FCFF | B7: =B5*B6 -> 27798.782 | C7: =C5*C6 -> 31879.337 | D7: =D5*D6 -> 36558.873 | E7: =E5*E6 -> 41925.313 | F7: =F5*F6 -> 48079.487
A9: Output | B9: Value
A10: PV explicit FCFF | B10: =SUM(B7:F7) -> 186241.79
A11: Terminal value | B11: =IF(Assumptions!$E$11>Assumptions!$E$12,F5*(1+Assumptions!$E$12)/(Assumptions!$E$11-Assumptions!$E$12),0) -> 1166548.6
A12: PV terminal value | B12: =B11*F6 -> 758176.53
A13: Enterprise value | B13: =B10+B12 -> 944418.32
A14: Cash | B14: =Forecast!B15 -> 0
A15: Debt | B15: =Forecast!B16 -> 0
A16: Equity value | B16: =B13+B14-B15 -> 944418.32
A17: Diluted shares (mm) | B17: 0
A18: Implied value / share | B18: =IF(B17>0,B16/B17,0) -> 0
A19: Current market price
A20: Upside / (downside) | B20: =IF(B19>0,B18/B19-1,0) -> 0

Sheet Sensitivity
A1: Valuation sensitivity
A2: Enterprise value sensitivity to WACC and terminal growth.
A4: WACC / g | B4: 0.07 | C4: 0.08 | D4: 0.09 | E4: 0.1 | F4: 0.11
A5: 0.01 | B5: =SUMPRODUCT(Valuation!$B$5:$F$5,1/(1+B$4)^{1,2,3,4,5})+IF(B$4>$A5,Valuation!$F$5*(1+$A5)/(B$4-$A5)/(1+B$4)^5,0) -> 1085799.1 | C5: =SUMPRODUCT(Valuation!$B$5:$F$5,1/(1+C$4)^{1,2,3,4,5})+IF(C$4>$A5,Valuation!$F$5*(1+$A5)/(C$4-$A5)/(1+C$4)^5,0) -> 918394.42 | D5: =SUMPRODUCT(Valuation!$B$5:$F$5,1/(1+D$4)^{1,2,3,4,5})+IF(D$4>$A5,Valuation!$F$5*(1+$A5)/(D$4-$A5)/(1+D$4)^5,0) -> 793245.31 | E5: =SUMPRODUCT(Valuation!$B$5:$F$5,1/(1+E$4)^{1,2,3,4,5})+IF(E$4>$A5,Valuation!$F$5*(1+$A5)/(E$4-$A5)/(1+E$4)^5,0) -> 696249.29 | F5: =SUMPRODUCT(Valuation!$B$5:$F$5,1/(1+F$4)^{1,2,3,4,5})+IF(F$4>$A5,Valuation!$F$5*(1+$A5)/(F$4-$A5)/(1+F$4)^5,0) -> 618945.73
A6: 0.02 | B6: =SUMPRODUCT(Valuation!$B$5:$F$5,1/(1+B$4)^{1,2,3,4,5})+IF(B$4>$A6,Valuation!$F$5*(1+$A6)/(B$4-$A6)/(1+B$4)^5,0) -> 1273919.5 | C6: =SUMPRODUCT(Valuation!$B$5:$F$5,1/(1+C$4)^{1,2,3,4,5})+IF(C$4>$A6,Valuation!$F$5*(1+$A6)/(C$4-$A6)/(1+C$4)^5,0) -> 1047858.1 | D6: =SUMPRODUCT(Valuation!$B$5:$F$5,1/(1+D$4)^{1,2,3,4,5})+IF(D$4>$A6,Valuation!$F$5*(1+$A6)/(D$4-$A6)/(1+D$4)^5,0) -> 886828.6 | E6: =SUMPRODUCT(Valuation!$B$5:$F$5,1/(1+E$4)^{1,2,3,4,5})+IF(E$4>$A6,Valuation!$F$5*(1+$A6)/(E$4-$A6)/(1+E$4)^5,0) -> 766425.36 | F6: =SUMPRODUCT(Valuation!$B$5:$F$5,1/(1+F$4)^{1,2,3,4,5})+IF(F$4>$A6,Valuation!$F$5*(1+$A6)/(F$4-$A6)/(1+F$4)^5,0) -> 673090.67
A7: 0.03 | B7: =SUMPRODUCT(Valuation!$B$5:$F$5,1/(1+B$4)^{1,2,3,4,5})+IF(B$4>$A7,Valuation!$F$5*(1+$A7)/(B$4-$A7)/(1+B$4)^5,0) -> 1556100.2 | C7: =SUMPRODUCT(Valuation!$B$5:$F$5,1/(1+C$4)^{1,2,3,4,5})+IF(C$4>$A7,Valuation!$F$5*(1+$A7)/(C$4-$A7)/(1+C$4)^5,0) -> 1229107.3 | D7: =SUMPRODUCT(Valuation!$B$5:$F$5,1/(1+D$4)^{1,2,3,4,5})+IF(D$4>$A7,Valuation!$F$5*(1+$A7)/(D$4-$A7)/(1+D$4)^5,0) -> 1011606.3 | E7: =SUMPRODUCT(Valuation!$B$5:$F$5,1/(1+E$4)^{1,2,3,4,5})+IF(E$4>$A7,Valuation!$F$5*(1+$A7)/(E$4-$A7)/(1+E$4)^5,0) -> 856651.75 | F7: =SUMPRODUCT(Valuation!$B$5:$F$5,1/(1+F$4)^{1,2,3,4,5})+IF(F$4>$A7,Valuation!$F$5*(1+$A7)/(F$4-$A7)/(1+F$4)^5,0) -> 740771.85
A8: 0.04 | B8: =SUMPRODUCT(Valuation!$B$5:$F$5,1/(1+B$4)^{1,2,3,4,5})+IF(B$4>$A8,Valuation!$F$5*(1+$A8)/(B$4-$A8)/(1+B$4)^5,0) -> 2026401.2 | C8: =SUMPRODUCT(Valuation!$B$5:$F$5,1/(1+C$4)^{1,2,3,4,5})+IF(C$4>$A8,Valuation!$F$5*(1+$A8)/(C$4-$A8)/(1+C$4)^5,0) -> 1500981 | D8: =SUMPRODUCT(Valuation!$B$5:$F$5,1/(1+D$4)^{1,2,3,4,5})+IF(D$4>$A8,Valuation!$F$5*(1+$A8)/(D$4-$A8)/(1+D$4)^5,0) -> 1186295.1 | E8: =SUMPRODUCT(Valuation!$B$5:$F$5,1/(1+E$4)^{1,2,3,4,5})+IF(E$4>$A8,Valuation!$F$5*(1+$A8)/(E$4-$A8)/(1+E$4)^5,0) -> 976953.59 | F8: =SUMPRODUCT(Valuation!$B$5:$F$5,1/(1+F$4)^{1,2,3,4,5})+IF(F$4>$A8,Valuation!$F$5*(1+$A8)/(F$4-$A8)/(1+F$4)^5,0) -> 827790.5
A9: 0.05 | B9: =SUMPRODUCT(Valuation!$B$5:$F$5,1/(1+B$4)^{1,2,3,4,5})+IF(B$4>$A9,Valuation!$F$5*(1+$A9)/(B$4-$A9)/(1+B$4)^5,0) -> 2967003.3 | C9: =SUMPRODUCT(Valuation!$B$5:$F$5,1/(1+C$4)^{1,2,3,4,5})+IF(C$4>$A9,Valuation!$F$5*(1+$A9)/(C$4-$A9)/(1+C$4)^5,0) -> 1954104 | D9: =SUMPRODUCT(Valuation!$B$5:$F$5,1/(1+D$4)^{1,2,3,4,5})+IF(D$4>$A9,Valuation!$F$5*(1+$A9)/(D$4-$A9)/(1+D$4)^5,0) -> 1448328.3 | E9: =SUMPRODUCT(Valuation!$B$5:$F$5,1/(1+E$4)^{1,2,3,4,5})+IF(E$4>$A9,Valuation!$F$5*(1+$A9)/(E$4-$A9)/(1+E$4)^5,0) -> 1145376.2 | F9: =SUMPRODUCT(Valuation!$B$5:$F$5,1/(1+F$4)^{1,2,3,4,5})+IF(F$4>$A9,Valuation!$F$5*(1+$A9)/(F$4-$A9)/(1+F$4)^5,0) -> 943815.38

Sheet Checks
A1: Model checks
A2: All critical checks should read PASS before decision use.
A4: Check | B4: Result | C4: Severity | D4: Interpretation
A5: Forecast revenue non-negative | B5: =IF(MIN(Forecast!C5:G5)>=0,"PASS","FAIL") -> PASS | C5: Critical | D5: No negative revenue
A6: FCFF formula populated | B6: =IF(COUNT(Forecast!C14:G14)=5,"PASS","FAIL") -> PASS | C6: Critical | D6: Five forecast cash flows
A7: WACC exceeds terminal growth | B7: =IF(Assumptions!E11>Assumptions!E12,"PASS","FAIL") -> PASS | C7: Critical | D7: Required for convergent DCF
A8: Valuation bridge | B8: =IF(ABS(Valuation!B16-(Valuation!B13+Valuation!B14-Valuation!B15))<0.1,"PASS","FAIL") -> PASS | C8: Critical | D8: EV plus cash less debt equals equity value
A9: Historical source coverage | B9: LIMITED | C9: Readiness | D9: Manual/summary sources or missing financial history remain explicitly limited
A11: Overall gate | B11: =IF(COUNTIF(B5:B9,"FAIL")=0,IF(COUNTIF(B5:B9,"LIMITED")=0,"PASS","PASS WITH LIMITATIONS"),"FAIL") -> PASS WITH LIMITATIONS
A12: Decision use | B12: Official-results operating model

Sheet Sector_KPIs
A1: Sector KPI framework
A2: A decision-useful model requires sector drivers beyond the three statements.
A4: KPI | B4: Historical | C4: Forecast | D4: Status / source requirement
A5: Revenue by platform | D5: Input-ready; populate from issuer operating disclosures
A6: Units / wafer shipments | D6: Input-ready; populate from issuer operating disclosures
A7: ASP | D7: Input-ready; populate from issuer operating disclosures
A8: Gross margin | D8: Input-ready; populate from issuer operating disclosures
A9: R&D intensity | D9: Input-ready; populate from issuer operating disclosures
A10: Capex intensity | D10: Input-ready; populate from issuer operating disclosures
A11: Backlog | D11: Input-ready; populate from issuer operating disclosures
A12: Inventory days | D12: Input-ready; populate from issuer operating disclosures
A13: Free cash flow | D13: Input-ready; populate from issuer operating disclosures

Sheet Change_Log
A1: Change log and governance
A2: Version history and model-owner review record.
A4: Date | B4: Version | C4: Author | D4: Change | E4: Evidence | F4: Reviewer status
A5: 2026-07-15 | B5: 1.0 | C5: Codex | D5: Initial institutional model framework and source pack | E5: https://news.skhynix.com/sk-hynix-announces-fy25-financial-results/ | F5: Builder-verified
A6: 2026-07-15 | B6: 1.0 | C6: Codex | D6: Formula, package and visual QA | E6: Checks sheet and preview artifacts | F6: Pending owner investment judgment
A7: 46224 | B7: Elevation pass 1 (statement-grade, Samsung pilot pattern): added audited FY2023-FY2025 (FY2023 BS excluded, SOURCE_GAP) statement sheets IS_Hist/CI_Hist/BS_Hist/CF_Hist (KRW mm, published constants from SEC Form 424(B)(4)), Checks_TieOut (24 tie-outs incl. cross-statement + cross-schedule), Sources_Audited, and sector schedules PPE_Capex/Debt_Schedule/Inventory_Schedule (Notes 12/16/9). FY2021-FY2022 documented as SOURCE_GAP (no public English audited FS; confidential 144A/Reg S bond circulars found but not used per redistribution restriction; DART is Korean-only). Forecast/Assumptions/Valuation NOT rewired to new base — left PARTIAL, flagged in Sources_Audited. Root model untouched; v2 saved under the maintainer's archive. Built via Mog SDK. | C7: Claude (run 41538014)

Sheet IS_Hist
A1: SK hynix Inc. and Subsidiaries — Consolidated Statements of Profit or Loss (audited)
A2: KRW millions. FY2023-FY2025 per SEC Form 424(B)(4), 3-yr comparative income statement (source: 424B4, pp. F-6).
A4: Line item | B4: FY2023A | C4: FY2024A | D4: FY2025A | E4: Note ref
A5: Revenue | B5: 32765719 | C5: 66192960 | D5: 97146675 | E5: 4,24,31
A6: Cost of sales | B6: 33299167 | C6: 34364814 | D6: 38455885 | E6: 26.31
A7: Gross profit (loss) | B7: -533448 | C7: 31828146 | D7: 58690790
A8: Selling and administrative expenses | B8: 3446158 | C8: 3924486 | D8: 5018834 | E8: 25.26
A9: Research and development expenses | B9: 3750707 | C9: 4436341 | D9: 6465637 | E9: 25.26
A10: Finance income | B10: 2261801 | C10: 4855082 | D10: 16373480 | E10: 5.27
A11: Finance expenses | B11: 6093167 | C11: 5707997 | D11: 12504998 | E11: 5.27
A12: Share of profit (loss) of equity-accounted investees | B12: 15061 | C12: -38245 | D12: -564553 | E12: 11
A13: Other income | B13: 623867 | C13: 1476579 | D13: 333277 | E13: 28
A14: Other expenses | B14: 735065 | C14: 167388 | D14: 377973 | E14: 28
A15: Profit (loss) before income tax | B15: -11657816 | C15: 23885350 | D15: 50465552
A16: Income tax expense (benefits) | B16: -2520269 | C16: 4088448 | D16: 7517650 | E16: 29
A17: Profit (loss) for the year | B17: -9137547 | C17: 19796902 | D17: 42947902
A19: Profit (loss) attributable to:
A20: Owners of the Parent Company | B20: -9112428 | C20: 19788681 | D20: 42919287
A21: Non-controlling interests | B21: -25119 | C21: 8221 | D21: 28615
A23: Earnings (loss) per share — basic (won) | B23: -13244 | C23: 28732 | D23: 62044 | E23: 30
A24: Earnings (loss) per share — diluted (won) | B24: -13244 | C24: 28419 | D24: 60378 | E24: 30

Sheet CI_Hist
A1: SK hynix Inc. and Subsidiaries — Consolidated Statements of Comprehensive Income (Loss) (audited)
A2: KRW millions. Same source basis as IS_Hist (424B4, p. F-6).
A4: Line item | B4: FY2023A | C4: FY2024A | D4: FY2025A | E4: Note ref
A5: Profit (loss) for the year | B5: -9137547 | C5: 19796902 | D5: 42947902
A6: Item that will never be reclassified to profit or loss:
A7: Remeasurements of defined benefit liability, net of tax | B7: -17944 | C7: -273610 | D7: -79633 | E7: 19
A8: Items that are or may be reclassified to profit or loss:
A9: Foreign operations - foreign currency translation differences, net of tax | B9: 132561 | C9: 1374587 | D9: 173701
A10: Gain (loss) on valuation of derivatives, net of tax | B10: -22414 | C10: 637 | D10: 2118 | E10: 21
A11: Equity-accounted investees - share of OCI (loss), net of tax | B11: 7848 | C11: 145906 | D11: -26740 | E11: 11
A12: Other comprehensive income for the year, net of tax | B12: 100051 | C12: 1247520 | D12: 69446
A13: Total comprehensive income (loss) for the year | B13: -9037496 | C13: 21044422 | D13: 43017348
A14: Total comprehensive income (loss) attributable to:
A15: Owners of the Parent Company | B15: -9014999 | C15: 21033123 | D15: 42984408
A16: Non-controlling interests | B16: -22497 | C16: 11299 | D16: 32940

Sheet BS_Hist
A1: SK hynix Inc. and Subsidiaries — Consolidated Statements of Financial Position (audited)
A2: KRW millions, as of December 31. 424B4 presents only a 2-yr comparative BS (FY2024/FY2025); FY2023 = SOURCE_GAP, see Sources_Audited (424B4, pp. F-4/F-5).
A4: Line item | B4: FY2023A | C4: FY2024A | D4: FY2025A | E4: Note ref
A5: Assets
A6: Current assets
A7: Cash and cash equivalents | C7: 11205117 | D7: 14923766 | E7: 5.6
A8: Short-term financial instruments | C8: 2382010 | D8: 14679719 | E8: 5,6,7
A9: Short-term investment assets | C9: 569236 | D9: 5338768 | E9: 5.6
A10: Trade receivables, net | C10: 13019006 | D10: 18199078 | E10: 5,6,8,31
A11: Loans and other receivables, net | C11: 293061 | D11: 386343 | E11: 5,6,8,31
A12: Other financial assets | C12: 45309 | D12: 195259 | E12: 5,6,7,21
A13: Inventories, net | C13: 13313937 | D13: 14289390 | E13: 9
A14: Current tax assets | C14: 57467 | D14: 67715
A15: Other current assets | C15: 1393744 | D15: 1378035 | E15: 10
A16: Total current assets | C16: 42278887 | D16: 69458073
A17: Non-current assets
A18: Investments in associates and joint ventures | C18: 1940663 | D18: 1320927 | E18: 11
A19: Long-term investment assets | C19: 4041276 | D19: 14547099 | E19: 5.6
A20: Loans and other receivables, net (non-current) | C20: 444286 | D20: 420036 | E20: 5,6,8,31
A21: Other financial assets (non-current) | C21: 346749 | D21: 1114462 | E21: 5,6,7,21
A22: Property, plant and equipment, net | C22: 60157474 | D22: 77502704 | E22: 12.32
A23: Right-of-use assets, net | C23: 2486871 | D23: 2336457 | E23: 13.31
A24: Intangible assets, net | C24: 4018847 | D24: 4049402 | E24: 14
A25: Investment property, net | C25: 200 | D25: 188
A26: Deferred tax assets | C26: 2811559 | D26: 3660493 | E26: 20.29
A27: Employee benefit assets | C27: 1154255 | D27: 1552888 | E27: 19
A28: Other non-current assets | C28: 174142 | D28: 144930 | E28: 10
A29: Total non-current assets | C29: 77576322 | D29: 106649586
A30: Total assets | C30: 119855209 | D30: 176107659
A32: Liabilities
A33: Current liabilities
A34: Trade payables | C34: 2277347 | D34: 2848455 | E34: 5,6,31
A35: Other payables | C35: 6967013 | D35: 6434144 | E35: 5,6,31,32
A36: Other non-trade payables | C36: 3983543 | D36: 6283111 | E36: 5,6,15,31
A37: Borrowings | C37: 5252238 | D37: 8161757 | E37: 5,6,16,31,32
A38: Other financial liabilities | C38: 1741587 | D38: 4913879 | E38: 5,6,21,31
A39: Provisions | C39: 270235 | D39: 228937 | E39: 18
A40: Current tax liabilities | C40: 3083950 | D40: 7023813
A41: Lease liabilities | C41: 588355 | D41: 547296 | E41: 5,6,13,31
A42: Other current liabilities | C42: 801176 | D42: 937607 | E42: 17
...

Sheet CF_Hist
A1: SK hynix Inc. and Subsidiaries — Consolidated Statements of Cash Flows (audited)
A2: KRW millions. FY2023-FY2025, 3-yr comparative. Signs as published (outflows negative). Primary statement only; sub-ledger reconciliation (profit -> adjustments -> cash generated) lives in Note 33, not replicated here (424B4, p. F-10).
A4: Line item | B4: FY2023A | C4: FY2024A | D4: FY2025A | E4: Note ref
A5: Operating activities
A6: Cash generated from operating activities | B6: 6688866 | C6: 31250846 | D6: 58904432 | E6: 33
A7: Interest received | B7: 198872 | C7: 322960 | D7: 337982
A8: Interest paid | B8: -1261540 | C8: -1276564 | D8: -938849
A9: Dividends received | B9: 35935 | C9: 50731 | D9: 960716
A10: Income tax paid | B10: -1383942 | C10: -552088 | D10: -5891155
A11: Net cash provided by operating activities | B11: 4278191 | C11: 29795885 | D11: 53373126
A13: Investing activities
A14: Decrease in short-term financial instruments | B14: 1409187 | C14: 1499026 | D14: 6513772
A15: Increase in short-term financial instruments | B15: -1469396 | C15: -3370863 | D15: -18804330
A16: Decrease (increase) in short-term investment assets, net | B16: 199912 | C16: 457163 | D16: -4552604
A17: Collection of loans and other receivables | B17: 47564 | C17: 38222 | D17: 32880
A18: Increase in loans and other receivables | B18: -251498 | C18: -47704 | D18: -178331
A19: Proceeds from disposal of long-term investment assets | B19: 18279 | C19: 2373 | D19: 1233030
A20: Acquisitions of long-term investment assets | B20: -30537 | C20: -19460 | D20: -33956
A21: Decrease in other financial assets | B21: 577 | C21: 57 | D21: 115091
A22: Increase in other financial assets | B22: -5358 | C22: -109646 | D22: -1105649
A23: Proceeds from disposal of property, plant and equipment | B23: 1539825 | C23: 47126 | D23: 144828
A24: Acquisitions of property, plant and equipment | B24: -8325138 | C24: -15945534 | D24: -27518924
A25: Proceeds from disposal of intangible assets | B25: 484 | C25: 19703 | D25: 2142
... A28: Acquisitions of investments in associates | B28: -22765 | C28: -25859 | D28: -9000
A29: Proceeds from disposal of assets held for sale | C29: 145355 | D29: 85216
A30: Cash outflow from business combination | D30: -3079783 | E30: 32
A31: Receipt of government grants | D31: 144911
A32: Net cash used in investing activities | B32: -7334727 | C32: -18004637 | D32: -48054251
A34: Financing activities
A35: Proceeds from borrowings | B35: 20657967 | C35: 8717964 | D35: 8183735 | E35: 33
A36: Repayment of borrowings | B36: -13689433 | C36: -16093621 | D36: -7416131 | E36: 33
A37: Payment of lease liabilities | B37: -461466 | C37: -601821 | D37: -596465 | E37: 33
A38: Dividends paid | B38: -825575 | C38: -826323 | D38: -1681166
A39: Exercise stock-options | B39: 53
A40: Issue of shares by subsidiaries and changes in ownership in subsidiaries | B40: -9220 | C40: 6032
A41: Proceeds from disposal of treasury shares | B41: 24519 | C41: 93829 | D41: 65035
A42: Net cash provided by (used in) financing activities | B42: 5696845 | C42: -8703940 | D42: -1444992
A44: Effects of exchange rate changes on cash and cash equivalents | B44: -29987 | C44: 530480 | D44: -155234
A45: Net increase in cash and cash equivalents | B45: 2610322 | C45: 3617788 | D45: 3718649
A46: Cash and cash equivalents at the beginning of the year | B46: 4977007 | C46: 7587329 | D46: 11205117
...

Sheet PPE_Capex
A1: SK hynix Inc. and Subsidiaries — Property, Plant & Equipment / Capex Schedule (audited, Note 12)
A2: KRW millions. FY2024/FY2025 rollforward disclosed at this granularity; FY2023 acquisitions/capex line only available via CF_Hist (Acquisitions of PP&E). Memory-sector capex is the dominant driver of PP&E growth.
A4: Line item | B4: FY2023A | C4: FY2024A | D4: FY2025A
A5: Beginning balance | C5: 52704853 | D5: 60157474
A6: Acquisitions (capex) | C6: 17955821 | D6: 30172818
A7: Impairment | C7: 9 | D7: -45157
A8: Disposals | C8: -32050 | D8: -91416
A9: Depreciation | C9: -11535635 | D9: -12663516
A10: Transfers | C10: -1071 | D10: 7660
A11: FX differences and other | C11: 1542376 | D11: -74055
A12: Reclassified as assets held for sale | C12: -478971 | D12: -2363
A13: Business combination | D13: 41259
A14: Ending balance | C14: 60157474 | D14: 77502704
A16: Acquisition cost (gross) | C16: 156604752 | D16: 184637341
A17: Accumulated depreciation | C17: -95991943 | D17: -106670892
A18: Accumulated impairment | C18: -368826 | D18: -409571
A19: Government grants (contra) | C19: -86509 | D19: -54174
A21: Depreciation allocated to cost of sales | B21: 11810720 | C21: 10696150 | D21: 11839495
A22: Depreciation allocated to SG&A | B22: 250180 | C22: 249368 | D22: 242739
A23: Depreciation allocated to R&D and other | B23: 669550 | C23: 590117 | D23: 581282
A24: Total depreciation (cross-check to rollforward) | B24: 12730450 | C24: 11535635 | D24: 12663516
A26: Capitalized borrowing costs on qualifying assets | B26: 136622 | C26: 202995 | D26: 249760
A27: Capitalization rate used (%) | B27: 4.34 | C27: 6.32 | D27: 3.91

Sheet Debt_Schedule
A1: SK hynix Inc. and Subsidiaries — Debt / Borrowings Schedule (audited, Note 16)
A2: KRW millions. Balance detail FY2024/FY2025 (Note 16(1)); financing cash-flow rows FY2023-FY2025 (CF_Hist).
A4: Line item | B4: FY2023A | C4: FY2024A | D4: FY2025A
A5: Balance by type
A6: Short-term borrowings | C6: 1283488 | D6: 2395797
A7: Current portion of long-term borrowings | C7: 1143258 | D7: 1470301
A8: Current portion of debentures | C8: 2825492 | D8: 4295659
A9: Total current borrowings | C9: 5252238 | D9: 8161757
A10: Long-term borrowings (non-current) | C10: 5022069 | D10: 2879750
A11: Debentures (non-current) | C11: 12409426 | D11: 11206398
A12: Total non-current borrowings | C12: 17431495 | D12: 14086148
A13: Total borrowings (gross debt) | C13: 22683733 | D13: 22247905
A15: CF financing activity (debt)
A16: Proceeds from borrowings | B16: 20657967 | C16: 8717964 | D16: 8183735
A17: Repayment of borrowings | B17: -13689433 | C17: -16093621 | D17: -7416131
A18: Net financing cash flow — borrowings | B18: 6968534 | C18: -7375657 | D18: 767604
A20: Financing costs (IS)
A21: Finance expenses (IS, total incl. non-debt items) | B21: 6093167 | C21: 5707997 | D21: 12504998
A22: Interest paid (CF) | B22: -1261540 | C22: -1276564 | D22: -938849
A24: Notes: FY2023 debt balance not disclosed at this granularity in the 2-yr comparative BS/Note 16 (SOURCE_GAP, see Sources_Audited). Foreign exchangeable bond (USD 1,700mm issued, USD 738.4mm outstanding at FY25, 1.75% coupon, matures 2030-04-11) embedded in current debentures. Capitalized borrowing cost and capitalization rate cross-referenced from PPE_Capex sheet (Note 12(4)).

Sheet Inventory_Schedule
A1: SK hynix Inc. and Subsidiaries — Inventory Schedule (audited, Note 9)
A2: KRW millions. Category-level detail FY2024/FY2025 (Note 9(1)/(3)); cost-of-sales linkage FY2023-FY2025 (Note 9(2)).
A4: Line item | B4: FY2023A | C4: FY2024A | D4: FY2025A
A5: Carrying amount by category — Dec 31, 2025
A6: Merchandise | D6: 5303
A7: Finished goods | D7: 2406965
A8: Work-in-process | D8: 9207437
A9: Raw materials | D9: 1489313
A10: Supplies | D10: 902612
A11: Goods in transit | D11: 277760
A12: Total inventories, net (2025) | D12: 14289390
A14: Carrying amount by category — Dec 31, 2024
A15: Merchandise | C15: 6775
A16: Finished goods | C16: 2514283
A17: Work-in-process | C17: 8622765
A18: Raw materials | C18: 1461026
A19: Supplies | C19: 586299
A20: Goods in transit | C20: 122789
A21: Total inventories, net (2024) | C21: 13313937
A23: Valuation allowance rollforward
A24: Beginning balance | C24: 2426602 | D24: 1156637
A25: Charged to cost of sales | C25: 98592 | D25: 112906
A26: Utilization upon sales | C26: -1368557 | D26: -774638
A27: Ending balance | C27: 1156637 | D27: 494905
A29: P&L linkage
A30: Inventories recognized as cost of sales | B30: 32206255 | C30: 35634490 | D30: 39117310
A31: Cost of sales (IS, total incl. non-inventory) | B31: 33299167 | C31: 34364814 | D31: 38455885
A33: Notes: acquisition-cost / valuation-allowance split by category available only for FY2024/FY2025 (Note 9(1)); FY2023 category-level detail not disclosed in this filing (SOURCE_GAP). "Inventories recognized as cost of sales" (Note 9(2)) differs from total Cost of sales (IS) because IS cost of sales also includes non-inventory production costs (labor, depreciation allocated to COGS, etc. per Note 12(2)).

Sheet Checks_TieOut
A1: Tie-out checks — audited historical statements (all deltas must be 0; KRW millions)
A2: MASTER | B2: =IF(COUNTIF(E5:E31,"FAIL")=0,"OK — ALL TIE-OUTS PASS","FAIL") -> OK — ALL TIE-OUTS PASS
A4: Check | B4: FY2023A | C4: FY2024A | D4: FY2025A | E4: Status
A5: IS: Gross profit = Revenue − COGS | B5: =IS_Hist!B5-IS_Hist!B6-IS_Hist!B7 -> 0 | C5: =IS_Hist!C5-IS_Hist!C6-IS_Hist!C7 -> 0 | D5: =IS_Hist!D5-IS_Hist!D6-IS_Hist!D7 -> 0 | E5: =IF(AND(ABS(N(B5))<=0.5,ABS(N(C5))<=0.5,ABS(N(D5))<=0.5),"PASS","FAIL") -> PASS
A6: IS: PBT chain (Gross−SG&A−R&D+FinInc−FinExp+JV+OthInc−OthExp) | B6: =IS_Hist!B7-IS_Hist!B8-IS_Hist!B9+IS_Hist!B10-IS_Hist!B11+IS_Hist!B12+IS_Hist!B13-IS_Hist!B14-IS_Hist!B15 -> 0 | C6: =IS_Hist!C7-IS_Hist!C8-IS_Hist!C9+IS_Hist!C10-IS_Hist!C11+IS_Hist!C12+IS_Hist!C13-IS_Hist!C14-IS_Hist!C15 -> 0 | D6: =IS_Hist!D7-IS_Hist!D8-IS_Hist!D9+IS_Hist!D10-IS_Hist!D11+IS_Hist!D12+IS_Hist!D13-IS_Hist!D14-IS_Hist!D15 -> 0 | E6: =IF(AND(ABS(N(B6))<=0.5,ABS(N(C6))<=0.5,ABS(N(D6))<=0.5),"PASS","FAIL") -> PASS
A7: IS: NI = PBT − tax | B7: =IS_Hist!B15-IS_Hist!B16-IS_Hist!B17 -> 0 | C7: =IS_Hist!C15-IS_Hist!C16-IS_Hist!C17 -> 0 | D7: =IS_Hist!D15-IS_Hist!D16-IS_Hist!D17 -> 0 | E7: =IF(AND(ABS(N(B7))<=0.5,ABS(N(C7))<=0.5,ABS(N(D7))<=0.5),"PASS","FAIL") -> PASS
A8: IS: NI = parent + NCI | B8: =IS_Hist!B20+IS_Hist!B21-IS_Hist!B17 -> 0 | C8: =IS_Hist!C20+IS_Hist!C21-IS_Hist!C17 -> 0 | D8: =IS_Hist!D20+IS_Hist!D21-IS_Hist!D17 -> 0 | E8: =IF(AND(ABS(N(B8))<=0.5,ABS(N(C8))<=0.5,ABS(N(D8))<=0.5),"PASS","FAIL") -> PASS
A9: CI: OCI total = sum of components | B9: =SUM(CI_Hist!B7:B11)-CI_Hist!B12 -> 0 | C9: =SUM(CI_Hist!C7:C11)-CI_Hist!C12 -> 0 | D9: =SUM(CI_Hist!D7:D11)-CI_Hist!D12 -> 0 | E9: =IF(AND(ABS(N(B9))<=0.5,ABS(N(C9))<=0.5,ABS(N(D9))<=0.5),"PASS","FAIL") -> PASS
A10: CI: TCI = NI + OCI | B10: =CI_Hist!B5+CI_Hist!B12-CI_Hist!B13 -> 0 | C10: =CI_Hist!C5+CI_Hist!C12-CI_Hist!C13 -> 0 | D10: =CI_Hist!D5+CI_Hist!D12-CI_Hist!D13 -> 0 | E10: =IF(AND(ABS(N(B10))<=0.5,ABS(N(C10))<=0.5,ABS(N(D10))<=0.5),"PASS","FAIL") -> PASS
A11: CI: TCI = parent + NCI | B11: =CI_Hist!B15+CI_Hist!B16-CI_Hist!B13 -> 0 | C11: =CI_Hist!C15+CI_Hist!C16-CI_Hist!C13 -> 0 | D11: =CI_Hist!D15+CI_Hist!D16-CI_Hist!D13 -> 0 | E11: =IF(AND(ABS(N(B11))<=0.5,ABS(N(C11))<=0.5,ABS(N(D11))<=0.5),"PASS","FAIL") -> PASS
A12: CF: CFO chain (Cash gen + Int recd + Int paid + Div recd + Tax paid) | B12: =CF_Hist!B6+CF_Hist!B7+CF_Hist!B8+CF_Hist!B9+CF_Hist!B10-CF_Hist!B11 -> 0 | C12: =CF_Hist!C6+CF_Hist!C7+CF_Hist!C8+CF_Hist!C9+CF_Hist!C10-CF_Hist!C11 -> 0 | D12: =CF_Hist!D6+CF_Hist!D7+CF_Hist!D8+CF_Hist!D9+CF_Hist!D10-CF_Hist!D11 -> 0 | E12: =IF(AND(ABS(N(B12))<=0.5,ABS(N(C12))<=0.5,ABS(N(D12))<=0.5),"PASS","FAIL") -> PASS
A13: CF: CFI sum | B13: =SUM(CF_Hist!B14:B31)-CF_Hist!B32 -> 0 | C13: =SUM(CF_Hist!C14:C31)-CF_Hist!C32 -> 0 | D13: =SUM(CF_Hist!D14:D31)-CF_Hist!D32 -> 0 | E13: =IF(AND(ABS(N(B13))<=0.5,ABS(N(C13))<=0.5,ABS(N(D13))<=0.5),"PASS","FAIL") -> PASS
A14: CF: CFF sum | B14: =SUM(CF_Hist!B35:B41)-CF_Hist!B42 -> 0 | C14: =SUM(CF_Hist!C35:C41)-CF_Hist!C42 -> 0 | D14: =SUM(CF_Hist!D35:D41)-CF_Hist!D42 -> 0 | E14: =IF(AND(ABS(N(B14))<=0.5,ABS(N(C14))<=0.5,ABS(N(D14))<=0.5),"PASS","FAIL") -> PASS
A15: CF: Net change = CFO+CFI+CFF+FX | B15: =CF_Hist!B11+CF_Hist!B32+CF_Hist!B42+CF_Hist!B44-CF_Hist!B45 -> 0 | C15: =CF_Hist!C11+CF_Hist!C32+CF_Hist!C42+CF_Hist!C44-CF_Hist!C45 -> 0 | D15: =CF_Hist!D11+CF_Hist!D32+CF_Hist!D42+CF_Hist!D44-CF_Hist!D45 -> 0 | E15: =IF(AND(ABS(N(B15))<=0.5,ABS(N(C15))<=0.5,ABS(N(D15))<=0.5),"PASS","FAIL") -> PASS
A16: CF: End cash = begin + change | B16: =CF_Hist!B46+CF_Hist!B45-CF_Hist!B47 -> 0 | C16: =CF_Hist!C46+CF_Hist!C45-CF_Hist!C47 -> 0 | D16: =CF_Hist!D46+CF_Hist!D45-CF_Hist!D47 -> 0 | E16: =IF(AND(ABS(N(B16))<=0.5,ABS(N(C16))<=0.5,ABS(N(D16))<=0.5),"PASS","FAIL") -> PASS
A17: BS: Current assets sum | B17: n/a (FY2023 BS SOURCE_GAP) | C17: =SUM(BS_Hist!C7:C15)-BS_Hist!C16 -> 0 | D17: =SUM(BS_Hist!D7:D15)-BS_Hist!D16 -> 0 | E17: =IF(AND(ABS(N(C17))<=0.5,ABS(N(D17))<=0.5),"PASS","FAIL") -> PASS
A18: BS: Non-current assets sum | B18: n/a (FY2023 BS SOURCE_GAP) | C18: =SUM(BS_Hist!C18:C28)-BS_Hist!C29 -> 0 | D18: =SUM(BS_Hist!D18:D28)-BS_Hist!D29 -> 0 | E18: =IF(AND(ABS(N(C18))<=0.5,ABS(N(D18))<=0.5),"PASS","FAIL") -> PASS
A19: BS: Total assets = CA + NCA | B19: n/a (FY2023 BS SOURCE_GAP) | C19: =BS_Hist!C16+BS_Hist!C29-BS_Hist!C30 -> 0 | D19: =BS_Hist!D16+BS_Hist!D29-BS_Hist!D30 -> 0 | E19: =IF(AND(ABS(N(C19))<=0.5,ABS(N(D19))<=0.5),"PASS","FAIL") -> PASS
A20: BS: Current liabilities sum | B20: n/a (FY2023 BS SOURCE_GAP) | C20: =SUM(BS_Hist!C34:C42)-BS_Hist!C43 -> 0 | D20: =SUM(BS_Hist!D34:D42)-BS_Hist!D43 -> 0 | E20: =IF(AND(ABS(N(C20))<=0.5,ABS(N(D20))<=0.5),"PASS","FAIL") -> PASS
A21: BS: Non-current liabilities sum | B21: n/a (FY2023 BS SOURCE_GAP) | C21: =SUM(BS_Hist!C45:C52)-BS_Hist!C53 -> 0 | D21: =SUM(BS_Hist!D45:D52)-BS_Hist!D53 -> 0 | E21: =IF(AND(ABS(N(C21))<=0.5,ABS(N(D21))<=0.5),"PASS","FAIL") -> PASS
A22: BS: Total liabilities = CL + NCL | B22: n/a (FY2023 BS SOURCE_GAP) | C22: =BS_Hist!C43+BS_Hist!C53-BS_Hist!C54 -> 0 | D22: =BS_Hist!D43+BS_Hist!D53-BS_Hist!D54 -> 0 | E22: =IF(AND(ABS(N(C22))<=0.5,ABS(N(D22))<=0.5),"PASS","FAIL") -> PASS
A23: BS: Parent equity sum | B23: n/a (FY2023 BS SOURCE_GAP) | C23: =SUM(BS_Hist!C57:C61)-BS_Hist!C62 -> 0 | D23: =SUM(BS_Hist!D57:D61)-BS_Hist!D62 -> 0 | E23: =IF(AND(ABS(N(C23))<=0.5,ABS(N(D23))<=0.5),"PASS","FAIL") -> PASS
A24: BS: Total equity = parent + NCI | B24: n/a (FY2023 BS SOURCE_GAP) | C24: =BS_Hist!C62+BS_Hist!C63-BS_Hist!C64 -> 0 | D24: =BS_Hist!D62+BS_Hist!D63-BS_Hist!D64 -> 0 | E24: =IF(AND(ABS(N(C24))<=0.5,ABS(N(D24))<=0.5),"PASS","FAIL") -> PASS
A25: BS: TL&E = TL + TE | B25: n/a (FY2023 BS SOURCE_GAP) | C25: =BS_Hist!C54+BS_Hist!C64-BS_Hist!C65 -> 0 | D25: =BS_Hist!D54+BS_Hist!D64-BS_Hist!D65 -> 0 | E25: =IF(AND(ABS(N(C25))<=0.5,ABS(N(D25))<=0.5),"PASS","FAIL") -> PASS
A26: BS: Balance (TA − TL&E) | B26: n/a (FY2023 BS SOURCE_GAP) | C26: =BS_Hist!C30-BS_Hist!C65 -> 0 | D26: =BS_Hist!D30-BS_Hist!D65 -> 0 | E26: =IF(AND(ABS(N(C26))<=0.5,ABS(N(D26))<=0.5),"PASS","FAIL") -> PASS
A27: X: CF end cash = BS cash | B27: n/a (FY2023 BS SOURCE_GAP) | C27: =CF_Hist!C47-BS_Hist!C7 -> 0 | D27: =CF_Hist!D47-BS_Hist!D7 -> 0 | E27: =IF(AND(ABS(N(C27))<=0.5,ABS(N(D27))<=0.5),"PASS","FAIL") -> PASS
A28: CF: Beginning cash = prior-year end cash (FY24, FY25) | C28: =CF_Hist!C46-CF_Hist!B47 -> 0 | D28: =CF_Hist!D46-CF_Hist!C47 -> 0 | E28: =IF(AND(ABS(N(C28))<=0.5,ABS(N(D28))<=0.5),"PASS","FAIL") -> PASS
A29: X: Debt_Schedule total borrowings = BS Borrowings (current+non-current) | B29: n/a (FY2023 BS SOURCE_GAP) | C29: =Debt_Schedule!C13-(BS_Hist!C37+BS_Hist!C47) -> 0 | D29: =Debt_Schedule!D13-(BS_Hist!D37+BS_Hist!D47) -> 0 | E29: =IF(AND(ABS(N(C29))<=0.5,ABS(N(D29))<=0.5),"PASS","FAIL") -> PASS
A30: X: PPE_Capex ending balance = BS PP&E, net | B30: n/a (FY2023 BS SOURCE_GAP) | C30: =PPE_Capex!C14-BS_Hist!C22 -> 0 | D30: =PPE_Capex!D14-BS_Hist!D22 -> 0 | E30: =IF(AND(ABS(N(C30))<=0.5,ABS(N(D30))<=0.5),"PASS","FAIL") -> PASS
A31: X: Inventory_Schedule ending balance = BS Inventories, net | B31: n/a (FY2023 BS SOURCE_GAP) | C31: =Inventory_Schedule!C21-BS_Hist!C13 -> 0 | D31: =Inventory_Schedule!D12-BS_Hist!D13 -> 0 | E31: =IF(AND(ABS(N(C31))<=0.5,ABS(N(D31))<=0.5),"PASS","FAIL") -> PASS

Sheet Sources_Audited
A1: Audited source register — SK hynix Inc. consolidated FS
A3: Model year | B3: Source report | C3: File / page ref | D3: Closing FX rate (KRW/USD, noon buying rate)
A4: FY2023A | B4: IS/CI/CF only (3-yr comparative in FY2025 audited FS); BS not presented for FY2023 in this filing | C4: 2023-2025_consolidated-audited-financial-statements_SEC-424B4.pdf | IS/CI p.F-6, CF p.F-10 | D4: 1291
A5: FY2024A | B5: FY2025 audited consolidated FS, FY2024 comparative column | C5: 2023-2025_consolidated-audited-financial-statements_SEC-424B4.pdf | BS p.F-4/F-5, IS/CI p.F-6, CF p.F-10, PP&E Note 12 p.F-46, Debt Note 16 p.F-51/52, Inventory Note 9 p.F-41 | D5: 1477.9
A6: FY2025A | B6: FY2025 audited consolidated FS (primary year) | C6: 2023-2025_consolidated-audited-financial-statements_SEC-424B4.pdf | BS p.F-4/F-5, IS/CI p.F-6, CF p.F-10, PP&E Note 12 p.F-46, Debt Note 16 p.F-51/52, Inventory Note 9 p.F-41 | D6: 1444.6
A8: FX methodology: closing (Dec 31) noon buying rate as quoted by the Federal Reserve Bank of New York, per the 424B4 "Exchange Rates" section (Item, MD&A) — same convention the maintainer signed off on for the Samsung pilot (report-cited rate, not an internal assumption). No per-year USD convenience-translation note is included in this filing (unlike Samsung); rates above are cited from the MD&A exchange-rate table, not from a Note 2.xx USD translation footnote. No full USD-translated statement layer built in this pass, matching Samsung pilot scope — rates are for downstream USD analysis, statements stay KRW-native.
A9: SEC EDGAR: SK hynix Inc. (CIK 0002120882), Form 424(B)(4), filed 2026-07-10, accession 0001193125-26-299963, primary doc d32785d424b4.htm. Retrieved 2026-07-21 per the maintainer's archive.
A10: SOURCE_GAP — FY2021 and FY2022: no public English-language audited consolidated FS located. Only source found: SK hynix 144A/Reg S USD bond offering circulars (2023 preliminary, 2024-01-08 final), both marked STRICTLY CONFIDENTIAL and restricted to QIBs/non-US persons — not retained or used per instructions (redistribution would violate the documents' own terms). Pending path: DART (Korean-only; englishdart.fss.or.kr index pages are English but attachments are Korean-only, verified for FY2025 "Submission of Audit Report" rcpNo 20260304801686) — would require Korean-source translation/verification before use, not attempted this pass.
A11: SOURCE_GAP — FY2023 balance sheet: the 424B4 presents only a 2-year comparative Statement of Financial Position (FY2024/FY2025); FY2023 BS line items are not disclosed anywhere in this filing. BS_Hist column B (FY2023A) is intentionally blank.
A12: SOURCE_GAP — FY2023 PP&E rollforward and debt-balance detail: Note 12 PP&E changes and Note 16 borrowings detail are also only disclosed for FY2024/FY2025 (tied to the 2-yr comparative BS). FY2023 PPE_Capex/Debt_Schedule columns show only the items independently available from CF_Hist/IS_Hist (capex outflow, financing cash flows, depreciation allocation, capitalized borrowing cost).
A13: Forecast/Assumptions/Valuation sheets: PARTIAL / not rewired in this pass. Same disposition as the Samsung pilot — driver-built 5-yr forecast requires a stable multi-year historical base; with only 2 audited BS years (FY24-25) and a 3-yr IS/CF, and FY21-22 unavailable in English, a defensible driver forecast was not attempted here. The pre-existing Forecast/Assumptions/Valuation sheets in this workbook predate this elevation pass and were NOT rewired to the new audited KRW base — do not treat their outputs as reconciled to IS_Hist/BS_Hist/CF_Hist until a follow-up pass revisits them (see Change_Log).

Sheet Claude Code Log
A1: Turn # | B1: Date | C1: User Request | D1: Action Taken | E1: Details | F1: Outcome
A2: 1 | B2: 46324.359 | C2: Prepare a public model copy | D2: Remove local paths and private build references; preserve financial formulas and inputs | E2: Agent run with MOG as the tool, checked by guard v1. The guard measured every sheet before and after the run. Changed: Change_Log: 1 cell written, at B7; Sources_Audited: 5 cells written, at C4, C5, C6, A8, A9. Agent: OpenFinmods export | F2: Compare against source and review public copy
