Workbook

Sheet 00_Cover
A1: LILA / LILAK | 9-of-10 Regated Public-Company Model | B1: LILA / LILAK | 9-of-10 Regated Public-Company Model | C1: LILA / LILAK | 9-of-10 Regated Public-Company Model | D1: LILA / LILAK | 9-of-10 Regated Public-Company Model | E1: LILA / LILAK | 9-of-10 Regated Public-Company Model | F1: LILA / LILAK | 9-of-10 Regated Public-Company Model | G1: LILA / LILAK | 9-of-10 Regated Public-Company Model | H1: LILA / LILAK | 9-of-10 Regated Public-Company Model
A2: Liberty Latin America Ltd. | Telecommunications / cable | Controlled artifact-tool rebuild; independent certification remains outside owner scope. | B2: Liberty Latin America Ltd. | Telecommunications / cable | Controlled artifact-tool rebuild; independent certification remains outside owner scope. | C2: Liberty Latin America Ltd. | Telecommunications / cable | Controlled artifact-tool rebuild; independent certification remains outside owner scope. | D2: Liberty Latin America Ltd. | Telecommunications / cable | Controlled artifact-tool rebuild; independent certification remains outside owner scope. | E2: Liberty Latin America Ltd. | Telecommunications / cable | Controlled artifact-tool rebuild; independent certification remains outside owner scope. | F2: Liberty Latin America Ltd. | Telecommunications / cable | Controlled artifact-tool rebuild; independent certification remains outside owner scope. | G2: Liberty Latin America Ltd. | Telecommunications / cable | Controlled artifact-tool rebuild; independent certification remains outside owner scope. | H2: Liberty Latin America Ltd. | Telecommunications / cable | Controlled artifact-tool rebuild; independent certification remains outside owner scope.
A4: Company | B4: Liberty Latin America Ltd.
A5: Ticker | B5: LILA / LILAK
A6: Model as of | B6: 2025-12-31
A7: Currency | B7: USD millions unless stated
A8: Forecast horizon | B8: 2026E-2030E
A9: Active case | B9: =Assumptions!B4 -> Base
A10: Overall status | B10: =Checks!B4 -> PASS
A11: Primary valuation | B11: Unlevered FCFF DCF
A12: Market-price comparison | B12: Omitted — no independently refreshed exact-dated quote in this owner lane
A13: Debt definition | B13: LongTermDebtAndCapitalLeaseObligationsIncludingCurrentMaturities; finance leases are already included and are not double counted.
A14: Cash policy | B14: Net debt deducts cash and cash equivalents only; restricted cash is excluded.
A15: Acquisition / perimeter | B15: 2025 consolidated USD facts preserve filed currency and segment perimeter; no current-FX restatement across history. 2024 includes the LPR acquisition perimeter change.
A16: Known limitation | B16: LILA does not disclose a single consolidated absolute ARPU or churn rate. The model uses a clearly labeled residential revenue-per-unit proxy and reported Q4 organic RGU losses; neither is represented as company-reported ARPU/churn.
A19: Investor view: begin with operating drivers and the debt bridge, then assess valuation only after Checks!B4 passes. Gate_9of10 is owner preflight, not independent certification. | B19: Investor view: begin with operating drivers and the debt bridge, then assess valuation only after Checks!B4 passes. Gate_9of10 is owner preflight, not independent certification. | C19: Investor view: begin with operating drivers and the debt bridge, then assess valuation only after Checks!B4 passes. Gate_9of10 is owner preflight, not independent certification. | D19: Investor view: begin with operating drivers and the debt bridge, then assess valuation only after Checks!B4 passes. Gate_9of10 is owner preflight, not independent certification. | E19: Investor view: begin with operating drivers and the debt bridge, then assess valuation only after Checks!B4 passes. Gate_9of10 is owner preflight, not independent certification. | F19: Investor view: begin with operating drivers and the debt bridge, then assess valuation only after Checks!B4 passes. Gate_9of10 is owner preflight, not independent certification. | G19: Investor view: begin with operating drivers and the debt bridge, then assess valuation only after Checks!B4 passes. Gate_9of10 is owner preflight, not independent certification. | H19: Investor view: begin with operating drivers and the debt bridge, then assess valuation only after Checks!B4 passes. Gate_9of10 is owner preflight, not independent certification.

Sheet Sources
A1: LILA / LILAK | Source and Transformation Ledger | B1: LILA / LILAK | Source and Transformation Ledger | C1: LILA / LILAK | Source and Transformation Ledger | D1: LILA / LILAK | Source and Transformation Ledger | E1: LILA / LILAK | Source and Transformation Ledger | F1: LILA / LILAK | Source and Transformation Ledger | G1: LILA / LILAK | Source and Transformation Ledger | H1: LILA / LILAK | Source and Transformation Ledger | I1: LILA / LILAK | Source and Transformation Ledger | J1: LILA / LILAK | Source and Transformation Ledger | K1: LILA / LILAK | Source and Transformation Ledger | L1: LILA / LILAK | Source and Transformation Ledger | M1: LILA / LILAK | Source and Transformation Ledger | N1: LILA / LILAK | Source and Transformation Ledger | O1: LILA / LILAK | Source and Transformation Ledger | P1: LILA / LILAK | Source and Transformation Ledger | Q1: LILA / LILAK | Source and Transformation Ledger
A2: Every material input identifies target, metric, period, filing metadata, retrieval date, exact URL, scale/sign transform and perimeter note. | B2: Every material input identifies target, metric, period, filing metadata, retrieval date, exact URL, scale/sign transform and perimeter note. | C2: Every material input identifies target, metric, period, filing metadata, retrieval date, exact URL, scale/sign transform and perimeter note. | D2: Every material input identifies target, metric, period, filing metadata, retrieval date, exact URL, scale/sign transform and perimeter note. | E2: Every material input identifies target, metric, period, filing metadata, retrieval date, exact URL, scale/sign transform and perimeter note. | F2: Every material input identifies target, metric, period, filing metadata, retrieval date, exact URL, scale/sign transform and perimeter note. | G2: Every material input identifies target, metric, period, filing metadata, retrieval date, exact URL, scale/sign transform and perimeter note. | H2: Every material input identifies target, metric, period, filing metadata, retrieval date, exact URL, scale/sign transform and perimeter note. | I2: Every material input identifies target, metric, period, filing metadata, retrieval date, exact URL, scale/sign transform and perimeter note. | J2: Every material input identifies target, metric, period, filing metadata, retrieval date, exact URL, scale/sign transform and perimeter note. | K2: Every material input identifies target, metric, period, filing metadata, retrieval date, exact URL, scale/sign transform and perimeter note. | L2: Every material input identifies target, metric, period, filing metadata, retrieval date, exact URL, scale/sign transform and perimeter note. | M2: Every material input identifies target, metric, period, filing metadata, retrieval date, exact URL, scale/sign transform and perimeter note. | N2: Every material input identifies target, metric, period, filing metadata, retrieval date, exact URL, scale/sign transform and perimeter note. | O2: Every material input identifies target, metric, period, filing metadata, retrieval date, exact URL, scale/sign transform and perimeter note. | P2: Every material input identifies target, metric, period, filing metadata, retrieval date, exact URL, scale/sign transform and perimeter note. | Q2: Every material input identifies target, metric, period, filing metadata, retrieval date, exact URL, scale/sign transform and perimeter note.
A4: Source ID | B4: Target | C4: Metric | D4: Value | E4: Units | F4: Period start | G4: Period end / as-of | H4: Taxonomy / tag | I4: Form | J4: Filed | K4: Accession | L4: Source title | M4: Source class | N4: Retrieved | O4: Exact URL | P4: Transform | Q4: Notes / perimeter
A5: SRC-001 | B5: Historical!C5 | C5: Revenue | D5: 4511.1 | E5: USD mm | F5: 2023-01-01 | G5: 2023-12-31 | H5: us-gaap:RevenueFromContractWithCustomerIncludingAssessedTax | I5: 10-K | J5: 2026-02-18 | K5: 0001712184-26-000023 | L5: Liberty Latin America Ltd. Form 10-K / SEC Company Facts | M5: Primary — SEC filed | N5: 2026-07-16 | O5: https://data.sec.gov/api/xbrl/companyfacts/CIK0001712184.json | P5: Filed USD divided by 1,000,000; sign preserved | Q5: 2025 consolidated USD facts preserve filed currency and segment perimeter; no current-FX restatement across history. 2024 includes the LPR acquisition perimeter change.
A6: SRC-002 | B6: Historical!D5 | C6: Revenue | D6: 4446.8 | E6: USD mm | F6: 2024-01-01 | G6: 2024-12-31 | H6: us-gaap:RevenueFromContractWithCustomerIncludingAssessedTax | I6: 10-K | J6: 2026-02-18 | K6: 0001712184-26-000023 | L6: Liberty Latin America Ltd. Form 10-K / SEC Company Facts | M6: Primary — SEC filed | N6: 2026-07-16 | O6: https://data.sec.gov/api/xbrl/companyfacts/CIK0001712184.json | P6: Filed USD divided by 1,000,000; sign preserved | Q6: 2025 consolidated USD facts preserve filed currency and segment perimeter; no current-FX restatement across history. 2024 includes the LPR acquisition perimeter change.
A7: SRC-003 | B7: Historical!E5 | C7: Revenue | D7: 4442.2 | E7: USD mm | F7: 2025-01-01 | G7: 2025-12-31 | H7: us-gaap:RevenueFromContractWithCustomerIncludingAssessedTax | I7: 10-K | J7: 2026-02-18 | K7: 0001712184-26-000023 | L7: Liberty Latin America Ltd. Form 10-K / SEC Company Facts | M7: Primary — SEC filed | N7: 2026-07-16 | O7: https://data.sec.gov/api/xbrl/companyfacts/CIK0001712184.json | P7: Filed USD divided by 1,000,000; sign preserved | Q7: 2025 consolidated USD facts preserve filed currency and segment perimeter; no current-FX restatement across history. 2024 includes the LPR acquisition perimeter change.
A8: SRC-004 | B8: Historical!C6 | C8: Operating income (EBIT) | D8: 517.7 | E8: USD mm | F8: 2023-01-01 | G8: 2023-12-31 | H8: us-gaap:OperatingIncomeLoss | I8: 10-K | J8: 2026-02-18 | K8: 0001712184-26-000023 | L8: Liberty Latin America Ltd. Form 10-K / SEC Company Facts | M8: Primary — SEC filed | N8: 2026-07-16 | O8: https://data.sec.gov/api/xbrl/companyfacts/CIK0001712184.json | P8: Filed USD divided by 1,000,000; sign preserved | Q8: 2025 consolidated USD facts preserve filed currency and segment perimeter; no current-FX restatement across history. 2024 includes the LPR acquisition perimeter change.
A9: SRC-005 | B9: Historical!D6 | C9: Operating income (EBIT) | D9: -76.8 | E9: USD mm | F9: 2024-01-01 | G9: 2024-12-31 | H9: us-gaap:OperatingIncomeLoss | I9: 10-K | J9: 2026-02-18 | K9: 0001712184-26-000023 | L9: Liberty Latin America Ltd. Form 10-K / SEC Company Facts | M9: Primary — SEC filed | N9: 2026-07-16 | O9: https://data.sec.gov/api/xbrl/companyfacts/CIK0001712184.json | P9: Filed USD divided by 1,000,000; sign preserved | Q9: 2025 consolidated USD facts preserve filed currency and segment perimeter; no current-FX restatement across history. 2024 includes the LPR acquisition perimeter change.
A10: SRC-006 | B10: Historical!E6 | C10: Operating income (EBIT) | D10: 108.2 | E10: USD mm | F10: 2025-01-01 | G10: 2025-12-31 | H10: us-gaap:OperatingIncomeLoss | I10: 10-K | J10: 2026-02-18 | K10: 0001712184-26-000023 | L10: Liberty Latin America Ltd. Form 10-K / SEC Company Facts | M10: Primary — SEC filed | N10: 2026-07-16 | O10: https://data.sec.gov/api/xbrl/companyfacts/CIK0001712184.json | P10: Filed USD divided by 1,000,000; sign preserved | Q10: 2025 consolidated USD facts preserve filed currency and segment perimeter; no current-FX restatement across history. 2024 includes the LPR acquisition perimeter change.
A11: SRC-007 | B11: Historical!C7 | C11: Net income | D11: -73.6 | E11: USD mm | F11: 2023-01-01 | G11: 2023-12-31 | H11: us-gaap:NetIncomeLoss | I11: 10-K | J11: 2026-02-18 | K11: 0001712184-26-000023 | L11: Liberty Latin America Ltd. Form 10-K / SEC Company Facts | M11: Primary — SEC filed | N11: 2026-07-16 | O11: https://data.sec.gov/api/xbrl/companyfacts/CIK0001712184.json | P11: Filed USD divided by 1,000,000; sign preserved | Q11: 2025 consolidated USD facts preserve filed currency and segment perimeter; no current-FX restatement across history. 2024 includes the LPR acquisition perimeter change.
A12: SRC-008 | B12: Historical!D7 | C12: Net income | D12: -689.4 | E12: USD mm | F12: 2024-01-01 | G12: 2024-12-31 | H12: us-gaap:NetIncomeLoss | I12: 10-K | J12: 2026-02-18 | K12: 0001712184-26-000023 | L12: Liberty Latin America Ltd. Form 10-K / SEC Company Facts | M12: Primary — SEC filed | N12: 2026-07-16 | O12: https://data.sec.gov/api/xbrl/companyfacts/CIK0001712184.json | P12: Filed USD divided by 1,000,000; sign preserved | Q12: 2025 consolidated USD facts preserve filed currency and segment perimeter; no current-FX restatement across history. 2024 includes the LPR acquisition perimeter change.
A13: SRC-009 | B13: Historical!E7 | C13: Net income | D13: -611.2 | E13: USD mm | F13: 2025-01-01 | G13: 2025-12-31 | H13: us-gaap:NetIncomeLoss | I13: 10-K | J13: 2026-02-18 | K13: 0001712184-26-000023 | L13: Liberty Latin America Ltd. Form 10-K / SEC Company Facts | M13: Primary — SEC filed | N13: 2026-07-16 | O13: https://data.sec.gov/api/xbrl/companyfacts/CIK0001712184.json | P13: Filed USD divided by 1,000,000; sign preserved | Q13: 2025 consolidated USD facts preserve filed currency and segment perimeter; no current-FX restatement across history. 2024 includes the LPR acquisition perimeter change.
A14: SRC-010 | B14: Historical!C8 | C14: Cash from operations | D14: 897 | E14: USD mm | F14: 2023-01-01 | G14: 2023-12-31 | H14: us-gaap:NetCashProvidedByUsedInOperatingActivities | I14: 10-K | J14: 2026-02-18 | K14: 0001712184-26-000023 | L14: Liberty Latin America Ltd. Form 10-K / SEC Company Facts | M14: Primary — SEC filed | N14: 2026-07-16 | O14: https://data.sec.gov/api/xbrl/companyfacts/CIK0001712184.json | P14: Filed USD divided by 1,000,000; sign preserved | Q14: 2025 consolidated USD facts preserve filed currency and segment perimeter; no current-FX restatement across history. 2024 includes the LPR acquisition perimeter change.
A15: SRC-011 | B15: Historical!D8 | C15: Cash from operations | D15: 756.3 | E15: USD mm | F15: 2024-01-01 | G15: 2024-12-31 | H15: us-gaap:NetCashProvidedByUsedInOperatingActivities | I15: 10-K | J15: 2026-02-18 | K15: 0001712184-26-000023 | L15: Liberty Latin America Ltd. Form 10-K / SEC Company Facts | M15: Primary — SEC filed | N15: 2026-07-16 | O15: https://data.sec.gov/api/xbrl/companyfacts/CIK0001712184.json | P15: Filed USD divided by 1,000,000; sign preserved | Q15: 2025 consolidated USD facts preserve filed currency and segment perimeter; no current-FX restatement across history. 2024 includes the LPR acquisition perimeter change.
A16: SRC-012 | B16: Historical!E8 | C16: Cash from operations | D16: 805.9 | E16: USD mm | F16: 2025-01-01 | G16: 2025-12-31 | H16: us-gaap:NetCashProvidedByUsedInOperatingActivities | I16: 10-K | J16: 2026-02-18 | K16: 0001712184-26-000023 | L16: Liberty Latin America Ltd. Form 10-K / SEC Company Facts | M16: Primary — SEC filed | N16: 2026-07-16 | O16: https://data.sec.gov/api/xbrl/companyfacts/CIK0001712184.json | P16: Filed USD divided by 1,000,000; sign preserved | Q16: 2025 consolidated USD facts preserve filed currency and segment perimeter; no current-FX restatement across history. 2024 includes the LPR acquisition perimeter change.
... A89: SRC-085 | B89: Sector_KPIs!E16 | C89: Adjusted OIBDA | D89: 1706.3 | E89: USD mm | F89: 2025-01-01 | G89: 2025-12-31 | H89: Exhibit 99.1 — Full-year consolidated results table — row: Adjusted OIBDA — year ended December 31, 2025 | I89: 8-K Exhibit 99.1 | J89: 2026-02-18 | K89: 0001712184-26-000025 | L89: Liberty Latin America Q4 and full-year 2025 results | M89: Primary — SEC filed company results | N89: 2026-07-16 | O89: https://www.sec.gov/Archives/edgar/data/1712184/000171218426000025/ex991toform_llaq42025earni.htm | P89: Filed USD divided by 1,000,000 where applicable; sign preserved | Q89: Reported non-GAAP measure; reconciliation is in the filed results.
A90: SRC-086 | B90: Historical / Valuation | C90: Debt definition | D90: LongTermDebtAndCapitalLeaseObligationsIncludingCurrentMaturities; finance leases are already included and are not double counted. | E90: Policy | F90: N/A | G90: 2025-12-31 | H90: Accounting policy | I90: 10-K | J90: 2026-02-18 | K90: 0001712184-26-000023 | L90: Liberty Latin America Ltd. 2025 Form 10-K | M90: Primary — SEC filed | N90: 2026-07-16 | O90: https://www.sec.gov/Archives/edgar/data/1712184/000171218426000023/lila-20251231.htm | P90: Explicit sum of filed debt components | Q90: Net debt deducts cash and cash equivalents only; restricted cash is excluded.
A91: SRC-087 | B91: Entire model | C91: Acquisition / perimeter note | D91: 2025 consolidated USD facts preserve filed currency and segment perimeter; no current-FX restatement across history. 2024 includes the LPR acquisition perimeter change. | E91: Policy | F91: N/A | G91: 2025-12-31 | H91: Perimeter policy | I91: 10-K | J91: 2026-02-18 | K91: 0001712184-26-000023 | L91: Liberty Latin America Ltd. 2025 Form 10-K | M91: Primary — SEC filed | N91: 2026-07-16 | O91: https://www.sec.gov/Archives/edgar/data/1712184/000171218426000023/lila-20251231.htm | P91: No current-FX restatement; filed values preserved | Q91: LILA does not disclose a single consolidated absolute ARPU or churn rate. The model uses a clearly labeled residential revenue-per-unit proxy and reported Q4 organic RGU losses; neither is represented as company-reported ARPU/churn.

Sheet Historical
A1: LILA / LILAK | Historical Financials | B1: LILA / LILAK | Historical Financials | C1: LILA / LILAK | Historical Financials | D1: LILA / LILAK | Historical Financials | E1: LILA / LILAK | Historical Financials | F1: LILA / LILAK | Historical Financials | G1: LILA / LILAK | Historical Financials | H1: LILA / LILAK | Historical Financials | I1: LILA / LILAK | Historical Financials
A2: Filed values and explicit debt bridge. USD in millions except per-share and share-count data. | B2: Filed values and explicit debt bridge. USD in millions except per-share and share-count data. | C2: Filed values and explicit debt bridge. USD in millions except per-share and share-count data. | D2: Filed values and explicit debt bridge. USD in millions except per-share and share-count data. | E2: Filed values and explicit debt bridge. USD in millions except per-share and share-count data. | F2: Filed values and explicit debt bridge. USD in millions except per-share and share-count data. | G2: Filed values and explicit debt bridge. USD in millions except per-share and share-count data. | H2: Filed values and explicit debt bridge. USD in millions except per-share and share-count data. | I2: Filed values and explicit debt bridge. USD in millions except per-share and share-count data.
A4: Metric | B4: Units | C4: 2023A | D4: 2024A | E4: 2025A | F4: Source definition | G4: Source IDs | H4: Policy / transform | I4: Quality
A5: Revenue | B5: USD mm | C5: 4511.1 | D5: 4446.8 | E5: 4442.2 | F5: SEC Company Facts / filed 10-K; RevenueFromContractWithCustomerIncludingAssessedTax or Revenues or SalesRevenueNet | G5: SRC-001, SRC-002, SRC-003 | H5: Filed USD; no FX restatement; sign preserved. | I5: Filed
A6: Operating income (EBIT) | B6: USD mm | C6: 517.7 | D6: -76.8 | E6: 108.2 | F6: SEC Company Facts / filed 10-K; OperatingIncomeLoss | G6: SRC-004, SRC-005, SRC-006 | H6: Filed USD; no FX restatement; sign preserved. | I6: Filed
A7: Net income | B7: USD mm | C7: -73.6 | D7: -689.4 | E7: -611.2 | F7: SEC Company Facts / filed 10-K; NetIncomeLoss or ProfitLoss | G7: SRC-007, SRC-008, SRC-009 | H7: Filed USD; no FX restatement; sign preserved. | I7: Filed
A8: Cash from operations | B8: USD mm | C8: 897 | D8: 756.3 | E8: 805.9 | F8: SEC Company Facts / filed 10-K; NetCashProvidedByUsedInOperatingActivities | G8: SRC-010, SRC-011, SRC-012 | H8: Filed USD; no FX restatement; sign preserved. | I8: Filed
A9: Depreciation & amortization | B9: USD mm | C9: 1008.3 | D9: 968.3 | E9: 904.9 | F9: SEC Company Facts / filed 10-K; DepreciationDepletionAndAmortization or DepreciationDepletionAndAmortization or DepreciationAndAmortization | G9: SRC-013, SRC-014, SRC-015 | H9: Filed USD; no FX restatement; sign preserved. | I9: Filed
A10: Cash capex / P&E additions | B10: USD mm | D10: 725.3 | E10: 640.1 | F10: SEC Company Facts / filed 10-K; PaymentsToAcquirePropertyPlantAndEquipment or PaymentsForAdditionsToPropertyPlantAndEquipment | G10: SRC-016, SRC-017 | H10: Filed USD; no FX restatement; sign preserved. | I10: Partial / see Sources
A11: Total assets | B11: USD mm | C11: 13594.6 | D11: 12783.7 | E11: 12225.9 | F11: SEC Company Facts / filed 10-K; Assets | G11: SRC-018, SRC-019, SRC-020 | H11: Filed USD; no FX restatement; sign preserved. | I11: Filed
A12: Stockholders' equity | B12: USD mm | C12: 1763.5 | D12: 1088.6 | E12: 555.6 | F12: SEC Company Facts / filed 10-K; StockholdersEquity or StockholdersEquityIncludingPortionAttributableToNoncontrollingInterest | G12: SRC-021, SRC-022, SRC-023 | H12: Filed USD; no FX restatement; sign preserved. | I12: Filed
A13: Cash & cash equivalents | B13: USD mm | C13: 988.6 | D13: 654.3 | E13: 783.9 | F13: SEC Company Facts / filed 10-K; CashAndCashEquivalentsAtCarryingValue or CashCashEquivalentsRestrictedCashAndRestrictedCashEquivalents | G13: SRC-024, SRC-025, SRC-026 | H13: Filed USD; no FX restatement; sign preserved. | I13: Filed
A14: Long-term debt | B14: USD mm | C14: 8179.9 | D14: 8080.2 | E14: 8279.2 | F14: SEC Company Facts / filed 10-K; LongTermDebt or LongTermDebtAndCapitalLeaseObligationsIncludingCurrentMaturities | G14: SRC-027, SRC-028, SRC-029 | H14: LongTermDebtAndCapitalLeaseObligationsIncludingCurrentMaturities; finance leases are already included and are not double counted. | I14: Filed
A15: Short-term borrowings | B15: USD mm | C15: 0 | D15: 0 | E15: 0 | F15: SEC Company Facts / filed 10-K; ShortTermBorrowings or CommercialPaper | G15: SRC-030, SRC-031, SRC-032 | H15: LongTermDebtAndCapitalLeaseObligationsIncludingCurrentMaturities; finance leases are already included and are not double counted. | I15: Filed
A16: Finance lease liability | B16: USD mm | C16: 0 | D16: 0 | E16: 0 | F16: SEC Company Facts / filed 10-K; FinanceLeaseLiability | G16: SRC-033, SRC-034, SRC-035 | H16: LongTermDebtAndCapitalLeaseObligationsIncludingCurrentMaturities; finance leases are already included and are not double counted. | I16: Filed
A17: Diluted weighted-average shares | B17: mm shares | C17: 210 | D17: 198.4 | E17: 199.5 | F17: SEC Company Facts / filed 10-K; WeightedAverageNumberOfDilutedSharesOutstanding | G17: SRC-036, SRC-037, SRC-038 | H17: Filed USD; no FX restatement; sign preserved. | I17: Filed
A18: Total debt | B18: USD mm | C18: =C14+C15+C16 -> 8179.9 | D18: =D14+D15+D16 -> 8080.2 | E18: =E14+E15+E16 -> 8279.2 | F18: LongTermDebtAndCapitalLeaseObligationsIncludingCurrentMaturities; finance leases are already included and are not double counted. | G18: Formula | H18: LongTermDebtAndCapitalLeaseObligationsIncludingCurrentMaturities; finance leases are already included and are not double counted. | I18: Modeled
A19: Net debt | B19: USD mm | C19: =C18-C13 -> 7191.3 | D19: =D18-D13 -> 7425.9 | E19: =E18-E13 -> 7495.3 | F19: Total debt less cash and cash equivalents | G19: Formula | H19: Net debt deducts cash and cash equivalents only; restricted cash is excluded. | I19: Modeled
A21: Debt policy | B21: LongTermDebtAndCapitalLeaseObligationsIncludingCurrentMaturities; finance leases are already included and are not double counted.
A22: Cash policy | B22: Net debt deducts cash and cash equivalents only; restricted cash is excluded.
A23: Perimeter | B23: 2025 consolidated USD facts preserve filed currency and segment perimeter; no current-FX restatement across history. 2024 includes the LPR acquisition perimeter change.

Sheet Assumptions
A1: LILA / LILAK | Scenario Assumptions | B1: LILA / LILAK | Scenario Assumptions | C1: LILA / LILAK | Scenario Assumptions | D1: LILA / LILAK | Scenario Assumptions | E1: LILA / LILAK | Scenario Assumptions | F1: LILA / LILAK | Scenario Assumptions | G1: LILA / LILAK | Scenario Assumptions
A2: Blue cells are inputs; green cells are links/formulas. Selector 1=Base, 2=Bull, 3=Bear. | B2: Blue cells are inputs; green cells are links/formulas. Selector 1=Base, 2=Bull, 3=Bear. | C2: Blue cells are inputs; green cells are links/formulas. Selector 1=Base, 2=Bull, 3=Bear. | D2: Blue cells are inputs; green cells are links/formulas. Selector 1=Base, 2=Bull, 3=Bear. | E2: Blue cells are inputs; green cells are links/formulas. Selector 1=Base, 2=Bull, 3=Bear. | F2: Blue cells are inputs; green cells are links/formulas. Selector 1=Base, 2=Bull, 3=Bear. | G2: Blue cells are inputs; green cells are links/formulas. Selector 1=Base, 2=Bull, 3=Bear.
A3: Scenario selector | B3: 1
A4: Active case | B4: =CHOOSE(B3,"Base","Bull","Bear") -> Base
A6: Driver | B6: Units | C6: Bear | D6: Base | E6: Bull | F6: Active | G6: Rationale / calibration
A7: Homes passed growth | B7: % / year | C7: 0 | D7: 0.02 | E7: 0.035 | F7: =CHOOSE($B$3,D7,E7,C7) -> 0.02 | G7: 2025 homes-passed base from the 10-K operating statistics table.
A8: Fixed RGU density growth (net adds/churn) | B8: % / year | C8: -0.04 | D8: -0.01 | E8: 0.01 | F8: =CHOOSE($B$3,D8,E8,C8) -> -0.01 | G8: Captures fixed RGU additions and churn through RGUs per home passed.
A9: Mobile subscriber growth | B9: % / year | C9: -0.02 | D9: 0.02 | E9: 0.04 | F9: =CHOOSE($B$3,D9,E9,C9) -> 0.02 | G9: 2025 mobile subscriber base from the 10-K.
A10: Residential revenue-per-unit proxy growth | B10: % / year | C10: -0.01 | D10: 0.02 | E10: 0.04 | F10: =CHOOSE($B$3,D10,E10,C10) -> 0.02 | G10: Proxy only; LILA reports directional ARPU effects rather than one consolidated absolute ARPU.
A11: B2B / other revenue growth | B11: % / year | C11: -0.03 | D11: 0.01 | E11: 0.03 | F11: =CHOOSE($B$3,D11,E11,C11) -> 0.01 | G11: Residual revenue outside modeled residential revenue.
A12: Adjusted OIBDA margin | B12: % | C12: 0.35 | D12: 0.384 | E12: 0.4 | F12: =CHOOSE($B$3,D12,E12,C12) -> 0.384 | G12: 2025 reported margin was 38.4%.
A13: D&A as % revenue | B13: % | C13: 0.21 | D13: 0.204 | E13: 0.2 | F13: =CHOOSE($B$3,D13,E13,C13) -> 0.204 | G13: Anchored to 2025 SEC D&A / revenue.
A14: P&E additions as % revenue | B14: % | C14: 0.16 | D14: 0.144 | E14: 0.13 | F14: =CHOOSE($B$3,D14,E14,C14) -> 0.144 | G14: 2025 reported P&E additions ratio was 14.4%.
A15: Cash tax rate | B15: % | C15: 0.26 | D15: 0.24 | E15: 0.22 | F15: =CHOOSE($B$3,D15,E15,C15) -> 0.24 | G15: Normalized cash-tax assumption.
A16: NWC investment / change in revenue | B16: % | C16: 0.03 | D16: 0.02 | E16: 0.01 | F16: =CHOOSE($B$3,D16,E16,C16) -> 0.02 | G16: Working-capital sensitivity assumption.
A17: Annual net debt reduction | B17: % | C17: 0.02 | D17: 0.05 | E17: 0.08 | F17: =CHOOSE($B$3,D17,E17,C17) -> 0.05 | G17: Visible leverage-path assumption; no residual cash plug.
A18: WACC | B18: % | C18: 0.12 | D18: 0.105 | E18: 0.095 | F18: =CHOOSE($B$3,D18,E18,C18) -> 0.105 | G18: Leveraged multi-market telecom discount-rate assumption.
... A20: Exit EV / Adjusted OIBDA | B20: x | C20: 4.5 | D20: 5.5 | E20: 6.5 | F20: =CHOOSE($B$3,D20,E20,C20) -> 5.5 | G20: Telecom DCF cross-check multiple.
A22: Debt definition | B22: LongTermDebtAndCapitalLeaseObligationsIncludingCurrentMaturities; finance leases are already included and are not double counted.
A23: Cash policy | B23: Net debt deducts cash and cash equivalents only; restricted cash is excluded.
A24: Known limitation | B24: LILA does not disclose a single consolidated absolute ARPU or churn rate. The model uses a clearly labeled residential revenue-per-unit proxy and reported Q4 organic RGU losses; neither is represented as company-reported ARPU/churn.

Sheet Forecast
A1: LILA / LILAK | Integrated Forecast | B1: LILA / LILAK | Integrated Forecast | C1: LILA / LILAK | Integrated Forecast | D1: LILA / LILAK | Integrated Forecast | E1: LILA / LILAK | Integrated Forecast | F1: LILA / LILAK | Integrated Forecast | G1: LILA / LILAK | Integrated Forecast
A2: Operating drivers flow from Sector_KPIs into FCFF and DCF valuation. | B2: Operating drivers flow from Sector_KPIs into FCFF and DCF valuation. | C2: Operating drivers flow from Sector_KPIs into FCFF and DCF valuation. | D2: Operating drivers flow from Sector_KPIs into FCFF and DCF valuation. | E2: Operating drivers flow from Sector_KPIs into FCFF and DCF valuation. | F2: Operating drivers flow from Sector_KPIs into FCFF and DCF valuation. | G2: Operating drivers flow from Sector_KPIs into FCFF and DCF valuation.
A4: Metric | B4: Units | C4: 2026E | D4: 2027E | E4: 2028E | F4: 2029E | G4: 2030E
A5: Revenue | B5: USD mm | C5: =Sector_KPIs!F14 -> 4566.3524 | D5: =Sector_KPIs!G14 -> 4694.7427 | E5: =Sector_KPIs!H14 -> 4827.5277 | F5: =Sector_KPIs!I14 -> 4964.8701 | G5: =Sector_KPIs!J14 -> 5106.9386
A6: Adjusted OIBDA | B6: USD mm | C6: =Sector_KPIs!F16 -> 1753.4793 | D6: =Sector_KPIs!G16 -> 1802.7812 | E6: =Sector_KPIs!H16 -> 1853.7706 | F6: =Sector_KPIs!I16 -> 1906.5101 | G6: =Sector_KPIs!J16 -> 1961.0644
A7: Depreciation & amortization | B7: USD mm | C7: =C5*Assumptions!$F$13 -> 931.53588 | D7: =D5*Assumptions!$F$13 -> 957.72751 | E7: =E5*Assumptions!$F$13 -> 984.81565 | F7: =F5*Assumptions!$F$13 -> 1012.8335 | G7: =G5*Assumptions!$F$13 -> 1041.8155
A8: EBIT | B8: USD mm | C8: =C6-C7 -> 821.94343 | D8: =D6-D7 -> 845.05369 | E8: =E6-E7 -> 868.95499 | F8: =F6-F7 -> 893.67661 | G8: =G6-G7 -> 919.24895
A9: Cash taxes | B9: USD mm | C9: =MAX(0,C8*Assumptions!$F$15) -> 197.26642 | D9: =MAX(0,D8*Assumptions!$F$15) -> 202.81289 | E9: =MAX(0,E8*Assumptions!$F$15) -> 208.5492 | F9: =MAX(0,F8*Assumptions!$F$15) -> 214.48239 | G9: =MAX(0,G8*Assumptions!$F$15) -> 220.61975
A10: NOPAT | B10: USD mm | C10: =C8-C9 -> 624.677 | D10: =D8-D9 -> 642.2408 | E10: =E8-E9 -> 660.40579 | F10: =F8-F9 -> 679.19422 | G10: =G8-G9 -> 698.6292
A11: D&A add-back | B11: USD mm | C11: =C7 -> 931.53588 | D11: =D7 -> 957.72751 | E11: =E7 -> 984.81565 | F11: =F7 -> 1012.8335 | G11: =G7 -> 1041.8155
A12: Capital expenditures | B12: USD mm | C12: =Sector_KPIs!F18 -> 657.55474 | D12: =Sector_KPIs!G18 -> 676.04295 | E12: =Sector_KPIs!H18 -> 695.16399 | F12: =Sector_KPIs!I18 -> 714.94129 | G12: =Sector_KPIs!J18 -> 735.39916
A13: Change in net working capital | B13: USD mm | C13: =MAX(0,(Sector_KPIs!F14-Sector_KPIs!E14)*Assumptions!$F$16) -> 2.4830475 | D13: =MAX(0,(Sector_KPIs!G14-Sector_KPIs!F14)*Assumptions!$F$16) -> 2.5678068 | E13: =MAX(0,(Sector_KPIs!H14-Sector_KPIs!G14)*Assumptions!$F$16) -> 2.6557 | F13: =MAX(0,(Sector_KPIs!I14-Sector_KPIs!H14)*Assumptions!$F$16) -> 2.7468468 | G13: =MAX(0,(Sector_KPIs!J14-Sector_KPIs!I14)*Assumptions!$F$16) -> 2.8413716
A14: FCFF | B14: USD mm | C14: =C10+C11-C12-C13 -> 896.1751 | D14: =D10+D11-D12-D13 -> 921.35756 | E14: =E10+E11-E12-E13 -> 947.40175 | F14: =F10+F11-F12-F13 -> 974.33958 | G14: =G10+G11-G12-G13 -> 1002.2042
A15: FCFF margin | B15: % | C15: =IFERROR(C14/C5,0) -> 0.19625623 | D15: =IFERROR(D14/D5,0) -> 0.19625305 | E15: =IFERROR(E14/E5,0) -> 0.19624988 | F15: =IFERROR(F14/F5,0) -> 0.19624674 | G15: =IFERROR(G14/G5,0) -> 0.19624363
A18: FCFF is derived from operating drivers, normalized cash taxes, explicit capex and a revenue-linked NWC assumption. | B18: FCFF is derived from operating drivers, normalized cash taxes, explicit capex and a revenue-linked NWC assumption. | C18: FCFF is derived from operating drivers, normalized cash taxes, explicit capex and a revenue-linked NWC assumption. | D18: FCFF is derived from operating drivers, normalized cash taxes, explicit capex and a revenue-linked NWC assumption. | E18: FCFF is derived from operating drivers, normalized cash taxes, explicit capex and a revenue-linked NWC assumption. | F18: FCFF is derived from operating drivers, normalized cash taxes, explicit capex and a revenue-linked NWC assumption. | G18: FCFF is derived from operating drivers, normalized cash taxes, explicit capex and a revenue-linked NWC assumption.

Sheet Valuation
A1: LILA / LILAK | DCF Valuation | B1: LILA / LILAK | DCF Valuation | C1: LILA / LILAK | DCF Valuation | D1: LILA / LILAK | DCF Valuation | E1: LILA / LILAK | DCF Valuation | F1: LILA / LILAK | DCF Valuation | G1: LILA / LILAK | DCF Valuation
A2: Primary method: unlevered FCFF DCF. Exit EV / Adjusted OIBDA is an explicit cross-check. | B2: Primary method: unlevered FCFF DCF. Exit EV / Adjusted OIBDA is an explicit cross-check. | C2: Primary method: unlevered FCFF DCF. Exit EV / Adjusted OIBDA is an explicit cross-check. | D2: Primary method: unlevered FCFF DCF. Exit EV / Adjusted OIBDA is an explicit cross-check. | E2: Primary method: unlevered FCFF DCF. Exit EV / Adjusted OIBDA is an explicit cross-check. | F2: Primary method: unlevered FCFF DCF. Exit EV / Adjusted OIBDA is an explicit cross-check. | G2: Primary method: unlevered FCFF DCF. Exit EV / Adjusted OIBDA is an explicit cross-check.
A4: Metric | B4: Units | C4: 2026E | D4: 2027E | E4: 2028E | F4: 2029E | G4: 2030E
A5: FCFF | B5: USD mm | C5: =Forecast!C14 -> 896.1751 | D5: =Forecast!D14 -> 921.35756 | E5: =Forecast!E14 -> 947.40175 | F5: =Forecast!F14 -> 974.33958 | G5: =Forecast!G14 -> 1002.2042
A6: Discount period | B6: years | C6: 1 | D6: 2 | E6: 3 | F6: 4 | G6: 5
A7: Discount factor | B7: x | C7: =1/(1+Assumptions!$F$18)^C6 -> 0.90497738 | D7: =1/(1+Assumptions!$F$18)^D6 -> 0.81898405 | E7: =1/(1+Assumptions!$F$18)^E6 -> 0.74116204 | F7: =1/(1+Assumptions!$F$18)^F6 -> 0.67073487 | G7: =1/(1+Assumptions!$F$18)^G6 -> 0.60699989
A8: PV of FCFF | B8: USD mm | C8: =C5*C7 -> 811.01819 | D8: =D5*D7 -> 754.57715 | E8: =E5*E7 -> 702.17821 | F8: =F5*F7 -> 653.52354 | G8: =G5*G7 -> 608.33781
A11: WACC | B11: =Assumptions!$F$18 -> 0.105
A12: Terminal growth | B12: =Assumptions!$F$19 -> 0.015
A13: Terminal value | B13: =IFERROR(G5*(1+B12)/(B11-B12),0) -> 11302.636
A14: PV of terminal value | B14: =B13*G7 -> 6860.6986
A15: Enterprise value | B15: =SUM(C8:G8)+B14 -> 10390.333
A16: Cash & cash equivalents | B16: =Historical!E13 -> 783.9
A17: Total debt | B17: =Historical!E18 -> 8279.2
A18: Equity value | B18: =MAX(0,B15+B16-B17) -> 2895.0335
A19: Diluted weighted-average shares | B19: =Historical!E17 -> 199.5
A20: DCF value / share | B20: =IFERROR(B18/B19,0) -> 14.511446
A21: Market-price comparison | B21: Omitted
A22: Reason | B22: No independently refreshed exact-dated quote was obtained in the controlled owner lane.
A23: 2030E Adjusted OIBDA | B23: =Sector_KPIs!J16 -> 1961.0644
A24: Exit-multiple enterprise value | B24: =B23*Assumptions!$F$20 -> 10785.854
A25: Exit-multiple value / share | B25: =IFERROR(MAX(0,B24+B16-B17)/B19,0) -> 16.494007
A29: Valuation date / horizon | B29: Filed FY2025 actuals with an explicit 2026E-2030E forecast; terminal value is measured at 2030E and discounted to the valuation date.
A30: Debt / cash policy | B30: LongTermDebtAndCapitalLeaseObligationsIncludingCurrentMaturities; finance leases are already included and are not double counted. Net debt deducts cash and cash equivalents only; restricted cash is excluded.
A31: Share-count basis | B31: Per-share valuation uses FY2025 diluted weighted-average shares; this is a period-average share count, not a point-in-time shares-outstanding quote.

Sheet Sensitivity
A1: LILA / LILAK | DCF Sensitivity | B1: LILA / LILAK | DCF Sensitivity | C1: LILA / LILAK | DCF Sensitivity | D1: LILA / LILAK | DCF Sensitivity | E1: LILA / LILAK | DCF Sensitivity | F1: LILA / LILAK | DCF Sensitivity | G1: LILA / LILAK | DCF Sensitivity | H1: LILA / LILAK | DCF Sensitivity
A2: Equity value per share across WACC and terminal-growth assumptions. Center cell equals the active DCF case. | B2: Equity value per share across WACC and terminal-growth assumptions. Center cell equals the active DCF case. | C2: Equity value per share across WACC and terminal-growth assumptions. Center cell equals the active DCF case. | D2: Equity value per share across WACC and terminal-growth assumptions. Center cell equals the active DCF case. | E2: Equity value per share across WACC and terminal-growth assumptions. Center cell equals the active DCF case. | F2: Equity value per share across WACC and terminal-growth assumptions. Center cell equals the active DCF case. | G2: Equity value per share across WACC and terminal-growth assumptions. Center cell equals the active DCF case. | H2: Equity value per share across WACC and terminal-growth assumptions. Center cell equals the active DCF case.
A4: Terminal growth → / WACC ↓ | B4: =Assumptions!$F$19+-0.01 -> 0.005 | C4: =Assumptions!$F$19+-0.005 -> 0.01 | D4: =Assumptions!$F$19+0 -> 0.015 | E4: =Assumptions!$F$19+0.005 -> 0.02 | F4: =Assumptions!$F$19+0.01 -> 0.025 | G4: Base DCF / share | H4: =Valuation!B20 -> 14.511446
A5: =Assumptions!$F$18+0.02 -> 0.125 | B5: =IFERROR((Forecast!C14/(1+$A5)+Forecast!D14/(1+$A5)^2+Forecast!E14/(1+$A5)^3+Forecast!F14/(1+$A5)^4+Forecast!G14/(1+$A5)^5+Forecast!G14*(1+B$4)/($A5-B$4)/(1+$A5)^5+Historical!E13-Historical!E18)/Historical!E17,0) -> 2.5908683 | C5: =IFERROR((Forecast!C14/(1+$A5)+Forecast!D14/(1+$A5)^2+Forecast!E14/(1+$A5)^3+Forecast!F14/(1+$A5)^4+Forecast!G14/(1+$A5)^5+Forecast!G14*(1+C$4)/($A5-C$4)/(1+$A5)^5+Historical!E13-Historical!E18)/Historical!E17,0) -> 3.7271712 | D5: =IFERROR((Forecast!C14/(1+$A5)+Forecast!D14/(1+$A5)^2+Forecast!E14/(1+$A5)^3+Forecast!F14/(1+$A5)^4+Forecast!G14/(1+$A5)^5+Forecast!G14*(1+D$4)/($A5-D$4)/(1+$A5)^5+Historical!E13-Historical!E18)/Historical!E17,0) -> 4.9667744 | E5: =IFERROR((Forecast!C14/(1+$A5)+Forecast!D14/(1+$A5)^2+Forecast!E14/(1+$A5)^3+Forecast!F14/(1+$A5)^4+Forecast!G14/(1+$A5)^5+Forecast!G14*(1+E$4)/($A5-E$4)/(1+$A5)^5+Historical!E13-Historical!E18)/Historical!E17,0) -> 6.324435 | F5: =IFERROR((Forecast!C14/(1+$A5)+Forecast!D14/(1+$A5)^2+Forecast!E14/(1+$A5)^3+Forecast!F14/(1+$A5)^4+Forecast!G14/(1+$A5)^5+Forecast!G14*(1+F$4)/($A5-F$4)/(1+$A5)^5+Historical!E13-Historical!E18)/Historical!E17,0) -> 7.8178617
A6: =Assumptions!$F$18+0.01 -> 0.115 | B6: =IFERROR((Forecast!C14/(1+$A6)+Forecast!D14/(1+$A6)^2+Forecast!E14/(1+$A6)^3+Forecast!F14/(1+$A6)^4+Forecast!G14/(1+$A6)^5+Forecast!G14*(1+B$4)/($A6-B$4)/(1+$A6)^5+Historical!E13-Historical!E18)/Historical!E17,0) -> 6.3063946 | C6: =IFERROR((Forecast!C14/(1+$A6)+Forecast!D14/(1+$A6)^2+Forecast!E14/(1+$A6)^3+Forecast!F14/(1+$A6)^4+Forecast!G14/(1+$A6)^5+Forecast!G14*(1+C$4)/($A6-C$4)/(1+$A6)^5+Historical!E13-Historical!E18)/Historical!E17,0) -> 7.7134197 | D6: =IFERROR((Forecast!C14/(1+$A6)+Forecast!D14/(1+$A6)^2+Forecast!E14/(1+$A6)^3+Forecast!F14/(1+$A6)^4+Forecast!G14/(1+$A6)^5+Forecast!G14*(1+D$4)/($A6-D$4)/(1+$A6)^5+Historical!E13-Historical!E18)/Historical!E17,0) -> 9.2611473 | E6: =IFERROR((Forecast!C14/(1+$A6)+Forecast!D14/(1+$A6)^2+Forecast!E14/(1+$A6)^3+Forecast!F14/(1+$A6)^4+Forecast!G14/(1+$A6)^5+Forecast!G14*(1+E$4)/($A6-E$4)/(1+$A6)^5+Historical!E13-Historical!E18)/Historical!E17,0) -> 10.971794 | F6: =IFERROR((Forecast!C14/(1+$A6)+Forecast!D14/(1+$A6)^2+Forecast!E14/(1+$A6)^3+Forecast!F14/(1+$A6)^4+Forecast!G14/(1+$A6)^5+Forecast!G14*(1+F$4)/($A6-F$4)/(1+$A6)^5+Historical!E13-Historical!E18)/Historical!E17,0) -> 12.872512
A7: =Assumptions!$F$18+0 -> 0.105 | B7: =IFERROR((Forecast!C14/(1+$A7)+Forecast!D14/(1+$A7)^2+Forecast!E14/(1+$A7)^3+Forecast!F14/(1+$A7)^4+Forecast!G14/(1+$A7)^5+Forecast!G14*(1+B$4)/($A7-B$4)/(1+$A7)^5+Historical!E13-Historical!E18)/Historical!E17,0) -> 10.767568 | C7: =IFERROR((Forecast!C14/(1+$A7)+Forecast!D14/(1+$A7)^2+Forecast!E14/(1+$A7)^3+Forecast!F14/(1+$A7)^4+Forecast!G14/(1+$A7)^5+Forecast!G14*(1+C$4)/($A7-C$4)/(1+$A7)^5+Historical!E13-Historical!E18)/Historical!E17,0) -> 12.540984 | D7: =IFERROR((Forecast!C14/(1+$A7)+Forecast!D14/(1+$A7)^2+Forecast!E14/(1+$A7)^3+Forecast!F14/(1+$A7)^4+Forecast!G14/(1+$A7)^5+Forecast!G14*(1+D$4)/($A7-D$4)/(1+$A7)^5+Historical!E13-Historical!E18)/Historical!E17,0) -> 14.511446 | E7: =IFERROR((Forecast!C14/(1+$A7)+Forecast!D14/(1+$A7)^2+Forecast!E14/(1+$A7)^3+Forecast!F14/(1+$A7)^4+Forecast!G14/(1+$A7)^5+Forecast!G14*(1+E$4)/($A7-E$4)/(1+$A7)^5+Historical!E13-Historical!E18)/Historical!E17,0) -> 16.713727 | F7: =IFERROR((Forecast!C14/(1+$A7)+Forecast!D14/(1+$A7)^2+Forecast!E14/(1+$A7)^3+Forecast!F14/(1+$A7)^4+Forecast!G14/(1+$A7)^5+Forecast!G14*(1+F$4)/($A7-F$4)/(1+$A7)^5+Historical!E13-Historical!E18)/Historical!E17,0) -> 19.191293
A8: =Assumptions!$F$18+-0.01 -> 0.095 | B8: =IFERROR((Forecast!C14/(1+$A8)+Forecast!D14/(1+$A8)^2+Forecast!E14/(1+$A8)^3+Forecast!F14/(1+$A8)^4+Forecast!G14/(1+$A8)^5+Forecast!G14*(1+B$4)/($A8-B$4)/(1+$A8)^5+Historical!E13-Historical!E18)/Historical!E17,0) -> 16.223073 | C8: =IFERROR((Forecast!C14/(1+$A8)+Forecast!D14/(1+$A8)^2+Forecast!E14/(1+$A8)^3+Forecast!F14/(1+$A8)^4+Forecast!G14/(1+$A8)^5+Forecast!G14*(1+C$4)/($A8-C$4)/(1+$A8)^5+Historical!E13-Historical!E18)/Historical!E17,0) -> 18.506912 | D8: =IFERROR((Forecast!C14/(1+$A8)+Forecast!D14/(1+$A8)^2+Forecast!E14/(1+$A8)^3+Forecast!F14/(1+$A8)^4+Forecast!G14/(1+$A8)^5+Forecast!G14*(1+D$4)/($A8-D$4)/(1+$A8)^5+Historical!E13-Historical!E18)/Historical!E17,0) -> 21.07623 | E8: =IFERROR((Forecast!C14/(1+$A8)+Forecast!D14/(1+$A8)^2+Forecast!E14/(1+$A8)^3+Forecast!F14/(1+$A8)^4+Forecast!G14/(1+$A8)^5+Forecast!G14*(1+E$4)/($A8-E$4)/(1+$A8)^5+Historical!E13-Historical!E18)/Historical!E17,0) -> 23.988124 | F8: =IFERROR((Forecast!C14/(1+$A8)+Forecast!D14/(1+$A8)^2+Forecast!E14/(1+$A8)^3+Forecast!F14/(1+$A8)^4+Forecast!G14/(1+$A8)^5+Forecast!G14*(1+F$4)/($A8-F$4)/(1+$A8)^5+Historical!E13-Historical!E18)/Historical!E17,0) -> 27.316003
A9: =Assumptions!$F$18+-0.02 -> 0.085 | B9: =IFERROR((Forecast!C14/(1+$A9)+Forecast!D14/(1+$A9)^2+Forecast!E14/(1+$A9)^3+Forecast!F14/(1+$A9)^4+Forecast!G14/(1+$A9)^5+Forecast!G14*(1+B$4)/($A9-B$4)/(1+$A9)^5+Historical!E13-Historical!E18)/Historical!E17,0) -> 23.045945 | C9: =IFERROR((Forecast!C14/(1+$A9)+Forecast!D14/(1+$A9)^2+Forecast!E14/(1+$A9)^3+Forecast!F14/(1+$A9)^4+Forecast!G14/(1+$A9)^5+Forecast!G14*(1+C$4)/($A9-C$4)/(1+$A9)^5+Historical!E13-Historical!E18)/Historical!E17,0) -> 26.066683 | D9: =IFERROR((Forecast!C14/(1+$A9)+Forecast!D14/(1+$A9)^2+Forecast!E14/(1+$A9)^3+Forecast!F14/(1+$A9)^4+Forecast!G14/(1+$A9)^5+Forecast!G14*(1+D$4)/($A9-D$4)/(1+$A9)^5+Historical!E13-Historical!E18)/Historical!E17,0) -> 29.518956 | E9: =IFERROR((Forecast!C14/(1+$A9)+Forecast!D14/(1+$A9)^2+Forecast!E14/(1+$A9)^3+Forecast!F14/(1+$A9)^4+Forecast!G14/(1+$A9)^5+Forecast!G14*(1+E$4)/($A9-E$4)/(1+$A9)^5+Historical!E13-Historical!E18)/Historical!E17,0) -> 33.502347 | F9: =IFERROR((Forecast!C14/(1+$A9)+Forecast!D14/(1+$A9)^2+Forecast!E14/(1+$A9)^3+Forecast!F14/(1+$A9)^4+Forecast!G14/(1+$A9)^5+Forecast!G14*(1+F$4)/($A9-F$4)/(1+$A9)^5+Historical!E13-Historical!E18)/Historical!E17,0) -> 38.149637

Sheet Checks
A1: LILA / LILAK | Formula-Driven Model Checks | B1: LILA / LILAK | Formula-Driven Model Checks | C1: LILA / LILAK | Formula-Driven Model Checks | D1: LILA / LILAK | Formula-Driven Model Checks | E1: LILA / LILAK | Formula-Driven Model Checks | F1: LILA / LILAK | Formula-Driven Model Checks | G1: LILA / LILAK | Formula-Driven Model Checks | H1: LILA / LILAK | Formula-Driven Model Checks
A2: Overall status is aggregated from check-row formulas. No check status is hardcoded. | B2: Overall status is aggregated from check-row formulas. No check status is hardcoded. | C2: Overall status is aggregated from check-row formulas. No check status is hardcoded. | D2: Overall status is aggregated from check-row formulas. No check status is hardcoded. | E2: Overall status is aggregated from check-row formulas. No check status is hardcoded. | F2: Overall status is aggregated from check-row formulas. No check status is hardcoded. | G2: Overall status is aggregated from check-row formulas. No check status is hardcoded. | H2: Overall status is aggregated from check-row formulas. No check status is hardcoded.
A3: Model as of | B3: 2025-12-31
A4: Overall model status | B4: =IF(COUNTIF(G7:G16,"<>PASS")=0,"PASS","REMEDIATE") -> PASS
A6: Check ID | B6: Category | C6: Actual | D6: Expected | E6: Difference | F6: Tolerance | G6: Status | H6: Evidence / fix hint
A7: C01 | B7: Source ledger exact URLs | C7: =COUNTBLANK(Sources!O5:O91) -> 0 | D7: 0 | E7: =C7-D7 -> 0 | F7: 0.01 | G7: =IF(ABS(E7)<=F7,"PASS","FAIL") -> PASS | H7: All material rows require an exact URL.
A8: C02 | B8: Source ledger accession field complete | C8: =COUNTBLANK(Sources!K5:K91) -> 0 | D8: 0 | E8: =C8-D8 -> 0 | F8: 0.01 | G8: =IF(ABS(E8)<=F8,"PASS","FAIL") -> PASS | H8: Every source row must carry a filed accession or an explicit N/A.
A9: C03 | B9: Debt bridge | C9: =Historical!E18-SUM(Historical!E14:E16) -> 0 | D9: 0 | E9: =C9-D9 -> 0 | F9: 0.01 | G9: =IF(ABS(E9)<=F9,"PASS","FAIL") -> PASS | H9: LongTermDebtAndCapitalLeaseObligationsIncludingCurrentMaturities; finance leases are already included and are not double counted.
A10: C04 | B10: Net debt bridge | C10: =Historical!E19-(Historical!E18-Historical!E13) -> 0 | D10: 0 | E10: =C10-D10 -> 0 | F10: 0.01 | G10: =IF(ABS(E10)<=F10,"PASS","FAIL") -> PASS | H10: Net debt deducts cash and cash equivalents only; restricted cash is excluded.
A11: C05 | B11: Operating model historical revenue tie | C11: =Sector_KPIs!E14-Historical!E5 -> 0 | D11: 0 | E11: =C11-D11 -> 0 | F11: 0.01 | G11: =IF(ABS(E11)<=F11,"PASS","FAIL") -> PASS | H11: 2025 operating schedule revenue must equal filed revenue.
A12: C06 | B12: Forecast operating link | C12: =Forecast!C5-Sector_KPIs!F14 -> 0 | D12: 0 | E12: =C12-D12 -> 0 | F12: 0.01 | G12: =IF(ABS(E12)<=F12,"PASS","FAIL") -> PASS | H12: 2026E revenue must flow from the operating model.
A13: C07 | B13: Scenario selector | C13: =IF(AND(Assumptions!B3>=1,Assumptions!B3<=3),1,0) -> 1 | D13: 1 | E13: =C13-D13 -> 0 | F13: 0.01 | G13: =IF(ABS(E13)<=F13,"PASS","FAIL") -> PASS | H13: Selector must be 1, 2 or 3.
A14: C08 | B14: Share count positive | C14: =IF(Historical!E17>0,1,0) -> 1 | D14: 1 | E14: =C14-D14 -> 0 | F14: 0.01 | G14: =IF(ABS(E14)<=F14,"PASS","FAIL") -> PASS | H14: Per-share valuation requires a positive share count.
A15: C09 | B15: Sensitivity center reconciliation | C15: =Sensitivity!D7-Valuation!B20 -> 0 | D15: 0 | E15: =C15-D15 -> 0 | F15: 0.01 | G15: =IF(ABS(E15)<=F15,"PASS","FAIL") -> PASS | H15: Center sensitivity cell must equal the active valuation.
A16: C10 | B16: Valuation finite / non-negative | C16: =IF(AND(ISNUMBER(Valuation!B20),Valuation!B20>=0),1,0) -> 1 | D16: 1 | E16: =C16-D16 -> 0 | F16: 0.01 | G16: =IF(ABS(E16)<=F16,"PASS","FAIL") -> PASS | H16: Primary equity value per share must be finite and non-negative; equity is floored at zero in downside cases.

Sheet Sector_KPIs
A1: LILA | Homes / RGUs / Mobile-to-Cash-Flow Model | B1: LILA | Homes / RGUs / Mobile-to-Cash-Flow Model | C1: LILA | Homes / RGUs / Mobile-to-Cash-Flow Model | D1: LILA | Homes / RGUs / Mobile-to-Cash-Flow Model | E1: LILA | Homes / RGUs / Mobile-to-Cash-Flow Model | F1: LILA | Homes / RGUs / Mobile-to-Cash-Flow Model | G1: LILA | Homes / RGUs / Mobile-to-Cash-Flow Model | H1: LILA | Homes / RGUs / Mobile-to-Cash-Flow Model | I1: LILA | Homes / RGUs / Mobile-to-Cash-Flow Model | J1: LILA | Homes / RGUs / Mobile-to-Cash-Flow Model
A2: No consolidated reported ARPU/churn exists; the model uses a residential revenue-per-unit proxy and fixed RGU density. | B2: No consolidated reported ARPU/churn exists; the model uses a residential revenue-per-unit proxy and fixed RGU density. | C2: No consolidated reported ARPU/churn exists; the model uses a residential revenue-per-unit proxy and fixed RGU density. | D2: No consolidated reported ARPU/churn exists; the model uses a residential revenue-per-unit proxy and fixed RGU density. | E2: No consolidated reported ARPU/churn exists; the model uses a residential revenue-per-unit proxy and fixed RGU density. | F2: No consolidated reported ARPU/churn exists; the model uses a residential revenue-per-unit proxy and fixed RGU density. | G2: No consolidated reported ARPU/churn exists; the model uses a residential revenue-per-unit proxy and fixed RGU density. | H2: No consolidated reported ARPU/churn exists; the model uses a residential revenue-per-unit proxy and fixed RGU density. | I2: No consolidated reported ARPU/churn exists; the model uses a residential revenue-per-unit proxy and fixed RGU density. | J2: No consolidated reported ARPU/churn exists; the model uses a residential revenue-per-unit proxy and fixed RGU density.
A4: Metric | B4: Units | C4: 2023A | D4: 2024A | E4: 2025A | F4: 2026E | G4: 2027E | H4: 2028E | I4: 2029E | J4: 2030E
A5: Homes passed | B5: mm | E5: 4.6926 | F5: =E5*(1+Assumptions!$F$7) -> 4.786452 | G5: =F5*(1+Assumptions!$F$7) -> 4.882181 | H5: =G5*(1+Assumptions!$F$7) -> 4.9798247 | I5: =H5*(1+Assumptions!$F$7) -> 5.0794212 | J5: =I5*(1+Assumptions!$F$7) -> 5.1810096
A6: Fixed RGUs | B6: mm | E6: 3.8366 | F6: =F5*F7 -> 3.8741987 | G6: =G5*G7 -> 3.9121658 | H6: =H5*H7 -> 3.9505051 | I6: =I5*I7 -> 3.98922 | J6: =J5*J7 -> 4.0283144
A7: Fixed RGUs / home passed | B7: x | D7: =IF(OR(D5="",D6=""),"",D6/D5) | E7: =IF(OR(E5="",E6=""),"",E6/E5) -> 0.81758513 | F7: =E7*(1+Assumptions!$F$8) -> 0.80940928 | G7: =F7*(1+Assumptions!$F$8) -> 0.80131519 | H7: =G7*(1+Assumptions!$F$8) -> 0.79330204 | I7: =H7*(1+Assumptions!$F$8) -> 0.78536902 | J7: =I7*(1+Assumptions!$F$8) -> 0.77751533
A8: Reported Q4 organic RGU losses | B8: mm / quarter | E8: -0.1422
A9: Mobile subscribers | B9: mm | E9: 6.794 | F9: =E9*(1+Assumptions!$F$9) -> 6.92988 | G9: =F9*(1+Assumptions!$F$9) -> 7.0684776 | H9: =G9*(1+Assumptions!$F$9) -> 7.2098472 | I9: =H9*(1+Assumptions!$F$9) -> 7.3540441 | J9: =I9*(1+Assumptions!$F$9) -> 7.501125
A10: Total modeled residential units | B10: mm | D10: =IF(AND(D6="",D9=""),"",SUM(D6,D9)) | E10: =IF(AND(E6="",E9=""),"",SUM(E6,E9)) -> 10.6306 | F10: =F6+F9 -> 10.804079 | G10: =G6+G9 -> 10.980643 | H10: =H6+H9 -> 11.160352 | I10: =I6+I9 -> 11.343264 | J10: =J6+J9 -> 11.529439
A11: Residential revenue / unit proxy | B11: $ / month | D11: =IF(OR(D10="",D10=0,D12=""),"",D12/D10/12) | E11: =IF(OR(E10="",E10=0,E12=""),"",E12/E10/12) -> 23.456657 | F11: =E11*(1+Assumptions!$F$10) -> 23.92579 | G11: =F11*(1+Assumptions!$F$10) -> 24.404305 | H11: =G11*(1+Assumptions!$F$10) -> 24.892392 | I11: =H11*(1+Assumptions!$F$10) -> 25.390239 | J11: =I11*(1+Assumptions!$F$10) -> 25.898044
A12: Residential revenue | B12: USD mm | D12: 2953.8 | E12: 2992.3 | F12: =F10*F11*12 -> 3101.9534 | G12: =G10*G11*12 -> 3215.6997 | H12: =H10*H11*12 -> 3333.6943 | I12: =I10*I11*12 -> 3456.0983 | J12: =J10*J11*12 -> 3583.0792
A13: B2B / other revenue | B13: USD mm | D13: =D14-D12 -> 1493 | E13: =E14-E12 -> 1449.9 | F13: =E13*(1+Assumptions!$F$11) -> 1464.399 | G13: =F13*(1+Assumptions!$F$11) -> 1479.043 | H13: =G13*(1+Assumptions!$F$11) -> 1493.8334 | I13: =H13*(1+Assumptions!$F$11) -> 1508.7718 | J13: =I13*(1+Assumptions!$F$11) -> 1523.8595
A14: Total revenue | B14: USD mm | D14: 4446.8 | E14: 4442.2 | F14: =F12+F13 -> 4566.3524 | G14: =G12+G13 -> 4694.7427 | H14: =H12+H13 -> 4827.5277 | I14: =I12+I13 -> 4964.8701 | J14: =J12+J13 -> 5106.9386
A15: Adjusted OIBDA margin | B15: % | D15: 0.35198345 | E15: 0.38411148 | F15: =Assumptions!$F$12 -> 0.384 | G15: =Assumptions!$F$12 -> 0.384 | H15: =Assumptions!$F$12 -> 0.384 | I15: =Assumptions!$F$12 -> 0.384 | J15: =Assumptions!$F$12 -> 0.384
A16: Adjusted OIBDA | B16: USD mm | D16: 1565.2 | E16: 1706.3 | F16: =F14*F15 -> 1753.4793 | G16: =G14*G15 -> 1802.7812 | H16: =H14*H15 -> 1853.7706 | I16: =I14*I15 -> 1906.5101 | J16: =J14*J15 -> 1961.0644
A17: P&E additions / revenue | B17: % | D17: 0.16310605 | E17: 0.14409527 | F17: =Assumptions!$F$14 -> 0.144 | G17: =Assumptions!$F$14 -> 0.144 | H17: =Assumptions!$F$14 -> 0.144 | I17: =Assumptions!$F$14 -> 0.144 | J17: =Assumptions!$F$14 -> 0.144
A18: P&E additions | B18: USD mm | D18: 725.3 | E18: 640.1 | F18: =F14*F17 -> 657.55474 | G18: =G14*G17 -> 676.04295 | H18: =H14*H17 -> 695.16399 | I18: =I14*I17 -> 714.94129 | J18: =J14*J17 -> 735.39916
A19: Net debt | B19: USD mm | D19: =Historical!D19 -> 7425.9 | E19: =Historical!E19 -> 7495.3 | F19: =E19*(1-Assumptions!$F$17) -> 7120.535 | G19: =F19*(1-Assumptions!$F$17) -> 6764.5083 | H19: =G19*(1-Assumptions!$F$17) -> 6426.2828 | I19: =H19*(1-Assumptions!$F$17) -> 6104.9687 | J19: =I19*(1-Assumptions!$F$17) -> 5799.7203
A20: Modeled net leverage | B20: x | D20: =IFERROR(D19/D16,0) -> 4.7443777 | E20: =IFERROR(E19/E16,0) -> 4.3927211 | F20: =IFERROR(F19/F16,0) -> 4.0608035 | G20: =IFERROR(G19/G16,0) -> 3.7522625 | H20: =IFERROR(H19/H16,0) -> 3.4666008 | I20: =IFERROR(I19/I16,0) -> 3.2021696 | J20: =IFERROR(J19/J16,0) -> 2.9574348
A21: Reported consolidated net leverage | B21: x | E21: 4.3
A24: Model limitation: LILA does not disclose a single consolidated absolute ARPU or churn rate. The model uses a clearly labeled residential revenue-per-unit proxy and reported Q4 organic RGU losses; neither is represented as company-reported ARPU/churn. | B24: Model limitation: LILA does not disclose a single consolidated absolute ARPU or churn rate. The model uses a clearly labeled residential revenue-per-unit proxy and reported Q4 organic RGU losses; neither is represented as company-reported ARPU/churn. | C24: Model limitation: LILA does not disclose a single consolidated absolute ARPU or churn rate. The model uses a clearly labeled residential revenue-per-unit proxy and reported Q4 organic RGU losses; neither is represented as company-reported ARPU/churn. | D24: Model limitation: LILA does not disclose a single consolidated absolute ARPU or churn rate. The model uses a clearly labeled residential revenue-per-unit proxy and reported Q4 organic RGU losses; neither is represented as company-reported ARPU/churn. | E24: Model limitation: LILA does not disclose a single consolidated absolute ARPU or churn rate. The model uses a clearly labeled residential revenue-per-unit proxy and reported Q4 organic RGU losses; neither is represented as company-reported ARPU/churn. | F24: Model limitation: LILA does not disclose a single consolidated absolute ARPU or churn rate. The model uses a clearly labeled residential revenue-per-unit proxy and reported Q4 organic RGU losses; neither is represented as company-reported ARPU/churn. | G24: Model limitation: LILA does not disclose a single consolidated absolute ARPU or churn rate. The model uses a clearly labeled residential revenue-per-unit proxy and reported Q4 organic RGU losses; neither is represented as company-reported ARPU/churn. | H24: Model limitation: LILA does not disclose a single consolidated absolute ARPU or churn rate. The model uses a clearly labeled residential revenue-per-unit proxy and reported Q4 organic RGU losses; neither is represented as company-reported ARPU/churn. | I24: Model limitation: LILA does not disclose a single consolidated absolute ARPU or churn rate. The model uses a clearly labeled residential revenue-per-unit proxy and reported Q4 organic RGU losses; neither is represented as company-reported ARPU/churn. | J24: Model limitation: LILA does not disclose a single consolidated absolute ARPU or churn rate. The model uses a clearly labeled residential revenue-per-unit proxy and reported Q4 organic RGU losses; neither is represented as company-reported ARPU/churn.
A27: Year | B27: Revenue | C27: Adjusted OIBDA
A28: 2025A | B28: =E14 -> 4442.2 | C28: =E16 -> 1706.3
A29: 2026E | B29: =F14 -> 4566.3524 | C29: =F16 -> 1753.4793
A30: 2027E | B30: =G14 -> 4694.7427 | C30: =G16 -> 1802.7812
A31: 2028E | B31: =H14 -> 4827.5277 | C31: =H16 -> 1853.7706
A32: 2029E | B32: =I14 -> 4964.8701 | C32: =I16 -> 1906.5101
A33: 2030E | B33: =J14 -> 5106.9386 | C33: =J16 -> 1961.0644

Sheet Change_Log
A1: LILA / LILAK | Controlled Change Log | B1: LILA / LILAK | Controlled Change Log | C1: LILA / LILAK | Controlled Change Log | D1: LILA / LILAK | Controlled Change Log | E1: LILA / LILAK | Controlled Change Log | F1: LILA / LILAK | Controlled Change Log
A2: Prior workbook is preserved. This output is a new artifact with documented source, model, gate and recalculation changes. | B2: Prior workbook is preserved. This output is a new artifact with documented source, model, gate and recalculation changes. | C2: Prior workbook is preserved. This output is a new artifact with documented source, model, gate and recalculation changes. | D2: Prior workbook is preserved. This output is a new artifact with documented source, model, gate and recalculation changes. | E2: Prior workbook is preserved. This output is a new artifact with documented source, model, gate and recalculation changes. | F2: Prior workbook is preserved. This output is a new artifact with documented source, model, gate and recalculation changes.
A4: Timestamp | B4: Version | C4: Area | D4: Change | E4: Evidence | F4: Owner scope
A5: UTC 2026-07-16T21:40:00Z | B5: 9of10-regated | C5: Preservation | D5: Prior workbook preserved without overwrite. | E5: Original SHA-256: 6d0729636bf8366712df47378856b6f4b2833e159e2b83d58fe77e2c3adb825e | F5: Controlled rebuild
A6: UTC 2026-07-16T21:40:00Z | B6: 9of10-regated | C6: Sources | D6: Replaced generic source list with exact SEC accession, filing URL, taxonomy/tag, period, unit, transform and target-cell ledger. | E6: Sources!A4:Q* | F6: Owner preflight
A7: UTC 2026-07-16T21:40:00Z | B7: 9of10-regated | C7: Debt / cash / shares | D7: Rebuilt total debt from explicit filed components; documented cash/restricted-cash and share-count policies. | E7: Historical!A13:I19 | F7: Owner preflight
A8: UTC 2026-07-16T21:40:00Z | B8: 9of10-regated | C8: Operating model | D8: Connected homes passed, RGU density, mobile subscribers and a labeled revenue-per-unit proxy to cash flow. | E8: Sector_KPIs | F8: Owner preflight
A9: UTC 2026-07-16T21:40:00Z | B9: 9of10-regated | C9: Valuation | D9: Established formula-driven DCF with exit-multiple cross-check. | E9: Valuation + Sensitivity | F9: Owner preflight
A10: UTC 2026-07-16T21:40:00Z | B10: 9of10-regated | C10: Gate | D10: Added formula-driven Checks and H0-H9 owner-preflight gate; independent certification is explicitly excluded. | E10: Checks + Gate_9of10 | F10: Owner preflight
A11: UTC 2026-07-16T21:40:00Z | B11: 9of10-regated | C11: Output | D11: Authored with artifact-tool; native recalculation and final visual manifest are referenced in Gate_9of10 and support evidence. | E11: Liberty_Latin_America_9of10_Regated.xlsx | F11: Owner preflight

Sheet Gate_9of10
A1: LILA / LILAK | H0-H9 Owner Preflight Gate | B1: LILA / LILAK | H0-H9 Owner Preflight Gate | C1: LILA / LILAK | H0-H9 Owner Preflight Gate | D1: LILA / LILAK | H0-H9 Owner Preflight Gate | E1: LILA / LILAK | H0-H9 Owner Preflight Gate | F1: LILA / LILAK | H0-H9 Owner Preflight Gate | G1: LILA / LILAK | H0-H9 Owner Preflight Gate
A2: This sheet records owner preflight readiness. Independent certification is still required and is not self-awarded. | B2: This sheet records owner preflight readiness. Independent certification is still required and is not self-awarded. | C2: This sheet records owner preflight readiness. Independent certification is still required and is not self-awarded. | D2: This sheet records owner preflight readiness. Independent certification is still required and is not self-awarded. | E2: This sheet records owner preflight readiness. Independent certification is still required and is not self-awarded. | F2: This sheet records owner preflight readiness. Independent certification is still required and is not self-awarded. | G2: This sheet records owner preflight readiness. Independent certification is still required and is not self-awarded.
