Workbook

Sheet 00_Cover
A1: TMUS | 9-of-10 Regated Public-Company Model | B1: TMUS | 9-of-10 Regated Public-Company Model | C1: TMUS | 9-of-10 Regated Public-Company Model | D1: TMUS | 9-of-10 Regated Public-Company Model | E1: TMUS | 9-of-10 Regated Public-Company Model | F1: TMUS | 9-of-10 Regated Public-Company Model | G1: TMUS | 9-of-10 Regated Public-Company Model | H1: TMUS | 9-of-10 Regated Public-Company Model
A2: T-Mobile US, Inc. | Telecommunications | Controlled artifact-tool rebuild; independent certification remains outside owner scope. | B2: T-Mobile US, Inc. | Telecommunications | Controlled artifact-tool rebuild; independent certification remains outside owner scope. | C2: T-Mobile US, Inc. | Telecommunications | Controlled artifact-tool rebuild; independent certification remains outside owner scope. | D2: T-Mobile US, Inc. | Telecommunications | Controlled artifact-tool rebuild; independent certification remains outside owner scope. | E2: T-Mobile US, Inc. | Telecommunications | Controlled artifact-tool rebuild; independent certification remains outside owner scope. | F2: T-Mobile US, Inc. | Telecommunications | Controlled artifact-tool rebuild; independent certification remains outside owner scope. | G2: T-Mobile US, Inc. | Telecommunications | Controlled artifact-tool rebuild; independent certification remains outside owner scope. | H2: T-Mobile US, Inc. | Telecommunications | Controlled artifact-tool rebuild; independent certification remains outside owner scope.
A4: Company | B4: T-Mobile US, Inc.
A5: Ticker | B5: TMUS
A6: Model as of | B6: 2025-12-31
A7: Currency | B7: USD millions unless stated
A8: Forecast horizon | B8: 2026E-2030E
A9: Active case | B9: =Assumptions!B4 -> Base
A10: Overall status | B10: =Checks!B4 -> PASS
A11: Primary valuation | B11: Unlevered FCFF DCF
A12: Market-price comparison | B12: Omitted — no independently refreshed exact-dated quote in this owner lane
A13: Debt definition | B13: LongTermDebt + ShortTermBorrowings + FinanceLeaseLiability; all carrying values, USD mm.
A14: Cash policy | B14: Net debt deducts cash and cash equivalents only; restricted cash and non-operating investments are excluded.
A15: Acquisition / perimeter | B15: 2025 customer/revenue perimeter includes UScellular, Metronet and Lumos acquisitions; 2024 includes Ka'ena. Forecast cases normalize acquisition-heavy growth.
A16: Known limitation | B16: Reported postpaid ARPA is per account while churn is postpaid phone churn; the driver model therefore uses phone customers/ARPU for phone service revenue and treats other postpaid revenue separately.
A19: Investor view: begin with operating drivers and the debt bridge, then assess valuation only after Checks!B4 passes. Gate_9of10 is owner preflight, not independent certification. | B19: Investor view: begin with operating drivers and the debt bridge, then assess valuation only after Checks!B4 passes. Gate_9of10 is owner preflight, not independent certification. | C19: Investor view: begin with operating drivers and the debt bridge, then assess valuation only after Checks!B4 passes. Gate_9of10 is owner preflight, not independent certification. | D19: Investor view: begin with operating drivers and the debt bridge, then assess valuation only after Checks!B4 passes. Gate_9of10 is owner preflight, not independent certification. | E19: Investor view: begin with operating drivers and the debt bridge, then assess valuation only after Checks!B4 passes. Gate_9of10 is owner preflight, not independent certification. | F19: Investor view: begin with operating drivers and the debt bridge, then assess valuation only after Checks!B4 passes. Gate_9of10 is owner preflight, not independent certification. | G19: Investor view: begin with operating drivers and the debt bridge, then assess valuation only after Checks!B4 passes. Gate_9of10 is owner preflight, not independent certification. | H19: Investor view: begin with operating drivers and the debt bridge, then assess valuation only after Checks!B4 passes. Gate_9of10 is owner preflight, not independent certification.

Sheet Sources
A1: TMUS | Source and Transformation Ledger | B1: TMUS | Source and Transformation Ledger | C1: TMUS | Source and Transformation Ledger | D1: TMUS | Source and Transformation Ledger | E1: TMUS | Source and Transformation Ledger | F1: TMUS | Source and Transformation Ledger | G1: TMUS | Source and Transformation Ledger | H1: TMUS | Source and Transformation Ledger | I1: TMUS | Source and Transformation Ledger | J1: TMUS | Source and Transformation Ledger | K1: TMUS | Source and Transformation Ledger | L1: TMUS | Source and Transformation Ledger | M1: TMUS | Source and Transformation Ledger | N1: TMUS | Source and Transformation Ledger | O1: TMUS | Source and Transformation Ledger | P1: TMUS | Source and Transformation Ledger | Q1: TMUS | Source and Transformation Ledger
A2: Every material input identifies target, metric, period, filing metadata, retrieval date, exact URL, scale/sign transform and perimeter note. | B2: Every material input identifies target, metric, period, filing metadata, retrieval date, exact URL, scale/sign transform and perimeter note. | C2: Every material input identifies target, metric, period, filing metadata, retrieval date, exact URL, scale/sign transform and perimeter note. | D2: Every material input identifies target, metric, period, filing metadata, retrieval date, exact URL, scale/sign transform and perimeter note. | E2: Every material input identifies target, metric, period, filing metadata, retrieval date, exact URL, scale/sign transform and perimeter note. | F2: Every material input identifies target, metric, period, filing metadata, retrieval date, exact URL, scale/sign transform and perimeter note. | G2: Every material input identifies target, metric, period, filing metadata, retrieval date, exact URL, scale/sign transform and perimeter note. | H2: Every material input identifies target, metric, period, filing metadata, retrieval date, exact URL, scale/sign transform and perimeter note. | I2: Every material input identifies target, metric, period, filing metadata, retrieval date, exact URL, scale/sign transform and perimeter note. | J2: Every material input identifies target, metric, period, filing metadata, retrieval date, exact URL, scale/sign transform and perimeter note. | K2: Every material input identifies target, metric, period, filing metadata, retrieval date, exact URL, scale/sign transform and perimeter note. | L2: Every material input identifies target, metric, period, filing metadata, retrieval date, exact URL, scale/sign transform and perimeter note. | M2: Every material input identifies target, metric, period, filing metadata, retrieval date, exact URL, scale/sign transform and perimeter note. | N2: Every material input identifies target, metric, period, filing metadata, retrieval date, exact URL, scale/sign transform and perimeter note. | O2: Every material input identifies target, metric, period, filing metadata, retrieval date, exact URL, scale/sign transform and perimeter note. | P2: Every material input identifies target, metric, period, filing metadata, retrieval date, exact URL, scale/sign transform and perimeter note. | Q2: Every material input identifies target, metric, period, filing metadata, retrieval date, exact URL, scale/sign transform and perimeter note.
A4: Source ID | B4: Target | C4: Metric | D4: Value | E4: Units | F4: Period start | G4: Period end / as-of | H4: Taxonomy / tag | I4: Form | J4: Filed | K4: Accession | L4: Source title | M4: Source class | N4: Retrieved | O4: Exact URL | P4: Transform | Q4: Notes / perimeter
A5: SRC-001 | B5: Historical!C5 | C5: Revenue | D5: 78558 | E5: USD mm | F5: 2023-01-01 | G5: 2023-12-31 | H5: us-gaap:RevenueFromContractWithCustomerExcludingAssessedTax | I5: 10-K | J5: 2026-02-11 | K5: 0001283699-26-000010 | L5: T-Mobile US, Inc. Form 10-K / SEC Company Facts | M5: Primary — SEC filed | N5: 2026-07-16 | O5: https://data.sec.gov/api/xbrl/companyfacts/CIK0001283699.json | P5: Filed USD divided by 1,000,000; sign preserved | Q5: 2025 customer/revenue perimeter includes UScellular, Metronet and Lumos acquisitions; 2024 includes Ka'ena. Forecast cases normalize acquisition-heavy growth.
A6: SRC-002 | B6: Historical!D5 | C6: Revenue | D6: 81400 | E6: USD mm | F6: 2024-01-01 | G6: 2024-12-31 | H6: us-gaap:RevenueFromContractWithCustomerExcludingAssessedTax | I6: 10-K | J6: 2026-02-11 | K6: 0001283699-26-000010 | L6: T-Mobile US, Inc. Form 10-K / SEC Company Facts | M6: Primary — SEC filed | N6: 2026-07-16 | O6: https://data.sec.gov/api/xbrl/companyfacts/CIK0001283699.json | P6: Filed USD divided by 1,000,000; sign preserved | Q6: 2025 customer/revenue perimeter includes UScellular, Metronet and Lumos acquisitions; 2024 includes Ka'ena. Forecast cases normalize acquisition-heavy growth.
A7: SRC-003 | B7: Historical!E5 | C7: Revenue | D7: 88309 | E7: USD mm | F7: 2025-01-01 | G7: 2025-12-31 | H7: us-gaap:RevenueFromContractWithCustomerExcludingAssessedTax | I7: 10-K | J7: 2026-02-11 | K7: 0001283699-26-000010 | L7: T-Mobile US, Inc. Form 10-K / SEC Company Facts | M7: Primary — SEC filed | N7: 2026-07-16 | O7: https://data.sec.gov/api/xbrl/companyfacts/CIK0001283699.json | P7: Filed USD divided by 1,000,000; sign preserved | Q7: 2025 customer/revenue perimeter includes UScellular, Metronet and Lumos acquisitions; 2024 includes Ka'ena. Forecast cases normalize acquisition-heavy growth.
A8: SRC-004 | B8: Historical!C6 | C8: Operating income (EBIT) | D8: 14266 | E8: USD mm | F8: 2023-01-01 | G8: 2023-12-31 | H8: us-gaap:OperatingIncomeLoss | I8: 10-K | J8: 2026-02-11 | K8: 0001283699-26-000010 | L8: T-Mobile US, Inc. Form 10-K / SEC Company Facts | M8: Primary — SEC filed | N8: 2026-07-16 | O8: https://data.sec.gov/api/xbrl/companyfacts/CIK0001283699.json | P8: Filed USD divided by 1,000,000; sign preserved | Q8: 2025 customer/revenue perimeter includes UScellular, Metronet and Lumos acquisitions; 2024 includes Ka'ena. Forecast cases normalize acquisition-heavy growth.
A9: SRC-005 | B9: Historical!D6 | C9: Operating income (EBIT) | D9: 18010 | E9: USD mm | F9: 2024-01-01 | G9: 2024-12-31 | H9: us-gaap:OperatingIncomeLoss | I9: 10-K | J9: 2026-02-11 | K9: 0001283699-26-000010 | L9: T-Mobile US, Inc. Form 10-K / SEC Company Facts | M9: Primary — SEC filed | N9: 2026-07-16 | O9: https://data.sec.gov/api/xbrl/companyfacts/CIK0001283699.json | P9: Filed USD divided by 1,000,000; sign preserved | Q9: 2025 customer/revenue perimeter includes UScellular, Metronet and Lumos acquisitions; 2024 includes Ka'ena. Forecast cases normalize acquisition-heavy growth.
A10: SRC-006 | B10: Historical!E6 | C10: Operating income (EBIT) | D10: 18279 | E10: USD mm | F10: 2025-01-01 | G10: 2025-12-31 | H10: us-gaap:OperatingIncomeLoss | I10: 10-K | J10: 2026-02-11 | K10: 0001283699-26-000010 | L10: T-Mobile US, Inc. Form 10-K / SEC Company Facts | M10: Primary — SEC filed | N10: 2026-07-16 | O10: https://data.sec.gov/api/xbrl/companyfacts/CIK0001283699.json | P10: Filed USD divided by 1,000,000; sign preserved | Q10: 2025 customer/revenue perimeter includes UScellular, Metronet and Lumos acquisitions; 2024 includes Ka'ena. Forecast cases normalize acquisition-heavy growth.
A11: SRC-007 | B11: Historical!C7 | C11: Net income | D11: 8317 | E11: USD mm | F11: 2023-01-01 | G11: 2023-12-31 | H11: us-gaap:NetIncomeLoss | I11: 10-K | J11: 2026-02-11 | K11: 0001283699-26-000010 | L11: T-Mobile US, Inc. Form 10-K / SEC Company Facts | M11: Primary — SEC filed | N11: 2026-07-16 | O11: https://data.sec.gov/api/xbrl/companyfacts/CIK0001283699.json | P11: Filed USD divided by 1,000,000; sign preserved | Q11: 2025 customer/revenue perimeter includes UScellular, Metronet and Lumos acquisitions; 2024 includes Ka'ena. Forecast cases normalize acquisition-heavy growth.
A12: SRC-008 | B12: Historical!D7 | C12: Net income | D12: 11339 | E12: USD mm | F12: 2024-01-01 | G12: 2024-12-31 | H12: us-gaap:NetIncomeLoss | I12: 10-K | J12: 2026-02-11 | K12: 0001283699-26-000010 | L12: T-Mobile US, Inc. Form 10-K / SEC Company Facts | M12: Primary — SEC filed | N12: 2026-07-16 | O12: https://data.sec.gov/api/xbrl/companyfacts/CIK0001283699.json | P12: Filed USD divided by 1,000,000; sign preserved | Q12: 2025 customer/revenue perimeter includes UScellular, Metronet and Lumos acquisitions; 2024 includes Ka'ena. Forecast cases normalize acquisition-heavy growth.
A13: SRC-009 | B13: Historical!E7 | C13: Net income | D13: 10992 | E13: USD mm | F13: 2025-01-01 | G13: 2025-12-31 | H13: us-gaap:NetIncomeLoss | I13: 10-K | J13: 2026-02-11 | K13: 0001283699-26-000010 | L13: T-Mobile US, Inc. Form 10-K / SEC Company Facts | M13: Primary — SEC filed | N13: 2026-07-16 | O13: https://data.sec.gov/api/xbrl/companyfacts/CIK0001283699.json | P13: Filed USD divided by 1,000,000; sign preserved | Q13: 2025 customer/revenue perimeter includes UScellular, Metronet and Lumos acquisitions; 2024 includes Ka'ena. Forecast cases normalize acquisition-heavy growth.
A14: SRC-010 | B14: Historical!C8 | C14: Cash from operations | D14: 18559 | E14: USD mm | F14: 2023-01-01 | G14: 2023-12-31 | H14: us-gaap:NetCashProvidedByUsedInOperatingActivities | I14: 10-K | J14: 2026-02-11 | K14: 0001283699-26-000010 | L14: T-Mobile US, Inc. Form 10-K / SEC Company Facts | M14: Primary — SEC filed | N14: 2026-07-16 | O14: https://data.sec.gov/api/xbrl/companyfacts/CIK0001283699.json | P14: Filed USD divided by 1,000,000; sign preserved | Q14: 2025 customer/revenue perimeter includes UScellular, Metronet and Lumos acquisitions; 2024 includes Ka'ena. Forecast cases normalize acquisition-heavy growth.
A15: SRC-011 | B15: Historical!D8 | C15: Cash from operations | D15: 22293 | E15: USD mm | F15: 2024-01-01 | G15: 2024-12-31 | H15: us-gaap:NetCashProvidedByUsedInOperatingActivities | I15: 10-K | J15: 2026-02-11 | K15: 0001283699-26-000010 | L15: T-Mobile US, Inc. Form 10-K / SEC Company Facts | M15: Primary — SEC filed | N15: 2026-07-16 | O15: https://data.sec.gov/api/xbrl/companyfacts/CIK0001283699.json | P15: Filed USD divided by 1,000,000; sign preserved | Q15: 2025 customer/revenue perimeter includes UScellular, Metronet and Lumos acquisitions; 2024 includes Ka'ena. Forecast cases normalize acquisition-heavy growth.
A16: SRC-012 | B16: Historical!E8 | C16: Cash from operations | D16: 27950 | E16: USD mm | F16: 2025-01-01 | G16: 2025-12-31 | H16: us-gaap:NetCashProvidedByUsedInOperatingActivities | I16: 10-K | J16: 2026-02-11 | K16: 0001283699-26-000010 | L16: T-Mobile US, Inc. Form 10-K / SEC Company Facts | M16: Primary — SEC filed | N16: 2026-07-16 | O16: https://data.sec.gov/api/xbrl/companyfacts/CIK0001283699.json | P16: Filed USD divided by 1,000,000; sign preserved | Q16: 2025 customer/revenue perimeter includes UScellular, Metronet and Lumos acquisitions; 2024 includes Ka'ena. Forecast cases normalize acquisition-heavy growth.
... A100: SRC-096 | B100: Sector_KPIs!E18 | C100: Adjusted EBITDA 2025 | D100: 33937 | E100: USD mm | F100: N/A | G100: 2025-12-31 | H100: MD&A — Selected financial data / Non-GAAP Financial Measures — row: Adjusted EBITDA — column 2025 | I100: 10-K | J100: 2026-02-11 | K100: 0001283699-26-000010 | L100: T-Mobile US, Inc. 2025 Form 10-K | M100: Primary — SEC filed | N100: 2026-07-16 | O100: https://www.sec.gov/Archives/edgar/data/1283699/000128369926000010/tmus-20251231.htm | P100: Transcribed from filed table; USD values in millions unless stated | Q100: 2025 customer/revenue perimeter includes UScellular, Metronet and Lumos acquisitions; 2024 includes Ka'ena. Forecast cases normalize acquisition-heavy growth.
A101: SRC-097 | B101: Historical / Valuation | C101: Debt definition | D101: LongTermDebt + ShortTermBorrowings + FinanceLeaseLiability; all carrying values, USD mm. | E101: Policy | F101: N/A | G101: 2025-12-31 | H101: Accounting policy | I101: 10-K | J101: 2026-02-11 | K101: 0001283699-26-000010 | L101: T-Mobile US, Inc. 2025 Form 10-K | M101: Primary — SEC filed | N101: 2026-07-16 | O101: https://www.sec.gov/Archives/edgar/data/1283699/000128369926000010/tmus-20251231.htm | P101: Explicit sum of filed debt components | Q101: Net debt deducts cash and cash equivalents only; restricted cash and non-operating investments are excluded.
A102: SRC-098 | B102: Entire model | C102: Acquisition / perimeter note | D102: 2025 customer/revenue perimeter includes UScellular, Metronet and Lumos acquisitions; 2024 includes Ka'ena. Forecast cases normalize acquisition-heavy growth. | E102: Policy | F102: N/A | G102: 2025-12-31 | H102: Perimeter policy | I102: 10-K | J102: 2026-02-11 | K102: 0001283699-26-000010 | L102: T-Mobile US, Inc. 2025 Form 10-K | M102: Primary — SEC filed | N102: 2026-07-16 | O102: https://www.sec.gov/Archives/edgar/data/1283699/000128369926000010/tmus-20251231.htm | P102: No current-FX restatement; filed values preserved | Q102: Reported postpaid ARPA is per account while churn is postpaid phone churn; the driver model therefore uses phone customers/ARPU for phone service revenue and treats other postpaid revenue separately.

Sheet Historical
A1: TMUS | Historical Financials | B1: TMUS | Historical Financials | C1: TMUS | Historical Financials | D1: TMUS | Historical Financials | E1: TMUS | Historical Financials | F1: TMUS | Historical Financials | G1: TMUS | Historical Financials | H1: TMUS | Historical Financials | I1: TMUS | Historical Financials
A2: Filed values and explicit debt bridge. USD in millions except per-share and share-count data. | B2: Filed values and explicit debt bridge. USD in millions except per-share and share-count data. | C2: Filed values and explicit debt bridge. USD in millions except per-share and share-count data. | D2: Filed values and explicit debt bridge. USD in millions except per-share and share-count data. | E2: Filed values and explicit debt bridge. USD in millions except per-share and share-count data. | F2: Filed values and explicit debt bridge. USD in millions except per-share and share-count data. | G2: Filed values and explicit debt bridge. USD in millions except per-share and share-count data. | H2: Filed values and explicit debt bridge. USD in millions except per-share and share-count data. | I2: Filed values and explicit debt bridge. USD in millions except per-share and share-count data.
A4: Metric | B4: Units | C4: 2023A | D4: 2024A | E4: 2025A | F4: Source definition | G4: Source IDs | H4: Policy / transform | I4: Quality
A5: Revenue | B5: USD mm | C5: 78558 | D5: 81400 | E5: 88309 | F5: SEC Company Facts / filed 10-K; RevenueFromContractWithCustomerExcludingAssessedTax or Revenues or SalesRevenueNet | G5: SRC-001, SRC-002, SRC-003 | H5: Filed USD; no FX restatement; sign preserved. | I5: Filed
A6: Operating income (EBIT) | B6: USD mm | C6: 14266 | D6: 18010 | E6: 18279 | F6: SEC Company Facts / filed 10-K; OperatingIncomeLoss | G6: SRC-004, SRC-005, SRC-006 | H6: Filed USD; no FX restatement; sign preserved. | I6: Filed
A7: Net income | B7: USD mm | C7: 8317 | D7: 11339 | E7: 10992 | F7: SEC Company Facts / filed 10-K; NetIncomeLoss or ProfitLoss | G7: SRC-007, SRC-008, SRC-009 | H7: Filed USD; no FX restatement; sign preserved. | I7: Filed
A8: Cash from operations | B8: USD mm | C8: 18559 | D8: 22293 | E8: 27950 | F8: SEC Company Facts / filed 10-K; NetCashProvidedByUsedInOperatingActivities | G8: SRC-010, SRC-011, SRC-012 | H8: Filed USD; no FX restatement; sign preserved. | I8: Filed
A9: Depreciation & amortization | B9: USD mm | C9: 12818 | D9: 12919 | E9: 13508 | F9: SEC Company Facts / filed 10-K; DepreciationDepletionAndAmortization or DepreciationDepletionAndAmortization or DepreciationAndAmortization | G9: SRC-013, SRC-014, SRC-015 | H9: Filed USD; no FX restatement; sign preserved. | I9: Filed
A10: Cash capex / P&E additions | B10: USD mm | C10: 9801 | D10: 8840 | E10: 9955 | F10: SEC Company Facts / filed 10-K; PaymentsToAcquirePropertyPlantAndEquipment or PaymentsForAdditionsToPropertyPlantAndEquipment | G10: SRC-016, SRC-017, SRC-018 | H10: Filed USD; no FX restatement; sign preserved. | I10: Filed
A11: Total assets | B11: USD mm | C11: 207682 | D11: 208035 | E11: 219237 | F11: SEC Company Facts / filed 10-K; Assets | G11: SRC-019, SRC-020, SRC-021 | H11: Filed USD; no FX restatement; sign preserved. | I11: Filed
A12: Stockholders' equity | B12: USD mm | C12: 64715 | D12: 61741 | E12: 59203 | F12: SEC Company Facts / filed 10-K; StockholdersEquity or StockholdersEquityIncludingPortionAttributableToNoncontrollingInterest | G12: SRC-022, SRC-023, SRC-024 | H12: Filed USD; no FX restatement; sign preserved. | I12: Filed
A13: Cash & cash equivalents | B13: USD mm | C13: 5135 | D13: 5409 | E13: 5598 | F13: SEC Company Facts / filed 10-K; CashAndCashEquivalentsAtCarryingValue or CashCashEquivalentsRestrictedCashAndRestrictedCashEquivalents | G13: SRC-025, SRC-026, SRC-027 | H13: Filed USD; no FX restatement; sign preserved. | I13: Filed
A14: Long-term debt | B14: USD mm | C14: 75018 | D14: 78265 | E14: 86282 | F14: SEC Company Facts / filed 10-K; LongTermDebt or LongTermDebtAndCapitalLeaseObligationsIncludingCurrentMaturities | G14: SRC-028, SRC-029, SRC-030 | H14: LongTermDebt + ShortTermBorrowings + FinanceLeaseLiability; all carrying values, USD mm. | I14: Filed
A15: Short-term borrowings | B15: USD mm | C15: 3619 | D15: 4068 | E15: 5135 | F15: SEC Company Facts / filed 10-K; ShortTermBorrowings or CommercialPaper | G15: SRC-031, SRC-032, SRC-033 | H15: LongTermDebt + ShortTermBorrowings + FinanceLeaseLiability; all carrying values, USD mm. | I15: Filed
A16: Finance lease liability | B16: USD mm | C16: 2496 | D16: 2326 | E16: 2270 | F16: SEC Company Facts / filed 10-K; FinanceLeaseLiability | G16: SRC-034, SRC-035, SRC-036 | H16: LongTermDebt + ShortTermBorrowings + FinanceLeaseLiability; all carrying values, USD mm. | I16: Filed
A17: Diluted weighted-average shares | B17: mm shares | C17: 1200.2863 | D17: 1173.2139 | E17: 1131.0763 | F17: SEC Company Facts / filed 10-K; WeightedAverageNumberOfDilutedSharesOutstanding | G17: SRC-037, SRC-038, SRC-039 | H17: Filed USD; no FX restatement; sign preserved. | I17: Filed
A18: Total debt | B18: USD mm | C18: =C14+C15+C16 -> 81133 | D18: =D14+D15+D16 -> 84659 | E18: =E14+E15+E16 -> 93687 | F18: LongTermDebt + ShortTermBorrowings + FinanceLeaseLiability; all carrying values, USD mm. | G18: Formula | H18: LongTermDebt + ShortTermBorrowings + FinanceLeaseLiability; all carrying values, USD mm. | I18: Modeled
A19: Net debt | B19: USD mm | C19: =C18-C13 -> 75998 | D19: =D18-D13 -> 79250 | E19: =E18-E13 -> 88089 | F19: Total debt less cash and cash equivalents | G19: Formula | H19: Net debt deducts cash and cash equivalents only; restricted cash and non-operating investments are excluded. | I19: Modeled
A21: Debt policy | B21: LongTermDebt + ShortTermBorrowings + FinanceLeaseLiability; all carrying values, USD mm.
A22: Cash policy | B22: Net debt deducts cash and cash equivalents only; restricted cash and non-operating investments are excluded.
A23: Perimeter | B23: 2025 customer/revenue perimeter includes UScellular, Metronet and Lumos acquisitions; 2024 includes Ka'ena. Forecast cases normalize acquisition-heavy growth.

Sheet Assumptions
A1: TMUS | Scenario Assumptions | B1: TMUS | Scenario Assumptions | C1: TMUS | Scenario Assumptions | D1: TMUS | Scenario Assumptions | E1: TMUS | Scenario Assumptions | F1: TMUS | Scenario Assumptions | G1: TMUS | Scenario Assumptions
A2: Blue cells are inputs; green cells are links/formulas. Selector 1=Base, 2=Bull, 3=Bear. | B2: Blue cells are inputs; green cells are links/formulas. Selector 1=Base, 2=Bull, 3=Bear. | C2: Blue cells are inputs; green cells are links/formulas. Selector 1=Base, 2=Bull, 3=Bear. | D2: Blue cells are inputs; green cells are links/formulas. Selector 1=Base, 2=Bull, 3=Bear. | E2: Blue cells are inputs; green cells are links/formulas. Selector 1=Base, 2=Bull, 3=Bear. | F2: Blue cells are inputs; green cells are links/formulas. Selector 1=Base, 2=Bull, 3=Bear. | G2: Blue cells are inputs; green cells are links/formulas. Selector 1=Base, 2=Bull, 3=Bear.
A3: Scenario selector | B3: 1
A4: Active case | B4: =CHOOSE(B3,"Base","Bull","Bear") -> Base
A6: Driver | B6: Units | C6: Bear | D6: Base | E6: Bull | F6: Active | G6: Rationale / calibration
A7: Gross phone adds rate | B7: % / year | C7: 0.11 | D7: 0.135 | E7: 0.16 | F7: =CHOOSE($B$3,D7,E7,C7) -> 0.135 | G7: Gross-add assumption calibrated so churn produces normalized postpaid phone growth after 2025 acquisition effects.
A8: Postpaid phone churn | B8: % / month | C8: 0.0105 | D8: 0.0093 | E8: 0.0085 | F8: =CHOOSE($B$3,D8,E8,C8) -> 0.0093 | G8: 2025 reported churn was 0.93%; cases frame retention risk.
A9: Postpaid phone ARPU growth | B9: % / year | C9: 0 | D9: 0.02 | E9: 0.035 | F9: =CHOOSE($B$3,D9,E9,C9) -> 0.02 | G9: 2025 reported ARPU growth was 2%.
A10: Other postpaid service revenue growth | B10: % / year | C10: -0.01 | D10: 0.02 | E10: 0.04 | F10: =CHOOSE($B$3,D10,E10,C10) -> 0.02 | G10: Captures broadband, connected-device and fee revenue outside the phone ARPU proxy.
A11: Non-postpaid service revenue growth | B11: % / year | C11: -0.02 | D11: 0.01 | E11: 0.03 | F11: =CHOOSE($B$3,D11,E11,C11) -> 0.01 | G11: Prepaid plus wholesale/other service revenue case.
A12: Equipment/other revenue as % service revenue | B12: % | C12: 0.2 | D12: 0.22 | E12: 0.24 | F12: =CHOOSE($B$3,D12,E12,C12) -> 0.22 | G12: Anchored to 2025 equipment revenue and service revenue.
A13: Adjusted EBITDA margin on service revenue | B13: % | C13: 0.45 | D13: 0.48 | E13: 0.5 | F13: =CHOOSE($B$3,D13,E13,C13) -> 0.48 | G13: 2025 reported Adjusted EBITDA margin was 48%.
A14: D&A as % total revenue | B14: % | C14: 0.15 | D14: 0.153 | E14: 0.155 | F14: =CHOOSE($B$3,D14,E14,C14) -> 0.153 | G14: Anchored to 2025 SEC D&A / revenue.
A15: Cash capex as % total revenue | B15: % | C15: 0.13 | D15: 0.113 | E15: 0.105 | F15: =CHOOSE($B$3,D15,E15,C15) -> 0.113 | G15: Anchored to 2025 cash purchases of P&E.
A16: Cash tax rate | B16: % | C16: 0.26 | D16: 0.24 | E16: 0.22 | F16: =CHOOSE($B$3,D16,E16,C16) -> 0.24 | G16: Normalized cash-tax assumption.
A17: NWC investment / change in revenue | B17: % | C17: 0.02 | D17: 0.01 | E17: 0.005 | F17: =CHOOSE($B$3,D17,E17,C17) -> 0.01 | G17: Working-capital sensitivity assumption.
A18: Annual net debt reduction | B18: % | C18: 0.02 | D18: 0.05 | E18: 0.08 | F18: =CHOOSE($B$3,D18,E18,C18) -> 0.05 | G18: Visible leverage-path assumption; no residual cash plug.
... A21: Exit EV / Adjusted EBITDA | B21: x | C21: 6.5 | D21: 7 | E21: 7.5 | F21: =CHOOSE($B$3,D21,E21,C21) -> 7 | G21: Telecom DCF cross-check multiple.
A23: Debt definition | B23: LongTermDebt + ShortTermBorrowings + FinanceLeaseLiability; all carrying values, USD mm.
A24: Cash policy | B24: Net debt deducts cash and cash equivalents only; restricted cash and non-operating investments are excluded.
A25: Known limitation | B25: Reported postpaid ARPA is per account while churn is postpaid phone churn; the driver model therefore uses phone customers/ARPU for phone service revenue and treats other postpaid revenue separately.

Sheet Forecast
A1: TMUS | Integrated Forecast | B1: TMUS | Integrated Forecast | C1: TMUS | Integrated Forecast | D1: TMUS | Integrated Forecast | E1: TMUS | Integrated Forecast | F1: TMUS | Integrated Forecast | G1: TMUS | Integrated Forecast
A2: Operating drivers flow from Sector_KPIs into FCFF and DCF valuation. | B2: Operating drivers flow from Sector_KPIs into FCFF and DCF valuation. | C2: Operating drivers flow from Sector_KPIs into FCFF and DCF valuation. | D2: Operating drivers flow from Sector_KPIs into FCFF and DCF valuation. | E2: Operating drivers flow from Sector_KPIs into FCFF and DCF valuation. | F2: Operating drivers flow from Sector_KPIs into FCFF and DCF valuation. | G2: Operating drivers flow from Sector_KPIs into FCFF and DCF valuation.
A4: Metric | B4: Units | C4: 2026E | D4: 2027E | E4: 2028E | F4: 2029E | G4: 2030E
A5: Revenue | B5: USD mm | C5: =Sector_KPIs!F16 -> 89323.279 | D5: =Sector_KPIs!G16 -> 92499.571 | E5: =Sector_KPIs!H16 -> 95805.938 | F5: =Sector_KPIs!I16 -> 99247.958 | G5: =Sector_KPIs!J16 -> 102831.45
A6: Adjusted EBITDA | B6: USD mm | C6: =Sector_KPIs!F18 -> 35143.585 | D6: =Sector_KPIs!G18 -> 36393.274 | E6: =Sector_KPIs!H18 -> 37694.139 | F6: =Sector_KPIs!I18 -> 39048.377 | G6: =Sector_KPIs!J18 -> 40458.275
A7: Depreciation & amortization | B7: USD mm | C7: =C5*Assumptions!$F$14 -> 13666.462 | D7: =D5*Assumptions!$F$14 -> 14152.434 | E7: =E5*Assumptions!$F$14 -> 14658.308 | F7: =F5*Assumptions!$F$14 -> 15184.938 | G7: =G5*Assumptions!$F$14 -> 15733.212
A8: EBIT | B8: USD mm | C8: =C6-C7 -> 21477.124 | D8: =D6-D7 -> 22240.839 | E8: =E6-E7 -> 23035.831 | F8: =F6-F7 -> 23863.439 | G8: =G6-G7 -> 24725.064
A9: Cash taxes | B9: USD mm | C9: =MAX(0,C8*Assumptions!$F$16) -> 5154.5097 | D9: =MAX(0,D8*Assumptions!$F$16) -> 5337.8014 | E9: =MAX(0,E8*Assumptions!$F$16) -> 5528.5994 | F9: =MAX(0,F8*Assumptions!$F$16) -> 5727.2254 | G9: =MAX(0,G8*Assumptions!$F$16) -> 5934.0153
A10: NOPAT | B10: USD mm | C10: =C8-C9 -> 16322.614 | D10: =D8-D9 -> 16903.038 | E10: =E8-E9 -> 17507.232 | F10: =F8-F9 -> 18136.214 | G10: =G8-G9 -> 18791.048
A11: D&A add-back | B11: USD mm | C11: =C7 -> 13666.462 | D11: =D7 -> 14152.434 | E11: =E7 -> 14658.308 | F11: =F7 -> 15184.938 | G11: =G7 -> 15733.212
A12: Capital expenditures | B12: USD mm | C12: =Sector_KPIs!F19 -> 10093.531 | D12: =Sector_KPIs!G19 -> 10452.451 | E12: =Sector_KPIs!H19 -> 10826.071 | F12: =Sector_KPIs!I19 -> 11215.019 | G12: =Sector_KPIs!J19 -> 11619.954
A13: Change in net working capital | B13: USD mm | C13: =MAX(0,(Sector_KPIs!F16-Sector_KPIs!E16)*Assumptions!$F$17) -> 10.142792 | D13: =MAX(0,(Sector_KPIs!G16-Sector_KPIs!F16)*Assumptions!$F$17) -> 31.762913 | E13: =MAX(0,(Sector_KPIs!H16-Sector_KPIs!G16)*Assumptions!$F$17) -> 33.063673 | F13: =MAX(0,(Sector_KPIs!I16-Sector_KPIs!H16)*Assumptions!$F$17) -> 34.4202 | G13: =MAX(0,(Sector_KPIs!J16-Sector_KPIs!I16)*Assumptions!$F$17) -> 35.834921
A14: FCFF | B14: USD mm | C14: =C10+C11-C12-C13 -> 19885.402 | D14: =D10+D11-D12-D13 -> 20571.258 | E14: =E10+E11-E12-E13 -> 21306.405 | F14: =F10+F11-F12-F13 -> 22071.712 | G14: =G10+G11-G12-G13 -> 22868.471
A15: FCFF margin | B15: % | C15: =IFERROR(C14/C5,0) -> 0.22262284 | D15: =IFERROR(D14/D5,0) -> 0.22239301 | E15: =IFERROR(E14/E5,0) -> 0.22239128 | F15: =IFERROR(F14/F5,0) -> 0.22238958 | G15: =IFERROR(G14/G5,0) -> 0.22238791
A18: FCFF is derived from operating drivers, normalized cash taxes, explicit capex and a revenue-linked NWC assumption. | B18: FCFF is derived from operating drivers, normalized cash taxes, explicit capex and a revenue-linked NWC assumption. | C18: FCFF is derived from operating drivers, normalized cash taxes, explicit capex and a revenue-linked NWC assumption. | D18: FCFF is derived from operating drivers, normalized cash taxes, explicit capex and a revenue-linked NWC assumption. | E18: FCFF is derived from operating drivers, normalized cash taxes, explicit capex and a revenue-linked NWC assumption. | F18: FCFF is derived from operating drivers, normalized cash taxes, explicit capex and a revenue-linked NWC assumption. | G18: FCFF is derived from operating drivers, normalized cash taxes, explicit capex and a revenue-linked NWC assumption.

Sheet Valuation
A1: TMUS | DCF Valuation | B1: TMUS | DCF Valuation | C1: TMUS | DCF Valuation | D1: TMUS | DCF Valuation | E1: TMUS | DCF Valuation | F1: TMUS | DCF Valuation | G1: TMUS | DCF Valuation
A2: Primary method: unlevered FCFF DCF. Exit EV / Adjusted EBITDA is an explicit cross-check. | B2: Primary method: unlevered FCFF DCF. Exit EV / Adjusted EBITDA is an explicit cross-check. | C2: Primary method: unlevered FCFF DCF. Exit EV / Adjusted EBITDA is an explicit cross-check. | D2: Primary method: unlevered FCFF DCF. Exit EV / Adjusted EBITDA is an explicit cross-check. | E2: Primary method: unlevered FCFF DCF. Exit EV / Adjusted EBITDA is an explicit cross-check. | F2: Primary method: unlevered FCFF DCF. Exit EV / Adjusted EBITDA is an explicit cross-check. | G2: Primary method: unlevered FCFF DCF. Exit EV / Adjusted EBITDA is an explicit cross-check.
A4: Metric | B4: Units | C4: 2026E | D4: 2027E | E4: 2028E | F4: 2029E | G4: 2030E
A5: FCFF | B5: USD mm | C5: =Forecast!C14 -> 19885.402 | D5: =Forecast!D14 -> 20571.258 | E5: =Forecast!E14 -> 21306.405 | F5: =Forecast!F14 -> 22071.712 | G5: =Forecast!G14 -> 22868.471
A6: Discount period | B6: years | C6: 1 | D6: 2 | E6: 3 | F6: 4 | G6: 5
A7: Discount factor | B7: x | C7: =1/(1+Assumptions!$F$19)^C6 -> 0.91324201 | D7: =1/(1+Assumptions!$F$19)^D6 -> 0.83401097 | E7: =1/(1+Assumptions!$F$19)^E6 -> 0.76165385 | F7: =1/(1+Assumptions!$F$19)^F6 -> 0.69557429 | G7: =1/(1+Assumptions!$F$19)^G6 -> 0.63522767
A8: PV of FCFF | B8: USD mm | C8: =C5*C7 -> 18160.185 | D8: =D5*D7 -> 17156.655 | E8: =E5*E7 -> 16228.106 | F8: =F5*F7 -> 15352.515 | G8: =G5*G7 -> 14526.686
A11: WACC | B11: =Assumptions!$F$19 -> 0.095
A12: Terminal growth | B12: =Assumptions!$F$20 -> 0.025
A13: Terminal value | B13: =IFERROR(G5*(1+B12)/(B11-B12),0) -> 334859.76
A14: PV of terminal value | B14: =B13*G7 -> 212712.18
A15: Enterprise value | B15: =SUM(C8:G8)+B14 -> 294136.33
A16: Cash & cash equivalents | B16: =Historical!E13 -> 5598
A17: Total debt | B17: =Historical!E18 -> 93687
A18: Equity value | B18: =MAX(0,B15+B16-B17) -> 206047.33
A19: Diluted weighted-average shares | B19: =Historical!E17 -> 1131.0763
A20: DCF value / share | B20: =IFERROR(B18/B19,0) -> 182.16927
A21: Market-price comparison | B21: Omitted
A22: Reason | B22: No independently refreshed exact-dated quote was obtained in the controlled owner lane.
A23: 2030E Adjusted EBITDA | B23: =Sector_KPIs!J18 -> 40458.275
A24: Exit-multiple enterprise value | B24: =B23*Assumptions!$F$21 -> 283207.93
A25: Exit-multiple value / share | B25: =IFERROR(MAX(0,B24+B16-B17)/B19,0) -> 172.50732
A29: Valuation date / horizon | B29: Filed FY2025 actuals with an explicit 2026E-2030E forecast; terminal value is measured at 2030E and discounted to the valuation date.
A30: Debt / cash policy | B30: LongTermDebt + ShortTermBorrowings + FinanceLeaseLiability; all carrying values, USD mm. Net debt deducts cash and cash equivalents only; restricted cash and non-operating investments are excluded.
A31: Share-count basis | B31: Per-share valuation uses FY2025 diluted weighted-average shares; this is a period-average share count, not a point-in-time shares-outstanding quote.

Sheet Sensitivity
A1: TMUS | DCF Sensitivity | B1: TMUS | DCF Sensitivity | C1: TMUS | DCF Sensitivity | D1: TMUS | DCF Sensitivity | E1: TMUS | DCF Sensitivity | F1: TMUS | DCF Sensitivity | G1: TMUS | DCF Sensitivity | H1: TMUS | DCF Sensitivity
A2: Equity value per share across WACC and terminal-growth assumptions. Center cell equals the active DCF case. | B2: Equity value per share across WACC and terminal-growth assumptions. Center cell equals the active DCF case. | C2: Equity value per share across WACC and terminal-growth assumptions. Center cell equals the active DCF case. | D2: Equity value per share across WACC and terminal-growth assumptions. Center cell equals the active DCF case. | E2: Equity value per share across WACC and terminal-growth assumptions. Center cell equals the active DCF case. | F2: Equity value per share across WACC and terminal-growth assumptions. Center cell equals the active DCF case. | G2: Equity value per share across WACC and terminal-growth assumptions. Center cell equals the active DCF case. | H2: Equity value per share across WACC and terminal-growth assumptions. Center cell equals the active DCF case.
A4: Terminal growth → / WACC ↓ | B4: =Assumptions!$F$20+-0.01 -> 0.015 | C4: =Assumptions!$F$20+-0.005 -> 0.02 | D4: =Assumptions!$F$20+0 -> 0.025 | E4: =Assumptions!$F$20+0.005 -> 0.03 | F4: =Assumptions!$F$20+0.01 -> 0.035 | G4: Base DCF / share | H4: =Valuation!B20 -> 182.16927
A5: =Assumptions!$F$19+0.02 -> 0.115 | B5: =IFERROR(MAX(0,Forecast!C14/(1+$A5)+Forecast!D14/(1+$A5)^2+Forecast!E14/(1+$A5)^3+Forecast!F14/(1+$A5)^4+Forecast!G14/(1+$A5)^5+Forecast!G14*(1+B$4)/($A5-B$4)/(1+$A5)^5+Historical!E13-Historical!E18)/Historical!E17,0) -> 109.54217 | C5: =IFERROR(MAX(0,Forecast!C14/(1+$A5)+Forecast!D14/(1+$A5)^2+Forecast!E14/(1+$A5)^3+Forecast!F14/(1+$A5)^4+Forecast!G14/(1+$A5)^5+Forecast!G14*(1+C$4)/($A5-C$4)/(1+$A5)^5+Historical!E13-Historical!E18)/Historical!E17,0) -> 116.42699 | D5: =IFERROR(MAX(0,Forecast!C14/(1+$A5)+Forecast!D14/(1+$A5)^2+Forecast!E14/(1+$A5)^3+Forecast!F14/(1+$A5)^4+Forecast!G14/(1+$A5)^5+Forecast!G14*(1+D$4)/($A5-D$4)/(1+$A5)^5+Historical!E13-Historical!E18)/Historical!E17,0) -> 124.07678 | E5: =IFERROR(MAX(0,Forecast!C14/(1+$A5)+Forecast!D14/(1+$A5)^2+Forecast!E14/(1+$A5)^3+Forecast!F14/(1+$A5)^4+Forecast!G14/(1+$A5)^5+Forecast!G14*(1+E$4)/($A5-E$4)/(1+$A5)^5+Historical!E13-Historical!E18)/Historical!E17,0) -> 132.62655 | F5: =IFERROR(MAX(0,Forecast!C14/(1+$A5)+Forecast!D14/(1+$A5)^2+Forecast!E14/(1+$A5)^3+Forecast!F14/(1+$A5)^4+Forecast!G14/(1+$A5)^5+Forecast!G14*(1+F$4)/($A5-F$4)/(1+$A5)^5+Historical!E13-Historical!E18)/Historical!E17,0) -> 142.24504
A6: =Assumptions!$F$19+0.01 -> 0.105 | B6: =IFERROR(MAX(0,Forecast!C14/(1+$A6)+Forecast!D14/(1+$A6)^2+Forecast!E14/(1+$A6)^3+Forecast!F14/(1+$A6)^4+Forecast!G14/(1+$A6)^5+Forecast!G14*(1+B$4)/($A6-B$4)/(1+$A6)^5+Historical!E13-Historical!E18)/Historical!E17,0) -> 130.65426 | C6: =IFERROR(MAX(0,Forecast!C14/(1+$A6)+Forecast!D14/(1+$A6)^2+Forecast!E14/(1+$A6)^3+Forecast!F14/(1+$A6)^4+Forecast!G14/(1+$A6)^5+Forecast!G14*(1+C$4)/($A6-C$4)/(1+$A6)^5+Historical!E13-Historical!E18)/Historical!E17,0) -> 139.51775 | D6: =IFERROR(MAX(0,Forecast!C14/(1+$A6)+Forecast!D14/(1+$A6)^2+Forecast!E14/(1+$A6)^3+Forecast!F14/(1+$A6)^4+Forecast!G14/(1+$A6)^5+Forecast!G14*(1+D$4)/($A6-D$4)/(1+$A6)^5+Historical!E13-Historical!E18)/Historical!E17,0) -> 149.48917 | E6: =IFERROR(MAX(0,Forecast!C14/(1+$A6)+Forecast!D14/(1+$A6)^2+Forecast!E14/(1+$A6)^3+Forecast!F14/(1+$A6)^4+Forecast!G14/(1+$A6)^5+Forecast!G14*(1+E$4)/($A6-E$4)/(1+$A6)^5+Historical!E13-Historical!E18)/Historical!E17,0) -> 160.79012 | F6: =IFERROR(MAX(0,Forecast!C14/(1+$A6)+Forecast!D14/(1+$A6)^2+Forecast!E14/(1+$A6)^3+Forecast!F14/(1+$A6)^4+Forecast!G14/(1+$A6)^5+Forecast!G14*(1+F$4)/($A6-F$4)/(1+$A6)^5+Historical!E13-Historical!E18)/Historical!E17,0) -> 173.70549
A7: =Assumptions!$F$19+0 -> 0.095 | B7: =IFERROR(MAX(0,Forecast!C14/(1+$A7)+Forecast!D14/(1+$A7)^2+Forecast!E14/(1+$A7)^3+Forecast!F14/(1+$A7)^4+Forecast!G14/(1+$A7)^5+Forecast!G14*(1+B$4)/($A7-B$4)/(1+$A7)^5+Historical!E13-Historical!E18)/Historical!E17,0) -> 157.05614 | C7: =IFERROR(MAX(0,Forecast!C14/(1+$A7)+Forecast!D14/(1+$A7)^2+Forecast!E14/(1+$A7)^3+Forecast!F14/(1+$A7)^4+Forecast!G14/(1+$A7)^5+Forecast!G14*(1+C$4)/($A7-C$4)/(1+$A7)^5+Historical!E13-Historical!E18)/Historical!E17,0) -> 168.7756 | D7: =IFERROR(MAX(0,Forecast!C14/(1+$A7)+Forecast!D14/(1+$A7)^2+Forecast!E14/(1+$A7)^3+Forecast!F14/(1+$A7)^4+Forecast!G14/(1+$A7)^5+Forecast!G14*(1+D$4)/($A7-D$4)/(1+$A7)^5+Historical!E13-Historical!E18)/Historical!E17,0) -> 182.16927 | E7: =IFERROR(MAX(0,Forecast!C14/(1+$A7)+Forecast!D14/(1+$A7)^2+Forecast!E14/(1+$A7)^3+Forecast!F14/(1+$A7)^4+Forecast!G14/(1+$A7)^5+Forecast!G14*(1+E$4)/($A7-E$4)/(1+$A7)^5+Historical!E13-Historical!E18)/Historical!E17,0) -> 197.6235 | F7: =IFERROR(MAX(0,Forecast!C14/(1+$A7)+Forecast!D14/(1+$A7)^2+Forecast!E14/(1+$A7)^3+Forecast!F14/(1+$A7)^4+Forecast!G14/(1+$A7)^5+Forecast!G14*(1+F$4)/($A7-F$4)/(1+$A7)^5+Historical!E13-Historical!E18)/Historical!E17,0) -> 215.65343
A8: =Assumptions!$F$19+-0.01 -> 0.085 | B8: =IFERROR(MAX(0,Forecast!C14/(1+$A8)+Forecast!D14/(1+$A8)^2+Forecast!E14/(1+$A8)^3+Forecast!F14/(1+$A8)^4+Forecast!G14/(1+$A8)^5+Forecast!G14*(1+B$4)/($A8-B$4)/(1+$A8)^5+Historical!E13-Historical!E18)/Historical!E17,0) -> 191.01553 | C8: =IFERROR(MAX(0,Forecast!C14/(1+$A8)+Forecast!D14/(1+$A8)^2+Forecast!E14/(1+$A8)^3+Forecast!F14/(1+$A8)^4+Forecast!G14/(1+$A8)^5+Forecast!G14*(1+C$4)/($A8-C$4)/(1+$A8)^5+Historical!E13-Historical!E18)/Historical!E17,0) -> 207.04743 | D8: =IFERROR(MAX(0,Forecast!C14/(1+$A8)+Forecast!D14/(1+$A8)^2+Forecast!E14/(1+$A8)^3+Forecast!F14/(1+$A8)^4+Forecast!G14/(1+$A8)^5+Forecast!G14*(1+D$4)/($A8-D$4)/(1+$A8)^5+Historical!E13-Historical!E18)/Historical!E17,0) -> 225.75131 | E8: =IFERROR(MAX(0,Forecast!C14/(1+$A8)+Forecast!D14/(1+$A8)^2+Forecast!E14/(1+$A8)^3+Forecast!F14/(1+$A8)^4+Forecast!G14/(1+$A8)^5+Forecast!G14*(1+E$4)/($A8-E$4)/(1+$A8)^5+Historical!E13-Historical!E18)/Historical!E17,0) -> 247.85589 | F8: =IFERROR(MAX(0,Forecast!C14/(1+$A8)+Forecast!D14/(1+$A8)^2+Forecast!E14/(1+$A8)^3+Forecast!F14/(1+$A8)^4+Forecast!G14/(1+$A8)^5+Forecast!G14*(1+F$4)/($A8-F$4)/(1+$A8)^5+Historical!E13-Historical!E18)/Historical!E17,0) -> 274.38139
A9: =Assumptions!$F$19+-0.02 -> 0.075 | B9: =IFERROR(MAX(0,Forecast!C14/(1+$A9)+Forecast!D14/(1+$A9)^2+Forecast!E14/(1+$A9)^3+Forecast!F14/(1+$A9)^4+Forecast!G14/(1+$A9)^5+Forecast!G14*(1+B$4)/($A9-B$4)/(1+$A9)^5+Historical!E13-Historical!E18)/Historical!E17,0) -> 236.31199 | C9: =IFERROR(MAX(0,Forecast!C14/(1+$A9)+Forecast!D14/(1+$A9)^2+Forecast!E14/(1+$A9)^3+Forecast!F14/(1+$A9)^4+Forecast!G14/(1+$A9)^5+Forecast!G14*(1+C$4)/($A9-C$4)/(1+$A9)^5+Historical!E13-Historical!E18)/Historical!E17,0) -> 259.25062 | D9: =IFERROR(MAX(0,Forecast!C14/(1+$A9)+Forecast!D14/(1+$A9)^2+Forecast!E14/(1+$A9)^3+Forecast!F14/(1+$A9)^4+Forecast!G14/(1+$A9)^5+Forecast!G14*(1+D$4)/($A9-D$4)/(1+$A9)^5+Historical!E13-Historical!E18)/Historical!E17,0) -> 286.77697 | E9: =IFERROR(MAX(0,Forecast!C14/(1+$A9)+Forecast!D14/(1+$A9)^2+Forecast!E14/(1+$A9)^3+Forecast!F14/(1+$A9)^4+Forecast!G14/(1+$A9)^5+Forecast!G14*(1+E$4)/($A9-E$4)/(1+$A9)^5+Historical!E13-Historical!E18)/Historical!E17,0) -> 320.4203 | F9: =IFERROR(MAX(0,Forecast!C14/(1+$A9)+Forecast!D14/(1+$A9)^2+Forecast!E14/(1+$A9)^3+Forecast!F14/(1+$A9)^4+Forecast!G14/(1+$A9)^5+Forecast!G14*(1+F$4)/($A9-F$4)/(1+$A9)^5+Historical!E13-Historical!E18)/Historical!E17,0) -> 362.47445

Sheet Checks
A1: TMUS | Formula-Driven Model Checks | B1: TMUS | Formula-Driven Model Checks | C1: TMUS | Formula-Driven Model Checks | D1: TMUS | Formula-Driven Model Checks | E1: TMUS | Formula-Driven Model Checks | F1: TMUS | Formula-Driven Model Checks | G1: TMUS | Formula-Driven Model Checks | H1: TMUS | Formula-Driven Model Checks
A2: Overall status is aggregated from check-row formulas. No check status is hardcoded. | B2: Overall status is aggregated from check-row formulas. No check status is hardcoded. | C2: Overall status is aggregated from check-row formulas. No check status is hardcoded. | D2: Overall status is aggregated from check-row formulas. No check status is hardcoded. | E2: Overall status is aggregated from check-row formulas. No check status is hardcoded. | F2: Overall status is aggregated from check-row formulas. No check status is hardcoded. | G2: Overall status is aggregated from check-row formulas. No check status is hardcoded. | H2: Overall status is aggregated from check-row formulas. No check status is hardcoded.
A3: Model as of | B3: 2025-12-31
A4: Overall model status | B4: =IF(COUNTIF(G7:G16,"<>PASS")=0,"PASS","REMEDIATE") -> PASS
A6: Check ID | B6: Category | C6: Actual | D6: Expected | E6: Difference | F6: Tolerance | G6: Status | H6: Evidence / fix hint
A7: C01 | B7: Source ledger exact URLs | C7: =COUNTBLANK(Sources!O5:O102) -> 0 | D7: 0 | E7: =C7-D7 -> 0 | F7: 0.01 | G7: =IF(ABS(E7)<=F7,"PASS","FAIL") -> PASS | H7: All material rows require an exact URL.
A8: C02 | B8: Source ledger accession field complete | C8: =COUNTBLANK(Sources!K5:K102) -> 0 | D8: 0 | E8: =C8-D8 -> 0 | F8: 0.01 | G8: =IF(ABS(E8)<=F8,"PASS","FAIL") -> PASS | H8: Every source row must carry a filed accession or an explicit N/A.
A9: C03 | B9: Debt bridge | C9: =Historical!E18-SUM(Historical!E14:E16) -> 0 | D9: 0 | E9: =C9-D9 -> 0 | F9: 0.01 | G9: =IF(ABS(E9)<=F9,"PASS","FAIL") -> PASS | H9: LongTermDebt + ShortTermBorrowings + FinanceLeaseLiability; all carrying values, USD mm.
A10: C04 | B10: Net debt bridge | C10: =Historical!E19-(Historical!E18-Historical!E13) -> 0 | D10: 0 | E10: =C10-D10 -> 0 | F10: 0.01 | G10: =IF(ABS(E10)<=F10,"PASS","FAIL") -> PASS | H10: Net debt deducts cash and cash equivalents only; restricted cash and non-operating investments are excluded.
A11: C05 | B11: Operating model historical revenue tie | C11: =Sector_KPIs!E16-Historical!E5 -> 0 | D11: 0 | E11: =C11-D11 -> 0 | F11: 0.01 | G11: =IF(ABS(E11)<=F11,"PASS","FAIL") -> PASS | H11: 2025 operating schedule revenue must equal filed revenue.
A12: C06 | B12: Forecast operating link | C12: =Forecast!C5-Sector_KPIs!F16 -> 0 | D12: 0 | E12: =C12-D12 -> 0 | F12: 0.01 | G12: =IF(ABS(E12)<=F12,"PASS","FAIL") -> PASS | H12: 2026E revenue must flow from the operating model.
A13: C07 | B13: Scenario selector | C13: =IF(AND(Assumptions!B3>=1,Assumptions!B3<=3),1,0) -> 1 | D13: 1 | E13: =C13-D13 -> 0 | F13: 0.01 | G13: =IF(ABS(E13)<=F13,"PASS","FAIL") -> PASS | H13: Selector must be 1, 2 or 3.
A14: C08 | B14: Share count positive | C14: =IF(Historical!E17>0,1,0) -> 1 | D14: 1 | E14: =C14-D14 -> 0 | F14: 0.01 | G14: =IF(ABS(E14)<=F14,"PASS","FAIL") -> PASS | H14: Per-share valuation requires a positive share count.
A15: C09 | B15: Sensitivity center reconciliation | C15: =Sensitivity!D7-Valuation!B20 -> 0 | D15: 0 | E15: =C15-D15 -> 0 | F15: 0.01 | G15: =IF(ABS(E15)<=F15,"PASS","FAIL") -> PASS | H15: Center sensitivity cell must equal the active valuation.
A16: C10 | B16: Valuation finite / non-negative | C16: =IF(AND(ISNUMBER(Valuation!B20),Valuation!B20>=0),1,0) -> 1 | D16: 1 | E16: =C16-D16 -> 0 | F16: 0.01 | G16: =IF(ABS(E16)<=F16,"PASS","FAIL") -> PASS | H16: Primary equity value per share must be finite and non-negative; equity is floored at zero in downside cases.

Sheet Sector_KPIs
A1: TMUS | Subscriber-to-Cash-Flow Operating Model | B1: TMUS | Subscriber-to-Cash-Flow Operating Model | C1: TMUS | Subscriber-to-Cash-Flow Operating Model | D1: TMUS | Subscriber-to-Cash-Flow Operating Model | E1: TMUS | Subscriber-to-Cash-Flow Operating Model | F1: TMUS | Subscriber-to-Cash-Flow Operating Model | G1: TMUS | Subscriber-to-Cash-Flow Operating Model | H1: TMUS | Subscriber-to-Cash-Flow Operating Model | I1: TMUS | Subscriber-to-Cash-Flow Operating Model | J1: TMUS | Subscriber-to-Cash-Flow Operating Model
A2: Phone customers and ARPU drive phone service revenue; other service revenue is modeled separately to avoid ARPA/customer-unit mismatch. | B2: Phone customers and ARPU drive phone service revenue; other service revenue is modeled separately to avoid ARPA/customer-unit mismatch. | C2: Phone customers and ARPU drive phone service revenue; other service revenue is modeled separately to avoid ARPA/customer-unit mismatch. | D2: Phone customers and ARPU drive phone service revenue; other service revenue is modeled separately to avoid ARPA/customer-unit mismatch. | E2: Phone customers and ARPU drive phone service revenue; other service revenue is modeled separately to avoid ARPA/customer-unit mismatch. | F2: Phone customers and ARPU drive phone service revenue; other service revenue is modeled separately to avoid ARPA/customer-unit mismatch. | G2: Phone customers and ARPU drive phone service revenue; other service revenue is modeled separately to avoid ARPA/customer-unit mismatch. | H2: Phone customers and ARPU drive phone service revenue; other service revenue is modeled separately to avoid ARPA/customer-unit mismatch. | I2: Phone customers and ARPU drive phone service revenue; other service revenue is modeled separately to avoid ARPA/customer-unit mismatch. | J2: Phone customers and ARPU drive phone service revenue; other service revenue is modeled separately to avoid ARPA/customer-unit mismatch.
A4: Metric | B4: Units | C4: 2023A | D4: 2024A | E4: 2025A | F4: 2026E | G4: 2027E | H4: 2028E | I4: 2029E | J4: 2030E
A5: Postpaid phone customers | B5: mm | C5: 75.936 | D5: 79.013 | E5: 85.594 | F5: =E5*(1+F8) -> 87.5969 | G5: =F5*(1+G8) -> 89.646667 | H5: =G5*(1+H8) -> 91.744399 | I5: =H5*(1+I8) -> 93.891218 | J5: =I5*(1+J8) -> 96.088272
A6: Gross phone adds rate (modeled) | B6: % / year | F6: =Assumptions!$F$7 -> 0.135 | G6: =Assumptions!$F$7 -> 0.135 | H6: =Assumptions!$F$7 -> 0.135 | I6: =Assumptions!$F$7 -> 0.135 | J6: =Assumptions!$F$7 -> 0.135
A7: Postpaid phone churn | B7: % / month | C7: 0.0087 | D7: 0.0086 | E7: 0.0093 | F7: =Assumptions!$F$8 -> 0.0093 | G7: =Assumptions!$F$8 -> 0.0093 | H7: =Assumptions!$F$8 -> 0.0093 | I7: =Assumptions!$F$8 -> 0.0093 | J7: =Assumptions!$F$8 -> 0.0093
A8: Net phone customer growth | B8: % / year | D8: =IFERROR(D5/C5-1,0) -> 0.040520965 | E8: =IFERROR(E5/D5-1,0) -> 0.083290092 | F8: =F6-F7*12 -> 0.0234 | G8: =G6-G7*12 -> 0.0234 | H8: =H6-H7*12 -> 0.0234 | I8: =I6-I7*12 -> 0.0234 | J8: =J6-J7*12 -> 0.0234
A9: Postpaid phone ARPU | B9: $ / month | C9: 48.83 | D9: 49.35 | E9: 50.37 | F9: =E9*(1+Assumptions!$F$9) -> 51.3774 | G9: =F9*(1+Assumptions!$F$9) -> 52.404948 | H9: =G9*(1+Assumptions!$F$9) -> 53.453047 | I9: =H9*(1+Assumptions!$F$9) -> 54.522108 | J9: =I9*(1+Assumptions!$F$9) -> 55.61255
A10: Phone service revenue proxy | B10: USD mm | C10: =C5*C9*12 -> 44495.459 | D10: =D5*D9*12 -> 46791.499 | E10: =E5*E9*12 -> 51736.437 | F10: =AVERAGE(E5,F5)*F9*12 -> 53388.589 | G10: =AVERAGE(F5,G5)*G9*12 -> 55730.639 | H10: =AVERAGE(G5,H5)*H9*12 -> 58175.431 | I10: =AVERAGE(H5,I5)*I9*12 -> 60727.471 | J10: =AVERAGE(I5,J5)*J9*12 -> 63391.464
A11: Reported postpaid service revenue | B11: USD mm | C11: 48692 | D11: 52340 | E11: 57932 | F11: =F10+F12 -> 59708.063 | G11: =G10+G12 -> 62176.503 | H11: =H10+H12 -> 64750.212 | I11: =I10+I12 -> 67433.747 | J11: =J10+J12 -> 70231.865
A12: Other postpaid service revenue | B12: USD mm | C12: =C11-C10 -> 4196.5414 | D12: =D11-D10 -> 5548.5014 | E12: =E11-E10 -> 6195.5626 | F12: =E12*(1+Assumptions!$F$10) -> 6319.4739 | G12: =F12*(1+Assumptions!$F$10) -> 6445.8634 | H12: =G12*(1+Assumptions!$F$10) -> 6574.7806 | I12: =H12*(1+Assumptions!$F$10) -> 6706.2763 | J12: =I12*(1+Assumptions!$F$10) -> 6840.4018
A13: Prepaid / wholesale / other service revenue | B13: USD mm | C13: =C14-C11 -> 14549 | D13: =D14-D11 -> 13838 | E13: =E14-E11 -> 13374 | F13: =E13*(1+Assumptions!$F$11) -> 13507.74 | G13: =F13*(1+Assumptions!$F$11) -> 13642.817 | H13: =G13*(1+Assumptions!$F$11) -> 13779.246 | I13: =H13*(1+Assumptions!$F$11) -> 13917.038 | J13: =I13*(1+Assumptions!$F$11) -> 14056.208
A14: Total service revenue | B14: USD mm | C14: 63241 | D14: 66178 | E14: 71306 | F14: =F11+F13 -> 73215.803 | G14: =G11+G13 -> 75819.32 | H14: =H11+H13 -> 78529.457 | I14: =I11+I13 -> 81350.785 | J14: =J11+J13 -> 84288.074
A15: Equipment & other revenue | B15: USD mm | C15: 15317 | D15: 15222 | E15: 17003 | F15: =F14*Assumptions!$F$12 -> 16107.477 | G15: =G14*Assumptions!$F$12 -> 16680.25 | H15: =H14*Assumptions!$F$12 -> 17276.481 | I15: =I14*Assumptions!$F$12 -> 17897.173 | J15: =J14*Assumptions!$F$12 -> 18543.376
A16: Total revenue | B16: USD mm | C16: =C14+C15 -> 78558 | D16: =D14+D15 -> 81400 | E16: =E14+E15 -> 88309 | F16: =F14+F15 -> 89323.279 | G16: =G14+G15 -> 92499.571 | H16: =H14+H15 -> 95805.938 | I16: =I14+I15 -> 99247.958 | J16: =J14+J15 -> 102831.45
A17: Adjusted EBITDA margin on service revenue | B17: % | C17: 0.46533104 | D17: 0.48148932 | E17: 0.4759347 | F17: =Assumptions!$F$13 -> 0.48 | G17: =Assumptions!$F$13 -> 0.48 | H17: =Assumptions!$F$13 -> 0.48 | I17: =Assumptions!$F$13 -> 0.48 | J17: =Assumptions!$F$13 -> 0.48
A18: Adjusted EBITDA | B18: USD mm | C18: 29428 | D18: 31864 | E18: 33937 | F18: =F14*F17 -> 35143.585 | G18: =G14*G17 -> 36393.274 | H18: =H14*H17 -> 37694.139 | I18: =I14*I17 -> 39048.377 | J18: =J14*J17 -> 40458.275
A19: Cash capex | B19: USD mm | C19: 9801 | D19: 8840 | E19: 9955 | F19: =F16*Assumptions!$F$15 -> 10093.531 | G19: =G16*Assumptions!$F$15 -> 10452.451 | H19: =H16*Assumptions!$F$15 -> 10826.071 | I19: =I16*Assumptions!$F$15 -> 11215.019 | J19: =J16*Assumptions!$F$15 -> 11619.954
A20: Net debt | B20: USD mm | C20: =Historical!C19 -> 75998 | D20: =Historical!D19 -> 79250 | E20: =Historical!E19 -> 88089 | F20: =E20*(1-Assumptions!$F$18) -> 83684.55 | G20: =F20*(1-Assumptions!$F$18) -> 79500.322 | H20: =G20*(1-Assumptions!$F$18) -> 75525.306 | I20: =H20*(1-Assumptions!$F$18) -> 71749.041 | J20: =I20*(1-Assumptions!$F$18) -> 68161.589
A21: Net leverage | B21: x | C21: =IFERROR(C20/C18,0) -> 2.5825065 | D21: =IFERROR(D20/D18,0) -> 2.4871328 | E21: =IFERROR(E20/E18,0) -> 2.5956626 | F21: =IFERROR(F20/F18,0) -> 2.3812183 | G21: =IFERROR(G20/G18,0) -> 2.1844785 | H21: =IFERROR(H20/H18,0) -> 2.0036352 | I21: =IFERROR(I20/I18,0) -> 1.8374398 | J21: =IFERROR(J20/J18,0) -> 1.6847379
A24: Model limitation: Reported postpaid ARPA is per account while churn is postpaid phone churn; the driver model therefore uses phone customers/ARPU for phone service revenue and treats other postpaid revenue separately. | B24: Model limitation: Reported postpaid ARPA is per account while churn is postpaid phone churn; the driver model therefore uses phone customers/ARPU for phone service revenue and treats other postpaid revenue separately. | C24: Model limitation: Reported postpaid ARPA is per account while churn is postpaid phone churn; the driver model therefore uses phone customers/ARPU for phone service revenue and treats other postpaid revenue separately. | D24: Model limitation: Reported postpaid ARPA is per account while churn is postpaid phone churn; the driver model therefore uses phone customers/ARPU for phone service revenue and treats other postpaid revenue separately. | E24: Model limitation: Reported postpaid ARPA is per account while churn is postpaid phone churn; the driver model therefore uses phone customers/ARPU for phone service revenue and treats other postpaid revenue separately. | F24: Model limitation: Reported postpaid ARPA is per account while churn is postpaid phone churn; the driver model therefore uses phone customers/ARPU for phone service revenue and treats other postpaid revenue separately. | G24: Model limitation: Reported postpaid ARPA is per account while churn is postpaid phone churn; the driver model therefore uses phone customers/ARPU for phone service revenue and treats other postpaid revenue separately. | H24: Model limitation: Reported postpaid ARPA is per account while churn is postpaid phone churn; the driver model therefore uses phone customers/ARPU for phone service revenue and treats other postpaid revenue separately. | I24: Model limitation: Reported postpaid ARPA is per account while churn is postpaid phone churn; the driver model therefore uses phone customers/ARPU for phone service revenue and treats other postpaid revenue separately. | J24: Model limitation: Reported postpaid ARPA is per account while churn is postpaid phone churn; the driver model therefore uses phone customers/ARPU for phone service revenue and treats other postpaid revenue separately.
A27: Year | B27: Revenue | C27: Adj. EBITDA
A28: 2025A | B28: =E16 -> 88309 | C28: =E18 -> 33937
A29: 2026E | B29: =F16 -> 89323.279 | C29: =F18 -> 35143.585
A30: 2027E | B30: =G16 -> 92499.571 | C30: =G18 -> 36393.274
A31: 2028E | B31: =H16 -> 95805.938 | C31: =H18 -> 37694.139
A32: 2029E | B32: =I16 -> 99247.958 | C32: =I18 -> 39048.377
A33: 2030E | B33: =J16 -> 102831.45 | C33: =J18 -> 40458.275

Sheet Change_Log
A1: TMUS | Controlled Change Log | B1: TMUS | Controlled Change Log | C1: TMUS | Controlled Change Log | D1: TMUS | Controlled Change Log | E1: TMUS | Controlled Change Log | F1: TMUS | Controlled Change Log
A2: Prior workbook is preserved. This output is a new artifact with documented source, model, gate and recalculation changes. | B2: Prior workbook is preserved. This output is a new artifact with documented source, model, gate and recalculation changes. | C2: Prior workbook is preserved. This output is a new artifact with documented source, model, gate and recalculation changes. | D2: Prior workbook is preserved. This output is a new artifact with documented source, model, gate and recalculation changes. | E2: Prior workbook is preserved. This output is a new artifact with documented source, model, gate and recalculation changes. | F2: Prior workbook is preserved. This output is a new artifact with documented source, model, gate and recalculation changes.
A4: Timestamp | B4: Version | C4: Area | D4: Change | E4: Evidence | F4: Owner scope
A5: UTC 2026-07-16T22:00:00Z | B5: 9of10-regated | C5: Preservation | D5: Prior workbook preserved without overwrite. | E5: Original SHA-256: 8d802deaaeff11ab5a3c232c176fd64ad6e0a8f2da36fd0c8d33693922f63011 | F5: Controlled rebuild
A6: UTC 2026-07-16T22:00:00Z | B6: 9of10-regated | C6: Sources | D6: Replaced generic source list with exact SEC accession, filing URL, taxonomy/tag, period, unit, transform and target-cell ledger. | E6: Sources!A4:Q* | F6: Owner preflight
A7: UTC 2026-07-16T22:00:00Z | B7: 9of10-regated | C7: Debt / cash / shares | D7: Rebuilt total debt from explicit filed components; documented cash/restricted-cash and share-count policies. | E7: Historical!A13:I19 | F7: Owner preflight
A8: UTC 2026-07-16T22:00:00Z | B8: 9of10-regated | C8: Operating model | D8: Connected phone customers, churn and ARPU to service revenue, EBITDA, FCFF and valuation. | E8: Sector_KPIs | F8: Owner preflight
A9: UTC 2026-07-16T22:00:00Z | B9: 9of10-regated | C9: Valuation | D9: Established formula-driven DCF with exit-multiple cross-check. | E9: Valuation + Sensitivity | F9: Owner preflight
A10: UTC 2026-07-16T22:00:00Z | B10: 9of10-regated | C10: Gate | D10: Added formula-driven Checks and H0-H9 owner-preflight gate; independent certification is explicitly excluded. | E10: Checks + Gate_9of10 | F10: Owner preflight
A11: UTC 2026-07-16T22:00:00Z | B11: 9of10-regated | C11: Output | D11: Authored with artifact-tool; native recalculation and final visual manifest are referenced in Gate_9of10 and support evidence. | E11: T_Mobile_US_9of10_Regated.xlsx | F11: Owner preflight
A12: 46224 | B12: Elevation Ola 2 (statement-grade IG): added audited FY2021-FY2025 statement sheets IS_Hist/BS_Hist/CF_Hist/SCE_Hist (USD mm, published constants; FY2023-25 full line detail from 10-K R-files, FY2021-22 aggregate per companyfacts.json XBRL — gaps documented, not invented), Checks_TieOut (cross-statement + continuity tie-outs), Sources_Audited (exact R-file/accession/tag citations). Existing Historical/Forecast/Valuation/Sensitivity/Checks/Sector_KPIs/Assumptions sheets and their formulas untouched — pre-existing 5-year FY2026E-2030E Base/Bull/Bear driver-built forecast and DCF valuation already satisfied the forecast requirement and were not rebuilt. Root model untouched; v2 saved under the maintainer's archive. Built via Mog SDK only (no openpyxl/LibreOffice). | C12: Claude (run 24e4a1f1)
