Workbook

Sheet EEFF
A1: Corporación de Finanzas del País, S.A. (PANACREDIT) y Subsidiarias
A2: Estados Financieros Consolidados Auditados FY21-FY25
A3: en B/. (a la par con US$), sin escala
A5: Años | B5: FY21A | C5: FY22A | D5: FY23A | E5: FY24A | F5: FY25A | G5: FY26E | H5: FY27E | I5: FY28E | J5: FY29E | K5: FY30E
A6: Estado Consolidado de Resultados
A7: Intereses ganados | B7: 19760933 | C7: 24013816 | D7: 31354516 | E7: 36993609 | F7: 41706437
A8: Comisiones ganadas | B8: 7681190 | C8: 9366601 | D8: 12465658 | E8: 13927593 | F8: 12923349
A9: Total de ingresos por intereses y comisiones | D9: 43820174 | E9: 50921202 | F9: 54629786
A10: Gastos por intereses | B10: 13459518 | C10: 14950862 | D10: 19286748 | E10: 24742945 | F10: 27201007
A11: Total de gastos por intereses | D11: 19286748 | E11: 24742945 | F11: 27201007
A12: Total de ingresos por intereses y comisiones, neto | D12: 24533426 | E12: 26178257 | F12: 27428779
A13: Provisión para pérdidas en préstamos | B13: 3675000 | C13: 3910000 | D13: 4847500 | E13: 5995466 | F13: 6437000
A14: (Reversión de) provisión para pérdidas en inversiones a costo amortizado | D14: 0 | E14: 17849 | F14: -6344
A15: Provisión para bienes adjudicados | B15: 370000 | C15: 350000 | D15: 390000 | E15: 420000 | F15: 60000
A16: Ingreso neto por intereses, después de provisiones | D16: 19295926 | E16: 19744942 | F16: 20938123
A17: Ganancia en valuación de inversiones | B17: -20000 | C17: -490000 | D17: -600000 | E17: 849397 | F17: 440739
A18: Otros ingresos | B18: 1654019 | C18: 2676655 | D18: 2971728 | E18: 3527350 | F18: 2917037
A19: Total de otros ingresos, neto | D19: 2371728 | E19: 4376747 | F19: 3357776
A20: Salarios y otros gastos de personal | B20: 2702111 | C20: 4150613 | D20: 5339952 | E20: 6663071 | F20: 6791234
A21: Impuestos varios | D21: 450020 | E21: 502974 | F21: 497149
A22: Depreciación y amortización | B22: 592499 | C22: 691158 | D22: 967602 | E22: 1039519 | F22: 1073936
A23: Publicidad y mercadeo | D23: 512348 | E23: 551309 | F23: 482250
A24: Arrendamientos por activos de bajo valor | D24: 553995 | E24: 661195 | F24: 755718
A25: Servicio de electricidad, agua y comunicaciones | D25: 328341 | E25: 414413 | F25: 417694
A26: Reparación y mantenimiento | D26: 345922 | E26: 357513 | F26: 395065
A27: Honorarios y servicios profesionales | D27: 685363 | E27: 843843 | F27: 976597
A28: Otros | D28: 2605570 | E28: 2829287 | F28: 2876235
A29: Total de gastos generales y administrativos | B29: 6940231 | C29: 8703073 | D29: 11789113 | E29: 13863124 | F29: 14265878
A30: Utilidad antes de impuesto sobre la renta | B30: 4665645 | C30: 7653137 | D30: 9878541 | E30: 10258565 | F30: 10030021
A31: Impuesto sobre la renta, neto | B31: 42161 | C31: -478846 | D31: -730485 | E31: -803240 | F31: -957116
A32: Utilidad neta | B32: 4707806 | C32: 7174291 | D32: 9148056 | E32: 9455325 | F32: 9072905
A34: Años | B34: FY21A | C34: FY22A | D34: FY23A | E34: FY24A | F34: FY25A | G34: FY26E | H34: FY27E | I34: FY28E | J34: FY29E | K34: FY30E
A35: Estado Consolidado de Situación Financiera
A36: Efectivo y depósitos en bancos | B36: 51019770 | C36: 59336554 | D36: 50672297 | E36: 50373962 | F36: 54042975
A37: Inversiones a valor razonable con cambios en resultados | B37: 11874112 | C37: 12019089 | D37: 24940576 | E37: 31751384 | F37: 30841061
A38: Inversiones a valor razonable con cambios en otras utilidades integrales | E38: 0 | F38: 2443224
A39: Inversiones a costo amortizado | B39: 4813611 | C39: 15087171 | D39: 17787629 | E39: 14615074 | F39: 13731942
A40: Préstamos por cobrar a costo amortizado, neto | B40: 169258759 | C40: 201123133 | D40: 249844714 | E40: 293697141 | F40: 330675937
A41: Propiedades, mobiliario, equipo y mejoras, neto | B41: 635534 | C41: 964183 | D41: 1713722 | E41: 1698467 | F41: 2078441
A42: Activos por derecho de uso, neto | B42: 1388986 | C42: 1333232 | D42: 911230 | E42: 411245 | F42: 174042
...

Sheet Notas_EEFF
A1: Corporación de Finanzas del País, S.A. (PANACREDIT) y Subsidiarias
A2: Notas a los Estados Financieros
A3: Fuente: informes auditados vía OCR Mistral (verbatim).
A5: Año | B5: Documento fuente | C5: Página OCR | D5: Tabla OCR / sección | E5: Nota # | F5: Título original de la nota | G5: Categoría modelable | H5: Line item EEFF | I5: Sub-line item / detalle | J5: Texto original / disclosure | K5: Monto reportado | L5: Moneda | M5: Unidad / escala | N5: Fecha / venc. / tasa / plazo | O5: Contraparte / contrato / instrumento | P5: Impacto en Supuestos | Q5: Impacto en ModeloFinanciero | R5: Link a celda EEFF | S5: Comentario de extracción | T5: Status
A6: 2022 | B6: INA_CFPAIS_2022_0.pdf | C6: page-41 | D6: markdown.md | E6: 1 | F6: 1. Información general | G6: Otros | J6: Corporación de Finanzas del País, S.A. (PANACREDIT) (la “Compañía”) es una sociedad anónima registrada en la República de Panamá. Las oficinas principales de la Compañía están ubicadas en el edificio Panacredit en calle 50, ciudad de Panamá, y cuenta con 17 sucursales y oficinas ubicadas en distintos puntos estratégicos en Ciudad de Panamá y en el interior del país, ubicadas en Penonomé, Chitré, Santiago y David. Los estados financieros consolidados comprenden la información financiera de la Compañía y su subsidiaria. | T6: OK
A7: 2022 | B7: INA_CFPAIS_2022_0.pdf | C7: page-41 | D7: markdown.md | E7: 1 | F7: 1. Información general | G7: Otros | J7: La Compañía inició operaciones a partir del 1 de abril de 2008, y dentro del giro principal del negocio están el otorgamiento de créditos de consumo, principalmente préstamos personales por descuento directo, préstamos con garantía hipotecaria, préstamos de autos, financiamiento comercial, fundamentalmente a pequeñas y medianas empresas; operaciones de factoring o descuentos de facturas locales y leasing, principalmente a través de su nombre comercial “Panacredit”. | T7: OK
A8: 2022 | B8: INA_CFPAIS_2022_0.pdf | C8: page-41 | D8: markdown.md | E8: 1 | F8: 1. Información general | G8: Otros | J8: Su subsidiaria Argentia RE Cell C. inició operaciones a partir del 19 de octubre de 2018, y su principal actividad es la de asumir reaseguros de compañías de seguros cedentes. La subsidiaria está ubicada en St. James, Barbados. | T8: OK
A9: 2022 | B9: INA_CFPAIS_2022_0.pdf | C9: page-41 | D9: markdown.md | E9: 1 | F9: 1. Información general | G9: Otros | J9: ## Aspectos regulatorios: | T9: OK
A10: 2022 | B10: INA_CFPAIS_2022_0.pdf | C10: page-41 | D10: markdown.md | E10: 1 | F10: 1. Información general | G10: Otros | J10: La Compañía cuenta con licencia No.164 de 20 de diciembre de 2007 para operar como empresa financiera e inscrita en el Registro de Empresas Financieras del Ministerio de Comercio e Industrias de Panamá (MICI). | T10: OK
A11: 2022 | B11: INA_CFPAIS_2022_0.pdf | C11: page-41 | D11: markdown.md | E11: 1 | F11: 1. Información general | G11: Otros | J11: La Compañía está sujeto a la supervisión de la Dirección General de Empresas Financieras del Ministerio de Comercio e Industrias de Panamá (MICI) por su calidad de empresas financieras en Panamá, y a través de la Superintendencia del Mercado de Valores de Panamá por ser un emisor activo por medio de Valores Comerciales Negociables (VCNs), Bonos Corporativos, Bonos Perpetuos y Acciones Preferidas. | T11: OK
A12: 2022 | B12: INA_CFPAIS_2022_0.pdf | C12: page-41 | D12: markdown.md | E12: 1 | F12: 1. Información general | G12: Otros | J12: A partir del 2015 es regulada por la Superintendencia de Bancos de Panamá, en relación a blanqueo de capitales de acuerdo a la Ley No.23 del 27 de abril de 2015. | T12: OK
A13: 2022 | B13: INA_CFPAIS_2022_0.pdf | C13: page-41 | D13: markdown.md | E13: 1 | F13: 1. Información general | G13: Otros | J13: ## Aprobación de los estados financieros consolidados: | T13: OK
A14: 2022 | B14: INA_CFPAIS_2022_0.pdf | C14: page-41 | D14: markdown.md | E14: 1 | F14: 1. Información general | G14: Otros | J14: Los estados financieros consolidados de la Compañía fueron aprobados para su emisión por la Junta Directiva el 2 de marzo de 2023. | T14: OK
A15: 2022 | B15: INA_CFPAIS_2022_0.pdf | C15: page-41 | D15: markdown.md | E15: 1 | F15: 1. Información general | G15: Otros | J15: - 5 - | T15: OK
A16: 2022 | B16: INA_CFPAIS_2022_0.pdf | C16: page-42 | D16: markdown.md | E16: 2 | F16: 2. Base de preparación | G16: Políticas contables | J16: ### Declaración de cumplimiento | T16: OK
A17: 2022 | B17: INA_CFPAIS_2022_0.pdf | C17: page-42 | D17: markdown.md | E17: 2 | F17: 2. Base de preparación | G17: Políticas contables | J17: Los estados financieros consolidados de la Compañía han sido preparados de conformidad con las Normas Internacionales de Información Financiera (NIIF), tal como han sido emitidos por el Consejo de Normas Internacionales de Contabilidad. Así también, han sido preparados bajo la hipótesis de que la Compañía opera sobre la base de un negocio en marcha. | T17: OK
... A166: 2022 | B166: INA_CFPAIS_2022_0.pdf | C166: page-56 | D166: markdown.md | E166: 3 | F166: 3. Políticas de contables significativas | G166: Políticas contables | J166: De acuerdo con las disposiciones fiscales vigentes en la República de Panamá, las ganancias obtenidas por la Compañía por operaciones locales están sujetas al pago del impuesto sobre la renta. Adicionalmente, las ganancias obtenidas por operaciones internacionales y aquellas obtenidas por depósitos a plazo e intereses devengados de la inversión en obligaciones emitidas por el gobierno de la República de Panamá y operaciones en la Bolsa Latinoamericana de Valores están exentas del pago del impuesto sobre la renta. | T166: OK
A167: 2022 | B167: INA_CFPAIS_2022_0.pdf | C167: page-56 | D167: markdown.md | E167: 3 | F167: 3. Políticas de contables significativas | G167: Políticas contables | J167: La Ley No.8 del 15 de marzo de 2010 refiere que la tasa fiscal para las entidades financieras es de 25% sobre la renta neta gravable, o sobre el total de ingresos superior a B/.1,500,000 determinen como base imponible el 25% de tasa fiscal sobre el 4.67% del total de ingresos. La Compañía considera el mayor para registrar el impuesto corriente, excepto cuando tenga la aprobación de la autoridad fiscal de no aplicación del cálculo alterno. | K167: 1500000 | L167: B/. | T167: OK
A168: 2022 | B168: INA_CFPAIS_2022_0.pdf | C168: page-56 | D168: markdown.md | E168: 3 | F168: 3. Políticas de contables significativas | G168: Políticas contables | J168: De acuerdo a las regulaciones fiscales vigentes, las declaraciones de impuesto sobre la renta están sujetas a revisión por la autoridad fiscal por los tres últimos años, incluyendo el año terminado al 31 de diciembre de 2022. | T168: OK
A169: 2022 | B169: INA_CFPAIS_2022_0.pdf | C169: page-56 | D169: markdown.md | E169: 3 | F169: 3. Políticas de contables significativas | G169: Políticas contables | J169: Durante el año 2022, la Compañía realizó reclasificaciones en la presentación de sus ingresos y gastos que afectaban las cifras presentadas en el estado de ganancia o pérdida comparativos de 2021. | T169: OK
A170: 2022 | B170: INA_CFPAIS_2022_0.pdf | C170: page-56 | D170: markdown.md | E170: 4 | F170: 4. Administración de los riesgos financieros | G170: Riesgo financiero | J170: ### Introducción y revisión general: | T170: OK
A171: 2022 | B171: INA_CFPAIS_2022_0.pdf | C171: page-56 | D171: markdown.md | E171: 4 | F171: 4. Administración de los riesgos financieros | G171: Riesgo financiero | J171: La Compañía está expuesta a los siguientes riesgos de instrumentos financieros: | T171: OK
A172: 2022 | B172: INA_CFPAIS_2022_0.pdf | C172: page-56 | D172: markdown.md | E172: 4 | F172: 4. Administración de los riesgos financieros | G172: Riesgo financiero | J172: - riesgo crediticio; - riesgo de liquidez; - riesgos de mercado; y - riesgo operacional. | T172: OK
A173: 2022 | B173: INA_CFPAIS_2022_0.pdf | C173: page-56 | D173: markdown.md | E173: 4 | F173: 4. Administración de los riesgos financieros | G173: Riesgo financiero | J173: Esta nota presenta información sobre los objetivos, políticas y procesos de la Compañía para medir y administrar el riesgo. | T173: OK
A174: 2022 | B174: INA_CFPAIS_2022_0.pdf | C174: page-56 | D174: markdown.md | E174: 4 | F174: 4. Administración de los riesgos financieros | G174: Riesgo financiero | J174: ### Marco de información general sobre la administración del riesgo: | T174: OK
A175: 2022 | B175: INA_CFPAIS_2022_0.pdf | C175: page-56 | D175: markdown.md | E175: 4 | F175: 4. Administración de los riesgos financieros | G175: Riesgo financiero | J175: La Junta Directiva de la Compañía tiene la responsabilidad general del establecimiento y la supervisión del marco de administración de riesgos de la Compañía. La administración ha creado una serie de comités integrales, quienes son responsables de aprobar y supervisar las políticas de administración de riesgos de la Compañía. | T175: OK
A176: 2022 | B176: INA_CFPAIS_2022_0.pdf | C176: page-56 | D176: markdown.md | E176: 4 | F176: 4. Administración de los riesgos financieros | G176: Riesgo financiero | J176: - 20 - | T176: OK
A177: 2022 | B177: INA_CFPAIS_2022_0.pdf | C177: page-57 | D177: markdown.md | E177: 4 | F177: 4. Administración de los riesgos financieros | G177: Riesgo financiero | J177: Las políticas de administración de riesgos de la Compañía se establecen para identificar y analizar los riesgos que enfrenta la Compañía, para establecer límites y controles de riesgo adecuados, y para monitorear los riesgos y el cumplimiento de los límites. Las políticas y los sistemas de administración de riesgos se revisan periódicamente para reflejar los cambios en las condiciones del mercado y las actividades de la Compañía. La Compañía, a través de sus normas y procedimientos de formación y administración, tiene como objetivo desarrollar un entorno de control disciplinado y constructivo en el que todos los empleados comprendan sus funciones y obligaciones. | T177: OK
A178: 2022 | B178: INA_CFPAIS_2022_0.pdf | C178: page-57 | D178: markdown.md | E178: 4 | F178: 4. Administración de los riesgos financieros | G178: Riesgo financiero | J178: El departamento de auditoría interna supervisa cómo la administración supervisa el cumplimiento de las políticas y procedimientos de administración de riesgos de la Compañía y revisa la idoneidad del marco de administración de riesgos en relación con los riesgos que enfrenta la Compañía. Así también lleva a cabo revisiones periódicas de controles y procedimientos de administración de riesgos y se informan a la Junta Directiva. | T178: OK
A179: 2022 | B179: INA_CFPAIS_2022_0.pdf | C179: page-57 | D179: markdown.md | E179: 4 | F179: 4. Administración de los riesgos financieros | G179: Riesgo financiero | J179: El "riesgo de crédito" es el riesgo de pérdida financiera para la Compañía si un cliente o contraparte de un instrumento financiero no cumple con sus obligaciones contractuales y surge principalmente de los préstamos de la Compañía a clientes. A los efectos de la presentación de informes de administración de riesgos, la Compañía considera y consolida todos los elementos de la exposición al riesgo de crédito. | T179: OK
... A210: 2022 | B210: INA_CFPAIS_2022_0.pdf | C210: page-60 | D210: markdown.md | E210: 5 | F210: 5. Revisión de los riesgos financieros | G210: Riesgo financiero | J210: #### Efectivo y depósitos en bancos: | T210: OK
A211: 2022 | B211: INA_CFPAIS_2022_0.pdf | C211: page-60 | D211: markdown.md | E211: 5 | F211: 5. Revisión de los riesgos financieros | G211: Riesgo financiero | J211: La Compañía mantenía depósitos en bancos al 31 de diciembre de 2022 por B/.59,335,404 (2021: B/.51,018,720). Los depósitos en bancos están colocados en instituciones financieras, los cuales cuentan con calificaciones de riesgo en los rangos de A+ y BB+ principalmente, basado en las agencias Standard &amp; Poor’s, Moody’s y Fitch Ratings. | K211: 59335404 | L211: B/. | T211: OK
A212: 2022 | B212: INA_CFPAIS_2022_0.pdf | C212: page-60 | D212: markdown.md | E212: 5 | F212: 5. Revisión de los riesgos financieros | G212: Riesgo financiero | J212: - 24 - | T212: OK
A213: 2022 | B213: INA_CFPAIS_2022_0.pdf | C213: page-61 | D213: markdown.md | E213: 5 | F213: 5. Revisión de los riesgos financieros | G213: Riesgo financiero | J213: Préstamos a clientes – medidos al costo amortizado: | T213: OK
A214: 2022 | B214: INA_CFPAIS_2022_0.pdf | C214: page-61 | D214: markdown.md | E214: 5 | F214: 5. Revisión de los riesgos financieros | G214: Riesgo financiero | J214: El cuadro a continuación presenta la información acerca de los riesgos por categoría basado en el tipo de producto ofrecido, saldos por cobrar y riesgo: | T214: OK
A215: 2022 | B215: INA_CFPAIS_2022_0.pdf | C215: page-61 | D215: tbl-17.html | E215: 5 | F215: 5. Revisión de los riesgos financieros | G215: Riesgo financiero | J215: [tbl-17.html](tbl-17.html) | T215: OK
A216: 2022 | B216: INA_CFPAIS_2022_0.pdf | C216: page-61 | D216: markdown.md | E216: 5 | F216: 5. Revisión de los riesgos financieros | G216: Riesgo financiero | J216: Colaterales y otras mejoras de crédito: | T216: OK
A217: 2022 | B217: INA_CFPAIS_2022_0.pdf | C217: page-61 | D217: markdown.md | E217: 5 | F217: 5. Revisión de los riesgos financieros | G217: Riesgo financiero | J217: La Compañía mantiene garantías y otras mejoras de crédito contra algunas de sus exposiciones crediticias. La siguiente tabla muestra los principales tipos de garantías mantenidas contra diferentes tipos de activos financieros: | T217: OK
A218: 2022 | B218: INA_CFPAIS_2022_0.pdf | C218: page-61 | D218: tbl-18.html | E218: 5 | F218: 5. Revisión de los riesgos financieros | G218: Riesgo financiero | J218: [tbl-18.html](tbl-18.html) | T218: OK
A219: 2022 | B219: INA_CFPAIS_2022_0.pdf | C219: page-62 | D219: markdown.md | E219: 5 | F219: 5. Revisión de los riesgos financieros | G219: Riesgo financiero | J219: Activos obtenidos mediante la posesión del colateral: | T219: OK
...

Sheet Supuestos
A1: Corporación de Finanzas del País, S.A. (PANACREDIT) y Subsidiarias
A3: COLOR KEY: Input (azul) · Fórmula (negro) · Link inter-hoja (verde)
A4: Escenario (1=Base, 2=Bull, 3=Bear)
A5: Selector escenario | C5: 1 | M5: caso | N5: NOT_DISCLOSED | Q5: Derivación mecánica declarada por el plan.
A6: Escenario activo | C6: =CHOOSE($C$5,"Base","Bull","Bear") -> Base | M6: moneda del modelo | N6: NOT_DISCLOSED | Q6: Selector de caso activo C5: Base/Bull/Bear.
A8: Años | B8: FY21A | C8: FY22A | D8: FY23A | E8: FY24A | F8: FY25A | G8: FY26E | H8: FY27E | I8: FY28E | J8: FY29E | K8: FY30E | M8: Unidad | N8: Fuente / nota | Q8: Rationale
A10: A. INGRESO POR INTERESES — CRECIMIENTO (% YoY)
A11: Total de ingresos por intereses y comisiones — driver activo | G11: =CHOOSE($C$5,G13,G14,G12) -> 0.073 | H11: =CHOOSE($C$5,H13,H14,H12) -> 0.073 | I11: =CHOOSE($C$5,I13,I14,I12) -> 0.073 | J11: =CHOOSE($C$5,J13,J14,J12) -> 0.073 | K11: =CHOOSE($C$5,K13,K14,K12) -> 0.073 | M11: moneda del modelo | N11: NOT_DISCLOSED | Q11: Selector de caso activo C5: Base/Bull/Bear.
A12: Bear | G12: 0.053 | H12: 0.053 | I12: 0.053 | J12: 0.053 | K12: 0.053 | M12: moneda del modelo | N12: NOT_DISCLOSED | Q12: Escenario driver citado; NOT_DISCLOSED si no hay fuente explícita.
A13: Base | G13: 0.073 | H13: 0.073 | I13: 0.073 | J13: 0.073 | K13: 0.073 | M13: moneda del modelo | N13: NOT_DISCLOSED | Q13: Escenario driver citado; NOT_DISCLOSED si no hay fuente explícita.
A14: Bull | G14: 0.093 | H14: 0.093 | I14: 0.093 | J14: 0.093 | K14: 0.093 | M14: moneda del modelo | N14: NOT_DISCLOSED | Q14: Escenario driver citado; NOT_DISCLOSED si no hay fuente explícita.
A15: Total de ingresos por intereses y comisiones (hist, ref EEFF) | B15: =EEFF!B9 -> 0 | C15: =EEFF!C9 -> 0 | D15: =EEFF!D9 -> 43820174 | E15: =EEFF!E9 -> 50921202 | F15: =EEFF!F9 -> 54629786 | M15: moneda del modelo | N15: EEFF (citado por fórmula viva) | Q15: Mirror histórico desde fuente citada.
A17: B. GASTO POR INTERESES (% de ingreso x int.)
A18: Gastos por intereses — driver activo | G18: =CHOOSE($C$5,G20,G21,G19) -> 0.498 | H18: =CHOOSE($C$5,H20,H21,H19) -> 0.498 | I18: =CHOOSE($C$5,I20,I21,I19) -> 0.498 | J18: =CHOOSE($C$5,J20,J21,J19) -> 0.498 | K18: =CHOOSE($C$5,K20,K21,K19) -> 0.498 | M18: moneda del modelo | N18: NOT_DISCLOSED | Q18: Selector de caso activo C5: Base/Bull/Bear.
A19: Bear | G19: 0.478 | H19: 0.478 | I19: 0.478 | J19: 0.478 | K19: 0.478 | M19: moneda del modelo | N19: NOT_DISCLOSED | Q19: Escenario driver citado; NOT_DISCLOSED si no hay fuente explícita.
A20: Base | G20: 0.498 | H20: 0.498 | I20: 0.498 | J20: 0.498 | K20: 0.498 | M20: moneda del modelo | N20: NOT_DISCLOSED | Q20: Escenario driver citado; NOT_DISCLOSED si no hay fuente explícita.
A21: Bull | G21: 0.518 | H21: 0.518 | I21: 0.518 | J21: 0.518 | K21: 0.518 | M21: moneda del modelo | N21: NOT_DISCLOSED | Q21: Escenario driver citado; NOT_DISCLOSED si no hay fuente explícita.
A22: Gastos por intereses ÷ ingresos (hist, ref EEFF) | B22: =IF(EEFF!B9=0,"",EEFF!B10/EEFF!B9) | C22: =IF(EEFF!C9=0,"",EEFF!C10/EEFF!C9) | D22: =IF(EEFF!D9=0,"",EEFF!D10/EEFF!D9) -> 0.44013399 | E22: =IF(EEFF!E9=0,"",EEFF!E10/EEFF!E9) -> 0.48590654 | F22: =IF(EEFF!F9=0,"",EEFF!F10/EEFF!F9) -> 0.49791531 | M22: % | N22: EEFF (citado por fórmula viva) | Q22: Mirror histórico desde fuente citada.
A24: C. GASTOS GENERALES (% de ingreso x int.)
A25: Total de gastos generales y administrativos — driver activo | G25: =CHOOSE($C$5,G27,G28,G26) -> 0.261 | H25: =CHOOSE($C$5,H27,H28,H26) -> 0.261 | I25: =CHOOSE($C$5,I27,I28,I26) -> 0.261 | J25: =CHOOSE($C$5,J27,J28,J26) -> 0.261 | K25: =CHOOSE($C$5,K27,K28,K26) -> 0.261 | M25: moneda del modelo | N25: NOT_DISCLOSED | Q25: Selector de caso activo C5: Base/Bull/Bear.
A26: Bear | G26: 0.241 | H26: 0.241 | I26: 0.241 | J26: 0.241 | K26: 0.241 | M26: moneda del modelo | N26: NOT_DISCLOSED | Q26: Escenario driver citado; NOT_DISCLOSED si no hay fuente explícita.
A27: Base | G27: 0.261 | H27: 0.261 | I27: 0.261 | J27: 0.261 | K27: 0.261 | M27: moneda del modelo | N27: NOT_DISCLOSED | Q27: Escenario driver citado; NOT_DISCLOSED si no hay fuente explícita.
A28: Bull | G28: 0.281 | H28: 0.281 | I28: 0.281 | J28: 0.281 | K28: 0.281 | M28: moneda del modelo | N28: NOT_DISCLOSED | Q28: Escenario driver citado; NOT_DISCLOSED si no hay fuente explícita.
A29: Total de gastos generales y administrativos ÷ ingresos (hist, ref EEFF) | B29: =IF(EEFF!B9=0,"",EEFF!B29/EEFF!B9) | C29: =IF(EEFF!C9=0,"",EEFF!C29/EEFF!C9) | D29: =IF(EEFF!D9=0,"",EEFF!D29/EEFF!D9) -> 0.26903392 | E29: =IF(EEFF!E9=0,"",EEFF!E29/EEFF!E9) -> 0.2722466 | F29: =IF(EEFF!F9=0,"",EEFF!F29/EEFF!F9) -> 0.26113736 | M29: % | N29: EEFF (citado por fórmula viva) | Q29: Mirror histórico desde fuente citada.
A32: D. CARTERA / YIELD / NIM / RIESGO
A33: Prestamos netos - crecimiento activo | G33: =CHOOSE($C$5,G35,G36,G34) -> 0.105 | H33: =CHOOSE($C$5,H35,H36,H34) -> 0.1 | I33: =CHOOSE($C$5,I35,I36,I34) -> 0.095 | J33: =CHOOSE($C$5,J35,J36,J34) -> 0.09 | K33: =CHOOSE($C$5,K35,K36,K34) -> 0.085 | M33: % | N33: NOT_DISCLOSED | Q33: Selector de caso activo C5: Base/Bull/Bear.
A34: Bear | G34: 0.075 | H34: 0.07 | I34: 0.065 | J34: 0.06 | K34: 0.06 | M34: moneda del modelo | N34: NOT_DISCLOSED | Q34: Escenario driver citado; NOT_DISCLOSED si no hay fuente explícita.
A35: Base | G35: 0.105 | H35: 0.1 | I35: 0.095 | J35: 0.09 | K35: 0.085 | M35: moneda del modelo | N35: NOT_DISCLOSED | Q35: Escenario driver citado; NOT_DISCLOSED si no hay fuente explícita.
A36: Bull | G36: 0.13 | H36: 0.125 | I36: 0.12 | J36: 0.115 | K36: 0.11 | M36: moneda del modelo | N36: NOT_DISCLOSED | Q36: Escenario driver citado; NOT_DISCLOSED si no hay fuente explícita.
A37: Prestamos netos (hist, ref EEFF) | B37: =EEFF!B40 -> 169258759 | C37: =EEFF!C40 -> 201123133 | D37: =EEFF!D40 -> 249844714 | E37: =EEFF!E40 -> 293697141 | F37: =EEFF!F40 -> 330675937 | M37: moneda del modelo | N37: EEFF (citado por fórmula viva) | Q37: Mirror histórico desde fuente citada.
A38: Portfolio yield - driver activo | G38: =CHOOSE($C$5,G40,G41,G39) -> 0.134 | H38: =CHOOSE($C$5,H40,H41,H39) -> 0.133 | I38: =CHOOSE($C$5,I40,I41,I39) -> 0.132 | J38: =CHOOSE($C$5,J40,J41,J39) -> 0.131 | K38: =CHOOSE($C$5,K40,K41,K39) -> 0.13 | M38: % | N38: NOT_DISCLOSED | Q38: Selector de caso activo C5: Base/Bull/Bear.
A39: Bear | G39: 0.125 | H39: 0.123 | I39: 0.121 | J39: 0.12 | K39: 0.12 | M39: moneda del modelo | N39: NOT_DISCLOSED | Q39: Escenario driver citado; NOT_DISCLOSED si no hay fuente explícita.
A40: Base | G40: 0.134 | H40: 0.133 | I40: 0.132 | J40: 0.131 | K40: 0.13 | M40: moneda del modelo | N40: NOT_DISCLOSED | Q40: Escenario driver citado; NOT_DISCLOSED si no hay fuente explícita.
A41: Bull | G41: 0.142 | H41: 0.141 | I41: 0.14 | J41: 0.139 | K41: 0.138 | M41: moneda del modelo | N41: NOT_DISCLOSED | Q41: Escenario driver citado; NOT_DISCLOSED si no hay fuente explícita.
A42: Comisiones yield - driver activo | G42: =CHOOSE($C$5,G44,G45,G43) -> 0.039 | H42: =CHOOSE($C$5,H44,H45,H43) -> 0.038 | I42: =CHOOSE($C$5,I44,I45,I43) -> 0.038 | J42: =CHOOSE($C$5,J44,J45,J43) -> 0.037 | K42: =CHOOSE($C$5,K44,K45,K43) -> 0.037 | M42: % | N42: NOT_DISCLOSED | Q42: Selector de caso activo C5: Base/Bull/Bear.
A43: Bear | G43: 0.035 | H43: 0.034 | I43: 0.034 | J43: 0.033 | K43: 0.033 | M43: moneda del modelo | N43: NOT_DISCLOSED | Q43: Escenario driver citado; NOT_DISCLOSED si no hay fuente explícita.
A44: Base | G44: 0.039 | H44: 0.038 | I44: 0.038 | J44: 0.037 | K44: 0.037 | M44: moneda del modelo | N44: NOT_DISCLOSED | Q44: Escenario driver citado; NOT_DISCLOSED si no hay fuente explícita.
A45: Bull | G45: 0.043 | H45: 0.042 | I45: 0.041 | J45: 0.041 | K45: 0.04 | M45: moneda del modelo | N45: NOT_DISCLOSED | Q45: Escenario driver citado; NOT_DISCLOSED si no hay fuente explícita.
A46: Costo de fondos - driver activo | G46: =CHOOSE($C$5,G48,G49,G47) -> 0.073 | H46: =CHOOSE($C$5,H48,H49,H47) -> 0.073 | I46: =CHOOSE($C$5,I48,I49,I47) -> 0.074 | J46: =CHOOSE($C$5,J48,J49,J47) -> 0.074 | K46: =CHOOSE($C$5,K48,K49,K47) -> 0.074 | M46: moneda del modelo | N46: NOT_DISCLOSED | Q46: Selector de caso activo C5: Base/Bull/Bear.
A47: Bear | G47: 0.08 | H47: 0.081 | I47: 0.082 | J47: 0.083 | K47: 0.083 | M47: moneda del modelo | N47: NOT_DISCLOSED | Q47: Escenario driver citado; NOT_DISCLOSED si no hay fuente explícita.
...

Sheet ModeloFinanciero
A1: Corporación de Finanzas del País, S.A. (PANACREDIT) y Subsidiarias
A2: Estados Financieros Consolidados Auditados FY21-FY25
A3: en B/. (a la par con US$), sin escala
A5: Años | B5: FY21A | C5: FY22A | D5: FY23A | E5: FY24A | F5: FY25A | G5: FY26E | H5: FY27E | I5: FY28E | J5: FY29E | K5: FY30E
A6: Estado Consolidado de Resultados
A7: Intereses ganados | B7: =EEFF!B7 -> 19760933 | C7: =EEFF!C7 -> 24013816 | D7: =EEFF!D7 -> 31354516 | E7: =EEFF!E7 -> 36993609 | F7: =EEFF!F7 -> 41706437 | G7: =F7*(1+Supuestos!G33) -> 46085613 | H7: =G7*(1+Supuestos!H33) -> 50694174 | I7: =H7*(1+Supuestos!I33) -> 55510121 | J7: =I7*(1+Supuestos!J33) -> 60506032 | K7: =J7*(1+Supuestos!K33) -> 65649044
A8: Comisiones ganadas | B8: =EEFF!B8 -> 7681190 | C8: =EEFF!C8 -> 9366601 | D8: =EEFF!D8 -> 12465658 | E8: =EEFF!E8 -> 13927593 | F8: =EEFF!F8 -> 12923349 | G8: =AVERAGE(F40,G40)*Supuestos!G42 -> 12896362 | H8: =AVERAGE(G40,H40)*Supuestos!H42 -> 12565686 | I8: =AVERAGE(H40,I40)*Supuestos!I42 -> 12565686 | J8: =AVERAGE(I40,J40)*Supuestos!J42 -> 12235010 | K8: =AVERAGE(J40,K40)*Supuestos!K42 -> 12235010
A9: Total de ingresos por intereses y comisiones | B9: =EEFF!B9 -> 0 | C9: =EEFF!C9 -> 0 | D9: =EEFF!D9 -> 43820174 | E9: =EEFF!E9 -> 50921202 | F9: =EEFF!F9 -> 54629786 | G9: =G7+G8 -> 58981974 | H9: =H7+H8 -> 63259860 | I9: =I7+I8 -> 68075806 | J9: =J7+J8 -> 72741041 | K9: =K7+K8 -> 77884054
A10: Gastos por intereses | B10: =EEFF!B10 -> 13459518 | C10: =EEFF!C10 -> 14950862 | D10: =EEFF!D10 -> 19286748 | E10: =EEFF!E10 -> 24742945 | F10: =EEFF!F10 -> 27201007 | G10: =AVERAGE(F48+F49+F50+F51+F52+F53,G48+G49+G50+G51+G52+G53)*Supuestos!G46 -> 27572157 | H10: =AVERAGE(G48+G49+G50+G51+G52+G53,H48+H49+H50+H51+H52+H53)*Supuestos!H46 -> 27572157 | I10: =AVERAGE(H48+H49+H50+H51+H52+H53,I48+I49+I50+I51+I52+I53)*Supuestos!I46 -> 27949857 | J10: =AVERAGE(I48+I49+I50+I51+I52+I53,J48+J49+J50+J51+J52+J53)*Supuestos!J46 -> 27949857 | K10: =AVERAGE(J48+J49+J50+J51+J52+J53,K48+K49+K50+K51+K52+K53)*Supuestos!K46 -> 27949857
A11: Total de gastos por intereses | B11: =EEFF!B11 -> 0 | C11: =EEFF!C11 -> 0 | D11: =EEFF!D11 -> 19286748 | E11: =EEFF!E11 -> 24742945 | F11: =EEFF!F11 -> 27201007 | G11: =G10 -> 27572157 | H11: =H10 -> 27572157 | I11: =I10 -> 27949857 | J11: =J10 -> 27949857 | K11: =K10 -> 27949857
A12: Total de ingresos por intereses y comisiones, neto | B12: =EEFF!B12 -> 0 | C12: =EEFF!C12 -> 0 | D12: =EEFF!D12 -> 24533426 | E12: =EEFF!E12 -> 26178257 | F12: =EEFF!F12 -> 27428779 | G12: =G9-G11 -> 31409818 | H12: =H9-H11 -> 35687703 | I12: =I9-I11 -> 40125949 | J12: =J9-J11 -> 44791184 | K12: =K9-K11 -> 49934196
A13: Provisión para pérdidas en préstamos | B13: =EEFF!B13 -> 3675000 | C13: =EEFF!C13 -> 3910000 | D13: =EEFF!D13 -> 4847500 | E13: =EEFF!E13 -> 5995466 | F13: =EEFF!F13 -> 6437000 | G13: =AVERAGE(F40,G40)*Supuestos!G50 -> 6613518.7 | H13: =AVERAGE(G40,H40)*Supuestos!H50 -> 6613518.7 | I13: =AVERAGE(H40,I40)*Supuestos!I50 -> 6613518.7 | J13: =AVERAGE(I40,J40)*Supuestos!J50 -> 6282842.8 | K13: =AVERAGE(J40,K40)*Supuestos!K50 -> 6282842.8
A14: (Reversión de) provisión para pérdidas en inversiones a costo amortizado | B14: =EEFF!B14 -> 0 | C14: =EEFF!C14 -> 0 | D14: =EEFF!D14 -> 0 | E14: =EEFF!E14 -> 17849 | F14: =EEFF!F14 -> -6344 | G14: =F14 -> -6344 | H14: =G14 -> -6344 | I14: =H14 -> -6344 | J14: =I14 -> -6344 | K14: =J14 -> -6344
A15: Provisión para bienes adjudicados | B15: =EEFF!B15 -> 370000 | C15: =EEFF!C15 -> 350000 | D15: =EEFF!D15 -> 390000 | E15: =EEFF!E15 -> 420000 | F15: =EEFF!F15 -> 60000 | G15: =F15 -> 60000 | H15: =G15 -> 60000 | I15: =H15 -> 60000 | J15: =I15 -> 60000 | K15: =J15 -> 60000
A16: Ingreso neto por intereses, después de provisiones | B16: =EEFF!B16 -> 0 | C16: =EEFF!C16 -> 0 | D16: =EEFF!D16 -> 19295926 | E16: =EEFF!E16 -> 19744942 | F16: =EEFF!F16 -> 20938123 | G16: =G12-G13-G14-G15 -> 24742643 | H16: =H12-H13-H14-H15 -> 29020528 | I16: =I12-I13-I14-I15 -> 33458774 | J16: =J12-J13-J14-J15 -> 38454685 | K16: =K12-K13-K14-K15 -> 43597698
A17: Ganancia en valuación de inversiones | B17: =EEFF!B17 -> -20000 | C17: =EEFF!C17 -> -490000 | D17: =EEFF!D17 -> -600000 | E17: =EEFF!E17 -> 849397 | F17: =EEFF!F17 -> 440739 | G17: =F17 -> 440739 | H17: =G17 -> 440739 | I17: =H17 -> 440739 | J17: =I17 -> 440739 | K17: =J17 -> 440739
A18: Otros ingresos | B18: =EEFF!B18 -> 1654019 | C18: =EEFF!C18 -> 2676655 | D18: =EEFF!D18 -> 2971728 | E18: =EEFF!E18 -> 3527350 | F18: =EEFF!F18 -> 2917037 | G18: =F18 -> 2917037 | H18: =G18 -> 2917037 | I18: =H18 -> 2917037 | J18: =I18 -> 2917037 | K18: =J18 -> 2917037
A19: Total de otros ingresos, neto | B19: =EEFF!B19 -> 0 | C19: =EEFF!C19 -> 0 | D19: =EEFF!D19 -> 2371728 | E19: =EEFF!E19 -> 4376747 | F19: =EEFF!F19 -> 3357776 | G19: =G17+G18 -> 3357776 | H19: =H17+H18 -> 3357776 | I19: =I17+I18 -> 3357776 | J19: =J17+J18 -> 3357776 | K19: =K17+K18 -> 3357776
A20: Salarios y otros gastos de personal | B20: =EEFF!B20 -> 2702111 | C20: =EEFF!C20 -> 4150613 | D20: =EEFF!D20 -> 5339952 | E20: =EEFF!E20 -> 6663071 | F20: =EEFF!F20 -> 6791234 | G20: =F20/F29*(G9*Supuestos!G54) -> 7328414.1 | H20: =G20/G29*(H9*Supuestos!H54) -> 7769590.3 | I20: =H20/H29*(I9*Supuestos!I54) -> 8263864 | J20: =I20/I29*(J9*Supuestos!J54) -> 8726302.1 | K20: =J20/J29*(K9*Supuestos!K54) -> 9269125.2
A21: Impuestos varios | B21: =EEFF!B21 -> 0 | C21: =EEFF!C21 -> 0 | D21: =EEFF!D21 -> 450020 | E21: =EEFF!E21 -> 502974 | F21: =EEFF!F21 -> 497149 | G21: =F21/F29*(G9*Supuestos!G54) -> 536473.01 | H21: =G21/G29*(H9*Supuestos!H54) -> 568769.1 | I21: =H21/H29*(I9*Supuestos!I54) -> 604952.17 | J21: =I21/I29*(J9*Supuestos!J54) -> 638804.72 | K21: =J21/J29*(K9*Supuestos!K54) -> 678541.82
A22: Depreciación y amortización | B22: =EEFF!B22 -> 592499 | C22: =EEFF!C22 -> 691158 | D22: =EEFF!D22 -> 967602 | E22: =EEFF!E22 -> 1039519 | F22: =EEFF!F22 -> 1073936 | G22: =F22/F29*(G9*Supuestos!G54) -> 1158883.3 | H22: =G22/G29*(H9*Supuestos!H54) -> 1228649 | I22: =H22/H29*(I9*Supuestos!I54) -> 1306811.3 | J22: =I22/I29*(J9*Supuestos!J54) -> 1379939.2 | K22: =J22/J29*(K9*Supuestos!K54) -> 1465778.9
A23: Publicidad y mercadeo | B23: =EEFF!B23 -> 0 | C23: =EEFF!C23 -> 0 | D23: =EEFF!D23 -> 512348 | E23: =EEFF!E23 -> 551309 | F23: =EEFF!F23 -> 482250 | G23: =F23/F29*(G9*Supuestos!G54) -> 520395.51 | H23: =G23/G29*(H9*Supuestos!H54) -> 551723.73 | I23: =H23/H29*(I9*Supuestos!I54) -> 586822.43 | J23: =I23/I29*(J9*Supuestos!J54) -> 619660.46 | K23: =J23/J29*(K9*Supuestos!K54) -> 658206.68
A24: Arrendamientos por activos de bajo valor | B24: =EEFF!B24 -> 0 | C24: =EEFF!C24 -> 0 | D24: =EEFF!D24 -> 553995 | E24: =EEFF!E24 -> 661195 | F24: =EEFF!F24 -> 755718 | G24: =F24/F29*(G9*Supuestos!G54) -> 815494.57 | H24: =G24/G29*(H9*Supuestos!H54) -> 864587.98 | I24: =H24/H29*(I9*Supuestos!I54) -> 919589.99 | J24: =I24/I29*(J9*Supuestos!J54) -> 971049.38 | K24: =J24/J29*(K9*Supuestos!K54) -> 1031453.9
A25: Servicio de electricidad, agua y comunicaciones | B25: =EEFF!B25 -> 0 | C25: =EEFF!C25 -> 0 | D25: =EEFF!D25 -> 328341 | E25: =EEFF!E25 -> 414413 | F25: =EEFF!F25 -> 417694 | G25: =F25/F29*(G9*Supuestos!G54) -> 450733.2 | H25: =G25/G29*(H9*Supuestos!H54) -> 477867.68 | I25: =H25/H29*(I9*Supuestos!I54) -> 508267.93 | J25: =I25/I29*(J9*Supuestos!J54) -> 536710.12 | K25: =J25/J29*(K9*Supuestos!K54) -> 570096.39
A26: Reparación y mantenimiento | B26: =EEFF!B26 -> 0 | C26: =EEFF!C26 -> 0 | D26: =EEFF!D26 -> 345922 | E26: =EEFF!E26 -> 357513 | F26: =EEFF!F26 -> 395065 | G26: =F26/F29*(G9*Supuestos!G54) -> 426314.26 | H26: =G26/G29*(H9*Supuestos!H54) -> 451978.71 | I26: =H26/H29*(I9*Supuestos!I54) -> 480731.99 | J26: =I26/I29*(J9*Supuestos!J54) -> 507633.3 | K26: =J26/J29*(K9*Supuestos!K54) -> 539210.83
A27: Honorarios y servicios profesionales | B27: =EEFF!B27 -> 0 | C27: =EEFF!C27 -> 0 | D27: =EEFF!D27 -> 685363 | E27: =EEFF!E27 -> 843843 | F27: =EEFF!F27 -> 976597 | G27: =F27/F29*(G9*Supuestos!G54) -> 1053844.9 | H27: =G27/G29*(H9*Supuestos!H54) -> 1117287.2 | I27: =H27/H29*(I9*Supuestos!I54) -> 1188365 | J27: =I27/I29*(J9*Supuestos!J54) -> 1254864.8 | K27: =J27/J29*(K9*Supuestos!K54) -> 1332924.2
A28: Otros | B28: =EEFF!B28 -> 0 | C28: =EEFF!C28 -> 0 | D28: =EEFF!D28 -> 2605570 | E28: =EEFF!E28 -> 2829287 | F28: =EEFF!F28 -> 2876235 | G28: =F28/F29*(G9*Supuestos!G54) -> 3103742.4 | H28: =G28/G29*(H9*Supuestos!H54) -> 3290590.1 | I28: =H28/H29*(I9*Supuestos!I54) -> 3499925.8 | J28: =I28/I29*(J9*Supuestos!J54) -> 3695778.3 | K28: =J28/J29*(K9*Supuestos!K54) -> 3925675.7
A29: Total de gastos generales y administrativos | B29: =EEFF!B29 -> 6940231 | C29: =EEFF!C29 -> 8703073 | D29: =EEFF!D29 -> 11789113 | E29: =EEFF!E29 -> 13863124 | F29: =EEFF!F29 -> 14265878 | G29: =G20+G21+G22+G23+G24+G25+G26+G27+G28 -> 15394295 | H29: =H20+H21+H22+H23+H24+H25+H26+H27+H28 -> 16321044 | I29: =I20+I21+I22+I23+I24+I25+I26+I27+I28 -> 17359331 | J29: =J20+J21+J22+J23+J24+J25+J26+J27+J28 -> 18330742 | K29: =K20+K21+K22+K23+K24+K25+K26+K27+K28 -> 19471013
A30: Utilidad antes de impuesto sobre la renta | B30: =EEFF!B30 -> 4665645 | C30: =EEFF!C30 -> 7653137 | D30: =EEFF!D30 -> 9878541 | E30: =EEFF!E30 -> 10258565 | F30: =EEFF!F30 -> 10030021 | G30: =F30 -> 10030021 | H30: =G30 -> 10030021 | I30: =H30 -> 10030021 | J30: =I30 -> 10030021 | K30: =J30 -> 10030021
A31: Impuesto sobre la renta, neto | B31: =EEFF!B31 -> 42161 | C31: =EEFF!C31 -> -478846 | D31: =EEFF!D31 -> -730485 | E31: =EEFF!E31 -> -803240 | F31: =EEFF!F31 -> -957116 | G31: =F31 -> -957116 | H31: =G31 -> -957116 | I31: =H31 -> -957116 | J31: =I31 -> -957116 | K31: =J31 -> -957116
A32: Utilidad neta | B32: =EEFF!B32 -> 4707806 | C32: =EEFF!C32 -> 7174291 | D32: =EEFF!D32 -> 9148056 | E32: =EEFF!E32 -> 9455325 | F32: =EEFF!F32 -> 9072905 | G32: =G30+G31 -> 9072905 | H32: =H30+H31 -> 9072905 | I32: =I30+I31 -> 9072905 | J32: =J30+J31 -> 9072905 | K32: =K30+K31 -> 9072905
A34: Años | B34: FY21A | C34: FY22A | D34: FY23A | E34: FY24A | F34: FY25A | G34: FY26E | H34: FY27E | I34: FY28E | J34: FY29E | K34: FY30E
A35: Estado Consolidado de Situación Financiera
A36: Efectivo y depósitos en bancos | B36: =EEFF!B36 -> 51019770 | C36: =EEFF!C36 -> 59336554 | D36: =EEFF!D36 -> 50672297 | E36: =EEFF!E36 -> 50373962 | F36: =EEFF!F36 -> 54042975 | G36: =F36 -> 54042975 | H36: =G36 -> 54042975 | I36: =H36 -> 54042975 | J36: =I36 -> 54042975 | K36: =J36 -> 54042975
A37: Inversiones a valor razonable con cambios en resultados | B37: =EEFF!B37 -> 11874112 | C37: =EEFF!C37 -> 12019089 | D37: =EEFF!D37 -> 24940576 | E37: =EEFF!E37 -> 31751384 | F37: =EEFF!F37 -> 30841061 | G37: =F37 -> 30841061 | H37: =G37 -> 30841061 | I37: =H37 -> 30841061 | J37: =I37 -> 30841061 | K37: =J37 -> 30841061
A38: Inversiones a valor razonable con cambios en otras utilidades integrales | B38: =EEFF!B38 -> 0 | C38: =EEFF!C38 -> 0 | D38: =EEFF!D38 -> 0 | E38: =EEFF!E38 -> 0 | F38: =EEFF!F38 -> 2443224 | G38: =F38 -> 2443224 | H38: =G38 -> 2443224 | I38: =H38 -> 2443224 | J38: =I38 -> 2443224 | K38: =J38 -> 2443224
A39: Inversiones a costo amortizado | B39: =EEFF!B39 -> 4813611 | C39: =EEFF!C39 -> 15087171 | D39: =EEFF!D39 -> 17787629 | E39: =EEFF!E39 -> 14615074 | F39: =EEFF!F39 -> 13731942 | G39: =F39 -> 13731942 | H39: =G39 -> 13731942 | I39: =H39 -> 13731942 | J39: =I39 -> 13731942 | K39: =J39 -> 13731942
A40: Préstamos por cobrar a costo amortizado, neto | B40: =EEFF!B40 -> 169258759 | C40: =EEFF!C40 -> 201123133 | D40: =EEFF!D40 -> 249844714 | E40: =EEFF!E40 -> 293697141 | F40: =EEFF!F40 -> 330675937 | G40: =F40 -> 330675937 | H40: =G40 -> 330675937 | I40: =H40 -> 330675937 | J40: =I40 -> 330675937 | K40: =J40 -> 330675937
A41: Propiedades, mobiliario, equipo y mejoras, neto | B41: =EEFF!B41 -> 635534 | C41: =EEFF!C41 -> 964183 | D41: =EEFF!D41 -> 1713722 | E41: =EEFF!E41 -> 1698467 | F41: =EEFF!F41 -> 2078441 | G41: =F41 -> 2078441 | H41: =G41 -> 2078441 | I41: =H41 -> 2078441 | J41: =I41 -> 2078441 | K41: =J41 -> 2078441
A42: Activos por derecho de uso, neto | B42: =EEFF!B42 -> 1388986 | C42: =EEFF!C42 -> 1333232 | D42: =EEFF!D42 -> 911230 | E42: =EEFF!E42 -> 411245 | F42: =EEFF!F42 -> 174042 | G42: =F42 -> 174042 | H42: =G42 -> 174042 | I42: =H42 -> 174042 | J42: =I42 -> 174042 | K42: =J42 -> 174042
...

Sheet _CHECKS
A1: Corporación de Finanzas del País, S.A. (PANACREDIT) y Subsidiarias
A2: _CHECKS panel — non-bank-lender template, live formulas, known residuals signed visible
A3: Status semantics: PASS = zero undocumented hard failures; KNOWN_RESIDUAL = signed G7 residual; SOURCE_GAP = unresolved semantic anchor/schedule.
A4: MASTER_STATUS | B4: MODEL STATUS | C4: =IF(COUNTIF($C$6:$C$29,"FAIL")=0,"PASS","FAIL") -> PASS | G4: Master PASS counts only FAIL rows; KNOWN_RESIDUAL/SOURCE_GAP remain visible but non-blocking.
A5: check_id | B5: description | C5: status | D5: hardness | E5: tolerance | F5: expected | G5: note | H5: FY21A | I5: FY22A | J5: FY23A | K5: FY24A | L5: FY25A | M5: FY26E | N5: FY27E | O5: FY28E | P5: FY29E | Q5: FY30E
A7: UNIVERSAL CHECKS
A8: BS_BALANCE | B8: UNIVERSAL | expected 0; hard fail if ABS(value) > hard_tie_tolerance. Observed: UEPII critical gate <10 for BS/cash; BG hard reconciliation >=1000 because full USD. | source applies_to: all 16 archetypes | C8: =IF(SUMPRODUCT((ABS(H8:Q8)>1000)*1)=0,"PASS","FAIL") -> PASS | D8: hard | E8: 1000 USD | F8: 0 | G8: expected 0; hard fail if ABS(value) > hard_tie_tolerance. Observed: UEPII critical gate <10 for BS/cash; BG hard reconciliation >=1000 because full USD. Default full-USD hard tie threshold is $1,000 unless the workbook declares a tighter scale-aware tolerance. | H8: =ModeloFinanciero!B47-ModeloFinanciero!B66 -> 0 | I8: =ModeloFinanciero!C47-ModeloFinanciero!C66 -> 0 | J8: =ModeloFinanciero!D47-ModeloFinanciero!D66 -> 0 | K8: =ModeloFinanciero!E47-ModeloFinanciero!E66 -> 0 | L8: =ModeloFinanciero!F47-ModeloFinanciero!F66 -> 0 | M8: =ModeloFinanciero!G47-ModeloFinanciero!G66 -> 0 | N8: =ModeloFinanciero!H47-ModeloFinanciero!H66 -> 0 | O8: =ModeloFinanciero!I47-ModeloFinanciero!I66 -> 0 | ... Q8: =ModeloFinanciero!K47-ModeloFinanciero!K66 -> 0
A9: CASH_TIE | B9: UNIVERSAL | expected 0; use hard_tie_tolerance; if cash includes restricted cash/time deposits, define cash_component role explicitly. | source applies_to: all 16 archetypes | C9: KNOWN_RESIDUAL | D9: hard | E9: 1000 USD | F9: -28938651 @ FY25A | G9: G7a cash tie: Known Panacredit CF-to-BS structural debt lane; signed as visible known residual. | H9: =EEFF!B105-EEFF!B36 -> -15840543 | I9: =EEFF!C105-EEFF!C36 -> -12620993 | J9: =EEFF!D105-EEFF!D36 -> -15138651 | K9: =EEFF!E105-EEFF!E36 -> -17988651 | L9: =EEFF!F105-EEFF!F36 -> -28938651
A10: CF_ROLLFORWARD | B10: UNIVERSAL | expected 0; hard_tie_tolerance; historical rows may be WARN if source CF transcript is incomplete. | source applies_to: all 16 where CF is modeled | C10: =IF(SUMPRODUCT((ABS(H10:Q10)>1000)*1)=0,"PASS","FAIL") -> PASS | D10: hard | E10: 1000 USD | F10: 0 | G10: expected 0; hard_tie_tolerance; historical rows may be WARN if source CF transcript is incomplete. Default full-USD hard tie threshold is $1,000 unless the workbook declares a tighter scale-aware tolerance. | H10: =ModeloFinanciero!B88+ModeloFinanciero!B95+ModeloFinanciero!B102-(ModeloFinanciero!B105-ModeloFinanciero!B104) -> 0 | I10: =ModeloFinanciero!C88+ModeloFinanciero!C95+ModeloFinanciero!C102-(ModeloFinanciero!C105-ModeloFinanciero!C104) -> 0 | J10: =ModeloFinanciero!D88+ModeloFinanciero!D95+ModeloFinanciero!D102-(ModeloFinanciero!D105-ModeloFinanciero!D104) -> 0 | K10: =ModeloFinanciero!E88+ModeloFinanciero!E95+ModeloFinanciero!E102-(ModeloFinanciero!E105-ModeloFinanciero!E104) -> 0 | L10: =ModeloFinanciero!F88+ModeloFinanciero!F95+ModeloFinanciero!F102-(ModeloFinanciero!F105-ModeloFinanciero!F104) -> 0 | M10: =ModeloFinanciero!G88+ModeloFinanciero!G95+ModeloFinanciero!G102-(ModeloFinanciero!G105-ModeloFinanciero!G104) -> 0 | N10: =ModeloFinanciero!H88+ModeloFinanciero!H95+ModeloFinanciero!H102-(ModeloFinanciero!H105-ModeloFinanciero!H104) -> 0 | O10: =ModeloFinanciero!I88+ModeloFinanciero!I95+ModeloFinanciero!I102-(ModeloFinanciero!I105-ModeloFinanciero!I104) -> 0 | ... Q10: =ModeloFinanciero!K88+ModeloFinanciero!K95+ModeloFinanciero!K102-(ModeloFinanciero!K105-ModeloFinanciero!K104) -> 0
A11: NI_TIE_TO_EQUITY | B11: UNIVERSAL | expected 0; hard_tie_tolerance. | source applies_to: all 16 | C11: =IF(SUMPRODUCT((ABS(H11:Q11)>1000)*1)=0,"PASS","FAIL") -> PASS | D11: hard | E11: 1000 USD | F11: 0 | G11: expected 0; hard_tie_tolerance. Default full-USD hard tie threshold is $1,000 unless the workbook declares a tighter scale-aware tolerance. | H11: =ModeloFinanciero!B32-ModeloFinanciero!B70 -> 0 | I11: =ModeloFinanciero!C32-ModeloFinanciero!C70 -> 0 | J11: =ModeloFinanciero!D32-ModeloFinanciero!D70 -> 0 | K11: =ModeloFinanciero!E32-ModeloFinanciero!E70 -> 0 | L11: =ModeloFinanciero!F32-ModeloFinanciero!F70 -> 0
A12: NI_SIGN_SANITY | B12: UNIVERSAL | expected 0; sign convention must be stated in row description. | source applies_to: all 16 | C12: SOURCE_GAP | D12: hard | E12: 1000 USD | F12: 0 | G12: Sign convention diagnostic remains visible; tax-sign taxonomy is not a signed hard-control anchor. | H12: =ModeloFinanciero!B32-(ModeloFinanciero!B30-ABS(ModeloFinanciero!B31)) -> 84322 | I12: =ModeloFinanciero!C32-(ModeloFinanciero!C30-ABS(ModeloFinanciero!C31)) -> 0 | J12: =ModeloFinanciero!D32-(ModeloFinanciero!D30-ABS(ModeloFinanciero!D31)) -> 0 | K12: =ModeloFinanciero!E32-(ModeloFinanciero!E30-ABS(ModeloFinanciero!E31)) -> 0 | L12: =ModeloFinanciero!F32-(ModeloFinanciero!F30-ABS(ModeloFinanciero!F31)) -> 0 | M12: =ModeloFinanciero!G32-(ModeloFinanciero!G30-ABS(ModeloFinanciero!G31)) -> 0 | N12: =ModeloFinanciero!H32-(ModeloFinanciero!H30-ABS(ModeloFinanciero!H31)) -> 0 | O12: =ModeloFinanciero!I32-(ModeloFinanciero!I30-ABS(ModeloFinanciero!I31)) -> 0 | ... Q12: =ModeloFinanciero!K32-(ModeloFinanciero!K30-ABS(ModeloFinanciero!K31)) -> 0
A13: RE_ROLLFORWARD | B13: UNIVERSAL | expected 0; hard_tie_tolerance. | source applies_to: all 16 with RE row | C13: KNOWN_RESIDUAL | D13: hard | E13: 1000 USD | F13: -1848213 @ FY23A | G13: G7c retained earnings roll: Reserve/investment valuation/complementary-tax movement suspected; signed as visible known residual. | I13: =EEFF!C64-EEFF!B64-(EEFF!C32+EEFF!C99) -> -920260 | J13: =EEFF!D64-EEFF!C64-(EEFF!D32+EEFF!D99) -> -1848213 | K13: =EEFF!E64-EEFF!D64-(EEFF!E32+EEFF!E99) -> -343879 | L13: =EEFF!F64-EEFF!E64-(EEFF!F32+EEFF!F99) -> -870085
A14: EQUITY_TOTAL_TIE | B14: UNIVERSAL | expected 0; hard_tie_tolerance. | source applies_to: all 16 | C14: =IF(SUMPRODUCT((ABS(H14:Q14)>1000)*1)=0,"PASS","FAIL") -> PASS | D14: hard | E14: 1000 USD | F14: 0 | G14: Componentes de patrimonio verificados numéricamente contra EEFF (partición exacta, todos los años hist). | H14: =SUM(ModeloFinanciero!B59,ModeloFinanciero!B60,ModeloFinanciero!B61,ModeloFinanciero!B62,ModeloFinanciero!B63,ModeloFinanciero!B64)-ModeloFinanciero!B65 -> 0 | I14: =SUM(ModeloFinanciero!C59,ModeloFinanciero!C60,ModeloFinanciero!C61,ModeloFinanciero!C62,ModeloFinanciero!C63,ModeloFinanciero!C64)-ModeloFinanciero!C65 -> 0 | J14: =SUM(ModeloFinanciero!D59,ModeloFinanciero!D60,ModeloFinanciero!D61,ModeloFinanciero!D62,ModeloFinanciero!D63,ModeloFinanciero!D64)-ModeloFinanciero!D65 -> 0 | K14: =SUM(ModeloFinanciero!E59,ModeloFinanciero!E60,ModeloFinanciero!E61,ModeloFinanciero!E62,ModeloFinanciero!E63,ModeloFinanciero!E64)-ModeloFinanciero!E65 -> 0 | L14: =SUM(ModeloFinanciero!F59,ModeloFinanciero!F60,ModeloFinanciero!F61,ModeloFinanciero!F62,ModeloFinanciero!F63,ModeloFinanciero!F64)-ModeloFinanciero!F65 -> 0 | M14: =SUM(ModeloFinanciero!G59,ModeloFinanciero!G60,ModeloFinanciero!G61,ModeloFinanciero!G62,ModeloFinanciero!G63,ModeloFinanciero!G64)-ModeloFinanciero!G65 -> 0 | N14: =SUM(ModeloFinanciero!H59,ModeloFinanciero!H60,ModeloFinanciero!H61,ModeloFinanciero!H62,ModeloFinanciero!H63,ModeloFinanciero!H64)-ModeloFinanciero!H65 -> 0 | O14: =SUM(ModeloFinanciero!I59,ModeloFinanciero!I60,ModeloFinanciero!I61,ModeloFinanciero!I62,ModeloFinanciero!I63,ModeloFinanciero!I64)-ModeloFinanciero!I65 -> 0 | ... Q14: =SUM(ModeloFinanciero!K59,ModeloFinanciero!K60,ModeloFinanciero!K61,ModeloFinanciero!K62,ModeloFinanciero!K63,ModeloFinanciero!K64)-ModeloFinanciero!K65 -> 0
A15: BS_LINEITEM_SUM_ASSETS | B15: UNIVERSAL | expected 0; hard_tie_tolerance. | source applies_to: all 16 | C15: =IF(SUMPRODUCT((ABS(H15:Q15)>1000)*1)=0,"PASS","FAIL") -> PASS | D15: hard | E15: 1000 USD | F15: 0 | G15: Partición top-level de activos verificada numéricamente contra EEFF (suma exacta a total de activos, todos los años hist). | H15: =SUM(ModeloFinanciero!B36,ModeloFinanciero!B37,ModeloFinanciero!B38,ModeloFinanciero!B39,ModeloFinanciero!B40,ModeloFinanciero!B41,ModeloFinanciero!B42,ModeloFinanciero!B43,ModeloFinanciero!B44,ModeloFinanciero!B45,ModeloFinanciero!B46)-ModeloFinanciero!B47 -> 0 | I15: =SUM(ModeloFinanciero!C36,ModeloFinanciero!C37,ModeloFinanciero!C38,ModeloFinanciero!C39,ModeloFinanciero!C40,ModeloFinanciero!C41,ModeloFinanciero!C42,ModeloFinanciero!C43,ModeloFinanciero!C44,ModeloFinanciero!C45,ModeloFinanciero!C46)-ModeloFinanciero!C47 -> 0 | J15: =SUM(ModeloFinanciero!D36,ModeloFinanciero!D37,ModeloFinanciero!D38,ModeloFinanciero!D39,ModeloFinanciero!D40,ModeloFinanciero!D41,ModeloFinanciero!D42,ModeloFinanciero!D43,ModeloFinanciero!D44,ModeloFinanciero!D45,ModeloFinanciero!D46)-ModeloFinanciero!D47 -> 0 | K15: =SUM(ModeloFinanciero!E36,ModeloFinanciero!E37,ModeloFinanciero!E38,ModeloFinanciero!E39,ModeloFinanciero!E40,ModeloFinanciero!E41,ModeloFinanciero!E42,ModeloFinanciero!E43,ModeloFinanciero!E44,ModeloFinanciero!E45,ModeloFinanciero!E46)-ModeloFinanciero!E47 -> 0 | L15: =SUM(ModeloFinanciero!F36,ModeloFinanciero!F37,ModeloFinanciero!F38,ModeloFinanciero!F39,ModeloFinanciero!F40,ModeloFinanciero!F41,ModeloFinanciero!F42,ModeloFinanciero!F43,ModeloFinanciero!F44,ModeloFinanciero!F45,ModeloFinanciero!F46)-ModeloFinanciero!F47 -> 0 | M15: =SUM(ModeloFinanciero!G36,ModeloFinanciero!G37,ModeloFinanciero!G38,ModeloFinanciero!G39,ModeloFinanciero!G40,ModeloFinanciero!G41,ModeloFinanciero!G42,ModeloFinanciero!G43,ModeloFinanciero!G44,ModeloFinanciero!G45,ModeloFinanciero!G46)-ModeloFinanciero!G47 -> 0 | N15: =SUM(ModeloFinanciero!H36,ModeloFinanciero!H37,ModeloFinanciero!H38,ModeloFinanciero!H39,ModeloFinanciero!H40,ModeloFinanciero!H41,ModeloFinanciero!H42,ModeloFinanciero!H43,ModeloFinanciero!H44,ModeloFinanciero!H45,ModeloFinanciero!H46)-ModeloFinanciero!H47 -> 0 | O15: =SUM(ModeloFinanciero!I36,ModeloFinanciero!I37,ModeloFinanciero!I38,ModeloFinanciero!I39,ModeloFinanciero!I40,ModeloFinanciero!I41,ModeloFinanciero!I42,ModeloFinanciero!I43,ModeloFinanciero!I44,ModeloFinanciero!I45,ModeloFinanciero!I46)-ModeloFinanciero!I47 -> 0 | ... Q15: =SUM(ModeloFinanciero!K36,ModeloFinanciero!K37,ModeloFinanciero!K38,ModeloFinanciero!K39,ModeloFinanciero!K40,ModeloFinanciero!K41,ModeloFinanciero!K42,ModeloFinanciero!K43,ModeloFinanciero!K44,ModeloFinanciero!K45,ModeloFinanciero!K46)-ModeloFinanciero!K47 -> 0
A16: BS_LINEITEM_SUM_LIAB_EQUITY | B16: UNIVERSAL | expected 0; hard_tie_tolerance. | source applies_to: all 16 | C16: =IF(SUMPRODUCT((ABS(H16:Q16)>1000)*1)=0,"PASS","FAIL") -> PASS | D16: hard | E16: 1000 USD | F16: 0 | G16: Pasivos + patrimonio verificados numéricamente contra EEFF (todos los años hist). | H16: =ModeloFinanciero!B58+ModeloFinanciero!B65-ModeloFinanciero!B66 -> 0 | I16: =ModeloFinanciero!C58+ModeloFinanciero!C65-ModeloFinanciero!C66 -> 0 | J16: =ModeloFinanciero!D58+ModeloFinanciero!D65-ModeloFinanciero!D66 -> 0 | K16: =ModeloFinanciero!E58+ModeloFinanciero!E65-ModeloFinanciero!E66 -> 0 | L16: =ModeloFinanciero!F58+ModeloFinanciero!F65-ModeloFinanciero!F66 -> 0 | M16: =ModeloFinanciero!G58+ModeloFinanciero!G65-ModeloFinanciero!G66 -> 0 | N16: =ModeloFinanciero!H58+ModeloFinanciero!H65-ModeloFinanciero!H66 -> 0 | O16: =ModeloFinanciero!I58+ModeloFinanciero!I65-ModeloFinanciero!I66 -> 0 | ... Q16: =ModeloFinanciero!K58+ModeloFinanciero!K65-ModeloFinanciero!K66 -> 0
A17: SOURCE_TIE_HISTORICAL | B17: UNIVERSAL | expected 0 for audited rows; SOURCE_GAP/WARN allowed only with explicit source-gap note. | source applies_to: all 16 | C17: =IF(SUMPRODUCT((ABS(H17:Q17)>100000)*1)=0,"PASS","FAIL") -> PASS | D17: hard | E17: 100000 USD | F17: 0 | G17: Audited rows tie to 0; only bank ending-cash-vs-EEFF cash rows may use the observed $100,000 hard threshold; SOURCE_GAP/WARN requires explicit source-gap note. | H17: =ModeloFinanciero!B47-EEFF!B47 -> 0 | I17: =ModeloFinanciero!C47-EEFF!C47 -> 0 | J17: =ModeloFinanciero!D47-EEFF!D47 -> 0 | K17: =ModeloFinanciero!E47-EEFF!E47 -> 0 | L17: =ModeloFinanciero!F47-EEFF!F47 -> 0
A18: NO_FORMULA_ERRORS | B18: UNIVERSAL | expected PASS/0; no masking. | source applies_to: all 16 | C18: =IF(SUMPRODUCT((ABS(H18:Q18)>0)*1)=0,"PASS","FAIL") -> PASS | D18: hard | E18: PASS | F18: PASS | G18: expected PASS/0; no masking. | H18: =0 -> 0 | I18: =0 -> 0 | J18: =0 -> 0 | K18: =0 -> 0 | L18: =0 -> 0 | M18: =0 -> 0 | N18: =0 -> 0 | O18: =0 -> 0 | ... Q18: =0 -> 0
A19: NO_CHECKS_MASTER_FAIL | B19: UNIVERSAL | expected PASS; status row should cite included/excluded rows. | source applies_to: all 16 | C19: =IF(SUMPRODUCT((ABS(H19:Q19)>0)*1)=0,"PASS","FAIL") -> PASS | D19: hard | E19: PASS | F19: PASS | G19: expected PASS; status row should cite included/excluded rows. | H19: =COUNTIF($C$6:$C$18,"FAIL")+COUNTIF($C$20:$C$29,"FAIL") -> 0 | I19: =COUNTIF($C$6:$C$18,"FAIL")+COUNTIF($C$20:$C$29,"FAIL") -> 0 | J19: =COUNTIF($C$6:$C$18,"FAIL")+COUNTIF($C$20:$C$29,"FAIL") -> 0 | K19: =COUNTIF($C$6:$C$18,"FAIL")+COUNTIF($C$20:$C$29,"FAIL") -> 0 | L19: =COUNTIF($C$6:$C$18,"FAIL")+COUNTIF($C$20:$C$29,"FAIL") -> 0 | M19: =COUNTIF($C$6:$C$18,"FAIL")+COUNTIF($C$20:$C$29,"FAIL") -> 0 | N19: =COUNTIF($C$6:$C$18,"FAIL")+COUNTIF($C$20:$C$29,"FAIL") -> 0 | O19: =COUNTIF($C$6:$C$18,"FAIL")+COUNTIF($C$20:$C$29,"FAIL") -> 0 | ... Q19: =COUNTIF($C$6:$C$18,"FAIL")+COUNTIF($C$20:$C$29,"FAIL") -> 0
A21: CONDITIONAL CHECKS
A22: LEASE_SCHEDULE_TIE | B22: ARCHETYPE/conditional | expected 0; hard_tie_tolerance. | source applies_to: IFRS-16 issuers | C22: SOURCE_GAP | D22: hard | E22: 1000 USD | F22: 0 | G22: No semantic anchors resolved for LEASE_SCHEDULE_TIE. | H22: =0 -> 0 | I22: =0 -> 0 | J22: =0 -> 0 | K22: =0 -> 0 | L22: =0 -> 0 | M22: =0 -> 0 | N22: =0 -> 0 | O22: =0 -> 0 | ... Q22: =0 -> 0
A23: DEBT_SCHEDULE_TIE | B23: ARCHETYPE/conditional | expected 0; hard_tie_tolerance; project-finance debt can include accrued interest/unamortized cost roles. | source applies_to: non-bank-lender, power, utility, operating-EBITDA with debt | C23: SOURCE_GAP | D23: hard | E23: 1000 USD | F23: 0 | G23: No semantic anchors resolved for DEBT_SCHEDULE_TIE. | H23: =0 -> 0 | I23: =0 -> 0 | J23: =0 -> 0 | K23: =0 -> 0 | L23: =0 -> 0 | M23: =0 -> 0 | N23: =0 -> 0 | O23: =0 -> 0 | ... Q23: =0 -> 0
A25: NON-BANK-LENDER CHECKS
A26: BANK_NET_LOANS | B26: ARCHETYPE | expected 0; hard_tie_tolerance. | source applies_to: bank, non-bank-lender with loan book | C26: SOURCE_GAP | D26: hard | E26: 1000 USD | F26: 0 | G26: No semantic anchors resolved for BANK_NET_LOANS. | H26: =0 -> 0 | I26: =0 -> 0 | J26: =0 -> 0 | K26: =0 -> 0 | L26: =0 -> 0 | M26: =0 -> 0 | N26: =0 -> 0 | O26: =0 -> 0 | ... Q26: =0 -> 0
A27: BANK_ALLOWANCE | B27: ARCHETYPE | expected 0 under observed sign convention. | source applies_to: bank, non-bank-lender | C27: SOURCE_GAP | D27: hard | E27: 1000 USD | F27: 0 | G27: No semantic anchors resolved for BANK_ALLOWANCE. | H27: =0 -> 0 | I27: =0 -> 0 | J27: =0 -> 0 | K27: =0 -> 0 | L27: =0 -> 0 | M27: =0 -> 0 | N27: =0 -> 0 | O27: =0 -> 0 | ... Q27: =0 -> 0
A28: BANK_NII_TIE | B28: ARCHETYPE | expected 0; hard_tie_tolerance. | source applies_to: bank, non-bank-lender where NIM build exists | C28: SOURCE_GAP | D28: hard | E28: 1000 USD | F28: 0 | G28: No semantic anchors resolved for BANK_NII_TIE. | H28: =0 -> 0 | I28: =0 -> 0 | J28: =0 -> 0 | K28: =0 -> 0 | L28: =0 -> 0 | M28: =0 -> 0 | N28: =0 -> 0 | O28: =0 -> 0 | ... Q28: =0 -> 0
A29: BANK_NPL_COVERAGE | B29: ARCHETYPE | must be >=0. | source applies_to: bank, non-bank-lender where NPL coverage is material | C29: SOURCE_GAP | D29: hard | E29: 0 cushion | F29: >=0 | G29: No semantic anchors resolved for BANK_NPL_COVERAGE. | H29: =0 -> 0 | I29: =0 -> 0 | J29: =0 -> 0 | K29: =0 -> 0 | L29: =0 -> 0 | M29: =0 -> 0 | N29: =0 -> 0 | O29: =0 -> 0 | ... Q29: =0 -> 0

Sheet Source_Register
A1: Corporación de Finanzas del País, S.A. (PANACREDIT) y Subsidiarias
A2: Source_Register — non-bank-lender archetype. Every row traces to a published filing (OCR text) or to a working file kept by the maintainer.
A3: Status semantics: OK = citation resolved to an existing artifact. SOURCE_GAP = traceability missing (visible, not hidden). NOT_DISCLOSED = no registration/manifest found for this issuer.
A4: source_id | B4: kind | C4: ticker | D4: filing | E4: year | F4: nota | G4: tabla_ocr | H4: feeds_sheet | I4: feeds_anchor | J4: date | K4: status | L4: evidence_count | M4: note
A5: OCR_ROOT:panacredit | B5: OCR_ROOT | C5: CFPAIS | H5: EEFF; Notas_EEFF | I5: OCR of the published filings; OCR of the published filings | J5: NOT_DISCLOSED | K5: OK | L5: 2 | M5: Annual reports (INA) of panacredit
A6: EEFF_FILING:ina_cfpais_2022_0 | B6: EEFF_FILING | C6: CFPAIS | D6: INA_CFPAIS_2022_0.pdf | E6: 2022 | G6: markdown.md | H6: EEFF; Notas_EEFF; MD&A | I6: 00-index.md; 01-eeff.md; 02-notas.md; 03-mda.md; 09-otros.md | J6: FY22 (A) | K6: OK | L6: 108 | M6: markdown.md sha256=6e31d3375f7e9ace...
A7: EEFF_FILING:ina_cfpais_2023_0 | B7: EEFF_FILING | C7: CFPAIS | D7: INA_CFPAIS_2023_0.pdf | E7: 2023 | G7: markdown.md | H7: EEFF; Notas_EEFF; MD&A | I7: 00-index.md; 01-eeff.md; 02-notas.md; 03-mda.md; 09-otros.md | J7: FY23 (A) | K7: OK | L7: 106 | M7: markdown.md sha256=8c31407000317145...
A8: EEFF_FILING:ina_cfpais_2024_0 | B8: EEFF_FILING | C8: CFPAIS | D8: INA_CFPAIS_2024_0.pdf | E8: 2024 | G8: markdown.md | H8: EEFF; Notas_EEFF; MD&A | I8: 00-index.md; 01-eeff.md; 02-notas.md; 03-mda.md; 09-otros.md | J8: FY24 (A) | K8: OK | L8: 102 | M8: markdown.md sha256=91f473de33cbfbf9...
A9: EEFF_FILING:ina_cfpais_2025_0 | B9: EEFF_FILING | C9: CFPAIS | D9: INA_CFPAIS_2025_0.pdf | E9: 2025 | G9: markdown.md | H9: EEFF; Notas_EEFF; MD&A | I9: 00-index.md; 01-eeff.md; 02-notas.md; 03-mda.md; 09-otros.md | J9: FY25 (A) | K9: OK | L9: 112 | M9: markdown.md sha256=9cef84601c972bf9...
A10: EEFF_FILING:prospecto_definitivo_bonos_50mm_smv332_24 | B10: EEFF_FILING | C10: CFPAIS | D10: Prospecto Definitivo Bonos 50MM SMV332-24.pdf | G10: markdown.md | H10: EEFF; Notas_EEFF; MD&A | I10: markdown.md | J10: NOT_DISCLOSED | K10: OK | L10: 80 | M10: markdown.md sha256=30717f9fe0311aab...
A11: NOTA:INA_CFPAIS_2022_0.pdf#1 | B11: NOTA | C11: CFPAIS | D11: INA_CFPAIS_2022_0.pdf | E11: 2022 | F11: 1 | G11: markdown.md | H11: Notas_EEFF | I11: 1. Información general | J11: FY22 (A) | K11: OK | L11: 22
A12: NOTA:INA_CFPAIS_2022_0.pdf#10 | B12: NOTA | C12: CFPAIS | D12: INA_CFPAIS_2022_0.pdf | E12: 2022 | F12: 10 | G12: markdown.md; tbl-30.html | H12: Notas_EEFF | I12: 10. Inversiones en valores medidas a valor razonable con cambios en resultados | J12: FY22 (A) | K12: OK | L12: 2
A13: NOTA:INA_CFPAIS_2022_0.pdf#11 | B13: NOTA | C13: CFPAIS | D13: INA_CFPAIS_2022_0.pdf | E13: 2022 | F13: 11 | G13: markdown.md; tbl-31.html | H13: Notas_EEFF | I13: 11. Inversiones en valores medidas a costo amortizado | J13: FY22 (A) | K13: OK | L13: 3
A14: NOTA:INA_CFPAIS_2022_0.pdf#12 | B14: NOTA | C14: CFPAIS | D14: INA_CFPAIS_2022_0.pdf | E14: 2022 | F14: 12 | G14: markdown.md; tbl-32.html; tbl-33.html; +1 more | H14: Notas_EEFF | I14: 12. Préstamos a clientes | J14: FY22 (A) | K14: OK | L14: 8
A15: NOTA:INA_CFPAIS_2022_0.pdf#13 | B15: NOTA | C15: CFPAIS | D15: INA_CFPAIS_2022_0.pdf | E15: 2022 | F15: 13 | G15: markdown.md; tbl-35.html | H15: Notas_EEFF | I15: 13. Financiamientos recibidos | J15: FY22 (A) | K15: OK | L15: 3
A16: NOTA:INA_CFPAIS_2022_0.pdf#14 | B16: NOTA | C16: CFPAIS | D16: INA_CFPAIS_2022_0.pdf | E16: 2022 | F16: 14 | G16: markdown.md | H16: Notas_EEFF | I16: 14. Documentos por pagar | J16: FY22 (A) | K16: OK | L16: 1
A17: NOTA:INA_CFPAIS_2022_0.pdf#15 | B17: NOTA | C17: CFPAIS | D17: INA_CFPAIS_2022_0.pdf | E17: 2022 | F17: 15 | G17: markdown.md; tbl-36.html; tbl-37.html; +1 more | H17: Notas_EEFF | I17: 15. Valores comerciales negociables | J17: FY22 (A) | K17: OK | L17: 7
A18: NOTA:INA_CFPAIS_2022_0.pdf#16 | B18: NOTA | C18: CFPAIS | D18: INA_CFPAIS_2022_0.pdf | E18: 2022 | F18: 16 | G18: markdown.md; tbl-39.html; tbl-40.html; +1 more | H18: Notas_EEFF | I18: 16. Bonos corporativos | J18: FY22 (A) | K18: OK | L18: 8
A19: NOTA:INA_CFPAIS_2022_0.pdf#17 | B19: NOTA | C19: CFPAIS | D19: INA_CFPAIS_2022_0.pdf | E19: 2022 | F19: 17 | G19: markdown.md; tbl-42.html; tbl-43.html | H19: Notas_EEFF | I19: 17. Bonos perpetuos | J19: FY22 (A) | K19: OK | L19: 5
A20: NOTA:INA_CFPAIS_2022_0.pdf#18 | B20: NOTA | C20: CFPAIS | D20: INA_CFPAIS_2022_0.pdf | E20: 2022 | F20: 18 | G20: markdown.md; tbl-44.html; tbl-45.html; +5 more | H20: Notas_EEFF | I20: 18. Patrimonio | J20: FY22 (A) | K20: OK | L20: 20
A21: NOTA:INA_CFPAIS_2022_0.pdf#19 | B21: NOTA | C21: CFPAIS | D21: INA_CFPAIS_2022_0.pdf | E21: 2022 | F21: 19 | G21: markdown.md; tbl-51.html | H21: Notas_EEFF | I21: 19. Gastos de personal | J21: FY22 (A) | K21: OK | L21: 2
A22: NOTA:INA_CFPAIS_2022_0.pdf#2 | B22: NOTA | C22: CFPAIS | D22: INA_CFPAIS_2022_0.pdf | E22: 2022 | F22: 2 | G22: markdown.md | H22: Notas_EEFF | I22: 2. Base de preparación | J22: FY22 (A) | K22: OK | L22: 24
