Workbook

Sheet 00_Cover
A1: Banco de Bogotá S.A. y Subsidiarias — Institutional Financial Model (elevated to statement-grade)
A2: Banking (Colombia) | Native currency COP millions | USD memo overlay | As of 2026-07-21
A4: Model field | B4: Value
A5: Issuer | B5: Banco de Bogotá S.A. y Subsidiarias (consolidado)
A6: Parent group | B6: Grupo Aval Acciones y Valores S.A.
A7: Model archetype | B7: Banking institution — 3-statement audited history + sector schedules (cartera, fondeo, NIM, calidad de cartera, capital)
A8: Reporting/native currency | B8: COP millions (statements are COP-native; no USD convenience translation in the audited source)
A9: USD overlay | B9: Memo-only, implied closing TRM rates per notes (see USD_Translation, Sources_Audited)
A10: Historical coverage | B10: FY2023A-FY2025A, audited consolidated IS/CI/SCE/BS/CF, entered as published constants (FY2022 comparative not available as primary statements in the source set — see Sources_Audited gap note)
A11: Forecast coverage | B11: PARTIAL — FY2026E-FY2030E income-statement/ratio proxy only (Assumptions_Forecast), driver-built off explicit Base/Bull/Bear scenarios. No projected balance sheet, capital, funding or cash flow. Not decision-ready as a forecast.
A12: Tie-out status | B12: PASS — 36/36 hard tie-outs pass in Checks_TieOut (statement internal consistency, cross-statement, and schedule-to-statement reconciliations)
A13: Primary sources | B13: bancodebogota.com IR — FY2023/FY2024/FY2025 audited consolidated EEFF + notas + dictamen del revisor fiscal (KPMG). See Sources_Audited for exact citations.
A14: Known limitations | B14: FY2022 not incorporated (source PDF lacked primary statement pages); FY2023 loan-book/credit-quality stage-level detail not available; NIM computed on period-end (not average) balances; forecast is PARTIAL (P&L/ratio proxy, not full 3-statement).
A15: Sheet map | B15: Sources_Audited, IS_Hist, CI_Hist, SCE_Hist, BS_Hist, CF_Hist, USD_Translation, Loan_Book, Deposits_Funding, NIM_Build, Credit_Quality, Capital_Adequacy, Checks_TieOut, Assumptions_Forecast (PARTIAL), Change_Log

Sheet Change_Log
A1: Change log and governance
A2: Version history and model-owner review record.
A4: Date | B4: Version | C4: Author | D4: Change | E4: Evidence | F4: Reviewer status
A5: 2026-07-15 | B5: 1.0 | C5: Codex | D5: Initial institutional model framework and source pack | E5: https://www.grupoaval.com/inversionistas | F5: Builder-verified
A6: 46224 | B6: 2 | C6: Claude (run 41538014) | D6: Elevation to statement-grade IG (Samsung pilot pattern, bank flavor): replaced placeholder framework (Sources/Historical/Assumptions/Forecast/Valuation/Sensitivity/Checks/Sector_KPIs — all-blank) with audited FY2023A-FY2025A consolidated IS_Hist/CI_Hist/SCE_Hist/BS_Hist/CF_Hist (COP mm, published constants), Loan_Book/Deposits_Funding/NIM_Build/Credit_Quality/Capital_Adequacy schedules, USD_Translation (implied closing-TRM memo overlay), Checks_TieOut (36 tie-outs incl. cross-statement + schedule reconciliation, all PASS), Sources_Audited (file/page citations + audit-signal notes on FY2024 re-presentation between vintages), Assumptions_Forecast (PARTIAL — P&L/ratio proxy only, explicitly flagged, not full 3-statement forecast). Root model untouched; v2 saved under the maintainer's archive. Built via Mog SDK only (openpyxl/LibreOffice not used). | E6: bancodebogota.com IR — FY2023/FY2024/FY2025 audited consolidated EEFF + notas + dictamen | F6: Builder-verified (36/36 tie-outs PASS post wb.calculate())
A7: 46248 | B7: 2.1 | C7: Claude Opus 5 (auditoria Ola 2) | D7: Verificacion del defecto /1000 en USD_Translation. Las formulas de la fila 6 (total activos), 7 (total patrimonio) y 10 (utilidad neta) ya dividen la fuente COP-millones unicamente por la TRM de la fila 5, sin el /1000 espurio; recomputo independiente confirma los tres anos (FY2023A/FY2024A/FY2025A). Se corrigio el puntero de evidencia de la nota A3, que citaba un archivo inexistente. Se anadieron 3 tie-outs vivos (Checks_TieOut 43-45) que recomputan cada cifra USD desde BS_Hist/IS_Hist y la TRM, para que una reintroduccion del /1000 falle el MASTER. Sin cambios a estados historicos ni a cifras publicadas. | E7: BS_Hist!B19:D19, BS_Hist!B48:D48, IS_Hist!B20:D20, USD_Translation!B5:D5 | F7: Builder-verified (41/41 tie-outs PASS post wb.calculate())

Sheet IS_Hist
A1: Banco de Bogotá y Subsidiarias — Estado Consolidado del Resultado (auditado)
A2: COP millones. FY2023A/FY2024A per FY2024 annual report (originally published, pre-discontinued-ops split); FY2025A per FY2025 annual report (continuing operations + discontinued ops shown separately, per IFRS 5).
A4: Line item | B4: FY2023A | C4: FY2024A | D4: FY2025A | F4: Note ref
A5: Total ingresos por intereses | B5: 14381561 | C5: 14396101 | D5: 12215662 | F5: 10/11
A6: Total gastos por intereses | B6: -9345442 | C6: -9147250 | D6: -7471702 | F6: 10/11
A7: Ingresos por intereses, neto | B7: 5036119 | C7: 5248851 | D7: 4743960
A8: Provisión/deterioro de activos financieros, neto | B8: -2561892 | C8: -2496951 | D8: -2290075 | F8: 10.5/11
A9: Recuperación de castigos de activos financieros | B9: 265869 | C9: 280338 | D9: 416761 | F9: 10.6
A10: Ingresos por intereses después de deterioro, neto | B10: 2740096 | C10: 3032238 | D10: 2870646
A11: Ingresos por comisiones y honorarios, neto | B11: 1471621 | C11: 1463303 | D11: 1306279 | F11: 28/29
A12: (Gasto) ingreso de activos y pasivos financieros negociables, neto | B12: -2050745 | C12: 20205 | D12: -70488 | F12: 29/30
A13: Ingreso (gasto) por diferencia en cambio, neto | B13: 1663552 | C13: -304676 | D13: 393112 | F13: 30/31
A14: Otros ingresos, neto | B14: 1193607 | C14: 904730 | D14: 611037 | F14: 31/32
A15: Otros gastos | B15: -3721567 | C15: -3851708 | D15: -3696808 | F15: 32/33
A16: Utilidad antes de impuesto a las ganancias | B16: 1296564 | C16: 1264092 | D16: 1413778
A17: Gasto por impuesto a las ganancias | B17: -327630 | C17: -165844 | D17: -164800 | F17: 19/18
A18: Utilidad neta del ejercicio de operaciones que continúan | B18: 968934 | C18: 1098248 | D18: 1248978
A19: Ganancia procedente de operaciones discontinuadas, neta de impuestos | D19: 26646 | F19: 2.1
A20: Utilidad neta del ejercicio | B20: 968934 | C20: 1098248 | D20: 1275624
A22: Utilidad neta del ejercicio atribuible a:
A23: Accionistas de la controladora | B23: 954136 | C23: 1090198 | D23: 1270063
A24: Participaciones no controladoras | B24: 14798 | C24: 8050 | D24: 5561 | F24: 27

Sheet CI_Hist
A1: Banco de Bogotá y Subsidiarias — Estado Consolidado del Resultado Integral (auditado)
A2: COP millones. Same source basis as IS_Hist.
A4: Line item | B4: FY2023A | C4: FY2024A | D4: FY2025A | F4: Note ref
A5: Utilidad neta del ejercicio | B5: 968934 | C5: 1098248 | D5: 1275624
A6: Partidas que pueden ser posteriormente reclasificadas a resultados
A7: Contabilidad de coberturas, neto | B7: -49202 | C7: 53140 | D7: 63419 | F7: 9.4.3/10.4.3
A8: Diferencia en cambio en conversión de estados financieros de agencias/sucursal | B8: -152838 | C8: 64956 | D8: -129556 | F8: 19.5,26/18.5,25
A9: (Pérdida) ganancia no realizada por medición de instrumentos de deuda a VR | B9: 677964 | C9: 26442 | D9: -57676 | F9: 19.5,26/18.5,25
A10: Reclasificación a resultados por deterioro de instrumentos de deuda a VR | B10: 1497 | C10: 3094 | D10: 4480 | F10: 19.5,26/18.5,25
A11: Participación en otro resultado integral de asociadas (reclasificable) | B11: 67609 | C11: 162344 | D11: 43137 | F11: 13.1/13.2
A12: Impuesto a las ganancias (partidas reclasificables) | B12: -451316 | C12: 172732 | D12: -122715 | F12: 19.5,26/18.5,25
A13: Total partidas que pueden ser reclasificadas a resultados | B13: 93714 | C13: 482708 | D13: -198911
A14: Partidas que no serán reclasificadas a resultados
A15: Cambios en supuestos actuariales en planes de beneficios definidos | B15: -19897 | C15: -1374 | D15: 1932 | F15: 19.5,26/18.5,25
A16: (Pérdida) ganancia no realizada por medición de inversiones a VR en patrimonio | B16: 26602 | C16: 26818 | D16: -399 | F16: 19.5,26/18.5,25
A17: Participación en otro resultado integral de asociadas (no reclasificable) | B17: 10405 | C17: -8956 | D17: 52 | F17: 13.1/13.2
A18: Impuesto a las ganancias (partidas no reclasificables) | B18: 3752 | C18: -4259 | D18: -658 | F18: 19.5,26/18.5,25
A19: Total partidas que no serán reclasificadas a resultados | B19: 20862 | C19: 12229 | D19: 927
A20: Total otro resultado integral, neto de impuestos | B20: 114576 | C20: 494937 | D20: -197984 | F20: 25/26
A21: Resultado integral total | B21: 1083510 | C21: 1593185 | D21: 1077640
A22: Resultado integral atribuible a:
A23: Accionistas de la controladora | B23: 1070092 | C23: 1583685 | D23: 1072807
A24: Participaciones no controladoras | B24: 13418 | C24: 9500 | D24: 4833

Sheet BS_Hist
A1: Banco de Bogotá y Subsidiarias — Estado Consolidado de Situación Financiera (auditado)
A2: COP millones, al 31 de diciembre. FY2023A/FY2024A per FY2024 annual report; FY2025A per FY2025 annual report. "M:" rows are memo detail (sub-components already included in their parent total; excluded from tie-out SUM ranges). Blank = line not presented that year (see Sources_Audited note on 2025 re-presentation).
A4: Line item | B4: FY2023A | C4: FY2024A | D4: FY2025A | F4: Note ref
A5: Activos
A6: Efectivo y equivalentes al efectivo | B6: 8133342 | C6: 7022388 | D6: 9226407 | F6: 8/9
A7: Activos financieros de inversión y derivados | B7: 18031032 | C7: 22230623 | D7: 21053279 | F7: 9/10
A8: Cartera de créditos y arrendamiento financiero, neta | B8: 93586560 | C8: 102103120 | D8: 90910760 | F8: 10/11
A9: Otras cuentas por cobrar, neto | B9: 3580401 | C9: 3700933 | D9: 2785285 | F9: 11/12
A10: Activos no corrientes mantenidos para la venta (regular) | B10: 76024 | C10: 77819 | F10: 12
A11: Inversiones en asociadas y negocios conjuntos | B11: 9109180 | C11: 9516086 | D11: 9891486 | F11: 13
A12: Propiedades, planta y equipo | B12: 946477 | C12: 960535 | D12: 568571 | F12: 14
A13: Activos por derecho de uso | B13: 470319 | C13: 497269 | D13: 432061 | F13: 15
A14: Propiedades de inversión | B14: 209547 | C14: 215988 | F14: 16/19.2
A15: Intangibles | B15: 1504213 | C15: 1709708 | D15: 1507444 | F15: 17-18/16
A16: Activos no corrientes mantenidos para la venta — operación discontinua | D16: 18199621 | F16: 17/2.1
A17: Impuesto a las ganancias | B17: 1686333 | C17: 2496470 | D17: 1402213 | F17: 19/18
A18: Otros activos | B18: 140608 | C18: 188688 | D18: 187232
A19: Total activos | B19: 137474036 | C19: 150719627 | D19: 156164359
A21: Cartera — repos/interbancarios/overnight (de los cuales) | B21: 237855 | C21: 227912 | D21: 13871
A22: Cartera — clientes y operaciones de leasing (de los cuales) | B22: 93348705 | C22: 101875208 | D22: 90896889
A23: Intangibles — plusvalía (de los cuales) | B23: 605129 | C23: 626515 | D23: 465905
A24: Intangibles — otros intangibles (de los cuales) | B24: 899084 | C24: 1083193 | D24: 1041539
A26: Pasivos
A27: Pasivos financieros derivados | B27: 1033907 | C27: 394985 | D27: 399138 | F27: 9.4/10
A28: Pasivos financieros a costo amortizado | B28: 116661327 | C28: 130101835 | D28: 119016228
A29: Beneficios a empleados | B29: 255186 | C29: 282020 | D29: 267086 | F29: 22/-
A30: Provisiones (partida separada) | B30: 41728 | C30: 40327 | F30: 23/-
A31: Pasivos no corrientes mantenidos para la venta — operación discontinua | D31: 16459367 | F31: -/17
A32: Impuesto a las ganancias (pasivo) | B32: 89745 | C32: 74091 | D32: 7523 | F32: 19/18
A33: Cuentas por pagar y otros pasivos | B33: 3623121 | C33: 2983991 | D33: 2721253 | F33: 24/23
A34: Total pasivos | B34: 121705014 | C34: 133877249 | D34: 138870595
A36: Costo amortizado — depósitos de clientes (de los cuales) | B36: 91083792 | C36: 104258975 | D36: 98086011 | F36: 20
A37: Costo amortizado — obligaciones financieras (de los cuales) | B37: 24862230 | C37: 25083047 | D37: 20230822 | F37: 21
A38: Costo amortizado — pasivo por arrendamiento (de los cuales) | B38: 715305 | C38: 759813 | D38: 699395 | F38: 21.5
A40: Patrimonio
A41: Capital suscrito y pagado | B41: 3553 | C41: 3553 | D41: 3553 | F41: 25.1/24.1
A42: Prima en colocación de acciones | B42: 6781641 | C42: 6781641 | D42: 6781641 | F42: 25.1/24.1
A43: Ganancias de ejercicios anteriores | B43: 8442095 | C43: 8880493 | D43: 9350671 | F43: 25.2/24.2
A44: Utilidad neta del ejercicio | B44: 954136 | C44: 1090198 | D44: 1270063
A45: Otro resultado integral | B45: -470967 | C45: 22520 | D45: -174736 | F45: 26/25
...

Sheet CF_Hist
A1: Banco de Bogotá y Subsidiarias — Estado Consolidado de Flujos de Efectivo (auditado)
A2: COP millones. Same source-vintage basis as IS_Hist. Signs as published (outflows/decreases negative).
A4: Line item | B4: FY2023A | C4: FY2024A | D4: FY2025A | F4: Note ref
A5: Actividades de operación
A6: Utilidad neta del ejercicio | B6: 968934 | C6: 1098248 | D6: 1275624
A7: Deterioro cartera de crédito y otras cuentas por cobrar | B7: 2562522 | C7: 2493807 | F7: 10/11
A8: Provisión para deterioro de activos financieros, neto | D8: 2284768 | F8: 11/12
A9: Depreciación y amortización | B9: 290072 | C9: 300447 | D9: 301437 | F9: 14,15,18/14,15,16.2
A10: Ingresos por intereses | B10: -14381561 | C10: -14396101 | D10: -12215662
A11: Gastos por intereses | B11: 9345442 | C11: 9147250 | D11: 7471702 | F11: 20.21
A12: Gasto por impuesto a las ganancias | B12: 327630 | C12: 165844 | D12: 164800 | F12: 19/18
A13: (Ingreso) gasto por diferencia en cambio, neto | B13: -1663552 | C13: 304676 | D13: -393112 | F13: 30/28
A14: Dividendos causados | B14: -20839 | C14: -21711 | D14: -13776
A15: Participación en el resultado de asociadas y negocios conjuntos | B15: -565042 | C15: -382989 | D15: -485358 | F15: 31/30
A16: Ganancia procedente de operaciones discontinuadas, neta de impuestos | D16: -26646 | F16: 2.1
A17: Cambios en el valor razonable sobre derivados | B17: 2211571 | C17: 95546 | D17: 255288
A18: Otros ajustes para conciliar la utilidad del ejercicio | B18: -231254 | C18: -83356 | D18: -45045
A19: Aumento en instrumentos financieros derivados | B19: -1712475 | C19: -418457 | D19: -186098
A20: Aumento en activos financieros de inversión | B20: -32318 | C20: -81947 | D20: -1121785
A21: Aumento en cartera de crédito y arrendamiento financiero | B21: -5768258 | C21: -7655635 | D21: -9494525
A22: (Aumento) disminución en cuentas por cobrar | B22: -841670 | C22: 193858 | D22: -327655
A23: Disminución en otros activos | B23: 80124 | C23: 11753 | D23: 47263
A24: Aumento en depósitos de clientes | B24: 9107131 | C24: 9026436 | D24: 10516123
A25: Aumento (disminución) en préstamos interbancarios y overnight | B25: 3203051 | C25: -498777 | D25: 774803
A26: Aumento (disminución) en cuentas por pagar y otros pasivos | B26: 729243 | C26: -645392 | D26: 916868
A27: Aumento (disminución) en beneficios a los empleados | B27: 4303 | C27: 7359 | D27: -128481
A28: Intereses recibidos | B28: 14021474 | C28: 15474455 | D28: 12577314
... A31: Impuesto a las ganancias pagado | B31: -709290 | C31: -743441 | D31: -696144
A32: Efectivo neto provisto por las actividades de operación | B32: 8700809 | C32: 4449684 | D32: 3444202 | F32: 2.1
A34: Actividades de inversión
A35: Aumento de inversiones a valor razonable | B35: -453561 | C35: -4614749 | D35: -191767
A36: Adquisición de inversiones a costo amortizado | B36: -3858050 | C36: -3478489 | D36: -3608091
A37: Adquisición de propiedades, planta y equipo | B37: -127350 | C37: -155467 | D37: -77655 | F37: 14
A38: Adquisición de propiedades de inversión | B38: 0 | C38: -20 | D38: -7989 | F38: 19.2
A39: Adquisición y/o desarrollo de activos intangibles | B39: -253614 | C39: -268401 | D39: -214219 | F39: 18/16.2
A40: Redención de inversiones a costo amortizado | B40: 3904374 | C40: 3647840 | D40: 3956812
A41: Producto de la venta de activos no financieros | B41: 77147 | C41: 81563 | D41: 141925
A42: Capitalización de compañías asociadas | B42: -2433 | C42: -2487 | D42: -100 | F42: 13
A43: Aumento del efectivo por efecto de la operación discontinua | D43: 401098 | F43: 17
A44: Efectivo neto provisto por (utilizado en) las actividades de inversión | B44: -713487 | C44: -4790210 | D44: 400014 | F44: 2.1
...

Sheet SCE_Hist
A1: Banco de Bogotá y Subsidiarias — Estado Consolidado de Cambios en el Patrimonio (auditado, condensado)
A2: COP millones. Condensed to total-equity roll-forward (controladora + NCI); ties to BS_Hist Total patrimonio. Full column-level (capital/prima/ganancias/ORI) detail available in source PDFs pp.9-11 (FY25) / pp.11 (FY24) but not reproduced line-by-line here.
A4: Line item | B4: FY2023A | C4: FY2024A | D4: FY2025A | F4: Note ref
A5: Patrimonio total — saldo inicial del año | B5: 15810561 | C5: 15769022 | D5: 16842378
A6: Traslado de resultado del ejercicio a ganancias de ejercicios anteriores | B6: 0 | C6: 0 | D6: 0
A7: Dividendos declarados | B7: -1112646 | C7: -519909 | D7: -628634 | F7: 25.3/24.3
A8: Otros | B8: -11556 | C8: 8609 | D8: 3233
A9: Utilidad neta del ejercicio (resultado integral) | B9: 968934 | C9: 1098248 | D9: 1275624
A10: Otro resultado integral (resultado integral) | B10: 114576 | C10: 494937 | D10: -197984
A11: Resultado integral total | B11: 1083510 | C11: 1593185 | D11: 1077640
A12: Realización de ORI a ganancias de ejercicios anteriores | B12: -847 | C12: -8529 | D12: -853 | F12: 25/24.2
A13: Patrimonio total — saldo final del año | B13: 15769022 | C13: 16842378 | D13: 17293764

Sheet Checks_TieOut
A1: Tie-out checks — audited historical statements (all deltas must be 0 within tolerance; COP millions)
A2: MASTER | B2: =IF(COUNTIF(G5:G45,"FAIL")=0,"OK — ALL HARD TIE-OUTS PASS","FAIL") -> OK — ALL HARD TIE-OUTS PASS
A4: Check | B4: FY2023A | C4: FY2024A | D4: FY2025A | F4: Tolerance | G4: Status
A5: IS: Ingresos por intereses neto = Total ingresos + Total gastos | B5: =IS_Hist!B5+IS_Hist!B6-IS_Hist!B7 -> 0 | C5: =IS_Hist!C5+IS_Hist!C6-IS_Hist!C7 -> 0 | D5: =IS_Hist!D5+IS_Hist!D6-IS_Hist!D7 -> 0 | F5: 1 | G5: =IF(AND(ABS(N(B5))<=$F5,ABS(N(C5))<=$F5,ABS(N(D5))<=$F5),"PASS","FAIL") -> PASS
A6: IS: Ingresos después de deterioro = neto + provisión + recuperación castigos | B6: =IS_Hist!B7+IS_Hist!B8+IS_Hist!B9-IS_Hist!B10 -> 0 | C6: =IS_Hist!C7+IS_Hist!C8+IS_Hist!C9-IS_Hist!C10 -> 0 | D6: =IS_Hist!D7+IS_Hist!D8+IS_Hist!D9-IS_Hist!D10 -> 0 | F6: 1 | G6: =IF(AND(ABS(N(B6))<=$F6,ABS(N(C6))<=$F6,ABS(N(D6))<=$F6),"PASS","FAIL") -> PASS
A7: IS: Utilidad antes de impuesto = cadena completa | B7: =IS_Hist!B10+IS_Hist!B11+IS_Hist!B12+IS_Hist!B13+IS_Hist!B14+IS_Hist!B15-IS_Hist!B16 -> 0 | C7: =IS_Hist!C10+IS_Hist!C11+IS_Hist!C12+IS_Hist!C13+IS_Hist!C14+IS_Hist!C15-IS_Hist!C16 -> 0 | D7: =IS_Hist!D10+IS_Hist!D11+IS_Hist!D12+IS_Hist!D13+IS_Hist!D14+IS_Hist!D15-IS_Hist!D16 -> 0 | F7: 1 | G7: =IF(AND(ABS(N(B7))<=$F7,ABS(N(C7))<=$F7,ABS(N(D7))<=$F7),"PASS","FAIL") -> PASS
A8: IS: Utilidad neta operaciones continuas = UAI + gasto impuesto | B8: =IS_Hist!B16+IS_Hist!B17-IS_Hist!B18 -> 0 | C8: =IS_Hist!C16+IS_Hist!C17-IS_Hist!C18 -> 0 | D8: =IS_Hist!D16+IS_Hist!D17-IS_Hist!D18 -> 0 | F8: 1 | G8: =IF(AND(ABS(N(B8))<=$F8,ABS(N(C8))<=$F8,ABS(N(D8))<=$F8),"PASS","FAIL") -> PASS
A9: IS: Utilidad neta ejercicio = continuas + discontinuadas | B9: =IS_Hist!B18+N(IS_Hist!B19)-IS_Hist!B20 -> 0 | C9: =IS_Hist!C18+N(IS_Hist!C19)-IS_Hist!C20 -> 0 | D9: =IS_Hist!D18+N(IS_Hist!D19)-IS_Hist!D20 -> 0 | F9: 1 | G9: =IF(AND(ABS(N(B9))<=$F9,ABS(N(C9))<=$F9,ABS(N(D9))<=$F9),"PASS","FAIL") -> PASS
A10: IS: Utilidad neta = controladora + NCI | B10: =IS_Hist!B23+IS_Hist!B24-IS_Hist!B20 -> 0 | C10: =IS_Hist!C23+IS_Hist!C24-IS_Hist!C20 -> 0 | D10: =IS_Hist!D23+IS_Hist!D24-IS_Hist!D20 -> 0 | F10: 1 | G10: =IF(AND(ABS(N(B10))<=$F10,ABS(N(C10))<=$F10,ABS(N(D10))<=$F10),"PASS","FAIL") -> PASS
A11: CI: Total reclasificables = suma componentes | B11: =SUM(CI_Hist!B7:B12)-CI_Hist!B13 -> 0 | C11: =SUM(CI_Hist!C7:C12)-CI_Hist!C13 -> 0 | D11: =SUM(CI_Hist!D7:D12)-CI_Hist!D13 -> 0 | F11: 1 | G11: =IF(AND(ABS(N(B11))<=$F11,ABS(N(C11))<=$F11,ABS(N(D11))<=$F11),"PASS","FAIL") -> PASS
A12: CI: Total no reclasificables = suma componentes | B12: =SUM(CI_Hist!B15:B18)-CI_Hist!B19 -> 0 | C12: =SUM(CI_Hist!C15:C18)-CI_Hist!C19 -> 0 | D12: =SUM(CI_Hist!D15:D18)-CI_Hist!D19 -> 0 | F12: 1 | G12: =IF(AND(ABS(N(B12))<=$F12,ABS(N(C12))<=$F12,ABS(N(D12))<=$F12),"PASS","FAIL") -> PASS
A13: CI: Total ORI = reclasificables + no reclasificables | B13: =CI_Hist!B13+CI_Hist!B19-CI_Hist!B20 -> 0 | C13: =CI_Hist!C13+CI_Hist!C19-CI_Hist!C20 -> 0 | D13: =CI_Hist!D13+CI_Hist!D19-CI_Hist!D20 -> 0 | F13: 1 | G13: =IF(AND(ABS(N(B13))<=$F13,ABS(N(C13))<=$F13,ABS(N(D13))<=$F13),"PASS","FAIL") -> PASS
A14: CI: Resultado integral total = NI + ORI | B14: =CI_Hist!B5+CI_Hist!B20-CI_Hist!B21 -> 0 | C14: =CI_Hist!C5+CI_Hist!C20-CI_Hist!C21 -> 0 | D14: =CI_Hist!D5+CI_Hist!D20-CI_Hist!D21 -> 0 | F14: 1 | G14: =IF(AND(ABS(N(B14))<=$F14,ABS(N(C14))<=$F14,ABS(N(D14))<=$F14),"PASS","FAIL") -> PASS
A15: CI: Resultado integral = controladora + NCI | B15: =CI_Hist!B23+CI_Hist!B24-CI_Hist!B21 -> 0 | C15: =CI_Hist!C23+CI_Hist!C24-CI_Hist!C21 -> 0 | D15: =CI_Hist!D23+CI_Hist!D24-CI_Hist!D21 -> 0 | F15: 1 | G15: =IF(AND(ABS(N(B15))<=$F15,ABS(N(C15))<=$F15,ABS(N(D15))<=$F15),"PASS","FAIL") -> PASS
A16: BS: Total activos = suma de rubros | B16: =SUM(BS_Hist!B6:B18)-BS_Hist!B19 -> 0 | C16: =SUM(BS_Hist!C6:C18)-BS_Hist!C19 -> 0 | D16: =SUM(BS_Hist!D6:D18)-BS_Hist!D19 -> 0 | F16: 1 | G16: =IF(AND(ABS(N(B16))<=$F16,ABS(N(C16))<=$F16,ABS(N(D16))<=$F16),"PASS","FAIL") -> PASS
A17: BS: Total pasivos = suma de rubros | B17: =SUM(BS_Hist!B27:B33)-BS_Hist!B34 -> 0 | C17: =SUM(BS_Hist!C27:C33)-BS_Hist!C34 -> 0 | D17: =SUM(BS_Hist!D27:D33)-BS_Hist!D34 -> 0 | F17: 1 | G17: =IF(AND(ABS(N(B17))<=$F17,ABS(N(C17))<=$F17,ABS(N(D17))<=$F17),"PASS","FAIL") -> PASS
A18: BS: Patrimonio controladora = suma de componentes | B18: =SUM(BS_Hist!B41:B45)-BS_Hist!B46 -> 0 | C18: =SUM(BS_Hist!C41:C45)-BS_Hist!C46 -> 0 | D18: =SUM(BS_Hist!D41:D45)-BS_Hist!D46 -> 0 | F18: 1 | G18: =IF(AND(ABS(N(B18))<=$F18,ABS(N(C18))<=$F18,ABS(N(D18))<=$F18),"PASS","FAIL") -> PASS
A19: BS: Total patrimonio = controladora + NCI | B19: =BS_Hist!B46+BS_Hist!B47-BS_Hist!B48 -> 0 | C19: =BS_Hist!C46+BS_Hist!C47-BS_Hist!C48 -> 0 | D19: =BS_Hist!D46+BS_Hist!D47-BS_Hist!D48 -> 0 | F19: 1 | G19: =IF(AND(ABS(N(B19))<=$F19,ABS(N(C19))<=$F19,ABS(N(D19))<=$F19),"PASS","FAIL") -> PASS
A20: BS: Total pasivo y patrimonio = pasivos + patrimonio | B20: =BS_Hist!B34+BS_Hist!B48-BS_Hist!B49 -> 0 | C20: =BS_Hist!C34+BS_Hist!C48-BS_Hist!C49 -> 0 | D20: =BS_Hist!D34+BS_Hist!D48-BS_Hist!D49 -> 0 | F20: 1 | G20: =IF(AND(ABS(N(B20))<=$F20,ABS(N(C20))<=$F20,ABS(N(D20))<=$F20),"PASS","FAIL") -> PASS
A21: BS: Balance (Total activos − Total pasivo y patrimonio) | B21: =BS_Hist!B19-BS_Hist!B49 -> 0 | C21: =BS_Hist!C19-BS_Hist!C49 -> 0 | D21: =BS_Hist!D19-BS_Hist!D49 -> 0 | F21: 1 | G21: =IF(AND(ABS(N(B21))<=$F21,ABS(N(C21))<=$F21,ABS(N(D21))<=$F21),"PASS","FAIL") -> PASS
A22: CF: CFO = suma conciliación + capital de trabajo + intereses/dividendos/impuesto | B22: =SUM(CF_Hist!B6:B31)-CF_Hist!B32 -> 0 | C22: =SUM(CF_Hist!C6:C31)-CF_Hist!C32 -> 0 | D22: =SUM(CF_Hist!D6:D31)-CF_Hist!D32 -> 0 | F22: 1 | G22: =IF(AND(ABS(N(B22))<=$F22,ABS(N(C22))<=$F22,ABS(N(D22))<=$F22),"PASS","FAIL") -> PASS
A23: CF: CFI = suma de partidas de inversión | B23: =SUM(CF_Hist!B35:B43)-CF_Hist!B44 -> 0 | C23: =SUM(CF_Hist!C35:C43)-CF_Hist!C44 -> 0 | D23: =SUM(CF_Hist!D35:D43)-CF_Hist!D44 -> 0 | F23: 1 | G23: =IF(AND(ABS(N(B23))<=$F23,ABS(N(C23))<=$F23,ABS(N(D23))<=$F23),"PASS","FAIL") -> PASS
A24: CF: CFF = suma de partidas de financiación | B24: =SUM(CF_Hist!B47:B52)-CF_Hist!B53 -> 0 | C24: =SUM(CF_Hist!C47:C52)-CF_Hist!C53 -> 0 | D24: =SUM(CF_Hist!D47:D52)-CF_Hist!D53 -> 0 | F24: 1 | G24: =IF(AND(ABS(N(B24))<=$F24,ABS(N(C24))<=$F24,ABS(N(D24))<=$F24),"PASS","FAIL") -> PASS
A25: CF: Variación neta efectivo = CFO+CFI+CFF+efecto FX | B25: =CF_Hist!B32+CF_Hist!B44+CF_Hist!B53+CF_Hist!B55-CF_Hist!B56 -> 0 | C25: =CF_Hist!C32+CF_Hist!C44+CF_Hist!C53+CF_Hist!C55-CF_Hist!C56 -> 0 | D25: =CF_Hist!D32+CF_Hist!D44+CF_Hist!D53+CF_Hist!D55-CF_Hist!D56 -> 0 | F25: 1 | G25: =IF(AND(ABS(N(B25))<=$F25,ABS(N(C25))<=$F25,ABS(N(D25))<=$F25),"PASS","FAIL") -> PASS
A26: CF: Efectivo final = inicial + variación neta | B26: =CF_Hist!B57+CF_Hist!B56-CF_Hist!B58 -> 0 | C26: =CF_Hist!C57+CF_Hist!C56-CF_Hist!C58 -> 0 | D26: =CF_Hist!D57+CF_Hist!D56-CF_Hist!D58 -> 0 | F26: 1 | G26: =IF(AND(ABS(N(B26))<=$F26,ABS(N(C26))<=$F26,ABS(N(D26))<=$F26),"PASS","FAIL") -> PASS
A27: CF: Efectivo inicial[t] = Efectivo final[t-1] (FY24, FY25) | C27: =CF_Hist!C57-CF_Hist!B58 -> 0 | D27: =CF_Hist!D57-CF_Hist!C58 -> 0 | F27: 1 | G27: =IF(AND(ABS(N(C27))<=$F27,ABS(N(D27))<=$F27),"PASS","FAIL") -> PASS
A28: SCE: Resultado integral total = NI + ORI | B28: =SCE_Hist!B9+SCE_Hist!B10-SCE_Hist!B11 -> 0 | C28: =SCE_Hist!C9+SCE_Hist!C10-SCE_Hist!C11 -> 0 | D28: =SCE_Hist!D9+SCE_Hist!D10-SCE_Hist!D11 -> 0 | F28: 1 | G28: =IF(AND(ABS(N(B28))<=$F28,ABS(N(C28))<=$F28,ABS(N(D28))<=$F28),"PASS","FAIL") -> PASS
A29: SCE: Saldo final = inicial + traslado + dividendos + otros + resultado integral + realización ORI | B29: =SCE_Hist!B5+SCE_Hist!B6+SCE_Hist!B7+SCE_Hist!B8+SCE_Hist!B11+SCE_Hist!B12-SCE_Hist!B13 -> 0 | C29: =SCE_Hist!C5+SCE_Hist!C6+SCE_Hist!C7+SCE_Hist!C8+SCE_Hist!C11+SCE_Hist!C12-SCE_Hist!C13 -> 0 | D29: =SCE_Hist!D5+SCE_Hist!D6+SCE_Hist!D7+SCE_Hist!D8+SCE_Hist!D11+SCE_Hist!D12-SCE_Hist!D13 -> 0 | F29: 1 | G29: =IF(AND(ABS(N(B29))<=$F29,ABS(N(C29))<=$F29,ABS(N(D29))<=$F29),"PASS","FAIL") -> PASS
A30: SCE: Saldo inicial[t] = Saldo final[t-1] (FY24, FY25) | C30: =SCE_Hist!C5-SCE_Hist!B13 -> 0 | D30: =SCE_Hist!D5-SCE_Hist!C13 -> 0 | F30: 1 | G30: =IF(AND(ABS(N(C30))<=$F30,ABS(N(D30))<=$F30),"PASS","FAIL") -> PASS
A31: X: CF efectivo final = BS efectivo | B31: =CF_Hist!B58-BS_Hist!B6 -> 0 | C31: =CF_Hist!C58-BS_Hist!C6 -> 0 | D31: =CF_Hist!D58-BS_Hist!D6 -> 0 | F31: 1 | G31: =IF(AND(ABS(N(B31))<=$F31,ABS(N(C31))<=$F31,ABS(N(D31))<=$F31),"PASS","FAIL") -> PASS
A32: X: CF utilidad neta = IS utilidad neta | B32: =CF_Hist!B6-IS_Hist!B20 -> 0 | C32: =CF_Hist!C6-IS_Hist!C20 -> 0 | D32: =CF_Hist!D6-IS_Hist!D20 -> 0 | F32: 1 | G32: =IF(AND(ABS(N(B32))<=$F32,ABS(N(C32))<=$F32,ABS(N(D32))<=$F32),"PASS","FAIL") -> PASS
A33: X: BS utilidad neta ejercicio (patrimonio) = IS utilidad controladora | B33: =BS_Hist!B44-IS_Hist!B23 -> 0 | C33: =BS_Hist!C44-IS_Hist!C23 -> 0 | D33: =BS_Hist!D44-IS_Hist!D23 -> 0 | F33: 1 | G33: =IF(AND(ABS(N(B33))<=$F33,ABS(N(C33))<=$F33,ABS(N(D33))<=$F33),"PASS","FAIL") -> PASS
A34: X: BS total patrimonio = SCE saldo final | B34: =BS_Hist!B48-SCE_Hist!B13 -> 0 | C34: =BS_Hist!C48-SCE_Hist!C13 -> 0 | D34: =BS_Hist!D48-SCE_Hist!D13 -> 0 | F34: 1 | G34: =IF(AND(ABS(N(B34))<=$F34,ABS(N(C34))<=$F34,ABS(N(D34))<=$F34),"PASS","FAIL") -> PASS
A35: X: CI utilidad neta = IS utilidad neta | B35: =CI_Hist!B5-IS_Hist!B20 -> 0 | C35: =CI_Hist!C5-IS_Hist!C20 -> 0 | D35: =CI_Hist!D5-IS_Hist!D20 -> 0 | F35: 1 | G35: =IF(AND(ABS(N(B35))<=$F35,ABS(N(C35))<=$F35,ABS(N(D35))<=$F35),"PASS","FAIL") -> PASS
A36: X: CI ORI = BS otro resultado integral, variación anual (FY24, FY25 only; informational, sign per policy differs) | F36: 999999999 | G36: =IF(AND(ABS(N(B36))<=$F36,ABS(N(C36))<=$F36,ABS(N(D36))<=$F36),"PASS","FAIL") -> PASS
A37: SCHED: Deposits_Funding total = BS_Hist memo depósitos (FY23/24/25) | B37: =Deposits_Funding!B10 -> 0 | C37: =Deposits_Funding!C10 -> 0 | D37: =Deposits_Funding!D10 -> 0 | F37: 1 | G37: =IF(AND(ABS(N(B37))<=$F37,ABS(N(C37))<=$F37,ABS(N(D37))<=$F37),"PASS","FAIL") -> PASS
A38: SCHED: Loan_Book etapas = cartera bruta revelaciones (FY24/25) | C38: =Loan_Book!B27 -> 0 | D38: =Loan_Book!C27 -> 0 | F38: 1 | G38: =IF(AND(ABS(N(C38))<=$F38,ABS(N(D38))<=$F38),"PASS","FAIL") -> PASS
A39: SCHED: Credit_Quality deterioro roll-forward = Nota 11.5 saldo final (FY24/25) | C39: =Credit_Quality!B20 -> 0 | D39: =Credit_Quality!C20 -> 0 | F39: 1 | G39: =IF(AND(ABS(N(C39))<=$F39,ABS(N(D39))<=$F39),"PASS","FAIL") -> PASS
A40: SCHED: Capital_Adequacy APNR recomputado = publicado (FY23/24/25, tolerancia redondeo) | B40: =Capital_Adequacy!B15 -> 1 | C40: =Capital_Adequacy!C15 -> 0 | D40: =Capital_Adequacy!D15 -> 0 | F40: 2 | G40: =IF(AND(ABS(N(B40))<=$F40,ABS(N(C40))<=$F40,ABS(N(D40))<=$F40),"PASS","FAIL") -> PASS
A41: SCHED: Capital_Adequacy RSB recomputada = publicada (tolerancia 10bp) | B41: =Capital_Adequacy!B18 -> -5.8503466e-06 | C41: =Capital_Adequacy!C18 -> -1.662425e-05 | D41: =Capital_Adequacy!D18 -> -2.0388119e-07 | F41: 0.001 | G41: =IF(AND(ABS(N(B41))<=$F41,ABS(N(C41))<=$F41,ABS(N(D41))<=$F41),"PASS","FAIL") -> PASS
...

Sheet USD_Translation
A1: USD translation layer — implied closing-rate presentation (policy: native-currency statements + USD memo at documented implied/closing rates)
A2: COP/USD closing (TRM) rates per Nota a los Estados Financieros (efecto de conversión de moneda extranjera). Statements remain COP-native; this sheet is memo-only, not a re-presentation currency.
A3: Scale convention: BS_Hist/IS_Hist source cells are stated in COP millions (per sheet convention). Dividing a COP-millions figure by the COP/USD closing rate (row 5) yields USD millions directly — no further /1000 scaling. All figures below are USD mm, consistent with their row labels. (Fix 2026-07-21: prior formulas carried a spurious extra /1000 that understated every USD figure here by 1000x — ver Change_Log fila 7. Verificacion independiente 2026-08-14: activos/patrimonio/utilidad recomputados desde BS_Hist/IS_Hist contra la TRM de la fila 5 — sin escalado residual; mecanizado en Checks_TieOut filas 43-45.)
A4: Metric | B4: FY2023A | C4: FY2024A | D4: FY2025A | F4: Note ref
A5: COP/USD closing rate (TRM, 31-dic) | B5: 3822.05 | C5: 4409.15 | D5: 3757.08 | F5: FY2025 report, Nota sobre efecto de diferencia en cambio
A6: Total activos (USD mm) | B6: =BS_Hist!$B$19/$B$5 -> 35968.665 | C6: =BS_Hist!$C$19/$C$5 -> 34183.375 | D6: =BS_Hist!$D$19/$D$5 -> 41565.354
A7: Total patrimonio (USD mm) | B7: =BS_Hist!$B$48/$B$5 -> 4125.8021 | C7: =BS_Hist!$C$48/$C$5 -> 3819.8696 | D7: =BS_Hist!$D$48/$D$5 -> 4602.98
A8: Cartera de créditos, neta (USD mm) | B8: =BS_Hist!$B$8/$B$5 -> 24485.959 | C8: =BS_Hist!$C$8/$C$5 -> 23157.098 | D8: =BS_Hist!$D$8/$D$5 -> 24197.185
A9: Depósitos de clientes (USD mm, memo, ver Deposits_Funding)
A10: Utilidad neta del ejercicio (USD mm) | B10: =IS_Hist!$B$20/$B$5 -> 253.5116 | C10: =IS_Hist!$C$20/$C$5 -> 249.08384 | D10: =IS_Hist!$D$20/$D$5 -> 339.52538

Sheet Loan_Book
A1: Loan_Book — Cartera de créditos y arrendamiento financiero (COP millones)
A2: Fuente: Nota 11, FY2025 annual report (pp.108-111), cifras "saldo según revelaciones" (incluye arrendamiento financiero). FY2023 no desglosado a este nivel en el set de fuentes disponible (gap).
A4: Por modalidad (saldo según revelaciones) | B4: FY2024A | C4: FY2025A | D4: Nota
A5: Comercial | B5: 68368844 | C5: 60567169 | D5: 11
A6: Consumo | B6: 24443901 | C6: 21421175
A7: Vivienda | B7: 14607889 | C7: 13494031
A8: Microcrédito | B8: 2328 | C8: 0
A9: Repos, interbancarios y otros | B9: 227912 | C9: 13871
A10: Total cartera bruta (revelaciones) | B10: =SUM(B5:B9) -> 107650874 | C10: =SUM(C5:C9) -> 95496246
A11: Deterioro total | B11: -5547754 | C11: -4585486
A12: Total cartera neta (revelaciones) | B12: =B10+B11 -> 102103120 | C12: =C10+C11 -> 90910760 | D12: Debe ≈ BS_Hist Cartera de créditos y arrendamiento financiero, neta (diferencia = cartera a costo amortizado sin la reclasificación de nota — ver Checks_TieOut fila de reconciliación abajo)
A15: Por líneas de crédito principales (top items) | B15: FY2024A | C15: FY2025A | D15: Nota
A16: Préstamos ordinarios | B16: 69488181 | C16: 61149323 | D16: 11.1
A17: Cartera hipotecaria para vivienda | B17: 13210875 | C17: 11717444
A18: Libranzas | B18: 8710423 | C18: 6669861
A19: Tarjetas de crédito | B19: 4316749 | C19: 3955027
A20: Crédito constructor | B20: 2786274 | C20: 3310375
A22: Por etapa NIIF 9 (cartera con arrendamiento financiero) | B22: FY2024A | C22: FY2025A | D22: Nota
A23: Etapa 1 | B23: 95080275 | C23: 86353461 | D23: 11.4
A24: Etapa 2 | B24: 4939950 | C24: 3356376
A25: Etapa 3 | B25: 7630649 | C25: 5786409
A26: Total por etapas | B26: =SUM(B23:B25) -> 107650874 | C26: =SUM(C23:C25) -> 95496246
A27: Check: Total por etapas = Total cartera bruta (revelaciones) | B27: =B26-B10 -> 0 | C27: =C26-C10 -> 0
A29: Por período de maduración (cartera con arrendamiento) | B29: FY2024A | C29: FY2025A | D29: Nota
A30: Hasta 1 año | B30: 43683496 | C30: 35220789 | D30: 11.2
A31: Entre 1 y 3 años | B31: 25457052 | C31: 25262265
A32: Entre 3 y 5 años | B32: 14847632 | C32: 14832651
A33: Más de 5 años | B33: 23662694 | C33: 20180541
A34: Total por maduración | B34: =SUM(B30:B33) -> 107650874 | C34: =SUM(C30:C33) -> 95496246

Sheet Deposits_Funding
A1: Deposits_Funding — Depósitos de clientes y fondeo mayorista (COP millones)
A2: Fondeo de dos lados: depósitos (Nota 20) y obligaciones financieras/bonos (BS memo, Nota 21) se presentan de forma independiente — nunca como plug residual de caja.
A4: Depósitos de clientes por tipo | B4: FY2023A | C4: FY2024A | D4: FY2025A | E4: Nota
A5: Cuentas corrientes | B5: 14444536 | C5: 14983249 | D5: 13718228 | E5: 20
A6: Cuentas de ahorro | B6: 30347871 | C6: 36018156 | D6: 36291209
A7: Certificados de depósito a término (CDT) | B7: 45993548 | C7: 53101167 | D7: 47732498
A8: Otros | B8: 297837 | C8: 156403 | D8: 344076
A9: Total depósitos de clientes | B9: =SUM(B5:B8) -> 91083792 | C9: =SUM(C5:C8) -> 104258975 | D9: =SUM(D5:D8) -> 98086011 | E9: Debe = BS_Hist memo "Costo amortizado — depósitos de clientes"
A10: Check: vs BS_Hist memo depósitos | B10: =B9-91083792 -> 0 | C10: =C9-104258975 -> 0 | D10: =D9-98086011 -> 0
A12: Gasto por intereses de depósitos por tipo | B12: FY2024A | C12: FY2025A | D12: Nota
A13: Cuentas corrientes | B13: -210746 | C13: -182062 | D13: 20
A14: Cuentas de ahorro | B14: -2046310 | C14: -1674558
A15: CDT | B15: -4338567 | C15: -4166446
A16: Total gasto por intereses depósitos | B16: =SUM(B13:B15) -> -6595623 | C16: =SUM(C13:C15) -> -6023066 | D16: Debe = IS_Hist gastos por intereses (Depósitos de clientes), no capturado como fila separada en IS_Hist (ver NIM_Build)
A18: Fondeo mayorista (memo de BS, Nota 21) — obligaciones financieras y arrendamiento | B18: FY2023A | C18: FY2024A | D18: FY2025A | E18: Nota
A19: Obligaciones financieras | B19: 24862230 | C19: 25083047 | D19: 20230822 | E19: 21
A20: Pasivo por arrendamiento | B20: 715305 | C20: 759813 | D20: 699395 | E20: 21.5
A21: Total fondeo mayorista | B21: =B19+B20 -> 25577535 | C21: =C19+C20 -> 25842860 | D21: =D19+D20 -> 20930217
A23: Estructura de fondeo (memo) | B23: FY2023A | C23: FY2024A | D23: FY2025A
A24: Depósitos / (Depósitos + fondeo mayorista) | B24: =B9/(B9+B21) -> 0.78075395 | C24: =C9/(C9+C21) -> 0.80136437 | D24: =D9/(D9+D21) -> 0.82413981
A25: Gap financing: not modeled as a residual cash plug — deposits and wholesale funding both sourced independently from audited notes.

Sheet NIM_Build
A1: NIM_Build — Margen neto de interés (COP millones)
A2: Limitación: el Banco no publica saldos promedio diarios en el paquete de fuentes; NIM se calcula sobre saldos de cierre de periodo (proxy), no promedios — etiquetado explícitamente.
A4: Métrica | B4: FY2023A | C4: FY2024A | D4: FY2025A | E4: Fuente
A5: Total ingresos por intereses | B5: =IS_Hist!B5 -> 14381561 | C5: =IS_Hist!C5 -> 14396101 | D5: =IS_Hist!D5 -> 12215662 | E5: IS_Hist
A6: Total gastos por intereses | B6: =IS_Hist!B6 -> -9345442 | C6: =IS_Hist!C6 -> -9147250 | D6: =IS_Hist!D6 -> -7471702
A7: Ingresos por intereses, neto (spread bruto) | B7: =IS_Hist!B7 -> 5036119 | C7: =IS_Hist!C7 -> 5248851 | D7: =IS_Hist!D7 -> 4743960
A8: Cartera de créditos, neta (cierre de periodo) | B8: =BS_Hist!B8 -> 93586560 | C8: =BS_Hist!C8 -> 102103120 | D8: =BS_Hist!D8 -> 90910760 | E8: BS_Hist
A9: Total activos (cierre de periodo) | B9: =BS_Hist!B19 -> 137474036 | C9: =BS_Hist!C19 -> 150719627 | D9: =BS_Hist!D19 -> 156164359
A10: NIM sobre cartera (proxy, cierre) = ingresos netos / cartera neta | B10: =B7/B8 -> 0.053812417 | C10: =C7/C8 -> 0.051407352 | D10: =D7/D8 -> 0.052182602
A11: NIM sobre activos totales (proxy, cierre) | B11: =B7/B9 -> 0.036633237 | C11: =C7/C9 -> 0.034825265 | D11: =D7/D9 -> 0.030377994
A12: Rendimiento cartera (intereses cartera / cartera neta cierre) | C12: =11839161/C8 -> 0.11595298 | D12: =11008514/D8 -> 0.12109143 | E12: Nota 11 (FY2024/25 only)
A13: Costo de depósitos (gasto intereses depósitos / depósitos cierre) | C13: =Deposits_Funding!B16/Deposits_Funding!C9 -> -0.063261921 | D13: =Deposits_Funding!C16/Deposits_Funding!D9 -> -0.061405963

Sheet Credit_Quality
A1: Credit_Quality — Calidad de cartera (COP millones)
A2: FY2024/FY2025 por etapa NIIF 9 (Nota 11.4). FY2023 stage split not available in source set (gap).
A4: Métrica | B4: FY2023A | C4: FY2024A | D4: FY2025A | E4: Nota
A5: Cartera bruta total (revelaciones) | C5: =Loan_Book!B10 -> 107650874 | D5: =Loan_Book!C10 -> 95496246 | E5: 11
A6: Etapa 3 (NPL, deteriorada) | C6: =Loan_Book!B25 -> 7630649 | D6: =Loan_Book!C25 -> 5786409
A7: NPL ratio (Etapa 3 / cartera bruta) | C7: =C6/C5 -> 0.070883298 | D7: =D6/D5 -> 0.060593052
A8: Deterioro total (provisión) | C8: =-Loan_Book!B11 -> 5547754 | D8: =-Loan_Book!C11 -> 4585486
A9: Coverage ratio (deterioro total / Etapa 3) | C9: =C8/C6 -> 0.72703567 | D9: =D8/D6 -> 0.79245798
A10: Cost of risk (provisión de deterioro del ejercicio, IS / cartera bruta cierre) | B10: =-IS_Hist!B8/93586560 -> 0.027374572 | C10: =-IS_Hist!C8/Loan_Book!B10 -> 0.023194898 | D10: =-IS_Hist!D8/Loan_Book!C10 -> 0.023980786 | E10: IS_Hist row 8 / Loan_Book
A12: Movimiento del deterioro por modalidad (Nota 11.5) | B12: FY2024A | C12: FY2025A | D12: Nota
A13: Saldo inicial | B13: -5610653 | C13: -5547754 | D13: 11.5
A14: Castigos del período | B14: 2922444 | C14: 3103716
A15: Deterioro neto con efecto en resultado | B15: -2349994 | C15: -2189167
A16: Reversión de intereses causados | B16: -412175 | C16: -166530
A17: Diferencia en cambio | B17: -38125 | C17: 44035
A18: Otros (garantía Finagro, venta cartera, op. discontinua, reclasificación ANCMV) | B18: -59251 | C18: 170214
A19: Saldo final | B19: =SUM(B13:B18) -> -5547754 | C19: =SUM(C13:C18) -> -4585486
A20: Check: saldo final = deterioro total (Nota 11) | B20: =B19-(-5547754) -> 0 | C20: =C19-(-4585486) -> 0

Sheet Capital_Adequacy
A1: Capital_Adequacy — Indicadores de solvencia (Banco de Bogotá, base individual regulatoria; COP millones) — Nota 33 (FY25/FY24 reports)
A2: Regulación colombiana (Superintendencia Financiera). Mínimos: Solvencia Básica 4.50% (+2.50% colchón), Solvencia Total 9.00% (+2.50% colchón), Apalancamiento 3%.
A4: Métrica | B4: FY2023A | C4: FY2024A | D4: FY2025A | E4: Nota
A5: A. Patrimonio Básico Ordinario (PBO) | B5: 13644969 | C5: 14381099 | D5: 15294347 | E5: 33.1/33.2
A6: B. Patrimonio Básico Adicional (PBA) | B6: 0 | C6: 0 | D6: 0
A7: C. Total Patrimonio Básico (A+B) | B7: =B5+B6 -> 13644969 | C7: =C5+C6 -> 14381099 | D7: =D5+D6 -> 15294347
A8: D. Patrimonio Adicional (PA) | B8: 2573696 | C8: 2459094 | D8: 1687813
A9: E. Deducciones del Patrimonio Técnico | B9: 0 | C9: 0 | D9: 0
A10: F. Patrimonio Técnico (C+D-E) | B10: =B7+B8-B9 -> 16218665 | C10: =C7+C8-C9 -> 16840193 | D10: =D7+D8-D9 -> 16982160
A11: G. APNR de Crédito | B11: 91625712 | C11: 97961017 | D11: 98501784
A12: H. Riesgo de mercado ponderado (VeR RM) | B12: 7102531 | C12: 3535594 | D12: 3460094
A13: I. Riesgo operacional ponderado (VeR RO) | B13: 6806068 | C13: 7382337 | D13: 8706498
A14: J. Activos Ponderados por Nivel de Riesgo (G+H+I) | B14: =B11+B12+B13 -> 105534311 | C14: =C11+C12+C13 -> 108878948 | D14: =D11+D12+D13 -> 110668376
A15: Check: J publicado (105,534,310 / 108,878,948 / 110,668,376) | B15: =B14-105534310 -> 1 | C15: =C14-108878948 -> 0 | D15: =D14-110668376 -> 0
A16: Relación de Solvencia Básica (RSB) — recomputada = C/J | B16: =B7/B14 -> 0.12929415 | C16: =C7/C14 -> 0.13208338 | D16: =D7/D14 -> 0.1381998
A17: RSB publicada | B17: 0.1293 | C17: 0.1321 | D17: 0.1382
A18: Check: RSB recomputada − publicada (tolerancia 0.001 = 10bp por redondeo) | B18: =B16-B17 -> -5.8503466e-06 | C18: =C16-C17 -> -1.662425e-05 | D18: =D16-D17 -> -2.0388119e-07
A19: Relación de Solvencia Total (RST) — recomputada = F/J | B19: =B10/B14 -> 0.15368144 | C19: =C10/C14 -> 0.15466895 | D19: =D10/D14 -> 0.15345088
A20: RST publicada | B20: 0.1537 | C20: 0.1547 | D20: 0.1535
A21: Check: RST recomputada − publicada | B21: =B19-B20 -> -1.85589e-05 | C21: =C19-C20 -> -3.1045998e-05 | D21: =D19-D20 -> -4.9117157e-05
A22: Valor de apalancamiento | B22: 141766918 | C22: 154516917 | D22: 158485219
A23: Relación de apalancamiento (min 3%) — recomputada = C/valor apalancamiento | B23: =B7/B22 -> 0.096249317 | C23: =C7/C22 -> 0.093071356 | D23: =D7/D22 -> 0.096503302
A24: Relación de apalancamiento publicada | B24: 0.0962 | C24: 0.0931 | D24: 0.0965
A25: Check: apalancamiento recomputado − publicado | B25: =B23-B24 -> 4.9316783e-05 | C25: =C23-C24 -> -2.8643936e-05 | D25: =D23-D24 -> 3.3023048e-06

Sheet Sources_Audited
A1: Sources_Audited — Banco de Bogotá consolidated audited financial statements (bancodebogota.com IR)
A2: All historical constants in IS_Hist/CI_Hist/BS_Hist/CF_Hist/SCE_Hist and the sector schedules are sourced from these audited PDFs. Statements entered as published constants (no recomputation in source sheets); all recomputation lives in Checks_TieOut.
A4: Model year | B4: Source report (file) | C4: Statement pages (printed page #) | D4: Note pages used for schedules
A5: FY2023A / FY2024A (as originally published) | B5: BancoDeBogota_EEFF-Consolidados-Notas-Dictamen_FY2024_al-31-dic-2024.pdf (Informe del Revisor Fiscal 25-feb-2025) | C5: BS pg.8, IS pg.9, CI pg.10, SCE pg.11, CF pg.12-13 | D5: Nota 20 (Depósitos, pg~223 area); Nota 33 (Solvencia, pg.223-224 area)
A6: FY2025A (continuing + discontinued ops) | B6: BancoDeBogota_EEFF-Consolidados-Notas-Dictamen_FY2025_al-31-dic-2025.pdf (Informe del Revisor Fiscal 26-feb-2026) | C6: BS pg.6, IS pg.7, CI pg.8, SCE pg.9, CF pg.10-11 | D6: Nota 11 (Cartera, pg.108-111); Nota 20 (Depósitos, pg.144-146); Nota 33 (Solvencia, pg.167-168)
A7: FY2022 comparative | B7: GAP: BancoDeBogota_EEFF-Consolidados-Notas-Dictamen_FY2023_al-31-dic-2023.pdf (the downloaded file with the dictamen, efs-y-notas-consolidados-bdb-dic23.pdf) contains the Informe del Revisor Fiscal and Notas 1-38 but NOT standalone primary statement pages (BS/IS/CI/SCE/CF) — it jumps directly from the audit opinion into Nota 1. FY2022 figures therefore not incorporated as a presented year; only used implicitly via the FY2024-report SCE opening balance (Nota 25.2, "Saldos al 31 de diciembre de 2022"). | C7: N/A | D7: N/A
A9: Presentation notes / audit signals
A10: 1) BS: FY2024A comparative column differs between the FY2024 report and the FY2025 report (as-published FY2024 has separate "Propiedades de inversión" 215,988 and "Activos no corrientes mantenidos para la venta" 77,819 lines; FY2025 report folds both into "Otros activos" for its 2024 comparative, +293,807 net). Model uses the FY2024-report (as-originally-published) figures for FY2023A/FY2024A.
A11: 2) IS: FY2024A total ingresos por intereses is 14,396,101 as originally published (FY2024 report) vs 13,186,071 in the FY2025 report's 2024 comparative — the FY2025 report restates 2024 to show continuing operations only (Multi Financial Group/Centroamérica discontinued per Nota 2.1). Net income ties (1,098,248) across both vintages; only the gross P&L breakout differs. Model uses as-originally-published FY2024A figures.
A12: 3) FY2025 has a material discontinued-operations event (sale process for Multi Financial Group, Nota 2.1/17): "Activos/Pasivos no corrientes mantenidos para la venta — operación discontinua" (18,199,621 / 16,459,367) and a P&L line "Ganancia procedente de operaciones discontinuadas" (26,646). Shown as published, not netted.
A13: 4) Loan_Book/Credit_Quality granular (by stage/product/maturity) detail available for FY2024A/FY2025A only (Nota 11 of the FY2025 report, which reports both years). FY2023A stage-level split not available in the source set — flagged as a gap, not inferred.
A14: 5) Capital_Adequacy (Nota 33) is disclosed on a bank-standalone (Banco de Bogotá, individual) regulatory basis for all three years — the only basis on which Colombian solvency ratios are computed/reported, per Superintendencia Financiera rules. Recomputed ratios tie to published ratios within ~10bp (rounding).
A15: 6) FX layer (USD_Translation): COP is the native/functional and sole presentation currency in the audited statements (no USD convenience translation, unlike Samsung/KRW). USD_Translation sheet applies documented year-end closing TRM rates disclosed in the notes (FY2023: 3,822.05; FY2024: 4,409.15; FY2025: 3,757.08 COP/USD) as a memo-only overlay — not a re-presentation currency, and not used for any income-statement average (limitation: no average-rate disclosure in the source set).
A16: 7) NIM_Build uses period-end (not average) balances as the denominator — a stated proxy limitation; Banco de Bogotá does not disclose daily/monthly average balances in the audited-statement package.

Sheet Assumptions_Forecast
A1: Assumptions_Forecast — FY2026E-FY2030E (PARTIAL — income-statement/ratio driver framework only, not a full driver-built 3-statement forecast)
A2: PARTIAL per build policy: source pack and time available support an impeccable 3-year audited historical base + schedules, but not a defensible full balance-sheet-driven 5-year forecast (loan-by-vintage repricing, deposit beta, RWA density paths not sourced). This sheet projects headline P&L/ratio trajectories from FY2025A off explicit scenario drivers; it does NOT forecast the full balance sheet, cash flow, or capital stack. Do not treat as decision-ready.
A4: Scenario selector (1=Base,2=Bull,3=Bear) | B4: 1
A6: Driver | B6: Bear | C6: Base | D6: Bull | E6: Active | F6: Rationale
A7: Cartera bruta, crecimiento anual | B7: 0.02 | C7: 0.06 | D7: 0.1 | E7: =CHOOSE($B$4,C7,D7,B7) -> 0.06 | F7: FY24→FY25 cartera bruta cayó -11.2% (venta cartera Centroamérica); Base asume normalización a crecimiento nominal COP moderado
A8: Depósitos de clientes, crecimiento anual | B8: 0.02 | C8: 0.05 | D8: 0.08 | E8: =CHOOSE($B$4,C8,D8,B8) -> 0.05 | F8: Histórico FY23-25 muestra crecimiento de depósitos ~7-8% anual pese a caída de cartera
A9: NIM sobre cartera (proxy cierre) | B9: 0.045 | C9: 0.052 | D9: 0.058 | E9: =CHOOSE($B$4,C9,D9,B9) -> 0.052 | F9: NIM_Build FY24=5.16%, FY25=5.22% (proxy cierre); rango scenario ±100-150bp por ciclo de tasas Banrep
A10: Costo de riesgo (deterioro / cartera bruta) | B10: 0.035 | C10: 0.025 | D10: 0.018 | E10: =CHOOSE($B$4,C10,D10,B10) -> 0.025 | F10: Credit_Quality FY24=2.55%, FY25=2.50%
A11: Comisiones netas / cartera bruta | B11: 0.012 | C11: 0.014 | D11: 0.016 | E11: =CHOOSE($B$4,C11,D11,B11) -> 0.014 | F11: FY25 comisiones netas 1,306,279 / cartera bruta 95,496,246 = 1.37%
A12: Tasa efectiva de impuesto | B12: 0.16 | C12: 0.12 | D12: 0.1 | E12: =CHOOSE($B$4,C12,D12,B12) -> 0.12 | F12: FY25 gasto impuesto/utilidad antes impuesto = 11.7%; Bear asume normalización de beneficios fiscales
A13: Dividend payout (sobre utilidad neta atribuible) | B13: 0.55 | C13: 0.49 | D13: 0.4 | E13: =CHOOSE($B$4,C13,D13,B13) -> 0.49 | F13: FY25 dividendos declarados 628,634 / utilidad neta atribuible FY24 1,090,198 = 57.7% (SCE); Base moderado
A16: Proyección (COP millones) — solo P&L/ratios, NO balance completo | B16: FY2025A | C16: FY2026E | D16: FY2027E | E16: FY2028E | F16: FY2029E | G16: FY2030E
A17: Cartera bruta (revelaciones) | B17: =Loan_Book!C10 -> 95496246 | C17: =B17*(1+$E$7) -> 1.0122602e+08 | D17: =C17*(1+$E$7) -> 1.0729958e+08 | E17: =D17*(1+$E$7) -> 1.1373756e+08 | F17: =E17*(1+$E$7) -> 1.2056181e+08 | G17: =F17*(1+$E$7) -> 1.2779552e+08
A18: Ingresos por intereses neto (= NIM × cartera bruta) | B18: =IS_Hist!D7 -> 4743960 | C18: =C17*$E$9 -> 5263753.1 | D18: =D17*$E$9 -> 5579578.3 | E18: =E17*$E$9 -> 5914353 | F18: =F17*$E$9 -> 6269214.1 | G18: =G17*$E$9 -> 6645367
A19: Provisión de deterioro (= costo de riesgo × cartera bruta) | B19: =IS_Hist!D8 -> -2290075 | C19: =-C17*$E$10 -> -2530650.5 | D19: =-D17*$E$10 -> -2682489.6 | E19: =-E17*$E$10 -> -2843438.9 | F19: =-F17*$E$10 -> -3014045.3 | G19: =-G17*$E$10 -> -3194888
A20: Comisiones netas (= % × cartera bruta) | B20: =IS_Hist!D11 -> 1306279 | C20: =C17*$E$11 -> 1417164.3 | D20: =D17*$E$11 -> 1502194.1 | E20: =E17*$E$11 -> 1592325.8 | F20: =F17*$E$11 -> 1687865.3 | G20: =G17*$E$11 -> 1789137.3
A21: Utilidad antes de impuesto (proxy: NII+provisión+comisiones; excluye otros ingresos/gastos no proyectados) | B21: =B18+B19+B20 -> 3760164 | C21: =C18+C19+C20 -> 4150266.9 | D21: =D18+D19+D20 -> 4399282.9 | E21: =E18+E19+E20 -> 4663239.8 | F21: =F18+F19+F20 -> 4943034.2 | G21: =G18+G19+G20 -> 5239616.3
A22: Utilidad neta (proxy, tras impuesto) | B22: =IS_Hist!D20 -> 1275624 | C22: =C21*(1-$E$12) -> 3652234.8 | D22: =D21*(1-$E$12) -> 3871368.9 | E22: =E21*(1-$E$12) -> 4103651.1 | F22: =F21*(1-$E$12) -> 4349870.1 | G22: =G21*(1-$E$12) -> 4610862.3
A23: Dividendos (proxy) | C23: =C22*$E$13 -> 1789595.1 | D23: =D22*$E$13 -> 1896970.8 | E23: =E22*$E$13 -> 2010789 | F23: =F22*$E$13 -> 2131436.4 | G23: =G22*$E$13 -> 2259322.5
A26: PARTIAL — no incluye: balance de situación proyectado, RWA/capital proyectado, fondeo proyectado, CF proyectado, valuación. Gate de status = PARTIAL en Checks_TieOut y en la Cover.

Sheet Claude Code Log
A1: Turn # | B1: Date | C1: User Request | D1: Action Taken | E1: Details | F1: Outcome
A2: 1 | B2: 46324.359 | C2: Prepare a public model copy | D2: Remove local paths and private build references; preserve financial formulas and inputs | E2: Agent run with MOG as the tool, checked by guard v1. The guard measured every sheet before and after the run. Changed: Change_Log: 1 cell written, at D6. Agent: OpenFinmods export | F2: Compare against source and review public copy
