Workbook

Sheet 00_Cover
A1: Anthropic, PBC | Financial model: statements as filed in the Form S-1, forecast 2026E-2035E, valuation and credit
A2: Built 27 Oct 2026 from the Form S-1 filed with the SEC on 26 Oct 2026 (CIK 0002130357, accession 0001628280-26-067168).
A4: What this workbook holds
A5: Every line of the statements in the S-1: fiscal 2023 to 2025 (audited) and the six months to 30 June 2025 and 2026 (unaudited).
A6: Quarterly results, revenue by pricing model and region, costs by function, non-GAAP measures and the capital structure.
A7: Forecast 2026E-2035E with Base, Bull and Bear (switch: Assumptions!C5); valuation (DCF, comparables, funding marks, reverse DCF); credit view.
A8: Reference price: the Series H price in the S-1, US$589.0095 per preferred share = US$58.90 per common share. No IPO price exists yet.
A9: How to read it
A10: Units: USD millions, except per-share amounts (USD) and share counts (stated on each sheet).
A11: Signs follow the filing. A number in parentheses in the filing is negative here.
A12: Blue numbers are typed from the S-1 or are inputs. Black numbers are formulas. Green numbers link to another sheet.
A13: Column M on the year sheets is for your comments. Column N shows the source or the derivation.
A14: The thin vertical line separates actual and forecast columns.
A16: Master check (all checks on the Checks sheet) | C16: =Checks!C4 -> OK
A18: Key outputs (active scenario unless stated) | C18: Value
A19: Active scenario | C19: =Assumptions!$C$6 -> Base
A20: Series H price per common share (USD) | C20: =Market_Package!B10 -> 58.90095
A21: DCF value per share, perpetuity (USD) | C21: =DCF!C33 -> 80.416348
A22: Against the Series H price | C22: =DCF!C35 -> 0.365281
A23: Probability-weighted DCF value, Bear 25% / Base 50% / Bull 25% (USD) | C23: =Valuation!C52 -> 82.499139
A24: Revenue CAGR 2026E-2035E the Series H price needs (Base) | C24: =Valuation!C36 -> 0.24482088
A25: Revenue 2026E (USD m) | C25: =Forecast_3Stmt!C7 -> 54786
A26: Revenue 2030E (USD m) | C26: =Forecast_3Stmt!G7 -> 322620.29
A27: Fully diluted shares (millions) | C27: =Cap_Table!B47 -> 16281.166
A29: Sheet | B29: What it shows
A30: IS_Hist | B30: Statements of operations as filed, with tie-out checks
A31: CI_Hist | B31: Statements of comprehensive loss as filed
A32: BS_Hist | B32: Balance sheets as filed (31 Dec 2024, 31 Dec 2025, 30 Jun 2026)
A33: CF_Hist | B33: Statements of cash flows as filed
A34: SCE_Hist | B34: Statements of preferred stock and stockholders' deficit as filed
A35: Quarterly_Hist | B35: Six quarters to Q2 2026 and adjusted operating income
A36: Revenue_Hist | B36: Revenue by pricing model and region, customers, costs by function, non-GAAP, key metrics, the Q3 2026 floor
A37: Cap_Table | B37: Shares outstanding, preferred as converted, options, RSUs, notes; fully diluted count; Series H price
A38: Assumptions | B38: Every forecast input: Base, Bull, Bear and the switch (C5)
A39: Interim_Bridge | B39: 2026E = six months actual + second-half estimate; IPO conversion
A40: Schedules | B40: Capex and depreciation, loss carryforwards and taxes, working capital, unlevered free cash flow
... A51: Claude Code Log | B51: Log of every scripted write

Sheet IS_Hist
A1: Anthropic, PBC | Consolidated statements of operations, as filed in the Form S-1
A2: USD millions, except per-share amounts (USD) and share counts (thousands). Fiscal years audited; six-month periods unaudited. Source: Form S-1, 26 Oct 2026, page F-7.
A4: Fiscal year ends 31 December | B4: 2023A | C4: 2024A | D4: 2025A | E4: 6M 2025A | F4: 6M 2026A | M4: Comentarios FG | N4: Source / derivation
A6: Revenue | B6: 41 | C6: 386 | D6: 4585 | E6: 1163 | F6: 16286 | N6: S-1 page F-7
A8: Operating expenses:
A9: Compute and infrastructure | B9: 433 | C9: 2522 | D9: 7326 | E9: 2334 | F9: 8945 | N9: S-1 page F-7
A10: Personnel | B10: 95 | C10: 454 | D10: 1839 | E10: 538 | F10: 3152 | N10: S-1 page F-7
A11: Bartz settlement | B11: 0 | C11: 0 | D11: 1500 | E11: 0 | F11: 0 | N11: S-1 page F-7
A12: Sales, marketing, and partnerships | B12: 2 | C12: 43 | D12: 568 | E12: 120 | F12: 3168 | N12: S-1 page F-7
A13: Other operating and administrative | B13: 62 | C13: 347 | D13: 1412 | E13: 306 | F13: 1714 | N13: S-1 page F-7
A14: Total operating expenses | B14: 592 | C14: 3366 | D14: 12645 | E14: 3298 | F14: 16979 | N14: S-1 page F-7
A15: Operating loss | B15: -551 | C15: -2980 | D15: -8060 | E15: -2135 | F15: -693 | N15: S-1 page F-7
A16: Interest income | B16: 69 | C16: 106 | D16: 431 | E16: 115 | F16: 1111 | N16: S-1 page F-7
A17: Change in fair value of convertible notes, derivative liabilities, and SAFEs | B17: -1045 | C17: -5434 | D17: -34308 | E17: -10942 | F17: -72388 | N17: S-1 page F-7
A18: Other income (expense), net | B18: -2 | C18: 0 | D18: -8 | E18: 0 | F18: -8757 | N18: S-1 page F-7
A19: Total other income (expense), net | B19: -978 | C19: -5328 | D19: -33885 | E19: -10827 | F19: -80034 | N19: S-1 page F-7
A20: Loss before provision for income taxes | B20: -1529 | C20: -8308 | D20: -41945 | E20: -12962 | F20: -80727 | N20: S-1 page F-7
... A24: Weighted-average shares outstanding, basic and diluted | B24: 1076881 | C24: 1528995 | D24: 1821085 | E24: 1788731 | F24: 2024973 | N24: S-1 page F-7
A26: Checks: recomputed less filed (zero passes)
A27: Total operating expenses | B27: =B9+B10+B11+B12+B13-B14 -> 0 | C27: =C9+C10+C11+C12+C13-C14 -> 0 | D27: =D9+D10+D11+D12+D13-D14 -> 0 | E27: =E9+E10+E11+E12+E13-E14 -> 0 | F27: =F9+F10+F11+F12+F13-F14 -> 0
A28: Operating loss | B28: =B6-B14-B15 -> 0 | C28: =C6-C14-C15 -> 0 | D28: =D6-D14-D15 -> 0 | E28: =E6-E14-E15 -> 0 | F28: =F6-F14-F15 -> 0
A29: Total other income (expense), net | B29: =B16+B17+B18-B19 -> 0 | C29: =C16+C17+C18-C19 -> 0 | D29: =D16+D17+D18-D19 -> 0 | E29: =E16+E17+E18-E19 -> 0 | F29: =F16+F17+F18-F19 -> 0
A30: Loss before provision for income taxes | B30: =B15+B19-B20 -> 0 | C30: =C15+C19-C20 -> 0 | D30: =D15+D19-D20 -> 0 | E30: =E15+E19-E20 -> 0 | F30: =F15+F19-F20 -> 0
A31: Net loss | B31: =B20-B21-B22 -> 0 | C31: =C20-C21-C22 -> 0 | D31: =D20-D21-D22 -> 0 | E31: =E20-E21-E22 -> 0 | F31: =F20-F21-F22 -> 0
A32: Net loss per share (rounded to cents) | B32: =ROUND(B22*1000/B24,2)-B23 -> 0 | C32: =ROUND(C22*1000/C24,2)-C23 -> 0 | D32: =ROUND(D22*1000/D24,2)-D23 -> 0 | E32: =ROUND(E22*1000/E24,2)-E23 -> 0 | F32: =ROUND(F22*1000/F24,2)-F23 -> 0

Sheet CI_Hist
A1: Anthropic, PBC | Consolidated statements of comprehensive loss, as filed in the Form S-1
A2: USD millions. Source: Form S-1, 26 Oct 2026, page F-8.
A4: Fiscal year ends 31 December | B4: 2023A | C4: 2024A | D4: 2025A | E4: 6M 2025A | F4: 6M 2026A | M4: Comentarios FG | N4: Source / derivation
A6: Net loss | B6: -1531 | C6: -8309 | D6: -41965 | E6: -12969 | F6: -80748 | N6: S-1 page F-8
A8: Other comprehensive income (loss):
A9: Net unrealized gain (loss) on available-for-sale securities, net of tax | B9: 0 | C9: 0 | D9: 4 | E9: 0 | F9: -49 | N9: S-1 page F-8
A10: Foreign currency translation adjustments | B10: 0 | C10: 0 | D10: 1 | E10: 1 | F10: -9 | N10: S-1 page F-8
A11: Other comprehensive income (loss) | B11: 0 | C11: 0 | D11: 5 | E11: 1 | F11: -58 | N11: S-1 page F-8
A12: Comprehensive loss | B12: -1531 | C12: -8309 | D12: -41960 | E12: -12968 | F12: -80806 | N12: S-1 page F-8
A14: Checks: recomputed less filed (zero passes)
A15: Other comprehensive income (loss) | B15: =B9+B10-B11 -> 0 | C15: =C9+C10-C11 -> 0 | D15: =D9+D10-D11 -> 0 | E15: =E9+E10-E11 -> 0 | F15: =F9+F10-F11 -> 0
A16: Comprehensive loss | B16: =B6+B11-B12 -> 0 | C16: =C6+C11-C12 -> 0 | D16: =D6+D11-D12 -> 0 | E16: =E6+E11-E12 -> 0 | F16: =F6+F11-F12 -> 0
A17: Net loss equals the statement of operations | B17: =B6-IS_Hist!B22 -> 0 | C17: =C6-IS_Hist!C22 -> 0 | D17: =D6-IS_Hist!D22 -> 0 | E17: =E6-IS_Hist!E22 -> 0 | F17: =F6-IS_Hist!F22 -> 0

Sheet BS_Hist
A1: Anthropic, PBC | Consolidated balance sheets, as filed in the Form S-1
A2: USD millions. 31 December audited; 30 June 2026 unaudited. Source: Form S-1, 26 Oct 2026, pages F-5 and F-6.
A4: Fiscal year ends 31 December | B4: 31 Dec 2024A | C4: 31 Dec 2025A | D4: 30 Jun 2026A | M4: Comentarios FG | N4: Source / derivation
A6: Assets
A8: Current assets:
A9: Cash and cash equivalents | B9: 3141 | C9: 17388 | D9: 112389 | N9: S-1 pages F-5 and F-6
A10: Short-term investments | B10: 0 | C10: 2889 | D10: 19262 | N10: S-1 pages F-5 and F-6
A11: Accounts receivable, net | B11: 95 | C11: 909 | D11: 5833 | N11: S-1 pages F-5 and F-6
A12: Prepaid expenses and other current assets | B12: 2076 | C12: 2560 | D12: 496 | N12: S-1 pages F-5 and F-6
A13: Total current assets | B13: 5312 | C13: 23746 | D13: 137980 | N13: S-1 pages F-5 and F-6
A14: Restricted cash | B14: 13 | C14: 13 | D14: 2529 | N14: S-1 pages F-5 and F-6
A15: Property and equipment, net | B15: 19 | C15: 146 | D15: 1187 | N15: S-1 pages F-5 and F-6
A16: Operating lease right-of-use assets | B16: 35 | C16: 126 | D16: 1157 | N16: S-1 pages F-5 and F-6
A17: Goodwill | B17: 0 | C17: 154 | D17: 576 | N17: S-1 pages F-5 and F-6
A18: Other assets, noncurrent | B18: 2373 | C18: 476 | D18: 3929 | N18: S-1 pages F-5 and F-6
A19: Total assets | B19: 7752 | C19: 24661 | D19: 147358 | N19: S-1 pages F-5 and F-6
A20: Liabilities, Redeemable Convertible Preferred Stock, and Stockholders’ Deficit
A22: Current liabilities:
A23: Accounts payable, accrued expenses, and other current liabilities | B23: 333 | C23: 2511 | D23: 5422 | N23: S-1 pages F-5 and F-6
A24: Operating lease liabilities, current | B24: 13 | C24: 37 | D24: 148 | N24: S-1 pages F-5 and F-6
A25: Deferred revenue | B25: 28 | C25: 269 | D25: 1650 | N25: S-1 pages F-5 and F-6
A26: Total current liabilities | B26: 374 | C26: 2817 | D26: 7220 | N26: S-1 pages F-5 and F-6
A27: Operating lease liabilities, noncurrent | B27: 39 | C27: 80 | D27: 931 | N27: S-1 pages F-5 and F-6
A28: Convertible notes payable | B28: 14116 | C28: 41677 | D28: 108566 | N28: S-1 pages F-5 and F-6
A29: Other noncurrent liabilities | B29: 150 | C29: 823 | D29: 750 | N29: S-1 pages F-5 and F-6
A30: Total liabilities | B30: 14679 | C30: 45397 | D30: 117467 | N30: S-1 pages F-5 and F-6
A31: Commitments and contingencies (Note 13)
A32: Redeemable convertible preferred stock | B32: 2874 | C32: 29769 | D32: 157510 | N32: Caption as filed: Redeemable convertible preferred stock, $0.00001 par value; 360,995, 728,289, and 1,040,441 shares authorized as of December 31, 2024 and 2025 and June 30, 2026 (unaudited), respectively; 220,219, 544,322, and 853,394 shares issued and outstanding as of December 31, 2024 and 2025 and June 30, 2026 (unaudited), respectively; aggregate liquidation preference of $2,874, $24,646, and $136,286 as of December 31, 2024 and 2025 and June 30, 2026 (unaudited), respectively
A34: Stockholders’ deficit:
A35: Class A common stock | B35: 0 | C35: 0 | D35: 0 | N35: Caption as filed: Class A common stock, $0.00001 par value; 6,319,705, 8,162,757, and 10,991,000 shares authorized as of December 31, 2024 and 2025 and June 30, 2026 (unaudited), respectively; 1,779,060, 1,901,267, and 2,157,398 shares issued and outstanding as of December 31, 2024 and 2025 and June 30, 2026 (unaudited), respectively
A36: Class N common stock | B36: 0 | C36: 0 | D36: 0 | N36: Caption as filed: Class N common stock, $0.00001 par value; 2,148,900, 5,547,243, and 7,044,000 shares authorized as of December 31, 2024 and 2025 and June 30, 2026 (unaudited), respectively; no shares issued and outstanding as of December 31, 2024 and 2025, and 30,643 shares issued and outstanding as of June 30, 2026 (unaudited)
A37: Class T common stock | B37: 0 | C37: 0 | D37: 0 | N37: Caption as filed: Class T common stock, $0.00001 par value; 0 shares authorized and issued as of December 31, 2024 and 2025 and June 30, 2026 (unaudited)
A38: Additional paid-in capital | B38: 239 | C38: 1644 | D38: 5336 | N38: S-1 pages F-5 and F-6
A39: Accumulated other comprehensive income (loss) | B39: 0 | C39: 5 | D39: -53 | N39: S-1 pages F-5 and F-6
A40: Accumulated deficit | B40: -10040 | C40: -52154 | D40: -132902 | N40: S-1 pages F-5 and F-6
A41: Total stockholders’ deficit | B41: -9801 | C41: -50505 | D41: -127619 | N41: S-1 pages F-5 and F-6
A42: Total liabilities, redeemable convertible preferred stock, and stockholders’ deficit | B42: 7752 | C42: 24661 | D42: 147358 | N42: S-1 pages F-5 and F-6
A44: Memo: items used by the model
A45: Cash, cash equivalents and short-term investments | B45: =B9+B10 -> 3141 | C45: =C9+C10 -> 20277 | D45: =D9+D10 -> 131651
A46: Finance lease liabilities (inside other liabilities) | B46: 0 | C46: 0 | D46: 443 | N46: S-1 Note 7: total finance lease liabilities 443 at 30 Jun 2026; none at 31 Dec 2025.
...

Sheet CF_Hist
A1: Anthropic, PBC | Consolidated statements of cash flows, as filed in the Form S-1
A2: USD millions. Fiscal years audited; six-month periods unaudited. Source: Form S-1, 26 Oct 2026, pages F-12 and F-13.
A4: Fiscal year ends 31 December | B4: 2023A | C4: 2024A | D4: 2025A | E4: 6M 2025A | F4: 6M 2026A | M4: Comentarios FG | N4: Source / derivation
A6: Cash flows from operating activities:
A7: Net loss | B7: -1531 | C7: -8309 | D7: -41965 | E7: -12969 | F7: -80748 | N7: S-1 pages F-12 and F-13
A9: Adjustments to reconcile net loss to net cash provided by (used in) operating activities:
A10: Stock-based compensation expense | B10: 29 | C10: 192 | D10: 1158 | E10: 279 | F10: 2185 | N10: S-1 pages F-12 and F-13
A11: Depreciation and amortization | B11: 3 | C11: 21 | D11: 40 | E11: 14 | F11: 97 | N11: S-1 pages F-12 and F-13
A12: Change in fair value of convertible notes, derivative liabilities, and SAFEs | B12: 1045 | C12: 5434 | D12: 34308 | E12: 10942 | F12: 72388 | N12: S-1 pages F-12 and F-13
A13: Donation matching program liability | B13: 0 | C13: 0 | D13: 541 | E13: 0 | F13: 126 | N13: S-1 pages F-12 and F-13
A14: Recognition and change in fair value of other financial instruments | B14: 0 | C14: 0 | D14: 0 | E14: 0 | F14: 8720 | N14: S-1 pages F-12 and F-13
A15: Other | B15: 0 | C15: 7 | D15: 11 | E15: 5 | F15: -7 | N15: S-1 pages F-12 and F-13
A17: Changes in operating assets and liabilities:
A18: Accounts receivable, net | B18: -10 | C18: -90 | D18: -834 | E18: -384 | F18: -4982 | N18: S-1 pages F-12 and F-13
A19: Prepaid expenses and other assets | B19: -1253 | C19: -3190 | D19: 1771 | E19: 212 | F19: 2094 | N19: S-1 pages F-12 and F-13
A20: Accounts payable, accrued expenses, and other liabilities | B20: 84 | C20: 222 | D20: 2079 | E20: 257 | F20: 2679 | N20: S-1 pages F-12 and F-13
A21: Lease liabilities | B21: -1 | C21: 0 | D21: 13 | E21: 7 | F21: -3 | N21: S-1 pages F-12 and F-13
A22: Deferred revenue | B22: 7 | C22: 21 | D22: 241 | E22: 124 | F22: 1380 | N22: S-1 pages F-12 and F-13
A23: Net cash provided by (used in) operating activities | B23: -1627 | C23: -5692 | D23: -2637 | E23: -1513 | F23: 3929 | N23: S-1 pages F-12 and F-13
A25: Cash flows from investing activities:
A26: Purchases of property and equipment | B26: -2 | C26: -15 | D26: -131 | E26: -18 | F26: -482 | N26: S-1 pages F-12 and F-13
A27: Purchases of short-term investments | B27: 0 | C27: 0 | D27: -3082 | E27: 0 | F27: -18972 | N27: S-1 pages F-12 and F-13
A28: Sales and maturities of short-term investments | B28: 0 | C28: 0 | D28: 213 | E28: 0 | F28: 2610 | N28: S-1 pages F-12 and F-13
A29: Other investing activities | B29: 0 | C29: -7 | D29: -77 | E29: -31 | F29: -337 | N29: S-1 pages F-12 and F-13
A30: Net cash used in investing activities | B30: -2 | C30: -22 | D30: -3077 | E30: -49 | F30: -17181 | N30: S-1 pages F-12 and F-13
A32: Cash flows from financing activities:
A33: Proceeds from issuance of redeemable convertible preferred stock, net of issuance costs | B33: 445 | C33: 1188 | D33: 16548 | E33: 3549 | F33: 110432 | N33: S-1 pages F-12 and F-13
A34: Principal payments for finance leases | B34: 0 | C34: 0 | D34: 0 | E34: 0 | F34: -4 | N34: S-1 pages F-12 and F-13
A35: Issuance of convertible notes for cash | B35: 1750 | C35: 6050 | D35: 3450 | E35: 1300 | F35: 0 | N35: S-1 pages F-12 and F-13
A36: Proceeds from issuance of common stock | B36: 3 | C36: 10 | D36: 111 | E36: 49 | F36: 355 | N36: S-1 pages F-12 and F-13
A37: Repurchase of common stock | B37: 0 | C37: 0 | D37: -149 | E37: -149 | F37: 0 | N37: S-1 pages F-12 and F-13
A38: Issuance of SAFEs for cash | B38: 122 | C38: 0 | D38: 0 | E38: 0 | F38: 0 | N38: S-1 pages F-12 and F-13
A39: Payment of deferred offering costs | B39: 0 | C39: 0 | D39: 0 | E39: 0 | F39: -9 | N39: S-1 pages F-12 and F-13
A40: Net cash provided by financing activities | B40: 2320 | C40: 7248 | D40: 19960 | E40: 4749 | F40: 110774 | N40: S-1 pages F-12 and F-13
A41: Effect of exchange rate changes on cash, cash equivalents, and restricted cash | B41: 0 | C41: 0 | D41: 1 | E41: 1 | F41: -5 | N41: S-1 pages F-12 and F-13
A42: Net increase in cash, cash equivalents, and restricted cash | B42: 691 | C42: 1534 | D42: 14247 | E42: 3188 | F42: 97517 | N42: S-1 pages F-12 and F-13
A43: Cash, cash equivalents, and restricted cash at beginning of period | B43: 929 | C43: 1620 | D43: 3154 | E43: 3154 | F43: 17401 | N43: S-1 pages F-12 and F-13
A44: Cash, cash equivalents, and restricted cash at end of period | B44: 1620 | C44: 3154 | D44: 17401 | E44: 6342 | F44: 114918 | N44: S-1 pages F-12 and F-13
A46: Checks: recomputed less filed (zero passes)
A47: Net cash from operating activities | B47: =B7+B10+B11+B12+B13+B14+B15+B18+B19+B20+B21+B22-B23 -> 0 | C47: =C7+C10+C11+C12+C13+C14+C15+C18+C19+C20+C21+C22-C23 -> 0 | D47: =D7+D10+D11+D12+D13+D14+D15+D18+D19+D20+D21+D22-D23 -> 0 | E47: =E7+E10+E11+E12+E13+E14+E15+E18+E19+E20+E21+E22-E23 -> 0 | F47: =F7+F10+F11+F12+F13+F14+F15+F18+F19+F20+F21+F22-F23 -> 0
...

Sheet SCE_Hist
A1: Anthropic, PBC | Statements of redeemable convertible preferred stock and stockholders' deficit, as filed
A2: USD millions; share counts in thousands (after the 10-for-1 split of 17 Sep 2026). Source: Form S-1, 26 Oct 2026, pages F-9 to F-11.
A4: Line | B4: Preferred shares (k) | C4: Preferred amount | D4: Class A shares (k) | E4: Class A amount | F4: Class N shares (k) | G4: Class N amount | H4: Class T shares (k) | I4: Class T amount | J4: Additional paid-in capital | K4: AOCI | L4: Accumulated deficit | M4: Total stockholders' deficit | N4: Comentarios FG | O4: Source / derivation
A6: Fiscal years 2023 to 2025 (audited)
A7: Balance as of December 31, 2022 | B7: 136005 | C7: 1106 | D7: 1738823 | E7: 0 | F7: 0 | G7: 0 | H7: 0 | I7: 0 | J7: 5 | K7: 0 | L7: -200 | M7: -195 | O7: S-1 pages F-9 to F-11
A8: Issuance of redeemable convertible preferred stock, net of issuance costs | B8: 39670 | C8: 445 | D8: 0 | E8: 0 | F8: 0 | G8: 0 | H8: 0 | I8: 0 | J8: 0 | K8: 0 | L8: 0 | M8: 0 | O8: S-1 pages F-9 to F-11
A9: Conversion of SAFE note into redeemable convertible preferred stock | B9: 89 | C9: 1 | D9: 0 | E9: 0 | F9: 0 | G9: 0 | H9: 0 | I9: 0 | J9: 0 | K9: 0 | L9: 0 | M9: 0 | O9: S-1 pages F-9 to F-11
A10: Issuance of Class T common stock | B10: 0 | C10: 0 | D10: 0 | E10: 0 | F10: 0 | G10: 0 | H10: 0 | I10: 0 | J10: 0 | K10: 0 | L10: 0 | M10: 0 | O10: S-1 pages F-9 to F-11
A11: Issuance of Class A common stock upon exercise of stock options | B11: 0 | C11: 0 | D11: 15330 | E11: 0 | F11: 0 | G11: 0 | H11: 0 | I11: 0 | J11: 3 | K11: 0 | L11: 0 | M11: 3 | O11: S-1 pages F-9 to F-11
A12: Stock-based compensation expense | B12: 0 | C12: 0 | D12: 0 | E12: 0 | F12: 0 | G12: 0 | H12: 0 | I12: 0 | J12: 29 | K12: 0 | L12: 0 | M12: 29 | O12: S-1 pages F-9 to F-11
A13: Net loss | B13: 0 | C13: 0 | D13: 0 | E13: 0 | F13: 0 | G13: 0 | H13: 0 | I13: 0 | J13: 0 | K13: 0 | L13: -1531 | M13: -1531 | O13: S-1 pages F-9 to F-11
A14: Balance as of December 31, 2023 | B14: 175764 | C14: 1552 | D14: 1754153 | E14: 0 | F14: 0 | G14: 0 | H14: 0 | I14: 0 | J14: 37 | K14: 0 | L14: -1731 | M14: -1694 | O14: S-1 pages F-9 to F-11
A15: Issuance of redeemable convertible preferred stock, net of issuance costs | B15: 39979 | C15: 1188 | D15: 0 | E15: 0 | F15: 0 | G15: 0 | H15: 0 | I15: 0 | J15: 0 | K15: 0 | L15: 0 | M15: 0 | O15: S-1 pages F-9 to F-11
A16: Conversion of SAFE notes into redeemable convertible preferred stock | B16: 4476 | C16: 134 | D16: 0 | E16: 0 | F16: 0 | G16: 0 | H16: 0 | I16: 0 | J16: 0 | K16: 0 | L16: 0 | M16: 0 | O16: S-1 pages F-9 to F-11
A17: Issuance of Class A common stock upon exercise of stock options | B17: 0 | C17: 0 | D17: 24907 | E17: 0 | F17: 0 | G17: 0 | H17: 0 | I17: 0 | J17: 10 | K17: 0 | L17: 0 | M17: 10 | O17: S-1 pages F-9 to F-11
A18: Stock-based compensation expense | B18: 0 | C18: 0 | D18: 0 | E18: 0 | F18: 0 | G18: 0 | H18: 0 | I18: 0 | J18: 192 | K18: 0 | L18: 0 | M18: 192 | O18: S-1 pages F-9 to F-11
... A30: Balance as of December 31, 2025 | B30: 544322 | C30: 29769 | D30: 1901267 | E30: 0 | F30: 0 | G30: 0 | H30: 0 | I30: 0 | J30: 1644 | K30: 5 | L30: -52154 | M30: -50505 | O30: S-1 pages F-9 to F-11
A32: Six months ended 30 June 2025 (unaudited)
A33: Balance as of December 31, 2024 | B33: 220219 | C33: 2874 | D33: 1779060 | E33: 0 | F33: 0 | G33: 0 | H33: 0 | I33: 0 | J33: 239 | K33: 0 | L33: -10040 | M33: -9801 | O33: S-1 pages F-9 to F-11
A34: Issuance of redeemable convertible preferred stock, net of issuance costs (unaudited) | B34: 63610 | C34: 3549 | D34: 0 | E34: 0 | F34: 0 | G34: 0 | H34: 0 | I34: 0 | J34: 0 | K34: 0 | L34: 0 | M34: 0 | O34: S-1 pages F-9 to F-11
A35: Conversion of convertible notes into redeemable convertible preferred stock (unaudited) | B35: 147533 | C35: 8168 | D35: 0 | E35: 0 | F35: 0 | G35: 0 | H35: 0 | I35: 0 | J35: 0 | K35: 0 | L35: 0 | M35: 0 | O35: S-1 pages F-9 to F-11
A36: Issuance of Class A common stock upon exercise of stock options and grants of restricted stock (unaudited) | B36: 0 | C36: 0 | D36: 83704 | E36: 0 | F36: 0 | G36: 0 | H36: 0 | I36: 0 | J36: 49 | K36: 0 | L36: 0 | M36: 49 | O36: S-1 pages F-9 to F-11
A37: Repurchase of outstanding common stock (unaudited) | B37: 0 | C37: 0 | D37: -27942 | E37: 0 | F37: 0 | G37: 0 | H37: 0 | I37: 0 | J37: 0 | K37: 0 | L37: -149 | M37: -149 | O37: S-1 pages F-9 to F-11
A38: Stock-based compensation expense (unaudited) | B38: 0 | C38: 0 | D38: 0 | E38: 0 | F38: 0 | G38: 0 | H38: 0 | I38: 0 | J38: 279 | K38: 0 | L38: 0 | M38: 279 | O38: S-1 pages F-9 to F-11
A39: Foreign currency translation adjustments (unaudited) | B39: 0 | C39: 0 | D39: 0 | E39: 0 | F39: 0 | G39: 0 | H39: 0 | I39: 0 | J39: 0 | K39: 1 | L39: 0 | M39: 1 | O39: S-1 pages F-9 to F-11
A40: Net loss (unaudited) | B40: 0 | C40: 0 | D40: 0 | E40: 0 | F40: 0 | G40: 0 | H40: 0 | I40: 0 | J40: 0 | K40: 0 | L40: -12969 | M40: -12969 | O40: S-1 pages F-9 to F-11
A41: Balance as of June 30, 2025 (unaudited) | B41: 431362 | C41: 14591 | D41: 1834822 | E41: 0 | F41: 0 | G41: 0 | H41: 0 | I41: 0 | J41: 567 | K41: 1 | L41: -23158 | M41: -22590 | O41: S-1 pages F-9 to F-11
A43: Six months ended 30 June 2026 (unaudited)
A44: Balance as of December 31, 2025 | B44: 544322 | C44: 29769 | D44: 1901267 | E44: 0 | F44: 0 | G44: 0 | H44: 0 | I44: 0 | J44: 1644 | K44: 5 | L44: -52154 | M44: -50505 | O44: S-1 pages F-9 to F-11
A45: Issuance of redeemable convertible preferred stock, net of issuance costs (unaudited) | B45: 285187 | C45: 122242 | D45: 0 | E45: 0 | F45: 0 | G45: 0 | H45: 0 | I45: 0 | J45: 0 | K45: 0 | L45: 0 | M45: 0 | O45: S-1 pages F-9 to F-11
A46: Conversion of convertible notes into redeemable convertible preferred stock (unaudited) | B46: 23885 | C46: 5499 | D46: 0 | E46: 0 | F46: 0 | G46: 0 | H46: 0 | I46: 0 | J46: 0 | K46: 0 | L46: 0 | M46: 0 | O46: S-1 pages F-9 to F-11
A47: Issuance of Class A common stock upon exercise of stock options, grants of restricted stock, and sales of common stock for cash (unaudited) | B47: 0 | C47: 0 | D47: 229818 | E47: 0 | F47: 0 | G47: 0 | H47: 0 | I47: 0 | J47: 355 | K47: 0 | L47: 0 | M47: 355 | O47: S-1 pages F-9 to F-11
A48: Issuance of Class A common stock in connection with acquisitions (unaudited) | B48: 0 | C48: 0 | D48: 26313 | E48: 0 | F48: 0 | G48: 0 | H48: 0 | I48: 0 | J48: 534 | K48: 0 | L48: 0 | M48: 534 | O48: S-1 pages F-9 to F-11
A49: Issuance of Class N common stock upon settlement of donation matching program liability (unaudited) | B49: 0 | C49: 0 | D49: 0 | E49: 0 | F49: 30643 | G49: 0 | H49: 0 | I49: 0 | J49: 667 | K49: 0 | L49: 0 | M49: 667 | O49: S-1 pages F-9 to F-11
A50: Stock-based compensation expense (unaudited) | B50: 0 | C50: 0 | D50: 0 | E50: 0 | F50: 0 | G50: 0 | H50: 0 | I50: 0 | J50: 2185 | K50: 0 | L50: 0 | M50: 2185 | O50: S-1 pages F-9 to F-11
A51: Foreign currency translation adjustments (unaudited) | B51: 0 | C51: 0 | D51: 0 | E51: 0 | F51: 0 | G51: 0 | H51: 0 | I51: 0 | J51: 0 | K51: -9 | L51: 0 | M51: -9 | O51: S-1 pages F-9 to F-11
A52: Net unrealized loss on available-for-sale securities (unaudited) | B52: 0 | C52: 0 | D52: 0 | E52: 0 | F52: 0 | G52: 0 | H52: 0 | I52: 0 | J52: 0 | K52: -49 | L52: 0 | M52: -49 | O52: S-1 pages F-9 to F-11
A53: Net loss (unaudited) | B53: 0 | C53: 0 | D53: 0 | E53: 0 | F53: 0 | G53: 0 | H53: 0 | I53: 0 | J53: 0 | K53: 0 | L53: -80748 | M53: -80748 | O53: S-1 pages F-9 to F-11
A54: Other (unaudited) | B54: 0 | C54: 0 | D54: 0 | E54: 0 | F54: 0 | G54: 0 | H54: 0 | I54: 0 | J54: -49 | K54: 0 | L54: 0 | M54: -49 | O54: S-1 pages F-9 to F-11
A55: Balance as of June 30, 2026 (unaudited) | B55: 853394 | C55: 157510 | D55: 2157398 | E55: 0 | F55: 30643 | G55: 0 | H55: 0 | I55: 0 | J55: 5336 | K55: -53 | L55: -132902 | M55: -127619 | O55: S-1 pages F-9 to F-11
...

Sheet Quarterly_Hist
A1: Anthropic, PBC | Quarterly statements of operations and adjusted operating income, as filed
A2: USD millions. Unaudited. Source: Form S-1, 26 Oct 2026, MD&A 'Quarterly Results of Operations'.
A4: Three months ended | B4: Q1 2025A | C4: Q2 2025A | D4: Q3 2025A | E4: Q4 2025A | F4: Q1 2026A | G4: Q2 2026A | M4: Comentarios FG | N4: Source / derivation
A6: Revenue | B6: 376 | C6: 787 | D6: 1382 | E6: 2040 | F6: 4731 | G6: 11555 | N6: S-1 MD&A, quarterly table
A7: Operating expenses:
A8: Compute and infrastructure | B8: 944 | C8: 1390 | D8: 2047 | E8: 2945 | F8: 3387 | G8: 5558 | N8: S-1 MD&A, quarterly table
A9: Personnel | B9: 218 | C9: 320 | D9: 489 | E9: 812 | F9: 1295 | G9: 1857 | N9: S-1 MD&A, quarterly table
A10: Bartz settlement | B10: 0 | C10: 0 | D10: 1500 | E10: 0 | F10: 0 | G10: 0 | N10: S-1 MD&A, quarterly table
A11: Sales, marketing, and partnerships | B11: 24 | C11: 96 | D11: 202 | E11: 246 | F11: 1033 | G11: 2135 | N11: S-1 MD&A, quarterly table
A12: Other operating and administrative | B12: 125 | C12: 181 | D12: 233 | E12: 873 | F12: 683 | G12: 1031 | N12: S-1 MD&A, quarterly table
A13: Total operating expenses | B13: 1311 | C13: 1987 | D13: 4471 | E13: 4876 | F13: 6398 | G13: 10581 | N13: S-1 MD&A, quarterly table
A14: Operating income (loss) | B14: -935 | C14: -1200 | D14: -3089 | E14: -2836 | F14: -1667 | G14: 974 | N14: S-1 MD&A, quarterly table
A15: Interest income | B15: 51 | C15: 64 | D15: 124 | E15: 192 | F15: 349 | G15: 762 | N15: S-1 MD&A, quarterly table
A16: Change in fair value of convertible notes, derivative liabilities, and SAFEs | B16: -5701 | C16: -5241 | D16: -9165 | E16: -14201 | F16: -12791 | G16: -59597 | N16: S-1 MD&A, quarterly table
A17: Other income (expense), net | B17: 0 | C17: 0 | D17: -3 | E17: -5 | F17: -309 | G17: -8448 | N17: S-1 MD&A, quarterly table
A18: Total other income (expense), net | B18: -5650 | C18: -5177 | D18: -9044 | E18: -14014 | F18: -12751 | G18: -67283 | N18: S-1 MD&A, quarterly table
A19: Loss before provision for income taxes | B19: -6585 | C19: -6377 | D19: -12133 | E19: -16850 | F19: -14418 | G19: -66309 | N19: S-1 MD&A, quarterly table
... A21: Net loss | B21: -6592 | C21: -6377 | D21: -12138 | E21: -16858 | F21: -14439 | G21: -66309 | N21: S-1 MD&A, quarterly table
A23: Adjusted operating income (company definition, non-GAAP)
A24: Stock-based compensation expense | B24: 105 | C24: 181 | D24: 305 | E24: 574 | F24: 924 | G24: 1261 | N24: S-1 MD&A, quarterly non-GAAP table
A25: Non-cash charitable contributions | B25: 0 | C25: 0 | D25: 0 | E25: 541 | F25: 126 | G25: 0 | N25: S-1 MD&A, quarterly non-GAAP table
A26: Bartz settlement | B26: 0 | C26: 0 | D26: 1500 | E26: 0 | F26: 0 | G26: 0 | N26: S-1 MD&A, quarterly non-GAAP table
A27: Adjusted Operating Income (Loss) | B27: -830 | C27: -1019 | D27: -1284 | E27: -1721 | F27: -617 | G27: 2235 | N27: S-1 MD&A, quarterly non-GAAP table
A29: Ratios (derived)
A30: Revenue: growth on the prior quarter | C30: =C6/B6-1 -> 1.0930851 | D30: =D6/C6-1 -> 0.75603558 | E30: =E6/D6-1 -> 0.47612156 | F30: =F6/E6-1 -> 1.3191176 | G30: =G6/F6-1 -> 1.4424012
A31: Compute and infrastructure: % of revenue | B31: =B8/B6 -> 2.5106383 | C31: =C8/C6 -> 1.7662008 | D31: =D8/D6 -> 1.4811867 | E31: =E8/E6 -> 1.4436275 | F31: =F8/F6 -> 0.7159163 | G31: =G8/G6 -> 0.48100389
A32: Personnel: % of revenue | B32: =B9/B6 -> 0.57978723 | C32: =C9/C6 -> 0.40660737 | D32: =D9/D6 -> 0.35383502 | E32: =E9/E6 -> 0.39803922 | F32: =F9/F6 -> 0.27372648 | G32: =G9/G6 -> 0.16070965
A33: Sales, marketing and partnerships: % of revenue | B33: =B11/B6 -> 0.063829787 | C33: =C11/C6 -> 0.12198221 | D33: =D11/D6 -> 0.14616498 | E33: =E11/E6 -> 0.12058824 | F33: =F11/F6 -> 0.21834707 | G33: =G11/G6 -> 0.1847685
A34: Other operating and administrative: % of revenue | B34: =B12/B6 -> 0.33244681 | C34: =C12/C6 -> 0.22998729 | D34: =D12/D6 -> 0.16859624 | E34: =E12/E6 -> 0.42794118 | F34: =F12/F6 -> 0.14436694 | G34: =G12/G6 -> 0.089225444
A35: Personnel excluding stock-based compensation: % of revenue | B35: =(B9-B24)/B6 -> 0.30053191 | C35: =(C9-C24)/C6 -> 0.17662008 | D35: =(D9-D24)/D6 -> 0.13314038 | E35: =(E9-E24)/E6 -> 0.11666667 | F35: =(F9-F24)/F6 -> 0.078418939 | G35: =(G9-G24)/G6 -> 0.051579403
A36: Operating margin | B36: =B14/B6 -> -2.4867021 | C36: =C14/C6 -> -1.5247776 | D36: =D14/D6 -> -2.2351664 | E36: =E14/E6 -> -1.3901961 | F36: =F14/F6 -> -0.3523568 | G36: =G14/G6 -> 0.084292514
A37: Adjusted operating margin (company definition) | B37: =B27/B6 -> -2.2074468 | C37: =C27/C6 -> -1.2947903 | D37: =D27/D6 -> -0.92908828 | E37: =E27/E6 -> -0.84362745 | F37: =F27/F6 -> -0.1304164 | G37: =G27/G6 -> 0.19342276
A39: Checks (zero passes)
A40: Total operating expenses | B40: =B8+B9+B10+B11+B12-B13 -> 0 | C40: =C8+C9+C10+C11+C12-C13 -> 0 | D40: =D8+D9+D10+D11+D12-D13 -> 0 | E40: =E8+E9+E10+E11+E12-E13 -> 0 | F40: =F8+F9+F10+F11+F12-F13 -> 0 | G40: =G8+G9+G10+G11+G12-G13 -> 0
A41: Net loss | B41: =B14+B18-B20-B21 -> 0 | C41: =C14+C18-C20-C21 -> 0 | D41: =D14+D18-D20-D21 -> 0 | E41: =E14+E18-E20-E21 -> 0 | F41: =F14+F18-F20-F21 -> 0 | G41: =G14+G18-G20-G21 -> 0
A42: Adjusted operating income | B42: =B14+B24+B25+B26-B27 -> 0 | C42: =C14+C24+C25+C26-C27 -> 0 | D42: =D14+D24+D25+D26-D27 -> 0 | E42: =E14+E24+E25+E26-E27 -> 0 | F42: =F14+F24+F25+F26-F27 -> 0 | G42: =G14+G24+G25+G26-G27 -> 0
A43: Quarters add up to the statements: rev | B43: =SUM(B6:E6)-IS_Hist!D6 -> 0 | C43: =B6+C6-IS_Hist!E6 -> 0 | D43: =F6+G6-IS_Hist!F6 -> 0 | N43: B: Q1-Q4 2025 against FY2025; C: Q1-Q2 2025 against 6M 2025; D: Q1-Q2 2026 against 6M 2026.
A44: Quarters add up to the statements: comp | B44: =SUM(B8:E8)-IS_Hist!D9 -> 0 | C44: =B8+C8-IS_Hist!E9 -> 0 | D44: =F8+G8-IS_Hist!F9 -> 0 | N44: B: Q1-Q4 2025 against FY2025; C: Q1-Q2 2025 against 6M 2025; D: Q1-Q2 2026 against 6M 2026.
A45: Quarters add up to the statements: topex | B45: =SUM(B13:E13)-IS_Hist!D14 -> 0 | C45: =B13+C13-IS_Hist!E14 -> 0 | D45: =F13+G13-IS_Hist!F14 -> 0 | N45: B: Q1-Q4 2025 against FY2025; C: Q1-Q2 2025 against 6M 2025; D: Q1-Q2 2026 against 6M 2026.
A46: Quarters add up to the statements: nl | B46: =SUM(B21:E21)-IS_Hist!D22 -> 0 | C46: =B21+C21-IS_Hist!E22 -> 0 | D46: =F21+G21-IS_Hist!F22 -> 0 | N46: B: Q1-Q4 2025 against FY2025; C: Q1-Q2 2025 against 6M 2025; D: Q1-Q2 2026 against 6M 2026.

Sheet Revenue_Hist
A1: Anthropic, PBC | Revenue, customers, costs by function and non-GAAP measures, as filed
A2: USD millions unless stated. Source: Form S-1, 26 Oct 2026: notes 2 and 3, the MD&A and the business section.
A4: Fiscal year ends 31 December | B4: 2023A | C4: 2024A | D4: 2025A | E4: 6M 2025A | F4: 6M 2026A | M4: Comentarios FG | N4: Source / derivation
A6: Revenue by pricing model (S-1 Note 3)
A7: Consumption-based | B7: 39 | C7: 288 | D7: 3796 | E7: 983 | F7: 13064 | N7: S-1 Note 3
A8: Subscription-based | B8: 2 | C8: 98 | D8: 789 | E8: 180 | F8: 3222 | N8: S-1 Note 3
A9: Total | B9: 41 | C9: 386 | D9: 4585 | E9: 1163 | F9: 16286 | N9: S-1 Note 3
A10: Subscription-based: % of revenue | B10: =B8/B9 -> 0.048780488 | C10: =C8/C9 -> 0.25388601 | D10: =D8/D9 -> 0.17208288 | E10: =E8/E9 -> 0.15477214 | F10: =F8/F9 -> 0.19783863
A12: Revenue by region, billing address of the customer (S-1 Note 3)
A13: United States | B13: 34 | C13: 263 | D13: 3362 | E13: 820 | F13: 11763 | N13: S-1 Note 3
A14: International | B14: 7 | C14: 123 | D14: 1223 | E14: 343 | F14: 4523 | N14: S-1 Note 3
A15: Total | B15: 41 | C15: 386 | D15: 4585 | E15: 1163 | F15: 16286 | N15: S-1 Note 3
A16: International: % of revenue | B16: =B14/B15 -> 0.17073171 | C16: =C14/C15 -> 0.31865285 | D16: =D14/D15 -> 0.26673937 | E16: =E14/E15 -> 0.29492691 | F16: =F14/F15 -> 0.2777232
A18: Customers above 10% of revenue (S-1 Note 2; a dash means below 10%)
A19: Customer A | B19: 0 | C19: 0 | D19: 0.12 | E19: 0 | F19: 0 | N19: S-1 Note 2, concentration of revenue
A20: Customer B | B20: 0 | C20: 0 | D20: 0.12 | E20: 0.18 | F20: 0 | N20: S-1 Note 2, concentration of revenue
A21: Customer C | B21: 0.43 | C21: 0 | D21: 0 | E21: 0 | F21: 0.11 | N21: S-1 Note 2, concentration of revenue
A22: Customer D | B22: 0.11 | C22: 0 | D22: 0 | E22: 0 | F22: 0 | N22: S-1 Note 2, concentration of revenue
A24: Operating expenses by function (S-1 Note 2)
A25: Cost of revenue | B25: 26 | C25: 752 | D25: 2773 | E25: 1019 | F25: 2380 | N25: S-1 Note 2, expenses by function
A26: Research and development | B26: 422 | C26: 2275 | D26: 6338 | E26: 1850 | F26: 9741 | N26: S-1 Note 2, expenses by function
A27: Sales and marketing | B27: 76 | C27: 163 | D27: 911 | E27: 239 | F27: 3808 | N27: S-1 Note 2, expenses by function
A28: Bartz settlement | B28: 0 | C28: 0 | D28: 1500 | E28: 0 | F28: 0 | N28: S-1 Note 2, expenses by function
A29: General and administrative | B29: 68 | C29: 176 | D29: 1123 | E29: 190 | F29: 1050 | N29: S-1 Note 2, expenses by function
A30: Total operating expenses | B30: 592 | C30: 3366 | D30: 12645 | E30: 3298 | F30: 16979 | N30: S-1 Note 2, expenses by function
A31: Gross margin: 1 - cost of revenue / revenue (derived) | B31: =1-B25/IS_Hist!B6 -> 0.36585366 | C31: =1-C25/IS_Hist!C6 -> -0.94818653 | D31: =1-D25/IS_Hist!D6 -> 0.39520174 | E31: =1-E25/IS_Hist!E6 -> 0.12381771 | F31: =1-F25/IS_Hist!F6 -> 0.85386221
A32: Research and development: % of revenue (derived) | B32: =B26/IS_Hist!B6 -> 10.292683 | C32: =C26/IS_Hist!C6 -> 5.8937824 | D32: =D26/IS_Hist!D6 -> 1.3823337 | E32: =E26/IS_Hist!E6 -> 1.5907137 | F32: =F26/IS_Hist!F6 -> 0.59812109
A34: Adjusted operating income and adjusted net income (company definitions, non-GAAP; S-1 MD&A)
A35: Operating loss | B35: -551 | C35: -2980 | D35: -8060 | E35: -2135 | F35: -693 | N35: S-1 MD&A, non-GAAP reconciliation
A36: Stock-based compensation expense | B36: 29 | C36: 192 | D36: 1165 | E36: 286 | F36: 2185 | N36: S-1 MD&A, non-GAAP reconciliation
A37: Non-cash charitable contributions | B37: 0 | C37: 0 | D37: 541 | E37: 0 | F37: 126 | N37: S-1 MD&A, non-GAAP reconciliation
A38: Bartz settlement | B38: 0 | C38: 0 | D38: 1500 | E38: 0 | F38: 0 | N38: S-1 MD&A, non-GAAP reconciliation
A39: Adjusted Operating Income (Loss) | B39: -522 | C39: -2788 | D39: -4854 | E39: -1849 | F39: 1618 | N39: S-1 MD&A, non-GAAP reconciliation
A40: Adjusted operating margin | B40: =B39/IS_Hist!B6 -> -12.731707 | C40: =C39/IS_Hist!C6 -> -7.2227979 | D40: =D39/IS_Hist!D6 -> -1.0586696 | E40: =E39/IS_Hist!E6 -> -1.5898538 | F40: =F39/IS_Hist!F6 -> 0.099349134
A41: Change in fair value of convertible notes, derivative liabilities, and SAFEs | B41: 1045 | C41: 5434 | D41: 34308 | E41: 10942 | F41: 72388 | N41: S-1 MD&A, adjusted net income reconciliation
A42: Change in fair value of certain mark-to-market financial instruments | B42: 0 | C42: 0 | D42: 3 | E42: 0 | F42: 8720 | N42: S-1 MD&A, adjusted net income reconciliation
A43: Adjusted Net Income (Loss) | B43: -457 | C43: -2683 | D43: -4448 | E43: -1741 | F43: 2671 | N43: S-1 MD&A, adjusted net income reconciliation
A45: Key metrics stated in the S-1 prose (as of 30 Sep 2026 unless stated)
B46: Value | C46: A year earlier
A47: Customers with US$100,000 or more of TTM revenue | B47: 11900 | C47: 950 | N47: S-1: We had more than 11,900 customers with $100,000 or more of revenue on a TTM basis as of September 30, 2026, up from more than 950 as of September 30, 2025
...

Sheet Cap_Table
A1: Anthropic, PBC | Capital structure, fully diluted shares and the Series H reference price
A2: Shares in thousands unless stated, after the 10-for-1 split of common stock on 17 Sep 2026. Source: Form S-1, 26 Oct 2026 (balance sheet captions, Notes 10 and 11).
A4: Item | B4: Value | C4: Price (USD) | D4: Comentarios FG | E4: Source / derivation
A6: A. Common stock outstanding, 30 Jun 2026
A7: Class A common stock | B7: 2157398 | E7: Balance sheet caption: 2,157,398 thousand issued and outstanding
A8: Class N common stock (non-voting) | B8: 30643 | E8: Balance sheet caption: 30,643 thousand
A9: Common shares outstanding | B9: =B7+B8 -> 2188041
A11: B. Redeemable convertible preferred stock, as converted into common (Note 10)
A12: Series A | B12: 485744 | E12: Note 10: common stock reserved, as-if converted, 30 Jun 2026
A13: Series B | B13: 874304 | E13: Note 10: common stock reserved, as-if converted, 30 Jun 2026
A14: Series C-1 | B14: 263972 | E14: Note 10: common stock reserved, as-if converted, 30 Jun 2026
A15: Series C-2 | B15: 133617 | E15: Note 10: common stock reserved, as-if converted, 30 Jun 2026
A16: Series D-1 | B16: 370299 | E16: Note 10: common stock reserved, as-if converted, 30 Jun 2026
A17: Series D-2 | B17: 46314 | E17: Note 10: common stock reserved, as-if converted, 30 Jun 2026
A18: Series D-3 | B18: 52873 | E18: Note 10: common stock reserved, as-if converted, 30 Jun 2026
A19: Series E-1 | B19: 636101 | E19: Note 10: common stock reserved, as-if converted, 30 Jun 2026
A20: Series E-2 | B20: 952819 | E20: Note 10: common stock reserved, as-if converted, 30 Jun 2026
A21: Series E-3 | B21: 126646 | E21: Note 10: common stock reserved, as-if converted, 30 Jun 2026
A22: Series E-4 | B22: 153429 | E22: Note 10: common stock reserved, as-if converted, 30 Jun 2026
A23: Series E-5 | B23: 242436 | E23: Note 10: common stock reserved, as-if converted, 30 Jun 2026
... A35: Series H-4 | B35: 0 | E35: Note 10: common stock reserved, as-if converted, 30 Jun 2026
A36: Preferred stock as converted | B36: =SUM(B12:B35) -> 8558869 | E36: Conversion ratio 10:1, Series D about 10.4-10.6:1 after anti-dilution adjustments (Note 10).
A38: C. Other dilutive securities, 30 Jun 2026
A39: Convertible notes (Amazon): Class N shares issuable on conversion | B39: 1840445 | E39: MD&A table: 1,840,444,962 shares at conversion prices US$2.0928 and US$5.0478; principal US$6,203m.
A40: Stock options outstanding | B40: 1797066 | C40: 2.89 | E40: Note 11: weighted-average exercise price US$2.89.
A41: Stock options, net shares by the treasury method at the Series H price | B41: =B40*(1-C40/C52) -> 1708892.2 | E41: Options x (1 - exercise price / reference price).
A42: Restricted stock units outstanding | B42: 1049631 | E42: Note 11: vest at the IPO for the service already given.
A43: Holdback shares (acquisitions) | B43: 1590 | E43: Note 12 anti-dilutive table.
A44: Shares available under the donation matching plan | B44: 933698 | E44: Note 10: reserved for the employee donation matching program; issued as donations are matched.
A45: Include the donation matching reserve (1 = yes, 0 = no) | B45: 1 | E45: Analyst choice. With it, the count matches the US$965bn Series H post-money within about 1%.
A46: Fully diluted shares (thousands) | B46: =B9+B36+B39+B41+B42+B43+B44*B45 -> 16281166
A47: Fully diluted shares (millions) | B47: =B46/1000 -> 16281.166
A49: D. Reference price: the Series H round (S-1)
A50: Series H-1 and H-2 price per preferred share (USD) | C50: 589.0095 | E50: S-1 Note 10: 'at a price of $589.0095 per share, for aggregate gross proceeds of $65.2 billion' (second quarter of 2026).
A51: Common shares per preferred share | B51: 10 | E51: Conversion ratio 10:1 after the split (Note 10).
A52: Series H price per common share (USD) | C52: =C50/B51 -> 58.90095
A53: Equity value at the Series H price (USD m) | B53: =B47*C52 -> 958976.16
A54: Memo: Series H post-money announced by the company (USD m) | B54: 965000 | E54: Company blog and Reuters, 28 May 2026: Series H at US$965bn post-money. Not in the S-1; memo check of the share count only
A55: Share count check: equity at the Series H price / post-money - 1 | B55: =B53/B54-1 -> -0.0062423253
A57: E. Original issue price by series (Note 10, 30 Jun 2026)
...

Sheet Assumptions
A1: Anthropic, PBC | Assumptions and scenarios
A2: Blue cells are inputs. Each driver has Base, Bull and Bear rows; the Active row follows the switch in C5. USD millions unless stated.
B3: Actual | C3: Forecast
A4: Fiscal year ends 31 December | B4: 2025A | C4: 2026E | D4: 2027E | E4: 2028E | F4: 2029E | G4: 2030E | H4: 2031E | I4: 2032E | J4: 2033E | K4: 2034E | L4: 2035E | M4: Comentarios FG | N4: Source / derivation
A5: Scenario switch: 1 = Base, 2 = Bull, 3 = Bear | C5: 1 | N5: Same convention as the house templates (Supuestos!C5).
A6: Active scenario | C6: =CHOOSE(C5,"Base","Bull","Bear") -> Base
A8: A. Second half of 2026 and valuation inputs (one value per scenario)
C9: Active | D9: Base | E9: Bull | F9: Bear
A10: Q3 2026E revenue (USD m) | C10: =CHOOSE($C$5,D10,E10,F10) -> 17500 | D10: 17500 | E10: 19000 | F10: 16700 | N10: S-1 floor: TTM revenue per employee 'over $6.6 million' x about 5,300 employees = TTM revenue above US$34,980m, so Q3 2026 is above US$16,654m (Revenue_Hist). Bear = the floor. Press: July 2026 run-rate above US$65bn (Reuters, 17 Aug 2026; not in the S-1).
A11: Q4 2026E revenue (USD m) | C11: =CHOOSE($C$5,D11,E11,F11) -> 21000 | D11: 21000 | E11: 25000 | F11: 17500 | N11: Base +20% on Q3 2026E; Bull +32%; Bear +5%. Q2 2026 grew 144% on Q1 (S-1). Analyst input.
A12: H2 2026E compute and infrastructure: % of revenue | C12: =CHOOSE($C$5,D12,E12,F12) -> 0.5 | D12: 0.5 | E12: 0.47 | F12: 0.54 | N12: Q2 2026 48.1% (S-1); the S-1 expects more short-term compute in the near term. Analyst input.
A13: H2 2026E personnel, cash part: % of revenue | C13: =CHOOSE($C$5,D13,E13,F13) -> 0.05 | D13: 0.05 | E13: 0.05 | F13: 0.055 | N13: Q2 2026 5.2% (S-1). Analyst input.
A14: H2 2026E sales, marketing and partnerships: % of revenue | C14: =CHOOSE($C$5,D14,E14,F14) -> 0.18 | D14: 0.18 | E14: 0.17 | F14: 0.19 | N14: Q2 2026 18.5% (S-1). Analyst input.
A15: H2 2026E other operating and administrative: % of revenue | C15: =CHOOSE($C$5,D15,E15,F15) -> 0.085 | D15: 0.085 | E15: 0.08 | F15: 0.09 | N15: Q2 2026 8.9% (S-1). Analyst input.
A16: Terminal growth (after 2035E) | C16: =CHOOSE($C$5,D16,E16,F16) -> 0.03 | D16: 0.03 | E16: 0.035 | F16: 0.025 | N16: Below the 10-year Treasury yield (5.00%); near long-run nominal GDP. Analyst input.
A17: Terminal return on new invested capital | C17: =CHOOSE($C$5,D17,E17,F17) -> 0.25 | D17: 0.25 | E17: 0.35 | F17: 0.15 | N17: Reinvestment = growth / ROIC (Damodaran). Mature software and platform returns 20%-40%. Analyst input.
A18: Exit EV / EBITDA multiple (2035E) | C18: =CHOOSE($C$5,D18,E18,F18) -> 15 | D18: 15 | E18: 18 | F18: 12 | N18: Cross-check only. AI platform peers today: Microsoft 20.6x, Alphabet 21.7x, Meta 14.2x LTM EV/EBITDA (stockanalysis.com, 26 Oct 2026). A 2035 exit sees lower growth. Analyst input.
A20: B. Inputs that do not change with the scenario
A21: H2 2026E stock-based compensation before the IPO catch-up (USD m) | C21: 2600 | N21: Q2 2026 1,261 (S-1), about 1,300 a quarter.
A22: Q4 2026E one-off RSU charge at the IPO (USD m) | C22: 2900 | N22: S-1: of US$26.6bn unrecognized RSU cost at 30 Jun 2026, 'US$2.9 billion relates to RSUs for which the service-based vesting condition had been satisfied or partially satisfied'; recorded when the S-1 becomes effective. Assumes an IPO before 31 Dec 2026.
A23: H2 2026E capital expenditures incl. finance-lease principal (USD m) | C23: 1500 | N23: 6M 2026 482 plus 148 accrued, unpaid (S-1). Anthropic Direct ramps. Analyst input.
A24: H2 2026E change in fair value of notes and other financial items (USD m) | C24: 0 | N24: Non-cash; stops when the notes convert at the IPO. The S-1 gives no estimate. Set to zero (no effect on cash or value).
A25: IPO primary proceeds to the company (USD m) | C25: 0 | N25: Price range and share count blank in the S-1. Kept at zero: new shares sold near fair value change value per share very little.
A26: Interest income yield on cash and short-term investments | C26: 0.035 | N26: 6M 2026 realized about 2.9% on average balances (S-1); 3-month bill 4.22% (Treasury, 26 Oct 2026). Analyst input.
A27: Cash tax rate on taxable income after loss carryforwards | C27: 0.21 | N27: US federal 21%; state taxes offset by research credits (S-1 tax note: R&D credit deferred tax asset 656). Analyst input.
A28: Deferred tax asset for net operating losses, 31 Dec 2025 (USD m) | C28: 2007 | N28: S-1 income tax note (fully reserved by the valuation allowance).
A29: Share of taxable income that loss carryforwards can offset | C29: 0.8 | N29: US federal limit for losses arising after 2017.
A30: Accounts receivable: % of revenue | C30: 0.18 | N30: 30 Jun 2026: 5,833 / (2 x 6M revenue 16,286) = 17.9% (S-1).
A31: Prepaid expenses and other current assets: % of revenue | C31: 0.015 | N31: 30 Jun 2026: 496 / 32,572 = 1.5% (S-1).
A32: Deferred revenue: % of revenue | C32: 0.05 | N32: 30 Jun 2026: 1,650 / 32,572 = 5.1% (S-1).
... A36: Sensitivity: compute cost shift, all years 2027E-2035E (pp of revenue) | C36: 0 | N36: Keep at 0. The Sensitivity sheet moves it.
A37: Net operating loss carryforwards, 31 Dec 2025, estimate (USD m) | C37: =C28/C27 -> 9557.1429 | N37: Deferred tax asset / 21%. The S-1 gives the tax asset, not the gross loss; mixed federal and state rates make this an estimate.
A39: C. Drivers by year (Base, Bull, Bear and the active row)
A40: Revenue: growth on a year earlier | N40: 2025A +1,088%; 6M 2026 +1,300% (S-1). The S-1 says growth will decline, possibly fast. Base 2027E: Q4 2026E run-rate (US$84bn) plus about 35% growth over 2027. Base 2028E (US$182bn) sits below the US$190-200bn the company reportedly gave investors (Reuters, 15 Aug 2026; not in the S-1); Bull reaches it. Analyst input.
A41: Base | D41: 1.1 | E41: 0.6 | F41: 0.38 | G41: 0.27 | H41: 0.2 | I41: 0.15 | J41: 0.12 | K41: 0.1 | L41: 0.08
A42: Bull | D42: 1.25 | E42: 0.7 | F42: 0.45 | G42: 0.32 | H42: 0.24 | I42: 0.18 | J42: 0.14 | K42: 0.11 | L42: 0.09
A43: Bear | D43: 0.7 | E43: 0.35 | F43: 0.22 | G43: 0.15 | H43: 0.11 | I43: 0.09 | J43: 0.07 | K43: 0.06 | L43: 0.05
A44: Active | D44: =CHOOSE($C$5,D41,D42,D43) -> 1.1 | E44: =CHOOSE($C$5,E41,E42,E43) -> 0.6 | F44: =CHOOSE($C$5,F41,F42,F43) -> 0.38 | G44: =CHOOSE($C$5,G41,G42,G43) -> 0.27 | H44: =CHOOSE($C$5,H41,H42,H43) -> 0.2 | I44: =CHOOSE($C$5,I41,I42,I43) -> 0.15 | J44: =CHOOSE($C$5,J41,J42,J43) -> 0.12 | K44: =CHOOSE($C$5,K41,K42,K43) -> 0.1 | L44: =CHOOSE($C$5,L41,L42,L43) -> 0.08
A45: Compute and infrastructure: % of revenue | N45: 2025A 159.8%; 6M 2026 54.9%; Q2 2026 48.1% (S-1). The S-1 warns that margins may compress as new compute comes online and as short-term compute rises. Includes CSP fees and all depreciation of owned infrastructure. Analyst input.
A46: Base | D46: 0.5 | E46: 0.48 | F46: 0.46 | G46: 0.44 | H46: 0.42 | I46: 0.41 | J46: 0.4 | K46: 0.4 | L46: 0.4
...

Sheet Interim_Bridge
A1: Anthropic, PBC | 2026E bridge: six months actual plus a second-half estimate
A2: 6M columns link to the S-1 statements; H2 2026E comes from the inputs on Assumptions. Balance sheet rows: 6M 2026A = 30 Jun 2026, FY2026E = 31 Dec 2026E. USD millions.
A4: Line | B4: 6M 2026A | C4: H2 2026E | D4: FY2026E | E4: 6M 2025A | F4: H2 2025A | G4: FY2025A | H4: Comentarios FG | I4: Source / derivation
A6: Income statement
A7: Revenue | B7: =IS_Hist!F6 -> 16286 | C7: =C8+C9 -> 38500 | D7: =B7+C7 -> 54786 | E7: =IS_Hist!E6 -> 1163 | F7: =G7-E7 -> 3422 | G7: =IS_Hist!D6 -> 4585
A8: Q3 2026E revenue | C8: =Assumptions!$C$10 -> 17500
A9: Q4 2026E revenue | C9: =Assumptions!$C$11 -> 21000
A10: Compute and infrastructure | B10: =IS_Hist!F9 -> 8945 | C10: =C7*Assumptions!$C$12 -> 19250 | D10: =B10+C10 -> 28195 | E10: =IS_Hist!E9 -> 2334 | F10: =G10-E10 -> 4992 | G10: =IS_Hist!D9 -> 7326
A11: Stock-based compensation (memo; inside personnel) | B11: =CF_Hist!F10 -> 2185 | C11: =Assumptions!$C$21+Assumptions!$C$22 -> 5500 | D11: =B11+C11 -> 7685 | E11: =CF_Hist!E10 -> 279 | F11: =G11-E11 -> 879 | G11: =CF_Hist!D10 -> 1158 | I11: H2 2026E includes the one-off RSU charge at the IPO.
A12: Personnel, cash part (memo) | B12: =IS_Hist!F10-B11 -> 967 | C12: =C7*Assumptions!$C$13 -> 1925 | D12: =B12+C12 -> 2892 | E12: =IS_Hist!E10-E11 -> 259 | F12: =G12-E12 -> 422 | G12: =IS_Hist!D10-G11 -> 681
A13: Personnel | B13: =IS_Hist!F10 -> 3152 | C13: =C12+C11 -> 7425 | D13: =B13+C13 -> 10577 | E13: =IS_Hist!E10 -> 538 | F13: =G13-E13 -> 1301 | G13: =IS_Hist!D10 -> 1839
A14: Bartz settlement | B14: =IS_Hist!F11 -> 0 | C14: 0 | D14: =B14+C14 -> 0 | E14: =IS_Hist!E11 -> 0 | F14: =G14-E14 -> 1500 | G14: =IS_Hist!D11 -> 1500
A15: Sales, marketing, and partnerships | B15: =IS_Hist!F12 -> 3168 | C15: =C7*Assumptions!$C$14 -> 6930 | D15: =B15+C15 -> 10098 | E15: =IS_Hist!E12 -> 120 | F15: =G15-E15 -> 448 | G15: =IS_Hist!D12 -> 568
A16: Other operating and administrative | B16: =IS_Hist!F13 -> 1714 | C16: =C7*Assumptions!$C$15 -> 3272.5 | D16: =B16+C16 -> 4986.5 | E16: =IS_Hist!E13 -> 306 | F16: =G16-E16 -> 1106 | G16: =IS_Hist!D13 -> 1412
A17: Total operating expenses | B17: =B10+B13+B14+B15+B16 -> 16979 | C17: =C10+C13+C14+C15+C16 -> 36877.5 | D17: =B17+C17 -> 53856.5 | E17: =E10+E13+E14+E15+E16 -> 3298 | F17: =G17-E17 -> 9347 | G17: =G10+G13+G14+G15+G16 -> 12645
A18: Operating income (loss) | B18: =B7-B17 -> -693 | C18: =C7-C17 -> 1622.5 | D18: =B18+C18 -> 929.5 | E18: =E7-E17 -> -2135 | F18: =G18-E18 -> -5925 | G18: =G7-G17 -> -8060
A19: Depreciation and amortization (memo; inside the costs above) | B19: =CF_Hist!F11 -> 97 | C19: =(BS_Hist!D15+0.5*Assumptions!$C$23)/Assumptions!$C$34*0.5 -> 193.7 | D19: =B19+C19 -> 290.7 | E19: =CF_Hist!E11 -> 14 | F19: =G19-E19 -> 26 | G19: =CF_Hist!D11 -> 40 | I19: H2 2026E: (PP&E at 30 Jun 2026 + half the H2 capex) / average life x half a year.
A20: Non-cash charitable contributions (memo) | B20: =Revenue_Hist!F37 -> 126 | C20: 0 | D20: =B20+C20 -> 126 | E20: =Revenue_Hist!E37 -> 0 | F20: =G20-E20 -> 541 | G20: =Revenue_Hist!D37 -> 541
A21: Adjusted operating income (company definition) | B21: =B18+B11+B20+B14 -> 1618 | C21: =C18+C11+C20+C14 -> 7122.5 | D21: =B21+C21 -> 8740.5 | E21: =E18+E11+E20+E14 -> -1856 | F21: =G21-E21 -> -3005 | G21: =G18+G11+G20+G14 -> -4861
A22: Interest income | B22: =IS_Hist!F16 -> 1111 | C22: =Assumptions!$C$26*B44*0.5 -> 2303.8925 | D22: =B22+C22 -> 3414.8925 | E22: =IS_Hist!E16 -> 115 | F22: =G22-E22 -> 316 | G22: =IS_Hist!D16 -> 431
A23: Change in fair value of notes and other items | B23: =IS_Hist!F17+IS_Hist!F18 -> -81145 | C23: =Assumptions!$C$24 -> 0 | D23: =B23+C23 -> -81145 | E23: =IS_Hist!E17+IS_Hist!E18 -> -10942 | F23: =G23-E23 -> -23374 | G23: =IS_Hist!D17+IS_Hist!D18 -> -34316
A24: Income (loss) before income taxes | B24: =B18+B22+B23 -> -80727 | C24: =C18+C22+C23 -> 3926.3925 | D24: =B24+C24 -> -76800.607 | E24: =E18+E22+E23 -> -12962 | F24: =G24-E24 -> -28983 | G24: =G18+G22+G23 -> -41945
A25: Provision for income taxes | B25: =IS_Hist!F21 -> 21 | C25: =MAX(0,Schedules!C20-B25) -> 161.46448 | D25: =B25+C25 -> 182.46448 | E25: =IS_Hist!E21 -> 7 | F25: =G25-E25 -> 13 | G25: =IS_Hist!D21 -> 20 | I25: FY2026E tax from the loss-carryforward schedule (Schedules) less the six-month actual.
A26: Net income (loss) | B26: =B24-B25 -> -80748 | C26: =C24-C25 -> 3764.928 | D26: =B26+C26 -> -76983.072 | E26: =E24-E25 -> -12969 | F26: =G26-E26 -> -28996 | G26: =G24-G25 -> -41965
A28: Cash flow (6M 2026A as filed; H2 2026E from the rows above and the balance sheet below)
A29: Net income (loss) | B29: =CF_Hist!F7 -> -80748 | C29: =C26 -> 3764.928 | D29: =B29+C29 -> -76983.072
A30: Depreciation and amortization | B30: =CF_Hist!F11 -> 97 | C30: =C19 -> 193.7 | D30: =B30+C30 -> 290.7
A31: Stock-based compensation | B31: =CF_Hist!F10 -> 2185 | C31: =C11 -> 5500 | D31: =B31+C31 -> 7685
A32: Fair value changes and other non-cash items | B32: =CF_Hist!F12+CF_Hist!F13+CF_Hist!F14+CF_Hist!F15 -> 81227 | C32: =-C23 -> 0 | D32: =B32+C32 -> 81227
A33: Changes in operating assets and liabilities | B33: =CF_Hist!F18+CF_Hist!F19+CF_Hist!F20+CF_Hist!F21+CF_Hist!F22 -> 1168 | C33: =-(D45-B45)-(D46-B46)+(D50-B50)+(D51-B51) -> -228.47 | D33: =B33+C33 -> 939.53
A34: Net cash from operating activities | B34: =B29+B30+B31+B32+B33 -> 3929 | C34: =C29+C30+C31+C32+C33 -> 9230.158 | D34: =B34+C34 -> 13159.158
A35: Capital expenditures | B35: =CF_Hist!F26 -> -482 | C35: =-Assumptions!$C$23 -> -1500 | D35: =B35+C35 -> -1982
A36: Other investing (excluding short-term investment flows) | B36: =CF_Hist!F29 -> -337 | C36: 0 | D36: =B36+C36 -> -337
A37: Net cash from financing activities | B37: =CF_Hist!F40 -> 110774 | C37: =Assumptions!$C$25 -> 0 | D37: =B37+C37 -> 110774 | I37: 6M 2026A: Series G and H proceeds US$110.4bn. H2 2026E: IPO primary proceeds input (zero).
A38: Restricted cash, exchange rates and investment marks (balancing item) | B38: =B44-B40-(B34+B35+B36+B37) -> -2510 | C38: 0 | D38: =B38+C38 -> -2510 | I38: 6M 2026A: restricted cash rose 2,516 (Broadcom and lease deposits), FX -5, investment marks 11.
A39: Net change in cash and short-term investments | B39: =B34+B35+B36+B37+B38 -> 111374 | C39: =C34+C35+C36+C37+C38 -> 7730.158 | D39: =B39+C39 -> 119104.16
A40: Cash and short-term investments, beginning | B40: =BS_Hist!C45 -> 20277 | C40: =B44 -> 131651 | D40: =B40 -> 20277
A41: Cash and short-term investments, ending | B41: =B40+B39 -> 131651 | C41: =C40+C39 -> 139381.16 | D41: =C41 -> 139381.16
A43: Balance sheet: 30 Jun 2026A (column B) to 31 Dec 2026E (column D)
A44: Cash and short-term investments | B44: =BS_Hist!D45 -> 131651 | D44: =C41 -> 139381.16
...

Sheet Schedules
A1: Anthropic, PBC | Schedules: capex and depreciation, loss carryforwards and taxes, working capital, unlevered free cash flow
A2: 2026E is the full year (six months actual plus the H2 estimate). USD millions.
B3: Actual | C3: Forecast
A4: Fiscal year ends 31 December | B4: 2025A | C4: 2026E | D4: 2027E | E4: 2028E | F4: 2029E | G4: 2030E | H4: 2031E | I4: 2032E | J4: 2033E | K4: 2034E | L4: 2035E | M4: Comentarios FG | N4: Source / derivation
A6: A. Capital expenditures and property and equipment
A7: Capital expenditures | B7: =-CF_Hist!D26 -> 131 | C7: =-CF_Hist!F26+Assumptions!$C$23 -> 1982 | D7: =Forecast_3Stmt!D7*Assumptions!D74 -> 6903.036 | E7: =Forecast_3Stmt!E7*Assumptions!E74 -> 14726.477 | F7: =Forecast_3Stmt!F7*Assumptions!F74 -> 20322.538 | G7: =Forecast_3Stmt!G7*Assumptions!G74 -> 22583.42 | H7: =Forecast_3Stmt!H7*Assumptions!H74 -> 23228.661 | I7: =Forecast_3Stmt!I7*Assumptions!I74 -> 26712.96 | J7: =Forecast_3Stmt!J7*Assumptions!J74 -> 24932.096 | K7: =Forecast_3Stmt!K7*Assumptions!K74 -> 27425.306 | L7: =Forecast_3Stmt!L7*Assumptions!L74 -> 29619.33
A8: % of revenue | B8: =B7/Forecast_3Stmt!B7 -> 0.028571429 | C8: =C7/Forecast_3Stmt!C7 -> 0.036177126 | D8: =D7/Forecast_3Stmt!D7 -> 0.06 | E8: =E7/Forecast_3Stmt!E7 -> 0.08 | F8: =F7/Forecast_3Stmt!F7 -> 0.08 | G8: =G7/Forecast_3Stmt!G7 -> 0.07 | H8: =H7/Forecast_3Stmt!H7 -> 0.06 | I8: =I7/Forecast_3Stmt!I7 -> 0.06 | ... L8: =L7/Forecast_3Stmt!L7 -> 0.05
A9: Property and equipment, beginning | C9: =B12 -> 146 | D9: =C12 -> 2493.3 | E9: =D12 -> 8207.3724 | F9: =E12 -> 19819.727 | G9: =F12 -> 34146.066 | H9: =G12 -> 47641.931 | I9: =H12 -> 59019.34 | J9: =I12 -> 71257.136 | ... L9: =K12 -> 88238.451
A10: Depreciation and amortization | B10: =CF_Hist!D11 -> 40 | C10: =Interim_Bridge!D19 -> 290.7 | D10: =(D9+0.5*D7)/Assumptions!$C$34 -> 1188.9636 | E10: =(E9+0.5*E7)/Assumptions!$C$34 -> 3114.1222 | F10: =(F9+0.5*F7)/Assumptions!$C$34 -> 5996.1992 | G10: =(G9+0.5*G7)/Assumptions!$C$34 -> 9087.5552 | H10: =(H9+0.5*H7)/Assumptions!$C$34 -> 11851.252 | I10: =(I9+0.5*I7)/Assumptions!$C$34 -> 14475.164 | J10: =(J9+0.5*J7)/Assumptions!$C$34 -> 16744.637 | K10: =(K9+0.5*K7)/Assumptions!$C$34 -> 18631.45 | L10: =(L9+0.5*L7)/Assumptions!$C$34 -> 20609.623 | N10: (Beginning PP&E + half the year's capex) / average life.
A11: Other additions (finance-lease assets, acquisitions, accrued capex) | C11: =C12-C9-C7+C10 -> 656 | D11: =0 -> 0 | E11: =0 -> 0 | F11: =0 -> 0 | G11: =0 -> 0 | H11: =0 -> 0 | I11: =0 -> 0 | J11: =0 -> 0 | K11: =0 -> 0 | L11: =0 -> 0 | N11: 2026E: balancing item to the 31 Dec 2026E balance (6M 2026: finance-lease assets 445, accrued capex 148).
A12: Property and equipment, ending | B12: =BS_Hist!C15 -> 146 | C12: =Interim_Bridge!D47 -> 2493.3 | D12: =D9+D7+D11-D10 -> 8207.3724 | E12: =E9+E7+E11-E10 -> 19819.727 | F12: =F9+F7+F11-F10 -> 34146.066 | G12: =G9+G7+G11-G10 -> 47641.931 | H12: =H9+H7+H11-H10 -> 59019.34 | I12: =I9+I7+I11-I10 -> 71257.136 | J12: =J9+J7+J11-J10 -> 79444.595 | K12: =K9+K7+K11-K10 -> 88238.451 | L12: =L9+L7+L11-L10 -> 97248.158
A14: B. Loss carryforwards and cash taxes
A15: Taxable income before loss carryforwards (operating income + interest income) | C15: =Forecast_3Stmt!C17+Forecast_3Stmt!C19 -> 4344.3925 | D15: =Forecast_3Stmt!D17+Forecast_3Stmt!D19 -> 18109.16 | E15: =Forecast_3Stmt!E17+Forecast_3Stmt!E19 -> 39683.546 | F15: =Forecast_3Stmt!F17+Forecast_3Stmt!F19 -> 69046.009 | G15: =Forecast_3Stmt!G17+Forecast_3Stmt!G19 -> 102342.4 | H15: =Forecast_3Stmt!H17+Forecast_3Stmt!H19 -> 139490.51 | I15: =Forecast_3Stmt!I17+Forecast_3Stmt!I19 -> 176103.94 | J15: =Forecast_3Stmt!J17+Forecast_3Stmt!J19 -> 207951.61 | ... L15: =Forecast_3Stmt!L17+Forecast_3Stmt!L19 -> 265413.56 | N15: Fair value changes on the notes are treated as neither taxable nor deductible.
A16: Loss carryforwards, beginning | C16: =Assumptions!$C$37 -> 9557.1429 | D16: =C19 -> 6081.6289 | E16: =D19 -> 0 | F16: =E19 -> 0 | G16: =F19 -> 0 | H16: =G19 -> 0 | I16: =H19 -> 0 | J16: =I19 -> 0 | K16: =J19 -> 0 | L16: =K19 -> 0
A17: Used | C17: =MIN(C16,MAX(0,C15)*Assumptions!$C$29) -> 3475.514 | D17: =MIN(D16,MAX(0,D15)*Assumptions!$C$29) -> 6081.6289 | E17: =MIN(E16,MAX(0,E15)*Assumptions!$C$29) -> 0 | F17: =MIN(F16,MAX(0,F15)*Assumptions!$C$29) -> 0 | G17: =MIN(G16,MAX(0,G15)*Assumptions!$C$29) -> 0 | H17: =MIN(H16,MAX(0,H15)*Assumptions!$C$29) -> 0 | I17: =MIN(I16,MAX(0,I15)*Assumptions!$C$29) -> 0 | J17: =MIN(J16,MAX(0,J15)*Assumptions!$C$29) -> 0 | ... L17: =MIN(L16,MAX(0,L15)*Assumptions!$C$29) -> 0
A18: Added | C18: =MAX(0,-C15) -> 0 | D18: =MAX(0,-D15) -> 0 | E18: =MAX(0,-E15) -> 0 | F18: =MAX(0,-F15) -> 0 | G18: =MAX(0,-G15) -> 0 | H18: =MAX(0,-H15) -> 0 | I18: =MAX(0,-I15) -> 0 | J18: =MAX(0,-J15) -> 0 | ... L18: =MAX(0,-L15) -> 0
A19: Loss carryforwards, ending | C19: =C16-C17+C18 -> 6081.6289 | D19: =D16-D17+D18 -> 0 | E19: =E16-E17+E18 -> 0 | F19: =F16-F17+F18 -> 0 | G19: =G16-G17+G18 -> 0 | H19: =H16-H17+H18 -> 0 | I19: =I16-I17+I18 -> 0 | J19: =J16-J17+J18 -> 0 | ... L19: =L16-L17+L18 -> 0
