Workbook

Sheet 00_Cover
A1: Amazon.com, Inc. (AMZN) — 9/10 Re-gated Institutional Model
A2: Owner-prepared submission; independent reviewer reproduction is required before certification
A4: Model snapshot
A5: Legal entity | B5: Amazon.com, Inc.
A6: Ticker | B6: AMZN
A7: Latest filing | B7: 2025-12-31 10-K filed 2026-02-06
A8: SEC accession | B8: 0001018724-26-000004
A9: Market price | B9: 254.96
A10: Market as-of | B10: 2026-07-15
A11: Active scenario | B11: =Assumptions!B4 -> Base
A12: DCF value / share | B12: =Valuation!G18 -> 61.190937
A13: Upside / (downside) | B13: =Valuation!G20 -> -0.75999789
A14: Gate decision | B14: =Gate_9of10!B17 -> OWNER READY — INDEPENDENT REVIEW REQUIRED
A16: What changed in the 9/10 re-gate
A17: 1 | B17: Replaced generic Sources sheet with target-cell provenance ledger
A18: 2 | B18: Replaced generic assumptions with company-specific operating drivers
A19: 3 | B19: Scenario selector now changes multiple operating outputs and the DCF
A20: 4 | B20: Debt, liquid assets and share-count valuation bridges are explicit
A21: 5 | B21: Checks are formula-driven; Gate_9of10 states owner evidence and review status
A22: 6 | B22: All original workbook files remain preserved; this is a new derivative output

Sheet Sources
A1: Amazon.com, Inc. — Source Provenance Ledger
A2: Every populated hardcoded historical or driver input is mapped to a target cell with period, value, unit, taxonomy/locator, accession and exact URL.
A4: Source ID | B4: Legal Entity | C4: Target Cell | D4: Metric | E4: Period / As-of | F4: Reported Value | G4: Units | H4: Currency | I4: Taxonomy / Locator | J4: Start | K4: End | L4: FY / FP | M4: Form | N4: Filed | O4: Accession | P4: Exact URL | Q4: Retrieved | R4: Source Class | S4: Transform / Mapping | T4: Verification | U4: Limitation / Disposition | V4: Complete?
A5: 1 | B5: Amazon.com, Inc. | C5: Historical!B5 | D5: Revenue | E5: 2021A | F5: 469822 | G5: USD millions | H5: USD | I5: us-gaap:RevenueFromContractWithCustomerExcludingAssessedTax | J5: 2021-01-01 | K5: 2021-12-31 | L5: 2023/FY | M5: 10-K | N5: 2024-02-02 | O5: 0001018724-24-000008 | P5: https://www.sec.gov/Archives/edgar/data/1018724/000101872424000008/0001018724-24-000008-index.htm | Q5: 2026-07-16 | R5: Primary - SEC filing / Company Facts | S5: USD divided by 1,000,000; sign as presented | T5: Matched legal entity, period, form, filed date, accession and target | U5: None identified | V5: =IF(COUNTA(A5:U5)=21,"OK","MISSING") -> OK
A6: 2 | B6: Amazon.com, Inc. | C6: Historical!C5 | D6: Revenue | E6: 2022A | F6: 513983 | G6: USD millions | H6: USD | I6: us-gaap:RevenueFromContractWithCustomerExcludingAssessedTax | J6: 2022-01-01 | K6: 2022-12-31 | L6: 2024/FY | M6: 10-K | N6: 2025-02-07 | O6: 0001018724-25-000004 | P6: https://www.sec.gov/Archives/edgar/data/1018724/000101872425000004/0001018724-25-000004-index.htm | Q6: 2026-07-16 | R6: Primary - SEC filing / Company Facts | S6: USD divided by 1,000,000; sign as presented | T6: Matched legal entity, period, form, filed date, accession and target | U6: None identified | V6: =IF(COUNTA(A6:U6)=21,"OK","MISSING") -> OK
A7: 3 | B7: Amazon.com, Inc. | C7: Historical!D5 | D7: Revenue | E7: 2023A | F7: 574785 | G7: USD millions | H7: USD | I7: us-gaap:RevenueFromContractWithCustomerExcludingAssessedTax | J7: 2023-01-01 | K7: 2023-12-31 | L7: 2025/FY | M7: 10-K | N7: 2026-02-06 | O7: 0001018724-26-000004 | P7: https://www.sec.gov/Archives/edgar/data/1018724/000101872426000004/0001018724-26-000004-index.htm | Q7: 2026-07-16 | R7: Primary - SEC filing / Company Facts | S7: USD divided by 1,000,000; sign as presented | T7: Matched legal entity, period, form, filed date, accession and target | U7: None identified | V7: =IF(COUNTA(A7:U7)=21,"OK","MISSING") -> OK
A8: 4 | B8: Amazon.com, Inc. | C8: Historical!E5 | D8: Revenue | E8: 2024A | F8: 637959 | G8: USD millions | H8: USD | I8: us-gaap:RevenueFromContractWithCustomerExcludingAssessedTax | J8: 2024-01-01 | K8: 2024-12-31 | L8: 2025/FY | M8: 10-K | N8: 2026-02-06 | O8: 0001018724-26-000004 | P8: https://www.sec.gov/Archives/edgar/data/1018724/000101872426000004/0001018724-26-000004-index.htm | Q8: 2026-07-16 | R8: Primary - SEC filing / Company Facts | S8: USD divided by 1,000,000; sign as presented | T8: Matched legal entity, period, form, filed date, accession and target | U8: None identified | V8: =IF(COUNTA(A8:U8)=21,"OK","MISSING") -> OK
A9: 5 | B9: Amazon.com, Inc. | C9: Historical!F5 | D9: Revenue | E9: 2025A | F9: 716924 | G9: USD millions | H9: USD | I9: us-gaap:RevenueFromContractWithCustomerExcludingAssessedTax | J9: 2025-01-01 | K9: 2025-12-31 | L9: 2025/FY | M9: 10-K | N9: 2026-02-06 | O9: 0001018724-26-000004 | P9: https://www.sec.gov/Archives/edgar/data/1018724/000101872426000004/0001018724-26-000004-index.htm | Q9: 2026-07-16 | R9: Primary - SEC filing / Company Facts | S9: USD divided by 1,000,000; sign as presented | T9: Matched legal entity, period, form, filed date, accession and target | U9: None identified | V9: =IF(COUNTA(A9:U9)=21,"OK","MISSING") -> OK
A10: 6 | B10: Amazon.com, Inc. | C10: Historical!B7 | D10: Operating income / EBIT | E10: 2021A | F10: 24879 | G10: USD millions | H10: USD | I10: us-gaap:OperatingIncomeLoss | J10: 2021-01-01 | K10: 2021-12-31 | L10: 2023/FY | M10: 10-K | N10: 2024-02-02 | O10: 0001018724-24-000008 | P10: https://www.sec.gov/Archives/edgar/data/1018724/000101872424000008/0001018724-24-000008-index.htm | Q10: 2026-07-16 | R10: Primary - SEC filing / Company Facts | S10: USD divided by 1,000,000; sign as presented | T10: Matched legal entity, period, form, filed date, accession and target | U10: None identified | V10: =IF(COUNTA(A10:U10)=21,"OK","MISSING") -> OK
A11: 7 | B11: Amazon.com, Inc. | C11: Historical!C7 | D11: Operating income / EBIT | E11: 2022A | F11: 12248 | G11: USD millions | H11: USD | I11: us-gaap:OperatingIncomeLoss | J11: 2022-01-01 | K11: 2022-12-31 | L11: 2024/FY | M11: 10-K | N11: 2025-02-07 | O11: 0001018724-25-000004 | P11: https://www.sec.gov/Archives/edgar/data/1018724/000101872425000004/0001018724-25-000004-index.htm | Q11: 2026-07-16 | R11: Primary - SEC filing / Company Facts | S11: USD divided by 1,000,000; sign as presented | T11: Matched legal entity, period, form, filed date, accession and target | U11: None identified | V11: =IF(COUNTA(A11:U11)=21,"OK","MISSING") -> OK
A12: 8 | B12: Amazon.com, Inc. | C12: Historical!D7 | D12: Operating income / EBIT | E12: 2023A | F12: 36852 | G12: USD millions | H12: USD | I12: us-gaap:OperatingIncomeLoss | J12: 2023-01-01 | K12: 2023-12-31 | L12: 2025/FY | M12: 10-K | N12: 2026-02-06 | O12: 0001018724-26-000004 | P12: https://www.sec.gov/Archives/edgar/data/1018724/000101872426000004/0001018724-26-000004-index.htm | Q12: 2026-07-16 | R12: Primary - SEC filing / Company Facts | S12: USD divided by 1,000,000; sign as presented | T12: Matched legal entity, period, form, filed date, accession and target | U12: None identified | V12: =IF(COUNTA(A12:U12)=21,"OK","MISSING") -> OK
A13: 9 | B13: Amazon.com, Inc. | C13: Historical!E7 | D13: Operating income / EBIT | E13: 2024A | F13: 68593 | G13: USD millions | H13: USD | I13: us-gaap:OperatingIncomeLoss | J13: 2024-01-01 | K13: 2024-12-31 | L13: 2025/FY | M13: 10-K | N13: 2026-02-06 | O13: 0001018724-26-000004 | P13: https://www.sec.gov/Archives/edgar/data/1018724/000101872426000004/0001018724-26-000004-index.htm | Q13: 2026-07-16 | R13: Primary - SEC filing / Company Facts | S13: USD divided by 1,000,000; sign as presented | T13: Matched legal entity, period, form, filed date, accession and target | U13: None identified | V13: =IF(COUNTA(A13:U13)=21,"OK","MISSING") -> OK
A14: 10 | B14: Amazon.com, Inc. | C14: Historical!F7 | D14: Operating income / EBIT | E14: 2025A | F14: 79975 | G14: USD millions | H14: USD | I14: us-gaap:OperatingIncomeLoss | J14: 2025-01-01 | K14: 2025-12-31 | L14: 2025/FY | M14: 10-K | N14: 2026-02-06 | O14: 0001018724-26-000004 | P14: https://www.sec.gov/Archives/edgar/data/1018724/000101872426000004/0001018724-26-000004-index.htm | Q14: 2026-07-16 | R14: Primary - SEC filing / Company Facts | S14: USD divided by 1,000,000; sign as presented | T14: Matched legal entity, period, form, filed date, accession and target | U14: None identified | V14: =IF(COUNTA(A14:U14)=21,"OK","MISSING") -> OK
A15: 11 | B15: Amazon.com, Inc. | C15: Historical!B8 | D15: Net income | E15: 2021A | F15: 33364 | G15: USD millions | H15: USD | I15: us-gaap:NetIncomeLoss | J15: 2021-01-01 | K15: 2021-12-31 | L15: 2023/FY | M15: 10-K | N15: 2024-02-02 | O15: 0001018724-24-000008 | P15: https://www.sec.gov/Archives/edgar/data/1018724/000101872424000008/0001018724-24-000008-index.htm | Q15: 2026-07-16 | R15: Primary - SEC filing / Company Facts | S15: USD divided by 1,000,000; sign as presented | T15: Matched legal entity, period, form, filed date, accession and target | U15: None identified | V15: =IF(COUNTA(A15:U15)=21,"OK","MISSING") -> OK
A16: 12 | B16: Amazon.com, Inc. | C16: Historical!C8 | D16: Net income | E16: 2022A | F16: -2722 | G16: USD millions | H16: USD | I16: us-gaap:NetIncomeLoss | J16: 2022-01-01 | K16: 2022-12-31 | L16: 2024/FY | M16: 10-K | N16: 2025-02-07 | O16: 0001018724-25-000004 | P16: https://www.sec.gov/Archives/edgar/data/1018724/000101872425000004/0001018724-25-000004-index.htm | Q16: 2026-07-16 | R16: Primary - SEC filing / Company Facts | S16: USD divided by 1,000,000; sign as presented | T16: Matched legal entity, period, form, filed date, accession and target | U16: None identified | V16: =IF(COUNTA(A16:U16)=21,"OK","MISSING") -> OK
... A76: 72 | B76: Amazon.com, Inc. | C76: Valuation!G19 | D76: Market close | E76: 2026-07-15 | F76: 254.96 | G76: USD per share | H76: USD | I76: Secondary market:Historical daily close | J76: N/A - instant | K76: 2026-07-15 | L76: N/A | M76: Market data | N76: 2026-07-15 | O76: N/A - market data | P76: https://www.advfn.com/stock-market/NASDAQ/AMZN/historical/more-historical-data | Q76: 2026-07-16 | R76: Secondary - dated market close | S76: Closing price as displayed; no FX | T76: Date and close matched on cited historical-price surface | U76: Secondary market source; refresh before transaction use | V76: =IF(COUNTA(A76:U76)=21,"OK","MISSING") -> OK
A78: Ledger completeness | G78: =COUNTIF(V5:V76,"OK") -> 72 | H78: 72 | I78: =IF(G78=H78,"OK","REVIEW") -> OK

Sheet Historical
A1: Amazon.com, Inc. — Historical Financials
A2: SEC 10-K / Company Facts lineage; USD millions except per-share data and shares
A4: Metric | B4: 2021A | C4: 2022A | D4: 2023A | E4: 2024A | F4: 2025A
A5: Revenue | B5: 469822 | C5: 513983 | D5: 574785 | E5: 637959 | F5: 716924
A6: Gross profit
A7: Operating income / EBIT | B7: 24879 | C7: 12248 | D7: 36852 | E7: 68593 | F7: 79975
A8: Net income | B8: 33364 | C8: -2722 | D8: 30425 | E8: 59248 | F8: 77670
A9: Cash from operations | B9: 46327 | C9: 46752 | D9: 84946 | E9: 115877 | F9: 139514
A10: Capital expenditures | B10: 61053 | C10: 63645 | D10: 52729 | E10: 82999 | F10: 131819
A11: Total assets | B11: 420549 | C11: 462675 | D11: 527854 | E11: 624894 | F11: 818042
A12: Shareholders' equity | B12: 138245 | C12: 146043 | D12: 201875 | E12: 285970 | F12: 411065
A13: Cash and equivalents | B13: 36220 | C13: 53888 | D13: 73387 | E13: 78779 | F13: 86810
A14: Total debt | B14: 50553 | C14: 70542 | D14: 67182 | E14: 58000 | F14: 68836
A15: Diluted weighted-average shares | B15: 10296 | C15: 10189 | D15: 10492 | E15: 10721 | F15: 10827
A17: Bridge policy | B17: Latest balance-sheet cash policy
A18: Liquid assets used in DCF | B18: =SUM(B23:B24) -> 123029 | F18: USD millions
A19: Debt used in DCF | B19: =SUM(B25:B26) -> 69291 | F19: USD millions
A20: Share count used in DCF | B20: 10734.921 | F20: million shares
A22: Amazon valuation bridge | B22: 2025A | C22: Policy | D22: USD m | E22: Source | F22: Status
A23: Cash and equivalents | B23: =F13 -> 86810 | C23: Included | D23: USD m | E23: Historical latest balance | F23: Formula link
A24: Current marketable securities | B24: 36219 | C24: Included | D24: USD m | E24: us-gaap:MarketableSecuritiesCurrent | F24: OK
A25: Long-term debt | B25: =F14 -> 68836 | C25: Included | D25: USD m | E25: Historical latest balance | F25: Formula link
A26: Short-term borrowings | B26: 455 | C26: Included | D26: USD m | E26: us-gaap:ShortTermBorrowings | F26: OK

Sheet Assumptions
A1: Amazon.com, Inc. — Scenario Assumptions
A2: Selector drives operating revenues/margins and the DCF; blue/amber cells are editable inputs
A3: Scenario selector (1 Base / 2 Bull / 3 Bear) | B3: 1 | G3: Input
A4: Active scenario | B4: =CHOOSE(B3,"Base","Bull","Bear") -> Base | G4: Formula
A6: Assumption | B6: Units | C6: Base | D6: Bull | E6: Bear | F6: Active | G6: Rationale / evidence
A7: North America revenue growth | B7: % | C7: 0.08 | D7: 0.11 | E7: 0.05 | F7: =CHOOSE($B$3,C7,D7,E7) -> 0.08 | G7: 2025 segment revenue USD 426,305m
A8: International revenue growth | B8: % | C8: 0.09 | D8: 0.13 | E8: 0.05 | F8: =CHOOSE($B$3,C8,D8,E8) -> 0.09 | G8: 2025 segment revenue USD 161,894m
A9: AWS revenue growth | B9: % | C9: 0.18 | D9: 0.23 | E9: 0.12 | F9: =CHOOSE($B$3,C9,D9,E9) -> 0.18 | G9: 2025 AWS revenue USD 128,725m
A10: North America operating margin | B10: % | C10: 0.075 | D10: 0.085 | E10: 0.06 | F10: =CHOOSE($B$3,C10,D10,E10) -> 0.075 | G10: 2025 reported 6.9%; normalized scenario
A11: International operating margin | B11: % | C11: 0.04 | D11: 0.06 | E11: 0.01 | F11: =CHOOSE($B$3,C11,D11,E11) -> 0.04 | G11: 2025 reported 2.9%; normalized scenario
A12: AWS operating margin | B12: % | C12: 0.36 | D12: 0.38 | E12: 0.32 | F12: =CHOOSE($B$3,C12,D12,E12) -> 0.36 | G12: 2025 reported 35.4%; normalized scenario
A13: Cash tax rate | B13: % | C13: 0.18 | D13: 0.16 | E13: 0.21 | F13: =CHOOSE($B$3,C13,D13,E13) -> 0.18 | G13: Normalized cash tax rate
A14: D&A as % revenue | B14: % | C14: 0.058 | D14: 0.06 | E14: 0.055 | F14: =CHOOSE($B$3,C14,D14,E14) -> 0.058 | G14: Normalized D&A intensity
A15: Capex as % revenue | B15: % | C15: 0.13 | D15: 0.11 | E15: 0.16 | F15: =CHOOSE($B$3,C15,D15,E15) -> 0.13 | G15: AI and fulfillment infrastructure intensity
A16: NWC investment / revenue growth | B16: % | C16: 0.015 | D16: 0.01 | E16: 0.02 | F16: =CHOOSE($B$3,C16,D16,E16) -> 0.015 | G16: FCFF working-capital policy
A17: WACC | B17: % | C17: 0.095 | D17: 0.085 | E17: 0.105 | F17: =CHOOSE($B$3,C17,D17,E17) -> 0.095 | G17: DCF discount-rate scenario
A18: Terminal growth | B18: % | C18: 0.03 | D18: 0.035 | E18: 0.025 | F18: =CHOOSE($B$3,C18,D18,E18) -> 0.03 | G18: DCF perpetual-growth scenario

Sheet Forecast
A1: Amazon.com, Inc. — Operating Forecast
A2: Scenario-linked driver build; USD millions except shares and per-share data
A4: Metric | B4: 2025A | C4: 2026E | D4: 2027E | E4: 2028E | F4: 2029E | G4: 2030E
A5: North America revenue | B5: 426305 | C5: =B5*(1+Assumptions!F7) -> 460409.4 | D5: =C5*(1+Assumptions!F7) -> 497242.15 | E5: =D5*(1+Assumptions!F7) -> 537021.52 | F5: =E5*(1+Assumptions!F7) -> 579983.25 | G5: =F5*(1+Assumptions!F7) -> 626381.91
A6: International revenue | B6: 161894 | C6: =B6*(1+Assumptions!F8) -> 176464.46 | D6: =C6*(1+Assumptions!F8) -> 192346.26 | E6: =D6*(1+Assumptions!F8) -> 209657.42 | F6: =E6*(1+Assumptions!F8) -> 228526.59 | G6: =F6*(1+Assumptions!F8) -> 249093.99
A7: AWS revenue | B7: 128725 | C7: =B7*(1+Assumptions!F9) -> 151895.5 | D7: =C7*(1+Assumptions!F9) -> 179236.69 | E7: =D7*(1+Assumptions!F9) -> 211499.29 | F7: =E7*(1+Assumptions!F9) -> 249569.17 | G7: =F7*(1+Assumptions!F9) -> 294491.62
A8: Total revenue | B8: =SUM(B5:B7) -> 716924 | C8: =SUM(C5:C7) -> 788769.36 | D8: =SUM(D5:D7) -> 868825.1 | E8: =SUM(E5:E7) -> 958178.24 | F8: =SUM(F5:F7) -> 1058079 | G8: =SUM(G5:G7) -> 1169967.5
A9: North America operating income | B9: 29619 | C9: =C5*Assumptions!F10 -> 34530.705 | D9: =D5*Assumptions!F10 -> 37293.161 | E9: =E5*Assumptions!F10 -> 40276.614 | F9: =F5*Assumptions!F10 -> 43498.743 | G9: =G5*Assumptions!F10 -> 46978.643
A10: International operating income | B10: 4750 | C10: =C6*Assumptions!F11 -> 7058.5784 | D10: =D6*Assumptions!F11 -> 7693.8505 | E10: =E6*Assumptions!F11 -> 8386.297 | F10: =F6*Assumptions!F11 -> 9141.0637 | G10: =G6*Assumptions!F11 -> 9963.7595
A11: AWS operating income | B11: 45606 | C11: =C7*Assumptions!F12 -> 54682.38 | D11: =D7*Assumptions!F12 -> 64525.208 | E11: =E7*Assumptions!F12 -> 76139.746 | F11: =F7*Assumptions!F12 -> 89844.9 | G11: =G7*Assumptions!F12 -> 106016.98
A12: EBIT | B12: =SUM(B9:B11) -> 79975 | C12: =SUM(C9:C11) -> 96271.663 | D12: =SUM(D9:D11) -> 109512.22 | E12: =SUM(E9:E11) -> 124802.66 | F12: =SUM(F9:F11) -> 142484.71 | G12: =SUM(G9:G11) -> 162959.38
A13: Cash taxes | B13: =-B12*Assumptions!F13 -> -14395.5 | C13: =-C12*Assumptions!F13 -> -17328.899 | D13: =-D12*Assumptions!F13 -> -19712.2 | E13: =-E12*Assumptions!F13 -> -22464.478 | F13: =-F12*Assumptions!F13 -> -25647.247 | G13: =-G12*Assumptions!F13 -> -29332.689
A14: NOPAT | B14: =B12+B13 -> 65579.5 | C14: =SUM(C12:C13) -> 78942.764 | D14: =SUM(D12:D13) -> 89800.021 | E14: =SUM(E12:E13) -> 102338.18 | F14: =SUM(F12:F13) -> 116837.46 | G14: =SUM(G12:G13) -> 133626.7
A15: D&A | B15: 0 | C15: =C8*Assumptions!F14 -> 45748.623 | D15: =D8*Assumptions!F14 -> 50391.856 | E15: =E8*Assumptions!F14 -> 55574.338 | F15: =F8*Assumptions!F14 -> 61368.582 | G15: =G8*Assumptions!F14 -> 67858.116
A16: Capital expenditures | B16: 0 | C16: =-C8*Assumptions!F15 -> -102540.02 | D16: =-D8*Assumptions!F15 -> -112947.26 | E16: =-E8*Assumptions!F15 -> -124563.17 | F16: =-F8*Assumptions!F15 -> -137550.27 | G16: =-G8*Assumptions!F15 -> -152095.78
A17: Change in NWC | B17: 0 | C17: =-(C8-B8)*Assumptions!F16 -> -1077.6804 | D17: =-(D8-C8)*Assumptions!F16 -> -1200.8362 | E17: =-(E8-D8)*Assumptions!F16 -> -1340.2971 | F17: =-(F8-E8)*Assumptions!F16 -> -1498.5114 | G17: =-(G8-F8)*Assumptions!F16 -> -1678.3275
A18: FCFF | B18: 0 | C18: =SUM(C14:C17) -> 21073.69 | D18: =SUM(D14:D17) -> 26043.777 | E18: =SUM(E14:E17) -> 32009.048 | F18: =SUM(F14:F17) -> 39157.26 | G18: =SUM(G14:G17) -> 47710.707

Sheet Valuation
A1: Amazon.com, Inc. — DCF Valuation
A2: Unlevered FCFF; liquid-asset and debt bridge policies are explicit
A3: *** NO CLIENT-FACING (flagged 2026-08-14) *** DCF implies -76.0% vs market ($61.19 vs $254.96, market as-of 2026-07-15). This is NOT a formula error: the DCF arithmetic, bridge and per-share identity all reperform exactly. The driver is the operating assumption set. Capex is held at 13.0% of revenue in perpetuity while D&A is 5.8%, a permanent 7.2pp-of-revenue wedge (2030E: capex 152,096 vs D&A 67,858) carried into terminal value. Even forcing terminal capex to ZERO yields only $203.81/sh (-20% vs market), so no single input explains the gap. Market price implies terminal FCFF ~254,358 (21.7% of 2030E revenue) vs the model's 47,711 (4.1%). The whole Sensitivity grid (WACC 8.0-11.0%, TGR 1.5-3.5%) spans only $46.62-$81.39, so the gap is not a discount-rate question. Assumptions unrefreshed since build 2026-07-17 and the market quote is stale. Review Assumptions!C14 (D&A intensity, below Amazon's own ~8%+ historical run-rate) and C15 (capex intensity) and refresh the market date before ANY use.
A4: DCF item | B4: Year 1 | C4: Year 2 | D4: Year 3 | E4: Year 4 | F4: Year 5 | G4: Bridge / output
A5: FCFF | B5: =Forecast!C18 -> 21073.69 | C5: =Forecast!D18 -> 26043.777 | D5: =Forecast!E18 -> 32009.048 | E5: =Forecast!F18 -> 39157.26 | F5: =Forecast!G18 -> 47710.707
A6: Discount period | B6: 1 | C6: 2 | D6: 3 | E6: 4 | F6: 5
A7: Discount factor | B7: =1/(1+Assumptions!F17)^B6 -> 0.91324201 | C7: =1/(1+Assumptions!F17)^C6 -> 0.83401097 | D7: =1/(1+Assumptions!F17)^D6 -> 0.76165385 | E7: =1/(1+Assumptions!F17)^E6 -> 0.69557429 | F7: =1/(1+Assumptions!F17)^F6 -> 0.63522767
A8: Present value of FCFF | B8: =B5*B7 -> 19245.379 | C8: =C5*C7 -> 21720.796 | D8: =D5*D7 -> 24379.815 | E8: =E5*E7 -> 27236.784 | F8: =F5*F7 -> 30307.161
A9: Terminal value | F9: =F5*(1+Assumptions!F18)/(Assumptions!F17-Assumptions!F18) -> 756031.21
A10: PV of terminal value | F10: =F9*F7 -> 480251.94
A11: Enterprise value | G11: =SUM(B8:F8)+F10 -> 603141.87
A12: Liquid assets | G12: =Historical!B18 -> 123029
A13: Debt | G13: =Historical!B19 -> 69291
A14: Equity value | G14: =G11+G12-G13 -> 656879.87
A15: Shares outstanding / diluted policy | G15: =Historical!B20 -> 10734.921
A17: Per-share outputs
A18: DCF value / share | G18: =G14/G15 -> 61.190937
A19: Market price | G19: 254.96
A20: Upside / (downside) | G20: =G18/G19-1 -> -0.75999789
A21: Market as-of | G21: 2026-07-15
A23: Bridge note (2026-08-14): Historical!A14 labels the 68,836 figure 'Total debt' while Historical!A25 relabels the same linked cell 'Long-term debt' and then adds 'Short-term borrowings' of 455 on top (Historical!B26). If 68,836 is genuinely total debt, the bridge double-counts 455 (immaterial at ~$0.04/sh, but the label conflict must be resolved against the 10-K). Not corrected here: the correct reading cannot be determined without the source filing. Amazon finance/operating lease liabilities are NOT in the debt bridge; that is defensible only if EBIT is stated after lease expense - confirm before relying on the EV bridge.

Sheet Sensitivity
A1: Amazon.com, Inc. — DCF Sensitivity
A2: Implied value per share across WACC and terminal-growth assumptions
A4: WACC / TGR | B4: 0.015 | C4: 0.02 | D4: 0.025 | E4: 0.03 | F4: 0.035
A5: 0.08 | B5: =(SUM(Valuation!B8:F8)+Forecast!G18*(1+B$4)/($A5-B$4)*Valuation!F7+Valuation!G12-Valuation!G13)/Valuation!G15 -> 60.539422 | C5: =(SUM(Valuation!B8:F8)+Forecast!G18*(1+C$4)/($A5-C$4)*Valuation!F7+Valuation!G12-Valuation!G13)/Valuation!G15 -> 64.448511 | D5: =(SUM(Valuation!B8:F8)+Forecast!G18*(1+D$4)/($A5-D$4)*Valuation!F7+Valuation!G12-Valuation!G13)/Valuation!G15 -> 69.068343 | E5: =(SUM(Valuation!B8:F8)+Forecast!G18*(1+E$4)/($A5-E$4)*Valuation!F7+Valuation!G12-Valuation!G13)/Valuation!G15 -> 74.612142 | F5: =(SUM(Valuation!B8:F8)+Forecast!G18*(1+F$4)/($A5-F$4)*Valuation!F7+Valuation!G12-Valuation!G13)/Valuation!G15 -> 81.387897
A6: 0.0875 | B6: =(SUM(Valuation!B8:F8)+Forecast!G18*(1+B$4)/($A6-B$4)*Valuation!F7+Valuation!G12-Valuation!G13)/Valuation!G15 -> 55.978818 | C6: =(SUM(Valuation!B8:F8)+Forecast!G18*(1+C$4)/($A6-C$4)*Valuation!F7+Valuation!G12-Valuation!G13)/Valuation!G15 -> 59.115741 | D6: =(SUM(Valuation!B8:F8)+Forecast!G18*(1+D$4)/($A6-D$4)*Valuation!F7+Valuation!G12-Valuation!G13)/Valuation!G15 -> 62.754572 | E6: =(SUM(Valuation!B8:F8)+Forecast!G18*(1+E$4)/($A6-E$4)*Valuation!F7+Valuation!G12-Valuation!G13)/Valuation!G15 -> 67.026243 | F6: =(SUM(Valuation!B8:F8)+Forecast!G18*(1+F$4)/($A6-F$4)*Valuation!F7+Valuation!G12-Valuation!G13)/Valuation!G15 -> 72.111566
A7: 0.095 | B7: =(SUM(Valuation!B8:F8)+Forecast!G18*(1+B$4)/($A7-B$4)*Valuation!F7+Valuation!G12-Valuation!G13)/Valuation!G15 -> 52.273327 | C7: =(SUM(Valuation!B8:F8)+Forecast!G18*(1+C$4)/($A7-C$4)*Valuation!F7+Valuation!G12-Valuation!G13)/Valuation!G15 -> 54.849526 | D7: =(SUM(Valuation!B8:F8)+Forecast!G18*(1+D$4)/($A7-D$4)*Valuation!F7+Valuation!G12-Valuation!G13)/Valuation!G15 -> 57.793752 | E7: =(SUM(Valuation!B8:F8)+Forecast!G18*(1+E$4)/($A7-E$4)*Valuation!F7+Valuation!G12-Valuation!G13)/Valuation!G15 -> 61.190937 | F7: =(SUM(Valuation!B8:F8)+Forecast!G18*(1+F$4)/($A7-F$4)*Valuation!F7+Valuation!G12-Valuation!G13)/Valuation!G15 -> 65.154319
A8: 0.1025 | B8: =(SUM(Valuation!B8:F8)+Forecast!G18*(1+B$4)/($A8-B$4)*Valuation!F7+Valuation!G12-Valuation!G13)/Valuation!G15 -> 49.203064 | C8: =(SUM(Valuation!B8:F8)+Forecast!G18*(1+C$4)/($A8-C$4)*Valuation!F7+Valuation!G12-Valuation!G13)/Valuation!G15 -> 51.358986 | D8: =(SUM(Valuation!B8:F8)+Forecast!G18*(1+D$4)/($A8-D$4)*Valuation!F7+Valuation!G12-Valuation!G13)/Valuation!G15 -> 53.793091 | E8: =(SUM(Valuation!B8:F8)+Forecast!G18*(1+E$4)/($A8-E$4)*Valuation!F7+Valuation!G12-Valuation!G13)/Valuation!G15 -> 56.562935 | F8: =(SUM(Valuation!B8:F8)+Forecast!G18*(1+F$4)/($A8-F$4)*Valuation!F7+Valuation!G12-Valuation!G13)/Valuation!G15 -> 59.743126
A9: 0.11 | B9: =(SUM(Valuation!B8:F8)+Forecast!G18*(1+B$4)/($A9-B$4)*Valuation!F7+Valuation!G12-Valuation!G13)/Valuation!G15 -> 46.617579 | C9: =(SUM(Valuation!B8:F8)+Forecast!G18*(1+C$4)/($A9-C$4)*Valuation!F7+Valuation!G12-Valuation!G13)/Valuation!G15 -> 48.450202 | D9: =(SUM(Valuation!B8:F8)+Forecast!G18*(1+D$4)/($A9-D$4)*Valuation!F7+Valuation!G12-Valuation!G13)/Valuation!G15 -> 50.498429 | E9: =(SUM(Valuation!B8:F8)+Forecast!G18*(1+E$4)/($A9-E$4)*Valuation!F7+Valuation!G12-Valuation!G13)/Valuation!G15 -> 52.802683 | F9: =(SUM(Valuation!B8:F8)+Forecast!G18*(1+F$4)/($A9-F$4)*Valuation!F7+Valuation!G12-Valuation!G13)/Valuation!G15 -> 55.414172
B11: Central cross-check
B12: Active WACC | C12: =Assumptions!F17 -> 0.095
B13: Active TGR | C13: =Assumptions!F18 -> 0.03
B14: Active DCF value/share | C14: =Valuation!G18 -> 61.190937

Sheet Checks
A1: Amazon.com, Inc. — Model Checks
A2: Overall status is formula-driven from assertions; source completeness is linked to the provenance ledger
A4: Assertion | B4: Actual | C4: Expected | D4: Difference | E4: Tolerance | F4: Status | G4: Fix hint
A5: Source ledger complete | B5: =Sources!I78 -> OK | C5: OK | F5: =IF(B5=C5,"OK","REVIEW") -> OK | G5: Complete every mandatory provenance field
A6: Scenario selector valid | B6: =Assumptions!B3 -> 1 | C6: 1 | D6: =IF(AND(B6>=1,B6<=3),0,1) -> 0 | E6: 0 | F6: =IF(D6=E6,"OK","REVIEW") -> OK | G6: Set Assumptions!B3 to 1, 2 or 3
A7: Forecast revenue positive | B7: =Forecast!C8 -> 788769.36 | C7: 0 | D7: =IF(B7>0,0,1) -> 0 | E7: 0 | F7: =IF(D7=E7,"OK","REVIEW") -> OK | G7: Inspect revenue-driver formulas
A8: Five EBIT periods populated | B8: =COUNT(Forecast!C12:G12) -> 5 | C8: 5 | D8: =ABS(B8-C8) -> 0 | E8: 0 | F8: =IF(D8=E8,"OK","REVIEW") -> OK | G8: Inspect margin and opex build
A9: Five FCFF periods populated | B9: =COUNT(Forecast!C18:G18) -> 5 | C9: 5 | D9: =ABS(B9-C9) -> 0 | E9: 0 | F9: =IF(D9=E9,"OK","REVIEW") -> OK | G9: Inspect NOPAT, D&A, capex and NWC
A10: Latest historical capex source present | B10: =COUNT(Historical!F10) -> 1 | C10: 1 | D10: =ABS(B10-C10) -> 0 | E10: 0.1 | F10: =IF(D10<=E10,"OK","REVIEW") -> OK | G10: Historical inputs are positive as reported; forecast expense/capex anchors are negative model outflows
A11: DCF equity bridge | B11: =Valuation!G14 -> 656879.87 | C11: =Valuation!G11+Valuation!G12-Valuation!G13 -> 656879.87 | D11: =ABS(B11-C11) -> 0 | E11: 0.1 | F11: =IF(D11<=E11,"OK","REVIEW") -> OK | G11: Inspect EV, liquid assets and total debt
A12: DCF per-share identity | B12: =Valuation!G18 -> 61.190937 | C12: =Valuation!G14/Valuation!G15 -> 61.190937 | D12: =ABS(B12-C12) -> 0 | E12: 0.001 | F12: =IF(D12<=E12,"OK","REVIEW") -> OK | G12: Inspect shares bridge
A13: Market price positive and sourced | B13: =Valuation!G19 -> 254.96 | C13: 0 | D13: =IF(B13>0,0,1) -> 0 | E13: 0 | F13: =IF(D13=E13,"OK","REVIEW") -> OK | G13: Update the dated market source row in Sources
A15: Overall status | F15: =IF(COUNTIF(F5:F13,"OK")=9,"OK","REVIEW") -> OK

Sheet Sector_KPIs
A1: Amazon.com, Inc. — Company Operating Drivers
A2: Company-specific reported driver history; formulas reconcile the model totals to historical revenue where applicable
A4: Metric | B4: 2023A | C4: 2024A | D4: 2025A | E4: Units | F4: Source / locator | G4: Status
A5: North America revenue | B5: 352828 | C5: 387497 | D5: 426305 | E5: USD m | F5: 2025 Form 10-K segment table | G5: Reported
A6: International revenue | B6: 131200 | C6: 142906 | D6: 161894 | E6: USD m | F6: 2025 Form 10-K segment table | G6: Reported
A7: AWS revenue | B7: 90757 | C7: 107556 | D7: 128725 | E7: USD m | F7: 2025 Form 10-K segment table | G7: Reported
A8: Segment revenue total | B8: =SUM(B5:B7) -> 574785 | C8: =SUM(C5:C7) -> 637959 | D8: =SUM(D5:D7) -> 716924 | E8: USD m | F8: Sum of segments | G8: Formula
A9: North America operating income | B9: 14877 | C9: 24967 | D9: 29619 | E9: USD m | F9: 2025 Form 10-K segment table | G9: Reported
A10: International operating income | B10: -2656 | C10: 3792 | D10: 4750 | E10: USD m | F10: 2025 Form 10-K segment table | G10: Reported
A11: AWS operating income | B11: 24631 | C11: 39834 | D11: 45606 | E11: USD m | F11: 2025 Form 10-K segment table | G11: Reported
A12: Segment operating income total | B12: =SUM(B9:B11) -> 36852 | C12: =SUM(C9:C11) -> 68593 | D12: =SUM(D9:D11) -> 79975 | E12: USD m | F12: Sum of segments | G12: Formula

Sheet Change_Log
A1: Amazon.com, Inc. — Change Log
A2: Re-gating work performed without overwriting the prior workbook
A4: Timestamp (UTC) | B4: Scope | C4: Change | D4: Evidence | E4: Prior hash | F4: Preparer | G4: Disposition
A5: Build 2026-07-17T02:34:47.073Z | B5: Source lineage | C5: Added line-item target-cell provenance ledger | D5: Sources + SEC Company Facts / 10-K | E5: 753575f7be955a16d618d11d62214eaa1a63859ebcea30ec5c4534606d0dc5d6 | F5: Codex | G5: Ready for independent review
A6: Build 2026-07-17T02:34:47.073Z | B6: Operating model | C6: Added company-specific revenue and margin drivers | D6: Sector_KPIs, Assumptions, Forecast | E6: 753575f7be955a16d618d11d62214eaa1a63859ebcea30ec5c4534606d0dc5d6 | F6: Codex | G6: Ready for independent review
A7: Build 2026-07-17T02:34:47.073Z | B7: Valuation | C7: Rebuilt FCFF DCF, bridge and sensitivity | D7: Valuation + Sensitivity | E7: 753575f7be955a16d618d11d62214eaa1a63859ebcea30ec5c4534606d0dc5d6 | F7: Codex | G7: Ready for independent review
A8: Build 2026-07-17T02:34:47.073Z | B8: Governance | C8: Added formula-driven checks and Gate_9of10 | D8: Checks + Gate_9of10 | E8: 753575f7be955a16d618d11d62214eaa1a63859ebcea30ec5c4534606d0dc5d6 | F8: Codex | G8: Owner submission only
A9: 46224 | B9: Ola 2 elevation: added audited FY2021-FY2025 statement sheets IS_Hist/BS_Hist/CF_Hist/SCE_Hist (USD mm, filed/reported constants; FY2021 sub-line gaps flagged and residual-derived from exact totals, never invented), Checks_TieOut (20 tie-outs incl. cross-statement + cash continuity, all PASS), Sources_Audited (filing-level provenance + gap disclosure). Existing Historical/Assumptions/Forecast/Sensitivity/Valuation/Checks/Sources/Gate_9of10/00_Cover sheets preserved untouched (Forecast already driver-built FY2026E-30E with Base/Bull/Bear scenario switch on Assumptions!B3, ties to FY2025A base in IS_Hist). Built via Mog SDK only; root model untouched, v2 saved under the maintainer's archive. | C9: Claude (run 24e4a1f1)
A10: Audit 2026-08-14 | B10: Valuation / governance | C10: DCF -76% vs market diagnosed. NO assumptions, drivers or historicals changed. Arithmetic reperformed and confirmed exact (EV, bridge, per-share). Root cause is the operating assumption set, dominated by capex held at 13.0% of revenue in perpetuity vs D&A 5.8%; even zero terminal capex only reaches $203.81/sh vs $254.96 market, so no single input explains the gap. Added visible NO CLIENT-FACING warning at Valuation!A3 and a debt-bridge label note at Valuation!A23. Open item: Historical!A14 labels 68,836 as Total debt while Historical!A25 relabels it Long-term debt and adds 455 of short-term borrowings on top - resolve against the 10-K. | D10: Valuation!A3, Valuation!A23; Sensitivity!B5:F9 grid spans $46.62-$81.39 only | E10: 2d4cc8272747a77fef0fe40926eaa203277edf204672b8ec0d0262eb0e81eb76 | F10: Claude Opus 5 (auditoria Ola 2) | G10: BLOCKED FOR CLIENT USE - assumptions refresh required

Sheet Gate_9of10
A1: Amazon.com, Inc. — Gate 9/10 Owner Submission
A2: Independent review is a separate role; this sheet does not self-certify the workbook
A4: Gate | B4: Weight | C4: Owner status | D4: Blocker class | E4: Exact evidence range | F4: Native / visual evidence | G4: Independent action | H4: Notes
A5: H0 Controlled lineage / package | B5: 5 | C5: PASS | D5: None identified | E5: Change_Log!A4:G8; final .xlsx | F5: Prior hash preserved; OOXML integrity PASS 2026-07-17T02:36:50.237Z | G5: Reproduce lineage and package test | H5: Final JSON carries prior and final hashes
A6: H1 Source fidelity | B6: 20 | C6: PASS | D6: None identified | E6: Sources!A4:V500 | F6: SEC target-cell ledger + formula completeness | G6: Sample and reproduce ledger mappings | H6: Every populated hardcoded historical/driver cell mapped
A7: H2 Historical / formula / schedule mechanics | B7: 15 | C7: PASS | D7: None identified | E7: Historical!A4:F26; Forecast!A4:G30 | F7: Five-year historicals and formula-driven operating build | G7: Reperform historical and forecast ties | H7: Reported values preserved; forecast cells formula-driven
A8: H3 Scenario / sensitivity | B8: 10 | C8: PASS | D8: None identified | E8: Assumptions!A3:G30; Sensitivity!A4:G14 | F8: Base/Bull/Bear selector + dynamic DCF sensitivity | G8: Perturb selector 1/2/3 and reset to 1 | H8: Evidence JSON records exact outputs
A9: H4 Valuation fit / mechanics | B9: 15 | C9: PASS | D9: None identified | E9: Valuation!A4:G21; Historical!A17:F26 | F9: FCFF, bridge and per-share DCF | G9: Reperform DCF and balance-sheet bridge | H9: Debt/liquid asset/share policies explicit
A10: H5 Checks / error state | B10: 8 | C10: PASS | D10: None identified | E10: Checks!A4:G14 | F10: Formula-driven checks OK and zero formula-error matches 2026-07-17T02:35:35.817Z | G10: Reproduce checks and formula-error scan | H10: Final scan repeated after gate promotion
A11: H6 Native recalc / reproducibility | B11: 10 | C11: PASS | D11: None identified | E11: Checks!A4:G14 | F11: LibreOfficeDev 26.8.0.0.alpha0 2c87e51eeaa2b413ff4ae097b2705eea1995d8e5; save/reopen completed 2026-07-17T02:35:35.817Z | G11: Reopen and reproduce in native engine | H11: Final recalc repeated after gate promotion; evidence JSON carries hashes
A12: H7 Post-recalc all-sheet visual QA | B12: 7 | C12: PASS | D12: None identified | E12: internal QA evidence (not published) | F12: All 11 sheets rendered in preflight 2026-07-17T02:35:35.817Z; final render repeated after promotion | G12: Inspect preview manifest | H12: Final JSON carries per-sheet manifest
A13: H8 Material economic upgrade | B13: 5 | C13: PASS | D13: None identified | E13: Sector_KPIs!A4:G40; Assumptions!A6:G30; Forecast!A4:G30 | F13: Company-specific driver and margin build | G13: Challenge economic usefulness | H13: No relabel-only sector shell
A14: H9 Governance / limitations / handoff | B14: 5 | C14: PASS | D14: None identified | E14: Change_Log!A4:G8; Gate_9of10!A4:H26 | F14: Owner/reviewer separation and limitations explicit | G14: Assign independent reviewer | H14: No self-certification; evidence JSON is handoff surface
A16: Owner score | B16: =SUMIF(C5:C14,"PASS",B5:B14) -> 100
A17: Decision | B17: =IF(B16=100,"OWNER READY — INDEPENDENT REVIEW REQUIRED","PENDING OWNER QA") -> OWNER READY — INDEPENDENT REVIEW REQUIRED
A18: Overall model status | B18: =Checks!F15 -> OK
A20: Native recalculation / review metadata
A21: Build timestamp UTC | B21: Build 2026-07-17T02:34:47.073Z
A22: Required native engine | B22: LibreOfficeDev 26.8.0.0.alpha0 2c87e51eeaa2b413ff4ae097b2705eea1995d8e5
A23: Final native timestamp | B23: Native preflight 2026-07-17T02:35:35.817Z; final recalc after promotion 2026-07-17T02:36:52.069Z
A24: Visual manifest | B24: internal QA evidence (not published)
A25: Evidence manifest | B25: internal QA evidence (not published)
A26: Independent certification | B26: Not performed by owner-preparer

Sheet IS_Hist
A1: Amazon.com, Inc. — Consolidated Statements of Operations (audited/filed)
A2: USD millions except per-share/shares. Native reporting currency = USD (no FX layer needed). FY2023-25: FY2025 10-K (accn 0001018724-26-000004). FY2022-24 cross-checked vs FY2024 10-K Financial_Report.xlsx. FY2021: SEC companyfacts.json us-gaap tags (accn 0001018724-22-000005).
A4: Line item | B4: FY2021A | C4: FY2022A | D4: FY2023A | E4: FY2024A | F4: FY2025A | G4: Source / citation
A5: Total net sales | B5: 469822 | C5: 513983 | D5: 574785 | E5: 637959 | F5: 716924 | G5: us-gaap:RevenueFromContractWithCustomerExcludingAssessedTax
A6: Operating expenses
A7: Cost of sales | B7: 272344 | C7: 288831 | D7: 304739 | E7: 326288 | F7: 356414 | G7: us-gaap:CostOfGoodsAndServicesSold
A8: Fulfillment | C8: 84299 | D8: 90619 | E8: 98505 | F8: 109074 | G8: amzn:FulfillmentExpense (n/a FY21 — custom tag not in companyfacts pkg)
A9: Technology and infrastructure | C9: 73213 | D9: 85622 | E9: 88544 | F9: 108521 | G9: amzn:TechnologyAndInfrastructureExpense (n/a FY21)
A10: Sales and marketing | C10: 42238 | D10: 44370 | E10: 43907 | F10: 47129 | G10: amzn:custom (n/a FY21)
A11: General and administrative | C11: 11891 | D11: 11816 | E11: 11359 | F11: 11172 | G11: us-gaap:GeneralAndAdministrativeExpense (n/a FY21)
A12: Other operating expense (income), net | C12: 1263 | D12: 767 | E12: 763 | F12: 4639 | G12: amzn:custom (n/a FY21)
A13: GAP: Fulfillment+Tech&Infra+S&M+G&A+Other opex, combined (FY2021 only) | B13: 172599 | G13: derived = CostsAndExpenses - CostOfGoodsAndServicesSold; sub-line detail (custom amzn: tags) not present in companyfacts.json fetch for this run — see Sources_Audited
A14: Total operating expenses | B14: 444943 | C14: 501735 | D14: 537933 | E14: 569366 | F14: 636949 | G14: us-gaap:CostsAndExpenses
A15: Operating income | B15: 24879 | C15: 12248 | D15: 36852 | E15: 68593 | F15: 79975 | G15: us-gaap:OperatingIncomeLoss
A16: Interest income | B16: 448 | C16: 989 | D16: 2949 | E16: 4677 | F16: 4381 | G16: us-gaap:InvestmentIncomeInterest
A17: Interest expense | B17: -1809 | C17: -2367 | D17: -3182 | E17: -2406 | F17: -2274 | G17: us-gaap:InterestExpense (FY21-23) / R4 FY2025 10-K (FY24-25)
A18: Other income (expense), net | B18: 14633 | C18: -16806 | D18: 938 | E18: -2250 | F18: 15229 | G18: us-gaap:OtherNonoperatingIncomeExpense
A19: Total non-operating income (expense) | B19: 13272 | C19: -18184 | D19: 705 | E19: 21 | F19: 17336 | G19: us-gaap:NonoperatingIncomeExpense
A20: Income (loss) before income taxes | B20: 38151 | C20: -5936 | D20: 37557 | E20: 68614 | F20: 97311
A21: Provision (benefit) for income taxes | B21: -4791 | C21: 3217 | D21: -7120 | E21: -9265 | F21: -19087 | G21: us-gaap:IncomeTaxExpenseBenefit (sign flipped to filed presentation)
A22: Equity-method investment activity, net of tax | B22: 4 | C22: -3 | D22: -12 | E22: -101 | F22: -554 | G22: us-gaap:IncomeLossFromEquityMethodInvestments
A23: Net income (loss) | B23: 33364 | C23: -2722 | D23: 30425 | E23: 59248 | F23: 77670 | G23: us-gaap:NetIncomeLoss
A25: Basic earnings per share ($) | B25: 3.3 | C25: -0.27 | D25: 2.95 | E25: 5.66 | F25: 7.29 | G25: us-gaap:EarningsPerShareBasic
A26: Diluted earnings per share ($) | B26: 3.24 | C26: -0.27 | D26: 2.9 | E26: 5.53 | F26: 7.17 | G26: us-gaap:EarningsPerShareDiluted
A27: Weighted-average shares — basic (millions) | B27: 10117 | C27: 10189 | D27: 10304 | E27: 10473 | F27: 10656 | G27: us-gaap:WeightedAverageNumberOfSharesOutstandingBasic
A28: Weighted-average shares — diluted (millions) | B28: 10296 | C28: 10189 | D28: 10492 | E28: 10721 | F28: 10827 | G28: us-gaap:WeightedAverageNumberOfDilutedSharesOutstanding
A30: Memo: net sales disaggregation
A31: Net product sales | C31: 242901 | D31: 255887 | E31: 272311 | F31: 296266 | G31: R4/Financial_Report.xlsx (FY22-25); FY21 dimensional breakout not in companyfacts default facts — gap
A32: Net service sales | C32: 271082 | D32: 318898 | E32: 365648 | F32: 420658 | G32: R4/Financial_Report.xlsx (FY22-25); FY21 gap (see above)

Sheet BS_Hist
A1: Amazon.com, Inc. — Consolidated Balance Sheets (audited/filed)
A2: USD millions, as of December 31. FY2024-25 face BS (FY2025 10-K R7/R8). FY2021-23 built from independently-tagged companyfacts totals; algebraic identities verified against FY2024 10-K face BS where overlapping (FY23 exact match).
A4: Line item | B4: FY2021A | C4: FY2022A | D4: FY2023A | E4: FY2024A | F4: FY2025A | G4: Source / citation
A5: Current assets
A6: Cash and cash equivalents | B6: 36220 | C6: 53888 | D6: 73387 | E6: 78779 | F6: 86810 | G6: us-gaap:CashAndCashEquivalentsAtCarryingValue
A7: Marketable securities | B7: 59829 | C7: 16138 | D7: 13393 | E7: 22423 | F7: 36219 | G7: us-gaap:MarketableSecuritiesCurrent
A8: Inventories | B8: 32640 | C8: 34405 | D8: 33318 | E8: 34214 | F8: 38325 | G8: us-gaap:InventoryNet
A9: Accounts receivable, net and other | B9: 32891 | C9: 42360 | D9: 52253 | E9: 55451 | F9: 67729 | G9: us-gaap:AccountsReceivableNetCurrent
A10: Total current assets | B10: 161580 | C10: 146791 | D10: 172351 | E10: 190867 | F10: 229083 | G10: us-gaap:AssetsCurrent
A11: Non-current assets
A12: Property and equipment, net | B12: 160281 | C12: 186715 | D12: 204177 | E12: 252665 | F12: 357025 | G12: GAP: derived = Assets - AssetsCurrent - OperatingLeaseROU - Goodwill - OtherAssetsNoncurrent (FY21-23; direct us-gaap:PropertyPlantAndEquipmentNet FY24-25)
A13: Operating leases | B13: 56082 | C13: 66123 | D13: 72513 | E13: 76141 | F13: 86054 | G13: us-gaap:OperatingLeaseRightOfUseAsset
A14: Goodwill | B14: 15371 | C14: 20288 | D14: 22789 | E14: 23074 | F14: 23273 | G14: us-gaap:Goodwill
A15: Other assets | B15: 27235 | C15: 42758 | D15: 56024 | E15: 82147 | F15: 122607 | G15: us-gaap:OtherAssetsNoncurrent
A16: Total assets | B16: 420549 | C16: 462675 | D16: 527854 | E16: 624894 | F16: 818042 | G16: us-gaap:Assets
A18: Current liabilities
A19: Accounts payable | B19: 78664 | C19: 79600 | D19: 84981 | E19: 94363 | F19: 121909 | G19: us-gaap:AccountsPayableCurrent
A20: Accrued expenses and other | B20: 51775 | C20: 62566 | D20: 64709 | E20: 66965 | F20: 75520 | G20: us-gaap:AccruedLiabilitiesCurrent
A21: Unearned revenue | B21: 11827 | C21: 13227 | D21: 15227 | E21: 18103 | F21: 20576 | G21: us-gaap:ContractWithCustomerLiabilityCurrent
A22: Total current liabilities | B22: 142266 | C22: 155393 | D22: 164917 | E22: 179431 | F22: 218005 | G22: us-gaap:LiabilitiesCurrent
A23: Non-current liabilities
A24: Long-term lease liabilities | B24: 67651 | C24: 72968 | D24: 77297 | E24: 78277 | F24: 87339 | G24: us-gaap:OperatingLeaseLiabilityNoncurrent + us-gaap:FinanceLeaseLiabilityNoncurrent (sum matches filed line exactly for FY23-25)
A25: Long-term debt | B25: 48744 | C25: 67150 | D25: 58314 | E25: 52623 | F25: 65648 | G25: us-gaap:LongTermDebtNoncurrent
A26: Other long-term liabilities | B26: 23643 | C26: 21121 | D26: 25451 | E26: 28593 | F26: 35985 | G26: us-gaap:OtherLiabilitiesNoncurrent
A27: Total liabilities | B27: 282304 | C27: 316632 | D27: 325979 | E27: 338924 | F27: 406977 | G27: derived = Assets - StockholdersEquity (both exact tags); cross-checked = Total current + Total non-current liabilities
A29: Stockholders' equity
A30: Preferred stock | B30: 0 | C30: 0 | D30: 0 | E30: 0 | F30: 0 | G30: us-gaap:PreferredStockValue (par $0.01; 500mm auth.; none issued)
A31: Common stock | B31: 106 | C31: 108 | D31: 109 | E31: 111 | F31: 112 | G31: us-gaap:CommonStockValue
A32: Treasury stock, at cost | B32: -1837 | C32: -7837 | D32: -7837 | E32: -7837 | F32: -7837 | G32: us-gaap:TreasuryStockCommonValue (filed negative)
A33: Additional paid-in capital | B33: 55437 | C33: 75066 | D33: 99025 | E33: 120864 | F33: 140024 | G33: us-gaap:AdditionalPaidInCapital
A34: Accumulated other comprehensive income (loss) | B34: -1376 | C34: -4487 | D34: -3040 | E34: -34 | F34: 28230 | G34: us-gaap:AccumulatedOtherComprehensiveIncomeLossNetOfTax
A35: Retained earnings | B35: 85915 | C35: 83193 | D35: 113618 | E35: 172866 | F35: 250536 | G35: us-gaap:RetainedEarningsAccumulatedDeficit
A36: Total stockholders' equity | B36: 138245 | C36: 146043 | D36: 201875 | E36: 285970 | F36: 411065 | G36: us-gaap:StockholdersEquity
A37: Total liabilities and stockholders’ equity | B37: 420549 | C37: 462675 | D37: 527854 | E37: 624894 | F37: 818042 | G37: us-gaap:LiabilitiesAndStockholdersEquity

Sheet CF_Hist
A1: Amazon.com, Inc. — Consolidated Statements of Cash Flows (audited/filed)
A2: USD millions. Same source basis as IS_Hist. Signs as published (outflows negative). GAP rows are FY2021-only combined residuals computed from exact reported totals — flagged, never invented.
A4: Line item | B4: FY2021A | C4: FY2022A | D4: FY2023A | E4: FY2024A | F4: FY2025A | G4: Source / citation
A5: Beginning cash, cash equivalents, and restricted cash | B5: 42377 | C5: 36477 | D5: 54253 | E5: 73890 | F5: 82312 | G5: us-gaap:CashCashEquivalentsRestrictedCashAndRestrictedCashEquivalents (prior FY-end instant)
A6: Operating activities
A7: Net income (loss) | B7: 33364 | C7: -2722 | D7: 30425 | E7: 59248 | F7: 77670 | G7: us-gaap:NetIncomeLoss
A8: Depreciation and amortization | B8: 34433 | C8: 41921 | D8: 48663 | E8: 52795 | F8: 65756 | G8: us-gaap:DepreciationDepletionAndAmortization
A9: Stock-based compensation | B9: 12757 | C9: 19621 | D9: 24023 | E9: 22011 | F9: 19467 | G9: us-gaap:ShareBasedCompensation
A10: Non-operating expense (income), net (non-cash) | B10: -14306 | C10: 16966 | D10: -748 | E10: 2012 | F10: -14880 | G10: us-gaap:OtherNoncashIncomeExpense (filed sign; tag stored inverse of filed presentation — corrected here)
A11: Deferred income taxes | B11: -310 | C11: -8148 | D11: -5876 | E11: -4648 | F11: 11470 | G11: us-gaap:DeferredIncomeTaxExpenseBenefit
A12: Inventories | B12: -9487 | C12: -2592 | D12: 1449 | E12: -1884 | F12: -3002 | G12: us-gaap:IncreaseDecreaseInInventories (filed sign)
A13: Accounts receivable, net and other | C13: -8622 | D13: -8348 | E13: -3249 | F13: -7333 | G13: R3/Financial_Report.xlsx (n/a FY21 — see GAP row)
A14: Other assets | C14: -13275 | D14: -12265 | E14: -14483 | F14: -15632 | G14: R3/Financial_Report.xlsx (n/a FY21)
A15: Accounts payable | B15: 3602 | C15: 2945 | D15: 5473 | E15: 2972 | F15: 11231 | G15: us-gaap:IncreaseDecreaseInAccountsPayable
A16: Accrued expenses and other | C16: -1558 | D16: -2428 | E16: -2904 | F16: -5019 | G16: R3/Financial_Report.xlsx (n/a FY21)
A17: Unearned revenue | C17: 2216 | D17: 4578 | E17: 4007 | F17: -214 | G17: R3/Financial_Report.xlsx (n/a FY21)
A18: GAP: AR/other assets/accrued/unearned working-capital changes, combined (FY2021 only) | B18: -13726 | G18: derived residual = CFO - (all other tagged lines above); components not separately tagged in companyfacts for FY2021
A19: Net cash provided by (used in) operating activities | B19: 46327 | C19: 46752 | D19: 84946 | E19: 115877 | F19: 139514 | G19: us-gaap:NetCashProvidedByUsedInOperatingActivities
A20: Investing activities
A21: Purchases of property and equipment | B21: -61053 | C21: -63645 | D21: -52729 | E21: -82999 | F21: -131819 | G21: us-gaap:PaymentsToAcquireProductiveAssets (filed negative)
A22: Proceeds from property and equipment sales and incentives | C22: 5324 | D22: 4596 | E22: 5341 | F22: 3499 | G22: R3/Financial_Report.xlsx (n/a FY21)
A23: Acquisitions, net of cash acquired, non-marketable investments, and other | C23: -8316 | D23: -5839 | E23: -7082 | F23: -3841 | G23: R3/Financial_Report.xlsx (n/a FY21)
A24: GAP: PP&E-sale proceeds + acquisitions, net, combined (FY2021 only) | B24: 3672 | G24: derived residual = CFI - capex - (net marketable-securities activity); components not separately tagged for FY2021
A25: Sales and maturities of marketable securities | B25: 59384 | C25: 31601 | D25: 5627 | E25: 16403 | F25: 44386 | G25: us-gaap:ProceedsFromSaleAndMaturityOfMarketableSecurities
A26: Purchases of marketable securities | B26: -60157 | C26: -2565 | D26: -1488 | E26: -26005 | F26: -54770 | G26: us-gaap:PaymentsToAcquireMarketableSecurities (filed negative)
A27: Net cash provided by (used in) investing activities | B27: -58154 | C27: -37601 | D27: -49833 | E27: -94342 | F27: -142545 | G27: us-gaap:NetCashProvidedByUsedInInvestingActivities
A28: Financing activities
A29: Proceeds from short-term debt, and other | B29: 7956 | C29: 41553 | D29: 18129 | E29: 5142 | F29: 9320 | G29: us-gaap:ProceedsFromShortTermDebt
A30: Repayments of short-term debt, and other | B30: -7753 | C30: -37554 | D30: -25677 | E30: -5060 | F30: -8426 | G30: us-gaap:RepaymentsOfShortTermDebt (filed negative)
A31: Proceeds from long-term debt | B31: 19003 | C31: 21166 | D31: 0 | E31: 0 | F31: 15673 | G31: us-gaap:ProceedsFromIssuanceOfLongTermDebt
A32: Repayments of long-term debt | B32: -1590 | C32: -1258 | D32: -3676 | E32: -9182 | F32: -5021 | G32: us-gaap:RepaymentsOfLongTermDebt (filed negative)
A33: Principal repayments of finance leases | B33: -11163 | C33: -7941 | D33: -4384 | E33: -2043 | F33: -1557 | G33: us-gaap:FinanceLeasePrincipalPayments (filed negative)
A34: Common stock repurchased | C34: -6000 | D34: 0 | E34: 0 | F34: 0 | G34: R3/Financial_Report.xlsx (n/a FY21)
A35: Principal repayments of financing obligations | C35: -248 | D35: -271 | E35: -669 | F35: -328 | G35: R3/Financial_Report.xlsx (n/a FY21)
A36: GAP: financing obligations repayments + other, combined (FY2021 only) | B36: -162 | G36: derived residual = CFF - all other tagged financing lines; components not separately tagged for FY2021
A37: Net cash provided by (used in) financing activities | B37: 6291 | C37: 9718 | D37: -15879 | E37: -11812 | F37: 9661 | G37: us-gaap:NetCashProvidedByUsedInFinancingActivities
A38: Foreign currency effect on cash, cash equivalents, and restricted cash | B38: -364 | C38: -1093 | D38: 403 | E38: -1301 | F38: 1164 | G38: FY22-25 filed (R3/Financial_Report.xlsx); FY21 derived residual = NetChange - CFO - CFI - CFF
A39: Net increase (decrease) in cash, cash equivalents, and restricted cash | B39: -5900 | C39: 17776 | D39: 19637 | E39: 8422 | F39: 7794 | G39: us-gaap:CashCashEquivalentsRestrictedCashAndRestrictedCashEquivalentsPeriodIncreaseDecreaseIncludingExchangeRateEffect
A40: Ending cash, cash equivalents, and restricted cash | B40: 36477 | C40: 54253 | D40: 73890 | E40: 82312 | F40: 90106 | G40: us-gaap:CashCashEquivalentsRestrictedCashAndRestrictedCashEquivalents (FY-end instant)

Sheet SCE_Hist
A1: Amazon.com, Inc. — Consolidated Statements of Stockholders' Equity (audited/filed)
A2: USD millions. Full rollforward FY2023-25 from R9 (FY2025 10-K). FY2021-22 balance-only (rollforward detail not in source package).
A4: Line item | B4: FY2021A | C4: FY2022A | D4: FY2023A | E4: FY2024A | F4: FY2025A | G4: Source / citation
A5: Beginning total equity | C5: 138245 | D5: 146043 | E5: 201875 | F5: 285970 | G5: BS_Hist (FY21/22); R9 FY2025 10-K (FY23-25, exact Dec-31-2022 opening balance)
A6: Net income | B6: 33364 | C6: -2722 | D6: 30425 | E6: 59248 | F6: 77670 | G6: R9 (FY23-25); us-gaap:NetIncomeLoss (FY21/22, memo)
A7: Other comprehensive income (loss) | D7: 1447 | E7: 3006 | F7: 28264 | G7: R9 (FY23-25 only — GAP FY21/22, not in source pkg)
A8: Stock-based compensation and issuance of employee benefit plan stock | D8: 23960 | E8: 21841 | F8: 19161 | G8: R9 (FY23-25 only — GAP FY21/22)
A9: Ending total equity | B9: 138245 | C9: 146043 | D9: 201875 | E9: 285970 | F9: 411065 | G9: us-gaap:StockholdersEquity — ties to BS_Hist all 5 years (exact)

Sheet Checks_TieOut
A1: Tie-out checks — audited historical statements (all deltas must be 0; USD millions)
A2: MASTER | B2: =IF(COUNTIF(G5:G25,"FAIL")=0,"OK — ALL TIE-OUTS PASS","FAIL") -> OK — ALL TIE-OUTS PASS
A4: Check | B4: FY2021A | C4: FY2022A | D4: FY2023A | E4: FY2024A | F4: FY2025A | G4: Status
A5: IS: COGS + opex detail (or FY21 combined) = Total operating expenses | B5: =IS_Hist!B7+SUM(IS_Hist!B8:B13)-IS_Hist!B14 -> 0 | C5: =IS_Hist!C7+SUM(IS_Hist!C8:C13)-IS_Hist!C14 -> 0 | D5: =IS_Hist!D7+SUM(IS_Hist!D8:D13)-IS_Hist!D14 -> 0 | E5: =IS_Hist!E7+SUM(IS_Hist!E8:E13)-IS_Hist!E14 -> 0 | F5: =IS_Hist!F7+SUM(IS_Hist!F8:F13)-IS_Hist!F14 -> 0 | G5: =IF(AND(ABS(N(B5))<=0.5,ABS(N(C5))<=0.5,ABS(N(D5))<=0.5,ABS(N(E5))<=0.5,ABS(N(F5))<=0.5),"PASS","FAIL") -> PASS
A6: IS: Operating income = Revenue - Total opex | B6: =IS_Hist!B5-IS_Hist!B14-IS_Hist!B15 -> 0 | C6: =IS_Hist!C5-IS_Hist!C14-IS_Hist!C15 -> 0 | D6: =IS_Hist!D5-IS_Hist!D14-IS_Hist!D15 -> 0 | E6: =IS_Hist!E5-IS_Hist!E14-IS_Hist!E15 -> 0 | F6: =IS_Hist!F5-IS_Hist!F14-IS_Hist!F15 -> 0 | G6: =IF(AND(ABS(N(B6))<=0.5,ABS(N(C6))<=0.5,ABS(N(D6))<=0.5,ABS(N(E6))<=0.5,ABS(N(F6))<=0.5),"PASS","FAIL") -> PASS
A7: IS: Total non-op = Interest income + Interest expense + Other income(expense) | B7: =IS_Hist!B16+IS_Hist!B17+IS_Hist!B18-IS_Hist!B19 -> 0 | C7: =IS_Hist!C16+IS_Hist!C17+IS_Hist!C18-IS_Hist!C19 -> 0 | D7: =IS_Hist!D16+IS_Hist!D17+IS_Hist!D18-IS_Hist!D19 -> 0 | E7: =IS_Hist!E16+IS_Hist!E17+IS_Hist!E18-IS_Hist!E19 -> 0 | F7: =IS_Hist!F16+IS_Hist!F17+IS_Hist!F18-IS_Hist!F19 -> 0 | G7: =IF(AND(ABS(N(B7))<=0.5,ABS(N(C7))<=0.5,ABS(N(D7))<=0.5,ABS(N(E7))<=0.5,ABS(N(F7))<=0.5),"PASS","FAIL") -> PASS
A8: IS: PBT = Operating income + Total non-op | B8: =IS_Hist!B15+IS_Hist!B19-IS_Hist!B20 -> 0 | C8: =IS_Hist!C15+IS_Hist!C19-IS_Hist!C20 -> 0 | D8: =IS_Hist!D15+IS_Hist!D19-IS_Hist!D20 -> 0 | E8: =IS_Hist!E15+IS_Hist!E19-IS_Hist!E20 -> 0 | F8: =IS_Hist!F15+IS_Hist!F19-IS_Hist!F20 -> 0 | G8: =IF(AND(ABS(N(B8))<=0.5,ABS(N(C8))<=0.5,ABS(N(D8))<=0.5,ABS(N(E8))<=0.5,ABS(N(F8))<=0.5),"PASS","FAIL") -> PASS
A9: IS: NI = PBT + tax(filed sign) + equity-method | B9: =IS_Hist!B20+IS_Hist!B21+IS_Hist!B22-IS_Hist!B23 -> 0 | C9: =IS_Hist!C20+IS_Hist!C21+IS_Hist!C22-IS_Hist!C23 -> 0 | D9: =IS_Hist!D20+IS_Hist!D21+IS_Hist!D22-IS_Hist!D23 -> 0 | E9: =IS_Hist!E20+IS_Hist!E21+IS_Hist!E22-IS_Hist!E23 -> 0 | F9: =IS_Hist!F20+IS_Hist!F21+IS_Hist!F22-IS_Hist!F23 -> 0 | G9: =IF(AND(ABS(N(B9))<=0.5,ABS(N(C9))<=0.5,ABS(N(D9))<=0.5,ABS(N(E9))<=0.5,ABS(N(F9))<=0.5),"PASS","FAIL") -> PASS
A10: IS: Memo product+service sales = Total net sales (FY22-25 only) | B10: =IF(ISBLANK(IS_Hist!B31),0,IS_Hist!B31+IS_Hist!B32-IS_Hist!B5) -> 0 | C10: =IF(ISBLANK(IS_Hist!C31),0,IS_Hist!C31+IS_Hist!C32-IS_Hist!C5) -> 0 | D10: =IF(ISBLANK(IS_Hist!D31),0,IS_Hist!D31+IS_Hist!D32-IS_Hist!D5) -> 0 | E10: =IF(ISBLANK(IS_Hist!E31),0,IS_Hist!E31+IS_Hist!E32-IS_Hist!E5) -> 0 | F10: =IF(ISBLANK(IS_Hist!F31),0,IS_Hist!F31+IS_Hist!F32-IS_Hist!F5) -> 0 | G10: =IF(AND(ABS(N(B10))<=0.5,ABS(N(C10))<=0.5,ABS(N(D10))<=0.5,ABS(N(E10))<=0.5,ABS(N(F10))<=0.5),"PASS","FAIL") -> PASS
A11: BS: Current assets sum = Total current assets | B11: =SUM(BS_Hist!B6:B9)-BS_Hist!B10 -> 0 | C11: =SUM(BS_Hist!C6:C9)-BS_Hist!C10 -> 0 | D11: =SUM(BS_Hist!D6:D9)-BS_Hist!D10 -> 0 | E11: =SUM(BS_Hist!E6:E9)-BS_Hist!E10 -> 0 | F11: =SUM(BS_Hist!F6:F9)-BS_Hist!F10 -> 0 | G11: =IF(AND(ABS(N(B11))<=0.5,ABS(N(C11))<=0.5,ABS(N(D11))<=0.5,ABS(N(E11))<=0.5,ABS(N(F11))<=0.5),"PASS","FAIL") -> PASS
A12: BS: Total assets = Total CA + PP&E + Op leases + Goodwill + Other assets | B12: =BS_Hist!B10+BS_Hist!B12+BS_Hist!B13+BS_Hist!B14+BS_Hist!B15-BS_Hist!B16 -> 0 | C12: =BS_Hist!C10+BS_Hist!C12+BS_Hist!C13+BS_Hist!C14+BS_Hist!C15-BS_Hist!C16 -> 0 | D12: =BS_Hist!D10+BS_Hist!D12+BS_Hist!D13+BS_Hist!D14+BS_Hist!D15-BS_Hist!D16 -> 0 | E12: =BS_Hist!E10+BS_Hist!E12+BS_Hist!E13+BS_Hist!E14+BS_Hist!E15-BS_Hist!E16 -> 0 | F12: =BS_Hist!F10+BS_Hist!F12+BS_Hist!F13+BS_Hist!F14+BS_Hist!F15-BS_Hist!F16 -> 0 | G12: =IF(AND(ABS(N(B12))<=0.5,ABS(N(C12))<=0.5,ABS(N(D12))<=0.5,ABS(N(E12))<=0.5,ABS(N(F12))<=0.5),"PASS","FAIL") -> PASS
A13: BS: Current liabilities sum = Total current liabilities | B13: =SUM(BS_Hist!B19:B21)-BS_Hist!B22 -> 0 | C13: =SUM(BS_Hist!C19:C21)-BS_Hist!C22 -> 0 | D13: =SUM(BS_Hist!D19:D21)-BS_Hist!D22 -> 0 | E13: =SUM(BS_Hist!E19:E21)-BS_Hist!E22 -> 0 | F13: =SUM(BS_Hist!F19:F21)-BS_Hist!F22 -> 0 | G13: =IF(AND(ABS(N(B13))<=0.5,ABS(N(C13))<=0.5,ABS(N(D13))<=0.5,ABS(N(E13))<=0.5,ABS(N(F13))<=0.5),"PASS","FAIL") -> PASS
A14: BS: Total liabilities = Total CL + LT lease + LT debt + Other LT liabilities | B14: =BS_Hist!B22+BS_Hist!B24+BS_Hist!B25+BS_Hist!B26-BS_Hist!B27 -> 0 | C14: =BS_Hist!C22+BS_Hist!C24+BS_Hist!C25+BS_Hist!C26-BS_Hist!C27 -> 0 | D14: =BS_Hist!D22+BS_Hist!D24+BS_Hist!D25+BS_Hist!D26-BS_Hist!D27 -> 0 | E14: =BS_Hist!E22+BS_Hist!E24+BS_Hist!E25+BS_Hist!E26-BS_Hist!E27 -> 0 | F14: =BS_Hist!F22+BS_Hist!F24+BS_Hist!F25+BS_Hist!F26-BS_Hist!F27 -> 0 | G14: =IF(AND(ABS(N(B14))<=0.5,ABS(N(C14))<=0.5,ABS(N(D14))<=0.5,ABS(N(E14))<=0.5,ABS(N(F14))<=0.5),"PASS","FAIL") -> PASS
A15: BS: Equity components sum = Total stockholders' equity | B15: =SUM(BS_Hist!B30:B35)-BS_Hist!B36 -> 0 | C15: =SUM(BS_Hist!C30:C35)-BS_Hist!C36 -> 0 | D15: =SUM(BS_Hist!D30:D35)-BS_Hist!D36 -> 0 | E15: =SUM(BS_Hist!E30:E35)-BS_Hist!E36 -> 0 | F15: =SUM(BS_Hist!F30:F35)-BS_Hist!F36 -> 0 | G15: =IF(AND(ABS(N(B15))<=0.5,ABS(N(C15))<=0.5,ABS(N(D15))<=0.5,ABS(N(E15))<=0.5,ABS(N(F15))<=0.5),"PASS","FAIL") -> PASS
A16: BS: Total L&E = Total liabilities + Total equity | B16: =BS_Hist!B27+BS_Hist!B36-BS_Hist!B37 -> 0 | C16: =BS_Hist!C27+BS_Hist!C36-BS_Hist!C37 -> 0 | D16: =BS_Hist!D27+BS_Hist!D36-BS_Hist!D37 -> 0 | E16: =BS_Hist!E27+BS_Hist!E36-BS_Hist!E37 -> 0 | F16: =BS_Hist!F27+BS_Hist!F36-BS_Hist!F37 -> 0 | G16: =IF(AND(ABS(N(B16))<=0.5,ABS(N(C16))<=0.5,ABS(N(D16))<=0.5,ABS(N(E16))<=0.5,ABS(N(F16))<=0.5),"PASS","FAIL") -> PASS
A17: BS: Balance (Total assets - Total L&E) | B17: =BS_Hist!B16-BS_Hist!B37 -> 0 | C17: =BS_Hist!C16-BS_Hist!C37 -> 0 | D17: =BS_Hist!D16-BS_Hist!D37 -> 0 | E17: =BS_Hist!E16-BS_Hist!E37 -> 0 | F17: =BS_Hist!F16-BS_Hist!F37 -> 0 | G17: =IF(AND(ABS(N(B17))<=0.5,ABS(N(C17))<=0.5,ABS(N(D17))<=0.5,ABS(N(E17))<=0.5,ABS(N(F17))<=0.5),"PASS","FAIL") -> PASS
A18: CF: CFO chain (NI + non-cash adj + WC changes) | B18: =SUM(CF_Hist!B7:B18)-CF_Hist!B19 -> 0 | C18: =SUM(CF_Hist!C7:C18)-CF_Hist!C19 -> 0 | D18: =SUM(CF_Hist!D7:D18)-CF_Hist!D19 -> 0 | E18: =SUM(CF_Hist!E7:E18)-CF_Hist!E19 -> 0 | F18: =SUM(CF_Hist!F7:F18)-CF_Hist!F19 -> 0 | G18: =IF(AND(ABS(N(B18))<=0.5,ABS(N(C18))<=0.5,ABS(N(D18))<=0.5,ABS(N(E18))<=0.5,ABS(N(F18))<=0.5),"PASS","FAIL") -> PASS
A19: CF: CFI chain | B19: =SUM(CF_Hist!B21:B26)-CF_Hist!B27 -> 0 | C19: =SUM(CF_Hist!C21:C26)-CF_Hist!C27 -> 0 | D19: =SUM(CF_Hist!D21:D26)-CF_Hist!D27 -> 0 | E19: =SUM(CF_Hist!E21:E26)-CF_Hist!E27 -> 0 | F19: =SUM(CF_Hist!F21:F26)-CF_Hist!F27 -> 0 | G19: =IF(AND(ABS(N(B19))<=0.5,ABS(N(C19))<=0.5,ABS(N(D19))<=0.5,ABS(N(E19))<=0.5,ABS(N(F19))<=0.5),"PASS","FAIL") -> PASS
A20: CF: CFF chain | B20: =SUM(CF_Hist!B29:B36)-CF_Hist!B37 -> 0 | C20: =SUM(CF_Hist!C29:C36)-CF_Hist!C37 -> 0 | D20: =SUM(CF_Hist!D29:D36)-CF_Hist!D37 -> 0 | E20: =SUM(CF_Hist!E29:E36)-CF_Hist!E37 -> 0 | F20: =SUM(CF_Hist!F29:F36)-CF_Hist!F37 -> 0 | G20: =IF(AND(ABS(N(B20))<=0.5,ABS(N(C20))<=0.5,ABS(N(D20))<=0.5,ABS(N(E20))<=0.5,ABS(N(F20))<=0.5),"PASS","FAIL") -> PASS
A21: CF: Net change = CFO + CFI + CFF + FX effect | B21: =CF_Hist!B19+CF_Hist!B27+CF_Hist!B37+CF_Hist!B38-CF_Hist!B39 -> 0 | C21: =CF_Hist!C19+CF_Hist!C27+CF_Hist!C37+CF_Hist!C38-CF_Hist!C39 -> 0 | D21: =CF_Hist!D19+CF_Hist!D27+CF_Hist!D37+CF_Hist!D38-CF_Hist!D39 -> 0 | E21: =CF_Hist!E19+CF_Hist!E27+CF_Hist!E37+CF_Hist!E38-CF_Hist!E39 -> 0 | F21: =CF_Hist!F19+CF_Hist!F27+CF_Hist!F37+CF_Hist!F38-CF_Hist!F39 -> 0 | G21: =IF(AND(ABS(N(B21))<=0.5,ABS(N(C21))<=0.5,ABS(N(D21))<=0.5,ABS(N(E21))<=0.5,ABS(N(F21))<=0.5),"PASS","FAIL") -> PASS
A22: CF: Ending cash = Beginning cash + Net change | B22: =CF_Hist!B5+CF_Hist!B39-CF_Hist!B40 -> 0 | C22: =CF_Hist!C5+CF_Hist!C39-CF_Hist!C40 -> 0 | D22: =CF_Hist!D5+CF_Hist!D39-CF_Hist!D40 -> 0 | E22: =CF_Hist!E5+CF_Hist!E39-CF_Hist!E40 -> 0 | F22: =CF_Hist!F5+CF_Hist!F39-CF_Hist!F40 -> 0 | G22: =IF(AND(ABS(N(B22))<=0.5,ABS(N(C22))<=0.5,ABS(N(D22))<=0.5,ABS(N(E22))<=0.5,ABS(N(F22))<=0.5),"PASS","FAIL") -> PASS
A23: X: CF net income = IS net income | B23: =CF_Hist!B7-IS_Hist!B23 -> 0 | C23: =CF_Hist!C7-IS_Hist!C23 -> 0 | D23: =CF_Hist!D7-IS_Hist!D23 -> 0 | E23: =CF_Hist!E7-IS_Hist!E23 -> 0 | F23: =CF_Hist!F7-IS_Hist!F23 -> 0 | G23: =IF(AND(ABS(N(B23))<=0.5,ABS(N(C23))<=0.5,ABS(N(D23))<=0.5,ABS(N(E23))<=0.5,ABS(N(F23))<=0.5),"PASS","FAIL") -> PASS
A24: X: SCE ending equity = BS total equity | B24: =SCE_Hist!B9-BS_Hist!B36 -> 0 | C24: =SCE_Hist!C9-BS_Hist!C36 -> 0 | D24: =SCE_Hist!D9-BS_Hist!D36 -> 0 | E24: =SCE_Hist!E9-BS_Hist!E36 -> 0 | F24: =SCE_Hist!F9-BS_Hist!F36 -> 0 | G24: =IF(AND(ABS(N(B24))<=0.5,ABS(N(C24))<=0.5,ABS(N(D24))<=0.5,ABS(N(E24))<=0.5,ABS(N(F24))<=0.5),"PASS","FAIL") -> PASS
