Workbook

Sheet 00_Cover
A1: Space Exploration Technologies Corp. (SpaceX) | Financial model: statements as filed, segment forecast 2026E-2035E, valuation and credit
A2: Built 27 Oct 2026 from the 424B4 of 11 Jun 2026, the 10-Qs for Q2 and Q3 2026 and the 8-Ks of 20 and 26 Oct 2026. Nasdaq: SPCX. Includes xAI and X (from Feb 2026) and Cursor (from 14 Aug 2026).
A4: What this workbook holds
A5: Every line of the statements: fiscal 2023 to 2025 (audited) and the nine months to 30 September 2025 and 2026 (unaudited); seven quarters to Q3 2026.
A6: Segments (Space, Connectivity, SI), revenue by type, operating data (subscribers, ARPU, launches, GW of compute), customers, backlog, debt and commitments.
A7: Forecast by segment, Q4 2026E stub then 2027E-2035E, with Base, Bull and Bear (switch: Assumptions!C5); Apollo GPU lease from 2027; EchoStar spectrum at closing.
A8: Valuation: DCF (perpetuity and exit multiple), sum of the parts at trailing peer multiples, reverse DCF on revenue per GW, sensitivity, scenario summary; credit metrics.
A9: How to read it
A10: Units: USD millions, except per-share amounts (USD) and share counts (millions).
A11: Signs follow the filing. Interest expense is negative, as filed. A cell the filing shows as — is blank, with a note in column N.
A12: Blue numbers are typed from a filing or are inputs. Black numbers are formulas. Green numbers link to another sheet.
A13: Column M on the year sheets is for your comments. Column N shows the source or the derivation.
A14: The thin vertical line separates actual and forecast columns.
A16: Master check (all checks on the Checks sheet) | C16: =Checks!C4 -> OK
A18: Key outputs (active scenario unless stated) | C18: Value
A19: Active scenario | C19: =Assumptions!$C$6 -> Base
A20: SPCX price, 27 Oct 2026 (USD) | C20: =Market_Package!B10 -> 148.58
A21: DCF value per share, perpetuity (USD) | C21: =DCF!C37 -> 31.894477
A22: Against the price | C22: =DCF!C40 -> -0.78533802
A23: Base / Bull / Bear value per share (captured, USD): Base | C23: =Scenario_Summary!D23 -> 31.894477
A24: Bull | C24: =Scenario_Summary!E23 -> 67.790591
A25: Bear | C25: =Scenario_Summary!F23 -> 3.4085009
A26: DCF value per share with the Musk performance shares counted the other way (USD) | C26: =DCF!C38 -> 35.054485
A27: Sum of the parts at trailing peer multiples, average of the two bases (USD) | C27: =Valuation!C42 -> 29.7058
A28: Probability-weighted DCF value, Bear 25% / Base 50% / Bull 25% (USD) | C28: =Valuation!C49 -> 33.747011
A29: Shift on SI revenue per GW the price needs (Base) | C29: =Valuation!C35 -> 2.6335686
A30: Revenue 2026E (USD m) | C30: =Forecast_3Stmt!C10 -> 44225.754
A31: Revenue 2030E (USD m) | C31: =Forecast_3Stmt!G10 -> 178794.88
A32: WACC | C32: =Market_Package!B59 -> 0.10294983
A33: Diluted shares (millions) | C33: =Cap_Table!B56 -> 14444.097
A35: Sheet | B35: What it shows
A36: IS_Hist | B36: Statements of operations as filed, with tie-out checks
A37: CI_Hist | B37: Statements of comprehensive income (loss) as filed
A38: BS_Hist | B38: Balance sheets as filed (31 Dec 2024, 31 Dec 2025, 30 Sep 2026)
A39: CF_Hist | B39: Statements of cash flows as filed
A40: SCE_Hist | B40: Statements of preferred stock and shareholders' equity as filed
A41: Quarterly_Hist | B41: Seven quarters to Q3 2026 (Q4 2025 derived)
A42: Segments_Hist | B42: Segments, revenue by type, operating data, customers, backlog, derived Q3 2026 rates
A43: Cap_Table | B43: Shares outstanding, Musk performance-share tranches, options, RSUs, EchoStar shares; diluted count; market price
A44: Assumptions | B44: Every forecast input with its reason: Base, Bull, Bear and the switch (C5)
...

Sheet IS_Hist
A1: Space Exploration Technologies Corp. (SpaceX) | Consolidated statements of operations, as filed
A2: USD millions, except per-share amounts (USD) and shares (millions). FY2023-FY2025 audited (424B4 of 11 Jun 2026); nine months unaudited (10-Q Q3 2026).
A4: Fiscal year ends 31 December | B4: FY2023A | C4: FY2024A | D4: FY2025A | E4: 9M 2025A | F4: 9M 2026A | M4: Comentarios FG | N4: Source / derivation
A6: Revenue | B6: 10387 | C6: 14015 | D6: 18674 | E6: 13714 | F6: 27083 | N6: FY: 424B4 p. F-5; 9M: 10-Q Q3 2026 p. 4
A7: Costs and expenses
A8: Cost of revenue | B8: 6110 | C8: 7996 | D8: 9451 | E8: 6949 | F8: 11361 | N8: FY: 424B4 p. F-5; 9M: 10-Q Q3 2026 p. 4
A9: Research and development | B9: 2105 | C9: 3464 | D9: 8643 | E9: 5806 | F9: 11658 | N9: FY: 424B4 p. F-5; 9M: 10-Q Q3 2026 p. 4
A10: Selling, general, and administrative | B10: 1665 | C10: 1813 | D10: 2644 | E10: 1674 | F10: 3365 | N10: FY: 424B4 p. F-5; 9M: 10-Q Q3 2026 p. 4
A11: Restructuring charges (credits) | B11: 237 | C11: 213 | D11: 487 | E11: 472 | F11: -6 | N11: FY: 424B4 p. F-5; 9M: 10-Q Q3 2026 p. 4
A12: Impairment | B12: 3775 | C12: 63 | D12: 38 | E12: 29 | N12: FY: 424B4 p. F-5; 9M: 10-Q Q3 2026 p. 4. Filing shows — (nil) in 9M 2026A: left blank
A13: Total costs and expenses | B13: 13892 | C13: 13549 | D13: 21263 | E13: 14930 | F13: 26378 | N13: FY: 424B4 p. F-5; 9M: 10-Q Q3 2026 p. 4
A14: Income (loss) from operations | B14: -3505 | C14: 466 | D14: -2589 | E14: -1216 | F14: 705 | N14: FY: 424B4 p. F-5; 9M: 10-Q Q3 2026 p. 4
A15: Interest expense | B15: -1693 | C15: -1580 | D15: -1945 | E15: -1372 | F15: -1968 | N15: FY: 424B4 p. F-5; 9M: 10-Q Q3 2026 p. 4
A16: Interest income | B16: 249 | C16: 371 | D16: 492 | E16: 370 | F16: 1426 | N16: FY: 424B4 p. F-5; 9M: 10-Q Q3 2026 p. 4
A17: Other income (expense), net | B17: -42 | C17: 985 | D17: -177 | E17: 342 | F17: -937 | N17: FY: 424B4 p. F-5; 9M: 10-Q Q3 2026 p. 4
A18: Income (loss) before income taxes | B18: -4991 | C18: 242 | D18: -4219 | E18: -1876 | F18: -774 | N18: FY: 424B4 p. F-5; 9M: 10-Q Q3 2026 p. 4
A19: Provision for (benefit from) income taxes | B19: -363 | C19: -549 | D19: 718 | E19: 714 | F19: -361 | N19: FY: 424B4 p. F-5; 9M: 10-Q Q3 2026 p. 4
A20: Net income (loss) | B20: -4628 | C20: 791 | D20: -4937 | E20: -2590 | F20: -413 | N20: FY: 424B4 p. F-5; 9M: 10-Q Q3 2026 p. 4
A21: Net income (loss) attributable to shareholders, basic | B21: -4628 | C21: 18 | D21: -4937 | E21: -2590 | F21: -1084 | N21: FY: 424B4 p. F-5; 9M: 10-Q Q3 2026 p. 4
A22: Net income (loss) attributable to shareholders, diluted | B22: -4628 | C22: 21 | D22: -4937 | E22: =E21 -> -2590 | F22: =F21 -> -1084 | N22: FY: 424B4 p. F-5; 9M: 10-Q Q3 2026 p. 4. The 10-Q gives one line 'basic and diluted' for the nine months, so E and F link to the basic line
A24: Per share and share counts
A25: Net income (loss) per share, basic (USD) | B25: -1.68 | C25: 0.01 | D25: -1.69 | E25: -0.89 | F25: -0.15 | N25: FY: 424B4 p. F-5; 9M: 10-Q Q3 2026 p. 4
A26: Net income (loss) per share, diluted (USD) | B26: -1.68 | C26: 0 | D26: -1.69 | E26: -0.89 | F26: -0.15 | N26: FY: 424B4 p. F-5; 9M: 10-Q Q3 2026 p. 4
A27: Weighted average shares, basic (millions) | B27: 2759 | C27: 2848 | D27: 2926 | E27: 2915 | F27: 7274 | N27: FY: 424B4 p. F-5; 9M: 10-Q Q3 2026 p. 4
A28: Weighted average shares, diluted (millions) | B28: 2759 | C28: 9956 | D28: 2926 | E28: 2915 | F28: 7274 | N28: FY: 424B4 p. F-5; 9M: 10-Q Q3 2026 p. 4
A30: Checks: recomputed less filed (zero passes)
A31: Total costs and expenses | B31: =B8+B9+B10+B11+B12-B13 -> 0 | C31: =C8+C9+C10+C11+C12-C13 -> 0 | D31: =D8+D9+D10+D11+D12-D13 -> 0 | E31: =E8+E9+E10+E11+E12-E13 -> 0 | F31: =F8+F9+F10+F11+F12-F13 -> 0
A32: Income (loss) from operations | B32: =B6-B13-B14 -> 0 | C32: =C6-C13-C14 -> 0 | D32: =D6-D13-D14 -> 0 | E32: =E6-E13-E14 -> 0 | F32: =F6-F13-F14 -> 0
A33: Income (loss) before income taxes | B33: =B14+B15+B16+B17-B18 -> 0 | C33: =C14+C15+C16+C17-C18 -> 0 | D33: =D14+D15+D16+D17-D18 -> 0 | E33: =E14+E15+E16+E17-E18 -> 0 | F33: =F14+F15+F16+F17-F18 -> 0
A34: Net income (loss) | B34: =B18-B19-B20 -> 0 | C34: =C18-C19-C20 -> 0 | D34: =D18-D19-D20 -> 0 | E34: =E18-E19-E20 -> 0 | F34: =F18-F19-F20 -> 0
A35: Basic EPS (rounded to cents) | B35: =ROUND(B21/B27,2)-B25 -> 0 | C35: =ROUND(C21/C27,2)-C25 -> 0 | D35: =ROUND(D21/D27,2)-D25 -> 0 | E35: =ROUND(E21/E27,2)-E25 -> 0 | F35: =ROUND(F21/F27,2)-F25 -> 0
A36: Diluted EPS (rounded to cents) | B36: =ROUND(B22/B28,2)-B26 -> 0 | C36: =ROUND(C22/C28,2)-C26 -> 0 | D36: =ROUND(D22/D28,2)-D26 -> 0 | E36: =ROUND(E22/E28,2)-E26 -> 0 | F36: =ROUND(F22/F28,2)-F26 -> 0

Sheet CI_Hist
A1: Space Exploration Technologies Corp. (SpaceX) | Consolidated statements of comprehensive income (loss), as filed
A2: USD millions. FY: 424B4 p. F-6; 9M: 10-Q Q3 2026 p. 6.
A4: Fiscal year ends 31 December | B4: FY2023A | C4: FY2024A | D4: FY2025A | E4: 9M 2025A | F4: 9M 2026A | M4: Comentarios FG | N4: Source / derivation
A6: Net income (loss) | B6: -4628 | C6: 791 | D6: -4937 | E6: -2590 | F6: -413 | N6: FY: 424B4 p. F-6; 9M: 10-Q Q3 2026 p. 6
A7: Change in foreign currency translation adjustments, net of tax | B7: 222 | C7: -391 | D7: 805 | E7: 792 | F7: -207 | N7: FY: 424B4 p. F-6; 9M: 10-Q Q3 2026 p. 6
A8: Unrealized gains (losses) on marketable securities, net of tax | B8: 1 | C8: -1 | D8: 0 | F8: -27 | N8: FY: 424B4 p. F-6; 9M: 10-Q Q3 2026 p. 6. Filing shows — (nil) in 9M 2025A: left blank
A9: Other comprehensive income (loss) | B9: 223 | C9: -392 | D9: 805 | E9: 792 | F9: -234 | N9: FY: 424B4 p. F-6; 9M: 10-Q Q3 2026 p. 6
A10: Comprehensive income (loss) | B10: -4405 | C10: 399 | D10: -4132 | E10: -1798 | F10: -647 | N10: FY: 424B4 p. F-6; 9M: 10-Q Q3 2026 p. 6
A12: Checks: recomputed less filed (zero passes)
A13: Other comprehensive income (loss) | B13: =B7+B8-B9 -> 0 | C13: =C7+C8-C9 -> 0 | D13: =D7+D8-D9 -> 0 | E13: =E7+E8-E9 -> 0 | F13: =F7+F8-F9 -> 0
A14: Comprehensive income (loss) | B14: =B6+B9-B10 -> 0 | C14: =C6+C9-C10 -> 0 | D14: =D6+D9-D10 -> 0 | E14: =E6+E9-E10 -> 0 | F14: =F6+F9-F10 -> 0
A15: Net income equals the statement of operations | B15: =B6-IS_Hist!B20 -> 0 | C15: =C6-IS_Hist!C20 -> 0 | D15: =D6-IS_Hist!D20 -> 0 | E15: =E6-IS_Hist!E20 -> 0 | F15: =F6-IS_Hist!F20 -> 0

Sheet BS_Hist
A1: Space Exploration Technologies Corp. (SpaceX) | Consolidated balance sheets, as filed
A2: USD millions. 31 December audited (424B4); 30 September 2026 unaudited (10-Q Q3 2026).
A4: Fiscal year ends 31 December | B4: 31 Dec 2024A | C4: 31 Dec 2025A | D4: 30 Sep 2026A | M4: Comentarios FG | N4: Source / derivation
A6: Current assets
A7: Cash and cash equivalents | B7: 11385 | C7: 24747 | D7: 51294 | N7: 31 Dec: 424B4 p. F-4; 30 Sep 2026: 10-Q Q3 2026 p. 4
A8: Marketable securities | B8: 800 | D8: 38561 | N8: 31 Dec: 424B4 p. F-4; 30 Sep 2026: 10-Q Q3 2026 p. 4. Filing shows — (nil) in 31 Dec 2025A: left blank
A9: Accounts receivable, net | B9: 1052 | C9: 1579 | D9: 4772 | N9: 31 Dec: 424B4 p. F-4; 30 Sep 2026: 10-Q Q3 2026 p. 4
A10: Inventory | B10: 2003 | C10: 2416 | D10: 2891 | N10: 31 Dec: 424B4 p. F-4; 30 Sep 2026: 10-Q Q3 2026 p. 4
A11: Prepaid expenses and other current assets | B11: 868 | C11: 2210 | D11: 3457 | N11: 31 Dec: 424B4 p. F-4; 30 Sep 2026: 10-Q Q3 2026 p. 4
A12: Total current assets | B12: 16108 | C12: 30952 | D12: 100975 | N12: 31 Dec: 424B4 p. F-4; 30 Sep 2026: 10-Q Q3 2026 p. 4
A13: Noncurrent assets
A14: Property, plant, and equipment, net | B14: 21147 | C14: 42602 | D14: 89483 | N14: 31 Dec: 424B4 p. F-4; 30 Sep 2026: 10-Q Q3 2026 p. 4
A15: Finance lease right-of-use assets | B15: 1686 | C15: 1260 | D15: 1040 | N15: 31 Dec: 424B4 p. F-4; 30 Sep 2026: 10-Q Q3 2026 p. 4
A16: Intangible assets, net | B16: 2211 | C16: 1548 | D16: 6354 | N16: 31 Dec: 424B4 p. F-4; 30 Sep 2026: 10-Q Q3 2026 p. 4
A17: Digital assets | B17: 1749 | C17: 1637 | D17: 1573 | N17: 31 Dec: 424B4 p. F-4; 30 Sep 2026: 10-Q Q3 2026 p. 4
A18: Goodwill | B18: 11129 | C18: 11809 | D18: 48423 | N18: 31 Dec: 424B4 p. F-4; 30 Sep 2026: 10-Q Q3 2026 p. 4
A19: Deferred tax assets | B19: 696 | C19: 141 | D19: 388 | N19: 31 Dec: 424B4 p. F-4; 30 Sep 2026: 10-Q Q3 2026 p. 4
A20: Other assets | B20: 2336 | C20: 2130 | D20: 5809 | N20: 31 Dec: 424B4 p. F-4; 30 Sep 2026: 10-Q Q3 2026 p. 4
A21: Total assets | B21: 57062 | C21: 92079 | D21: 254045 | N21: 31 Dec: 424B4 p. F-4; 30 Sep 2026: 10-Q Q3 2026 p. 4
A22: Current liabilities
A23: Accounts payable | B23: 4413 | C23: 11792 | D23: 13259 | N23: 31 Dec: 424B4 p. F-4; 30 Sep 2026: 10-Q Q3 2026 p. 4
A24: Deferred revenue, current | B24: 5498 | C24: 6111 | D24: 10784 | N24: 31 Dec: 424B4 p. F-4; 30 Sep 2026: 10-Q Q3 2026 p. 4
A25: Debt and finance leases, current | B25: 372 | C25: 928 | D25: 2698 | N25: 31 Dec: 424B4 p. F-4; 30 Sep 2026: 10-Q Q3 2026 p. 4
A26: Accrued expenses and other current liabilities | B26: 1508 | C26: 2569 | D26: 5997 | N26: 31 Dec: 424B4 p. F-4; 30 Sep 2026: 10-Q Q3 2026 p. 4
A27: Total current liabilities | B27: 11791 | C27: 21400 | D27: 32738 | N27: 31 Dec: 424B4 p. F-4; 30 Sep 2026: 10-Q Q3 2026 p. 4
A28: Long-term liabilities
A29: Deferred revenue, net of current | B29: 4681 | C29: 6005 | D29: 6736 | N29: 31 Dec: 424B4 p. F-4; 30 Sep 2026: 10-Q Q3 2026 p. 4
A30: Debt and finance leases, net of current | B30: 13421 | C30: 21968 | D30: 36146 | N30: 31 Dec: 424B4 p. F-4; 30 Sep 2026: 10-Q Q3 2026 p. 4
A31: Other liabilities | B31: 1365 | C31: 1381 | D31: 1657 | N31: 31 Dec: 424B4 p. F-4; 30 Sep 2026: 10-Q Q3 2026 p. 4
A32: Total liabilities | B32: 31258 | C32: 50754 | D32: 77277 | N32: 31 Dec: 424B4 p. F-4; 30 Sep 2026: 10-Q Q3 2026 p. 4
A33: Redeemable convertible preferred stock
A34: Redeemable convertible preferred stock | B34: 20941 | C34: 38752 | N34: 31 Dec: 424B4 p. F-4; 30 Sep 2026: 10-Q Q3 2026 p. 4. Filing shows — (nil) in 30 Sep 2026A: left blank
A35: Shareholders' equity
A36: Class A common stock | B36: 2 | C36: 3 | D36: 8 | N36: 31 Dec: 424B4 p. F-4; 30 Sep 2026: 10-Q Q3 2026 p. 4
A37: Class B common stock | B37: 1 | C37: 1 | D37: 5 | N37: 31 Dec: 424B4 p. F-4; 30 Sep 2026: 10-Q Q3 2026 p. 4
A38: Class C common stock | B38: 0 | C38: 0 | N38: 31 Dec: 424B4 p. F-4; 30 Sep 2026: 10-Q Q3 2026 p. 4. Filing shows — (nil) in 30 Sep 2026A: left blank
A39: Additional paid-in capital | B39: 35865 | C39: 37706 | D39: 212539 | N39: 31 Dec: 424B4 p. F-4; 30 Sep 2026: 10-Q Q3 2026 p. 4
A40: Accumulated deficit | B40: -32098 | C40: -37035 | D40: -37448 | N40: 31 Dec: 424B4 p. F-4; 30 Sep 2026: 10-Q Q3 2026 p. 4
A41: Accumulated other comprehensive income | B41: 1093 | C41: 1898 | D41: 1664 | N41: 31 Dec: 424B4 p. F-4; 30 Sep 2026: 10-Q Q3 2026 p. 4
A42: Total shareholders' equity | B42: 4863 | C42: 2573 | D42: 176768 | N42: 31 Dec: 424B4 p. F-4; 30 Sep 2026: 10-Q Q3 2026 p. 4
...

Sheet CF_Hist
A1: Space Exploration Technologies Corp. (SpaceX) | Consolidated statements of cash flows, as filed
A2: USD millions. FY: 424B4 p. F-8 and F-9; 9M: 10-Q Q3 2026 p. 9. A blank with 'No such line' means the filing has no such row for that period.
A4: Fiscal year ends 31 December | B4: FY2023A | C4: FY2024A | D4: FY2025A | E4: 9M 2025A | F4: 9M 2026A | M4: Comentarios FG | N4: Source / derivation
A6: Cash flows from operating activities
A7: Net income (loss) | B7: -4628 | C7: 791 | D7: -4937 | E7: -2590 | F7: -413 | N7: FY: 424B4 p. F-8-F-9; 9M: 10-Q Q3 2026 p. 9
A8: Depreciation and amortization | B8: 2635 | C8: 3824 | D8: 6701 | E8: 4784 | F8: 8934 | N8: FY: 424B4 p. F-8-F-9; 9M: 10-Q Q3 2026 p. 9
A9: Share-based compensation | B9: 679 | C9: 784 | D9: 1947 | E9: 1044 | F9: 3833 | N9: FY: 424B4 p. F-8-F-9; 9M: 10-Q Q3 2026 p. 9
A10: Intangible asset impairment | B10: 3775 | N10: FY: 424B4 p. F-8-F-9; 9M: 10-Q Q3 2026 p. 9. Filing shows — (nil) in FY2024A, FY2025A: left blank. No such line in 9M 2025A, 9M 2026A
A11: Deferred income taxes | B11: -409 | C11: -675 | D11: 626 | E11: 623 | F11: -455 | N11: FY: 424B4 p. F-8-F-9; 9M: 10-Q Q3 2026 p. 9
A12: Unrealized (gain) loss on digital assets | C12: -955 | D12: 112 | E12: -389 | F12: 64 | N12: FY: 424B4 p. F-8-F-9; 9M: 10-Q Q3 2026 p. 9. Filing shows — (nil) in FY2023A: left blank
A13: Unrealized gain on investments in unconsolidated affiliates, net | F13: -532 | N13: FY: 424B4 p. F-8-F-9; 9M: 10-Q Q3 2026 p. 9. Filing shows — (nil) in 9M 2025A: left blank. No such line in FY2023A, FY2024A, FY2025A
A14: Impairment and loss on disposal of fixed assets, net | B14: 36 | C14: 135 | D14: 88 | N14: FY: 424B4 p. F-8-F-9; 9M: 10-Q Q3 2026 p. 9. No such line in 9M 2025A, 9M 2026A
A15: Amortization of debt discount and issuance costs | B15: 212 | C15: 84 | D15: 93 | N15: FY: 424B4 p. F-8-F-9; 9M: 10-Q Q3 2026 p. 9. No such line in 9M 2025A, 9M 2026A
A16: Loss on debt extinguishment | F16: 1545 | N16: FY: 424B4 p. F-8-F-9; 9M: 10-Q Q3 2026 p. 9. Filing shows — (nil) in 9M 2025A: left blank. No such line in FY2023A, FY2024A, FY2025A
A17: Other | B17: 214 | C17: 115 | D17: 66 | E17: 193 | F17: -254 | N17: FY: 424B4 p. F-8-F-9; 9M: 10-Q Q3 2026 p. 9
A19: Changes in operating assets and liabilities
A20: Accounts receivable | B20: 345 | C20: -347 | D20: -543 | E20: -934 | F20: -2882 | N20: FY: 424B4 p. F-8-F-9; 9M: 10-Q Q3 2026 p. 9
A21: Inventory | B21: -72 | C21: -309 | D21: -413 | E21: -378 | F21: -1381 | N21: FY: 424B4 p. F-8-F-9; 9M: 10-Q Q3 2026 p. 9
A22: Prepaid expenses and other assets | B22: 41 | C22: -328 | D22: -673 | E22: -427 | F22: -1305 | N22: FY: 424B4 p. F-8-F-9; 9M: 10-Q Q3 2026 p. 9
A23: Accounts payable | B23: 220 | C23: 472 | D23: 709 | E23: 668 | F23: -970 | N23: FY: 424B4 p. F-8-F-9; 9M: 10-Q Q3 2026 p. 9
A24: Deferred revenue | B24: 1695 | C24: 1876 | D24: 1929 | E24: 404 | F24: 4922 | N24: FY: 424B4 p. F-8-F-9; 9M: 10-Q Q3 2026 p. 9
A25: Operating lease liabilities, net | B25: -15 | C25: -37 | D25: -56 | N25: FY: 424B4 p. F-8-F-9; 9M: 10-Q Q3 2026 p. 9. No such line in 9M 2025A, 9M 2026A
A26: Other liabilities (9M: other liabilities, net) | B26: -208 | C26: 346 | D26: 1136 | E26: 1122 | F26: 1991 | N26: FY: 424B4 p. F-8-F-9; 9M: 10-Q Q3 2026 p. 9
A27: Net cash provided by operating activities | B27: 4520 | C27: 5776 | D27: 6785 | E27: 4120 | F27: 13097 | N27: FY: 424B4 p. F-8-F-9; 9M: 10-Q Q3 2026 p. 9
A29: Cash flows from investing activities
A30: Purchases of property, plant, and equipment | B30: -4415 | C30: -11163 | D30: -20737 | E30: -13846 | F30: -48069 | N30: FY: 424B4 p. F-8-F-9; 9M: 10-Q Q3 2026 p. 9
A31: Capitalized interest | D31: -169 | E31: -96 | F31: -20 | N31: FY: 424B4 p. F-8-F-9; 9M: 10-Q Q3 2026 p. 9. Filing shows — (nil) in FY2023A, FY2024A: left blank
A32: Proceeds from product rebates | D32: 118 | F32: 1372 | N32: FY: 424B4 p. F-8-F-9; 9M: 10-Q Q3 2026 p. 9. Filing shows — (nil) in FY2023A, FY2024A, 9M 2025A: left blank
A33: Purchases of marketable securities | B33: -3535 | C33: -3542 | D33: -611 | E33: -601 | F33: -46834 | N33: FY: 424B4 p. F-8-F-9; 9M: 10-Q Q3 2026 p. 9
A34: Maturities of marketable securities | B34: 2731 | C34: 3712 | D34: 548 | E34: 548 | F34: 9158 | N34: FY: 424B4 p. F-8-F-9; 9M: 10-Q Q3 2026 p. 9
A35: Proceeds from sales of marketable securities | B35: 333 | C35: 193 | D35: 1457 | E35: 1173 | F35: 77 | N35: FY: 424B4 p. F-8-F-9; 9M: 10-Q Q3 2026 p. 9
A36: Payments for intangible assets | F36: -866 | N36: FY: 424B4 p. F-8-F-9; 9M: 10-Q Q3 2026 p. 9. Filing shows — (nil) in 9M 2025A: left blank. No such line in FY2023A, FY2024A, FY2025A
A37: Cash received from acquisition of businesses | F37: 514 | N37: FY: 424B4 p. F-8-F-9; 9M: 10-Q Q3 2026 p. 9. Filing shows — (nil) in 9M 2025A: left blank. No such line in FY2023A, FY2024A, FY2025A
A38: Investments in unconsolidated affiliates | D38: -86 | N38: FY: 424B4 p. F-8-F-9; 9M: 10-Q Q3 2026 p. 9. Filing shows — (nil) in FY2023A, FY2024A: left blank. No such line in 9M 2025A, 9M 2026A
A39: Other investing activities, net | B39: 19 | C39: 4 | D39: -95 | E39: -175 | F39: 57 | N39: FY: 424B4 p. F-8-F-9; 9M: 10-Q Q3 2026 p. 9
A40: Net cash used in investing activities | B40: -4867 | C40: -10796 | D40: -19575 | E40: -12997 | F40: -84611 | N40: FY: 424B4 p. F-8-F-9; 9M: 10-Q Q3 2026 p. 9
A42: Cash flows from financing activities
A43: Principal repayments on finance leases | C43: -154 | D43: -295 | E43: -213 | F43: -270 | N43: FY: 424B4 p. F-8-F-9; 9M: 10-Q Q3 2026 p. 9. Filing shows — (nil) in FY2023A: left blank
A44: Proceeds from debt and other financing obligations | D44: 16055 | E44: 10947 | F44: 51834 | N44: FY: 424B4 p. F-8-F-9; 9M: 10-Q Q3 2026 p. 9. Filing shows — (nil) in FY2023A, FY2024A: left blank
A45: Payment of debt issuance costs | D45: -66 | E45: -66 | F45: -124 | N45: FY: 424B4 p. F-8-F-9; 9M: 10-Q Q3 2026 p. 9. Filing shows — (nil) in FY2023A, FY2024A: left blank
...

Sheet SCE_Hist
A1: Space Exploration Technologies Corp. (SpaceX) | Statements of redeemable convertible preferred stock and shareholders' equity, as filed
A2: USD millions; shares in millions. FY2023-FY2025: 424B4 p. F-7; nine months: 10-Q Q3 2026 p. 7 and 8. Cells the filing shows as — are blank.
A4: Line | B4: Preferred shares | C4: Preferred amount | D4: Common shares | E4: Common amount | F4: Additional paid-in capital | G4: Accumulated deficit | H4: AOCI | I4: Total shareholders' equity | J4: Comentarios FG | K4: Source / derivation
A6: Fiscal years 2023 to 2025 (audited)
A7: Balances at December 31, 2022 | B7: 136 | C7: 7239 | D7: 2742 | E7: 3 | F7: 35275 | G7: -28757 | H7: 1262 | I7: 7783 | K7: 424B4 p. F-7
A8: Share-based compensation | C8: 3 | F8: 784 | I8: 784 | K8: 424B4 p. F-7. Filing shows — (nil) in Preferred shares, Common shares, Common amount, Accumulated deficit, AOCI: left blank
A9: Issuance of redeemable convertible preferred stock | B9: 750 | C9: 750 | K9: 424B4 p. F-7. Filing shows — (nil) in Common shares, Common amount, Additional paid-in capital, Accumulated deficit, AOCI, Total shareholders' equity: left blank
A10: Common stock issued, net of tax withholding | D10: 249 | E10: 0 | F10: -41 | I10: -41 | K10: 424B4 p. F-7. Filing shows — (nil) in Preferred shares, Preferred amount, Accumulated deficit, AOCI: left blank
A11: Repurchase of common stock | D11: -11 | E11: 0 | F11: -170 | I11: -170 | K11: 424B4 p. F-7. Filing shows — (nil) in Preferred shares, Preferred amount, Accumulated deficit, AOCI: left blank
A12: Net loss | G12: -4628 | I12: -4628 | K12: 424B4 p. F-7. Filing shows — (nil) in Preferred shares, Preferred amount, Common shares, Common amount, Additional paid-in capital, AOCI: left blank
A13: Other comprehensive income (loss) | H13: 223 | I13: 223 | K13: 424B4 p. F-7. Filing shows — (nil) in Preferred shares, Preferred amount, Common shares, Common amount, Additional paid-in capital, Accumulated deficit: left blank
A14: Balances at December 31, 2023 | B14: 886 | C14: 7992 | D14: 2980 | E14: 3 | F14: 35848 | G14: -33385 | H14: 1485 | I14: 3951 | K14: 424B4 p. F-7
A15: Roll-forward to December 31, 2023: opening + movements - closing | B15: =B7+SUM(B8:B13)-B14 -> 0 | C15: =C7+SUM(C8:C13)-C14 -> 0 | D15: =D7+SUM(D8:D13)-D14 -> 0 | E15: =E7+SUM(E8:E13)-E14 -> 0 | F15: =F7+SUM(F8:F13)-F14 -> 0 | G15: =G7+SUM(G8:G13)-G14 -> 0 | H15: =H7+SUM(H8:H13)-H14 -> 0 | I15: =I7+SUM(I8:I13)-I14 -> 0
A16: Adjustment for prior periods from adoption of ASU 2023-08 | G16: 496 | I16: 496 | K16: 424B4 p. F-7. Filing shows — (nil) in Preferred shares, Preferred amount, Common shares, Common amount, Additional paid-in capital, AOCI: left blank
A17: Share-based compensation | F17: 914 | I17: 914 | K17: 424B4 p. F-7. Filing shows — (nil) in Preferred shares, Preferred amount, Common shares, Common amount, Accumulated deficit, AOCI: left blank
A18: Issuance of redeemable convertible preferred stock | B18: 862 | C18: 13001 | K18: 424B4 p. F-7. Filing shows — (nil) in Common shares, Common amount, Additional paid-in capital, Accumulated deficit, AOCI, Total shareholders' equity: left blank
A19: Common stock issued, net of tax withholding | D19: 75 | E19: 0 | F19: 72 | I19: 72 | K19: 424B4 p. F-7. Filing shows — (nil) in Preferred shares, Preferred amount, Accumulated deficit, AOCI: left blank
A20: Repurchase of common and redeemable convertible preferred stock | B20: 0 | C20: -21 | D20: -46 | E20: 0 | F20: -1000 | I20: -1000 | K20: 424B4 p. F-7. Filing shows — (nil) in Accumulated deficit, AOCI: left blank
A21: Conversion of redeemable convertible preferred stock to common stock | B21: 0 | C21: -31 | D21: 14 | E21: 0 | F21: 31 | I21: 31 | K21: 424B4 p. F-7. Filing shows — (nil) in Accumulated deficit, AOCI: left blank
A22: Net income | G22: 791 | I22: 791 | K22: 424B4 p. F-7. Filing shows — (nil) in Preferred shares, Preferred amount, Common shares, Common amount, Additional paid-in capital, AOCI: left blank
A23: Other comprehensive income (loss) | H23: -392 | I23: -392 | K23: 424B4 p. F-7. Filing shows — (nil) in Preferred shares, Preferred amount, Common shares, Common amount, Additional paid-in capital, Accumulated deficit: left blank
A24: Balances at December 31, 2024 | B24: 1748 | C24: 20941 | D24: 3023 | E24: 3 | F24: 35865 | G24: -32098 | H24: 1093 | I24: 4863 | K24: 424B4 p. F-7
A25: Roll-forward to December 31, 2024: opening + movements - closing | B25: =B14+SUM(B16:B23)-B24 -> 0 | C25: =C14+SUM(C16:C23)-C24 -> 0 | D25: =D14+SUM(D16:D23)-D24 -> 0 | E25: =E14+SUM(E16:E23)-E24 -> 0 | F25: =F14+SUM(F16:F23)-F24 -> 0 | G25: =G14+SUM(G16:G23)-G24 -> 0 | H25: =H14+SUM(H16:H23)-H24 -> 0 | I25: =I14+SUM(I16:I23)-I24 -> 0
A26: Share-based compensation | F26: 2087 | I26: 2087 | K26: 424B4 p. F-7. Filing shows — (nil) in Preferred shares, Preferred amount, Common shares, Common amount, Accumulated deficit, AOCI: left blank
A27: Issuance of redeemable convertible preferred stock | B27: 299 | C27: 17898 | K27: 424B4 p. F-7. Filing shows — (nil) in Common shares, Common amount, Additional paid-in capital, Accumulated deficit, AOCI, Total shareholders' equity: left blank
A28: Common stock issued, net of tax withholding | D28: 97 | E28: 1 | F28: 740 | I28: 741 | K28: 424B4 p. F-7. Filing shows — (nil) in Preferred shares, Preferred amount, Accumulated deficit, AOCI: left blank
A29: Repurchase of common stock | D29: -69 | E29: 0 | F29: -1125 | I29: -1125 | K29: 424B4 p. F-7. Filing shows — (nil) in Preferred shares, Preferred amount, Accumulated deficit, AOCI: left blank
A30: Conversion of redeemable convertible preferred stock to common stock | B30: -1 | C30: -87 | D30: 28 | E30: 0 | F30: 87 | I30: 87 | K30: 424B4 p. F-7. Filing shows — (nil) in Accumulated deficit, AOCI: left blank
A31: Transfer of equity in business combination | D31: 0 | E31: 0 | F31: 52 | I31: 52 | K31: 424B4 p. F-7. Filing shows — (nil) in Preferred shares, Preferred amount, Accumulated deficit, AOCI: left blank
A32: Net loss | G32: -4937 | I32: -4937 | K32: 424B4 p. F-7. Filing shows — (nil) in Preferred shares, Preferred amount, Common shares, Common amount, Additional paid-in capital, AOCI: left blank
A33: Other comprehensive income (loss) | H33: 805 | I33: 805 | K33: 424B4 p. F-7. Filing shows — (nil) in Preferred shares, Preferred amount, Common shares, Common amount, Additional paid-in capital, Accumulated deficit: left blank
A34: Balances at December 31, 2025 | B34: 2046 | C34: 38752 | D34: 3079 | E34: 4 | F34: 37706 | G34: -37035 | H34: 1898 | I34: 2573 | K34: 424B4 p. F-7
A35: Roll-forward to December 31, 2025: opening + movements - closing | B35: =B24+SUM(B26:B33)-B34 -> 0 | C35: =C24+SUM(C26:C33)-C34 -> 0 | D35: =D24+SUM(D26:D33)-D34 -> 0 | E35: =E24+SUM(E26:E33)-E34 -> 0 | F35: =F24+SUM(F26:F33)-F34 -> 0 | G35: =G24+SUM(G26:G33)-G34 -> 0 | H35: =H24+SUM(H26:H33)-H34 -> 0 | I35: =I24+SUM(I26:I33)-I34 -> 0
A37: Nine months ended 30 September 2025 (unaudited)
A38: Balances at December 31, 2024 | B38: 1748 | C38: 20941 | D38: 3023 | E38: 3 | F38: 35865 | G38: -32098 | H38: 1093 | I38: 4863 | K38: 10-Q Q3 2026 p. 8
A39: Share-based compensation | F39: 1150 | I39: 1150 | K39: 10-Q Q3 2026 p. 8. Filing shows — (nil) in Preferred shares, Preferred amount, Common shares, Common amount, Accumulated deficit, AOCI: left blank
A40: Issuance of redeemable convertible preferred stock | B40: 145 | C40: 4388 | K40: 10-Q Q3 2026 p. 8. Filing shows — (nil) in Common shares, Common amount, Additional paid-in capital, Accumulated deficit, AOCI, Total shareholders' equity: left blank
A41: Common stock issued, net of tax withholding | D41: 62 | E41: 1 | F41: 922 | I41: 923 | K41: 10-Q Q3 2026 p. 8. Filing shows — (nil) in Preferred shares, Preferred amount, Accumulated deficit, AOCI: left blank
A42: Conversion of redeemable convertible preferred stock to common stock | B42: 0 | C42: -1 | D42: 2 | E42: 0 | F42: 1 | I42: 1 | K42: 10-Q Q3 2026 p. 8. Filing shows — (nil) in Accumulated deficit, AOCI: left blank
A43: Repurchase of common stock | D43: -47 | E43: 0 | F43: -523 | I43: -523 | K43: 10-Q Q3 2026 p. 8. Filing shows — (nil) in Preferred shares, Preferred amount, Accumulated deficit, AOCI: left blank
...

Sheet Quarterly_Hist
A1: Space Exploration Technologies Corp. (SpaceX) | Quarterly statements of operations, Q1 2025 to Q3 2026
A2: USD millions, unaudited. Q1: 424B4 (Q1 2025 and Q1 2026 columns); Q2: 10-Q Q2 2026; Q3: 10-Q Q3 2026. Q4 2025A is derived: FY2025 less nine months 2025 (formula).
A4: Three months ended | B4: Q1 2025A | C4: Q2 2025A | D4: Q3 2025A | E4: Q4 2025A | F4: Q1 2026A | G4: Q2 2026A | H4: Q3 2026A | M4: Comentarios FG | N4: Source / derivation
A6: Revenue | B6: 4067 | C6: 4071 | D6: 5576 | E6: =IS_Hist!D6-IS_Hist!E6 -> 4960 | F6: 4694 | G6: 7814 | H6: 14575 | N6: Q1: 424B4 p. F-64; Q2: 10-Q Q2 2026 p. 4; Q3: 10-Q Q3 2026 p. 4; Q4 2025A: IS_Hist FY2025 less 9M 2025
A7: Cost of revenue | B7: 1962 | C7: 2282 | D7: 2705 | E7: =IS_Hist!D8-IS_Hist!E8 -> 2502 | F7: 2388 | G7: 3495 | H7: 5478 | N7: Q1: 424B4 p. F-64; Q2: 10-Q Q2 2026 p. 4; Q3: 10-Q Q3 2026 p. 4; Q4 2025A: IS_Hist FY2025 less 9M 2025
A8: Research and development | B8: 1557 | C8: 1958 | D8: 2291 | E8: =IS_Hist!D9-IS_Hist!E9 -> 2837 | F8: 3514 | G8: 3548 | H8: 4596 | N8: Q1: 424B4 p. F-64; Q2: 10-Q Q2 2026 p. 4; Q3: 10-Q Q3 2026 p. 4; Q4 2025A: IS_Hist FY2025 less 9M 2025
A9: Selling, general, and administrative | B9: 493 | C9: 606 | D9: 575 | E9: =IS_Hist!D10-IS_Hist!E10 -> 970 | F9: 746 | G9: 912 | H9: 1707 | N9: Q1: 424B4 p. F-64; Q2: 10-Q Q2 2026 p. 4; Q3: 10-Q Q3 2026 p. 4; Q4 2025A: IS_Hist FY2025 less 9M 2025
A10: Restructuring charges (credits) | B10: 4 | C10: 190 | D10: 278 | E10: =IS_Hist!D11-IS_Hist!E11 -> 15 | F10: -11 | G10: 2 | H10: 3 | N10: Q1: 424B4 p. F-64; Q2: 10-Q Q2 2026 p. 4; Q3: 10-Q Q3 2026 p. 4; Q4 2025A: IS_Hist FY2025 less 9M 2025
A11: Impairment | B11: 24 | C11: 5 | E11: =IS_Hist!D12-IS_Hist!E12 -> 9 | N11: Q1: 424B4 p. F-64; Q2: 10-Q Q2 2026 p. 4; Q3: 10-Q Q3 2026 p. 4; Q4 2025A: IS_Hist FY2025 less 9M 2025. Filing shows — (nil) in Q3 2025A, Q1 2026A, Q2 2026A, Q3 2026A: left blank
A12: Total costs and expenses | B12: 4040 | C12: 5041 | D12: 5849 | E12: =IS_Hist!D13-IS_Hist!E13 -> 6333 | F12: 6637 | G12: 7957 | H12: 11784 | N12: Q1: 424B4 p. F-64; Q2: 10-Q Q2 2026 p. 4; Q3: 10-Q Q3 2026 p. 4; Q4 2025A: IS_Hist FY2025 less 9M 2025
A13: Income (loss) from operations | B13: 27 | C13: -970 | D13: -273 | E13: =IS_Hist!D14-IS_Hist!E14 -> -1373 | F13: -1943 | G13: -143 | H13: 2791 | N13: Q1: 424B4 p. F-64; Q2: 10-Q Q2 2026 p. 4; Q3: 10-Q Q3 2026 p. 4; Q4 2025A: IS_Hist FY2025 less 9M 2025
A14: Interest expense | B14: -447 | C14: -411 | D14: -514 | E14: =IS_Hist!D15-IS_Hist!E15 -> -573 | F14: -664 | G14: -629 | H14: -675 | N14: Q1: 424B4 p. F-64; Q2: 10-Q Q2 2026 p. 4; Q3: 10-Q Q3 2026 p. 4; Q4 2025A: IS_Hist FY2025 less 9M 2025
A15: Interest income | B15: 117 | C15: 98 | D15: 155 | E15: =IS_Hist!D16-IS_Hist!E16 -> 122 | F15: 213 | G15: 340 | H15: 873 | N15: Q1: 424B4 p. F-64; Q2: 10-Q Q2 2026 p. 4; Q3: 10-Q Q3 2026 p. 4; Q4 2025A: IS_Hist FY2025 less 9M 2025
A16: Other income (expense), net | B16: -211 | C16: 413 | D16: 140 | E16: =IS_Hist!D17-IS_Hist!E17 -> -519 | F16: -1876 | G16: -86 | H16: 1025 | N16: Q1: 424B4 p. F-64; Q2: 10-Q Q2 2026 p. 4; Q3: 10-Q Q3 2026 p. 4; Q4 2025A: IS_Hist FY2025 less 9M 2025
A17: Income (loss) before income taxes | B17: -514 | C17: -870 | D17: -492 | E17: =IS_Hist!D18-IS_Hist!E18 -> -2343 | F17: -4270 | G17: -518 | H17: 4014 | N17: Q1: 424B4 p. F-64; Q2: 10-Q Q2 2026 p. 4; Q3: 10-Q Q3 2026 p. 4; Q4 2025A: IS_Hist FY2025 less 9M 2025
A18: Provision for (benefit from) income taxes | B18: 14 | C18: 138 | D18: 562 | E18: =IS_Hist!D19-IS_Hist!E19 -> 4 | F18: 6 | G18: 23 | H18: -390 | N18: Q1: 424B4 p. F-64; Q2: 10-Q Q2 2026 p. 4; Q3: 10-Q Q3 2026 p. 4; Q4 2025A: IS_Hist FY2025 less 9M 2025
A19: Net income (loss) | B19: -528 | C19: -1008 | D19: -1054 | E19: =IS_Hist!D20-IS_Hist!E20 -> -2347 | F19: -4276 | G19: -541 | H19: 4404 | N19: Q1: 424B4 p. F-64; Q2: 10-Q Q2 2026 p. 4; Q3: 10-Q Q3 2026 p. 4; Q4 2025A: IS_Hist FY2025 less 9M 2025
A20: Depreciation and amortization (memo) | B20: 1443 | C20: =SUM(Segments_Hist!C117:Segments_Hist!C119) -> 1526 | D20: =SUM(Segments_Hist!D117:Segments_Hist!D119) -> 1814 | E20: =CF_Hist!D8-CF_Hist!E8 -> 1917 | F20: 2442 | G20: =SUM(Segments_Hist!G117:Segments_Hist!G119) -> 2848 | H20: =SUM(Segments_Hist!H117:Segments_Hist!H119) -> 3644 | N20: Q1: 424B4 p. 119 (adjusted EBITDA reconciliation); Q2, Q3: sum of segment D&A (Segments_Hist); Q4 2025A: cash flow FY less 9M
A21: Segment adjusted EBITDA, total (memo) | B21: =SUM(Segments_Hist!B107:Segments_Hist!B109) -> 1730 | C21: =SUM(Segments_Hist!C107:Segments_Hist!C109) -> 1214 | D21: =SUM(Segments_Hist!D107:Segments_Hist!D109) -> 2169 | E21: =SUM(Segments_Hist!E107:Segments_Hist!E109) -> 1471 | F21: =SUM(Segments_Hist!F107:Segments_Hist!F109) -> 1127 | G21: =SUM(Segments_Hist!G107:Segments_Hist!G109) -> 3538 | H21: =SUM(Segments_Hist!H107:Segments_Hist!H109) -> 8809 | N21: Segments_Hist
A23: Ratios (derived)
A24: Revenue: growth on the prior quarter | C24: =C6/B6-1 -> 0.00098352594 | D24: =D6/C6-1 -> 0.36968804 | E24: =E6/D6-1 -> -0.11047346 | F24: =F6/E6-1 -> -0.053629032 | G24: =G6/F6-1 -> 0.66467831 | H24: =H6/G6-1 -> 0.86524187
A25: Operating margin | B25: =B13/B6 -> 0.0066388001 | C25: =C13/C6 -> -0.2382707 | D25: =D13/D6 -> -0.048959828 | E25: =E13/E6 -> -0.27681452 | F25: =F13/F6 -> -0.41393268 | G25: =G13/G6 -> -0.018300486 | H25: =H13/H6 -> 0.19149228
A26: Segment adjusted EBITDA margin | B26: =B21/B6 -> 0.42537497 | C26: =C21/C6 -> 0.29820683 | D26: =D21/D6 -> 0.38898852 | E26: =E21/E6 -> 0.29657258 | F26: =F21/F6 -> 0.24009374 | G26: =G21/G6 -> 0.45277707 | H26: =H21/H6 -> 0.60439108
A28: Checks (zero passes)
A29: Total costs and expenses | B29: =B7+B8+B9+B10+B11-B12 -> 0 | C29: =C7+C8+C9+C10+C11-C12 -> 0 | D29: =D7+D8+D9+D10+D11-D12 -> 0 | E29: =E7+E8+E9+E10+E11-E12 -> 0 | F29: =F7+F8+F9+F10+F11-F12 -> 0 | G29: =G7+G8+G9+G10+G11-G12 -> 0 | H29: =H7+H8+H9+H10+H11-H12 -> 0
A30: Operating result | B30: =B6-B12-B13 -> 0 | C30: =C6-C12-C13 -> 0 | D30: =D6-D12-D13 -> 0 | E30: =E6-E12-E13 -> 0 | F30: =F6-F12-F13 -> 0 | G30: =G6-G12-G13 -> 0 | H30: =H6-H12-H13 -> 0
A31: Net income (loss) | B31: =B13+B14+B15+B16-B18-B19 -> 0 | C31: =C13+C14+C15+C16-C18-C19 -> 0 | D31: =D13+D14+D15+D16-D18-D19 -> 0 | E31: =E13+E14+E15+E16-E18-E19 -> 0 | F31: =F13+F14+F15+F16-F18-F19 -> 0 | G31: =G13+G14+G15+G16-G18-G19 -> 0 | H31: =H13+H14+H15+H16-H18-H19 -> 0
A32: Quarters add up to nine months: revenue | B32: =SUM(B6:D6)-IS_Hist!E6 -> 0 | F32: =SUM(F6:H6)-IS_Hist!F6 -> 0 | N32: B: Q1-Q3 2025 against 9M 2025; F: Q1-Q3 2026 against 9M 2026. Q4 2025 is derived, so FY2025 adds up by construction.
A33: Quarters add up to nine months: total costs and expenses | B33: =SUM(B12:D12)-IS_Hist!E13 -> 0 | F33: =SUM(F12:H12)-IS_Hist!F13 -> 0 | N33: B: Q1-Q3 2025 against 9M 2025; F: Q1-Q3 2026 against 9M 2026. Q4 2025 is derived, so FY2025 adds up by construction.
A34: Quarters add up to nine months: income (loss) from operations | B34: =SUM(B13:D13)-IS_Hist!E14 -> 0 | F34: =SUM(F13:H13)-IS_Hist!F14 -> 0 | N34: B: Q1-Q3 2025 against 9M 2025; F: Q1-Q3 2026 against 9M 2026. Q4 2025 is derived, so FY2025 adds up by construction.
A35: Quarters add up to nine months: net income (loss) | B35: =SUM(B19:D19)-IS_Hist!E20 -> 0 | F35: =SUM(F19:H19)-IS_Hist!F20 -> 0 | N35: B: Q1-Q3 2025 against 9M 2025; F: Q1-Q3 2026 against 9M 2026. Q4 2025 is derived, so FY2025 adds up by construction.

Sheet Segments_Hist
A1: Space Exploration Technologies Corp. (SpaceX) | Segments, revenue by type, operating data and customers, as filed
A2: USD millions unless stated. The AI segment is called SI (Super Intelligence) from Q3 2026; same segment. Block A: years and nine months; block B: quarters.
A4: Fiscal year ends 31 December | B4: FY2023A | C4: FY2024A | D4: FY2025A | E4: 9M 2025A | F4: 9M 2026A | M4: Comentarios FG | N4: Source / derivation
A6: A1. Revenue by type and segment
A7: Launch Services | B7: 1964 | C7: 2584 | D7: 2576 | E7: 2056 | F7: 2108 | N7: FY: 424B4 p. F-22; 9M: 10-Q Q3 2026 p. 13
A8: Launch & Development | B8: 1593 | C8: 1212 | D8: 1510 | E8: 1221 | F8: 1240 | N8: FY: 424B4 p. F-22; 9M: 10-Q Q3 2026 p. 13
A9: Space | B9: 3557 | C9: 3796 | D9: 4086 | E9: 3277 | F9: 3348 | N9: FY: 424B4 p. F-22; 9M: 10-Q Q3 2026 p. 13
A10: Consumer | B10: 2817 | C10: 4830 | D10: 7208 | E10: 5198 | F10: 7754 | N10: FY: 424B4 p. F-22; 9M: 10-Q Q3 2026 p. 13
A11: Enterprise & Government | B11: 1052 | C11: 2769 | D11: 4179 | E11: 2961 | F11: 5042 | N11: FY: 424B4 p. F-22; 9M: 10-Q Q3 2026 p. 13
A12: Connectivity | B12: 3869 | C12: 7599 | D12: 11387 | E12: 8159 | F12: 12796 | N12: FY: 424B4 p. F-22; 9M: 10-Q Q3 2026 p. 13
A13: Advertising | B13: 2323 | C13: 1728 | D13: 1844 | E13: 1323 | F13: 1248 | N13: FY: 424B4 p. F-22; 9M: 10-Q Q3 2026 p. 13
A14: SI (AI) solutions & infrastructure | B14: 638 | C14: 892 | D14: 1357 | E14: 955 | F14: 9691 | N14: FY: 424B4 p. F-22; 9M: 10-Q Q3 2026 p. 13
A15: SI (AI) | B15: 2961 | C15: 2620 | D15: 3201 | E15: 2278 | F15: 10939 | N15: FY: 424B4 p. F-22; 9M: 10-Q Q3 2026 p. 13
A16: Total revenues | B16: 10387 | C16: 14015 | D16: 18674 | E16: 13714 | F16: 27083 | N16: FY: 424B4 p. F-22; 9M: 10-Q Q3 2026 p. 13
A18: A. Segment income (loss) from operations
A19: Space | B19: -1 | C19: 21 | D19: -657 | E19: -181 | F19: -1211 | N19: FY: 424B4 p. F-57-F-58 and 24; 9M: 10-Q Q3 2026 p. 33, 34
A20: Connectivity | B20: 469 | C20: 2006 | D20: 4423 | E20: 3147 | F20: 5211 | N20: FY: 424B4 p. F-57-F-58 and 24; 9M: 10-Q Q3 2026 p. 33, 34
A21: SI (formerly AI) | B21: -3973 | C21: -1561 | D21: -6355 | E21: -4182 | F21: -3295 | N21: FY: 424B4 p. F-57-F-58 and 24; 9M: 10-Q Q3 2026 p. 33, 34
A23: A. Depreciation and amortization
A24: Space | B24: 571 | C24: 637 | D24: 757 | E24: 572 | F24: 509 | N24: FY: 424B4 p. F-57-F-58 and 24; 9M: 10-Q Q3 2026 p. 33, 34
A25: Connectivity | B25: 884 | C25: 1508 | D25: 2376 | E25: 1706 | F25: 2574 | N25: FY: 424B4 p. F-57-F-58 and 24; 9M: 10-Q Q3 2026 p. 33, 34
A26: SI (formerly AI) | B26: 1180 | C26: 1679 | D26: 3568 | E26: 2506 | F26: 5851 | N26: FY: 424B4 p. F-57-F-58 and 24; 9M: 10-Q Q3 2026 p. 33, 34
A28: A. Share-based compensation (excluding acquisition awards)
A29: Space | B29: 427 | C29: 472 | D29: 515 | E29: 383 | F29: 503 | N29: FY: 424B4 p. F-57-F-58 and 24; 9M: 10-Q Q3 2026 p. 33, 34
A30: Connectivity | B30: 249 | C30: 296 | D30: 369 | E30: 270 | F30: 398 | N30: FY: 424B4 p. F-57-F-58 and 24; 9M: 10-Q Q3 2026 p. 33, 34
A31: SI (formerly AI) | B31: 3 | C31: 16 | D31: 1063 | E31: 391 | F31: 1715 | N31: FY: 424B4 p. F-57-F-58 and 24; 9M: 10-Q Q3 2026 p. 33, 34
A33: A. Share-based compensation related to acquisitions
A34: Space | N34: FY: 424B4 p. F-57-F-58 and 24; 9M: 10-Q Q3 2026 p. 33, 34. Filing shows — (nil) in 9M 2026A: left blank. No such line in FY2023A, FY2024A, FY2025A, 9M 2025A
A35: Connectivity | N35: FY: 424B4 p. F-57-F-58 and 24; 9M: 10-Q Q3 2026 p. 33, 34. Filing shows — (nil) in 9M 2026A: left blank. No such line in FY2023A, FY2024A, FY2025A, 9M 2025A
A36: SI (formerly AI) | F36: 1217 | N36: FY: 424B4 p. F-57-F-58 and 24; 9M: 10-Q Q3 2026 p. 33, 34. No such line in FY2023A, FY2024A, FY2025A, 9M 2025A
A38: A. Acquisition-related costs
A39: Space | N39: FY: 424B4 p. F-57-F-58 and 24; 9M: 10-Q Q3 2026 p. 33, 34. Filing shows — (nil) in 9M 2026A: left blank. No such line in FY2023A, FY2024A, FY2025A, 9M 2025A
A40: Connectivity | N40: FY: 424B4 p. F-57-F-58 and 24; 9M: 10-Q Q3 2026 p. 33, 34. Filing shows — (nil) in 9M 2026A: left blank. No such line in FY2023A, FY2024A, FY2025A, 9M 2025A
A41: SI (formerly AI) | F41: 8 | N41: FY: 424B4 p. F-57-F-58 and 24; 9M: 10-Q Q3 2026 p. 33, 34. No such line in FY2023A, FY2024A, FY2025A, 9M 2025A
A43: A. Restructuring charges (credits)
A44: Space | N44: FY: 424B4 p. F-57-F-58 and 24; 9M: 10-Q Q3 2026 p. 33, 34. Filing shows — (nil) in FY2023A, FY2024A, FY2025A, 9M 2025A, 9M 2026A: left blank
A45: Connectivity | N45: FY: 424B4 p. F-57-F-58 and 24; 9M: 10-Q Q3 2026 p. 33, 34. Filing shows — (nil) in FY2023A, FY2024A, FY2025A, 9M 2025A, 9M 2026A: left blank
A46: SI (formerly AI) | B46: 237 | C46: 213 | D46: 487 | E46: 472 | F46: -6 | N46: FY: 424B4 p. F-57-F-58 and 24; 9M: 10-Q Q3 2026 p. 33, 34
A48: A. Impairment
A49: Space | C49: 24 | D49: 38 | E49: 29 | N49: FY: 424B4 p. F-57-F-58 and 24; 9M: 10-Q Q3 2026 p. 33, 34. Filing shows — (nil) in FY2023A: left blank. No such line in 9M 2026A
...

Sheet Cap_Table
A1: Space Exploration Technologies Corp. (SpaceX) | Shares outstanding, dilutive securities and the diluted count at the market price
A2: Shares in millions. Treasury-stock method at the SPCX close of 27 Oct 2026. Sources: 10-Q Q3 2026 cover and Note 12-13; 424B4 (option prices, Musk awards, EchoStar shares).
A4: Item | B4: Value | C4: Price (USD) | D4: Comentarios FG | E4: Source / derivation
A6: A. Common stock outstanding, 15 Oct 2026 (10-Q cover)
A7: Class A common stock | B7: 8246.5412 | E7: 10-Q Q3 2026, cover page
A8: Class B common stock (10 votes per share) | B8: 5334.5225 | E8: 10-Q Q3 2026, cover page
A9: Shares outstanding | B9: =B7+B8 -> 13581.064
A10: Memo: Class A at 30 Sep 2026 (balance sheet caption) | B10: 8240 | E10: 10-Q Q3 2026 p. 4
A11: Memo: Class B at 30 Sep 2026 (balance sheet caption) | B11: 5339 | E11: 10-Q Q3 2026 p. 4
A13: B. Performance-based restricted Class B shares held by Mr. Musk (issued, outstanding and voted; not vested)
A14: SpaceX CEO Award, 13 Jan 2026: 15 tranches, market-cap milestones US$0.5tn to US$7.5tn, plus a permanent Mars colony of at least one million people | B14: 1000 | E14: 424B4 p. 235; tranche table 424B4 pp. 235-236; F-89
A15: AI CEO Award, 23 Mar 2026 (replaced the xAI award): 12 equal tranches, US$1.065tn to US$6.565tn, plus non-Earth data centers delivering 100 TW of compute a year | B15: 302.07229 | E15: 424B4 p. 236; F-89
A16: Performance-based restricted shares | B16: =B14+B15 -> 1302.0723 | E16: Inside the cover count (9M 2026 equity note: 1,306m Class B issued). Both awards require continued employment; Mr. Musk votes all of them. The 10-Q excludes 1,333m such awards from diluted EPS: 10-Q Q3 2026 p. 27
A17: Market capitalisation for the milestones: shares outstanding x price (USD bn) | B17: =B9*C61/1000 -> 2017.8744 | E17: Shares outstanding at 15 Oct 2026 x the 27 Oct 2026 close. The award's own definition (averaging period) is not reproduced; indicative.
A18: Tranche | B18: Shares (m) | C18: Milestone (USD bn) | D18: Market cap met (1 = yes) | E18: Second condition (both must be met to vest)
A19: SpaceX CEO Award, tranche 1 | B19: 66.666665 | C19: 500 | D19: =IF($B$17>=C19,1,0) -> 1 | E19: Mars colony of at least one million inhabitants: not met
A20: SpaceX CEO Award, tranche 2 | B20: 66.666665 | C20: 1000 | D20: =IF($B$17>=C20,1,0) -> 1 | E20: Mars colony of at least one million inhabitants: not met
A21: SpaceX CEO Award, tranche 3 | B21: 66.666665 | C21: 1500 | D21: =IF($B$17>=C21,1,0) -> 1 | E21: Mars colony of at least one million inhabitants: not met
A22: SpaceX CEO Award, tranche 4 | B22: 66.666665 | C22: 2000 | D22: =IF($B$17>=C22,1,0) -> 1 | E22: Mars colony of at least one million inhabitants: not met
A23: SpaceX CEO Award, tranche 5 | B23: 66.666665 | C23: 2500 | D23: =IF($B$17>=C23,1,0) -> 0 | E23: Mars colony of at least one million inhabitants: not met
A24: SpaceX CEO Award, tranche 6 | B24: 66.666665 | C24: 3000 | D24: =IF($B$17>=C24,1,0) -> 0 | E24: Mars colony of at least one million inhabitants: not met
A25: SpaceX CEO Award, tranche 7 | B25: 66.666665 | C25: 3500 | D25: =IF($B$17>=C25,1,0) -> 0 | E25: Mars colony of at least one million inhabitants: not met
A26: SpaceX CEO Award, tranche 8 | B26: 66.666665 | C26: 4000 | D26: =IF($B$17>=C26,1,0) -> 0 | E26: Mars colony of at least one million inhabitants: not met
A27: SpaceX CEO Award, tranche 9 | B27: 66.666665 | C27: 4500 | D27: =IF($B$17>=C27,1,0) -> 0 | E27: Mars colony of at least one million inhabitants: not met
A28: SpaceX CEO Award, tranche 10 | B28: 66.666665 | C28: 5000 | D28: =IF($B$17>=C28,1,0) -> 0 | E28: Mars colony of at least one million inhabitants: not met
A29: SpaceX CEO Award, tranche 11 | B29: 66.66667 | C29: 5500 | D29: =IF($B$17>=C29,1,0) -> 0 | E29: Mars colony of at least one million inhabitants: not met
A30: SpaceX CEO Award, tranche 12 | B30: 66.66667 | C30: 6000 | D30: =IF($B$17>=C30,1,0) -> 0 | E30: Mars colony of at least one million inhabitants: not met
... A33: SpaceX CEO Award, tranche 15 | B33: 66.66667 | C33: 7500 | D33: =IF($B$17>=C33,1,0) -> 0 | E33: Mars colony of at least one million inhabitants: not met
A34: AI CEO Award, tranche 1 | B34: =$B$15/12 -> 25.17269 | C34: 1065 | D34: =IF($B$17>=C34,1,0) -> 1 | E34: Non-Earth data centers delivering 100 TW of compute a year: not met
A35: AI CEO Award, tranche 2 | B35: =$B$15/12 -> 25.17269 | C35: 1565 | D35: =IF($B$17>=C35,1,0) -> 1 | E35: Non-Earth data centers delivering 100 TW of compute a year: not met
A36: AI CEO Award, tranche 3 | B36: =$B$15/12 -> 25.17269 | C36: 2065 | D36: =IF($B$17>=C36,1,0) -> 0 | E36: Non-Earth data centers delivering 100 TW of compute a year: not met
A37: AI CEO Award, tranche 4 | B37: =$B$15/12 -> 25.17269 | C37: 2565 | D37: =IF($B$17>=C37,1,0) -> 0 | E37: Non-Earth data centers delivering 100 TW of compute a year: not met
A38: AI CEO Award, tranche 5 | B38: =$B$15/12 -> 25.17269 | C38: 3065 | D38: =IF($B$17>=C38,1,0) -> 0 | E38: Non-Earth data centers delivering 100 TW of compute a year: not met
A39: AI CEO Award, tranche 6 | B39: =$B$15/12 -> 25.17269 | C39: 3565 | D39: =IF($B$17>=C39,1,0) -> 0 | E39: Non-Earth data centers delivering 100 TW of compute a year: not met
A40: AI CEO Award, tranche 7 | B40: =$B$15/12 -> 25.17269 | C40: 4065 | D40: =IF($B$17>=C40,1,0) -> 0 | E40: Non-Earth data centers delivering 100 TW of compute a year: not met
A41: AI CEO Award, tranche 8 | B41: =$B$15/12 -> 25.17269 | C41: 4565 | D41: =IF($B$17>=C41,1,0) -> 0 | E41: Non-Earth data centers delivering 100 TW of compute a year: not met
A42: AI CEO Award, tranche 9 | B42: =$B$15/12 -> 25.17269 | C42: 5065 | D42: =IF($B$17>=C42,1,0) -> 0 | E42: Non-Earth data centers delivering 100 TW of compute a year: not met
A43: AI CEO Award, tranche 10 | B43: =$B$15/12 -> 25.17269 | C43: 5565 | D43: =IF($B$17>=C43,1,0) -> 0 | E43: Non-Earth data centers delivering 100 TW of compute a year: not met
A44: AI CEO Award, tranche 11 | B44: =$B$15/12 -> 25.17269 | C44: 6065 | D44: =IF($B$17>=C44,1,0) -> 0 | E44: Non-Earth data centers delivering 100 TW of compute a year: not met
A45: AI CEO Award, tranche 12 | B45: =$B$15/12 -> 25.17269 | C45: 6565 | D45: =IF($B$17>=C45,1,0) -> 0 | E45: Non-Earth data centers delivering 100 TW of compute a year: not met
...

Sheet Assumptions
A1: Space Exploration Technologies Corp. (SpaceX) | Assumptions and scenarios
A2: Blue cells are inputs. Each driver has Base, Bull and Bear rows; the Active row follows the switch in C5. USD millions unless stated.
B3: Actual | C3: Forecast
A4: Fiscal year ends 31 December | B4: 2025A | C4: 2026E | D4: 2027E | E4: 2028E | F4: 2029E | G4: 2030E | H4: 2031E | I4: 2032E | J4: 2033E | K4: 2034E | L4: 2035E | M4: Comentarios FG | N4: Source / derivation
A5: Scenario switch: 1 = Base, 2 = Bull, 3 = Bear | C5: 1 | N5: Same convention as the house templates (Supuestos!C5).
A6: Active scenario | C6: =CHOOSE(C5,"Base","Bull","Bear") -> Base
A8: A. Q4 2026E stub and valuation inputs (one value per scenario)
C9: Active | D9: Base | E9: Bull | F9: Bear
A10: Q4 2026E: Starlink consumer subscribers at 31 Dec 2026 (millions) | C10: =CHOOSE($C$5,D10,E10,F10) -> 15.2 | D10: 15.2 | E10: 15.5 | F10: 14.8 | N10: 13.6m at 30 Sep 2026, +1.6m in Q3 and +1.7m in Q2 (10-Q). Base repeats the Q3 addition; Bull a little faster; Bear slower.
A11: Q4 2026E: Starlink consumer ARPU (USD per month) | C11: =CHOOSE($C$5,D11,E11,F11) -> 69 | D11: 69 | E11: 70 | F11: 67 | N11: US$69 in Q3 2026, US$66 in Q1 and Q2 (10-Q). Base holds Q3; Bear returns towards the 9M average of US$67.
A12: Q4 2026E: Enterprise & Government revenue growth on Q3 2026 | C12: =CHOOSE($C$5,D12,E12,F12) -> 0.08 | D12: 0.08 | E12: 0.12 | F12: 0.02 | N12: Q3 2026 +18% on Q2, +91% on Q3 2025 (10-Q). Base slows to +8% a quarter.
A13: Q4 2026E: customer launches (Falcon and Starship) | C13: =CHOOSE($C$5,D13,E13,F13) -> 13 | D13: 13 | E13: 15 | F13: 10 | N13: 12 in Q3 2026, 29 in 9M 2026; 43 in FY2025 (424B4, 10-Q). Base 13 brings 2026E to 42, close to 2025.
A14: Q4 2026E: Launch & Development revenue growth on Q3 2026 | C14: =CHOOSE($C$5,D14,E14,F14) -> 0 | D14: 0 | E14: 0.05 | F14: -0.1 | N14: Q3 2026 US$637m, Q2 US$314m: lumpy milestone revenue (10-Q). Base holds Q3.
A15: Q4 2026E: SI nameplate compute at 31 Dec 2026 (GW) | C15: =CHOOSE($C$5,D15,E15,F15) -> 2.1 | D15: 2.1 | E15: 2.3 | F15: 1.9 | N15: 1.0 GW at 31 Mar, 1.4 at 30 Jun, 1.7 at 30 Sep 2026 (424B4, 10-Q): +0.3 to +0.4 GW a quarter. Base +0.4 GW.
A16: Q4 2026E: change in SI compute revenue per average GW on Q3 2026 | C16: =CHOOSE($C$5,D16,E16,F16) -> 0 | D16: 0 | E16: 0.03 | F16: -0.08 | N16: Q3 2026 rate is a formula on Segments_Hist (SI solutions less Cursor, per average GW). Bear: new capacity comes on line before it earns.
A17: Q4 2026E: Cursor revenue growth on the Q3 daily run-rate | C17: =CHOOSE($C$5,D17,E17,F17) -> 0.1 | D17: 0.1 | E17: 0.2 | F17: 0 | N17: Q3 2026 Cursor revenue US$608m for the 47 days after the 14 Aug close (10-Q). Base +10% on that daily rate.
A18: Q4 2026E: advertising revenue growth on Q3 2026 | C18: =CHOOSE($C$5,D18,E18,F18) -> 0.08 | D18: 0.08 | E18: 0.15 | F18: -0.05 | N18: Q3 2026 US$538m, Q2 US$367m (10-Q); Q4 is the strongest ad quarter. Analyst input.
A19: Q4 2026E: Space segment adjusted EBITDA margin | C19: =CHOOSE($C$5,D19,E19,F19) -> 0.15 | D19: 0.15 | E19: 0.2 | F19: 0.05 | N19: Q3 2026 20.2%, 9M 2026 -5.9%, FY2025 16.0% (formulas on Segments_Hist). Base near FY2025.
A20: Q4 2026E: Connectivity segment adjusted EBITDA margin | C20: =CHOOSE($C$5,D20,E20,F20) -> 0.65 | D20: 0.65 | E20: 0.67 | F20: 0.62 | N20: Q3 2026 66.7%, 9M 2026 63.9% (Segments_Hist).
A21: Q4 2026E: SI segment adjusted EBITDA margin | C21: =CHOOSE($C$5,D21,E21,F21) -> 0.6 | D21: 0.6 | E21: 0.64 | F21: 0.5 | N21: Q3 2026 65.5%, the first quarter of large compute revenue; 9M 2026 50.2% (Segments_Hist).
... A29: Apollo GPU finance lease closes (1 = yes, 0 = no) | C29: =CHOOSE($C$5,D29,E29,F29) -> 1 | D29: 1 | E29: 1 | F29: 0 | N29: Binding commitment of 24 Oct 2026, subject to closing conditions, expected before year end (8-K 26 Oct 2026). Bear: it does not close and SI capex is paid in cash.
A31: B. Inputs that do not change with the scenario
A32: Apollo lease: aggregate principal (financed cost) | C32: 40000 | N32: 8-K 26 Oct 2026: 'aggregate principal payments ... approximately $40 billion'.
A33: Apollo lease: quarter of 2027 in which the schedules start (1 to 4) | C33: 2 | N33: 8-K: schedules 'commence during the first half of 2027'; Base takes Q2, one tranche for all. Convention.
A34: Apollo lease: fixed interest rate | C34: 0.065 | N34: Not disclosed: 'the fixed rate will be determined at pricing' (8-K 26 Oct 2026). Derivation: the June 2026 SpaceX Notes average 5.855% (10-Q Q3 Note 9); press reports put their coupons at about 5.35%-6.65%, and AI credit spreads have widened since June (FT and CNBC coverage, Oct 2026, as researched for this build, not re-read here). 6.5% sits at the top of the notes' range for a secured equipment lease. Convention. The FT described the package as about US$10bn of bank loans plus US$30bn of investment-grade debt; the model follows the 8-K's finance lease.
A35: EchoStar spectrum: year of the acquisition closing | C35: 2027 | N35: 424B4 p. 124: expected closing 30 Nov 2027; no later than 30 Nov 2028.
A36: EchoStar spectrum: cash at closing (payoff of EchoStar debt) | C36: 8500 | N36: 424B4 p. 123: 'up to $8.5 billion related to the payoff of designated EchoStar debt'.
A37: EchoStar spectrum: Class A shares issued at closing (millions) | C37: 261.8 | N37: 424B4 p. 123: 'approximately 261.8 million shares' at a fixed US$42.40.
A38: EchoStar spectrum: fixed value per share (USD) | C38: 42.4 | N38: 424B4 p. 123.
A39: EchoStar spectrum: Spectrum Credit Agreement payments in 2026 | C39: 1241 | N39: 424B4 p. 124.
A40: EchoStar spectrum: paid to the Trust by 30 Sep 2026 | C40: 856 | N40: 10-Q Q3 Note 6.
A41: EchoStar spectrum: payments in 2027 (closing 30 Nov 2027) | C41: 828 | N41: 424B4 p. 124.
A42: EchoStar spectrum: extra payments if closing slips to 30 Nov 2028 | C42: 827 | N42: 424B4 p. 124.
A43: Tax rate: US federal | C43: 0.21 | N43: US federal statutory rate 21% (10-Q Q3 Note 15).
... A66: Sensitivity: shift on revenue per GW, all years (0 = none) | C66: 0 | N66: Used by the captured tables and the reverse DCF; keep at 0.
A67: Tax rate, federal plus state (used for the terminal year and the WACC) | C67: =$C$43+$C$44 -> 0.23
A69: C. Drivers by year (Base, Bull, Bear and the active row)
A70: Connectivity: Starlink consumer subscribers at year end (millions) | N70: 8.9m end-2025, 13.6m at 30 Sep 2026 (+89% in a year; 10-Q). Base adds 6-7m a year to 2029 (direct-to-cell service on the EchoStar and 800 MHz spectrum helps), then slows. Bull keeps adding faster; Bear slows at once.
A71: Base | D71: 21 | E71: 28 | F71: 35 | G71: 41 | H71: 47 | I71: 52 | J71: 56 | K71: 60 | L71: 63
A72: Bull | D72: 23 | E72: 32 | F72: 42 | G72: 52 | H72: 62 | I72: 70 | J72: 77 | K72: 83 | L72: 88
...

Sheet Interim_Bridge
A1: Space Exploration Technologies Corp. (SpaceX) | 2026E bridge: nine months filed plus a Q4 2026E estimate by segment
A2: 9M columns link to the filings; Q4 2026E comes from the inputs on Assumptions (Section A). Balance sheet: column B = 30 Sep 2026A, column D = 31 Dec 2026E. USD millions.
A4: Line | B4: 9M 2026A | C4: Q4 2026E | D4: FY2026E | E4: 9M 2025A | F4: Q4 2025A | G4: FY2025A | H4: Comentarios FG | I4: Source / derivation
A6: Revenue by segment
A7: Space: customer launches | B7: =Segments_Hist!F68 -> 29 | C7: =Assumptions!$C$13 -> 13 | D7: =B7+C7 -> 42 | E7: =Segments_Hist!E68 -> 36 | F7: =G7-E7 -> 7 | G7: =Segments_Hist!D68 -> 43
A8: Space: Launch Services revenue per customer launch (USD m) | B8: =B9/B7 -> 72.689655 | C8: =B8 -> 72.689655 | D8: =D9/D7 -> 72.689655 | E8: =E9/E7 -> 57.111111 | F8: =F9/F7 -> 74.285714 | G8: =G9/G7 -> 59.906977 | I8: Q4 2026E holds the 9M 2026 rate (formula).
A9: Space: Launch Services | B9: =Segments_Hist!F7 -> 2108 | C9: =C7*C8 -> 944.96552 | D9: =B9+C9 -> 3052.9655 | E9: =Segments_Hist!E7 -> 2056 | F9: =G9-E9 -> 520 | G9: =Segments_Hist!D7 -> 2576
A10: Space: Launch & Development | B10: =Segments_Hist!F8 -> 1240 | C10: =Segments_Hist!H91*(1+Assumptions!$C$14) -> 637 | D10: =B10+C10 -> 1877 | E10: =Segments_Hist!E8 -> 1221 | F10: =G10-E10 -> 289 | G10: =Segments_Hist!D8 -> 1510 | I10: Q4 2026E = Q3 2026 x (1 + input).
A11: Space | B11: =B9+B10 -> 3348 | C11: =C9+C10 -> 1581.9655 | D11: =B11+C11 -> 4929.9655 | E11: =E9+E10 -> 3277 | F11: =G11-E11 -> 809 | G11: =G9+G10 -> 4086
A12: Connectivity: consumer subscribers, period end (millions) | B12: =Segments_Hist!H122 -> 13.6 | C12: =Assumptions!$C$10 -> 15.2 | D12: =C12 -> 15.2 | E12: =Segments_Hist!D122 -> 7.2 | F12: =G12 -> 8.9 | G12: =Segments_Hist!E122 -> 8.9 | I12: B: 30 Sep 2026; C and D: 31 Dec 2026E.
A13: Connectivity: consumer ARPU (USD per month) | B13: =Segments_Hist!F65 -> 67 | C13: =Assumptions!$C$11 -> 69 | E13: =Segments_Hist!E65 -> 84 | G13: =Segments_Hist!D65 -> 81
A14: Consumer subscription revenue, Q4 2026E (ARPU x average subscribers x 3) | C14: =C13*(B12+C12)/2*3 -> 2980.8
A15: Kits and other above subscription revenue (Q3 2026 rate) | C15: =Segments_Hist!H133 -> 0.17791365
A16: Connectivity: Consumer | B16: =Segments_Hist!F10 -> 7754 | C16: =C14*(1+C15) -> 3511.125 | D16: =B16+C16 -> 11265.125 | E16: =Segments_Hist!E10 -> 5198 | F16: =G16-E16 -> 2010 | G16: =Segments_Hist!D10 -> 7208
A17: Connectivity: Enterprise & Government | B17: =Segments_Hist!F11 -> 5042 | C17: =Segments_Hist!H94*(1+Assumptions!$C$12) -> 2297.16 | D17: =B17+C17 -> 7339.16 | E17: =Segments_Hist!E11 -> 2961 | F17: =G17-E17 -> 1218 | G17: =Segments_Hist!D11 -> 4179 | I17: Q4 2026E = Q3 2026 x (1 + input).
A18: Connectivity | B18: =B16+B17 -> 12796 | C18: =C16+C17 -> 5808.285 | D18: =B18+C18 -> 18604.285 | E18: =E16+E17 -> 8159 | F18: =G18-E18 -> 3228 | G18: =G16+G17 -> 11387
A19: SI: nameplate compute, period end (GW) | B19: =Segments_Hist!H124 -> 1.7 | C19: =Assumptions!$C$15 -> 2.1 | D19: =C19 -> 2.1 | E19: =Segments_Hist!E66 -> 0.6 | F19: =G19 -> 0.8 | G19: =Segments_Hist!D66 -> 0.8
A20: SI compute revenue per average GW, annualised (USD bn) | B20: =Segments_Hist!H135 -> 16.552258 | C20: =B20*(1+Assumptions!$C$16) -> 16.552258 | I20: B: Q3 2026 rate (Segments_Hist); C = B x (1 + input).
A21: SI: compute and AI services | B21: =Segments_Hist!F14-B22 -> 9083 | C21: =(B19+C19)/2*C20*1000/4 -> 7862.3226 | D21: =B21+C21 -> 16945.323 | E21: =Segments_Hist!E14 -> 955 | F21: =G21-E21 -> 402 | G21: =Segments_Hist!D14 -> 1357
A22: SI: Cursor | B22: =Segments_Hist!H129 -> 608 | C22: =B22/47*92*(1+Assumptions!$C$17) -> 1309.1404 | D22: =B22+C22 -> 1917.1404 | E22: 0 | F22: =G22-E22 -> 0 | G22: 0 | I22: Q4 2026E = Q3 Cursor revenue / 47 days (14 Aug to 30 Sep) x 92 days x (1 + input). No Cursor revenue before 14 Aug 2026.
A23: SI: Advertising (X) | B23: =Segments_Hist!F13 -> 1248 | C23: =Segments_Hist!H96*(1+Assumptions!$C$18) -> 581.04 | D23: =B23+C23 -> 1829.04 | E23: =Segments_Hist!E13 -> 1323 | F23: =G23-E23 -> 521 | G23: =Segments_Hist!D13 -> 1844
A24: SI | B24: =B21+B22+B23 -> 10939 | C24: =C21+C22+C23 -> 9752.503 | D24: =B24+C24 -> 20691.503 | E24: =E21+E22+E23 -> 2278 | F24: =G24-E24 -> 923 | G24: =G21+G22+G23 -> 3201
A25: Revenue | B25: =B11+B18+B24 -> 27083 | C25: =C11+C18+C24 -> 17142.754 | D25: =B25+C25 -> 44225.754 | E25: =E11+E18+E24 -> 13714 | F25: =G25-E25 -> 4960 | G25: =G11+G18+G24 -> 18674
A27: Income statement
A28: Segment adjusted EBITDA: Space | B28: =Segments_Hist!F54 -> -199 | C28: =C11*Assumptions!$C$19 -> 237.29483 | D28: =B28+C28 -> 38.294828 | E28: =Segments_Hist!E54 -> 803 | F28: =G28-E28 -> -150 | G28: =Segments_Hist!D54 -> 653
A29: Segment adjusted EBITDA: Connectivity | B29: =Segments_Hist!F55 -> 8183 | C29: =C18*Assumptions!$C$20 -> 3775.3852 | D29: =B29+C29 -> 11958.385 | E29: =Segments_Hist!E55 -> 5123 | F29: =G29-E29 -> 2045 | G29: =Segments_Hist!D55 -> 7168
A30: Segment adjusted EBITDA: SI | B30: =Segments_Hist!F56 -> 5490 | C30: =C24*Assumptions!$C$21 -> 5851.5018 | D30: =B30+C30 -> 11341.502 | E30: =Segments_Hist!E56 -> -813 | F30: =G30-E30 -> -424 | G30: =Segments_Hist!D56 -> -1237
A31: Segment adjusted EBITDA, total | B31: =B28+B29+B30 -> 13474 | C31: =C28+C29+C30 -> 9864.1819 | D31: =B31+C31 -> 23338.182 | E31: =E28+E29+E30 -> 5113 | F31: =G31-E31 -> 1471 | G31: =G28+G29+G30 -> 6584
A32: Depreciation and amortization | B32: =CF_Hist!F8 -> 8934 | C32: =C50+C51+C52 -> 3746.8125 | D32: =B32+C32 -> 12680.812 | E32: =CF_Hist!E8 -> 4784 | F32: =G32-E32 -> 1917 | G32: =CF_Hist!D8 -> 6701 | I32: Q4 2026E: existing PP&E, finance-lease assets and intangibles (memo below); Q4 capex starts depreciating on 1 Jan 2027.
