Workbook

Sheet 00_Cover
A1: Empresas Públicas de Medellín E.S.P. — Institutional Financial Model
A2: Energy generation, distribution, transmission and infrastructure | COP-native audited historicals FY2022A-FY2025A (statement-grade, 3 audited consolidated EEFF PDFs) | USD forecast/valuation layer is a placeholder pending re-basing | As of 2026-07-21
A4: Model field | B4: Value
A5: Ticker / identifier | B5: Private / public-sector issuer
A6: Model archetype | B6: Operating company / DCF
A7: Decision readiness | B7: Source-backed operating model; no public-equity price target
A8: Reporting currency | B8: COP
A9: Model currency | B9: USD millions
A10: Market-data date | B10: Not applicable
A11: Current market price | B11: Not available
A12: Primary source | B12: Audited consolidated EEFF (EPM Grupo, 2023/2024/2025 filings, see Sources_Audited); https://www.epm.com.co/inversionistas/noticias/resultados-financieros-2025-grupo-epm-solidez/
A13: Key limitation | B13: Historical base (BS_Hist/IS_Hist/CF_Hist/Segment_Hist, FY2022A-FY2025A) is COP-native, statement-grade, sourced and tied out from 3 audited consolidated EEFF PDFs (see Sources_Audited); Forecast/Assumptions/Valuation remain a USD-denominated placeholder layer, explicitly disclosed as PARTIAL and not yet re-based to the COP historicals.
A15: Institutional-grade means auditable sources, explicit assumptions, formula-driven forecasts, valuation, sensitivities, checks and governance. It does not mean that missing private-company disclosures have been invented.

Sheet Sources
A1: Sources and data lineage
A2: Every hardcode is mapped to a source, date, currency and transformation.
A4: Source ID | B4: Use | C4: URL / reference | D4: As of | E4: Source currency | F4: Transformation | G4: Limitation | H4: Status
A5: S1 | B5: Historical financials (COP-native, statement-grade) | C5: https://www.epm.com.co/inversionistas/noticias/resultados-financieros-2025-grupo-epm-solidez/ | D5: Audited consolidated EEFF FY2022A-FY2025A (3 PDFs: FY2023/FY2024/FY2025 filings; see Sources_Audited for per-year page/note citations) | E5: COP | F5: Historical statements (BS_Hist/IS_Hist/CF_Hist/Segment_Hist) carried natively in COP millions, as reported; USD_Presentation is a memo-only conversion at period-end TRM implied by the EPM international bond note (not a snapshot FX proxy). | G5: Historical figures cover FY2022A-FY2025A own-year (not later-report comparatives); Forecast/Assumptions/Valuation layer is still USD-denominated and not yet re-based to the COP historicals (documented as PARTIAL). | H5: Historical base source-backed and tied out (Checks_TieOut all PASS); forecast/valuation layer is a placeholder.
A6: S2 | B6: Market price | C6: Not applicable | D6: 2026-07-15 | E6: N/A | F6: Dated market input; not a historical financial source | G6: Market prices move after the as-of date | H6: Not loaded
A7: S3 | B7: FX snapshot | C7: Yahoo Finance COP/USD chart snapshot | D7: 2026-07-15 | E7: COP | F7: COP per USD, inverted | G7: Current FX used across historical years for comparability; not historical spot | H7: Loaded
A8: S4 | B8: Forecast assumptions | C8: Model Assumptions sheet | D8: 2026-07-15 | E8: USD | F8: User-editable scenario inputs | G8: Forecasts are estimates, not reported facts | H8: Model input

Sheet Historical
A1: Historical financials
A2: USD millions; blanks are intentional when the cited source did not support a defensible value.
A4: Metric | B4: 2021A | C4: 2022A | D4: 2023A | E4: 2024A | F4: 2025A | G4: Source tag / note | H4: Quality
A5: Revenue | F5: 12599.031 | G5: Issuer results / manual source mapping | H5: Source-backed / see note
A6: Gross profit | G6: Issuer results / manual source mapping | H6: Missing / not inferred
A7: Operating income / EBIT | F7: 3413.5306 | G7: Issuer results / manual source mapping | H7: Source-backed / see note
A8: Net income | F8: 1644.7011 | G8: Issuer results / manual source mapping | H8: Source-backed / see note
A9: Cash from operations | G9: Issuer results / manual source mapping | H9: Missing / not inferred
A10: Capital expenditure | G10: Issuer results / manual source mapping | H10: Missing / not inferred
A11: Assets | G11: Issuer results / manual source mapping | H11: Missing / not inferred
A12: Liabilities | G12: Issuer results / manual source mapping | H12: Missing / not inferred
A13: Equity | G13: Issuer results / manual source mapping | H13: Missing / not inferred
A14: Cash | G14: Issuer results / manual source mapping | H14: Missing / not inferred
A15: Debt | G15: Issuer results / manual source mapping | H15: Missing / not inferred
A16: Diluted shares (mm) | G16: Issuer results / manual source mapping | H16: Missing / not inferred

Sheet Assumptions
A1: Assumptions and scenarios
A2: Blue-font cells are user inputs. Scenario selector: 1 = Base, 2 = Bull, 3 = Bear.
A3: Scenario selector | B3: 1
A4: Metric | B4: Bear | C4: Base | D4: Bull | E4: Active | F4: Rationale / source
A5: Revenue growth | B5: 0.02 | C5: 0.05 | D5: 0.08 | E5: =CHOOSE($B$3,C5,D5,B5) -> 0.05 | F5: Historical trend / sector anchor
A6: EBIT margin | B6: 0.24093596 | C6: 0.27093596 | D6: 0.30093596 | E6: =CHOOSE($B$3,C6,D6,B6) -> 0.27093596 | F6: Latest EBITDA margin used as operating proxy
A7: Cash tax rate | B7: 0.25 | C7: 0.22 | D7: 0.19 | E7: =CHOOSE($B$3,C7,D7,B7) -> 0.22 | F7: Normalized cash-tax assumption
A8: D&A / revenue | B8: 0.03 | C8: 0.04 | D8: 0.05 | E8: =CHOOSE($B$3,C8,D8,B8) -> 0.04 | F8: Sector-neutral default when source facts are unavailable
A9: Capex / revenue | B9: 0.06 | C9: 0.045 | D9: 0.035 | E9: =CHOOSE($B$3,C9,D9,B9) -> 0.045 | F9: Capital intensity assumption
A10: NWC investment / incremental revenue | B10: 0.025 | C10: 0.015 | D10: 0.005 | E10: =CHOOSE($B$3,C10,D10,B10) -> 0.015 | F10: Working-capital intensity
A11: WACC | B11: 0.11 | C11: 0.09 | D11: 0.075 | E11: =CHOOSE($B$3,C11,D11,B11) -> 0.09 | F11: USD discount-rate assumption
A12: Terminal growth | B12: 0.015 | C12: 0.025 | D12: 0.035 | E12: =CHOOSE($B$3,C12,D12,B12) -> 0.025 | F12: Long-run nominal USD growth

Sheet Forecast
A1: Forecast model
A2: Formula-driven five-year projection in USD millions.
A4: Metric | B4: 2025A | C4: 2026E | D4: 2027E | E4: 2028E | F4: 2029E | G4: 2030E
A5: Revenue | B5: 12599.031 | C5: =B5*(1+Assumptions!$E$5) -> 13228.983 | D5: =C5*(1+Assumptions!$E$5) -> 13890.432 | E5: =D5*(1+Assumptions!$E$5) -> 14584.953 | F5: =E5*(1+Assumptions!$E$5) -> 15314.201 | G5: =F5*(1+Assumptions!$E$5) -> 16079.911
A6: Growth | C6: =IF(B5<>0,C5/B5-1,0) -> 0.05 | D6: =IF(C5<>0,D5/C5-1,0) -> 0.05 | E6: =IF(D5<>0,E5/D5-1,0) -> 0.05 | F6: =IF(E5<>0,F5/E5-1,0) -> 0.05 | G6: =IF(F5<>0,G5/F5-1,0) -> 0.05
A7: EBIT margin | B7: 0.27093596 | C7: =Assumptions!$E$6 -> 0.27093596 | D7: =Assumptions!$E$6 -> 0.27093596 | E7: =Assumptions!$E$6 -> 0.27093596 | F7: =Assumptions!$E$6 -> 0.27093596 | G7: =Assumptions!$E$6 -> 0.27093596
A8: EBIT | B8: 3413.5306 | C8: =C5*C7 -> 3584.2071 | D8: =D5*D7 -> 3763.4175 | E8: =E5*E7 -> 3951.5884 | F8: =F5*F7 -> 4149.1678 | G8: =G5*G7 -> 4356.6262
A9: Cash tax rate | C9: =Assumptions!$E$7 -> 0.22 | D9: =Assumptions!$E$7 -> 0.22 | E9: =Assumptions!$E$7 -> 0.22 | F9: =Assumptions!$E$7 -> 0.22 | G9: =Assumptions!$E$7 -> 0.22
A10: NOPAT | C10: =C8*(1-C9) -> 2795.6816 | D10: =D8*(1-D9) -> 2935.4657 | E10: =E8*(1-E9) -> 3082.2389 | F10: =F8*(1-F9) -> 3236.3509 | G10: =G8*(1-G9) -> 3398.1684
A11: D&A | C11: =C5*Assumptions!$E$8 -> 529.15931 | D11: =D5*Assumptions!$E$8 -> 555.61727 | E11: =E5*Assumptions!$E$8 -> 583.39814 | F11: =F5*Assumptions!$E$8 -> 612.56805 | G11: =G5*Assumptions!$E$8 -> 643.19645
A12: Capital expenditure | C12: =-C5*Assumptions!$E$9 -> -595.30422 | D12: =-D5*Assumptions!$E$9 -> -625.06943 | E12: =-E5*Assumptions!$E$9 -> -656.32291 | F12: =-F5*Assumptions!$E$9 -> -689.13905 | G12: =-G5*Assumptions!$E$9 -> -723.596
A13: Change in NWC | C13: =-(C5-B5)*Assumptions!$E$10 -> -9.4492734 | D13: =-(D5-C5)*Assumptions!$E$10 -> -9.9217371 | E13: =-(E5-D5)*Assumptions!$E$10 -> -10.417824 | F13: =-(F5-E5)*Assumptions!$E$10 -> -10.938715 | G13: =-(G5-F5)*Assumptions!$E$10 -> -11.485651
A14: FCFF | C14: =C10+C11+C12+C13 -> 2720.0874 | D14: =D10+D11+D12+D13 -> 2856.0918 | E14: =E10+E11+E12+E13 -> 2998.8963 | F14: =F10+F11+F12+F13 -> 3148.8412 | G14: =G10+G11+G12+G13 -> 3306.2832
A15: Cash | B15: 0 | C15: =$B$15 -> 0 | D15: =$B$15 -> 0 | E15: =$B$15 -> 0 | F15: =$B$15 -> 0 | G15: =$B$15 -> 0
A16: Debt | B16: 0 | C16: =$B$16 -> 0 | D16: =$B$16 -> 0 | E16: =$B$16 -> 0 | F16: =$B$16 -> 0 | G16: =$B$16 -> 0

Sheet Valuation
A1: Discounted cash flow valuation
A2: Valuation is formula-driven and scenario-sensitive; private-company outputs are enterprise-value ranges only.
A4: Metric | B4: Year 1 | C4: Year 2 | D4: Year 3 | E4: Year 4 | F4: Year 5 | G4: Total / output
A5: FCFF | B5: =Forecast!C14 -> 2720.0874 | C5: =Forecast!D14 -> 2856.0918 | D5: =Forecast!E14 -> 2998.8963 | E5: =Forecast!F14 -> 3148.8412 | F5: =Forecast!G14 -> 3306.2832
A6: Discount factor | B6: =1/(1+Assumptions!$E$11)^1 -> 0.91743119 | C6: =1/(1+Assumptions!$E$11)^2 -> 0.84167999 | D6: =1/(1+Assumptions!$E$11)^3 -> 0.77218348 | E6: =1/(1+Assumptions!$E$11)^4 -> 0.70842521 | F6: =1/(1+Assumptions!$E$11)^5 -> 0.64993139
A7: PV FCFF | B7: =B5*B6 -> 2495.493 | C7: =C5*C6 -> 2403.9153 | D7: =D5*D6 -> 2315.6982 | E7: =E5*E6 -> 2230.7185 | F7: =F5*F6 -> 2148.8572
A9: Output | B9: Value
A10: PV explicit FCFF | B10: =SUM(B7:F7) -> 11594.682
A11: Terminal value | B11: =IF(Assumptions!$E$11>Assumptions!$E$12,F5*(1+Assumptions!$E$12)/(Assumptions!$E$11-Assumptions!$E$12),0) -> 52137.543
A12: PV terminal value | B12: =B11*F6 -> 33885.826
A13: Enterprise value | B13: =B10+B12 -> 45480.508
A14: Cash | B14: =Forecast!B15 -> 0
A15: Debt | B15: =Forecast!B16 -> 0
A16: Equity value | B16: =B13+B14-B15 -> 45480.508
A17: Diluted shares (mm) | B17: 0
A18: Implied value / share | B18: =IF(B17>0,B16/B17,0) -> 0
A19: Current market price
A20: Upside / (downside) | B20: =IF(B19>0,B18/B19-1,0) -> 0

Sheet Sensitivity
A1: Valuation sensitivity
A2: Enterprise value sensitivity to WACC and terminal growth.
A4: WACC / g | B4: 0.07 | C4: 0.08 | D4: 0.09 | E4: 0.1 | F4: 0.11
A5: 0.01 | B5: =SUMPRODUCT(Valuation!$B$5:$F$5,1/(1+B$4)^{1,2,3,4,5})+IF(B$4>$A5,Valuation!$F$5*(1+$A5)/(B$4-$A5)/(1+B$4)^5,0) -> 51926.115 | C5: =SUMPRODUCT(Valuation!$B$5:$F$5,1/(1+C$4)^{1,2,3,4,5})+IF(C$4>$A5,Valuation!$F$5*(1+$A5)/(C$4-$A5)/(1+C$4)^5,0) -> 44379.734 | D5: =SUMPRODUCT(Valuation!$B$5:$F$5,1/(1+D$4)^{1,2,3,4,5})+IF(D$4>$A5,Valuation!$F$5*(1+$A5)/(D$4-$A5)/(1+D$4)^5,0) -> 38724.005 | E5: =SUMPRODUCT(Valuation!$B$5:$F$5,1/(1+E$4)^{1,2,3,4,5})+IF(E$4>$A5,Valuation!$F$5*(1+$A5)/(E$4-$A5)/(1+E$4)^5,0) -> 34328.539 | F5: =SUMPRODUCT(Valuation!$B$5:$F$5,1/(1+F$4)^{1,2,3,4,5})+IF(F$4>$A5,Valuation!$F$5*(1+$A5)/(F$4-$A5)/(1+F$4)^5,0) -> 30815.115
A6: 0.02 | B6: =SUMPRODUCT(Valuation!$B$5:$F$5,1/(1+B$4)^{1,2,3,4,5})+IF(B$4>$A6,Valuation!$F$5*(1+$A6)/(B$4-$A6)/(1+B$4)^5,0) -> 60333.94 | C6: =SUMPRODUCT(Valuation!$B$5:$F$5,1/(1+C$4)^{1,2,3,4,5})+IF(C$4>$A6,Valuation!$F$5*(1+$A6)/(C$4-$A6)/(1+C$4)^5,0) -> 50165.965 | D6: =SUMPRODUCT(Valuation!$B$5:$F$5,1/(1+D$4)^{1,2,3,4,5})+IF(D$4>$A6,Valuation!$F$5*(1+$A6)/(D$4-$A6)/(1+D$4)^5,0) -> 42906.602 | E6: =SUMPRODUCT(Valuation!$B$5:$F$5,1/(1+E$4)^{1,2,3,4,5})+IF(E$4>$A6,Valuation!$F$5*(1+$A6)/(E$4-$A6)/(1+E$4)^5,0) -> 37464.978 | F6: =SUMPRODUCT(Valuation!$B$5:$F$5,1/(1+F$4)^{1,2,3,4,5})+IF(F$4>$A6,Valuation!$F$5*(1+$A6)/(F$4-$A6)/(1+F$4)^5,0) -> 33235.061
A7: 0.03 | B7: =SUMPRODUCT(Valuation!$B$5:$F$5,1/(1+B$4)^{1,2,3,4,5})+IF(B$4>$A7,Valuation!$F$5*(1+$A7)/(B$4-$A7)/(1+B$4)^5,0) -> 72945.678 | C7: =SUMPRODUCT(Valuation!$B$5:$F$5,1/(1+C$4)^{1,2,3,4,5})+IF(C$4>$A7,Valuation!$F$5*(1+$A7)/(C$4-$A7)/(1+C$4)^5,0) -> 58266.688 | D7: =SUMPRODUCT(Valuation!$B$5:$F$5,1/(1+D$4)^{1,2,3,4,5})+IF(D$4>$A7,Valuation!$F$5*(1+$A7)/(D$4-$A7)/(1+D$4)^5,0) -> 48483.398 | E7: =SUMPRODUCT(Valuation!$B$5:$F$5,1/(1+E$4)^{1,2,3,4,5})+IF(E$4>$A7,Valuation!$F$5*(1+$A7)/(E$4-$A7)/(1+E$4)^5,0) -> 41497.542 | F7: =SUMPRODUCT(Valuation!$B$5:$F$5,1/(1+F$4)^{1,2,3,4,5})+IF(F$4>$A7,Valuation!$F$5*(1+$A7)/(F$4-$A7)/(1+F$4)^5,0) -> 36259.993
A8: 0.04 | B8: =SUMPRODUCT(Valuation!$B$5:$F$5,1/(1+B$4)^{1,2,3,4,5})+IF(B$4>$A8,Valuation!$F$5*(1+$A8)/(B$4-$A8)/(1+B$4)^5,0) -> 93965.242 | C8: =SUMPRODUCT(Valuation!$B$5:$F$5,1/(1+C$4)^{1,2,3,4,5})+IF(C$4>$A8,Valuation!$F$5*(1+$A8)/(C$4-$A8)/(1+C$4)^5,0) -> 70417.772 | D8: =SUMPRODUCT(Valuation!$B$5:$F$5,1/(1+D$4)^{1,2,3,4,5})+IF(D$4>$A8,Valuation!$F$5*(1+$A8)/(D$4-$A8)/(1+D$4)^5,0) -> 56290.913 | E8: =SUMPRODUCT(Valuation!$B$5:$F$5,1/(1+E$4)^{1,2,3,4,5})+IF(E$4>$A8,Valuation!$F$5*(1+$A8)/(E$4-$A8)/(1+E$4)^5,0) -> 46874.295 | F8: =SUMPRODUCT(Valuation!$B$5:$F$5,1/(1+F$4)^{1,2,3,4,5})+IF(F$4>$A8,Valuation!$F$5*(1+$A8)/(F$4-$A8)/(1+F$4)^5,0) -> 40149.192
A9: 0.05 | B9: =SUMPRODUCT(Valuation!$B$5:$F$5,1/(1+B$4)^{1,2,3,4,5})+IF(B$4>$A9,Valuation!$F$5*(1+$A9)/(B$4-$A9)/(1+B$4)^5,0) -> 136004.37 | C9: =SUMPRODUCT(Valuation!$B$5:$F$5,1/(1+C$4)^{1,2,3,4,5})+IF(C$4>$A9,Valuation!$F$5*(1+$A9)/(C$4-$A9)/(1+C$4)^5,0) -> 90669.58 | D9: =SUMPRODUCT(Valuation!$B$5:$F$5,1/(1+D$4)^{1,2,3,4,5})+IF(D$4>$A9,Valuation!$F$5*(1+$A9)/(D$4-$A9)/(1+D$4)^5,0) -> 68002.185 | E9: =SUMPRODUCT(Valuation!$B$5:$F$5,1/(1+E$4)^{1,2,3,4,5})+IF(E$4>$A9,Valuation!$F$5*(1+$A9)/(E$4-$A9)/(1+E$4)^5,0) -> 54401.748 | F9: =SUMPRODUCT(Valuation!$B$5:$F$5,1/(1+F$4)^{1,2,3,4,5})+IF(F$4>$A9,Valuation!$F$5*(1+$A9)/(F$4-$A9)/(1+F$4)^5,0) -> 45334.79

Sheet Checks
A1: Model checks
A2: All critical checks should read PASS before decision use.
A4: Check | B4: Result | C4: Severity | D4: Interpretation
A5: Forecast revenue non-negative | B5: =IF(MIN(Forecast!C5:G5)>=0,"PASS","FAIL") -> PASS | C5: Critical | D5: No negative revenue
A6: FCFF formula populated | B6: =IF(COUNT(Forecast!C14:G14)=5,"PASS","FAIL") -> PASS | C6: Critical | D6: Five forecast cash flows
A7: WACC exceeds terminal growth | B7: =IF(Assumptions!E11>Assumptions!E12,"PASS","FAIL") -> PASS | C7: Critical | D7: Required for convergent DCF
A8: Valuation bridge | B8: =IF(ABS(Valuation!B16-(Valuation!B13+Valuation!B14-Valuation!B15))<0.1,"PASS","FAIL") -> PASS | C8: Critical | D8: EV plus cash less debt equals equity value
A9: Historical source coverage | B9: LIMITED | C9: Readiness | D9: Manual/summary sources or missing financial history remain explicitly limited
A11: Overall gate | B11: =IF(COUNTIF(B5:B9,"FAIL")=0,IF(COUNTIF(B5:B9,"LIMITED")=0,"PASS","PASS WITH LIMITATIONS"),"FAIL") -> PASS WITH LIMITATIONS
A12: Decision use | B12: Source-backed operating model; no public-equity price target

Sheet Sector_KPIs
A1: Sector KPI framework
A2: A decision-useful model requires sector drivers beyond the three statements.
A4: KPI | B4: Historical | C4: Forecast | D4: Status / source requirement
A5: Generation / throughput | D5: Input-ready; populate from issuer operating disclosures
A6: Installed capacity | D6: Input-ready; populate from issuer operating disclosures
A7: Regulated rate base | D7: Input-ready; populate from issuer operating disclosures
A8: Realized price / tariff | D8: Input-ready; populate from issuer operating disclosures
A9: EBITDA margin | D9: Input-ready; populate from issuer operating disclosures
A10: Capex plan | D10: Input-ready; populate from issuer operating disclosures
A11: Net debt / EBITDA | D11: Input-ready; populate from issuer operating disclosures
A12: Interest coverage | D12: Input-ready; populate from issuer operating disclosures
A13: Carbon intensity | D13: Input-ready; populate from issuer operating disclosures

Sheet Change_Log
A1: Change log and governance
A2: Version history and model-owner review record.
A4: Date | B4: Version | C4: Author | D4: Change | E4: Evidence | F4: Reviewer status
A5: 2026-07-15 | B5: 1.0 | C5: Codex | D5: Initial institutional model framework and source pack | E5: https://www.epm.com.co/inversionistas/noticias/resultados-financieros-2025-grupo-epm-solidez/ | F5: Builder-verified
A6: 2026-07-15 | B6: 1.0 | C6: Codex | D6: Formula, package and visual QA | E6: Checks sheet and preview artifacts | F6: Pending owner investment judgment
A7: 46224 | B7: Elevacion a statement-grade IG (patron Samsung): BS_Hist/IS_Hist/CF_Hist auditados FY2022A-FY2025A (COP mm, constantes publicadas), Segment_Hist (8 segmentos, Nota 46.1/47.1), Checks_TieOut (31 tie-outs incl. cruces entre estados y continuidad de caja), USD_Presentation (TRM de cierre implicita por bono internacional), Sources_Audited (fuente por columna + reexpresiones detectadas). Forecast/Assumptions/Valuation/Sensitivity NO actualizados en esta pasada - quedan en el placeholder previo (USD, un solo año) y se marcan PARTIAL; requieren reconstruccion driver-based ancladas a la nueva base COP. Root model intacto; v2 en the maintainer's archive. | C7: Claude (run 41538014)

Sheet BS_Hist
A1: EPM Grupo - Estado de Situacion Financiera Consolidado (auditado)
A2: COP millones. FY2022 y FY2023 segun EEFF auditados al 31-12-2023 (FY2022 = comparativo, primera cifra auditada); FY2024 segun EEFF auditados al 31-12-2024; FY2025 segun EEFF auditados al 31-12-2025. Cada columna toma la cifra de "año propio" del informe correspondiente (no la cifra comparativa re-expresada en un informe posterior) — ver Sources_Audited para el detalle de reexpresiones detectadas.
A4: Line item | B4: FY2022A | C4: FY2023A | D4: FY2024A | E4: FY2025A | G4: Note ref
A5: Activo
A6: Activo no corriente
A7: Propiedades, planta y equipo, neto | B7: 44181617 | C7: 46604510 | D7: 51022424 | E7: 54029561 | G7: 5
A8: Propiedades de inversion | B8: 190574 | C8: 194610 | D8: 238825 | E8: 252578 | G8: 6
A9: Credito mercantil | B9: 3693266 | C9: 2977065 | D9: 2942675 | E9: 2665810 | G9: 7
A10: Otros activos intangibles | B10: 3405647 | C10: 2994207 | D10: 3360225 | E10: 3177617 | G10: 7
A11: Activos por derecho de uso | B11: 826955 | C11: 829895 | D11: 981647 | E11: 997304 | G11: 14
A12: Inversiones en asociadas | B12: 1153598 | C12: 1056124 | D12: 1087824 | E12: 241780 | G12: 9/10
A13: Inversiones en negocios conjuntos | B13: 17166 | C13: 17739 | D13: 16706 | E13: 2166 | G13: 10/11
A14: Activo por impuesto diferido | B14: 1217353 | C14: 1519458 | D14: 1931766 | E14: 2286225 | G14: 39-41
A15: Deudores comerciales y otras cuentas por cobrar (no corriente) | B15: 2441171 | C15: 3061104 | D15: 2511637 | E15: 2533237 | G15: 12
A16: Otros activos financieros (no corriente) | B16: 3023468 | C16: 2341311 | D16: 2804389 | E16: 3231857 | G16: 13
A17: Otros activos (no corriente) | B17: 331706 | C17: 360309 | D17: 505678 | E17: 437454 | G17: 16
A18: Efectivo y equivalentes de efectivo (restringido) | B18: 89065 | C18: 59346 | D18: 26371 | E18: 40559 | G18: 18
A19: Total activo no corriente | B19: 60571586 | C19: 62015678 | D19: 67430167 | E19: 69896148
A21: Activo corriente
A22: Inventarios | B22: 714643 | C22: 760329 | D22: 684938 | E22: 598065 | G22: 17
A23: Deudores comerciales y otras cuentas por cobrar (corriente) | B23: 7504762 | C23: 8463392 | D23: 8525876 | E23: 7893017 | G23: 12
A24: Activo por impuesto sobre la renta corriente | B24: 697964 | C24: 894782 | D24: 976499 | E24: 1109329 | G24: 26/41
A25: Otros activos financieros (corriente) | B25: 1047473 | C25: 517297 | D25: 933056 | E25: 866382 | G25: 13
A26: Otros activos (corriente) | B26: 947132 | C26: 1202032 | D26: 1375716 | E26: 1139051 | G26: 16
A27: Efectivo y equivalentes de efectivo | B27: 4038679 | C27: 3244472 | D27: 2817912 | E27: 4339445 | G27: 18
A28: Total activo corriente (antes de mantenidos para la venta) | B28: 14950653 | C28: 15082304 | D28: 15313997 | E28: 15945289
A29: Activos clasificados como mantenidos para la venta | E29: 1085175 | G29: 19
A30: Total activo corriente | B30: 14950653 | C30: 15082304 | D30: 15313997 | E30: 17030464
A32: Total activo | B32: 75522239 | C32: 77097982 | D32: 82744164 | E32: 86926612
A33: Saldos debito de cuentas regulatorias diferidas | B33: 56115 | C33: 137883 | D33: 695050 | E33: 303421 | G33: 30/31
A34: Total activo y saldos debito de cuentas regulatorias diferidas | B34: 75578354 | C34: 77235865 | D34: 83439214 | E34: 87230033
A36: Patrimonio
A37: Capital emitido | B37: 67 | C37: 67 | D37: 67 | E37: 67 | G37: 19/20
A38: Acciones en tesoreria | B38: -52 | C38: -52 | D38: 0 | E38: 0 | G38: 19/20
A39: Reservas | B39: 2518114 | C39: 2341067 | D39: 2453983 | E39: 2575007 | G39: 19/20
A40: Otro resultado integral acumulado | B40: 3765881 | C40: 2720926 | D40: 3065544 | E40: 3441811 | G40: 20/21
A41: Resultados acumulados | B41: 19212331 | C41: 21486694 | D41: 22285158 | E41: 24051250 | G41: 19/20
A42: Resultado neto del periodo | B42: 3845458 | C42: 3249354 | D42: 4541404 | E42: 4979411 | G42: 19/20
A43: Otros componentes de patrimonio | B43: 78565 | C43: 84698 | D43: 85754 | E43: 89307 | G43: 19/20
A44: Patrimonio atribuible a las participaciones controladoras | B44: 29420364 | C44: 29882754 | D44: 32431910 | E44: 35136853
...

Sheet IS_Hist
A1: EPM Grupo - Estado del Resultado Integral Consolidado (auditado)
A2: COP millones. Misma base de fuente por columna que BS_Hist.
A4: Line item | B4: FY2022A | C4: FY2023A | D4: FY2024A | E4: FY2025A | G4: Note ref
A5: Prestacion de servicios | B5: 31524554 | C5: 36897753 | D5: 39415019 | E5: 37867300 | G5: 31/32
A6: Venta de bienes | B6: 55457 | C6: 83399 | D6: 75563 | E6: 81660 | G6: 31/32
A7: Arrendamiento | B7: 148397 | C7: 157935 | D7: 127099 | E7: 168879 | G7: 31/32
A8: Ingresos de actividades ordinarias | B8: 31728408 | C8: 37139087 | D8: 39617681 | E8: 38117839
A9: Otros ingresos | B9: 488409 | C9: 392735 | D9: 1867024 | E9: 2427914 | G9: 32/33
A10: Utilidad en venta de activos | B10: 5652 | C10: 4894 | D10: 3206 | E10: 15466 | G10: 33/34
A11: Total ingresos | B11: 32222469 | C11: 37536716 | D11: 41487911 | E11: 40561219
A12: Costos por prestacion de servicios | B12: -20687461 | C12: -25066462 | D12: -27261863 | E12: -25704977 | G12: 34/35
A13: Gastos de administracion | B13: -2330073 | C13: -3461988 | D13: -4011361 | E13: -3044849 | G13: 35/36
A14: Deterioro de cuentas por cobrar, neto | B14: -1106405 | C14: -1199656 | D14: -1026925 | E14: -1213614 | G14: 12
A15: Otros gastos | B15: -138511 | C15: -125435 | D15: -157469 | E15: -220217 | G15: 36/37
A16: Ingresos financieros | B16: 397903 | C16: 804674 | D16: 759784 | E16: 421487 | G16: 37.1/38.1
A17: Gastos financieros | B17: -2284882 | C17: -3267082 | D17: -3510889 | E17: -3534428 | G17: 37.2/38.2
A18: Diferencia en cambio neta | B18: -103086 | C18: 171188 | D18: -241320 | E18: 305688 | G18: 38/39
A19: Metodo de participacion en asociadas y negocios conjuntos | B19: -237266 | C19: -567722 | D19: 14717 | E19: 234224 | G19: 9-11
A20: Efecto por participacion en inversiones patrimoniales | B20: 70722 | C20: 178118 | D20: 123334 | E20: 115947 | G20: 39/40
A21: Resultado del periodo antes de impuestos | B21: 5803410 | C21: 5002351 | D21: 6175919 | E21: 7920480
A22: Impuesto sobre la renta | B22: -1610791 | C22: -1516153 | D22: -1387096 | E22: -2489789 | G22: 40/41
A23: Resultado del periodo despues de impuestos | B23: 4192619 | C23: 3486198 | D23: 4788823 | E23: 5430691
A24: Movimiento neto cuentas regulatorias relacionadas con el resultado | B24: -97743 | C24: 105156 | D24: 172043 | E24: -115742 | G24: 30/31
A25: Movimiento neto imp. diferido rel. cuentas regulatorias del resultado | B25: 30625 | C25: -29408 | D25: -55457 | E25: 21984 | G25: 30/31
A26: Resultado neto del periodo y mov. neto saldos cuentas regulatorias | B26: 4125501 | C26: 3561946 | D26: 4905409 | E26: 5336933
A28: Otro resultado integral - partidas no reclasificables
A29: Nuevas mediciones de planes de beneficios definidos | B29: 126956 | C29: -214930 | D29: 164888 | E29: 23263 | G29: 20/21
A30: Inversiones patrimoniales medidas a VR a traves de patrimonio | B30: -131035 | C30: -539451 | D30: 119253 | E30: 777954 | G30: 20/21
A31: Reclasificacion de PP&E a propiedades de inversion | D31: 977 | G31: 21
A32: Metodo de participacion asociadas y NC (no reclasificable) | B32: -2714 | C32: -105778 | D32: 16851
A33: Activos no corrientes mantenidos para la venta (no reclasificable) | E33: 12574 | G33: 21
A34: Impuesto renta sobre componentes no reclasificables | B34: -349496 | C34: 180040 | D34: -69450 | E34: -111296 | G34: 20y40/21y41
A35: Subtotal partidas no reclasificadas | B35: -356289 | C35: -680119 | D35: 232519 | E35: 702495
A37: Otro resultado integral - partidas reclasificables
A38: Coberturas de flujos de efectivo | B38: -595470 | C38: 446908 | D38: -295209 | E38: 374212 | G38: 20/21
A39: Diferencias de cambio por conversion negocios en el extranjero | B39: 840297 | C39: -1123159 | D39: 416442 | E39: -598783 | G39: 20/21
A40: Metodo de participacion asociadas y NC (reclasificable) | B40: 3347 | C40: 273052 | D40: -6393 | G40: 10y20/10y21
A41: Coberturas de inversiones netas en negocios en el extranjero | B41: -216145 | C41: 283752 | D41: -150329 | E41: 167669
A42: Activos no corrientes mantenidos para la venta (reclasificable) | E42: -1165
A43: Impuesto renta sobre componentes reclasificables | B43: 288033 | C43: -250892 | D43: 152096 | E43: -266103 | G43: 20y40/21y41
...

Sheet CF_Hist
A1: EPM Grupo - Estado de Flujos de Efectivo Consolidado (auditado)
A2: COP millones. Misma base de fuente por columna que BS_Hist. Signos como publicados (salidas negativas).
A4: Line item | B4: FY2022A | C4: FY2023A | D4: FY2024A | E4: FY2025A | G4: Note ref
A5: Actividades de la operacion
A6: Resultado neto del periodo | B6: 4125501 | C6: 3561946 | D6: 4905409 | E6: 5336933
A7: Depreciacion y amortizacion de PP&E, ROU e intangibles | B7: 1524883 | C7: 1874177 | D7: 2025485 | E7: 2077456 | G7: 34y35/35y36
A8: Deterioro de valor de PP&E, ROU e intangibles | B8: 88647 | C8: 149245 | D8: 615903 | E8: 270898
A9: Deterioro de cuentas por cobrar, neto | B9: 1106405 | C9: 1199656 | D9: 1026925 | E9: 1213614 | G9: 12
A10: Reversion perdida deterioro PP&E/ROU/intangibles (operativo) | B10: -117 | C10: -34 | D10: -3 | G10: 8/11
A11: Reversion perdida deterioro otros activos no corrientes | D11: -6420 | G11: 11
A12: Deterioro de valor inversiones en asociadas y NC | B12: 6420 | E12: 12489 | G12: 8/10
A13: Reversion perdida deterioro PP&E/ROU/intangibles | E13: -726592
A14: Rebaja de valor inventarios, neto | B14: 2023 | C14: 3647 | D14: 5478 | E14: 8677
A15: Resultado por diferencia en cambio, neto | B15: 103086 | C15: -171188 | D15: 241320 | E15: -305688
A16: Resultado por valoracion de propiedades de inversion | B16: -20383 | C16: -10012 | D16: 5617 | E16: -11094
A17: Resultado valoracion instrumentos financieros y contab. cobertura | B17: 25353 | C17: -269693 | D17: -255254 | E17: -20919
A18: Resultado indemnizaciones asociadas a flujos de inversion | C18: -477 | D18: -9395 | E18: -321
A19: Provisiones, planes beneficios post-empleo y largo plazo | B19: 317572 | C19: 989939 | D19: 1407071 | E19: 258708
A20: Provisiones fiscales, seguros/reaseguros y actualizacion financiera | B20: 86223 | C20: 137515 | D20: 117232 | E20: 148047
A21: Subvenciones del gobierno aplicadas | B21: -119985 | C21: -119939 | D21: -120004 | E21: -120028
A22: Impuesto sobre la renta diferido | B22: -152669 | C22: -189569 | D22: -512401 | E22: 629009
A23: Impuesto sobre la renta corriente | B23: 1763460 | C23: 1705722 | D23: 1899497 | E23: 1860780
A24: Resultados por metodo de participacion en asociadas y NC | B24: 237266 | C24: 567721 | D24: -14717 | E24: -234224
A25: Ingresos por intereses y rendimientos | B25: -293616 | C25: -329588 | D25: -334464 | E25: -318143
A26: Gastos por intereses y comisiones | B26: 2069530 | C26: 2947300 | D26: 3223519 | E26: 3308336
A27: Resultado disposicion PP&E/ROU/intangibles/prop. inversion | B27: -5084 | C27: -2007 | D27: -1279 | E27: -14039
A28: Resultado retiro PP&E/ROU/intangibles/prop. inversion | B28: 51865 | C28: 56093 | D28: 59146 | E28: 51292
A29: Resultado disposicion instrumentos financieros | C29: 19
A30: Resultado medicion VR participacion retenida inv. patrimoniales | C30: 86
A31: Recuperaciones no efectivas | B31: -117643 | C31: -68570 | D31: -1367423 | E31: -1178811
A32: Resultado cuentas regulatorias diferidas | B32: 67117 | C32: -75748 | D32: -116586 | E32: 93758
A33: Resultado disposicion inversiones en asociadas y NC | B33: -83 | E33: 2488
A34: Dividendos de inversiones | B34: -77059 | C34: -178222 | D34: -116913 | E34: -130924
A35: Subtotal resultado neto + partidas de conciliacion | B35: 10788712 | C35: 11778019 | D35: 12677743 | E35: 12211702
A37: Cambios netos en activos y pasivos operacionales
A38: Variacion en inventarios | B38: -195929 | C38: -49595 | D38: 72316 | E38: 78781
A39: Variacion en deudores comerciales y otras cuentas por cobrar | B39: -3327709 | C39: -3275568 | D39: 1083805 | E39: 453854
A40: Variacion en otros activos | B40: -562298 | C40: 103042 | D40: -669206 | E40: 906480
A41: Variacion en acreedores y otras cuentas por pagar | B41: 639967 | C41: 598615 | D41: 39379 | E41: -932854
A42: Variacion en beneficios a los empleados | B42: 25369 | C42: 26301 | D42: -277420 | E42: -145526
...

Sheet Segment_Hist
A1: EPM Grupo - Ingresos por segmento operativo (Nota Informacion por segmentos)
A2: COP millones, ingresos de clientes externos por segmento (neto de intersegmentos). Fuente: Nota 46.1 (FY2023/FY2024 informes) / Nota 47.1 (FY2025 informe).
A4: Line item | B4: FY2022A | C4: FY2023A | D4: FY2024A | E4: FY2025A | G4: Note ref
A5: Generacion y comercializacion Energia | B5: 4753989 | C5: 6456029 | D5: 8599528 | E5: 7466366 | G5: 46.1/47.1
A6: Transmision Energia | B6: 347758 | C6: 374445 | D6: 370889 | E6: 395620 | G6: 46.1/47.1
A7: Distribucion y comercializacion Energia | B7: 22357862 | C7: 24970973 | D7: 26377608 | E7: 26013178 | G7: 46.1/47.1
A8: Distribucion y comercializacion Gas | B8: 1296008 | C8: 1546349 | D8: 1572580 | E8: 1439126 | G8: 46.1/47.1
A9: Provision y comercializacion Agua | B9: 1739639 | C9: 2130208 | D9: 2341970 | E9: 2499177 | G9: 46.1/47.1
A10: Gestion y comercializacion Aguas Residuales | B10: 1193245 | C10: 1451884 | D10: 1535773 | E10: 1904662 | G10: 46.1/47.1
A11: Gestion y comercializacion Residuos Solidos | B11: 285014 | C11: 325195 | D11: 417770 | E11: 506234 | G11: 46.1/47.1
A12: Otros segmentos | B12: 248954 | C12: 281633 | D12: 271793 | E12: 336856 | G12: 46.1/47.1
A13: Total ingresos de clientes externos (consolidado) | B13: 32222469 | C13: 37536716 | D13: 41487911 | E13: 40561219

Sheet Checks_TieOut
A1: Tie-out checks - EEFF consolidados auditados EPM (todos los deltas deben ser 0; COP millones)
A2: MASTER | B2: =IF(COUNTIF(G5:G37,"FAIL")=0,"OK - ALL TIE-OUTS PASS","FAIL") -> OK - ALL TIE-OUTS PASS
A4: Check | B4: FY2022A | C4: FY2023A | D4: FY2024A | E4: FY2025A | G4: Status
A5: BS: Activo no corriente = suma de partidas | B5: =SUM(BS_Hist!B7:B18)-BS_Hist!B19 -> 0 | C5: =SUM(BS_Hist!C7:C18)-BS_Hist!C19 -> 0 | D5: =SUM(BS_Hist!D7:D18)-BS_Hist!D19 -> 0 | E5: =SUM(BS_Hist!E7:E18)-BS_Hist!E19 -> 0 | G5: =IF(AND(ABS(N(B5))<=1,ABS(N(C5))<=1,ABS(N(D5))<=1,ABS(N(E5))<=1),"PASS","FAIL") -> PASS
A6: BS: Activo corriente (antes MPV) = suma de partidas | B6: =SUM(BS_Hist!B22:B27)-BS_Hist!B28 -> 0 | C6: =SUM(BS_Hist!C22:C27)-BS_Hist!C28 -> 0 | D6: =SUM(BS_Hist!D22:D27)-BS_Hist!D28 -> 0 | E6: =SUM(BS_Hist!E22:E27)-BS_Hist!E28 -> 0 | G6: =IF(AND(ABS(N(B6))<=1,ABS(N(C6))<=1,ABS(N(D6))<=1,ABS(N(E6))<=1),"PASS","FAIL") -> PASS
A7: BS: Activo corriente = antes MPV + mantenidos para la venta | B7: =BS_Hist!B28+N(BS_Hist!B29)-BS_Hist!B30 -> 0 | C7: =BS_Hist!C28+N(BS_Hist!C29)-BS_Hist!C30 -> 0 | D7: =BS_Hist!D28+N(BS_Hist!D29)-BS_Hist!D30 -> 0 | E7: =BS_Hist!E28+N(BS_Hist!E29)-BS_Hist!E30 -> 0 | G7: =IF(AND(ABS(N(B7))<=1,ABS(N(C7))<=1,ABS(N(D7))<=1,ABS(N(E7))<=1),"PASS","FAIL") -> PASS
A8: BS: Total activo = NC + C | B8: =BS_Hist!B19+BS_Hist!B30-BS_Hist!B32 -> 0 | C8: =BS_Hist!C19+BS_Hist!C30-BS_Hist!C32 -> 0 | D8: =BS_Hist!D19+BS_Hist!D30-BS_Hist!D32 -> 0 | E8: =BS_Hist!E19+BS_Hist!E30-BS_Hist!E32 -> 0 | G8: =IF(AND(ABS(N(B8))<=1,ABS(N(C8))<=1,ABS(N(D8))<=1,ABS(N(E8))<=1),"PASS","FAIL") -> PASS
A9: BS: Total activo + saldos debito regulatorios | B9: =BS_Hist!B32+BS_Hist!B33-BS_Hist!B34 -> 0 | C9: =BS_Hist!C32+BS_Hist!C33-BS_Hist!C34 -> 0 | D9: =BS_Hist!D32+BS_Hist!D33-BS_Hist!D34 -> 0 | E9: =BS_Hist!E32+BS_Hist!E33-BS_Hist!E34 -> 0 | G9: =IF(AND(ABS(N(B9))<=1,ABS(N(C9))<=1,ABS(N(D9))<=1,ABS(N(E9))<=1),"PASS","FAIL") -> PASS
A10: BS: Patrimonio controladora = suma de partidas | B10: =SUM(BS_Hist!B37:B43)-BS_Hist!B44 -> 0 | C10: =SUM(BS_Hist!C37:C43)-BS_Hist!C44 -> 0 | D10: =SUM(BS_Hist!D37:D43)-BS_Hist!D44 -> 0 | E10: =SUM(BS_Hist!E37:E43)-BS_Hist!E44 -> 0 | G10: =IF(AND(ABS(N(B10))<=1,ABS(N(C10))<=1,ABS(N(D10))<=1,ABS(N(E10))<=1),"PASS","FAIL") -> PASS
A11: BS: Total patrimonio = controladora + NCI | B11: =BS_Hist!B44+BS_Hist!B45-BS_Hist!B46 -> 0 | C11: =BS_Hist!C44+BS_Hist!C45-BS_Hist!C46 -> 0 | D11: =BS_Hist!D44+BS_Hist!D45-BS_Hist!D46 -> 0 | E11: =BS_Hist!E44+BS_Hist!E45-BS_Hist!E46 -> 0 | G11: =IF(AND(ABS(N(B11))<=1,ABS(N(C11))<=1,ABS(N(D11))<=1,ABS(N(E11))<=1),"PASS","FAIL") -> PASS
A12: BS: Pasivo no corriente = suma de partidas | B12: =SUM(BS_Hist!B50:B57)-BS_Hist!B58 -> 0 | C12: =SUM(BS_Hist!C50:C57)-BS_Hist!C58 -> 0 | D12: =SUM(BS_Hist!D50:D57)-BS_Hist!D58 -> 0 | E12: =SUM(BS_Hist!E50:E57)-BS_Hist!E58 -> 0 | G12: =IF(AND(ABS(N(B12))<=1,ABS(N(C12))<=1,ABS(N(D12))<=1,ABS(N(E12))<=1),"PASS","FAIL") -> PASS
A13: BS: Pasivo corriente = suma de partidas | B13: =SUM(BS_Hist!B61:B68)-BS_Hist!B69 -> 0 | C13: =SUM(BS_Hist!C61:C68)-BS_Hist!C69 -> 0 | D13: =SUM(BS_Hist!D61:D68)-BS_Hist!D69 -> 0 | E13: =SUM(BS_Hist!E61:E68)-BS_Hist!E69 -> 0 | G13: =IF(AND(ABS(N(B13))<=1,ABS(N(C13))<=1,ABS(N(D13))<=1,ABS(N(E13))<=1),"PASS","FAIL") -> PASS
A14: BS: Total pasivo = NC + C | B14: =BS_Hist!B58+BS_Hist!B69-BS_Hist!B71 -> 0 | C14: =BS_Hist!C58+BS_Hist!C69-BS_Hist!C71 -> 0 | D14: =BS_Hist!D58+BS_Hist!D69-BS_Hist!D71 -> 0 | E14: =BS_Hist!E58+BS_Hist!E69-BS_Hist!E71 -> 0 | G14: =IF(AND(ABS(N(B14))<=1,ABS(N(C14))<=1,ABS(N(D14))<=1,ABS(N(E14))<=1),"PASS","FAIL") -> PASS
A15: BS: Total pasivo + saldos credito/pasivo tributario regulatorio | B15: =BS_Hist!B71+N(BS_Hist!B72)+N(BS_Hist!B73)-BS_Hist!B74 -> 0 | C15: =BS_Hist!C71+N(BS_Hist!C72)+N(BS_Hist!C73)-BS_Hist!C74 -> 0 | D15: =BS_Hist!D71+N(BS_Hist!D72)+N(BS_Hist!D73)-BS_Hist!D74 -> 0 | E15: =BS_Hist!E71+N(BS_Hist!E72)+N(BS_Hist!E73)-BS_Hist!E74 -> 0 | G15: =IF(AND(ABS(N(B15))<=1,ABS(N(C15))<=1,ABS(N(D15))<=1,ABS(N(E15))<=1),"PASS","FAIL") -> PASS
A16: BS: TP&E = pasivo + patrimonio | B16: =BS_Hist!B74+BS_Hist!B46-BS_Hist!B76 -> 0 | C16: =BS_Hist!C74+BS_Hist!C46-BS_Hist!C76 -> 0 | D16: =BS_Hist!D74+BS_Hist!D46-BS_Hist!D76 -> 0 | E16: =BS_Hist!E74+BS_Hist!E46-BS_Hist!E76 -> 0 | G16: =IF(AND(ABS(N(B16))<=1,ABS(N(C16))<=1,ABS(N(D16))<=1,ABS(N(E16))<=1),"PASS","FAIL") -> PASS
A17: BS: Balance final (Activo - Pasivo&Patrimonio) | B17: =BS_Hist!B34-BS_Hist!B76 -> 0 | C17: =BS_Hist!C34-BS_Hist!C76 -> 0 | D17: =BS_Hist!D34-BS_Hist!D76 -> 0 | E17: =BS_Hist!E34-BS_Hist!E76 -> 0 | G17: =IF(AND(ABS(N(B17))<=1,ABS(N(C17))<=1,ABS(N(D17))<=1,ABS(N(E17))<=1),"PASS","FAIL") -> PASS
A18: IS: Total ingresos = ingresos ordinarios + otros + utilidad venta activos | B18: =IS_Hist!B8+IS_Hist!B9+IS_Hist!B10-IS_Hist!B11 -> 0 | C18: =IS_Hist!C8+IS_Hist!C9+IS_Hist!C10-IS_Hist!C11 -> 0 | D18: =IS_Hist!D8+IS_Hist!D9+IS_Hist!D10-IS_Hist!D11 -> 0 | E18: =IS_Hist!E8+IS_Hist!E9+IS_Hist!E10-IS_Hist!E11 -> 0 | G18: =IF(AND(ABS(N(B18))<=1,ABS(N(C18))<=1,ABS(N(D18))<=1,ABS(N(E18))<=1),"PASS","FAIL") -> PASS
A19: IS: PBT = total ingresos - costos/gastos + neto financiero + participaciones | B19: =IS_Hist!B11+IS_Hist!B12+IS_Hist!B13+IS_Hist!B14+IS_Hist!B15+IS_Hist!B16+IS_Hist!B17+IS_Hist!B18+IS_Hist!B19+IS_Hist!B20-IS_Hist!B21 -> 0 | C19: =IS_Hist!C11+IS_Hist!C12+IS_Hist!C13+IS_Hist!C14+IS_Hist!C15+IS_Hist!C16+IS_Hist!C17+IS_Hist!C18+IS_Hist!C19+IS_Hist!C20-IS_Hist!C21 -> 0 | D19: =IS_Hist!D11+IS_Hist!D12+IS_Hist!D13+IS_Hist!D14+IS_Hist!D15+IS_Hist!D16+IS_Hist!D17+IS_Hist!D18+IS_Hist!D19+IS_Hist!D20-IS_Hist!D21 -> 0 | E19: =IS_Hist!E11+IS_Hist!E12+IS_Hist!E13+IS_Hist!E14+IS_Hist!E15+IS_Hist!E16+IS_Hist!E17+IS_Hist!E18+IS_Hist!E19+IS_Hist!E20-IS_Hist!E21 -> 0 | G19: =IF(AND(ABS(N(B19))<=1,ABS(N(C19))<=1,ABS(N(D19))<=1,ABS(N(E19))<=1),"PASS","FAIL") -> PASS
A20: IS: Resultado despues impuestos = PBT - impuesto | B20: =IS_Hist!B21+IS_Hist!B22-IS_Hist!B23 -> 0 | C20: =IS_Hist!C21+IS_Hist!C22-IS_Hist!C23 -> 0 | D20: =IS_Hist!D21+IS_Hist!D22-IS_Hist!D23 -> 0 | E20: =IS_Hist!E21+IS_Hist!E22-IS_Hist!E23 -> 0 | G20: =IF(AND(ABS(N(B20))<=1,ABS(N(C20))<=1,ABS(N(D20))<=1,ABS(N(E20))<=1),"PASS","FAIL") -> PASS
A21: IS: Resultado neto+regulatorias = resultado desp. imp. + movimientos regulatorios | B21: =IS_Hist!B23+IS_Hist!B24+IS_Hist!B25-IS_Hist!B26 -> 0 | C21: =IS_Hist!C23+IS_Hist!C24+IS_Hist!C25-IS_Hist!C26 -> 0 | D21: =IS_Hist!D23+IS_Hist!D24+IS_Hist!D25-IS_Hist!D26 -> 0 | E21: =IS_Hist!E23+IS_Hist!E24+IS_Hist!E25-IS_Hist!E26 -> 0 | G21: =IF(AND(ABS(N(B21))<=1,ABS(N(C21))<=1,ABS(N(D21))<=1,ABS(N(E21))<=1),"PASS","FAIL") -> PASS
A22: IS: Resultado neto = atribuible controladora + NCI | B22: =IS_Hist!B50+IS_Hist!B51-IS_Hist!B26 -> 0 | C22: =IS_Hist!C50+IS_Hist!C51-IS_Hist!C26 -> 0 | D22: =IS_Hist!D50+IS_Hist!D51-IS_Hist!D26 -> 0 | E22: =IS_Hist!E50+IS_Hist!E51-IS_Hist!E26 -> 0 | G22: =IF(AND(ABS(N(B22))<=1,ABS(N(C22))<=1,ABS(N(D22))<=1,ABS(N(E22))<=1),"PASS","FAIL") -> PASS
A23: IS: OCI total = subtotal no reclasificado + subtotal reclasificado | B23: =IS_Hist!B35+IS_Hist!B44-IS_Hist!B46 -> 0 | C23: =IS_Hist!C35+IS_Hist!C44-IS_Hist!C46 -> 0 | D23: =IS_Hist!D35+IS_Hist!D44-IS_Hist!D46 -> 0 | E23: =IS_Hist!E35+IS_Hist!E44-IS_Hist!E46 -> 0 | G23: =IF(AND(ABS(N(B23))<=1,ABS(N(C23))<=1,ABS(N(D23))<=1,ABS(N(E23))<=1),"PASS","FAIL") -> PASS
A24: IS: Resultado integral total = resultado neto + OCI | B24: =IS_Hist!B26+IS_Hist!B46-IS_Hist!B47 -> 0 | C24: =IS_Hist!C26+IS_Hist!C46-IS_Hist!C47 -> 0 | D24: =IS_Hist!D26+IS_Hist!D46-IS_Hist!D47 -> 0 | E24: =IS_Hist!E26+IS_Hist!E46-IS_Hist!E47 -> 0 | G24: =IF(AND(ABS(N(B24))<=1,ABS(N(C24))<=1,ABS(N(D24))<=1,ABS(N(E24))<=1),"PASS","FAIL") -> PASS
A25: IS: Resultado integral total = atribuible controladora + NCI | B25: =IS_Hist!B52+IS_Hist!B53-IS_Hist!B47 -> 0 | C25: =IS_Hist!C52+IS_Hist!C53-IS_Hist!C47 -> 0 | D25: =IS_Hist!D52+IS_Hist!D53-IS_Hist!D47 -> 0 | E25: =IS_Hist!E52+IS_Hist!E53-IS_Hist!E47 -> 0 | G25: =IF(AND(ABS(N(B25))<=1,ABS(N(C25))<=1,ABS(N(D25))<=1,ABS(N(E25))<=1),"PASS","FAIL") -> PASS
A26: CF: Subtotal (resultado neto + ajustes) | B26: =SUM(CF_Hist!B6:B34)-CF_Hist!B35 -> 0 | C26: =SUM(CF_Hist!C6:C34)-CF_Hist!C35 -> 0 | D26: =SUM(CF_Hist!D6:D34)-CF_Hist!D35 -> 0 | E26: =SUM(CF_Hist!E6:E34)-CF_Hist!E35 -> 0 | G26: =IF(AND(ABS(N(B26))<=1,ABS(N(C26))<=1,ABS(N(D26))<=1,ABS(N(E26))<=1),"PASS","FAIL") -> PASS
A27: CF: Efectivo generado por operacion = subtotal + cambios capital de trabajo | B27: =CF_Hist!B35+SUM(CF_Hist!B38:B44)-CF_Hist!B45 -> 0 | C27: =CF_Hist!C35+SUM(CF_Hist!C38:C44)-CF_Hist!C45 -> 0 | D27: =CF_Hist!D35+SUM(CF_Hist!D38:D44)-CF_Hist!D45 -> 0 | E27: =CF_Hist!E35+SUM(CF_Hist!E38:E44)-CF_Hist!E45 -> 0 | G27: =IF(AND(ABS(N(B27))<=1,ABS(N(C27))<=1,ABS(N(D27))<=1,ABS(N(E27))<=1),"PASS","FAIL") -> PASS
A28: CF: Flujos netos operacion = generado + interes/impuestos | B28: =CF_Hist!B45+CF_Hist!B46+CF_Hist!B47+CF_Hist!B48-CF_Hist!B49 -> 0 | C28: =CF_Hist!C45+CF_Hist!C46+CF_Hist!C47+CF_Hist!C48-CF_Hist!C49 -> 0 | D28: =CF_Hist!D45+CF_Hist!D46+CF_Hist!D47+CF_Hist!D48-CF_Hist!D49 -> 0 | E28: =CF_Hist!E45+CF_Hist!E46+CF_Hist!E47+CF_Hist!E48-CF_Hist!E49 -> 0 | G28: =IF(AND(ABS(N(B28))<=1,ABS(N(C28))<=1,ABS(N(D28))<=1,ABS(N(E28))<=1),"PASS","FAIL") -> PASS
A29: CF: Flujos netos inversion = suma de partidas | B29: =SUM(CF_Hist!B52:B66)-CF_Hist!B67 -> 0 | C29: =SUM(CF_Hist!C52:C66)-CF_Hist!C67 -> 0 | D29: =SUM(CF_Hist!D52:D66)-CF_Hist!D67 -> 0 | E29: =SUM(CF_Hist!E52:E66)-CF_Hist!E67 -> 0 | G29: =IF(AND(ABS(N(B29))<=1,ABS(N(C29))<=1,ABS(N(D29))<=1,ABS(N(E29))<=1),"PASS","FAIL") -> PASS
A30: CF: Flujos netos financiacion = suma de partidas | B30: =SUM(CF_Hist!B70:B81)-CF_Hist!B82 -> 0 | C30: =SUM(CF_Hist!C70:C81)-CF_Hist!C82 -> 0 | D30: =SUM(CF_Hist!D70:D81)-CF_Hist!D82 -> 0 | E30: =SUM(CF_Hist!E70:E81)-CF_Hist!E82 -> 0 | G30: =IF(AND(ABS(N(B30))<=1,ABS(N(C30))<=1,ABS(N(D30))<=1,ABS(N(E30))<=1),"PASS","FAIL") -> PASS
A31: CF: Variacion neta efectivo = CFO + CFI + CFF | B31: =CF_Hist!B49+CF_Hist!B67+CF_Hist!B82-CF_Hist!B84 -> 0 | C31: =CF_Hist!C49+CF_Hist!C67+CF_Hist!C82-CF_Hist!C84 -> 0 | D31: =CF_Hist!D49+CF_Hist!D67+CF_Hist!D82-CF_Hist!D84 -> 0 | E31: =CF_Hist!E49+CF_Hist!E67+CF_Hist!E82-CF_Hist!E84 -> 0 | G31: =IF(AND(ABS(N(B31))<=1,ABS(N(C31))<=1,ABS(N(D31))<=1,ABS(N(E31))<=1),"PASS","FAIL") -> PASS
A32: CF: Efectivo final = inicial + variacion neta + efecto FX | B32: =CF_Hist!B86+CF_Hist!B84+CF_Hist!B85-CF_Hist!B87 -> 0 | C32: =CF_Hist!C86+CF_Hist!C84+CF_Hist!C85-CF_Hist!C87 -> 0 | D32: =CF_Hist!D86+CF_Hist!D84+CF_Hist!D85-CF_Hist!D87 -> 0 | E32: =CF_Hist!E86+CF_Hist!E84+CF_Hist!E85-CF_Hist!E87 -> 0 | G32: =IF(AND(ABS(N(B32))<=1,ABS(N(C32))<=1,ABS(N(D32))<=1,ABS(N(E32))<=1),"PASS","FAIL") -> PASS
A33: X: CF resultado neto = IS resultado neto+regulatorias | B33: =CF_Hist!B6-IS_Hist!B26 -> 0 | C33: =CF_Hist!C6-IS_Hist!C26 -> 0 | D33: =CF_Hist!D6-IS_Hist!D26 -> 0 | E33: =CF_Hist!E6-IS_Hist!E26 -> 0 | G33: =IF(AND(ABS(N(B33))<=1,ABS(N(C33))<=1,ABS(N(D33))<=1,ABS(N(E33))<=1),"PASS","FAIL") -> PASS
A34: X: CF efectivo final = BS efectivo corriente + efectivo restringido no corriente | B34: =CF_Hist!B87-BS_Hist!B27-BS_Hist!B18 -> 0 | C34: =CF_Hist!C87-BS_Hist!C27-BS_Hist!C18 -> 0 | D34: =CF_Hist!D87-BS_Hist!D27-BS_Hist!D18 -> 0 | E34: =CF_Hist!E87-BS_Hist!E27-BS_Hist!E18 -> 0 | G34: =IF(AND(ABS(N(B34))<=1,ABS(N(C34))<=1,ABS(N(D34))<=1,ABS(N(E34))<=1),"PASS","FAIL") -> PASS
A35: X: BS resultado neto del periodo = IS resultado neto atribuible controladora | B35: =BS_Hist!B42-IS_Hist!B50 -> 0 | C35: =BS_Hist!C42-IS_Hist!C50 -> 0 | D35: =BS_Hist!D42-IS_Hist!D50 -> 0 | E35: =BS_Hist!E42-IS_Hist!E50 -> 0 | G35: =IF(AND(ABS(N(B35))<=1,ABS(N(C35))<=1,ABS(N(D35))<=1,ABS(N(E35))<=1),"PASS","FAIL") -> PASS
A36: X: Segmentos - suma de segmentos = ingresos totales IS | B36: =SUM(Segment_Hist!B5:B12)-IS_Hist!B11 -> 0 | C36: =SUM(Segment_Hist!C5:C12)-IS_Hist!C11 -> 0 | D36: =SUM(Segment_Hist!D5:D12)-IS_Hist!D11 -> 0 | E36: =SUM(Segment_Hist!E5:E12)-IS_Hist!E11 -> 0 | G36: =IF(AND(ABS(N(B36))<=1,ABS(N(C36))<=1,ABS(N(D36))<=1,ABS(N(E36))<=1),"PASS","FAIL") -> PASS
A37: CF: Efectivo inicial = efectivo final del año anterior (FY23-FY25) | C37: =CF_Hist!C86-CF_Hist!B87 -> 0 | D37: =CF_Hist!D86-CF_Hist!C87 -> 0 | E37: =CF_Hist!E86-CF_Hist!D87 -> 0 | G37: =IF(AND(ABS(N(C37))<=1,ABS(N(D37))<=1,ABS(N(E37))<=1),"PASS","FAIL") -> PASS

Sheet USD_Presentation
A1: EPM Grupo - Capa de presentacion en USD (memo; COP es la moneda nativa de reporte)
A2: Tasas TRM de cierre implicitas: Notas 22/23 - bono internacional EPM USD 2019/07/18, notional fijo USD 1,000mm, revaluado a TRM de cierre cada periodo (valor nominal COP / 1,000). Confirmadas contra TRM Banco de la Republica publicada para cada fecha de cierre.
A4: Metrica | B4: FY2022A | C4: FY2023A | D4: FY2024A | E4: FY2025A
A5: TRM de cierre (COP/USD) | B5: 4810.2 | C5: 3822.05 | D5: 4409.15 | E5: 3757.08
A7: Total ingresos (USD mm) | B7: =IS_Hist!B11/B5 -> 6698.7795 | C7: =IS_Hist!C11/C5 -> 9821.095 | D7: =IS_Hist!D11/D5 -> 9409.5032 | E7: =IS_Hist!E11/E5 -> 10795.942
A8: Resultado del periodo antes de impuestos (USD mm) | B8: =IS_Hist!B21/B5 -> 1206.48 | C8: =IS_Hist!C21/C5 -> 1308.8136 | D8: =IS_Hist!D21/D5 -> 1400.7051 | E8: =IS_Hist!E21/E5 -> 2108.1478
A9: Resultado neto del periodo y mov. regulatorio (USD mm) | B9: =IS_Hist!B26/B5 -> 857.65685 | C9: =IS_Hist!C26/C5 -> 931.94647 | D9: =IS_Hist!D26/D5 -> 1112.5521 | E9: =IS_Hist!E26/E5 -> 1420.5002
A10: Total activo y saldos debito regulatorios (USD mm) | B10: =BS_Hist!B34/B5 -> 15712.102 | C10: =BS_Hist!C34/C5 -> 20207.968 | D10: =BS_Hist!D34/D5 -> 18924.104 | E10: =BS_Hist!E34/E5 -> 23217.507
A11: Total pasivo y saldos credito regulatorios (USD mm) | B11: =BS_Hist!B74/B5 -> 9270.1942 | C11: =BS_Hist!C74/C5 -> 12014.372 | D11: =BS_Hist!D74/D5 -> 11185.731 | E11: =BS_Hist!E74/E5 -> 13451.958
A12: Total patrimonio (USD mm) | B12: =BS_Hist!B46/B5 -> 6441.908 | C12: =BS_Hist!C46/C5 -> 8193.5961 | D12: =BS_Hist!D46/D5 -> 7738.3727 | E12: =BS_Hist!E46/E5 -> 9765.549
A14: Nota: capa memo, informativa. No sustituye los EEFF nativos en COP (BS_Hist/IS_Hist/CF_Hist), que son la fuente auditada. TRM verificadas de forma cruzada contra el valor COP del bono internacional USD 1,000mm de EPM en Notas 22 (FY2023/24) y 24 (FY2025).

Sheet Sources_Audited
A1: Registro de fuentes auditadas - EPM Grupo, EEFF consolidados (portal inversionistas epm.com.co)
A3: Columna del modelo | B3: Informe fuente | C3: Archivo (copia local del mantenedor) | D3: Paginas clave (BS/IS/CF/Segmentos, PDF interno) | E3: Notas
A4: FY2022A | B4: FY2023 EEFF consolidados, comparativo 2022 | C4: EPM_EEFF-Consolidados-Notas-InformeAuditor_FY2023_al-31-12-2023.pdf | D4: BS p.8-9 / IS p.10 / SCE p.11 / CF p.12 / Segmentos Nota 46.1 (comparativo) | E4: FY2022 tomado como comparativo dentro del informe FY2023 (primera cifra auditada disponible para 2022 en este set de fuentes); auditor Deloitte & Touche S.A.S. (dictamen 27-mar-2023 para 2022).
A5: FY2023A | B5: FY2023 EEFF consolidados, año propio | C5: EPM_EEFF-Consolidados-Notas-InformeAuditor_FY2023_al-31-12-2023.pdf | D5: BS p.8-9 / IS p.10 / SCE p.11 / CF p.12 / Segmentos Nota 46.1 | E5: Auditor Deloitte & Touche S.A.S., dictamen 20-mar-2024, opinion sin salvedades.
A6: FY2024A | B6: FY2024 EEFF consolidados, año propio | C6: EPM_EEFF-Consolidados-Notas-InformeAuditor_FY2024_al-31-12-2024.pdf | D6: BS p.8-9 / IS p.10 / SCE p.11 / CF p.12 / Segmentos Nota 46.1 | E6: Auditor Ernst & Young Audit S.A.S.
A7: FY2025A | B7: FY2025 EEFF consolidados, año propio | C7: EPM_EEFF-Consolidados-Notas-InformeAuditor_FY2025_al-31-12-2025.pdf | D7: BS p.8-9 / IS p.10 / SCE p.11 / CF p.12 / Segmentos Nota 47.1 | E7: Auditor Ernst & Young Audit S.A.S., certificacion firmada 17-mar-2026.
A9: Politica de sourcing por columna: cada columna anual toma la cifra "de año propio" (own-year) del informe donde ese año fue el cierre corriente, no la cifra comparativa re-expresada en un informe posterior. Se detectaron reexpresiones/reclasificaciones entre informes consecutivos para el mismo año (ej. FY2023 en el informe FY2023 vs FY2023 comparativo en el informe FY2024: Total activo 77,097,982 vs 76,801,520; Deudores comerciales corriente 8,463,392 vs 8,166,930; Total pasivo 45,878,166 vs 45,745,796). No se investigo la causa de la reexpresion en esta pasada — riesgo documentado, no resuelto.
A10: Politica FX: COP es la moneda nativa de los EEFF (NCIF/IFRS Colombia). Capa USD (hoja USD_Presentation) usa TRM de cierre implicita en la revaluacion del bono internacional USD 1,000mm de EPM (Notas 22/23/24 segun informe): FY2022=4,810.20 FY2023=3,822.05 FY2024=4,409.15 FY2025=3,757.08 COP/USD. Es capa memo informativa, no sustituye los estados nativos.
A11: Nota_ segmentos: cobertura completa FY2022-FY2025 (ingresos de clientes externos por 8 segmentos operativos, Nota 46.1/47.1). Adiciones de activos no corrientes por segmento solo capturadas para FY2025 en esta pasada (gap documentado en el reporte interno (no publicado)).
A12: Fuentes descargadas y verificadas (pdftotext/pdfinfo) según la copia local del mantenedor - URLs exactas del portal epm.com.co/inversionistas alli documentadas.

Sheet Claude Code Log
A1: Turn # | B1: Date | C1: User Request | D1: Action Taken | E1: Details | F1: Outcome
A2: 1 | B2: 46324.359 | C2: Prepare a public model copy | D2: Remove local paths and private build references; preserve financial formulas and inputs | E2: Agent run with MOG as the tool, checked by guard v1. The guard measured every sheet before and after the run. Changed: Change_Log: 1 cell written, at B7; Sources_Audited: 3 cells written, at C3, A11, A12. Agent: OpenFinmods export | F2: Compare against source and review public copy
