Workbook

Sheet 00_Cover
A1: Banco de Occidente S.A. — Institutional Financial Model
A2: Banking | USD millions | As of 2026-07-15
A4: Model field | B4: Value
A5: Ticker / identifier | B5: BVC: OCCIDENTE
A6: Model archetype | B6: Financial institution / residual income
A7: Decision readiness | B7: Source-backed audited history (FY2023A-FY2025A); consolidated 5yr forecast driver-built; granular bank-schedule forecast PARTIAL (documented gap)
A8: Reporting currency | B8: COP
A9: Model currency | B9: USD millions
A10: Market-data date | B10: Not applicable
A11: Current market price | B11: Not available
A12: Primary source | B12: https://portalpublico.bancodeoccidente.com.co (guest portal, 3 audited consolidated FS PDFs FY2023-FY2025; see Sources_Audited)
A13: Key limitation | B13: Full FY2023A-FY2025A audited consolidated statements (BS/IS/OCI/CF) now loaded as published constants with a 27-check tie-out layer (Checks_TieOut, all PASS). Bank sector schedules (cartera, fondeo, NIM, calidad, capital) are historical-only for FY2023-25; forward projection of those schedules is a documented next-phase gap. Capital_Adequacy is disclosed at the Matriz-individual level per the bank's own note 4.6 (not consolidated).
A15: Institutional-grade means auditable sources, explicit assumptions, formula-driven forecasts, valuation, sensitivities, checks and governance. It does not mean that missing private-company disclosures have been invented.

Sheet Sources
A1: Sources and data lineage
A2: Every hardcode is mapped to a source, date, currency and transformation.
A4: Source ID | B4: Use | C4: URL / reference | D4: As of | E4: Source currency | F4: Transformation | G4: Limitation | H4: Status
A5: S1 | B5: Historical financials | C5: https://portalpublico.bancodeoccidente.com.co/documents/d/guest/informe-gestion-bdo-2025 | D5: Latest annual filing/results | E5: COP | F5: Converted at current snapshot FX (COP to USD = 0.00031032) | G5: SUPERSEDED — replaced by S5-S7 (full audited FY2023-25 EEFF); FY2025 net income/ROE/assets/equity are no longer inferred, see BS_Hist/IS_Hist | H5: Superseded — see S5-S7
A6: S2 | B6: Market price | C6: Not applicable | D6: 2026-07-15 | E6: N/A | F6: Dated market input; not a historical financial source | G6: Market prices move after the as-of date | H6: Not loaded
A7: S3 | B7: FX snapshot | C7: Yahoo Finance COP/USD chart snapshot | D7: 2026-07-15 | E7: COP | F7: COP per USD, inverted | G7: Current FX used across historical years for comparability; not historical spot | H7: Loaded
A8: S4 | B8: Forecast assumptions | C8: Model Assumptions sheet | D8: 2026-07-15 | E8: USD | F8: User-editable scenario inputs | G8: Forecasts are estimates, not reported facts | H8: Model input
A9: S5 | B9: Historical financials (BS/IS/OCI/CF, FY2023A) | C9: https://portalpublico.bancodeoccidente.com.co/documents/d/guest/estado-financiero-consolidado-a-diciembre-31-de-2023 | D9: FY2023 audited consolidated FS (dictamen KPMG) | E9: COP | F9: Entered as published constants in BS_Hist/IS_Hist/CI_Hist/CF_Hist; no conversion at native layer | G9: None — full audited statement set with dictamen | H9: Loaded, tie-outs pass
A10: S6 | B10: Historical financials (BS/IS/OCI/CF, FY2024A + FY2023A comparative) | C10: https://portalpublico.bancodeoccidente.com.co/documents/d/guest/estado-financiero-consolidado-a-diciembre-31-de-2024 | D10: FY2024 audited consolidated FS (dictamen KPMG) | E10: COP | F10: Entered as published constants; FY2023 comparative column cross-checked against S5 | G10: None | H10: Loaded, tie-outs pass
A11: S7 | B11: Historical financials (BS/IS/OCI/CF, FY2025A + FY2024A comparative) | C11: https://portalpublico.bancodeoccidente.com.co/documents/d/guest/dic_25_con_eeff_bocc1 | D11: FY2025 audited consolidated FS (dictamen KPMG) | E11: COP | F11: Entered as published constants; FY2024 comparative column cross-checked against S6 | G11: None | H11: Loaded, tie-outs pass
A12: S8 | B12: USD presentation-layer FX (TRM close, FY2023A/24A/25A) | C12: actualicese.com TRM year-end articles (citing official Banrep/Superfinanciera TRM) | D12: 2026-07-21 (fetched this pass) | E12: COP | F12: COP per USD at each fiscal year-end close; used only to convert Historical/Forecast/Valuation to USD | G12: Aggregator source, not fetched directly from Banrep's series API | H12: Loaded

Sheet Historical
A1: Historical financials
A2: USD millions, converted from audited COP-millions statements (BS_Hist/IS_Hist) at each fiscal-year-end TRM close (Sources_Audited). FY2021A/FY2022A left blank — outside this elevation pass's audited-source batch (FY2023-25 dictamen PDFs only).
A4: Metric | B4: 2021A | C4: 2022A | D4: 2023A | E4: 2024A | F4: 2025A | G4: Source tag / note | H4: Quality
A5: Assets | D5: =BS_Hist!B29/Sources_Audited!$B$16 -> 17948.95 | E5: =BS_Hist!C29/Sources_Audited!$B$17 -> 17781.246 | F5: =BS_Hist!D29/Sources_Audited!$B$18 -> 23465.906 | G5: BS_Hist (COP mm) / TRM close, Sources_Audited | H5: Source-backed (audited, converted)
A6: Liabilities | D6: =BS_Hist!B47/Sources_Audited!$B$16 -> 16460.722 | E6: =BS_Hist!C47/Sources_Audited!$B$17 -> 16423.662 | F6: =BS_Hist!D47/Sources_Audited!$B$18 -> 21800.09 | G6: BS_Hist/IS_Hist (COP mm) / TRM close, Sources_Audited | H6: Source-backed (audited, converted)
A7: Equity | D7: =BS_Hist!B54/Sources_Audited!$B$16 -> 1478.5484 | E7: =BS_Hist!C54/Sources_Audited!$B$17 -> 1347.5402 | F7: =BS_Hist!D54/Sources_Audited!$B$18 -> 1653.0449 | G7: BS_Hist/IS_Hist (COP mm) / TRM close, Sources_Audited | H7: Source-backed (audited, converted)
A8: Net income | D8: =IS_Hist!B43/Sources_Audited!$B$16 -> 123.89869 | E8: =IS_Hist!C43/Sources_Audited!$B$17 -> 107.39734 | F8: =IS_Hist!D43/Sources_Audited!$B$18 -> 152.99541 | G8: BS_Hist/IS_Hist (COP mm) / TRM close, Sources_Audited | H8: Source-backed (audited, converted)
A9: Loans | D9: =BS_Hist!B16/Sources_Audited!$B$16 -> 12950.912 | E9: =BS_Hist!C16/Sources_Audited!$B$17 -> 12267.925 | F9: =BS_Hist!D16/Sources_Audited!$B$18 -> 15102.088 | G9: BS_Hist/IS_Hist (COP mm) / TRM close, Sources_Audited | H9: Source-backed (audited, converted)
A10: Deposits | D10: =BS_Hist!B33/Sources_Audited!$B$16 -> 12866.324 | E10: =BS_Hist!C33/Sources_Audited!$B$17 -> 12155.137 | F10: =BS_Hist!D33/Sources_Audited!$B$18 -> 15758.827 | G10: BS_Hist/IS_Hist (COP mm) / TRM close, Sources_Audited | H10: Source-backed (audited, converted)
A11: Interest income | D11: =IS_Hist!B5/Sources_Audited!$B$16 -> 2023.1965 | E11: =IS_Hist!C5/Sources_Audited!$B$17 -> 1717.8143 | F11: =IS_Hist!D5/Sources_Audited!$B$18 -> 1886.7176 | G11: BS_Hist/IS_Hist (COP mm) / TRM close, Sources_Audited | H11: Source-backed (audited, converted)
A12: Interest expense | D12: =IS_Hist!B13/Sources_Audited!$B$16 -> 1437.8025 | E12: =IS_Hist!C13/Sources_Audited!$B$17 -> 1189.7851 | F12: =IS_Hist!D13/Sources_Audited!$B$18 -> 1274.2257 | G12: BS_Hist/IS_Hist (COP mm) / TRM close, Sources_Audited | H12: Source-backed (audited, converted)
A13: Cash | D13: =BS_Hist!B6/Sources_Audited!$B$16 -> 1300.0623 | E13: =BS_Hist!C6/Sources_Audited!$B$17 -> 1049.8441 | F13: =BS_Hist!D6/Sources_Audited!$B$18 -> 1600.8523 | G13: BS_Hist/IS_Hist (COP mm) / TRM close, Sources_Audited | H13: Source-backed (audited, converted)
A14: Diluted shares (mm) | G14: Not disclosed at consolidated level (no public float / share count in EEFF) | H14: Missing / not inferred

Sheet Assumptions
A1: Assumptions and scenarios
A2: Blue-font cells are user inputs. Scenario selector: 1 = Base, 2 = Bull, 3 = Bear.
A3: Scenario selector | B3: 1
A4: Metric | B4: Bear | C4: Base | D4: Bull | E4: Active | F4: Rationale / source
A5: Asset growth | B5: 0.05 | C5: 0.1 | D5: 0.14 | E5: =CHOOSE($B$3,C5,D5,B5) -> 0.1 | F5: Reported total-asset growth FY23->24 = 14.28%, FY24->25 = 12.46% (BS_Hist, Sources_Audited); Base moderated to 10% from the 2yr avg (13.4%) for macro normalization; Bear/Bull bracket around it.
A6: Target ROE | B6: 0.06 | C6: 0.088 | D6: 0.11 | E6: =CHOOSE($B$3,C6,D6,B6) -> 0.088 | F6: Reported parent ROE (Intereses controlantes NI / avg Patrimonio de los intereses controlantes): FY24 8.17%, FY25 9.46% (BS_Hist/IS_Hist). Base = 2yr avg 8.8%.
A7: Dividend payout | B7: 0.45 | C7: 0.35 | D7: 0.25 | E7: =CHOOSE($B$3,C7,D7,B7) -> 0.35 | F7: Reported dividend payout (Dividendos pagados intereses controlantes / Resultado atribuible a intereses controlantes, same FY, CF_Hist/IS_Hist): FY23 39.6%, FY24 34.2%, FY25 30.2%, avg 34.7% — matches prior Base(35%) assumption; kept.
A8: Cost of equity | B8: 0.14 | C8: 0.12 | D8: 0.105 | E8: =CHOOSE($B$3,C8,D8,B8) -> 0.12 | F8: USD investor required return — modeling policy input (not a disclosed FS figure); unchanged pending a formal COE build (risk-free + country + equity risk premium).
A9: Terminal growth | B9: 0.02 | C9: 0.03 | D9: 0.04 | E9: =CHOOSE($B$3,C9,D9,B9) -> 0.03 | F9: Long-run nominal USD growth — modeling policy input; unchanged pending macro-linked terminal growth build.

Sheet Forecast
A1: Forecast model
A2: Formula-driven five-year projection in USD millions, anchored to FY2025A reported figures (Historical!F5/F7/F8, sourced from BS_Hist/IS_Hist via TRM close).
A4: Metric | B4: 2025A | C4: 2026E | D4: 2027E | E4: 2028E | F4: 2029E | G4: 2030E
A5: Assets | B5: =Historical!F5 -> 23465.906 | C5: =B5*(1+Assumptions!$E$5) -> 25812.496 | D5: =C5*(1+Assumptions!$E$5) -> 28393.746 | E5: =D5*(1+Assumptions!$E$5) -> 31233.12 | F5: =E5*(1+Assumptions!$E$5) -> 34356.433 | G5: =F5*(1+Assumptions!$E$5) -> 37792.076
A6: Asset growth | C6: =IF(B5<>0,C5/B5-1,0) -> 0.1 | D6: =IF(C5<>0,D5/C5-1,0) -> 0.1 | E6: =IF(D5<>0,E5/D5-1,0) -> 0.1 | F6: =IF(E5<>0,F5/E5-1,0) -> 0.1 | G6: =IF(F5<>0,G5/F5-1,0) -> 0.1
A7: Equity | B7: =Historical!F7 -> 1653.0449 | C7: =B12 -> 1653.0449 | D7: =C12 -> 1747.5991 | E7: =D12 -> 1847.5618 | F7: =E12 -> 1953.2423 | G7: =F12 -> 2064.9677
A8: Equity / assets | B8: 0.072916667 | C8: =IF(C5<>0,C7/C5,0) -> 0.06404049 | D8: =IF(D5<>0,D7/D5,0) -> 0.061548733 | E8: =IF(E5<>0,E7/E5,0) -> 0.059153928 | F8: =IF(F5<>0,F7/F5,0) -> 0.056852302 | G8: =IF(G5<>0,G7/G5,0) -> 0.054640231
A9: Net income | B9: =Historical!F8 -> 152.99541 | C9: =C7*Assumptions!$E$6 -> 145.46795 | D9: =D7*Assumptions!$E$6 -> 153.78872 | E9: =E7*Assumptions!$E$6 -> 162.58543 | F9: =F7*Assumptions!$E$6 -> 171.88532 | G9: =G7*Assumptions!$E$6 -> 181.71716
A10: ROE | B10: =IF(B7<>0,B9/B7,0) -> 0.092553693 | C10: =IF(C7<>0,C9/C7,0) -> 0.088 | D10: =IF(D7<>0,D9/D7,0) -> 0.088 | E10: =IF(E7<>0,E9/E7,0) -> 0.088 | F10: =IF(F7<>0,F9/F7,0) -> 0.088 | G10: =IF(G7<>0,G9/G7,0) -> 0.088
A11: Dividends | C11: =C9*Assumptions!$E$7 -> 50.913783 | D11: =D9*Assumptions!$E$7 -> 53.826052 | E11: =E9*Assumptions!$E$7 -> 56.904902 | F11: =F9*Assumptions!$E$7 -> 60.159862 | G11: =G9*Assumptions!$E$7 -> 63.601007
A12: Ending book value | B12: =B7 -> 1653.0449 | C12: =C7+C9-C11 -> 1747.5991 | D12: =D7+D9-D11 -> 1847.5618 | E12: =E7+E9-E11 -> 1953.2423 | F12: =F7+F9-F11 -> 2064.9677 | G12: =G7+G9-G11 -> 2183.0839

Sheet Valuation
A1: Residual-income valuation
A2: Valuation is formula-driven and scenario-sensitive; private-company outputs are enterprise-value ranges only.
A4: Metric | B4: Year 1 | C4: Year 2 | D4: Year 3 | E4: Year 4 | F4: Year 5 | G4: Total / output
A5: Beginning book value | B5: =Forecast!C7 -> 1653.0449 | C5: =Forecast!D7 -> 1747.5991 | D5: =Forecast!E7 -> 1847.5618 | E5: =Forecast!F7 -> 1953.2423 | F5: =Forecast!G7 -> 2064.9677
A6: Residual income | B6: =B5*(Forecast!C10-Assumptions!$E$8) -> -52.897437 | C6: =C5*(Forecast!D10-Assumptions!$E$8) -> -55.923171 | D6: =D5*(Forecast!E10-Assumptions!$E$8) -> -59.121976 | E6: =E5*(Forecast!F10-Assumptions!$E$8) -> -62.503753 | F6: =F5*(Forecast!G10-Assumptions!$E$8) -> -66.078968
A7: Discount factor | B7: =1/(1+Assumptions!$E$8)^1 -> 0.89285714 | C7: =1/(1+Assumptions!$E$8)^2 -> 0.79719388 | D7: =1/(1+Assumptions!$E$8)^3 -> 0.71178025 | E7: =1/(1+Assumptions!$E$8)^4 -> 0.63551808 | F7: =1/(1+Assumptions!$E$8)^5 -> 0.56742686
A8: PV residual income | B8: =B6*B7 -> -47.229855 | C8: =C6*C7 -> -44.581609 | D8: =D6*D7 -> -42.081855 | E8: =E6*E7 -> -39.722265 | F8: =F6*F7 -> -37.494981
A10: Output | B10: Value
A11: Current book value | B11: =Forecast!B7 -> 1653.0449
A12: PV explicit residual income | B12: =SUM(B8:F8) -> -211.11057
A13: Terminal residual income | B13: =F6*(1+Assumptions!$E$9) -> -68.061337
A14: PV terminal value | B14: =IF(Assumptions!$E$8>Assumptions!$E$9,B13/(Assumptions!$E$8-Assumptions!$E$9)*F7,0) -> -429.10923
A15: Implied equity value | B15: =B11+B12+B14 -> 1012.8251
A16: Diluted shares (mm) | B16: 0
A17: Implied value / share | B17: =IF(B16>0,B15/B16,0) -> 0
A18: Current market price

Sheet Sensitivity
A1: Valuation sensitivity
A2: Equity value sensitivity to cost of equity and terminal growth.
A4: CoE / g | B4: 0.1 | C4: 0.11 | D4: 0.12 | E4: 0.13 | F4: 0.14
A5: 0.01 | B5: =Forecast!$B$7+SUMPRODUCT(Valuation!$B$6:$F$6,1/(1+B$4)^{1,2,3,4,5})+IF(B$4>$A5,Valuation!$F$6*(1+$A5)/(B$4-$A5)/(1+B$4)^5,0) -> 970.1529 | C5: =Forecast!$B$7+SUMPRODUCT(Valuation!$B$6:$F$6,1/(1+C$4)^{1,2,3,4,5})+IF(C$4>$A5,Valuation!$F$6*(1+$A5)/(C$4-$A5)/(1+C$4)^5,0) -> 1040.3158 | D5: =Forecast!$B$7+SUMPRODUCT(Valuation!$B$6:$F$6,1/(1+D$4)^{1,2,3,4,5})+IF(D$4>$A5,Valuation!$F$6*(1+$A5)/(D$4-$A5)/(1+D$4)^5,0) -> 1097.6623 | E5: =Forecast!$B$7+SUMPRODUCT(Valuation!$B$6:$F$6,1/(1+E$4)^{1,2,3,4,5})+IF(E$4>$A5,Valuation!$F$6*(1+$A5)/(E$4-$A5)/(1+E$4)^5,0) -> 1145.3989 | F5: =Forecast!$B$7+SUMPRODUCT(Valuation!$B$6:$F$6,1/(1+F$4)^{1,2,3,4,5})+IF(F$4>$A5,Valuation!$F$6*(1+$A5)/(F$4-$A5)/(1+F$4)^5,0) -> 1185.7454
A6: 0.02 | B6: =Forecast!$B$7+SUMPRODUCT(Valuation!$B$6:$F$6,1/(1+B$4)^{1,2,3,4,5})+IF(B$4>$A6,Valuation!$F$6*(1+$A6)/(B$4-$A6)/(1+B$4)^5,0) -> 907.46842 | C6: =Forecast!$B$7+SUMPRODUCT(Valuation!$B$6:$F$6,1/(1+C$4)^{1,2,3,4,5})+IF(C$4>$A6,Valuation!$F$6*(1+$A6)/(C$4-$A6)/(1+C$4)^5,0) -> 991.95107 | D6: =Forecast!$B$7+SUMPRODUCT(Valuation!$B$6:$F$6,1/(1+D$4)^{1,2,3,4,5})+IF(D$4>$A6,Valuation!$F$6*(1+$A6)/(D$4-$A6)/(1+D$4)^5,0) -> 1059.4855 | E6: =Forecast!$B$7+SUMPRODUCT(Valuation!$B$6:$F$6,1/(1+E$4)^{1,2,3,4,5})+IF(E$4>$A6,Valuation!$F$6*(1+$A6)/(E$4-$A6)/(1+E$4)^5,0) -> 1114.6962 | F6: =Forecast!$B$7+SUMPRODUCT(Valuation!$B$6:$F$6,1/(1+F$4)^{1,2,3,4,5})+IF(F$4>$A6,Valuation!$F$6*(1+$A6)/(F$4-$A6)/(1+F$4)^5,0) -> 1160.6659
A7: 0.03 | B7: =Forecast!$B$7+SUMPRODUCT(Valuation!$B$6:$F$6,1/(1+B$4)^{1,2,3,4,5})+IF(B$4>$A7,Valuation!$F$6*(1+$A7)/(B$4-$A7)/(1+B$4)^5,0) -> 826.87409 | C7: =Forecast!$B$7+SUMPRODUCT(Valuation!$B$6:$F$6,1/(1+C$4)^{1,2,3,4,5})+IF(C$4>$A7,Valuation!$F$6*(1+$A7)/(C$4-$A7)/(1+C$4)^5,0) -> 931.49515 | D7: =Forecast!$B$7+SUMPRODUCT(Valuation!$B$6:$F$6,1/(1+D$4)^{1,2,3,4,5})+IF(D$4>$A7,Valuation!$F$6*(1+$A7)/(D$4-$A7)/(1+D$4)^5,0) -> 1012.8251 | E7: =Forecast!$B$7+SUMPRODUCT(Valuation!$B$6:$F$6,1/(1+E$4)^{1,2,3,4,5})+IF(E$4>$A7,Valuation!$F$6*(1+$A7)/(E$4-$A7)/(1+E$4)^5,0) -> 1077.8531 | F7: =Forecast!$B$7+SUMPRODUCT(Valuation!$B$6:$F$6,1/(1+F$4)^{1,2,3,4,5})+IF(F$4>$A7,Valuation!$F$6*(1+$A7)/(F$4-$A7)/(1+F$4)^5,0) -> 1131.0265
A8: 0.04 | B8: =Forecast!$B$7+SUMPRODUCT(Valuation!$B$6:$F$6,1/(1+B$4)^{1,2,3,4,5})+IF(B$4>$A8,Valuation!$F$6*(1+$A8)/(B$4-$A8)/(1+B$4)^5,0) -> 719.41499 | C8: =Forecast!$B$7+SUMPRODUCT(Valuation!$B$6:$F$6,1/(1+C$4)^{1,2,3,4,5})+IF(C$4>$A8,Valuation!$F$6*(1+$A8)/(C$4-$A8)/(1+C$4)^5,0) -> 853.7661 | D8: =Forecast!$B$7+SUMPRODUCT(Valuation!$B$6:$F$6,1/(1+D$4)^{1,2,3,4,5})+IF(D$4>$A8,Valuation!$F$6*(1+$A8)/(D$4-$A8)/(1+D$4)^5,0) -> 954.4996 | E8: =Forecast!$B$7+SUMPRODUCT(Valuation!$B$6:$F$6,1/(1+E$4)^{1,2,3,4,5})+IF(E$4>$A8,Valuation!$F$6*(1+$A8)/(E$4-$A8)/(1+E$4)^5,0) -> 1032.8226 | F8: =Forecast!$B$7+SUMPRODUCT(Valuation!$B$6:$F$6,1/(1+F$4)^{1,2,3,4,5})+IF(F$4>$A8,Valuation!$F$6*(1+$A8)/(F$4-$A8)/(1+F$4)^5,0) -> 1095.4592
A9: 0.05 | B9: =Forecast!$B$7+SUMPRODUCT(Valuation!$B$6:$F$6,1/(1+B$4)^{1,2,3,4,5})+IF(B$4>$A9,Valuation!$F$6*(1+$A9)/(B$4-$A9)/(1+B$4)^5,0) -> 568.97224 | C9: =Forecast!$B$7+SUMPRODUCT(Valuation!$B$6:$F$6,1/(1+C$4)^{1,2,3,4,5})+IF(C$4>$A9,Valuation!$F$6*(1+$A9)/(C$4-$A9)/(1+C$4)^5,0) -> 750.12738 | D9: =Forecast!$B$7+SUMPRODUCT(Valuation!$B$6:$F$6,1/(1+D$4)^{1,2,3,4,5})+IF(D$4>$A9,Valuation!$F$6*(1+$A9)/(D$4-$A9)/(1+D$4)^5,0) -> 879.50964 | E9: =Forecast!$B$7+SUMPRODUCT(Valuation!$B$6:$F$6,1/(1+E$4)^{1,2,3,4,5})+IF(E$4>$A9,Valuation!$F$6*(1+$A9)/(E$4-$A9)/(1+E$4)^5,0) -> 976.53441 | F9: =Forecast!$B$7+SUMPRODUCT(Valuation!$B$6:$F$6,1/(1+F$4)^{1,2,3,4,5})+IF(F$4>$A9,Valuation!$F$6*(1+$A9)/(F$4-$A9)/(1+F$4)^5,0) -> 1051.988

Sheet Checks
A1: Model checks
A2: All critical checks should read PASS before decision use.
A4: Check | B4: Result | C4: Severity | D4: Interpretation
A5: Forecast assets non-negative | B5: =IF(MIN(Forecast!C5:G5)>=0,"PASS","FAIL") -> PASS | C5: Critical | D5: No negative asset balance
A6: Ending equity non-negative | B6: =IF(MIN(Forecast!C12:G12)>=0,"PASS","FAIL") -> PASS | C6: Critical | D6: Capital remains positive
A7: ROE within model bounds | B7: =IF(AND(MIN(Forecast!C10:G10)>-0.5,MAX(Forecast!C10:G10)<0.5),"PASS","FAIL") -> PASS | C7: Critical | D7: Screens extreme profitability
A8: Discount rate exceeds terminal growth | B8: =IF(Assumptions!E8>Assumptions!E9,"PASS","FAIL") -> PASS | C8: Critical | D8: Required for convergent residual-income terminal value
A9: Historical source coverage (3-statement, FY2023A-FY2025A) | B9: PASS | C9: Critical | D9: BS/IS/OCI/CF fully sourced to audited dictamen PDFs (Sources_Audited); see Checks_TieOut for cross-statement tie-outs
A11: Overall gate | B11: =IF(COUNTIF(B5:B9,"FAIL")=0,IF(COUNTIF(B5:B9,"LIMITED")=0,"PASS","PASS WITH LIMITATIONS"),"FAIL") -> PASS
A12: Decision use | B12: Source-backed audited history (FY2023A-FY2025A, 27/27 tie-outs PASS); driver-built 5yr consolidated forecast; granular bank-schedule forecast PARTIAL
A13: Sector schedule + granular forecast scope | B13: PARTIAL | C13: Readiness | D13: Loan_Book/Deposits_Funding/NIM_Build/Credit_Quality/Capital_Adequacy are historical-only (audited, 3yr); the consolidated 5yr Forecast is driver-built (Assumptions Base/Bull/Bear) and anchored to real FY2025A, but projecting the granular bank schedules forward is a documented next-phase gap

Sheet Sector_KPIs
A1: Sector KPI framework
A2: Sector drivers sourced from Loan_Book / Deposits_Funding / NIM_Build / Credit_Quality / Capital_Adequacy (audited FY2023A-FY2025A, COP mm). Historical column shows FY2025A; Forecast column left input-ready pending a full driver-built bank projection (see Checks!B13 / build report gap note).
A4: KPI | B4: Historical | C4: Forecast | D4: Status / source requirement
A5: Loan growth | B5: =Loan_Book!D22 -> 0.048966094 | C5: Input-ready — full loan-book projection (segment mix + growth) is a next-phase build | D5: Input-ready; populate from issuer operating disclosures
A6: Deposit growth | B6: =Deposits_Funding!D22 -> 0.10473873 | C6: Input-ready — full deposit/funding projection is a next-phase build | D6: Input-ready; populate from issuer operating disclosures
A7: Net interest margin | B7: =NIM_Build!D33 -> 0.031350151 | C7: Input-ready — NIM projection requires an asset/liability repricing build, next phase | D7: Input-ready; populate from issuer operating disclosures
A8: Cost of risk | B8: =Credit_Quality!D14 -> 0.021355256 | C8: Input-ready — cost-of-risk projection requires a vintage/stage roll-forward, next phase | D8: Input-ready; populate from issuer operating disclosures
A9: NPL ratio | B9: =Credit_Quality!D20 -> 0.037911638 | C9: Input-ready — NPL projection requires a stage-migration build, next phase | D9: Input-ready; populate from issuer operating disclosures
A10: Coverage ratio | B10: =Credit_Quality!D8 -> 0.039396628 | C10: Input-ready — coverage projection follows from NPL + cost-of-risk build, next phase | D10: Input-ready; populate from issuer operating disclosures
A11: CET1 / capital ratio | B11: =Capital_Adequacy!D28 -> 0.129 | C11: Input-ready — capital-ratio projection requires an APNR/RWA build tied to the balance-sheet forecast, next phase | D11: Input-ready; populate from issuer operating disclosures
A12: Liquidity ratio | B12: N/A — liquidity coverage ratio not disclosed in the consolidated audited FS notes reviewed | C12: N/A — no disclosed base to project | D12: Input-ready; populate from issuer operating disclosures
A13: ROE | B13: =Historical!F8/AVERAGE(Historical!E7,Historical!F7) -> 0.10197705 | C13: =Forecast!G10 -> 0.088 | D13: Input-ready; populate from issuer operating disclosures
A14: Tangible book value per share | B14: N/A — no disclosed diluted share count (private float; Cover!B11 = Not available) | C14: N/A — no disclosed base to project | D14: Input-ready; populate from issuer operating disclosures

Sheet Change_Log
A1: Change log and governance
A2: Version history and model-owner review record.
A4: Date | B4: Version | C4: Author | D4: Change | E4: Evidence | F4: Reviewer status
A5: 2026-07-15 | B5: 1.0 | C5: Codex | D5: Initial institutional model framework and source pack | E5: https://portalpublico.bancodeoccidente.com.co/documents/d/guest/informe-gestion-bdo-2025 | F5: Builder-verified
A6: 2026-07-15 | B6: 1.0 | C6: Codex | D6: Formula, package and visual QA | E6: Checks sheet and preview artifacts | F6: Pending owner investment judgment
A7: 46224 | B7: 2 | C7: Claude (run 41538014) | D7: Elevation to statement-grade IG: replaced 3-cell algebraically-inferred FY2025 history with full audited FY2023A-FY2025A consolidated BS/IS/OCI/CF (BS_Hist/IS_Hist/CI_Hist/CF_Hist, COP mm, published constants); added bank schedules Loan_Book/Deposits_Funding/NIM_Build/Credit_Quality/Capital_Adequacy (historical, 3yr); added Checks_TieOut (27 checks, all PASS) and Sources_Audited (page-cited); rewired Historical (USD mm) and Forecast base year off real data via TRM close; Sector_KPIs populated from audited figures; Assumptions asset-growth/ROE re-anchored to reported trend. Granular bank-schedule forward projection left PARTIAL (documented gap). Built via Mog SDK only. Root workbook untouched; saved under the maintainer's archive. | E7: BancoDeOccidente_EEFF-Consolidados-Dictamen_FY2023/2024/2025 PDFs (KPMG dictamen); actualicese.com TRM close citations | F7: Builder-verified — 27/27 Checks_TieOut PASS, 0 error cells post-calculate, unzip -t OK (pending final QA pass)

Sheet BS_Hist
A1: Banco de Occidente S.A. y Subsidiarias — Estado Consolidado de Situación Financiera (auditado)
A2: COP millones. FY2023A-FY2025A. Fte: EEFF consolidados auditados (dictamen KPMG S.A.S.) FY2023/FY2024/FY2025 PDFs, sección Estado Consolidado de Situación Financiera.
A4: Line item | B4: FY2023A | C4: FY2024A | D4: FY2025A
A5: Activos
A6: Efectivo y equivalentes de efectivo | B6: 4968903 | C6: 4628920 | D6: 6014530
A7: Activos financieros a valor razonable con cambios en resultados | B7: 5445835 | C7: 9628213 | D7: 14485963
A8: Inversiones en títulos de deuda (VR resultados) | B8: 3459592 | C8: 8299454 | D8: 11820386
A9: Inversiones en instrumentos de patrimonio (VR resultados) | B9: 709520 | C9: 838051 | D9: 1140604
A10: Instrumentos derivativos de negociación (activo) | B10: 1276723 | C10: 490708 | D10: 1524973
A11: Activos financieros a valor razonable con cambios en ORI | B11: 4597797 | C11: 5888095 | D11: 6850925
A12: Inversiones en títulos de deuda (VR ORI) | B12: 4465686 | C12: 5721126 | D12: 6674681
A13: Inversiones en instrumentos de patrimonio (VR ORI) | B13: 132111 | C13: 166969 | D13: 176244
A14: Activos financieros en títulos de deuda a costo amortizado | B14: 2034558 | C14: 2133673 | D14: 1324900
A15: Instrumentos derivados de cobertura (activo) | C15: 6225 | D15: 48261
A16: Cartera de créditos a costo amortizado (bruta) | B16: 49499035 | C16: 54091123 | D16: 56739754
A17: Cartera comercial y leasing comercial | B17: 34426863 | C17: 37817965 | D17: 39589665
A18: Cartera consumo y leasing consumo | B18: 12462019 | C18: 13176358 | D18: 13286359
A19: Cartera hipotecario y leasing hipotecario | B19: 2610153 | C19: 3096800 | D19: 3863730
A20: Deterioro de cartera de crédito a costo amortizado | B20: -2416920 | C20: -2546964 | D20: -2235355
A21: Cartera de créditos a costo amortizado, neto | B21: 47082115 | C21: 51544159 | D21: 54504399
A22: Otras cuentas por cobrar, neto | B22: 547285 | C22: 634102 | D22: 661508
A23: Activos no corrientes mantenidos para la venta | B23: 3023 | C23: 1324
A24: Inversiones en compañías asociadas y negocios conjuntos | B24: 1800802 | C24: 1953172 | D24: 2099231
A25: Activos tangibles, neto | B25: 654052 | C25: 670246 | D25: 668772
A26: Activos intangibles, neto | B26: 600351 | C26: 657085 | D26: 730940
A27: Activo por impuesto a la ganancia | B27: 853501 | C27: 625406 | D27: 751944
A28: Otros activos | B28: 13562 | C28: 29561 | D28: 21912
A29: Total activos | B29: 68601784 | C29: 78400181 | D29: 88163285
A31: Pasivo
A32: Pasivos financieros a valor razonable - instrumentos derivados | B32: 1058390 | C32: 532716 | D32: 1285816
A33: Depósitos de clientes | B33: 49175732 | C33: 53593823 | D33: 59207172
A34: Cuentas corrientes | B34: 7092625 | C34: 7389155 | D34: 7606030
A35: Cuentas de ahorro | B35: 24153811 | C35: 28221791 | D35: 31112717
A36: Certificados de depósito a término | B36: 17866450 | C36: 17917502 | D36: 20416158
A37: Otros depósitos | B37: 62846 | C37: 65375 | D37: 72267
A38: Obligaciones financieras | B38: 10848602 | C38: 16849639 | D38: 19265710
A39: Fondos interbancarios y overnight | B39: 4403111 | C39: 8636674 | D39: 12281785
A40: Créditos de bancos y otros | B40: 3185957 | C40: 4480586 | D40: 3824902
A41: Bonos y títulos de inversión | B41: 2171345 | C41: 2670197 | D41: 2097440
A42: Obligaciones con entidades de redescuento | B42: 1088189 | C42: 1062182 | D42: 1061583
...

Sheet IS_Hist
A1: Banco de Occidente S.A. y Subsidiarias — Estado Consolidado de Resultados (auditado)
A2: COP millones. Misma base de fuente que BS_Hist.
A4: Line item | B4: FY2023A | C4: FY2024A | D4: FY2025A
A5: Ingresos por intereses y valoración | B5: 7732758 | C5: 7574101 | D5: 7088549
A6: Intereses cartera comercial | B6: 4851231 | C6: 4578841 | D6: 4012015
A7: Intereses cartera consumo | B7: 1921271 | C7: 1975581 | D7: 1908993
A8: Intereses cartera vivienda | B8: 248787 | C8: 311362 | D8: 376457
A9: Ingreso por repos e interbancarios | B9: 192719 | C9: 143703 | D9: 40158
A10: Ingresos por depósitos | B10: 35306 | C10: 34214 | D10: 102648
A11: Ingreso por intereses de otras cuentas por cobrar | B11: 1211 | C11: 6385 | D11: 4443
A12: Intereses y valoración inversiones costo amortizado | B12: 482233 | C12: 524015 | D12: 643835
A13: Gastos por intereses y similares | B13: 5495353 | C13: 5245941 | D13: 4787368
A14: Depósitos - cuentas corrientes | B14: 41408 | C14: 44781 | D14: 50410
A15: Depósitos de ahorro | B15: 2230879 | C15: 2204667 | D15: 1816585
A16: Certificados de depósito a término | B16: 2074357 | C16: 1777487 | D16: 1606372
... A40: Resultado del ejercicio | B40: 479557 | C40: 481047 | D40: 582138
A42: Resultado atribuible a:
A43: Intereses controlantes | B43: 473547 | C43: 473531 | D43: 574816
A44: Intereses no controlantes | B44: 6010 | C44: 7516 | D44: 7322

Sheet CI_Hist
A1: Banco de Occidente S.A. y Subsidiarias — Estado Consolidado de Otros Resultados Integrales (auditado)
A2: COP millones. Misma base de fuente que BS_Hist.
A4: Line item | B4: FY2023A | C4: FY2024A | D4: FY2025A
A5: Resultado del ejercicio | B5: 479557 | C5: 481047 | D5: 582138
A6: Partidas reclasificables a resultados
A7: Diferencia en cambio neta conversión operaciones extranjeras | B7: -38230 | C7: 15084 | D7: -14810
A8: Diferencia en cambio inversiones en subsidiarias en el exterior | B8: -73047 | C8: 63506 | D8: -84487
A9: (Pérdida) utilidad neta no realizada coberturas extranjeras | B9: 73047 | C9: -63506 | D9: 84487
A10: (Pérdida) utilidad valor razonable títulos de deuda ORI | B10: 393581 | C10: -67739 | D10: -56146
A11: Deterioro instrumentos VR-ORI títulos de deuda | B11: 80 | C11: 1457 | D11: 2312
A12: Utilidad método de participación patrimonial (OCI) | B12: 21611 | C12: 14493 | D12: 3067
A13: Impuesto diferido — partidas reclasificables | B13: -139430 | C13: 40545 | D13: 4598
A14: Total partidas reclasificables a resultados | B14: 237612 | C14: 3840 | D14: -60979
A15: Partidas no reclasificables a resultados
A16: Revalorización de propiedades de inversión | B16: -2376 | C16: -199
A17: Utilidad VR instrumentos de patrimonio | B17: 9263 | C17: 34857 | D17: 4015
A18: Utilidad (pérdida) actuarial beneficios definidos | B18: -4810 | C18: 2517 | D18: 57
A19: Impuesto diferido — partidas no reclasificables | B19: 2152 | C19: -6032 | D19: -920
A20: Total partidas no reclasificables a resultados | B20: 4229 | C20: 31143 | D20: 3152
A21: Total otros resultados integrales, neto de impuestos | B21: 241841 | C21: 34983 | D21: -57827
A22: Resultados integrales total del período | B22: 721398 | C22: 516030 | D22: 524310
A24: Resultados integrales atribuibles a:
A25: Intereses controlantes | B25: 714834 | C25: 506633 | D25: 518165
A26: Intereses no controlantes | B26: 6563 | C26: 9397 | D26: 6145

Sheet CF_Hist
A1: Banco de Occidente S.A. y Subsidiarias — Estado Consolidado de Flujos de Efectivo (auditado)
A2: COP millones. Signos como publicados (salidas negativas).
A4: Line item | B4: FY2023A | C4: FY2024A | D4: FY2025A
A5: Actividades de operación
A6: Resultado del ejercicio antes de impuesto a las ganancias | B6: 452212 | C6: 533223 | D6: 590890
A7: Ingresos netos por intereses y valoración | B7: -2237405 | C7: -2328160 | D7: -2301181
A8: Depreciación activos tangibles y PP&E derecho de uso | B8: 111082 | C8: 123280 | D8: 134575
A9: Amortización activos intangibles | B9: 74763 | C9: 85548 | D9: 107102
A10: Deterioro cartera de créditos y cuentas por cobrar, neto | B10: 1384446 | C10: 1527221 | D10: 1401261
A11: Recuperación deterioro activos tangibles, neto | B11: -85 | C11: -259 | D11: -3
A12: (Utilidad) pérdida venta propiedad y equipo uso propio | B12: -258 | C12: 169 | D12: -1007
A13: Diferencia en cambio | B13: 53273 | C13: -160521 | D13: -43766
A14: Utilidad venta activos no corrientes mantenidos para la venta | B14: -25437 | C14: -3028 | D14: -2569
A15: Utilidad venta de inversiones, neto | B15: -2637 | C15: -98 | D15: -434
A16: Participación utilidades asociadas y JVs | B16: -218882 | C16: -230687 | D16: -250881
A17: Dividendos (no-cash add-back) | B17: -5702 | C17: -6388 | D17: -7257
... A25: Variación neta — depósitos de clientes | B25: 6953537 | C25: 4365419 | D25: 6470992
A26: Variación neta — activos no corrientes mantenidos para la venta | C26: 24 | D26: 169
A27: Variación neta — préstamos interbancarios y fondos overnight | B27: 2160444 | C27: 4286319 | D27: 3569612
A28: Variación neta — otros pasivos y provisiones | B28: 198599 | C28: -189946 | D28: 250257
A29: Variación neta — beneficios a empleados | B29: -2571 | C29: 6687 | D29: 311
A30: Intereses recibidos de activos financieros | B30: 6383490 | C30: 6964701 | D30: 6452259
A31: Intereses pagados de pasivos financieros | B31: -5295413 | C31: -5836335 | D31: -4813377
A32: Pago intereses arrendamientos financieros | B32: -29293 | C32: -36204 | D32: -28714
A33: Impuesto sobre la renta pagado | B33: -38048 | C33: -17805 | D33: -39978
A34: Efectivo neto de actividades de operación | B34: 1496354 | C34: -810067 | D34: 2099201
A36: Actividades de inversión
A37: Adquisición inversiones mantenidas hasta el vencimiento | B37: -1970311 | C37: -2080998 | D37: -1323874
A38: Redención inversiones mantenidas hasta el vencimiento | B38: 1935253 | C38: 2162511 | D38: 2240741
A39: Adquisición inversiones VR-ORI | B39: -2001896 | C39: -4207438 | D39: -4083478
A40: Producto venta inversiones VR-ORI | B40: 2184855 | C40: 3461505 | D40: 3306173
A41: Adquisición de activos tangibles | B41: -48031 | C41: -55435 | D41: -61861
A42: Adquisición de otros activos intangibles | B42: -135104 | C42: -142238 | D42: -168970
A43: Producto venta de propiedad y equipo | B43: 53087 | C43: 34204 | D43: 148576
A44: Producto venta activos no corrientes mantenidos para la venta | B44: 5771 | C44: 5296 | D44: 14735
A45: Adquisición participación en asociadas y JVs | D45: -100
A46: Dividendos recibidos | B46: 109492 | C46: 99190 | D46: 114533
A47: Efectivo neto de actividades de inversión | B47: 133116 | C47: -723403 | D47: 186475
A49: Actividades de financiación
A50: Obligaciones financieras, neto | B50: 30730 | C50: 833006 | D50: -677612
...

Sheet Loan_Book
A1: Banco de Occidente — Cartera de créditos (Nota 10, auditada)
A2: COP millones salvo % indicado.
A4: Line item | B4: FY2023A | C4: FY2024A | D4: FY2025A
A5: Cartera de créditos por modalidad (Nota 10.1, bruta)
A6: Cartera comercial y leasing comercial | B6: 34426863 | C6: 37817965 | D6: 39589665
A7: Cartera consumo y leasing consumo | B7: 12462019 | C7: 13176358 | D7: 13286359
A8: Cartera hipotecario y leasing hipotecario | B8: 2610153 | C8: 3096800 | D8: 3863730
A9: Total cartera de créditos bruta | B9: 49499035 | C9: 54091123 | D9: 56739754
A11: Deterioro por segmento (Nota 10, saldo BS)
A12: Deterioro cartera comercial y leasing comercial | B12: -1311753 | C12: -1459791 | D12: -1230697
A13: Deterioro cartera consumo y leasing consumo | B13: -1033280 | C13: -998522 | D13: -887844
A14: Deterioro cartera hipotecaria y leasing hipotecaria | B14: -71887 | C14: -88651 | D14: -116814
A15: Total deterioro de cartera | B15: -2416920 | C15: -2546964 | D15: -2235355
A16: Cartera de créditos, neta | B16: 47082115 | C16: 51544159 | D16: 54504399
A18: Mezcla y crecimiento
A19: Mezcla comercial (% cartera bruta) | B19: =B6/B9 -> 0.69550574 | C19: =C6/C9 -> 0.69915289 | D19: =D6/D9 -> 0.69774122
A20: Mezcla consumo (% cartera bruta) | B20: =B7/B9 -> 0.25176287 | C20: =C7/C9 -> 0.24359557 | D20: =D7/D9 -> 0.23416314
A21: Mezcla hipotecario (% cartera bruta) | B21: =B8/B9 -> 0.052731392 | C21: =C8/C9 -> 0.057251538 | D21: =D8/D9 -> 0.068095642
A22: Crecimiento cartera bruta YoY | C22: =C9/B9-1 -> 0.092771263 | D22: =D9/C9-1 -> 0.048966094

Sheet Deposits_Funding
A1: Banco de Occidente — Depósitos y fondeo mayorista (Notas 17-18, auditadas)
A2: COP millones salvo % indicado.
A4: Line item | B4: FY2023A | C4: FY2024A | D4: FY2025A
A5: Depósitos de clientes (Nota 17, BS)
A6: Cuentas corrientes | B6: 7092625 | C6: 7389155 | D6: 7606030
A7: Cuentas de ahorro | B7: 24153811 | C7: 28221791 | D7: 31112717
A8: Certificados de depósito a término (CDT) | B8: 17866450 | C8: 17917502 | D8: 20416158
A9: Otros depósitos | B9: 62846 | C9: 65375 | D9: 72267
A10: Total depósitos de clientes | B10: 49175732 | C10: 53593823 | D10: 59207172
A12: Obligaciones financieras mayoristas (Nota 18, BS)
A13: Fondos interbancarios y overnight | B13: 4403111 | C13: 8636674 | D13: 12281785
A14: Créditos de bancos y otros | B14: 3185957 | C14: 4480586 | D14: 3824902
A15: Bonos y títulos de inversión | B15: 2171345 | C15: 2670197 | D15: 2097440
A16: Obligaciones con entidades de redescuento | B16: 1088189 | C16: 1062182 | D16: 1061583
A17: Total obligaciones financieras | B17: 10848602 | C17: 16849639 | D17: 19265710
A19: Total fondeo (depósitos + obligaciones financieras) | B19: =B10+B17 -> 60024334 | C19: =C10+C17 -> 70443462 | D19: =D10+D17 -> 78472882
A20: Depósitos / fondeo total | B20: =B10/B19 -> 0.81926327 | C20: =C10/C19 -> 0.76080621 | D20: =D10/D19 -> 0.75449213
A21: Depósitos transaccionales (corriente+ahorro) / total depósitos | B21: =(B6+B7)/B10 -> 0.63540358 | C21: =(C6+C7)/C10 -> 0.66445989 | D21: =(D6+D7)/D10 -> 0.65395366
A22: Crecimiento depósitos de clientes YoY | C22: =C10/B10-1 -> 0.089842913 | D22: =D10/C10-1 -> 0.10473873
A24: Cruce contra balance (Pasivos financieros a costo amortizado)
A25: Pasivos financieros a costo amortizado (BS, reportado) | B25: 60024334 | C25: 70443462 | D25: 78472882

Sheet NIM_Build
A1: Banco de Occidente — Construcción de margen de intermediación (Nota 25/IS, auditada)
A2: COP millones salvo % indicado.
A4: Line item | B4: FY2023A | C4: FY2024A | D4: FY2025A
A5: Ingresos por intereses (Nota 25/IS)
A6: Intereses cartera comercial | B6: 4851231 | C6: 4578841 | D6: 4012015
A7: Intereses cartera consumo | B7: 1921271 | C7: 1975581 | D7: 1908993
A8: Intereses cartera vivienda | B8: 248787 | C8: 311362 | D8: 376457
A9: Ingreso por repos e interbancarios | B9: 192719 | C9: 143703 | D9: 40158
A10: Ingresos por depósitos (rendimientos) | B10: 35306 | C10: 34214 | D10: 102648
A11: Intereses otras cuentas por cobrar | B11: 1211 | C11: 6385 | D11: 4443
A12: Intereses inversiones a costo amortizado | B12: 482233 | C12: 524015 | D12: 643835
A13: Total ingresos por intereses y valoración | B13: 7732758 | C13: 7574101 | D13: 7088549
A15: Gastos por intereses (Nota 25/IS)
A16: Depósitos - cuentas corrientes | B16: 41408 | C16: 44781 | D16: 50410
A17: Depósitos de ahorro | B17: 2230879 | C17: 2204667 | D17: 1816585
A18: Certificados de depósito a término | B18: 2074357 | C18: 1777487 | D18: 1606372
A19: Obligaciones — créditos interbancarios | B19: 431210 | C19: 559139 | D19: 764707
A20: Obligaciones — créditos de bancos y otros | B20: 251754 | C20: 271468 | D20: 232508
A21: Obligaciones — bonos y títulos de inversión | B21: 335437 | C21: 276866 | D21: 226332
A22: Obligaciones — entidades de redescuento | B22: 130308 | C22: 111533 | D22: 90454
A23: Total gastos por intereses y similares | B23: 5495353 | C23: 5245941 | D23: 4787368
A25: Ingresos netos por intereses y valoración (NII) | B25: 2237405 | C25: 2328160 | D25: 2301181
A27: Base de activos productivos (promedio, para NIM)
A28: Cartera de créditos bruta (fin de período) | B28: 49499035 | C28: 54091123 | D28: 56739754
A29: Inversiones en títulos de deuda (VR resultados + VR ORI + costo amortizado, fin de período) | B29: 9959836 | C29: 16154253 | D29: 19819967
A30: Activos productivos estimados (cartera bruta + inversiones deuda), fin de período | B30: 59458871 | C30: 70245376 | D30: 76559721
A31: Activos productivos promedio (2023: fin de período únicamente, sin saldo inicial 2022 en este build) | B31: =B30 -> 59458871 | C31: =AVERAGE(B30,C30) -> 64852124 | D31: =AVERAGE(C30,D30) -> 73402548
A33: NIM = NII / activos productivos promedio | B33: =B25/B31 -> 0.037629457 | C33: =C25/C31 -> 0.035899518 | D33: =D25/D31 -> 0.031350151

Sheet Credit_Quality
A1: Banco de Occidente — Calidad de cartera (Notas 10.1/10.4/25, auditadas)
A2: COP millones salvo % indicado. NPL proxy limitado a cartera individualmente evaluada (única cifra de cartera deteriorada individual desglosada en las notas al nivel consolidado); no incluye deterioro colectivo de consumo/hipotecario.
A4: Line item | B4: FY2023A | C4: FY2024A | D4: FY2025A
A5: Cartera bruta y deterioro (Nota 10.1, BS)
A6: Total cartera de créditos bruta | B6: 49499035 | C6: 54091123 | D6: 56739754
A7: Total provisión (deterioro) para cartera de créditos | B7: 2416920 | C7: 2546964 | D7: 2235355
A8: Índice de cobertura (provisión / cartera bruta) | B8: =B7/B6 -> 0.048827619 | C8: =C7/C6 -> 0.047086543 | D8: =D7/D6 -> 0.039396628
A10: Costo de riesgo (Nota 25/IS — cargo del período, no saldo)
A11: Deterioro cartera de créditos e intereses por cobrar (cargo P&G) | B11: 1384446 | C11: 1527221 | D11: 1401261
A12: Recuperación de castigos (P&G) | B12: -189298 | C12: -174145 | D12: -189569
A13: Deterioro neto de cartera (cargo P&G neto de recuperaciones) | B13: =B11+B12 -> 1195148 | C13: =C11+C12 -> 1353076 | D13: =D11+D12 -> 1211692
A14: Costo de riesgo = cargo neto / cartera bruta fin de período | B14: =B13/B6 -> 0.024144875 | C14: =C13/C6 -> 0.025014751 | D14: =D13/D6 -> 0.021355256
A16: Cartera individualmente evaluada con deterioro registrado (Nota 10.4, proxy de cartera deteriorada)
A17: Valor bruto — cartera individual con deterioro registrado | B17: 1916696 | C17: 2414600 | D17: 2151097
A18: Provisión constituida — cartera individual con deterioro | B18: 671207 | C18: 815973 | D18: 598061
A19: Garantías colaterales — cartera individual con deterioro | B19: 357401 | C19: 384963 | D19: 259464
A20: Cartera individual deteriorada / cartera bruta total (proxy NPL, solo evaluación individual) | B20: =B17/B6 -> 0.038721886 | C20: =C17/C6 -> 0.044639487 | D20: =D17/D6 -> 0.037911638
A21: Cobertura de cartera individual deteriorada (provisión indiv. / valor bruto indiv.) | B21: =B18/B17 -> 0.3501896 | C21: =C18/C17 -> 0.33793299 | D21: =D18/D17 -> 0.27802605
A23: Deterioro por segmento (saldo BS, para referencia)
A24: Deterioro cartera comercial y leasing comercial | B24: -1311753 | C24: -1459791 | D24: -1230697
A25: Deterioro cartera consumo y leasing consumo | B25: -1033280 | C25: -998522 | D25: -887844
A26: Deterioro cartera hipotecaria y leasing hipotecaria | B26: -71887 | C26: -88651 | D26: -116814

Sheet Capital_Adequacy
A1: Banco de Occidente — Adecuación de capital / solvencia (Nota 4.6, auditada, base individual Matriz)
A2: COP millones salvo % indicado. Los índices de solvencia se calculan y reportan a nivel de la Matriz individual (Banco de Occidente S.A.), no consolidado — así lo revela la Nota 4.6 en los tres ejercicios.
A4: Line item | B4: FY2023A | C4: FY2024A | D4: FY2025A
A5: Patrimonio técnico (Nota 4.6, matriz individual — base regulatoria)
A6: Capital suscrito y pagado | B6: 4677 | C6: 4677 | D6: 4677
A7: Reservas y utilidades retenidas | B7: 4996111 | C7: 5253452 | D7: 5477955
A8: Otro resultado integral | B8: 176033 | C8: 209136 | D8: 152485
A9: Utilidad neta del período | B9: 473554 | C9: 473554 | D9: 574590
A10: Interés minoritario | B10: 11843 | C10: 16902 | D10: 19155
A11: Deducciones — plusvalía y otros intangibles | B11: -594581 | C11: -651630 | D11: -726124
A12: Deducciones — otros | B12: -2867 | C12: -2743 | D12: -2747
A13: Patrimonio básico ordinario | B13: 5064770 | C13: 5303348 | D13: 5499992
A14: Patrimonio básico | B14: 5064770 | C14: 5303348 | D14: 5499992
A15: Instrumentos subordinados (patrimonio adicional) | B15: 649305 | C15: 1357700 | D15: 1075171
A16: Patrimonio técnico total | B16: 5714075 | C16: 6661048 | D16: 6575163
A18: Activos ponderados por riesgo (APNR)
A19: Riesgo crediticio | B19: 41324390 | C19: 44446464 | D19: 45511052
A20: Exposición riesgo de mercado | B20: 2426178 | C20: 4244121 | D20: 1694611
A21: Exposición riesgo operacional | B21: 2624878 | C21: 3150725 | D21: 3745856
A22: Total APNR (crédito + mercado + operacional) | B22: 46375446 | C22: 51841310 | D22: 50951519
A24: Índices de solvencia (según lo publicado)
A25: Relación de solvencia básica | B25: 0.1092 | C25: 0.1023 | D25: 0.1079
A26: Relación de solvencia básica adicional | B26: 0.1092 | C26: 0.1023 | D26: 0.1079
A27: Relación de solvencia contribuida por patrimonio adicional | B27: 0.014 | C27: 0.0262 | D27: 0.0211
A28: Relación de solvencia total | B28: 0.1232 | C28: 0.1285 | D28: 0.129
A29: Valor de apalancamiento | B29: 70759147 | C29: 81253921 | D29: 87702312
A30: Relación de apalancamiento | B30: 0.0716 | C30: 0.0653 | D30: 0.0627
A32: Mínimo regulatorio — patrimonio técnico / APNR | B32: 0.09 | C32: 0.09 | D32: 0.09
A33: Colchón de conservación de capital regulatorio | B33: 0.015 | C33: 0.015 | D33: 0.015

Sheet Checks_TieOut
A1: Tie-out checks — audited historical statements (all deltas must be 0; COP millions)
A2: MASTER | B2: =IF(COUNTIF(G5:G31,"FAIL")=0,"OK — ALL TIE-OUTS PASS","FAIL") -> OK — ALL TIE-OUTS PASS
A4: Check | B4: FY2023A | C4: FY2024A | D4: FY2025A | G4: Status
A5: BS: Total activos = suma de líneas | B5: =BS_Hist!B6+BS_Hist!B7+BS_Hist!B11+BS_Hist!B14+N(BS_Hist!B15)+BS_Hist!B21+BS_Hist!B22+N(BS_Hist!B23)+BS_Hist!B24+BS_Hist!B25+BS_Hist!B26+BS_Hist!B27+BS_Hist!B28-BS_Hist!B29 -> 0 | C5: =BS_Hist!C6+BS_Hist!C7+BS_Hist!C11+BS_Hist!C14+N(BS_Hist!C15)+BS_Hist!C21+BS_Hist!C22+N(BS_Hist!C23)+BS_Hist!C24+BS_Hist!C25+BS_Hist!C26+BS_Hist!C27+BS_Hist!C28-BS_Hist!C29 -> 0 | D5: =BS_Hist!D6+BS_Hist!D7+BS_Hist!D11+BS_Hist!D14+N(BS_Hist!D15)+BS_Hist!D21+BS_Hist!D22+N(BS_Hist!D23)+BS_Hist!D24+BS_Hist!D25+BS_Hist!D26+BS_Hist!D27+BS_Hist!D28-BS_Hist!D29 -> 0 | G5: =IF(AND(ABS(N(B5))<=1,ABS(N(C5))<=1,ABS(N(D5))<=1),"PASS","FAIL") -> PASS
A6: BS: Cartera neta = bruta + deterioro | B6: =BS_Hist!B16+BS_Hist!B20-BS_Hist!B21 -> 0 | C6: =BS_Hist!C16+BS_Hist!C20-BS_Hist!C21 -> 0 | D6: =BS_Hist!D16+BS_Hist!D20-BS_Hist!D21 -> 0 | G6: =IF(AND(ABS(N(B6))<=1,ABS(N(C6))<=1,ABS(N(D6))<=1),"PASS","FAIL") -> PASS
A7: BS: Cartera bruta = suma de segmentos | B7: =BS_Hist!B17+BS_Hist!B18+BS_Hist!B19-BS_Hist!B16 -> 0 | C7: =BS_Hist!C17+BS_Hist!C18+BS_Hist!C19-BS_Hist!C16 -> 0 | D7: =BS_Hist!D17+BS_Hist!D18+BS_Hist!D19-BS_Hist!D16 -> 0 | G7: =IF(AND(ABS(N(B7))<=1,ABS(N(C7))<=1,ABS(N(D7))<=1),"PASS","FAIL") -> PASS
A8: BS: Depósitos + Obligaciones financieras + otros = Total pasivos | B8: =BS_Hist!B32+BS_Hist!B33+BS_Hist!B38+BS_Hist!B43+N(BS_Hist!B44)+BS_Hist!B45+BS_Hist!B46-BS_Hist!B47 -> 0 | C8: =BS_Hist!C32+BS_Hist!C33+BS_Hist!C38+BS_Hist!C43+N(BS_Hist!C44)+BS_Hist!C45+BS_Hist!C46-BS_Hist!C47 -> 0 | D8: =BS_Hist!D32+BS_Hist!D33+BS_Hist!D38+BS_Hist!D43+N(BS_Hist!D44)+BS_Hist!D45+BS_Hist!D46-BS_Hist!D47 -> 0 | G8: =IF(AND(ABS(N(B8))<=1,ABS(N(C8))<=1,ABS(N(D8))<=1),"PASS","FAIL") -> PASS
A9: BS: Depósitos = suma de tipos | B9: =BS_Hist!B34+BS_Hist!B35+BS_Hist!B36+BS_Hist!B37-BS_Hist!B33 -> 0 | C9: =BS_Hist!C34+BS_Hist!C35+BS_Hist!C36+BS_Hist!C37-BS_Hist!C33 -> 0 | D9: =BS_Hist!D34+BS_Hist!D35+BS_Hist!D36+BS_Hist!D37-BS_Hist!D33 -> 0 | G9: =IF(AND(ABS(N(B9))<=1,ABS(N(C9))<=1,ABS(N(D9))<=1),"PASS","FAIL") -> PASS
A10: BS: Obligaciones financieras = suma de tipos | B10: =BS_Hist!B39+BS_Hist!B40+BS_Hist!B41+BS_Hist!B42-BS_Hist!B38 -> 0 | C10: =BS_Hist!C39+BS_Hist!C40+BS_Hist!C41+BS_Hist!C42-BS_Hist!C38 -> 0 | D10: =BS_Hist!D39+BS_Hist!D40+BS_Hist!D41+BS_Hist!D42-BS_Hist!D38 -> 0 | G10: =IF(AND(ABS(N(B10))<=1,ABS(N(C10))<=1,ABS(N(D10))<=1),"PASS","FAIL") -> PASS
A11: BS: Patrimonio de intereses controlantes = suma de líneas | B11: =BS_Hist!B50+BS_Hist!B51+BS_Hist!B52+BS_Hist!B53-BS_Hist!B54 -> 0 | C11: =BS_Hist!C50+BS_Hist!C51+BS_Hist!C52+BS_Hist!C53-BS_Hist!C54 -> 0 | D11: =BS_Hist!D50+BS_Hist!D51+BS_Hist!D52+BS_Hist!D53-BS_Hist!D54 -> 0 | G11: =IF(AND(ABS(N(B11))<=1,ABS(N(C11))<=1,ABS(N(D11))<=1),"PASS","FAIL") -> PASS
A12: BS: Total patrimonio = controlantes + no controlantes | B12: =BS_Hist!B54+BS_Hist!B55-BS_Hist!B56 -> 0 | C12: =BS_Hist!C54+BS_Hist!C55-BS_Hist!C56 -> 0 | D12: =BS_Hist!D54+BS_Hist!D55-BS_Hist!D56 -> 0 | G12: =IF(AND(ABS(N(B12))<=1,ABS(N(C12))<=1,ABS(N(D12))<=1),"PASS","FAIL") -> PASS
A13: BS: Total pasivos + patrimonio = Total pasivos y patrimonio | B13: =BS_Hist!B47+BS_Hist!B56-BS_Hist!B57 -> 0 | C13: =BS_Hist!C47+BS_Hist!C56-BS_Hist!C57 -> 0 | D13: =BS_Hist!D47+BS_Hist!D56-BS_Hist!D57 -> 0 | G13: =IF(AND(ABS(N(B13))<=1,ABS(N(C13))<=1,ABS(N(D13))<=1),"PASS","FAIL") -> PASS
A14: BS: Balance (Total activos − Total pasivos y patrimonio) | B14: =BS_Hist!B29-BS_Hist!B57 -> 0 | C14: =BS_Hist!C29-BS_Hist!C57 -> 0 | D14: =BS_Hist!D29-BS_Hist!D57 -> 0 | G14: =IF(AND(ABS(N(B14))<=1,ABS(N(C14))<=1,ABS(N(D14))<=1),"PASS","FAIL") -> PASS
A15: IS: Ingresos netos por intereses = Ingresos − Gastos por intereses | B15: =IS_Hist!B5-IS_Hist!B13-IS_Hist!B21 -> 0 | C15: =IS_Hist!C5-IS_Hist!C13-IS_Hist!C21 -> 0 | D15: =IS_Hist!D5-IS_Hist!D13-IS_Hist!D21 -> 0 | G15: =IF(AND(ABS(N(B15))<=1,ABS(N(C15))<=1,ABS(N(D15))<=1),"PASS","FAIL") -> PASS
A16: IS: Ingresos, neto de intereses después de deterioro | B16: =IS_Hist!B21-IS_Hist!B22-IS_Hist!B26 -> 0 | C16: =IS_Hist!C21-IS_Hist!C22-IS_Hist!C26 -> 0 | D16: =IS_Hist!D21-IS_Hist!D22-IS_Hist!D26 -> 0 | G16: =IF(AND(ABS(N(B16))<=1,ABS(N(C16))<=1,ABS(N(D16))<=1),"PASS","FAIL") -> PASS
A17: IS: Ingreso neto por comisiones = Ingresos − Gastos comisiones | B17: =IS_Hist!B27-IS_Hist!B28-IS_Hist!B29 -> 0 | C17: =IS_Hist!C27-IS_Hist!C28-IS_Hist!C29 -> 0 | D17: =IS_Hist!D27-IS_Hist!D28-IS_Hist!D29 -> 0 | G17: =IF(AND(ABS(N(B17))<=1,ABS(N(C17))<=1,ABS(N(D17))<=1),"PASS","FAIL") -> PASS
A18: IS: Utilidad antes de impuestos = suma de bloques | B18: =IS_Hist!B26+IS_Hist!B29+IS_Hist!B30+IS_Hist!B31-IS_Hist!B32-IS_Hist!B38 -> 0 | C18: =IS_Hist!C26+IS_Hist!C29+IS_Hist!C30+IS_Hist!C31-IS_Hist!C32-IS_Hist!C38 -> 0 | D18: =IS_Hist!D26+IS_Hist!D29+IS_Hist!D30+IS_Hist!D31-IS_Hist!D32-IS_Hist!D38 -> 0 | G18: =IF(AND(ABS(N(B18))<=1,ABS(N(C18))<=1,ABS(N(D18))<=1),"PASS","FAIL") -> PASS
A19: IS: Resultado del ejercicio = UAI − Impuesto | B19: =IS_Hist!B38-IS_Hist!B39-IS_Hist!B40 -> 0 | C19: =IS_Hist!C38-IS_Hist!C39-IS_Hist!C40 -> 0 | D19: =IS_Hist!D38-IS_Hist!D39-IS_Hist!D40 -> 0 | G19: =IF(AND(ABS(N(B19))<=1,ABS(N(C19))<=1,ABS(N(D19))<=1),"PASS","FAIL") -> PASS
A20: IS: Resultado = controlantes + no controlantes | B20: =IS_Hist!B43+IS_Hist!B44-IS_Hist!B40 -> 0 | C20: =IS_Hist!C43+IS_Hist!C44-IS_Hist!C40 -> 0 | D20: =IS_Hist!D43+IS_Hist!D44-IS_Hist!D40 -> 0 | G20: =IF(AND(ABS(N(B20))<=1,ABS(N(C20))<=1,ABS(N(D20))<=1),"PASS","FAIL") -> PASS
A21: CI: Resultados integrales = Resultado + OCI total | B21: =CI_Hist!B5+CI_Hist!B21-CI_Hist!B22 -> 0 | C21: =CI_Hist!C5+CI_Hist!C21-CI_Hist!C22 -> 0 | D21: =CI_Hist!D5+CI_Hist!D21-CI_Hist!D22 -> 1 | G21: =IF(AND(ABS(N(B21))<=1,ABS(N(C21))<=1,ABS(N(D21))<=1),"PASS","FAIL") -> PASS
A22: CI: Resultados integrales = controlantes + no controlantes | B22: =CI_Hist!B25+CI_Hist!B26-CI_Hist!B22 -> -1 | C22: =CI_Hist!C25+CI_Hist!C26-CI_Hist!C22 -> 0 | D22: =CI_Hist!D25+CI_Hist!D26-CI_Hist!D22 -> 0 | G22: =IF(AND(ABS(N(B22))<=1,ABS(N(C22))<=1,ABS(N(D22))<=1),"PASS","FAIL") -> PASS
A23: X: Resultado del ejercicio (IS) = Resultado del ejercicio (CI) | B23: =IS_Hist!B40-CI_Hist!B5 -> 0 | C23: =IS_Hist!C40-CI_Hist!C5 -> 0 | D23: =IS_Hist!D40-CI_Hist!D5 -> 0 | G23: =IF(AND(ABS(N(B23))<=1,ABS(N(C23))<=1,ABS(N(D23))<=1),"PASS","FAIL") -> PASS
A24: CF: Efectivo neto operación = suma de conciliación (aprox., ver nota) | B24: =CF_Hist!B6+CF_Hist!B7+CF_Hist!B8+CF_Hist!B9+CF_Hist!B10+N(CF_Hist!B11)+N(CF_Hist!B12)+CF_Hist!B13+CF_Hist!B14+CF_Hist!B15+CF_Hist!B16+CF_Hist!B17+CF_Hist!B18+CF_Hist!B19+CF_Hist!B20+CF_Hist!B21+CF_Hist!B22+CF_Hist!B23+CF_Hist!B24+CF_Hist!B25+N(CF_Hist!B26)+CF_Hist!B27+CF_Hist!B28+CF_Hist!B29+CF_Hist!B30+CF_Hist!B31+CF_Hist!B32+CF_Hist!B33-CF_Hist!B34 -> 0 | C24: =CF_Hist!C6+CF_Hist!C7+CF_Hist!C8+CF_Hist!C9+CF_Hist!C10+N(CF_Hist!C11)+N(CF_Hist!C12)+CF_Hist!C13+CF_Hist!C14+CF_Hist!C15+CF_Hist!C16+CF_Hist!C17+CF_Hist!C18+CF_Hist!C19+CF_Hist!C20+CF_Hist!C21+CF_Hist!C22+CF_Hist!C23+CF_Hist!C24+CF_Hist!C25+N(CF_Hist!C26)+CF_Hist!C27+CF_Hist!C28+CF_Hist!C29+CF_Hist!C30+CF_Hist!C31+CF_Hist!C32+CF_Hist!C33-CF_Hist!C34 -> 0 | D24: =CF_Hist!D6+CF_Hist!D7+CF_Hist!D8+CF_Hist!D9+CF_Hist!D10+N(CF_Hist!D11)+N(CF_Hist!D12)+CF_Hist!D13+CF_Hist!D14+CF_Hist!D15+CF_Hist!D16+CF_Hist!D17+CF_Hist!D18+CF_Hist!D19+CF_Hist!D20+CF_Hist!D21+CF_Hist!D22+CF_Hist!D23+CF_Hist!D24+CF_Hist!D25+N(CF_Hist!D26)+CF_Hist!D27+CF_Hist!D28+CF_Hist!D29+CF_Hist!D30+CF_Hist!D31+CF_Hist!D32+CF_Hist!D33-CF_Hist!D34 -> 0 | G24: =IF(AND(ABS(N(B24))<=1,ABS(N(C24))<=1,ABS(N(D24))<=1),"PASS","FAIL") -> PASS
A25: CF: Efectivo neto inversión = suma de líneas | B25: =CF_Hist!B37+CF_Hist!B38+CF_Hist!B39+CF_Hist!B40+CF_Hist!B41+CF_Hist!B42+CF_Hist!B43+CF_Hist!B44+N(CF_Hist!B45)+CF_Hist!B46-CF_Hist!B47 -> 0 | C25: =CF_Hist!C37+CF_Hist!C38+CF_Hist!C39+CF_Hist!C40+CF_Hist!C41+CF_Hist!C42+CF_Hist!C43+CF_Hist!C44+N(CF_Hist!C45)+CF_Hist!C46-CF_Hist!C47 -> 0 | D25: =CF_Hist!D37+CF_Hist!D38+CF_Hist!D39+CF_Hist!D40+CF_Hist!D41+CF_Hist!D42+CF_Hist!D43+CF_Hist!D44+N(CF_Hist!D45)+CF_Hist!D46-CF_Hist!D47 -> 0 | G25: =IF(AND(ABS(N(B25))<=1,ABS(N(C25))<=1,ABS(N(D25))<=1),"PASS","FAIL") -> PASS
A26: CF: Efectivo neto financiación = suma de líneas | B26: =CF_Hist!B50+N(CF_Hist!B51)+CF_Hist!B52+CF_Hist!B53+CF_Hist!B54+CF_Hist!B55-CF_Hist!B56 -> 0 | C26: =CF_Hist!C50+N(CF_Hist!C51)+CF_Hist!C52+CF_Hist!C53+CF_Hist!C54+CF_Hist!C55-CF_Hist!C56 -> 0 | D26: =CF_Hist!D50+N(CF_Hist!D51)+CF_Hist!D52+CF_Hist!D53+CF_Hist!D54+CF_Hist!D55-CF_Hist!D56 -> 0 | G26: =IF(AND(ABS(N(B26))<=1,ABS(N(C26))<=1,ABS(N(D26))<=1),"PASS","FAIL") -> PASS
A27: CF: Variación neta efectivo = Oper. + Inv. + Fin. + FX | B27: =CF_Hist!B34+CF_Hist!B47+CF_Hist!B56+CF_Hist!B58-CF_Hist!B59 -> 0 | C27: =CF_Hist!C34+CF_Hist!C47+CF_Hist!C56+CF_Hist!C58-CF_Hist!C59 -> 0 | D27: =CF_Hist!D34+CF_Hist!D47+CF_Hist!D56+CF_Hist!D58-CF_Hist!D59 -> 0 | G27: =IF(AND(ABS(N(B27))<=1,ABS(N(C27))<=1,ABS(N(D27))<=1),"PASS","FAIL") -> PASS
A28: CF: Efectivo final = inicial + variación neta | B28: =CF_Hist!B60+CF_Hist!B59-CF_Hist!B61 -> 0 | C28: =CF_Hist!C60+CF_Hist!C59-CF_Hist!C61 -> 0 | D28: =CF_Hist!D60+CF_Hist!D59-CF_Hist!D61 -> 0 | G28: =IF(AND(ABS(N(B28))<=1,ABS(N(C28))<=1,ABS(N(D28))<=1),"PASS","FAIL") -> PASS
A29: X: CF efectivo final = BS efectivo | B29: =CF_Hist!B61-BS_Hist!B6 -> 0 | C29: =CF_Hist!C61-BS_Hist!C6 -> 0 | D29: =CF_Hist!D61-BS_Hist!D6 -> 0 | G29: =IF(AND(ABS(N(B29))<=1,ABS(N(C29))<=1,ABS(N(D29))<=1),"PASS","FAIL") -> PASS
A30: X: CF resultado del ejercicio = IS resultado del ejercicio | B30: =CF_Hist!B6-IS_Hist!B38 -> 0 | C30: =CF_Hist!C6-IS_Hist!C38 -> 0 | D30: =CF_Hist!D6-IS_Hist!D38 -> 0 | G30: =IF(AND(ABS(N(B30))<=1,ABS(N(C30))<=1,ABS(N(D30))<=1),"PASS","FAIL") -> PASS
A31: X: Fondeo (Deposits_Funding) = Pasivos financieros a costo amortizado (BS) | B31: =Deposits_Funding!B10+Deposits_Funding!B17-Deposits_Funding!B25 -> 0 | C31: =Deposits_Funding!C10+Deposits_Funding!C17-Deposits_Funding!C25 -> 0 | D31: =Deposits_Funding!D10+Deposits_Funding!D17-Deposits_Funding!D25 -> 0 | G31: =IF(AND(ABS(N(B31))<=1,ABS(N(C31))<=1,ABS(N(D31))<=1),"PASS","FAIL") -> PASS

Sheet Sources_Audited
A1: Audited source register — Banco de Occidente S.A. y Subsidiarias, EEFF consolidados (dictamen KPMG S.A.S.)
A3: Model year | B3: Source report | C3: File | D3: Statement pages (BS / IS+OCI / CF) | E3: Key notes used (page)
A4: FY2023A | B4: FY2023 EEFF consolidados auditados (comparativo 2023/2022; también verificado contra columna propia del PDF FY2023) | C4: BancoDeOccidente_EEFF-Consolidados-Dictamen_FY2023_al-31-dic-2023.pdf | D4: BS p.9 (via FY2024 PDF comparative, byte-matched to FY2023 PDF p.8 own-year col) / IS p.10 / CF p.13 | E4: Nota 10 cartera p.105-111 (via FY2024 PDF); Nota 4.6 solvencia p.81-83 (via FY2024 PDF)
A5: FY2024A | B5: FY2024 EEFF consolidados auditados (comparativo 2024/2023) | C5: BancoDeOccidente_EEFF-Consolidados-Dictamen_FY2024_al-31-dic-2024.pdf | D5: BS p.9 / IS p.10 / OCI p.11 / CF p.13 | E5: Nota 10 cartera p.105-111; Nota 4.6 solvencia p.81-83
A6: FY2025A | B6: FY2025 EEFF consolidados auditados (comparativo 2025/2024) | C6: BancoDeOccidente_EEFF-Consolidados-Dictamen_FY2025_al-31-dic-2025.pdf | D6: BS p.8 / IS p.9 / OCI p.10 / CF p.12 | E6: Nota 10 cartera p.105-111; Nota 4.6 solvencia p.82-83
A8: Notes
A9: Statements entered as published constants (COP millions); all recomputation lives in Checks_TieOut. Página = página impresa en el PDF renderizado por pdftotext -layout (footer numérico del documento), no número de página del PDF viewer.
A10: FY2023 figures cross-checked byte-for-byte against the FY2023 PDF's own reporting-year column (cash, total assets match to the peso) before use.
A11: Capital_Adequacy (Nota 4.6) is disclosed at the level of the Matriz individual (Banco de Occidente S.A.), not the consolidated group — this is how the bank reports it in all three audited filings; flagged on the sheet itself.
A12: Credit_Quality NPL proxy uses Nota 10.4 (cartera evaluada individualmente con deterioro registrado) because the notes do not disclose a consolidated Stage-3/vencida balance broken out by all segments at group level; the note text explicitly distinguishes "cartera deteriorada" (risk-based) from "cartera vencida" (days-past-due) without tabulating the latter at total-book level. Labeled as a proxy, not a full NPL ratio.
A14: USD presentation layer — TRM (tasa representativa del mercado) at each fiscal year-end close
A15: Year | B15: TRM close (COP per USD) | C15: Source
A16: FY2023A (31-dic-2023) | B16: 3822.05 | C16: actualicese.com, "TRM al 31 de diciembre de 2023" — citing official Banco de la República / Superfinanciera TRM (fetched 2026-07-21)
A17: FY2024A (31-dic-2024) | B17: 4409.15 | C17: actualicese.com, "Así cerró la TRM al 31 de diciembre de 2024" — citing official TRM (fetched 2026-07-21)
A18: FY2025A (31-dic-2025) | B18: 3757.08 | C18: actualicese.com, "TRM 2025: valor y variación al cierre del año" — citing official TRM (fetched 2026-07-21)
A19: Note: TRM is a market close rate used only to build the USD presentation layer (Historical/Forecast/Valuation sheets, which are stated in USD). It is not part of the audited COP-native statements and is not an issuer-published convenience-translation rate (Banco de Occidente does not publish one, unlike some issuers). Cited via web source aggregating the official Banrep/Superfinanciera TRM series, not fetched directly from Banrep's API in this pass.

Sheet Claude Code Log
A1: Turn # | B1: Date | C1: User Request | D1: Action Taken | E1: Details | F1: Outcome
A2: 1 | B2: 46324.359 | C2: Prepare a public model copy | D2: Remove local paths and private build references; preserve financial formulas and inputs | E2: Agent run with MOG as the tool, checked by guard v1. The guard measured every sheet before and after the run. Changed: Change_Log: 1 cell written, at D7; Sources_Audited: 3 cells written, at C4, C5, C6. Agent: OpenFinmods export | F2: Compare against source and review public copy
