Workbook

Sheet 00_Cover
A1: ASML Holding N.V. — Regated institutional model
A2: Native-currency, source-ledgered semiconductor model | 2026-07-16 | owner-ready, independent certification pending
A4: Model identifier | B4: ASML_9of10_Regated
A5: Ticker / CIK | B5: ASML / 0000937966
A6: Reporting currency / scale | B6: EUR / EUR millions
A7: Latest historical period | B7: FY2025A
A8: Forecast horizon | B8: Five fiscal years
A9: Valuation method | B9: Unlevered DCF to USD traded-security value
A10: Scenario control | B10: Assumptions!B3 — 1 Base / 2 Bull / 3 Bear
A11: Source gate | B11: Formula-driven exact claim ledger
A12: Native recalculation | B12: LibreOffice 26.2.4.2; two isolated-profile passes + reopen
A13: Architecture | B13: Prior ten-sheet order preserved; Gate_9of10 appended last
A14: Decision status | B14: READY FOR INDEPENDENT 9/10 REVIEW — not self-certified
A16: Use sequence: Sources → Historical → Assumptions → Forecast → Valuation → Sensitivity → Checks → Gate_9of10. Forecasts are estimates. Historical values remain in native currency; only the final security bridge uses dated FX and ADR ratio.

Sheet Sources
A1: Claim-level source and provenance ledger
A2: Every historical hardcode and external valuation input carries exact identity, period, value, locator, accession/URL, target, transform and review status.
A4: Source ID | B4: Legal entity / identifier | C4: Metric / line item | D4: Value | E4: Unit | F4: Period / as-of | G4: Source / class | H4: Taxonomy / claim locator | I4: Form | J4: Filed | K4: Accession | L4: Target cell | M4: Scale / FX / sign transform | N4: Exact official URL | O4: Retrieved | P4: Preparer | Q4: Verification | R4: Limitation / disposition
A5: ASML-S001 | B5: ASML Holding N.V. | ASML | CIK 0000937966 | C5: Revenue | D5: 18611 | E5: EURm | F5: 2021-12-31 | G5: 20-F / Official regulator filing / XBRL | H5: us-gaap:RevenueFromContractWithCustomerExcludingAssessedTax | I5: 20-F | J5: 2024-02-14 | K5: 0000937966-24-000008 | L5: Historical!B5 | M5: EUR / 1e6; sign preserved | N5: https://www.sec.gov/Archives/edgar/data/937966/000093796624000008/0000937966-24-000008-index.html | O5: 2026-07-16 | P5: Codex / semiconductor cluster | Q5: VERIFIED | R5: None
A6: ASML-S002 | B6: ASML Holding N.V. | ASML | CIK 0000937966 | C6: Revenue | D6: 21173.4 | E6: EURm | F6: 2022-12-31 | G6: 20-F / Official regulator filing / XBRL | H6: us-gaap:RevenueFromContractWithCustomerExcludingAssessedTax | I6: 20-F | J6: 2025-03-05 | K6: 0000937966-25-000009 | L6: Historical!C5 | M6: EUR / 1e6; sign preserved | N6: https://www.sec.gov/Archives/edgar/data/937966/000093796625000009/0000937966-25-000009-index.html | O6: 2026-07-16 | P6: Codex / semiconductor cluster | Q6: VERIFIED | R6: None
A7: ASML-S003 | B7: ASML Holding N.V. | ASML | CIK 0000937966 | C7: Revenue | D7: 27558.5 | E7: EURm | F7: 2023-12-31 | G7: 20-F / Official regulator filing / XBRL | H7: us-gaap:RevenueFromContractWithCustomerExcludingAssessedTax | I7: 20-F | J7: 2026-02-25 | K7: 0001628280-26-011378 | L7: Historical!D5 | M7: EUR / 1e6; sign preserved | N7: https://www.sec.gov/Archives/edgar/data/937966/000162828026011378/0001628280-26-011378-index.html | O7: 2026-07-16 | P7: Codex / semiconductor cluster | Q7: VERIFIED | R7: None
A8: ASML-S004 | B8: ASML Holding N.V. | ASML | CIK 0000937966 | C8: Revenue | D8: 28262.9 | E8: EURm | F8: 2024-12-31 | G8: 20-F / Official regulator filing / XBRL | H8: us-gaap:RevenueFromContractWithCustomerExcludingAssessedTax | I8: 20-F | J8: 2026-02-25 | K8: 0001628280-26-011378 | L8: Historical!E5 | M8: EUR / 1e6; sign preserved | N8: https://www.sec.gov/Archives/edgar/data/937966/000162828026011378/0001628280-26-011378-index.html | O8: 2026-07-16 | P8: Codex / semiconductor cluster | Q8: VERIFIED | R8: None
A9: ASML-S005 | B9: ASML Holding N.V. | ASML | CIK 0000937966 | C9: Revenue | D9: 32667.3 | E9: EURm | F9: 2025-12-31 | G9: 20-F / Official regulator filing / XBRL | H9: us-gaap:RevenueFromContractWithCustomerExcludingAssessedTax | I9: 20-F | J9: 2026-02-25 | K9: 0001628280-26-011378 | L9: Historical!F5 | M9: EUR / 1e6; sign preserved | N9: https://www.sec.gov/Archives/edgar/data/937966/000162828026011378/0001628280-26-011378-index.html | O9: 2026-07-16 | P9: Codex / semiconductor cluster | Q9: VERIFIED | R9: None
A10: ASML-S006 | B10: ASML Holding N.V. | ASML | CIK 0000937966 | C10: Gross profit | D10: 9809 | E10: EURm | F10: 2021-12-31 | G10: 20-F / Official regulator filing / XBRL | H10: us-gaap:GrossProfit | I10: 20-F | J10: 2024-02-14 | K10: 0000937966-24-000008 | L10: Historical!B7 | M10: EUR / 1e6; sign preserved | N10: https://www.sec.gov/Archives/edgar/data/937966/000093796624000008/0000937966-24-000008-index.html | O10: 2026-07-16 | P10: Codex / semiconductor cluster | Q10: VERIFIED | R10: None
A11: ASML-S007 | B11: ASML Holding N.V. | ASML | CIK 0000937966 | C11: Gross profit | D11: 10700.1 | E11: EURm | F11: 2022-12-31 | G11: 20-F / Official regulator filing / XBRL | H11: us-gaap:GrossProfit | I11: 20-F | J11: 2025-03-05 | K11: 0000937966-25-000009 | L11: Historical!C7 | M11: EUR / 1e6; sign preserved | N11: https://www.sec.gov/Archives/edgar/data/937966/000093796625000009/0000937966-25-000009-index.html | O11: 2026-07-16 | P11: Codex / semiconductor cluster | Q11: VERIFIED | R11: None
A12: ASML-S008 | B12: ASML Holding N.V. | ASML | CIK 0000937966 | C12: Gross profit | D12: 14136.1 | E12: EURm | F12: 2023-12-31 | G12: 20-F / Official regulator filing / XBRL | H12: us-gaap:GrossProfit | I12: 20-F | J12: 2026-02-25 | K12: 0001628280-26-011378 | L12: Historical!D7 | M12: EUR / 1e6; sign preserved | N12: https://www.sec.gov/Archives/edgar/data/937966/000162828026011378/0001628280-26-011378-index.html | O12: 2026-07-16 | P12: Codex / semiconductor cluster | Q12: VERIFIED | R12: None
A13: ASML-S009 | B13: ASML Holding N.V. | ASML | CIK 0000937966 | C13: Gross profit | D13: 14492 | E13: EURm | F13: 2024-12-31 | G13: 20-F / Official regulator filing / XBRL | H13: us-gaap:GrossProfit | I13: 20-F | J13: 2026-02-25 | K13: 0001628280-26-011378 | L13: Historical!E7 | M13: EUR / 1e6; sign preserved | N13: https://www.sec.gov/Archives/edgar/data/937966/000162828026011378/0001628280-26-011378-index.html | O13: 2026-07-16 | P13: Codex / semiconductor cluster | Q13: VERIFIED | R13: None
A14: ASML-S010 | B14: ASML Holding N.V. | ASML | CIK 0000937966 | C14: Gross profit | D14: 17258 | E14: EURm | F14: 2025-12-31 | G14: 20-F / Official regulator filing / XBRL | H14: us-gaap:GrossProfit | I14: 20-F | J14: 2026-02-25 | K14: 0001628280-26-011378 | L14: Historical!F7 | M14: EUR / 1e6; sign preserved | N14: https://www.sec.gov/Archives/edgar/data/937966/000162828026011378/0001628280-26-011378-index.html | O14: 2026-07-16 | P14: Codex / semiconductor cluster | Q14: VERIFIED | R14: None
A15: ASML-S011 | B15: ASML Holding N.V. | ASML | CIK 0000937966 | C15: Operating income | D15: 6750.1 | E15: EURm | F15: 2021-12-31 | G15: 20-F / Official regulator filing / XBRL | H15: us-gaap:OperatingIncomeLoss | I15: 20-F | J15: 2024-02-14 | K15: 0000937966-24-000008 | L15: Historical!B9 | M15: EUR / 1e6; sign preserved | N15: https://www.sec.gov/Archives/edgar/data/937966/000093796624000008/0000937966-24-000008-index.html | O15: 2026-07-16 | P15: Codex / semiconductor cluster | Q15: VERIFIED | R15: None
A16: ASML-S012 | B16: ASML Holding N.V. | ASML | CIK 0000937966 | C16: Operating income | D16: 6500.7 | E16: EURm | F16: 2022-12-31 | G16: 20-F / Official regulator filing / XBRL | H16: us-gaap:OperatingIncomeLoss | I16: 20-F | J16: 2025-03-05 | K16: 0000937966-25-000009 | L16: Historical!C9 | M16: EUR / 1e6; sign preserved | N16: https://www.sec.gov/Archives/edgar/data/937966/000093796625000009/0000937966-25-000009-index.html | O16: 2026-07-16 | P16: Codex / semiconductor cluster | Q16: VERIFIED | R16: None
... A97: ASML-S093 | B97: ASML Holding N.V. | ASML | CIK 0000937966 | C97: Terminal growth | D97: 0.03 | E97: model input | F97: Forecast horizon | G97: Model input / Forecast assumption / model input | H97: Base/Bull/Bear estimate | I97: Model input | J97: 2026-07-16 | K97: n/a | L97: Assumptions!B21:D21 | M97: blue model input | N97: https://www.sec.gov/Archives/edgar/data/937966/000162828026011378/asml-20251231.htm | O97: 2026-07-16 | P97: Codex / semiconductor cluster | Q97: VERIFIED | R97: Not a reported fact

Sheet Historical
A1: Historical financials
A2: EUR millions; native reported history. Percent rows are formula-derived.
A4: Metric | B4: FY2021A | C4: FY2022A | D4: FY2023A | E4: FY2024A | F4: FY2025A | G4: Unit | H4: Source coverage
A5: Revenue | B5: 18611 | C5: 21173.4 | D5: 27558.5 | E5: 28262.9 | F5: 32667.3 | G5: EUR millions | H5: =IF(COUNTIF(Sources!$C$5:$C$97,"Revenue")>=1,"VERIFIED","CHECK") -> VERIFIED
A6: Growth | C6: =IF(B5<>0,C5/B5-1,0) -> 0.13768202 | D6: =IF(C5<>0,D5/C5-1,0) -> 0.30156234 | E6: =IF(D5<>0,E5/D5-1,0) -> 0.025560172 | F6: =IF(E5<>0,F5/E5-1,0) -> 0.1558368 | G6: % | H6: Formula-derived
A7: Gross profit | B7: 9809 | C7: 10700.1 | D7: 14136.1 | E7: 14492 | F7: 17258 | G7: EUR millions | H7: =IF(COUNTIF(Sources!$C$5:$C$97,"Gross profit")>=1,"VERIFIED","CHECK") -> VERIFIED
A8: Gross margin | B8: =IF(B5<>0,B7/B5,0) -> 0.52705389 | C8: =IF(C5<>0,C7/C5,0) -> 0.50535578 | D8: =IF(D5<>0,D7/D5,0) -> 0.51294882 | E8: =IF(E5<>0,E7/E5,0) -> 0.51275701 | F8: =IF(F5<>0,F7/F5,0) -> 0.52829588 | G8: % | H8: Formula-derived
A9: Operating income | B9: 6750.1 | C9: 6500.7 | D9: 9042.3 | E9: 9022.6 | F9: 11301.4 | G9: EUR millions | H9: =IF(COUNTIF(Sources!$C$5:$C$97,"Operating income")>=1,"VERIFIED","CHECK") -> VERIFIED
A10: Operating margin | B10: =IF(B5<>0,B9/B5,0) -> 0.36269411 | C10: =IF(C5<>0,C9/C5,0) -> 0.30702202 | D10: =IF(D5<>0,D9/D5,0) -> 0.32811292 | E10: =IF(E5<>0,E9/E5,0) -> 0.31923829 | F10: =IF(F5<>0,F9/F5,0) -> 0.34595452 | G10: % | H10: Formula-derived
A11: Net income attributable / consolidated | B11: 5883.2 | C11: 5624.2 | D11: 7839 | E11: 7571.6 | F11: 9609.4 | G11: EUR millions | H11: =IF(COUNTIF(Sources!$C$5:$C$97,"Net income attributable / consolidated")>=1,"VERIFIED","CHECK") -> VERIFIED
A12: Cash flow from operations | B12: 10845.8 | C12: 8486.8 | D12: 5443.4 | E12: 11166.2 | F12: 12658.5 | G12: EUR millions | H12: =IF(COUNTIF(Sources!$C$5:$C$97,"Cash flow from operations")>=1,"VERIFIED","CHECK") -> VERIFIED
A13: Capital expenditure | B13: 900.7 | C13: 1281.8 | D13: 2155.6 | E13: 2067.2 | F13: 1573.6 | G13: EUR millions | H13: =IF(COUNTIF(Sources!$C$5:$C$97,"Capital expenditure")>=1,"VERIFIED","CHECK") -> VERIFIED
A14: Research and development | B14: 2547 | C14: 3253.5 | D14: 3980.6 | E14: 4303.7 | F14: 4698.8 | G14: EUR millions | H14: =IF(COUNTIF(Sources!$C$5:$C$97,"Research and development")>=1,"VERIFIED","CHECK") -> VERIFIED
A15: Total assets | B15: 30231 | C15: 36300.4 | D15: 39957.5 | E15: 48589.6 | F15: 50566.6 | G15: EUR millions | H15: =IF(COUNTIF(Sources!$C$5:$C$97,"Total assets")>=1,"VERIFIED","CHECK") -> VERIFIED
A16: Total liabilities | B16: 20090.4 | C16: 27489.6 | D16: 26505.1 | E16: 30112.8 | F16: 30954.4 | G16: EUR millions | H16: =IF(COUNTIF(Sources!$C$5:$C$97,"Total liabilities")>=1,"VERIFIED","CHECK") -> VERIFIED
A17: Equity attributable / stockholders' equity | B17: 10140.6 | C17: 8810.8 | D17: 13452.4 | E17: 18476.8 | F17: 19612.2 | G17: EUR millions | H17: =IF(COUNTIF(Sources!$C$5:$C$97,"Equity attributable / stockholders' equity")>=1,"VERIFIED","CHECK") -> VERIFIED
A18: Cash and cash equivalents | B18: 6951.8 | C18: 7268.3 | D18: 7004.7 | E18: 12735.9 | F18: 12916 | G18: EUR millions | H18: =IF(COUNTIF(Sources!$C$5:$C$97,"Cash and cash equivalents")>=1,"VERIFIED","CHECK") -> VERIFIED
A19: Interest-bearing debt | B19: 4075 | C19: 3514.2 | D19: 4631.5 | E19: 3677.3 | F19: 2709 | G19: EUR millions | H19: =IF(COUNTIF(Sources!$C$5:$C$97,"Interest-bearing debt")>=1,"VERIFIED","CHECK") -> VERIFIED
A20: Diluted weighted-average shares | B20: 410.4 | C20: 398 | D20: 394.1 | E20: 393.6 | F20: 388.9 | G20: millions of shares | H20: =IF(COUNTIF(Sources!$C$5:$C$97,"Diluted weighted-average shares")>=1,"VERIFIED","CHECK") -> VERIFIED

Sheet Assumptions
A1: Scenario assumptions
A2: Blue = input; green = selected formula. Selector 1 Base / 2 Bull / 3 Bear. EUR stays native through DCF.
A3: Scenario selector | B3: 1
A4: Driver | B4: Base | C4: Bull | D4: Bear | E4: Active | F4: Classification / rationale
A5: System units growth — Y1 | B5: 0.05 | C5: 0.09 | D5: -0.03 | E5: =CHOOSE($B$3,B5,C5,D5) -> 0.05 | F5: Company-specific revenue driver estimate
A6: System units growth — Y5 | B6: 0.04 | C6: 0.07 | D6: 0.01 | E6: =CHOOSE($B$3,B6,C6,D6) -> 0.04 | F6: Company-specific revenue driver estimate
A7: Average system revenue growth — Y1 | B7: 0.05 | C7: 0.08 | D7: 0.02 | E7: =CHOOSE($B$3,B7,C7,D7) -> 0.05 | F7: Company-specific revenue driver estimate
A8: Average system revenue growth — Y5 | B8: 0.03 | C8: 0.06 | D8: 0.01 | E8: =CHOOSE($B$3,B8,C8,D8) -> 0.03 | F8: Company-specific revenue driver estimate
A9: Installed-base revenue growth — Y1 | B9: 0.1 | C9: 0.13 | D9: 0.06 | E9: =CHOOSE($B$3,B9,C9,D9) -> 0.1 | F9: Company-specific revenue driver estimate
A10: Installed-base revenue growth — Y5 | B10: 0.07 | C10: 0.1 | D10: 0.04 | E10: =CHOOSE($B$3,B10,C10,D10) -> 0.07 | F10: Company-specific revenue driver estimate
A11: Gross margin — Y1 | B11: 0.525 | C11: 0.54 | D11: 0.5 | E11: =CHOOSE($B$3,B11,C11,D11) -> 0.525 | F11: Operating / FCFF estimate
A12: Gross margin — Y5 | B12: 0.545 | C12: 0.57 | D12: 0.515 | E12: =CHOOSE($B$3,B12,C12,D12) -> 0.545 | F12: Operating / FCFF estimate
A13: R&D / revenue | B13: 0.143 | C13: 0.14 | D13: 0.15 | E13: =CHOOSE($B$3,B13,C13,D13) -> 0.143 | F13: Operating / FCFF estimate
A14: Other operating expense / revenue | B14: 0.039 | C14: 0.036 | D14: 0.043 | E14: =CHOOSE($B$3,B14,C14,D14) -> 0.039 | F14: Operating / FCFF estimate
A15: Cash tax rate | B15: 0.15 | C15: 0.14 | D15: 0.17 | E15: =CHOOSE($B$3,B15,C15,D15) -> 0.15 | F15: Operating / FCFF estimate
A16: D&A / revenue | B16: 0.05 | C16: 0.052 | D16: 0.048 | E16: =CHOOSE($B$3,B16,C16,D16) -> 0.05 | F16: Operating / FCFF estimate
... A26: Shareholder distributions / FCFF (dividends + buybacks payout ratio) | B26: 0.62 | C26: 0.55 | D26: 0.7 | E26: =CHOOSE($B$3,B26,C26,D26) -> 0.62 | F26: Cash roll-forward driver — FY2022-25A avg payout (dividend+buyback)/FCFF ≈0.62; Bull lower buyback intensity, Bear higher (defensive capital return). Fixes Forecast!C26:G26 frozen-cash defect.
A27: Debt policy | B27: Static — no financing driver modeled (documented simplifying assumption, not a hidden freeze)

Sheet Forecast
A1: Company-specific operating forecast
A2: EUR millions; sector operating drivers build revenue bottom-up.
A4: Metric | B4: FY2025A | C4: FY2026E | D4: FY2027E | E4: FY2028E | F4: FY2029E | G4: FY2030E
A5: Systems sold | B5: 535 | C5: =B5*(1+Assumptions!$E$5) -> 561.75 | D5: =C5*(1+Assumptions!$E$5+(Assumptions!$E$6-Assumptions!$E$5)*1/4) -> 588.43313 | E5: =D5*(1+Assumptions!$E$5+(Assumptions!$E$6-Assumptions!$E$5)*2/4) -> 614.91262 | F5: =E5*(1+Assumptions!$E$5+(Assumptions!$E$6-Assumptions!$E$5)*3/4) -> 641.0464 | G5: =F5*(1+Assumptions!$E$5+(Assumptions!$E$6-Assumptions!$E$5)*4/4) -> 666.68826
A6: Average system revenue | B6: 45.746355 | C6: =B6*(1+Assumptions!$E$7) -> 48.033673 | D6: =C6*(1+Assumptions!$E$7+(Assumptions!$E$8-Assumptions!$E$7)*1/4) -> 50.195188 | E6: =D6*(1+Assumptions!$E$7+(Assumptions!$E$8-Assumptions!$E$7)*2/4) -> 52.202996 | F6: =E6*(1+Assumptions!$E$7+(Assumptions!$E$8-Assumptions!$E$7)*3/4) -> 54.030101 | G6: =F6*(1+Assumptions!$E$7+(Assumptions!$E$8-Assumptions!$E$7)*4/4) -> 55.651004
A7: Installed Base Management revenue | B7: 8193 | C7: =B7*(1+Assumptions!$E$9) -> 9012.3 | D7: =C7*(1+Assumptions!$E$9+(Assumptions!$E$10-Assumptions!$E$9)*1/4) -> 9845.9378 | E7: =D7*(1+Assumptions!$E$9+(Assumptions!$E$10-Assumptions!$E$9)*2/4) -> 10682.842 | F7: =E7*(1+Assumptions!$E$9+(Assumptions!$E$10-Assumptions!$E$9)*3/4) -> 11510.763 | G7: =F7*(1+Assumptions!$E$9+(Assumptions!$E$10-Assumptions!$E$9)*4/4) -> 12316.516
A8: Total revenue | B8: =B5*B6+B7 -> 32667.3 | C8: =C5*C6+C7 -> 35995.216 | D8: =D5*D6+D7 -> 39382.449 | E8: =E5*E6+E7 -> 42783.123 | F8: =F5*F6+F7 -> 46146.564 | G8: =G5*G6+G7 -> 49418.387
A9: Revenue growth | B9: =Historical!F6 -> 0.1558368 | C9: =IF(B8<>0,C8/B8-1,0) -> 0.101873 | D9: =IF(C8<>0,D8/C8-1,0) -> 0.094102324 | E9: =IF(D8<>0,E8/D8-1,0) -> 0.086349985 | F9: =IF(E8<>0,F8/E8-1,0) -> 0.078616075 | G9: =IF(F8<>0,G8/F8-1,0) -> 0.070900673
A10: Gross margin | B10: =Historical!F8 -> 0.52829588 | C10: =Assumptions!$E$11 -> 0.525 | D10: =Assumptions!$E$11+(Assumptions!$E$12-Assumptions!$E$11)*1/4 -> 0.53 | E10: =Assumptions!$E$11+(Assumptions!$E$12-Assumptions!$E$11)*2/4 -> 0.535 | F10: =Assumptions!$E$11+(Assumptions!$E$12-Assumptions!$E$11)*3/4 -> 0.54 | G10: =Assumptions!$E$11+(Assumptions!$E$12-Assumptions!$E$11)*4/4 -> 0.545
A11: Gross profit | B11: =B8*B10 -> 17258 | C11: =C8*C10 -> 18897.488 | D11: =D8*D10 -> 20872.698 | E11: =E8*E10 -> 22888.971 | F11: =F8*F10 -> 24919.145 | G11: =G8*G10 -> 26933.021
A12: R&D / revenue | B12: =IF(B8<>0,Historical!F14/B8,0) -> 0.14383803 | C12: =Assumptions!$E$13 -> 0.143 | D12: =Assumptions!$E$13 -> 0.143 | E12: =Assumptions!$E$13 -> 0.143 | F12: =Assumptions!$E$13 -> 0.143 | G12: =Assumptions!$E$13 -> 0.143
A13: R&D | B13: =Historical!F14 -> 4698.8 | C13: =C8*C12 -> 5147.3159 | D13: =D8*D12 -> 5631.6902 | E13: =E8*E12 -> 6117.9866 | F13: =F8*F12 -> 6598.9587 | G13: =G8*G12 -> 7066.8293
A14: Other operating expense / revenue | B14: =IF(B8<>0,(B11-Historical!F9-B13)/B8,0) -> 0.038503335 | C14: =Assumptions!$E$14 -> 0.039 | D14: =Assumptions!$E$14 -> 0.039 | E14: =Assumptions!$E$14 -> 0.039 | F14: =Assumptions!$E$14 -> 0.039 | G14: =Assumptions!$E$14 -> 0.039
A15: Other operating expense | B15: =B8*B14 -> 1257.8 | C15: =C8*C14 -> 1403.8134 | D15: =D8*D14 -> 1535.9155 | E15: =E8*E14 -> 1668.5418 | F15: =F8*F14 -> 1799.716 | G15: =G8*G14 -> 1927.3171
A16: Operating income | B16: =B11-B13-B15 -> 11301.4 | C16: =C11-C13-C15 -> 12346.359 | D16: =D11-D13-D15 -> 13705.092 | E16: =E11-E13-E15 -> 15102.442 | F16: =F11-F13-F15 -> 16520.47 | G16: =G11-G13-G15 -> 17938.874
A17: Operating margin | B17: =IF(B8<>0,B16/B8,0) -> 0.34595452 | C17: =IF(C8<>0,C16/C8,0) -> 0.343 | D17: =IF(D8<>0,D16/D8,0) -> 0.348 | E17: =IF(E8<>0,E16/E8,0) -> 0.353 | F17: =IF(F8<>0,F16/F8,0) -> 0.358 | G17: =IF(G8<>0,G16/G8,0) -> 0.363
A18: Cash tax rate | B18: =Assumptions!E15 -> 0.15 | C18: =Assumptions!$E$15 -> 0.15 | D18: =Assumptions!$E$15 -> 0.15 | E18: =Assumptions!$E$15 -> 0.15 | F18: =Assumptions!$E$15 -> 0.15 | G18: =Assumptions!$E$15 -> 0.15
A19: NOPAT | B19: =B16*(1-B18) -> 9606.19 | C19: =C16*(1-C18) -> 10494.405 | D19: =D16*(1-D18) -> 11649.328 | E19: =E16*(1-E18) -> 12837.076 | F19: =F16*(1-F18) -> 14042.4 | G19: =G16*(1-G18) -> 15248.043
A20: D&A / revenue | B20: =Assumptions!E16 -> 0.05 | C20: =Assumptions!$E$16 -> 0.05 | D20: =Assumptions!$E$16 -> 0.05 | E20: =Assumptions!$E$16 -> 0.05 | F20: =Assumptions!$E$16 -> 0.05 | G20: =Assumptions!$E$16 -> 0.05
A21: D&A | B21: =B8*B20 -> 1633.365 | C21: =C8*C20 -> 1799.7608 | D21: =D8*D20 -> 1969.1225 | E21: =E8*E20 -> 2139.1562 | F21: =F8*F20 -> 2307.3282 | G21: =G8*G20 -> 2470.9193
A22: Capex / revenue | B22: =IF(B8<>0,Historical!F13/B8,0) -> 0.048170495 | C22: =Assumptions!$E$17 -> 0.05 | D22: =Assumptions!$E$17+(Assumptions!$E$18-Assumptions!$E$17)*1/4 -> 0.04875 | E22: =Assumptions!$E$17+(Assumptions!$E$18-Assumptions!$E$17)*2/4 -> 0.0475 | F22: =Assumptions!$E$17+(Assumptions!$E$18-Assumptions!$E$17)*3/4 -> 0.04625 | G22: =Assumptions!$E$17+(Assumptions!$E$18-Assumptions!$E$17)*4/4 -> 0.045
A23: Capital expenditure | B23: =Historical!F13 -> 1573.6 | C23: =C8*C22 -> 1799.7608 | D23: =D8*D22 -> 1919.8944 | E23: =E8*E22 -> 2032.1983 | F23: =F8*F22 -> 2134.2786 | G23: =G8*G22 -> 2223.8274
A24: Change in NWC | B24: 0 | C24: =MAX(0,(C8-B8)*Assumptions!$E$19) -> 99.837473 | D24: =MAX(0,(D8-C8)*Assumptions!$E$19) -> 101.617 | E24: =MAX(0,(E8-D8)*Assumptions!$E$19) -> 102.02022 | F24: =MAX(0,(F8-E8)*Assumptions!$E$19) -> 100.90324 | G24: =MAX(0,(G8-F8)*Assumptions!$E$19) -> 98.154674
A25: FCFF | B25: =B19+B21-B23-B24 -> 9665.955 | C25: =C19+C21-C23-C24 -> 10394.568 | D25: =D19+D21-D23-D24 -> 11596.94 | E25: =E19+E21-E23-E24 -> 12842.014 | F25: =F19+F21-F23-F24 -> 14114.546 | G25: =G19+G21-G23-G24 -> 15396.98
A26: Cash / liquidity | B26: 12916 | C26: =B26+Forecast!C25*(1-Assumptions!$E$26) -> 16865.936 | D26: =C26+Forecast!D25*(1-Assumptions!$E$26) -> 21272.773 | E26: =D26+Forecast!E25*(1-Assumptions!$E$26) -> 26152.738 | F26: =E26+Forecast!F25*(1-Assumptions!$E$26) -> 31516.265 | G26: =F26+Forecast!G25*(1-Assumptions!$E$26) -> 37367.118
A27: Interest-bearing debt | B27: 2709 | C27: =B$27 -> 2709 | D27: =B$27 -> 2709 | E27: =B$27 -> 2709 | F27: =B$27 -> 2709 | G27: =B$27 -> 2709
A28: Diluted shares | B28: 388.9 | C28: =$B$28 -> 388.9 | D28: =$B$28 -> 388.9 | E28: =$B$28 -> 388.9 | F28: =$B$28 -> 388.9 | G28: =$B$28 -> 388.9

Sheet Valuation
A1: Discounted cash flow valuation
A2: EUR millions; DCF stays native through equity value. Final line converts to the USD traded security.
A4: Metric | B4: Year 1 | C4: Year 2 | D4: Year 3 | E4: Year 4 | F4: Year 5 | G4: Output
A5: FCFF | B5: =Forecast!C25 -> 10394.568 | C5: =Forecast!D25 -> 11596.94 | D5: =Forecast!E25 -> 12842.014 | E5: =Forecast!F25 -> 14114.546 | F5: =Forecast!G25 -> 15396.98
A6: Discount factor | B6: =1/(1+Assumptions!$E$20)^1 -> 0.92165899 | C6: =1/(1+Assumptions!$E$20)^2 -> 0.84945529 | D6: =1/(1+Assumptions!$E$20)^3 -> 0.7829081 | E6: =1/(1+Assumptions!$E$20)^4 -> 0.72157428 | F6: =1/(1+Assumptions!$E$20)^5 -> 0.66504542
A7: PV of FCFF | B7: =B5*B6 -> 9580.2467 | C7: =C5*C6 -> 9851.0816 | D7: =D5*D6 -> 10054.117 | E7: =E5*E6 -> 10184.693 | F7: =F5*F6 -> 10239.691
A9: Output | B9: Value
A10: PV explicit FCFF | B10: =SUM(B7:F7) -> 49909.83
A11: Terminal value | B11: =IF(Assumptions!$E$20>Assumptions!$E$21,F5*(1+Assumptions!$E$21)/(Assumptions!$E$20-Assumptions!$E$21),0) -> 288343.45
A12: PV terminal value | B12: =B11*F6 -> 191761.49
A13: Enterprise value | B13: =B10+B12 -> 241671.32
A14: Cash / liquidity | B14: =Forecast!B26 -> 12916
A15: Interest-bearing debt | B15: =Forecast!B27 -> 2709
A16: Equity value | B16: =B13+B14-B15 -> 251878.32
A17: Diluted shares (mm) | B17: =Forecast!B28 -> 388.9
A18: Implied EUR / ordinary share | B18: =IF(B17>0,B16/B17,0) -> 647.66861
A19: FX conversion input | B19: =Assumptions!E22 -> 1.1474
A20: Ordinary shares per traded security | B20: =Assumptions!E23 -> 1
A21: Implied USD / traded security | B21: =B18*Assumptions!$E$22*Assumptions!$E$23 -> 743.13497
A22: Current traded-security price (USD) | B22: =Assumptions!E24 -> 1815.27
A23: Upside / (downside) | B23: =IF(B22>0,B21/B22-1,0) -> -0.59062015

Sheet Sensitivity
A1: DCF sensitivity — implied USD / traded security
A2: Dynamic per-share matrix; center is active WACC / terminal growth.
A4: Terminal growth / WACC | B4: =Assumptions!$E$20+-0.02 -> 0.065 | C4: =Assumptions!$E$20+-0.01 -> 0.075 | D4: =Assumptions!$E$20+0 -> 0.085 | E4: =Assumptions!$E$20+0.01 -> 0.095 | F4: =Assumptions!$E$20+0.02 -> 0.105
A5: =Assumptions!$E$21+-0.01 -> 0.02 | B5: =((Valuation!$B$5/(1+B$4)^1+Valuation!$C$5/(1+B$4)^2+Valuation!$D$5/(1+B$4)^3+Valuation!$E$5/(1+B$4)^4+Valuation!$F$5/(1+B$4)^5+IF(B$4>$A5,Valuation!$F$5*(1+$A5)/(B$4-$A5)/(1+B$4)^5,0)+Valuation!$B$14-Valuation!$B$15)/Valuation!$B$17)*Assumptions!$E$22*Assumptions!$E$23 -> 937.50928 | C5: =((Valuation!$B$5/(1+C$4)^1+Valuation!$C$5/(1+C$4)^2+Valuation!$D$5/(1+C$4)^3+Valuation!$E$5/(1+C$4)^4+Valuation!$F$5/(1+C$4)^5+IF(C$4>$A5,Valuation!$F$5*(1+$A5)/(C$4-$A5)/(1+C$4)^5,0)+Valuation!$B$14-Valuation!$B$15)/Valuation!$B$17)*Assumptions!$E$22*Assumptions!$E$23 -> 768.39778 | D5: =((Valuation!$B$5/(1+D$4)^1+Valuation!$C$5/(1+D$4)^2+Valuation!$D$5/(1+D$4)^3+Valuation!$E$5/(1+D$4)^4+Valuation!$F$5/(1+D$4)^5+IF(D$4>$A5,Valuation!$F$5*(1+$A5)/(D$4-$A5)/(1+D$4)^5,0)+Valuation!$B$14-Valuation!$B$15)/Valuation!$B$17)*Assumptions!$E$22*Assumptions!$E$23 -> 651.44592 | E5: =((Valuation!$B$5/(1+E$4)^1+Valuation!$C$5/(1+E$4)^2+Valuation!$D$5/(1+E$4)^3+Valuation!$E$5/(1+E$4)^4+Valuation!$F$5/(1+E$4)^5+IF(E$4>$A5,Valuation!$F$5*(1+$A5)/(E$4-$A5)/(1+E$4)^5,0)+Valuation!$B$14-Valuation!$B$15)/Valuation!$B$17)*Assumptions!$E$22*Assumptions!$E$23 -> 565.78474 | F5: =((Valuation!$B$5/(1+F$4)^1+Valuation!$C$5/(1+F$4)^2+Valuation!$D$5/(1+F$4)^3+Valuation!$E$5/(1+F$4)^4+Valuation!$F$5/(1+F$4)^5+IF(F$4>$A5,Valuation!$F$5*(1+$A5)/(F$4-$A5)/(1+F$4)^5,0)+Valuation!$B$14-Valuation!$B$15)/Valuation!$B$17)*Assumptions!$E$22*Assumptions!$E$23 -> 500.36624
A6: =Assumptions!$E$21+-0.005 -> 0.025 | B6: =((Valuation!$B$5/(1+B$4)^1+Valuation!$C$5/(1+B$4)^2+Valuation!$D$5/(1+B$4)^3+Valuation!$E$5/(1+B$4)^4+Valuation!$F$5/(1+B$4)^5+IF(B$4>$A6,Valuation!$F$5*(1+$A6)/(B$4-$A6)/(1+B$4)^5,0)+Valuation!$B$14-Valuation!$B$15)/Valuation!$B$17)*Assumptions!$E$22*Assumptions!$E$23 -> 1035.5963 | C6: =((Valuation!$B$5/(1+C$4)^1+Valuation!$C$5/(1+C$4)^2+Valuation!$D$5/(1+C$4)^3+Valuation!$E$5/(1+C$4)^4+Valuation!$F$5/(1+C$4)^5+IF(C$4>$A6,Valuation!$F$5*(1+$A6)/(C$4-$A6)/(1+C$4)^5,0)+Valuation!$B$14-Valuation!$B$15)/Valuation!$B$17)*Assumptions!$E$22*Assumptions!$E$23 -> 830.2444 | D6: =((Valuation!$B$5/(1+D$4)^1+Valuation!$C$5/(1+D$4)^2+Valuation!$D$5/(1+D$4)^3+Valuation!$E$5/(1+D$4)^4+Valuation!$F$5/(1+D$4)^5+IF(D$4>$A6,Valuation!$F$5*(1+$A6)/(D$4-$A6)/(1+D$4)^5,0)+Valuation!$B$14-Valuation!$B$15)/Valuation!$B$17)*Assumptions!$E$22*Assumptions!$E$23 -> 693.47006 | E6: =((Valuation!$B$5/(1+E$4)^1+Valuation!$C$5/(1+E$4)^2+Valuation!$D$5/(1+E$4)^3+Valuation!$E$5/(1+E$4)^4+Valuation!$F$5/(1+E$4)^5+IF(E$4>$A6,Valuation!$F$5*(1+$A6)/(E$4-$A6)/(1+E$4)^5,0)+Valuation!$B$14-Valuation!$B$15)/Valuation!$B$17)*Assumptions!$E$22*Assumptions!$E$23 -> 595.87782 | F6: =((Valuation!$B$5/(1+F$4)^1+Valuation!$C$5/(1+F$4)^2+Valuation!$D$5/(1+F$4)^3+Valuation!$E$5/(1+F$4)^4+Valuation!$F$5/(1+F$4)^5+IF(F$4>$A6,Valuation!$F$5*(1+$A6)/(F$4-$A6)/(1+F$4)^5,0)+Valuation!$B$14-Valuation!$B$15)/Valuation!$B$17)*Assumptions!$E$22*Assumptions!$E$23 -> 522.77018
A7: =Assumptions!$E$21+0 -> 0.03 | B7: =((Valuation!$B$5/(1+B$4)^1+Valuation!$C$5/(1+B$4)^2+Valuation!$D$5/(1+B$4)^3+Valuation!$E$5/(1+B$4)^4+Valuation!$F$5/(1+B$4)^5+IF(B$4>$A7,Valuation!$F$5*(1+$A7)/(B$4-$A7)/(1+B$4)^5,0)+Valuation!$B$14-Valuation!$B$15)/Valuation!$B$17)*Assumptions!$E$22*Assumptions!$E$23 -> 1161.7082 | C7: =((Valuation!$B$5/(1+C$4)^1+Valuation!$C$5/(1+C$4)^2+Valuation!$D$5/(1+C$4)^3+Valuation!$E$5/(1+C$4)^4+Valuation!$F$5/(1+C$4)^5+IF(C$4>$A7,Valuation!$F$5*(1+$A7)/(C$4-$A7)/(1+C$4)^5,0)+Valuation!$B$14-Valuation!$B$15)/Valuation!$B$17)*Assumptions!$E$22*Assumptions!$E$23 -> 905.8347 | D7: =((Valuation!$B$5/(1+D$4)^1+Valuation!$C$5/(1+D$4)^2+Valuation!$D$5/(1+D$4)^3+Valuation!$E$5/(1+D$4)^4+Valuation!$F$5/(1+D$4)^5+IF(D$4>$A7,Valuation!$F$5*(1+$A7)/(D$4-$A7)/(1+D$4)^5,0)+Valuation!$B$14-Valuation!$B$15)/Valuation!$B$17)*Assumptions!$E$22*Assumptions!$E$23 -> 743.13497 | E7: =((Valuation!$B$5/(1+E$4)^1+Valuation!$C$5/(1+E$4)^2+Valuation!$D$5/(1+E$4)^3+Valuation!$E$5/(1+E$4)^4+Valuation!$F$5/(1+E$4)^5+IF(E$4>$A7,Valuation!$F$5*(1+$A7)/(E$4-$A7)/(1+E$4)^5,0)+Valuation!$B$14-Valuation!$B$15)/Valuation!$B$17)*Assumptions!$E$22*Assumptions!$E$23 -> 630.60061 | F7: =((Valuation!$B$5/(1+F$4)^1+Valuation!$C$5/(1+F$4)^2+Valuation!$D$5/(1+F$4)^3+Valuation!$E$5/(1+F$4)^4+Valuation!$F$5/(1+F$4)^5+IF(F$4>$A7,Valuation!$F$5*(1+$A7)/(F$4-$A7)/(1+F$4)^5,0)+Valuation!$B$14-Valuation!$B$15)/Valuation!$B$17)*Assumptions!$E$22*Assumptions!$E$23 -> 548.16131
A8: =Assumptions!$E$21+0.005 -> 0.035 | B8: =((Valuation!$B$5/(1+B$4)^1+Valuation!$C$5/(1+B$4)^2+Valuation!$D$5/(1+B$4)^3+Valuation!$E$5/(1+B$4)^4+Valuation!$F$5/(1+B$4)^5+IF(B$4>$A8,Valuation!$F$5*(1+$A8)/(B$4-$A8)/(1+B$4)^5,0)+Valuation!$B$14-Valuation!$B$15)/Valuation!$B$17)*Assumptions!$E$22*Assumptions!$E$23 -> 1329.8574 | C8: =((Valuation!$B$5/(1+C$4)^1+Valuation!$C$5/(1+C$4)^2+Valuation!$D$5/(1+C$4)^3+Valuation!$E$5/(1+C$4)^4+Valuation!$F$5/(1+C$4)^5+IF(C$4>$A8,Valuation!$F$5*(1+$A8)/(C$4-$A8)/(1+C$4)^5,0)+Valuation!$B$14-Valuation!$B$15)/Valuation!$B$17)*Assumptions!$E$22*Assumptions!$E$23 -> 1000.3226 | D8: =((Valuation!$B$5/(1+D$4)^1+Valuation!$C$5/(1+D$4)^2+Valuation!$D$5/(1+D$4)^3+Valuation!$E$5/(1+D$4)^4+Valuation!$F$5/(1+D$4)^5+IF(D$4>$A8,Valuation!$F$5*(1+$A8)/(D$4-$A8)/(1+D$4)^5,0)+Valuation!$B$14-Valuation!$B$15)/Valuation!$B$17)*Assumptions!$E$22*Assumptions!$E$23 -> 802.73285 | E8: =((Valuation!$B$5/(1+E$4)^1+Valuation!$C$5/(1+E$4)^2+Valuation!$D$5/(1+E$4)^3+Valuation!$E$5/(1+E$4)^4+Valuation!$F$5/(1+E$4)^5+IF(E$4>$A8,Valuation!$F$5*(1+$A8)/(E$4-$A8)/(1+E$4)^5,0)+Valuation!$B$14-Valuation!$B$15)/Valuation!$B$17)*Assumptions!$E$22*Assumptions!$E$23 -> 671.11053 | F8: =((Valuation!$B$5/(1+F$4)^1+Valuation!$C$5/(1+F$4)^2+Valuation!$D$5/(1+F$4)^3+Valuation!$E$5/(1+F$4)^4+Valuation!$F$5/(1+F$4)^5+IF(F$4>$A8,Valuation!$F$5*(1+$A8)/(F$4-$A8)/(1+F$4)^5,0)+Valuation!$B$14-Valuation!$B$15)/Valuation!$B$17)*Assumptions!$E$22*Assumptions!$E$23 -> 577.17975
A9: =Assumptions!$E$21+0.01 -> 0.04 | B9: =((Valuation!$B$5/(1+B$4)^1+Valuation!$C$5/(1+B$4)^2+Valuation!$D$5/(1+B$4)^3+Valuation!$E$5/(1+B$4)^4+Valuation!$F$5/(1+B$4)^5+IF(B$4>$A9,Valuation!$F$5*(1+$A9)/(B$4-$A9)/(1+B$4)^5,0)+Valuation!$B$14-Valuation!$B$15)/Valuation!$B$17)*Assumptions!$E$22*Assumptions!$E$23 -> 1565.2662 | C9: =((Valuation!$B$5/(1+C$4)^1+Valuation!$C$5/(1+C$4)^2+Valuation!$D$5/(1+C$4)^3+Valuation!$E$5/(1+C$4)^4+Valuation!$F$5/(1+C$4)^5+IF(C$4>$A9,Valuation!$F$5*(1+$A9)/(C$4-$A9)/(1+C$4)^5,0)+Valuation!$B$14-Valuation!$B$15)/Valuation!$B$17)*Assumptions!$E$22*Assumptions!$E$23 -> 1121.807 | D9: =((Valuation!$B$5/(1+D$4)^1+Valuation!$C$5/(1+D$4)^2+Valuation!$D$5/(1+D$4)^3+Valuation!$E$5/(1+D$4)^4+Valuation!$F$5/(1+D$4)^5+IF(D$4>$A9,Valuation!$F$5*(1+$A9)/(D$4-$A9)/(1+D$4)^5,0)+Valuation!$B$14-Valuation!$B$15)/Valuation!$B$17)*Assumptions!$E$22*Assumptions!$E$23 -> 875.5747 | E9: =((Valuation!$B$5/(1+E$4)^1+Valuation!$C$5/(1+E$4)^2+Valuation!$D$5/(1+E$4)^3+Valuation!$E$5/(1+E$4)^4+Valuation!$F$5/(1+E$4)^5+IF(E$4>$A9,Valuation!$F$5*(1+$A9)/(E$4-$A9)/(1+E$4)^5,0)+Valuation!$B$14-Valuation!$B$15)/Valuation!$B$17)*Assumptions!$E$22*Assumptions!$E$23 -> 718.98589 | F9: =((Valuation!$B$5/(1+F$4)^1+Valuation!$C$5/(1+F$4)^2+Valuation!$D$5/(1+F$4)^3+Valuation!$E$5/(1+F$4)^4+Valuation!$F$5/(1+F$4)^5+IF(F$4>$A9,Valuation!$F$5*(1+$A9)/(F$4-$A9)/(1+F$4)^5,0)+Valuation!$B$14-Valuation!$B$15)/Valuation!$B$17)*Assumptions!$E$22*Assumptions!$E$23 -> 610.66257

Sheet Checks
A1: Formula-driven model checks
A2: Critical checks must pass after native recalculation/reopen; source coverage is computed, never hardcoded.
A4: Assertion | B4: Actual | C4: Expected | D4: Difference | E4: Tolerance | F4: Status | G4: Severity | H4: Fix hint
A5: Source records verified | B5: =COUNTIF(Sources!$Q$5:$Q$97,"VERIFIED") -> 93 | C5: =COUNTA(Sources!$A$5:$A$97) -> 93 | D5: =B5-C5 -> 0 | E5: 0 | F5: =IF(AND(D5=0,C5>0),"PASS","FAIL") -> PASS | G5: Critical | H5: Complete missing ledger rows
A6: Historical source coverage | B6: =COUNTIF(Historical!$H$5:$H$20,"CHECK") -> 0 | C6: 0 | D6: =B6-C6 -> 0 | E6: 0 | F6: =IF(ABS(D6)<=E6,"PASS","FAIL") -> PASS | G6: Critical | H6: Resolve metric-to-source mapping
A7: Revenue driver tie | B7: =Forecast!G8 -> 49418.387 | C7: =Forecast!G5*Forecast!G6+Forecast!G7 -> 49418.387 | D7: =B7-C7 -> 0 | E7: 0.1 | F7: =IF(ABS(D7)<=E7,"PASS","FAIL") -> PASS | G7: Critical | H7: Repair bottom-up formula
A8: Operating income tie | B8: =Forecast!G16 -> 17938.874 | C8: =Forecast!G11-Forecast!G13-Forecast!G15 -> 17938.874 | D8: =B8-C8 -> 0 | E8: 0.1 | F8: =IF(ABS(D8)<=E8,"PASS","FAIL") -> PASS | G8: Critical | H8: Repair operating formula
A9: FCFF tie | B9: =Forecast!G25 -> 15396.98 | C9: =Forecast!G19+Forecast!G21-Forecast!G23-Forecast!G24 -> 15396.98 | D9: =B9-C9 -> 0 | E9: 0.1 | F9: =IF(ABS(D9)<=E9,"PASS","FAIL") -> PASS | G9: Critical | H9: Repair FCFF formula
A10: WACC exceeds terminal growth | B10: =Assumptions!E20 -> 0.085 | C10: =Assumptions!E21 -> 0.03 | D10: =B10-C10 -> 0.055 | E10: 0 | F10: =IF(D10>E10,"PASS","FAIL") -> PASS | G10: Critical | H10: Adjust WACC / g
A11: Valuation bridge | B11: =Valuation!B16 -> 251878.32 | C11: =Valuation!B13+Valuation!B14-Valuation!B15 -> 251878.32 | D11: =B11-C11 -> 0 | E11: 0.1 | F11: =IF(ABS(D11)<=E11,"PASS","FAIL") -> PASS | G11: Critical | H11: Repair bridge
A12: Sensitivity center tie | B12: =Sensitivity!D7 -> 743.13497 | C12: =Valuation!B21 -> 743.13497 | D12: =B12-C12 -> 0 | E12: 0.1 | F12: =IF(ABS(D12)<=E12,"PASS","FAIL") -> PASS | G12: Critical | H12: Repair matrix
A13: Scenario selector valid | B13: =Assumptions!B3 -> 1 | C13: 1 | D13: =IF(OR(B13=1,B13=2,B13=3),0,1) -> 0 | E13: 0 | F13: =IF(D13=0,"PASS","FAIL") -> PASS | G13: Critical | H13: Reset 1/2/3
A14: Forecast revenue non-negative | B14: =MIN(Forecast!C8:G8) -> 35995.216 | C14: 0 | D14: =B14-C14 -> 35995.216 | E14: 0 | F14: =IF(D14>=0,"PASS","FAIL") -> PASS | G14: Critical | H14: Review drivers
A15: Cash and debt non-negative | B15: =MIN(Forecast!B26:G27) -> 2709 | C15: 0 | D15: =B15-C15 -> 2709 | E15: 0 | F15: =IF(D15>=0,"PASS","FAIL") -> PASS | G15: Critical | H15: Review balances
A16: Traded-security price positive | B16: =Valuation!B21 -> 743.13497 | C16: 0 | D16: =B16-C16 -> 743.13497 | E16: 0 | F16: =IF(D16>0,"PASS","FAIL") -> PASS | G16: Critical | H16: Review FX / ADR bridge
A17: Semantic KPI links | B17: 8 | C17: 8 | D17: =B17-C17 -> 0 | E17: 0 | F17: =IF(AND(ABS(Sector_KPIs!D5-Forecast!G5*Forecast!G6)<0.1,ABS(Sector_KPIs!D6-Forecast!G7)<0.1,ABS(Sector_KPIs!D7-Forecast!G5)<0.1,ABS(Sector_KPIs!D8-Forecast!G6)<0.1,ISTEXT(Sector_KPIs!D9),ABS(Sector_KPIs!D10-Forecast!G10)<0.000001,ABS(Sector_KPIs!D11-Forecast!C8)<0.1,ABS(Sector_KPIs!D12-Forecast!C8)<0.1),"PASS","FAIL") -> PASS | G17: Critical | H17: Repair company-specific KPI links
A18: KPI unit / range sanity | B18: =1 -> 1 | C18: =1 -> 1 | D18: =B18-C18 -> 0 | E18: 0 | F18: =IF(AND(Sector_KPIs!B5>0,Sector_KPIs!B6>0,Sector_KPIs!B7>0,Sector_KPIs!B8>0,Sector_KPIs!B9>0,Sector_KPIs!B10>=0,Sector_KPIs!B10<=1,Sector_KPIs!B11>0,Sector_KPIs!B12>=Sector_KPIs!B11,Sector_KPIs!D5>0,Sector_KPIs!D6>0,Sector_KPIs!D7>0,Sector_KPIs!D8>0,Sector_KPIs!D10>=0,Sector_KPIs!D10<=1,Sector_KPIs!D11>0,Sector_KPIs!D12>0),"PASS","FAIL") -> PASS | G18: Critical | H18: Repair units or economic ranges
A19: Source target-cell link coverage | B19: =COUNTA(Sources!$L$5:$L$97) -> 93 | C19: =COUNTA(Sources!$A$5:$A$97) -> 93 | D19: =B19-C19 -> 0 | E19: 0 | F19: =IF(ABS(D19)<=E19,"PASS","FAIL") -> PASS | G19: Critical | H19: Add exact sheet-and-cell targets
A20: Source unit completeness | B20: =COUNTBLANK(Sources!$E$5:$E$97) -> 0 | C20: 0 | D20: =B20-C20 -> 0 | E20: 0 | F20: =IF(ABS(D20)<=E20,"PASS","FAIL") -> PASS | G20: Critical | H20: Populate source units
A21: Exact source URL completeness | B21: =COUNTA(Sources!$N$5:$N$97) -> 93 | C21: =COUNTA(Sources!$A$5:$A$97) -> 93 | D21: =B21-C21 -> 0 | E21: 0 | F21: =IF(ABS(D21)<=E21,"PASS","FAIL") -> PASS | G21: Critical | H21: Use exact primary-source URLs
A23: Overall gate | B23: =IF(COUNTIF(F5:F21,"FAIL")=0,"PASS","FAIL") -> PASS
A24: Decision use | B24: Owner-ready only after independent review

Sheet Sector_KPIs
A1: Semiconductor operating KPI framework
A2: Reported sector drivers plus formula-linked active outputs; no generic blanks.
A4: KPI | B4: Reported latest | C4: Unit | D4: Forecast / active output | E4: Source / method | F4: Status
A5: Net system sales | B5: 24474.3 | C5: EURm | D5: =Forecast!G5*Forecast!G6 -> 37101.871 | E5: Official FY2025 annual report | F5: =IF(COUNTIF(Sources!$L$5:$L$97,"Sector_KPIs!B5")>=1,"VERIFIED","CHECK") -> VERIFIED
A6: Installed Base Management sales | B6: 8193 | C6: EURm | D6: =Forecast!G7 -> 12316.516 | E6: Official FY2025 annual report | F6: =IF(COUNTIF(Sources!$L$5:$L$97,"Sector_KPIs!B6")>=1,"VERIFIED","CHECK") -> VERIFIED
A7: Systems sold | B7: 535 | C7: systems | D7: =Forecast!G5 -> 666.68826 | E7: 48 EUV + 279 DUV + 208 metrology/inspection | F7: =IF(COUNTIF(Sources!$L$5:$L$97,"Sector_KPIs!B7")>=1,"VERIFIED","CHECK") -> VERIFIED
A8: Average revenue / system | B8: =IF(B7<>0,B5/B7,0) -> 45.746355 | C8: EURm / system | D8: =Forecast!G6 -> 55.651004 | E8: Formula-derived from net system sales and systems sold | F8: =IF(COUNTIF(Sources!$L$5:$L$97,"Sector_KPIs!B8")>=1,"VERIFIED","CHECK") -> VERIFIED
A9: Year-end backlog | B9: 38797 | C9: EURm | D9: ="Context only / reported backlog" -> Context only / reported backlog | E9: Official FY2025 annual report | F9: =IF(COUNTIF(Sources!$L$5:$L$97,"Sector_KPIs!B9")>=1,"VERIFIED","CHECK") -> VERIFIED
A10: Gross margin | B10: 0.528 | C10: % | D10: =Forecast!G10 -> 0.545 | E10: Official FY2025 annual report | F10: =IF(COUNTIF(Sources!$L$5:$L$97,"Sector_KPIs!B10")>=1,"VERIFIED","CHECK") -> VERIFIED
A11: 2026 revenue guidance low | B11: 34000 | C11: EURm | D11: =Forecast!C8 -> 35995.216 | E11: Official Q4 FY2025 results | F11: =IF(COUNTIF(Sources!$L$5:$L$97,"Sector_KPIs!B11")>=1,"VERIFIED","CHECK") -> VERIFIED
A12: 2026 revenue guidance high | B12: 39000 | C12: EURm | D12: =Forecast!C8 -> 35995.216 | E12: Official Q4 FY2025 results | F12: =IF(COUNTIF(Sources!$L$5:$L$97,"Sector_KPIs!B12")>=1,"VERIFIED","CHECK") -> VERIFIED

Sheet Change_Log
A1: Change log and governance
A2: Controlled rebuild; prior workbook preserved unchanged.
A4: Date | B4: Version | C4: Author | D4: Change | E4: Evidence | F4: Reviewer status | G4: Disposition
A5: 2026-07-16 | B5: 2.0 | C5: Codex | D5: Preserved prior ten sheets; appended Gate_9of10 | E5: Prior SHA-256 20c141773a2c775de7cfa826f5a62e4986727cdbe8baf5a5e6f46e579487e3eb | F5: Builder verified | G5: No overwrite
A6: 2026-07-16 | B6: 2.0 | C6: Codex | D6: Native-currency exact-source history | E6: Sources + Historical | F6: Builder verified | G6: Independent review pending
A7: 2026-07-16 | B7: 2.0 | C7: Codex | D7: Company-specific forecast, DCF, sensitivity and checks | E7: Forecast + Valuation + Checks | F7: Builder verified | G7: Independent review pending
A8: 2026-07-16 | B8: 2.0 | C8: Codex | D8: Native recalc/reopen and full-sheet QA | E8: internal QA evidence (not published) | F8: Post-LO evidence | G8: Independent review pending
A9: 2026-07-16 | B9: 2.1 | C9: Codex | D9: Repaired KPI semantics, exact source targets, unit/range/link gates and TSMC H1/H2/H5 | E9: Sector_KPIs + Sources + Checks + Gate_9of10 | F9: High-effort repair; independent review pending | G9: Frozen only after native recalc and hash-bound QA
A10: 46224 | B10: 2.2 | C10: Claude (run 24e4a1f1) | D10: Ola 2 elevation: added IS_Hist/CF_Hist (FY2022A-25A), BS_Hist/SCE_Hist (FY2023A-25A) full line-item audited statements, Checks_TieOut (cross-statement + dual-filing consistency), Sources_Audited. Fixed Forecast!C26:G26 frozen cash/debt defect — cash now rolls forward via FCFF less a documented payout-ratio driver (Assumptions!E26); debt kept flat under an explicit documented assumption (Assumptions!B27), not a bare self-reference. | E10: Sources: 20-F_2025-12-31 (accn 0001628280-26-011378) R3/R4/R6/R7/R8/R10/R11; 20-F_2024-12-31_Financial_Report.xlsx; companyfacts.json | F10: Builder verified | G10: Independent review pending; FY2021A-22A BS and FY2021A IS/CF full line-item detail remain a documented gap (PARTIAL), not fabricated
A11: 2026-08-14 | B11: 2.3 | C11: Claude (builder de cobertura, Ola 1 flota internacional) | D11: Capa de cobertura aditiva segun plantilla Apple: hojas nuevas Drivers_MDA (drivers del 20-F FY2021A-FY2025A: lineas de negocio, tecnologia/unidades/ASP, end-use, geografia, long-lived assets, backlog/RPO/contract liabilities, clientes, empleados, FX, deuda, retornos, guidance, NOT_AVAILABLE, puente al Forecast) y Market_Package (doble cotizacion EUR/USD fechada, puente a EV, WACC fechado, multiplos, implicitos del DCF, control de procedencia, anclas de extraccion independiente); 26 tie-outs nuevos en Checks_TieOut filas 36-61. UNICA celda preexistente modificada: Checks_TieOut!B2 (rango del COUNTIF ampliado J5:J33 -> J5:J61 — endurece el gate). Forecast intacto (fuera de alcance de la ola). | E11: Respaldo pre-cobertura SHA-256 5e7a68fb8aa65786786f32c5b4de1bbd22d8ae619d2b088df22193c2427751ef; fuentes: 20-F FY2021-FY2025 locales (asml/) + mercado fechado 2026-08-13/14 | F11: Builder verificado; refutacion independiente pendiente | G11: NOTA de gobernanza: Checks_TieOut NO esta cableado a Checks!B23 ni a Gate_9of10 (hallazgo M1 heredado del patron de flota); el MASTER de esta hoja es el gate de la capa. Cablearlo requiere tocar Checks — fuera del alcance de esta capa.

Sheet Gate_9of10
A1: 9-of-10 gate evidence
A2: Owner evidence register aligned exactly to the governing independent rubric; PASS means ready for review, not self-certification.
A4: Gate | B4: Weight | C4: Earned | D4: Status | E4: Exact workbook / external evidence | F4: Blocker class | G4: Notes
A5: H0 Controlled lineage / package | B5: 5 | C5: =IF(D5="PASS",B5,0) -> 5 | D5: PASS | E5: Change_Log!A5:G5; internal QA evidence (not published) | F5: Lineage | G5: Prior file preserved; 10-sheet order + Gate_9of10
A6: H1 Source fidelity | B6: 20 | C6: =IF(D6="PASS",B6,0) -> 20 | D6: =IF(AND(Checks!F5="PASS",Checks!F6="PASS",COUNTIF(Checks!F19:F21,"FAIL")=0),"PASS","FAIL") -> PASS | E6: Sources!A4:R; Checks!A5:F6; Checks!A19:F21 | F6: Source | G6: Claim-level exact-source ledger
A7: H2 Historical / formula / schedule mechanics | B7: 15 | C7: =IF(D7="PASS",B7,0) -> 15 | D7: =IF(AND(COUNTIF(Historical!H5:H20,"CHECK")=0,COUNTIF(Checks!F7:F9,"FAIL")=0,Checks!F17="PASS",Checks!F18="PASS"),"PASS","FAIL") -> PASS | E7: Historical!A4:H20; Forecast!A5:G28; Sector_KPIs!A4:F12; Checks!A7:F9; Checks!A17:F18 | F7: Mechanics | G7: Native history and formula-driven operating schedule
A8: H3 Scenario / sensitivity | B8: 10 | C8: =IF(D8="PASS",B8,0) -> 10 | D8: =IF(AND(Checks!F12="PASS",Checks!F13="PASS"),"PASS","FAIL") -> PASS | E8: Assumptions!B3:E24; Sensitivity!A4:F9; Checks!A12:F13 | F8: Scenario | G8: B/B/B perturb-reset evidence in support JSON
A9: H4 Valuation fit / mechanics | B9: 15 | C9: =IF(D9="PASS",B9,0) -> 15 | D9: =IF(AND(Checks!F10="PASS",Checks!F11="PASS",Checks!F12="PASS",Valuation!B21>0),"PASS","FAIL") -> PASS | E9: Valuation!A4:G23; Checks!A10:F12 | F9: Valuation | G9: Native-currency DCF and dated security bridge
A10: H5 Checks / error state | B10: 8 | C10: =IF(D10="PASS",B10,0) -> 8 | D10: =IF(Checks!B23="PASS","PASS","FAIL") -> PASS | E10: Checks!A4:H23; internal QA evidence (not published) | F10: Checks | G10: All critical checks and post-recalc error scan
A11: H6 Native recalc / reproducibility | B11: 10 | C11: =IF(D11="PASS",B11,0) -> 10 | D11: PASS | E11: internal QA evidence (not published) | native LibreOffice x2 + reopen | F11: Recalc | G11: Two unique LibreOffice profiles; evidence bound to final SHA-256
A12: H7 Post-recalc visual QA | B12: 7 | C12: =IF(D12="PASS",B12,0) -> 7 | D12: PASS | E12: internal QA evidence (not published) | F12: Visual | G12: Every final sheet rendered and reviewed
A13: H8 Economic upgrade | B13: 5 | C13: =IF(D13="PASS",B13,0) -> 5 | D13: =IF(AND(Forecast!G8>0,COUNTIF(Sector_KPIs!F5:F12,"VERIFIED")=8,Checks!F17="PASS",Checks!F18="PASS"),"PASS","FAIL") -> PASS | E13: Forecast!A5:G28; Sector_KPIs!A4:F | F13: Economics | G13: Company-specific semiconductor operating build
A14: H9 Governance / handoff | B14: 5 | C14: =IF(D14="PASS",B14,0) -> 5 | D14: PASS | E14: 00_Cover!A14:B18; Change_Log!A4:G8; Gate_9of10!A16:B18 | F14: Governance | G14: Independent certification remains pending
A16: Owner score | B16: =SUM(C5:C14) -> 100
A17: Decision | B17: =IF(AND(B16>=90,COUNTIF(D5:D14,"FAIL")=0),"READY FOR INDEPENDENT 9/10 REVIEW","OWNER DEMOTION / REMEDIATE") -> READY FOR INDEPENDENT 9/10 REVIEW
A18: Independent certification | B18: PENDING

Sheet IS_Hist
A1: ASML Holding N.V. — Consolidated Statements of Operations (audited, as published)
A2: EUR millions, shares in millions. FY2022A-FY2024A per 20-F_2024-12-31 Financial_Report.xlsx; FY2023A-FY2025A per 20-F_2025-12-31 R3/R4 (FY2023A & FY2024A byte-identical across both filings — verified in Checks_TieOut).
A4: Line item | B4: FY2022A | C4: FY2023A | D4: FY2024A | E4: FY2025A | G4: Note ref
A5: Total net sales | B5: 21173.4 | C5: 27558.5 | D5: 28262.9 | E5: 32667.3
A6: Total cost of sales | B6: -10473.3 | C6: -13422.4 | D6: -13770.9 | E6: -15409.3 | G6: 1
A7: Gross profit | B7: 10700.1 | C7: 14136.1 | D7: 14492 | E7: 17258
A8: Research and development (R&D) costs | B8: -3253.5 | C8: -3980.6 | D8: -4303.7 | E8: -4698.8
A9: Selling, general and administrative (SG&A) costs | B9: -945.9 | C9: -1113.2 | D9: -1165.7 | E9: -1257.8
A10: Income from operations | B10: 6500.7 | C10: 9042.3 | D10: 9022.6 | E10: 11301.4
A11: Interest and other, net | B11: -44.6 | C11: 41.2 | D11: 19.8 | E11: 104.7
A12: Income before income taxes | B12: 6456.1 | C12: 9083.5 | D12: 9042.4 | E12: 11406.1
A13: Income tax expense | B13: -969.9 | C13: -1435.8 | D13: -1680.6 | E13: -2013.4
A14: Income after income taxes | B14: 5486.2 | C14: 7647.7 | D14: 7361.8 | E14: 9392.7
A15: Profit from equity method investments | B15: 138 | C15: 191.3 | D15: 209.8 | E15: 216.7
A16: Net income | B16: 5624.2 | C16: 7839 | D16: 7571.6 | E16: 9609.4
A17: Basic net income per ordinary share (EUR) | B17: 14.14 | C17: 19.91 | D17: 19.25 | E17: 24.73
A18: Diluted net income per ordinary share (EUR) | B18: 14.13 | C18: 19.89 | D18: 19.24 | E18: 24.71
... A20: Diluted weighted-average shares (mm) | B20: 398 | C20: 394.1 | D20: 393.6 | E20: 388.9
A22: Memo — net sales by category
A23: Net system sales | B23: 15430.3 | C23: 21938.6 | D23: 21768.7 | E23: 24474.3
A24: Net system cost of sales | B24: -7582.3 | C24: -10151 | D24: -10406.9 | E24: -11384
A25: Net service and field option sales | B25: 5743.1 | C25: 5619.9 | D25: 6494.2 | E25: 8193
A26: Net service and field option cost of sales | B26: -2891 | C26: -3271.4 | D26: -3364 | E26: -4025.3

Sheet CF_Hist
A1: ASML Holding N.V. — Consolidated Statements of Cash Flows (audited, as published)
A2: EUR millions. Same dual-filing source basis as IS_Hist; signs as published (outflows negative). Blank/0.0 = line not presented that year in the source filing.
A4: Line item | B4: FY2022A | C4: FY2023A | D4: FY2024A | E4: FY2025A | G4: Note ref
A5: Net income | B5: 5624.2 | C5: 7839 | D5: 7571.6 | E5: 9609.4
A6: Adjustments to reconcile net income to operating cash flows:
A7: Depreciation and amortization | B7: 583.6 | C7: 739.8 | D7: 918.6 | E7: 1025.9 | G7: 1
A8: Impairment and loss on disposal | B8: 39.3 | C8: 37.5 | D8: 35.8 | E8: 49.7
A9: Share-based compensation expense | B9: 68.9 | C9: 134.8 | D9: 172.6 | E9: 202.3
A10: Inventory reserves | B10: 278.5 | C10: 485.3 | D10: 554.7 | E10: 469.4
A11: Deferred tax expense (benefit) | B11: -564.2 | C11: -133.6 | D11: -144.8 | E11: 180.7
A12: Equity method investments | B12: 15.3 | C12: 4.2 | D12: 4.4 | E12: 94.6 | G12: 2
A13: Changes in assets and liabilities:
A14: Accounts receivable, net | B14: -2338 | C14: 959.9 | D14: -139.9 | E14: 1415.5
A15: Finance receivables, net | B15: 212.2 | C15: -88.6 | D15: 1038.7 | E15: -227.2
A16: Inventories | B16: -2080.9 | C16: -1646.9 | D16: -1860.9 | E16: -832.5
A17: Other assets | B17: -864.3 | C17: -344.3 | D17: -1299 | E17: -561.9
A18: Accrued and other liabilities | B18: 439.7 | C18: 222 | D18: 625.5 | E18: -237.3
A19: Accounts payable | B19: 406.2 | C19: -261.7 | D19: 1127.6 | E19: 13.4
A20: Current tax assets and liabilities | B20: 33.6 | C20: -939.4 | D20: 689.5 | E20: 334.1
A21: Contract assets and liabilities | B21: 6632.7 | C21: -1564.6 | D21: 1871.8 | E21: 1122.4
A22: Net cash provided by operating activities | B22: 8486.8 | C22: 5443.4 | D22: 11166.2 | E22: 12658.5
A23: Investing activities
A24: Purchase of property, plant and equipment | B24: -1281.8 | C24: -2155.6 | D24: -2067.2 | E24: -1573.6 | G24: 3
A25: Purchase of intangible assets | B25: -37.5 | C25: -40.6 | D25: -15.9 | E25: -57.6
A26: Purchase of short-term investments | B26: -334.3 | C26: -23.6 | D26: -305.2 | E26: -406.2
A27: Maturity of short-term investments | B27: 864.7 | C27: 125.6 | D27: 305.2 | E27: 5.3
A28: Purchase of equity investments | B28: 0 | C28: 0 | D28: 0 | E28: -1302.2
A29: Loans issued and other investments | B29: -240 | C29: -561.5 | D29: -526.2 | E29: -703.7 | G29: 4
A30: Repayment on loans | B30: 0 | C30: 0 | D30: 0 | E30: 260.2
A31: Acquisition of subsidiaries (net of cash acquired) | B31: 0 | C31: -33.6 | D31: 0 | E31: 0
A32: Net cash used in investing activities | B32: -1028.9 | C32: -2689.3 | D32: -2609.3 | E32: -3777.8
A33: Financing activities
A34: Dividend paid | B34: -2559.8 | C34: -2348.3 | D34: -2452.9 | E34: -2550.3
A35: Purchase of treasury shares | B35: -4639.7 | C35: -1000 | D35: -500 | E35: -5950
A36: Net proceeds from issuance of shares | B36: 81.8 | C36: 99.4 | D36: 124 | E36: 142.3
A37: Net proceeds from issuance of notes / borrowings | B37: 495.6 | C37: 997.8 | D37: 22.5 | E37: 754.2
A38: Repayment of debt and finance lease obligations | B38: -516.2 | C38: -752.8 | D38: -25.7 | E38: -1066.7
A39: Net cash used in financing activities | B39: -7138.3 | C39: -3003.9 | D39: -2832.1 | E39: -8670.5
A40: Net cash flows | B40: 319.6 | C40: -249.8 | D40: 5724.8 | E40: 210.2
A41: Effect of foreign exchange rate changes | B41: -3.1 | C41: -13.8 | D41: 6.4 | E41: -30.1
...

Sheet BS_Hist
A1: ASML Holding N.V. — Consolidated Balance Sheets (audited, as published)
A2: EUR millions, as of December 31. FY2023A-FY2024A per 20-F_2024-12-31 Financial_Report.xlsx; FY2024A-FY2025A per 20-F_2025-12-31 R6/R7 (FY2024A byte-identical across both filings). FY2021A-FY2022A full line-item BS not in this source package — documented gap; Historical!B15:C19 retains the previously verified 5-yr summary aggregates unchanged.
A4: Line item | B4: FY2023A | C4: FY2024A | D4: FY2025A | F4: Note ref
A5: Assets
A6: Cash and cash equivalents | B6: 7004.7 | C6: 12735.9 | D6: 12916
A7: Short-term investments | B7: 5.4 | C7: 5.4 | D7: 405.9
A8: Accounts receivable, net | B8: 4334.1 | C8: 4477.5 | D8: 3023 | F8: 1
A9: Finance receivables, net (current) | B9: 1379.2 | C9: 82.6 | D9: 613.5
A10: Current tax assets | B10: 1001.2 | C10: 283.6 | D10: 88.9
A11: Contract assets | B11: 240.1 | C11: 320.6 | D11: 440.6
A12: Inventories, net | B12: 8850.7 | C12: 10891.5 | D12: 11429.3
A13: Loans receivable (current) | B13: 0 | C13: 0 | D13: 266.1 | F13: 2
A14: Other assets (current) | B14: 1578.5 | C14: 1940.3 | D14: 1432.8 | F14: 3
A15: Total current assets | B15: 24393.9 | C15: 30737.4 | D15: 30616.1
A16: Finance receivables, net (non-current) | B16: 60.6 | C16: 317.2 | D16: 13.3
A17: Deferred tax assets | B17: 1872.3 | C17: 1940.7 | D17: 1719.4
A18: Loans receivable (non-current) | B18: 929.2 | C18: 1456.6 | D18: 1653.9 | F18: 4
A19: Other assets (non-current) | B19: 651.8 | C19: 790.8 | D19: 1057.1 | F19: 5
A20: Equity investments | B20: 0 | C20: 0 | D20: 1320.7
A21: Equity method investments | B21: 919.6 | C21: 903 | D21: 822.6
A22: Goodwill | B22: 4588.6 | C22: 4588.6 | D22: 4588.6
A23: Other intangible assets, net | B23: 741.7 | C23: 621.3 | D23: 540.1
A24: Property, plant and equipment, net | B24: 5493.2 | C24: 6846.8 | D24: 7893.8
A25: Right-of-use assets | B25: 306.6 | C25: 387.2 | D25: 341
A26: Total non-current assets | B26: 15563.6 | C26: 17852.2 | D26: 19950.5
A27: Total assets | B27: 39957.5 | C27: 48589.6 | D27: 50566.6
A28: Liabilities and shareholders’ equity
A29: Accounts payable | B29: 2347.3 | C29: 3500.4 | D29: 3521.8 | F29: 6
A30: Accrued and other liabilities (current) | B30: 2177.4 | C30: 2686.6 | D30: 2567.3 | F30: 7
A31: Current tax liabilities | B31: 308.9 | C31: 283.3 | D31: 486.6
A32: Short-term borrowings / current portion of long-term debt | B32: 0.1 | C32: 1010.3 | D32: 1681.9
A33: Contract liabilities (current) | B33: 11441 | C33: 12570.8 | D33: 16006.3
A34: Total current liabilities | B34: 16274.7 | C34: 20051.4 | D34: 24263.9
A35: Long-term debt | B35: 4631.5 | C35: 3677.3 | D35: 2709
A36: Deferred and other income tax liabilities | B36: 372.2 | C36: 299.2 | D36: 183
A37: Contract liabilities (non-current) | B37: 4825.5 | C37: 5625.4 | D37: 3366.3
A38: Accrued and other liabilities (non-current) | B38: 401.2 | C38: 459.5 | D38: 432.2
A39: Total non-current liabilities | B39: 10230.4 | C39: 10061.4 | D39: 6690.5
A40: Total liabilities | B40: 26505.1 | C40: 30112.8 | D40: 30954.4 | F40: 8
A41: Issued and outstanding shares (par value) | B41: 36 | C41: 35.4 | D41: 34.9
...

Sheet SCE_Hist
A1: ASML Holding N.V. — Consolidated Statements of Shareholders’ Equity (audited, as published)
A2: EUR millions. Source: 20-F_2025-12-31 R8, rollforward from beginning balance at Dec 31, 2022 (€8,810.8mm, matches companyfacts.json us-gaap:StockholdersEquity). Each column is that fiscal year’s own movements.
A4: Line item | B4: FY2023A | C4: FY2024A | D4: FY2025A | F4: Note ref
A5: Beginning balance, total equity | B5: 8810.8 | C5: 13452.4 | D5: 18476.8
A6: Net income | B6: 7839 | C6: 7571.6 | D6: 9609.4
A7: Proportionate share of OCI from equity method investments | B7: 0.2 | C7: -12.1 | D7: 14.1
A8: Gain (loss) on foreign currency translation | B8: -68.3 | C8: 91.9 | D8: -257.8
A9: Gain (loss) on financial instruments | B9: -15.2 | C9: 29.3 | D9: -74.6
A10: Total comprehensive income | B10: 7755.7 | C10: 7680.7 | D10: 9291.1
A11: Purchase of treasury shares | B11: -1000 | C11: -500 | D11: -5950
A12: Cancellation of treasury shares (net zero, intra-equity reclass) | B12: 0 | C12: 0 | D12: 0
A13: Share-based payments | B13: 134.8 | C13: 172.6 | D13: 202.3
A14: Issuance of shares | B14: 99.4 | C14: 124 | D14: 142.3
A15: Dividend paid | B15: -2348.3 | C15: -2452.9 | D15: -2550.3
A16: Ending balance, total equity | B16: 13452.4 | C16: 18476.8 | D16: 19612.2

Sheet Checks_TieOut
A1: Tie-out checks — audited historical statements (all deltas must be 0; EUR millions)
A2: MASTER | B2: =IF(COUNTIF(J5:J61,"FAIL")=0,"OK — ALL TIE-OUTS PASS","FAIL") -> FAIL
B3: =COUNTIF(J5:J61,"PASS")&" PASS / "&(COUNTIF(J5:J61,"PASS")+COUNTIF(J5:J61,"FAIL"))&" checks" -> 54 PASS / 55 checks
A4: Check | F4: FY2022A | G4: FY2023A | H4: FY2024A | I4: FY2025A | J4: Status
A5: IS: Gross profit = Net sales − COGS | F5: =IS_Hist!B5+IS_Hist!B6-IS_Hist!B7 -> 0 | G5: =IS_Hist!C5+IS_Hist!C6-IS_Hist!C7 -> 0 | H5: =IS_Hist!D5+IS_Hist!D6-IS_Hist!D7 -> 0 | I5: =IS_Hist!E5+IS_Hist!E6-IS_Hist!E7 -> 0 | J5: =IF(AND(ABS(N(F5))<=0.5,ABS(N(G5))<=0.5,ABS(N(H5))<=0.5,ABS(N(I5))<=0.5),"PASS","FAIL") -> PASS
A6: IS: Income from ops = GP − R&D − SG&A | F6: =IS_Hist!B7+IS_Hist!B8+IS_Hist!B9-IS_Hist!B10 -> 0 | G6: =IS_Hist!C7+IS_Hist!C8+IS_Hist!C9-IS_Hist!C10 -> 0 | H6: =IS_Hist!D7+IS_Hist!D8+IS_Hist!D9-IS_Hist!D10 -> 0 | I6: =IS_Hist!E7+IS_Hist!E8+IS_Hist!E9-IS_Hist!E10 -> 0 | J6: =IF(AND(ABS(N(F6))<=0.5,ABS(N(G6))<=0.5,ABS(N(H6))<=0.5,ABS(N(I6))<=0.5),"PASS","FAIL") -> PASS
A7: IS: PBT = Ops income + interest/other | F7: =IS_Hist!B10+IS_Hist!B11-IS_Hist!B12 -> 0 | G7: =IS_Hist!C10+IS_Hist!C11-IS_Hist!C12 -> 0 | H7: =IS_Hist!D10+IS_Hist!D11-IS_Hist!D12 -> 0 | I7: =IS_Hist!E10+IS_Hist!E11-IS_Hist!E12 -> 0 | J7: =IF(AND(ABS(N(F7))<=0.5,ABS(N(G7))<=0.5,ABS(N(H7))<=0.5,ABS(N(I7))<=0.5),"PASS","FAIL") -> PASS
A8: IS: Income after tax = PBT − tax | F8: =IS_Hist!B12+IS_Hist!B13-IS_Hist!B14 -> 0 | G8: =IS_Hist!C12+IS_Hist!C13-IS_Hist!C14 -> 0 | H8: =IS_Hist!D12+IS_Hist!D13-IS_Hist!D14 -> 0 | I8: =IS_Hist!E12+IS_Hist!E13-IS_Hist!E14 -> 0 | J8: =IF(AND(ABS(N(F8))<=0.5,ABS(N(G8))<=0.5,ABS(N(H8))<=0.5,ABS(N(I8))<=0.5),"PASS","FAIL") -> PASS
A9: IS: Net income = after-tax + equity method | F9: =IS_Hist!B14+IS_Hist!B15-IS_Hist!B16 -> 0 | G9: =IS_Hist!C14+IS_Hist!C15-IS_Hist!C16 -> 0 | H9: =IS_Hist!D14+IS_Hist!D15-IS_Hist!D16 -> 0 | I9: =IS_Hist!E14+IS_Hist!E15-IS_Hist!E16 -> 0 | J9: =IF(AND(ABS(N(F9))<=0.5,ABS(N(G9))<=0.5,ABS(N(H9))<=0.5,ABS(N(I9))<=0.5),"PASS","FAIL") -> PASS
A10: IS: Net sales = system + service memo | F10: =IS_Hist!B23+IS_Hist!B25-IS_Hist!B5 -> 0 | G10: =IS_Hist!C23+IS_Hist!C25-IS_Hist!C5 -> 0 | H10: =IS_Hist!D23+IS_Hist!D25-IS_Hist!D5 -> 0 | I10: =IS_Hist!E23+IS_Hist!E25-IS_Hist!E5 -> 0 | J10: =IF(AND(ABS(N(F10))<=0.5,ABS(N(G10))<=0.5,ABS(N(H10))<=0.5,ABS(N(I10))<=0.5),"PASS","FAIL") -> PASS
A11: CF: CFO build sums to reported CFO | F11: =SUM(CF_Hist!B5:B21)-CF_Hist!B22 -> 0 | G11: =SUM(CF_Hist!C5:C21)-CF_Hist!C22 -> 0 | H11: =SUM(CF_Hist!D5:D21)-CF_Hist!D22 -> 0 | I11: =SUM(CF_Hist!E5:E21)-CF_Hist!E22 -> 0 | J11: =IF(AND(ABS(N(F11))<=0.5,ABS(N(G11))<=0.5,ABS(N(H11))<=0.5,ABS(N(I11))<=0.5),"PASS","FAIL") -> PASS
A12: CF: CFI build sums to reported CFI | F12: =SUM(CF_Hist!B24:B31)-CF_Hist!B32 -> 0 | G12: =SUM(CF_Hist!C24:C31)-CF_Hist!C32 -> 0 | H12: =SUM(CF_Hist!D24:D31)-CF_Hist!D32 -> 0 | I12: =SUM(CF_Hist!E24:E31)-CF_Hist!E32 -> 0 | J12: =IF(AND(ABS(N(F12))<=0.5,ABS(N(G12))<=0.5,ABS(N(H12))<=0.5,ABS(N(I12))<=0.5),"PASS","FAIL") -> PASS
A13: CF: CFF build sums to reported CFF | F13: =SUM(CF_Hist!B34:B38)-CF_Hist!B39 -> 0 | G13: =SUM(CF_Hist!C34:C38)-CF_Hist!C39 -> 0 | H13: =SUM(CF_Hist!D34:D38)-CF_Hist!D39 -> 0 | I13: =SUM(CF_Hist!E34:E38)-CF_Hist!E39 -> 0 | J13: =IF(AND(ABS(N(F13))<=0.5,ABS(N(G13))<=0.5,ABS(N(H13))<=0.5,ABS(N(I13))<=0.5),"PASS","FAIL") -> PASS
A14: CF: Net change = CFO+CFI+CFF | F14: =CF_Hist!B22+CF_Hist!B32+CF_Hist!B39-CF_Hist!B40 -> 0 | G14: =CF_Hist!C22+CF_Hist!C32+CF_Hist!C39-CF_Hist!C40 -> 0 | H14: =CF_Hist!D22+CF_Hist!D32+CF_Hist!D39-CF_Hist!D40 -> 0 | I14: =CF_Hist!E22+CF_Hist!E32+CF_Hist!E39-CF_Hist!E40 -> 0 | J14: =IF(AND(ABS(N(F14))<=0.5,ABS(N(G14))<=0.5,ABS(N(H14))<=0.5,ABS(N(I14))<=0.5),"PASS","FAIL") -> PASS
A15: CF: End cash = begin + change + FX | F15: =CF_Hist!B43+CF_Hist!B40+CF_Hist!B41-CF_Hist!B44 -> 0 | G15: =CF_Hist!C43+CF_Hist!C40+CF_Hist!C41-CF_Hist!C44 -> 0 | H15: =CF_Hist!D43+CF_Hist!D40+CF_Hist!D41-CF_Hist!D44 -> 0 | I15: =CF_Hist!E43+CF_Hist!E40+CF_Hist!E41-CF_Hist!E44 -> 0 | J15: =IF(AND(ABS(N(F15))<=0.5,ABS(N(G15))<=0.5,ABS(N(H15))<=0.5,ABS(N(I15))<=0.5),"PASS","FAIL") -> PASS
A16: X: CF net income = IS net income | F16: =CF_Hist!B5-IS_Hist!B16 -> 0 | G16: =CF_Hist!C5-IS_Hist!C16 -> 0 | H16: =CF_Hist!D5-IS_Hist!D16 -> 0 | I16: =CF_Hist!E5-IS_Hist!E16 -> 0 | J16: =IF(AND(ABS(N(F16))<=0.5,ABS(N(G16))<=0.5,ABS(N(H16))<=0.5,ABS(N(I16))<=0.5),"PASS","FAIL") -> PASS
A17: BS: Total current assets sum | G17: =SUM(BS_Hist!B6:B14)-BS_Hist!B15 -> 0 | H17: =SUM(BS_Hist!C6:C14)-BS_Hist!C15 -> 0 | I17: =SUM(BS_Hist!D6:D14)-BS_Hist!D15 -> 0 | J17: =IF(AND(ABS(N(G17))<=0.5,ABS(N(H17))<=0.5,ABS(N(I17))<=0.5),"PASS","FAIL") -> PASS
A18: BS: Total non-current assets sum | G18: =SUM(BS_Hist!B16:B25)-BS_Hist!B26 -> 0 | H18: =SUM(BS_Hist!C16:C25)-BS_Hist!C26 -> 0 | I18: =SUM(BS_Hist!D16:D25)-BS_Hist!D26 -> 0 | J18: =IF(AND(ABS(N(G18))<=0.5,ABS(N(H18))<=0.5,ABS(N(I18))<=0.5),"PASS","FAIL") -> PASS
A19: BS: Total assets = CA + NCA | G19: =BS_Hist!B15+BS_Hist!B26-BS_Hist!B27 -> 0 | H19: =BS_Hist!C15+BS_Hist!C26-BS_Hist!C27 -> 0 | I19: =BS_Hist!D15+BS_Hist!D26-BS_Hist!D27 -> 0 | J19: =IF(AND(ABS(N(G19))<=0.5,ABS(N(H19))<=0.5,ABS(N(I19))<=0.5),"PASS","FAIL") -> PASS
A20: BS: Total current liabilities sum | G20: =SUM(BS_Hist!B29:B33)-BS_Hist!B34 -> 0 | H20: =SUM(BS_Hist!C29:C33)-BS_Hist!C34 -> 0 | I20: =SUM(BS_Hist!D29:D33)-BS_Hist!D34 -> 0 | J20: =IF(AND(ABS(N(G20))<=0.5,ABS(N(H20))<=0.5,ABS(N(I20))<=0.5),"PASS","FAIL") -> PASS
A21: BS: Total non-current liabilities sum | G21: =SUM(BS_Hist!B35:B38)-BS_Hist!B39 -> 0 | H21: =SUM(BS_Hist!C35:C38)-BS_Hist!C39 -> 0 | I21: =SUM(BS_Hist!D35:D38)-BS_Hist!D39 -> 0 | J21: =IF(AND(ABS(N(G21))<=0.5,ABS(N(H21))<=0.5,ABS(N(I21))<=0.5),"PASS","FAIL") -> PASS
