Workbook

Sheet EEFF
A1: Panama Power Holdings, Inc. y Subsidiarias
A2: Estados Financieros Auditados FY21-FY25
A3: en B/. sin escala
A5: Años | B5: FY21A | C5: FY22A | D5: FY23A | E5: FY24A | F5: FY25A | G5: FY26E | H5: FY27E | I5: FY28E | J5: FY29E | K5: FY30E
A6: Estado de Resultados
A7: Venta de energía | B7: 42793727 | C7: 57204243 | D7: 53187368 | E7: 55356497 | F7: 48358044
A8: Compras de energía y costos asociados | B8: 4427043 | C8: 8559953 | D8: 12013335 | E8: 9960198 | F8: 4986124
A9: Cargo de transmisión | B9: 1368202 | C9: 1850469 | D9: 2243773 | E9: 2503761 | F9: 1761951
A10: Total de costo de energía | B10: 5795245 | C10: 10410422 | D10: 14257108 | E10: 12463959 | F10: 6748075
A11: Ingresos por crédito fiscal y otros | B11: 869881 | C11: 1974498 | D11: 2169724 | E11: 642966 | F11: 1922207
A12: Depreciación y amortización | B12: 11878451 | C12: 11881633 | D12: 11997283 | E12: 12446869 | F12: 12521408
A13: Operación y mantenimiento | B13: 2400538 | C13: 2548375 | D13: 2841019 | E13: 2549512 | F13: 3004212
A14: Generales y administrativos | B14: 4588379 | C14: 5332929 | D14: 5554329 | E14: 5511351 | F14: 5684677
A15: Otras pérdidas netas | C15: 0 | D15: 127418
A16: Pérdida en activos no financieros | B16: 20000
A17: Pérdida en activos financieros | B17: 139398
A18: Total de gastos operativos | B18: 19026766 | C18: 19762937 | D18: 20520049 | E18: 20507732 | F18: 21210297
A19: Utilidad operativa | B19: 18841597 | C19: 29005382 | D19: 20579935 | E19: 23027772 | F19: 22321879
A20: Costos financieros | B20: 10739963 | C20: 10140045 | D20: 9645428 | E20: 9291709 | F20: 8681196
A21: Ingresos financieros | B21: -129032 | C21: -140572 | D21: -242921 | E21: -362555 | F21: -547419
A22: Costos financieros, neto | B22: 10610931 | C22: 9999473 | D22: 9402507 | E22: 8929154 | F22: 8133777
A23: Utilidad antes de impuesto sobre la renta | B23: 8230666 | C23: 19005909 | D23: 11177428 | E23: 14098618 | F23: 14188102
A24: Impuesto sobre la renta | B24: -3095130 | C24: -5342988 | D24: -3950425 | E24: -4617385 | F24: -4887298
A25: Utilidad neta integral | B25: 5135536 | C25: 13662921 | D25: 7227003 | E25: 9481233 | F25: 9300804
A27: Años | B27: FY21A | C27: FY22A | D27: FY23A | E27: FY24A | F27: FY25A | G27: FY26E | H27: FY27E | I27: FY28E | J27: FY29E | K27: FY30E
A28: Balance General
A29: Efectivo | B29: 9167597 | C29: 10955792 | D29: 10299859 | E29: 9494389 | F29: 11057503
A30: Depósito a plazo fijo mayor a 90 días | F30: 8000000
A31: Cuentas por cobrar | B31: 9794078 | C31: 10480520 | D31: 10514874 | E31: 10018368 | F31: 8602706
A32: Inventario de repuestos y suministros | B32: 1954889 | C32: 2283806 | D32: 2176373 | E32: 2315599 | F32: 2666409
A33: Gastos pagados por adelantado | B33: 189074 | C33: 171942 | D33: 1400465 | E33: 475685 | F33: 836786
A34: Crédito fiscal por inversión | B34: 1825438 | C34: 2648365 | D34: 1541175 | E34: 1829780 | F34: 0
A35: Otros activos | B35: 654057 | C35: 1115702 | D35: 510364 | E35: 551482 | F35: 497274
A36: Total de activos circulantes | B36: 23585133 | C36: 27656127 | D36: 26443110 | E36: 24685303 | F36: 31660678
A37: Activo financiero restringido | B37: 4206485 | C37: 4234822 | D37: 4033700 | E37: 4197349 | F37: 4260349
A38: Cuentas por cobrar, no circulante | B38: 213118
A39: Propiedad, planta y equipo, neto | B39: 289872297 | C39: 280225020 | D39: 278143135 | E39: 266144886 | F39: 254111593
A40: Plusvalía | B40: 7033750 | C40: 7033750 | D40: 7033750 | E40: 7033750 | F40: 7033750
A41: Costos de exploración y evaluación | B41: 173084 | C41: 174084
A42: Activos intangibles, neto | B42: 538918 | C42: 525826 | D42: 512733 | E42: 499640 | F42: 509989
...

Sheet Supuestos
A1: Panama Power Holdings, Inc. y Subsidiarias
A3: COLOR KEY: Input (azul) · Fórmula (negro) · Link inter-hoja (verde)
A4: Escenario (1=Base, 2=Bull, 3=Bear)
A5: Selector escenario | C5: 1 | M5: caso | N5: NOT_DISCLOSED | Q5: Input de escenario desde fuente citada o NOT_DISCLOSED.
A6: Escenario activo | C6: =CHOOSE($C$5,"Base","Bull","Bear") -> Base | M6: moneda del modelo | N6: NOT_DISCLOSED | Q6: Selector de caso activo C5: Base/Bull/Bear.
A8: Años | B8: FY21A | C8: FY22A | D8: FY23A | E8: FY24A | F8: FY25A | G8: FY26E | H8: FY27E | I8: FY28E | J8: FY29E | K8: FY30E | M8: Unidad | N8: Fuente / nota | Q8: Rationale
A10: A. PRODUCCIÓN POR PLANTA (MWh neto = MW × 8.760 h × CF; CF derivado de generación real, blended hidro+solar)
A11: Factor de planta NETO (CF) — activo | G11: =CHOOSE($C$5,G13,G14,G12) -> 0.41 | H11: =CHOOSE($C$5,H13,H14,H12) -> 0.41 | I11: =CHOOSE($C$5,I13,I14,I12) -> 0.41 | J11: =CHOOSE($C$5,J13,J14,J12) -> 0.41 | K11: =CHOOSE($C$5,K13,K14,K12) -> 0.41 | M11: % | N11: a working file kept by the maintainer | Q11: Selector de caso activo C5: Base/Bull/Bear.
A12: Bear | G12: 0.35 | H12: 0.35 | I12: 0.35 | J12: 0.35 | K12: 0.35 | M12: % | N12: a working file kept by the maintainer | Q12: Escenario driver citado; NOT_DISCLOSED si no hay fuente explícita.
A13: Base | G13: 0.41 | H13: 0.41 | I13: 0.41 | J13: 0.41 | K13: 0.41 | M13: % | N13: a working file kept by the maintainer | Q13: Escenario driver citado; NOT_DISCLOSED si no hay fuente explícita.
A14: Bull | G14: 0.46 | H14: 0.46 | I14: 0.46 | J14: 0.46 | K14: 0.46 | M14: % | N14: a working file kept by the maintainer | Q14: Escenario driver citado; NOT_DISCLOSED si no hay fuente explícita.
A15: Horas / año | B15: 8760 | C15: 8760 | D15: 8760 | E15: 8760 | F15: 8760 | G15: 8760 | H15: 8760 | I15: 8760 | J15: 8760 | K15: 8760 | M15: horas/año | N15: a working file kept by the maintainer | Q15: Input de escenario desde fuente citada o NOT_DISCLOSED.
A16: El Alto — 73.18 MW | G16: =73.18*G15*G11 -> 262833.29 | H16: =73.18*H15*H11 -> 262833.29 | I16: =73.18*I15*I11 -> 262833.29 | J16: =73.18*J15*J11 -> 262833.29 | K16: =73.18*K15*K11 -> 262833.29 | M16: MW | N16: a working file kept by the maintainer | Q16: Derivación mecánica por fórmula viva.
A17: Pedregalito 1 — 20.1 MW | G17: =20.1*G15*G11 -> 72191.16 | H17: =20.1*H15*H11 -> 72191.16 | I17: =20.1*I15*I11 -> 72191.16 | J17: =20.1*J15*J11 -> 72191.16 | K17: =20.1*K15*K11 -> 72191.16 | M17: MW | N17: a working file kept by the maintainer | Q17: Derivación mecánica por fórmula viva.
A18: Pedregalito 2 — 12.5 MW | G18: =12.5*G15*G11 -> 44895 | H18: =12.5*H15*H11 -> 44895 | I18: =12.5*I15*I11 -> 44895 | J18: =12.5*J15*J11 -> 44895 | K18: =12.5*K15*K11 -> 44895 | M18: MW | N18: a working file kept by the maintainer | Q18: Derivación mecánica por fórmula viva.
A19: Cochea — 15.5 MW | G19: =15.5*G15*G11 -> 55669.8 | H19: =15.5*H15*H11 -> 55669.8 | I19: =15.5*I15*I11 -> 55669.8 | J19: =15.5*J15*J11 -> 55669.8 | K19: =15.5*K15*K11 -> 55669.8 | M19: MW | N19: a working file kept by the maintainer | Q19: Derivación mecánica por fórmula viva.
A20: Mini Central El Alto — 0.98 MW | G20: =0.98*G15*G11 -> 3519.768 | H20: =0.98*H15*H11 -> 3519.768 | I20: =0.98*I15*I11 -> 3519.768 | J20: =0.98*J15*J11 -> 3519.768 | K20: =0.98*K15*K11 -> 3519.768 | M20: MW | N20: a working file kept by the maintainer | Q20: Derivación mecánica por fórmula viva.
A21: Pedregalito Solar — 9.9 MW | G21: =9.9*G15*G11 -> 35556.84 | H21: =9.9*H15*H11 -> 35556.84 | I21: =9.9*I15*I11 -> 35556.84 | J21: =9.9*J15*J11 -> 35556.84 | K21: =9.9*K15*K11 -> 35556.84 | M21: MW | N21: a working file kept by the maintainer | Q21: Derivación mecánica por fórmula viva.
A22: Generación neta total (MWh) | B22: 426569 | C22: 549284 | D22: 374482 | E22: 497784 | F22: 470665 | G22: =G76 -> 476626.99 | H22: =H76 -> 476626.99 | I22: =I76 -> 476626.99 | J22: =J76 -> 476626.99 | K22: =K76 -> 476626.99 | M22: MWh | N22: F1 fila 76: suma generacion por planta (CF ENSO Bear/Base/Bull por planta, CND A2). Filas 16-21 = memo legacy CF-flota (ya no suman al total forecast). | Q22: Suma mecánica del bloque.
A24: B. PRECIOS POR FUENTE ($/MWh)
A25: PPA contratado ($/MWh, blended realizado FY25 potencia+energía) | B25: 106.01 | C25: 105.52 | D25: 112.15 | E25: 111.21 | F25: 108.46 | G25: =(G85+G92+G94+G96)/G32 -> 80.102546 | H25: =(H85+H92+H94+H96)/H32 -> 71.627493 | I25: =(I85+I92+I94+I96)/I32 -> 79.754891 | J25: =(J85+J92+J94+J96)/J32 -> 79.754891 | K25: =(K85+0.5*K65*91.649)/K32 -> 51.19908 | M25: MWh | N25: F2/F3: forecast = blended Seccion F (ingresos contratados: award GC-02-2026 fila 85 + PPAs vigentes filas 92/94/96) / MWh contratados fila 32; K = award + 0.5xCochea a 91.649 $/MWh (A4a). Solo energia (capacidad va como termino propio en fila 39). Label pinned por contrato ACTIVE pph_pilot_energy_pxq_v0 (node ppa_blended_price) — hist B-F sigue siendo blended realizado. | Q25: Derivación mecánica por fórmula viva.
A26: Spot / merchant ($/MWh) — activo | B26: 58.4 | C26: 77.76 | D26: 113.08 | E26: 72.56 | F26: 62.75 | G26: =CHOOSE($C$5,G28,G29,G27) -> 60 | H26: =CHOOSE($C$5,H28,H29,H27) -> 58 | I26: =CHOOSE($C$5,I28,I29,I27) -> 57 | J26: =CHOOSE($C$5,J28,J29,J27) -> 56 | K26: =CHOOSE($C$5,K28,K29,K27) -> 55 | M26: MWh | N26: a working file kept by the maintainer | Q26: Selector de caso activo C5: Base/Bull/Bear.
A27: Bear | G27: 45 | H27: 44 | I27: 43 | J27: 42 | K27: 41 | M27: moneda del modelo | N27: a working file kept by the maintainer | Q27: Escenario driver citado; NOT_DISCLOSED si no hay fuente explícita.
A28: Base | G28: 60 | H28: 58 | I28: 57 | J28: 56 | K28: 55 | M28: moneda del modelo | N28: a working file kept by the maintainer | Q28: Escenario driver citado; NOT_DISCLOSED si no hay fuente explícita.
A29: Bull | G29: 75 | H29: 73 | I29: 72 | J29: 71 | K29: 70 | M29: moneda del modelo | N29: a working file kept by the maintainer | Q29: Escenario driver citado; NOT_DISCLOSED si no hay fuente explícita.
A31: C. VOLUMEN POR CANAL (MWh, con cliffs PPA por parque)
A32: MWh contratado (potencia+energía y solo-energía) | B32: 300655 | C32: 306746 | D32: 276777 | E32: 282678 | F32: 305119 | G32: =G83+G55+G60+G65 -> 284701.22 | H32: =H83+H55+H60+H65 -> 364081.22 | I32: =I83+I55+I60+I65 -> 272938.22 | J32: =J83+J55+J60+J65 -> 272938.22 | K32: =K83+0.5*K65 -> 117889.08 | M32: MWh | N32: F2 fila 83 (award GC-02-2026 SED+SEO, MWh/ano activo) + F1 generacion Ped1(55)/Ped2(60)/Cochea(65) mientras PPA vigente (expiries dic-29/jun-30; sin re-contratacion asumida — ausentes de GC-02-2026). | Q32: Derivación mecánica por fórmula viva.
A33: MWh spot / merchant (residual) | B33: 157317 | C33: 246692 | D33: 129626 | E33: 219421 | F33: 215832 | G33: =MAX(0,G22-G32) -> 191925.77 | H33: =MAX(0,H22-H32) -> 112545.77 | I33: =MAX(0,I22-I32) -> 203688.77 | J33: =MAX(0,J22-J32) -> 203688.77 | K33: =MAX(0,K22-K32) -> 358737.91 | M33: MWh | N33: Fila 22 (= F1 fila 76, generacion total ENSO) - fila 32 (contratado). Referencia via fila 22 para mantener el nodo de contrato total_generation_mwh vivo (no decorativo). | Q33: Derivación mecánica por fórmula viva.
A35: D. INGRESO POR FUENTE ($ = MWh × precio)
A36: Ingreso energía FY25A (auditado, ref EEFF) | B36: =EEFF!B7 -> 42793727 | C36: =EEFF!C7 -> 57204243 | D36: =EEFF!D7 -> 53187368 | E36: =EEFF!E7 -> 55356497 | F36: =EEFF!F7 -> 48358044 | M36: MWh | N36: EEFF:Venta de energía | Q36: Mirror histórico desde fuente citada.
A37: Ingreso PPA | B37: =B32*B25 -> 31872437 | C37: =C32*C25 -> 32367838 | D37: =D32*D25 -> 31040541 | E37: =E32*E25 -> 31436620 | F37: =F32*F25 -> 33093207 | G37: =G32*G25 -> 22805293 | H37: =H32*H25 -> 26078226 | I37: =I32*I25 -> 21768158 | ... K37: =K32*K25 -> 6035812.4 | M37: moneda del modelo | N37: a working file kept by the maintainer | Q37: Derivación mecánica por fórmula viva.
A38: Ingreso spot / merchant | B38: =B33*B26 -> 9187312.8 | C38: =C33*C26 -> 19182770 | D38: =D33*D26 -> 14658108 | E38: =E33*E26 -> 15921188 | F38: =F33*F26 -> 13543458 | G38: =G33*G26 -> 11515546 | H38: =H33*H26 -> 6527654.5 | I38: =I33*I26 -> 11610260 | ... K38: =K33*K26 -> 19730585 | M38: moneda del modelo | N38: a working file kept by the maintainer | Q38: Derivación mecánica por fórmula viva.
A39: TOTAL INGRESO ENERGÍA | B39: =B37+B38 -> 41059749 | C39: =C37+C38 -> 51550608 | D39: =D37+D38 -> 45698649 | E39: =E37+E38 -> 47357808 | F39: =F37+F38 -> 46636665 | G39: =G37+G38+G82 -> 38521429 | H39: =H37+H38+H82 -> 32605880 | I39: =I37+I38+I82 -> 33463954 | J39: =J37+J38+J82 -> 33345801 | K39: =K37+K38+K82 -> 25937470 | M39: MWh | N39: Ingreso PPA (37) + spot/merchant (38) + capacidad El Alto (F2 fila 82: valle FY27 = 0 explicito, award 4.4MW@3.24 desde jul-2028). EEFF Venta de energia incluye canales de capacidad (Nota 20). | Q39: Suma mecánica del bloque.
A41: E. O&M Y COSTOS OPERATIVOS ($)
A42: Compras de energía y costos asociados (firming spot, hidrología) | B42: =EEFF!B8 -> 4427043 | C42: =EEFF!C8 -> 8559953 | D42: =EEFF!D8 -> 12013335 | E42: =EEFF!E8 -> 9960198 | F42: =EEFF!F8 -> 4986124 | G42: =G102 -> 5053166.2 | H42: =H102 -> 9162668.8 | I42: =I102 -> 4444195.7 | J42: =J102 -> 4444195.7 | K42: =K102 -> 4444195.7 | M42: MWh | N42: F4 fila 102: $/MWh firming (mediana FY22-24 auditada A6g, HCAISAN 84-91% de compras) x MWh comprometido El Alto (fila 83). | Q42: Derivación mecánica por fórmula viva.
A43: TOTAL COSTO DE ENERGÍA (COGS) | B43: =B42 -> 4427043 | C43: =C42 -> 8559953 | D43: =D42 -> 12013335 | E43: =E42 -> 9960198 | F43: =F42 -> 4986124 | G43: =G42 -> 5053166.2 | H43: =H42 -> 9162668.8 | I43: =I42 -> 4444195.7 | ... K43: =K42 -> 4444195.7 | M43: MWh | N43: a working file kept by the maintainer | Q43: Suma mecánica del bloque.
A44: Honorarios administración (RP InterEnergy) | B44: 959176 | C44: 1278900 | D44: 1278900 | E44: 1278900 | F44: 1278900 | G44: 1278900 | H44: 1278900 | I44: 1278900 | J44: 1278900 | K44: 1278900 | M44: moneda del modelo | N44: a working file kept by the maintainer | Q44: Input de escenario desde fuente citada o NOT_DISCLOSED.
A45: Resto G&A (= G&A total F4 auditado A6g − honorarios) | B45: =EEFF!B14-B44 -> 3629203 | C45: =EEFF!C14-C44 -> 4054029 | D45: =EEFF!D14-D44 -> 4275429 | E45: =EEFF!E14-E44 -> 4232451 | F45: =EEFF!F14-F44 -> 4405777 | G45: =G116-G44 -> 4232451 | H45: =H116-H44 -> 4232451 | I45: =I116-I44 -> 4232451 | J45: =J116-J44 -> 4232451 | K45: =K116-K44 -> 4232451 | M45: moneda del modelo | N45: F4 fila 116 (G&A total auditado A6g FY24, por subsidiaria) - fila 44 honorarios. Fila 46 = 44+45 = 5,511,351 = G&A emisor FY24. | Q45: Derivación mecánica por fórmula viva.
A46: TOTAL GASTOS ADMIN (G&A) | B46: =B44+B45 -> 4588379 | C46: =C44+C45 -> 5332929 | D46: =D44+D45 -> 5554329 | E46: =E44+E45 -> 5511351 | F46: =F44+F45 -> 5684677 | G46: =G44+G45 -> 5511351 | H46: =H44+H45 -> 5511351 | I46: =I44+I45 -> 5511351 | ... K46: =K44+K45 -> 5511351 | M46: moneda del modelo | N46: a working file kept by the maintainer | Q46: Suma mecánica del bloque.
A48: F. PROFORMA POR PLANTA — DRIVERS DE VOLUMEN, PRECIO Y COSTO (FY26E-FY30E)
...

Sheet Notas_EEFF
A1: Panama Power Holdings, Inc. y Subsidiarias
A2: Notas a los Estados Financieros
A3: Fuente: informes auditados vía OCR Mistral (verbatim).
A5: Año | B5: Documento fuente | C5: Página OCR | D5: Tabla OCR / sección | E5: Nota # | F5: Título original de la nota | G5: Categoría modelable | H5: Line item EEFF | I5: Sub-line item / detalle | J5: Texto original / disclosure | K5: Monto reportado | L5: Moneda | M5: Unidad / escala | N5: Fecha / venc. / tasa / plazo | O5: Contraparte / contrato / instrumento | P5: Impacto en Supuestos | Q5: Impacto en ModeloFinanciero | R5: Link a celda EEFF | S5: Comentario de extracción | T5: Status
A6: 2022 | B6: INA_PPHO_2022_0.pdf | C6: page-44 | D6: markdown.md | E6: 1 | F6: 1. Información General | G6: Otros | J6: Panama Power Holdings, Inc. (la "Compañía" o "PPH") fue constituida el 4 de abril de 2007 mediante Escritura Pública No.8298 de acuerdo con las leyes de la República de Panamá y continuada según Ley de Sociedades Mercantiles de las Islas Vírgenes Británicas el 3 de marzo de 2011 bajo el No.1575385, según consta en Escritura Pública No.6,697 del 19 de marzo de 2010. | T6: OK
A7: 2022 | B7: INA_PPHO_2022_0.pdf | C7: page-44 | D7: markdown.md | E7: 1 | F7: 1. Información General | G7: Otros | J7: La principal actividad de la Compañía y sus subsidiarias (en adelante el "Grupo") es llevar a cabo el negocio de generación de energía eléctrica, ya sea en forma directa o indirecta mediante la inversión o participación en sociedades que se dediquen a este giro de negocio. Todas las subsidiarias del Grupo se encuentran incorporadas en la República de Panamá. | T7: OK
A8: 2022 | B8: INA_PPHO_2022_0.pdf | C8: page-44 | D8: markdown.md | E8: 1 | F8: 1. Información General | G8: Otros | J8: La oficina principal del Grupo se encuentra ubicada en Paseo Roberto Motta, Costa del Este, Capital Plaza, Piso 12 en la Ciudad de Panamá, República de Panamá. | T8: OK
A9: 2022 | B9: INA_PPHO_2022_0.pdf | C9: page-44 | D9: markdown.md | E9: 1 | F9: 1. Información General | G9: Otros | J9: La siguiente tabla muestra las subsidiarias del Grupo, la fecha de adquisición y el porcentaje de participación: | T9: OK
A10: 2022 | B10: INA_PPHO_2022_0.pdf | C10: page-44 | D10: markdown.md | E10: 1 | F10: 1. Información General | G10: Otros | J10: | Compañías Subsidiarias | Porcentaje de Participación | Fecha de Adquisición | | --- | --- | --- | | Generadora Alto Valle, S. A. | 100% | 27/12/2007 | | Generadora Pedregalito, S. A. | 100% | 28/12/2007 | | Generadora Río Chico, S. A. | 100% | 28/12/2007 | | Hydro Caisán, S. A. | 100% | 30/06/2010 | | Panama Power Management Services, S. A. | 100% | 02/03/2012 | | Pedregalito Solar Power, S. A. | 100% | 07/07/2014 | | Río Chico Solar Power, S. A. | 100% | 07/07/2014 | | PPH Financing Services, S. A. | 100% | 17/03/2016 | | T10: OK
A11: 2022 | B11: INA_PPHO_2022_0.pdf | C11: page-44 | D11: markdown.md | E11: 1 | F11: 1. Información General | G11: Otros | J11: Las subsidiarias Generadora Pedregalito, S. A. (central "Pedregalito 1") y Generadora Río Chico, S. A. (central "Pedregalito 2") iniciaron la generación de energía en abril y octubre de 2011, respectivamente, la subsidiaria Generadora Alto Valle, S. A. (central "Cochea") inició la generación de energía en octubre de 2012 y la subsidiaria Hydro Caisán, S. A. (central "El Alto") en agosto de 2014. La principal actividad de las otras subsidiarias es brindar soporte a las operaciones del Grupo Panama Power Holdings, Inc. | T11: OK
A12: 2022 | B12: INA_PPHO_2022_0.pdf | C12: page-44 | D12: markdown.md | E12: 1 | F12: 1. Información General | G12: Otros | J12: Mediante Escritura Pública No. 2,797 del 28 de julio de 2021, inscrita en el Registro Público de Panamá el 25 de agosto de 2021, se protocolizó Acta de la Asamblea de Accionistas de la sociedad Generadora Río Piedra, S. A., para autorizar la disolución de la sociedad. | T12: OK
A13: 2022 | B13: INA_PPHO_2022_0.pdf | C13: page-44 | D13: markdown.md | E13: 1 | F13: 1. Información General | G13: Otros | J13: Mediante Escritura Pública No.2,798 del 28 de julio de 2021, inscrita en el Registro Público de Panamá el 16 de agosto de 2021, se protocolizó Acta de la Asamblea de Accionistas de la sociedad Multi Magnetic, Inc., para autorizar la disolución de la sociedad. | T13: OK
A14: 2022 | B14: INA_PPHO_2022_0.pdf | C14: page-45 | D14: markdown.md | E14: 1 | F14: 1. Información General (Continuación) | G14: Otros | J14: Mediante Escritura Pública No.2,799 del 28 de julio de 2021, inscrita en el Registro Público de Panamá el 16 de agosto de 2021, se protocolizó Acta de la Asamblea de Accionistas de la sociedad Caldera Power, Inc., para autorizar la disolución de la sociedad. | T14: OK
A15: 2022 | B15: INA_PPHO_2022_0.pdf | C15: page-45 | D15: markdown.md | E15: 1 | F15: 1. Información General (Continuación) | G15: Otros | J15: Mediante Escritura Pública No. 3465 de 8 de septiembre de 2021 se protocolizó el acuerdo de fusión entre las subsidiarias Hydro Caisán, S. A. y G.R.K. Energy Corp., mediante el cual Hydro Caisán, S. A. se mantiene como la entidad absorbente. Esta fusión se da para consolidar las sociedades que forman parte de un mismo proyecto. Derivado de esta fusión, las partes acordaron convertir la totalidad de las acciones de G.R.K. Energy Corp. en 100 acciones comunes sin valor nominal de Hydro Caisán, S. A., emitidas al accionista de la subsidiaria. La fusión por absorción no representó flujo de efectivo y se realizó a su valor en libros. | T15: OK
A16: 2022 | B16: INA_PPHO_2022_0.pdf | C16: page-45 | D16: markdown.md | E16: 1 | F16: 1. Información General (Continuación) | G16: Otros | J16: Mediante Escritura Pública No. 3464 de 8 de septiembre de 2021 se protocolizó el acuerdo de fusión entre las subsidiarias Hydro Caisán, S. A. y Goodsea Inc., mediante el cual Hydro Caisán, S. A. se mantiene como la entidad absorbente. Esta fusión se da para consolidar las sociedades que forman parte de un mismo proyecto. Derivado de esta fusión, las partes acordaron convertir la totalidad de las acciones de Goodsea, Inc. en 100 acciones comunes sin valor nominal de Hydro Caisán, S. A., emitidas al accionista de la subsidiaria. La fusión por absorción no representó flujo de efectivo y se realizó a su valor en libros. | T16: OK
A17: 2022 | B17: INA_PPHO_2022_0.pdf | C17: page-45 | D17: markdown.md | E17: 1 | F17: 1. Información General (Continuación) | G17: Otros | J17: Los estados financieros consolidados de Panama Power Holdings, Inc. y Subsidiarias fueron aprobados para su emisión por el Presidente del Grupo el 31 de marzo de 2023. El Presidente del Grupo tiene la autoridad de modificación y remisión de los estados financieros consolidados después de aprobados. | T17: OK
... A138: 2022 | B138: INA_PPHO_2022_0.pdf | C138: page-60 | D138: markdown.md | E138: 4 | F138: 4. Administración del Riesgo de Instrumentos Financieros (Continuación) | G138: Riesgo financiero | J138: A continuación se presentan los vencimientos de los pasivos no descontados, incluyendo los intereses calculados a la fecha de vencimiento: | T138: OK
A139: 2022 | B139: INA_PPHO_2022_0.pdf | C139: page-60 | D139: markdown.md | E139: 4 | F139: 4. Administración del Riesgo de Instrumentos Financieros (Continuación) | G139: Riesgo financiero | J139: | | Menos de un Año | Entre 1 y 5 Años | Más de 5 Años | | --- | --- | --- | --- | | 2022 | | | | | Préstamo por pagar | 758,413 | - | - | | Bonos por pagar | 18,269,526 | 83,349,063 | 114,556,708 | | Cuentas por pagar | 1,675,961 | - | - | | Impuesto sobre la renta por pagar | 2,384,922 | - | - | | Otros pasivos | 1,534,472 | 218,261 | - | | 2021 | | | | | Bonos por pagar | 18,776,204 | 88,662,102 | 130,164,2479 | | Cuentas por pagar | 3,817,823 | - | - | | Impuesto sobre la renta por pagar | 1,255,449 | - | - | | Otros pasivos | 1,522,447 | 204,886 | - | | K139: 83349063 | L139: B/. | T139: OK
A140: 2022 | B140: INA_PPHO_2022_0.pdf | C140: page-60 | D140: markdown.md | E140: 4 | F140: 4. Administración del Riesgo de Instrumentos Financieros (Continuación) | G140: Riesgo financiero | J140: Durante el período 2022, el Grupo estuvo monitoreando su posición financiera y operativa por los efectos que pudiese generar el COVID-19 (ver Nota 6). | T140: OK
A141: 2022 | B141: INA_PPHO_2022_0.pdf | C141: page-60 | D141: markdown.md | E141: 4 | F141: 4. Administración del Riesgo de Instrumentos Financieros (Continuación) | G141: Riesgo financiero | J141: ### Objetivos y Políticas de Gestión de Capital | T141: OK
A142: 2022 | B142: INA_PPHO_2022_0.pdf | C142: page-60 | D142: markdown.md | E142: 4 | F142: 4. Administración del Riesgo de Instrumentos Financieros (Continuación) | G142: Riesgo financiero | J142: El objetivo del Grupo en el manejo del capital es el de salvaguardar la habilidad del Grupo para continuar como negocio en marcha, con el objetivo de proveer retornos a sus accionistas y beneficios a otros acreedores y para mantener una estructura óptima de capital que reduzca el costo de capital. | T142: OK
A143: 2022 | B143: INA_PPHO_2022_0.pdf | C143: page-60 | D143: markdown.md | E143: 4 | F143: 4. Administración del Riesgo de Instrumentos Financieros (Continuación) | G143: Riesgo financiero | J143: El Grupo monitorea su capital sobre la base de razón de apalancamiento. El apalancamiento es el resultado de dividir la deuda neta entre el total del capital. La deuda neta se calcula como el total de préstamos que se muestran en el estado consolidado de situación financiera menos el efectivo. El total del capital está determinado como el total del patrimonio, más la deuda neta. | T143: OK
A144: 2022 | B144: INA_PPHO_2022_0.pdf | C144: page-61 | D144: markdown.md | E144: 4 | F144: 4. Administración del Riesgo de Instrumentos Financieros (Continuación) | G144: Riesgo financiero | J144: **Objetivos y Políticas de Gestión de Capital (continuación)** | T144: OK
A145: 2022 | B145: INA_PPHO_2022_0.pdf | C145: page-61 | D145: markdown.md | E145: 4 | F145: 4. Administración del Riesgo de Instrumentos Financieros (Continuación) | G145: Riesgo financiero | J145: A continuación se muestra la razón de apalancamiento del Grupo: | T145: OK
A146: 2022 | B146: INA_PPHO_2022_0.pdf | C146: page-61 | D146: markdown.md | E146: 4 | F146: 4. Administración del Riesgo de Instrumentos Financieros (Continuación) | G146: Riesgo financiero | J146: | | 2022 | 2021 | | --- | --- | --- | | Total de préstamos y bonos por pagar | 159,008,413 | 167,250,000 | | Menos: Efectivo y equivalentes de efectivo | (10,955,792) | (9,167,597) | | Efectivo restringido | (4,234,822) | (4,206,485) | | Deuda neta | 143,817,799 | 153,875,918 | | Total de patrimonio | 154,381,118 | 151,992,995 | | Total de capital | 298,198,917 | 305,868,913 | | Razón de apalancamiento | 48% | 50% | | K146: 167250000 | L146: B/. | T146: OK
A147: 2022 | B147: INA_PPHO_2022_0.pdf | C147: page-61 | D147: markdown.md | E147: 4 | F147: 4. Administración del Riesgo de Instrumentos Financieros (Continuación) | G147: Riesgo financiero | J147: Para propósitos de divulgación, las Normas Internacionales de Información Financiera especifican una jerarquía del valor razonable que clasifica en tres niveles, en base a las variables utilizadas en las técnicas de valorización para medir el valor razonable: La jerarquía se basa en la transparencia de las variables que se utilizan en la valorización de un activo a la fecha de su valorización. Estos tres niveles son los siguientes: | T147: OK
A148: 2022 | B148: INA_PPHO_2022_0.pdf | C148: page-61 | D148: markdown.md | E148: 4 | F148: 4. Administración del Riesgo de Instrumentos Financieros (Continuación) | G148: Riesgo financiero | J148: - Nivel 1: Precios cotizados (no ajustados) en mercados activos para activos y pasivos idénticos a la fecha de medición. - Nivel 2: Variables distintas a los precios cotizados incluidos en el Nivel 1 que son observables para el activo o pasivo, ya sea directamente (es decir, como precios) o indirectamente (es decir, derivados de los precios). - Nivel 3: Variables no observables para el activo y pasivo. | T148: OK
A149: 2022 | B149: INA_PPHO_2022_0.pdf | C149: page-61 | D149: markdown.md | E149: 4 | F149: 4. Administración del Riesgo de Instrumentos Financieros (Continuación) | G149: Riesgo financiero | J149: El Grupo no mantiene activos y pasivos registrados a valor razonable en el estado consolidado de situación financiera. Para los instrumentos financieros que no están registrados a su valor razonable en el estado consolidado de situación financiera, su valor en libros se aproxima a su valor razonable, debido a su naturaleza de corto plazo y bajo riesgo de créditos (en los casos de activos). Estos instrumentos financieros incluyen: el efectivo en banco, cuentas por cobrar, cuentas por pagar proveedores, obligaciones financieras de corto y cuentas con compañías relacionadas. Para los instrumentos financieros a largo plazo, el valor razonable se divulga en la Nota 16. | T149: OK
A150: 2022 | B150: INA_PPHO_2022_0.pdf | C150: page-62 | D150: markdown.md | E150: 5 | F150: 5. Efectivo | G150: Working capital | J150: El desglose del efectivo se presenta a continuación: | T150: OK
A151: 2022 | B151: INA_PPHO_2022_0.pdf | C151: page-62 | D151: markdown.md | E151: 5 | F151: 5. Efectivo | G151: Working capital | J151: | | 2022 | 2021 | | --- | --- | --- | | Caja menuda | 1,104 | 1,056 | | Banco General, S. A. | 10,178,021 | 8,512,233 | | MMG Bank, S. A. | 776,667 | 654,308 | | | 10,955,792 | 9,167,597 | | K151: 1104 | L151: B/. | T151: OK
A152: 2022 | B152: INA_PPHO_2022_0.pdf | C152: page-62 | D152: markdown.md | E152: 6 | F152: 6. Cuentas por Cobrar | G152: Cuentas por cobrar | J152: Las cuentas por cobrar se detallan de la siguiente manera: | T152: OK
A153: 2022 | B153: INA_PPHO_2022_0.pdf | C153: page-62 | D153: markdown.md | E153: 6 | F153: 6. Cuentas por Cobrar | G153: Cuentas por cobrar | J153: | | 2022 | 2021 | | --- | --- | --- | | Edemet-Edechi | 5,462,185 | 5,459,155 | | Elektra Noreste, S. A. | 2,501,926 | 2,497,992 | | Otros | 2,516,409 | 2,050,049 | | | 10,480,520 | 10,007,196 | | Menos: Porción circulante | 10,480,520 | 9,794,078 | | Porción no circulante | - | 213,118 | | K153: 5462185 | L153: B/. | T153: OK
A154: 2022 | B154: INA_PPHO_2022_0.pdf | C154: page-62 | D154: markdown.md | E154: 6 | F154: 6. Cuentas por Cobrar | G154: Cuentas por cobrar | J154: # Devolución de Ajuste Tarifario | T154: OK
A155: 2022 | B155: INA_PPHO_2022_0.pdf | C155: page-62 | D155: markdown.md | E155: 6 | F155: 6. Cuentas por Cobrar | G155: Cuentas por cobrar | J155: El 27 de septiembre de 2017, la Autoridad Nacional de los Servicios Públicos, emitió la Resolución AN No. 11667 - Elec, por la cual se autoriza a la Empresa de Transmisión Eléctrica, S. A. (ETESA), para diferir la devolución tarifaria de los años 2, 3 y 4 a los Agentes del Mercado del período tarifario de julio 2013 a junio 2017, como consecuencia de la revisión de los Cargos por Uso del Sistema Principal de Transmisión (CUSPT) y del Servicio de Operación Integrada (SOI), para que se haga efectiva a partir del mes de julio de 2021, por un período de 8 años. | T155: OK
A156: 2022 | B156: INA_PPHO_2022_0.pdf | C156: page-62 | D156: markdown.md | E156: 6 | F156: 6. Cuentas por Cobrar | G156: Cuentas por cobrar | J156: La Resolución AN No. 11667 - Elec, fue modificada mediante Resolución No. AN No. 11872-Elec del 4 de diciembre de 2017, para cambiar el período de devolución de 8 a 5 años para los ajustes a CUSPT y de 8 a 2 años para los ajustes SOI. | T156: OK
A157: 2022 | B157: INA_PPHO_2022_0.pdf | C157: page-62 | D157: markdown.md | E157: 6 | F157: 6. Cuentas por Cobrar | G157: Cuentas por cobrar | J157: Mediante Resolución No. AN. 13350 - Elec del 10 de mayo de 2019, se adiciona el requerimiento de publicación del ajuste final del año tarifario 4 (período tarifario de julio 2013 a junio 2017), y se ordena a ETESA establecer y notificar el Plan de Devolución mensual para cada Agente del Mercado confirmando los montos y los intereses sobre saldo hasta completar la devolución. En noviembre de 2021, las subsidiarias Generadora Alto Valle, S. A., Generadora Río Chico, S. A., Hydro Caisán, S. A., Generadora Alto Valle, S. A. y ETESA, suscribieron un Acuerdo para el pago anticipado de la devolución tarifaria correspondiente a los años 2, 3 y 4 del período tarifario 2013-2017, el cual establece la programación de dicho pago. | T157: OK
A158: 2022 | B158: INA_PPHO_2022_0.pdf | C158: page-63 | D158: markdown.md | E158: 6 | F158: 6. Cuentas por Cobrar (Continuación) | G158: Cuentas por cobrar | J158: Devolución de Ajuste Tarifario (continuación) | T158: OK
A159: 2022 | B159: INA_PPHO_2022_0.pdf | C159: page-63 | D159: markdown.md | E159: 6 | F159: 6. Cuentas por Cobrar (Continuación) | G159: Cuentas por cobrar | J159: El monto a devolver para las subsidiarias Hydro Caisán, S. A., Generadora Pedregalito, S. A., Generadora Alto Valle, S. A. y Generadora Río Chico, S. A. totalizaba B/.807,747 más intereses por B/.201,306, los cuales se encontraban registrados en las cuentas por cobrar clientes en porción circulante. Durante los meses de marzo, abril y mayo, se recibió la cancelación de esta cuenta por cobrar. | K159: 807747 | L159: B/. | T159: OK
A160: 2022 | B160: INA_PPHO_2022_0.pdf | C160: page-63 | D160: markdown.md | E160: 6 | F160: 6. Cuentas por Cobrar (Continuación) | G160: Cuentas por cobrar | J160: Mediante Ley 152 de 4 de mayo de 2020, se adoptaron una serie de medidas especiales en atención a la emergencia sanitaria nacional. Estas medidas incluyeron, entre otras, la suspensión, por el término de cuatro meses a partir del 1 de marzo de 2020, del pago de los servicios públicos de energía eléctrica, telefonía fija, móvil e internet a las personas afectadas según lo aprobado en dicha Ley. El pago de los servicios públicos antes mencionados, por parte de las personas afectadas que se acogieron a estas medidas, se prorrateó a un término de tres años a partir del 1 de julio de 2020. | T160: OK
A161: 2022 | B161: INA_PPHO_2022_0.pdf | C161: page-63 | D161: markdown.md | E161: 6 | F161: 6. Cuentas por Cobrar (Continuación) | G161: Cuentas por cobrar | J161: Mediante Resolución AN No. 16095-Elec del 21 de mayo de 2020, la Autoridad Nacional de los Servicios Públicos aprobó una serie de medidas transitorias que rigieron hasta el 30 de junio de 2020. Estas medidas incluyeron, entre otras, la posibilidad de una reducción en el pago tanto en el mercado de contratos como en el mercado ocasional, proporcional al déficit en la recaudación de los ingresos contemplados en dicha resolución. La resolución estableció que cualquier saldo adeudado a los Participantes del Mercado Mayorista de Electricidad generado dentro del período del 1 de marzo al 30 de junio de 2020, debía ser prorrateado en cuotas iguales en un plazo no mayor de treinta y seis meses, contados a partir de 1 de julio de 2020. Así mismo, los Participantes del Mercado Mayorista de electricidad, podrían llegar a Acuerdos de Pago distinto al establecido en el numeral 5 de dicha Resolución y debían remitir una copia de dicho Acuerdo a la Autoridad Nacional de los Servicios Públicos. | T161: OK
...

Sheet MDA
A1: Panama Power Holdings, Inc. y Subsidiarias
A2: MD&A — IN-A FY2025 (Panama Power Holdings, Inc.), Sección "Análisis de Resultados Financieros y Operativos" (transcripción verbatim del filing público; linaje archivo-línea en Source_Register).
A3: II. ANALISIS DE RESULTADOS FINANCIEROS Y OPERATIVOS
A4: Liquidez
A5: Al 31 de diciembre de 2025, PPH tiene un total de activos circulantes de $31,660,678 ($24,685,303 al 31
A6: de diciembre de 2024 y $26,443,110 al 31 de diciembre de 2023), compuesto por $19,057,503 en
A7: efectivo y equivalentes de efectivo ($9,494,389 al 31 de diciembre de 2024 y $10,299,859 al 31 de
A8: diciembre de 2023), $8,602,706 en cuentas por cobrar ($10,018,368 al 31 de diciembre de 2024 y
A9: $10,514,874 al 31 de diciembre de 2023), $2,666,409 en inventario de repuestos y consumibles
A10: ($2,315,599 al 31 de diciembre de 2024 y $2,176,373 al 31 de diciembre de 2023), $836,786 en gastos
A11: pagados por anticipado ($475,685 al 31 de diciembre de 2024 y $1,400,465 al 31 de diciembre de 2023),
A12: $0 en crédito fiscal por inversión ($1,829,780 al 31 de diciembre de 2024 y $1,541,175 al 31 de diciembre
... A47: planta Pedregalito Solar Power.
A48: 11
A49: ```
A50: ## PDF Page 15
A51: ```text
A52: Venta de Energía
A53: A continuación se presenta un resumen de la composición de la utilidad en venta de energía reflejada en
A54: el estado financiero.
A55: 31-dic-25 vs
A56: PPH Consolidado 31-dic-2025 31-dic-2024 31-dic-2023
A57: 31-dic-24
A58: ING
A59: Producción total 470,665 497,784 374,482 (27,119)
A60: Suplidor de pérdidas de transmisión (19,250) (22,248) (12,211) 2,998
... A100: 44,419MWh.
A101: 12
A102: ```
A103: ## PDF Page 16
A104: ```text
A105: El precio promedio de compras en el mercado ocasional disminuyó de $145/MWh al 31 de diciembre de
A106: 2024 a $70/MWh al 31 de diciembre de 2025. ($129/MWh al 31 de diciembre de 2023).
A107: Las ventas en el mercado ocasional disminuyeron en un 2% de 219,421MWh a 215,832MWh, aunado a
A108: una disminución en el precio promedio de ventas en el mercado ocasional de $73/MWh al 31 de
A109: diciembre de 2024 a $63/MWh al 31 de diciembre de 2025 resultó en una disminución en los ingresos por
A110: ventas en el mercado ocasional de $2,377,920. El precio promedio de ventas en el mercado ocasional
A111: disminuyó de $73/MWh al 31 de diciembre de 2024 a $63/MWh al 31 de diciembre de 2025. ($113/MWh
A112: al 31 de diciembre de 2023).
A113: Para los 12 meses terminados el 31 de diciembre de 2025, PPH generó una utilidad en venta de energía
...

Sheet ModeloFinanciero
A1: Panama Power Holdings, Inc. y Subsidiarias
A2: Estados Financieros Auditados FY21-FY25
A3: en B/. sin escala
A5: Años | B5: FY21A | C5: FY22A | D5: FY23A | E5: FY24A | F5: FY25A | G5: FY26E | H5: FY27E | I5: FY28E | J5: FY29E | K5: FY30E
A6: Estado de Resultados
A7: Venta de energía | B7: =EEFF!B7 -> 42793727 | C7: =EEFF!C7 -> 57204243 | D7: =EEFF!D7 -> 53187368 | E7: =EEFF!E7 -> 55356497 | F7: =EEFF!F7 -> 48358044 | G7: =Supuestos!G39 -> 38521429 | H7: =Supuestos!H39 -> 32605880 | I7: =Supuestos!I39 -> 33463954 | J7: =Supuestos!J39 -> 33345801 | K7: =Supuestos!K39 -> 25937470
A8: Compras de energía y costos asociados | B8: =EEFF!B8 -> 4427043 | C8: =EEFF!C8 -> 8559953 | D8: =EEFF!D8 -> 12013335 | E8: =EEFF!E8 -> 9960198 | F8: =EEFF!F8 -> 4986124 | G8: =Supuestos!G43 -> 5053166.2 | H8: =Supuestos!H43 -> 9162668.8 | I8: =Supuestos!I43 -> 4444195.7 | J8: =Supuestos!J43 -> 4444195.7 | K8: =Supuestos!K43 -> 4444195.7
A9: Cargo de transmisión | B9: =EEFF!B9 -> 1368202 | C9: =EEFF!C9 -> 1850469 | D9: =EEFF!D9 -> 2243773 | E9: =EEFF!E9 -> 2503761 | F9: =EEFF!F9 -> 1761951 | G9: =F9 -> 1761951 | H9: =G9 -> 1761951 | I9: =H9 -> 1761951 | J9: =I9 -> 1761951 | K9: =J9 -> 1761951
A10: Total de costo de energía | B10: =EEFF!B10 -> 5795245 | C10: =EEFF!C10 -> 10410422 | D10: =EEFF!D10 -> 14257108 | E10: =EEFF!E10 -> 12463959 | F10: =EEFF!F10 -> 6748075 | G10: =G8+G9 -> 6815117.2 | H10: =H8+H9 -> 10924620 | I10: =I8+I9 -> 6206146.7 | J10: =J8+J9 -> 6206146.7 | K10: =K8+K9 -> 6206146.7
A11: Ingresos por crédito fiscal y otros | B11: =EEFF!B11 -> 869881 | C11: =EEFF!C11 -> 1974498 | D11: =EEFF!D11 -> 2169724 | E11: =EEFF!E11 -> 642966 | F11: =EEFF!F11 -> 1922207 | G11: =F11 -> 1922207 | H11: =G11 -> 1922207 | I11: =H11 -> 1922207 | J11: =I11 -> 1922207 | K11: =J11 -> 1922207
A12: Depreciación y amortización | B12: =EEFF!B12 -> 11878451 | C12: =EEFF!C12 -> 11881633 | D12: =EEFF!D12 -> 11997283 | E12: =EEFF!E12 -> 12446869 | F12: =EEFF!F12 -> 12521408 | G12: =F12 -> 12521408 | H12: =G12 -> 12521408 | I12: =H12 -> 12521408 | J12: =I12 -> 12521408 | K12: =J12 -> 12521408
A13: Operación y mantenimiento | B13: =EEFF!B13 -> 2400538 | C13: =EEFF!C13 -> 2548375 | D13: =EEFF!D13 -> 2841019 | E13: =EEFF!E13 -> 2549512 | F13: =EEFF!F13 -> 3004212 | G13: =F13 -> 3004212 | H13: =G13 -> 3004212 | I13: =H13 -> 3004212 | J13: =I13 -> 3004212 | K13: =J13 -> 3004212
A14: Generales y administrativos | B14: =EEFF!B14 -> 4588379 | C14: =EEFF!C14 -> 5332929 | D14: =EEFF!D14 -> 5554329 | E14: =EEFF!E14 -> 5511351 | F14: =EEFF!F14 -> 5684677 | G14: =Supuestos!G46 -> 5511351 | H14: =Supuestos!H46 -> 5511351 | I14: =Supuestos!I46 -> 5511351 | J14: =Supuestos!J46 -> 5511351 | K14: =Supuestos!K46 -> 5511351
A15: Otras pérdidas netas | B15: =EEFF!B15 -> 0 | C15: =EEFF!C15 -> 0 | D15: =EEFF!D15 -> 127418 | E15: =EEFF!E15 -> 0 | F15: =EEFF!F15 -> 0
A16: Pérdida en activos no financieros | B16: =EEFF!B16 -> 20000 | C16: =EEFF!C16 -> 0 | D16: =EEFF!D16 -> 0 | E16: =EEFF!E16 -> 0 | F16: =EEFF!F16 -> 0
A17: Pérdida en activos financieros | B17: =EEFF!B17 -> 139398 | C17: =EEFF!C17 -> 0 | D17: =EEFF!D17 -> 0 | E17: =EEFF!E17 -> 0 | F17: =EEFF!F17 -> 0
A18: Total de gastos operativos | B18: =EEFF!B18 -> 19026766 | C18: =EEFF!C18 -> 19762937 | D18: =EEFF!D18 -> 20520049 | E18: =EEFF!E18 -> 20507732 | F18: =EEFF!F18 -> 21210297 | G18: =G12+G13+G14+G15+G16+G17 -> 21036971 | H18: =H12+H13+H14+H15+H16+H17 -> 21036971 | I18: =I12+I13+I14+I15+I16+I17 -> 21036971 | J18: =J12+J13+J14+J15+J16+J17 -> 21036971 | K18: =K12+K13+K14+K15+K16+K17 -> 21036971
A19: Utilidad operativa | B19: =EEFF!B19 -> 18841597 | C19: =EEFF!C19 -> 29005382 | D19: =EEFF!D19 -> 20579935 | E19: =EEFF!E19 -> 23027772 | F19: =EEFF!F19 -> 22321879 | G19: =G7-G10+G11-G18 -> 12591548 | H19: =H7-H10+H11-H18 -> 2566496.3 | I19: =I7-I10+I11-I18 -> 8143043.5 | J19: =J7-J10+J11-J18 -> 8024890.7 | K19: =K7-K10+K11-K18 -> 616558.91
A20: Costos financieros | B20: =EEFF!B20 -> 10739963 | C20: =EEFF!C20 -> 10140045 | D20: =EEFF!D20 -> 9645428 | E20: =EEFF!E20 -> 9291709 | F20: =EEFF!F20 -> 8681196 | G20: =Debt_Schedule!G18 -> 8152445.5 | H20: =Debt_Schedule!H18 -> 7623695.5 | I20: =Debt_Schedule!I18 -> 7094945.5 | J20: =Debt_Schedule!J18 -> 6566195.5 | K20: =Debt_Schedule!K18 -> 6001442.5
A21: Ingresos financieros | B21: =EEFF!B21 -> -129032 | C21: =EEFF!C21 -> -140572 | D21: =EEFF!D21 -> -242921 | E21: =EEFF!E21 -> -362555 | F21: =EEFF!F21 -> -547419 | G21: =F21 -> -547419 | H21: =G21 -> -547419 | I21: =H21 -> -547419 | J21: =I21 -> -547419 | K21: =J21 -> -547419
A22: Costos financieros, neto | B22: =EEFF!B22 -> 10610931 | C22: =EEFF!C22 -> 9999473 | D22: =EEFF!D22 -> 9402507 | E22: =EEFF!E22 -> 8929154 | F22: =EEFF!F22 -> 8133777 | G22: =G20+G21 -> 7605026.5 | H22: =H20+H21 -> 7076276.5 | I22: =I20+I21 -> 6547526.5 | J22: =J20+J21 -> 6018776.5 | K22: =K20+K21 -> 5454023.5
A23: Utilidad antes de impuesto sobre la renta | B23: =EEFF!B23 -> 8230666 | C23: =EEFF!C23 -> 19005909 | D23: =EEFF!D23 -> 11177428 | E23: =EEFF!E23 -> 14098618 | F23: =EEFF!F23 -> 14188102 | G23: =G19-G22 -> 4986521.8 | H23: =H19-H22 -> -4509780.2 | I23: =I19-I22 -> 1595517 | J23: =J19-J22 -> 2006114.2 | K23: =K19-K22 -> -4837464.6
A24: Impuesto sobre la renta | B24: =EEFF!B24 -> -3095130 | C24: =EEFF!C24 -> -5342988 | D24: =EEFF!D24 -> -3950425 | E24: =EEFF!E24 -> -4617385 | F24: =EEFF!F24 -> -4887298 | G24: =-ROUND(G23*0.3445,0) -> -1717857 | H24: =-ROUND(H23*0.3445,0) -> 1553619 | I24: =-ROUND(I23*0.3445,0) -> -549656 | J24: =-ROUND(J23*0.3445,0) -> -691106 | K24: =-ROUND(K23*0.3445,0) -> 1666507
A25: Utilidad neta integral | B25: =EEFF!B25 -> 5135536 | C25: =EEFF!C25 -> 13662921 | D25: =EEFF!D25 -> 7227003 | E25: =EEFF!E25 -> 9481233 | F25: =EEFF!F25 -> 9300804 | G25: =G23+G24 -> 3268664.8 | H25: =H23+H24 -> -2956161.2 | I25: =I23+I24 -> 1045861 | J25: =J23+J24 -> 1315008.2 | K25: =K23+K24 -> -3170957.6
A27: Años | B27: FY21A | C27: FY22A | D27: FY23A | E27: FY24A | F27: FY25A | G27: FY26E | H27: FY27E | I27: FY28E | J27: FY29E | K27: FY30E
A28: Balance General
A29: Efectivo | B29: =EEFF!B29 -> 9167597 | C29: =EEFF!C29 -> 10955792 | D29: =EEFF!D29 -> 10299859 | E29: =EEFF!E29 -> 9494389 | F29: =EEFF!F29 -> 11057503 | G29: =G110 -> 17614506 | H29: =H110 -> 17946683 | I29: =I110 -> 22280882 | J29: =J110 -> 26884228 | K29: =K110 -> 26965605
A30: Depósito a plazo fijo mayor a 90 días | B30: =EEFF!B30 -> 0 | C30: =EEFF!C30 -> 0 | D30: =EEFF!D30 -> 0 | E30: =EEFF!E30 -> 0 | F30: =EEFF!F30 -> 8000000 | G30: =F30 -> 8000000 | H30: =G30 -> 8000000 | I30: =H30 -> 8000000 | J30: =I30 -> 8000000 | K30: =J30 -> 8000000
A31: Cuentas por cobrar | B31: =EEFF!B31 -> 9794078 | C31: =EEFF!C31 -> 10480520 | D31: =EEFF!D31 -> 10514874 | E31: =EEFF!E31 -> 10018368 | F31: =EEFF!F31 -> 8602706 | G31: =F31 -> 8602706 | H31: =G31 -> 8602706 | I31: =H31 -> 8602706 | J31: =I31 -> 8602706 | K31: =J31 -> 8602706
A32: Inventario de repuestos y suministros | B32: =EEFF!B32 -> 1954889 | C32: =EEFF!C32 -> 2283806 | D32: =EEFF!D32 -> 2176373 | E32: =EEFF!E32 -> 2315599 | F32: =EEFF!F32 -> 2666409 | G32: =F32 -> 2666409 | H32: =G32 -> 2666409 | I32: =H32 -> 2666409 | J32: =I32 -> 2666409 | K32: =J32 -> 2666409
A33: Gastos pagados por adelantado | B33: =EEFF!B33 -> 189074 | C33: =EEFF!C33 -> 171942 | D33: =EEFF!D33 -> 1400465 | E33: =EEFF!E33 -> 475685 | F33: =EEFF!F33 -> 836786 | G33: =F33 -> 836786 | H33: =G33 -> 836786 | I33: =H33 -> 836786 | J33: =I33 -> 836786 | K33: =J33 -> 836786
A34: Crédito fiscal por inversión | B34: =EEFF!B34 -> 1825438 | C34: =EEFF!C34 -> 2648365 | D34: =EEFF!D34 -> 1541175 | E34: =EEFF!E34 -> 1829780 | F34: =EEFF!F34 -> 0 | G34: =F34 -> 0 | H34: =G34 -> 0 | I34: =H34 -> 0 | J34: =I34 -> 0 | K34: =J34 -> 0
A35: Otros activos | B35: =EEFF!B35 -> 654057 | C35: =EEFF!C35 -> 1115702 | D35: =EEFF!D35 -> 510364 | E35: =EEFF!E35 -> 551482 | F35: =EEFF!F35 -> 497274 | G35: =F35 -> 497274 | H35: =G35 -> 497274 | I35: =H35 -> 497274 | J35: =I35 -> 497274 | K35: =J35 -> 497274
A36: Total de activos circulantes | B36: =EEFF!B36 -> 23585133 | C36: =EEFF!C36 -> 27656127 | D36: =EEFF!D36 -> 26443110 | E36: =EEFF!E36 -> 24685303 | F36: =EEFF!F36 -> 31660678 | G36: =SUM(G29:G35) -> 38217681 | H36: =SUM(H29:H35) -> 38549858 | I36: =SUM(I29:I35) -> 42884057 | J36: =SUM(J29:J35) -> 47487403 | K36: =SUM(K29:K35) -> 47568780
A37: Activo financiero restringido | B37: =EEFF!B37 -> 4206485 | C37: =EEFF!C37 -> 4234822 | D37: =EEFF!D37 -> 4033700 | E37: =EEFF!E37 -> 4197349 | F37: =EEFF!F37 -> 4260349 | G37: =F37 -> 4260349 | H37: =G37 -> 4260349 | I37: =H37 -> 4260349 | J37: =I37 -> 4260349 | K37: =J37 -> 4260349
A38: Cuentas por cobrar, no circulante | B38: =EEFF!B38 -> 213118 | C38: =EEFF!C38 -> 0 | D38: =EEFF!D38 -> 0 | E38: =EEFF!E38 -> 0 | F38: =EEFF!F38 -> 0
A39: Propiedad, planta y equipo, neto | B39: =EEFF!B39 -> 289872297 | C39: =EEFF!C39 -> 280225020 | D39: =EEFF!D39 -> 278143135 | E39: =EEFF!E39 -> 266144886 | F39: =EEFF!F39 -> 254111593 | G39: =F39-G96-G12 -> 242032041 | H39: =G39-H96-H12 -> 229952489 | I39: =H39-I96-I12 -> 217872937 | J39: =I39-J96-J12 -> 205793385 | K39: =J39-K96-K12 -> 193713833
A40: Plusvalía | B40: =EEFF!B40 -> 7033750 | C40: =EEFF!C40 -> 7033750 | D40: =EEFF!D40 -> 7033750 | E40: =EEFF!E40 -> 7033750 | F40: =EEFF!F40 -> 7033750 | G40: =F40 -> 7033750 | H40: =G40 -> 7033750 | I40: =H40 -> 7033750 | J40: =I40 -> 7033750 | K40: =J40 -> 7033750
A41: Costos de exploración y evaluación | B41: =EEFF!B41 -> 173084 | C41: =EEFF!C41 -> 174084 | D41: =EEFF!D41 -> 0 | E41: =EEFF!E41 -> 0 | F41: =EEFF!F41 -> 0
A42: Activos intangibles, neto | B42: =EEFF!B42 -> 538918 | C42: =EEFF!C42 -> 525826 | D42: =EEFF!D42 -> 512733 | E42: =EEFF!E42 -> 499640 | F42: =EEFF!F42 -> 509989 | G42: =F42 -> 509989 | H42: =G42 -> 509989 | I42: =H42 -> 509989 | J42: =I42 -> 509989 | K42: =J42 -> 509989
...

Sheet Generation_PPA
A1: Panama Power Holdings, Inc. y Subsidiarias
A2: Generation_PPA - source-visible MW/MWh, price, and revenue bridge
A3: en B/. sin escala
A4: Filing facts only; use NOT_DISCLOSED where notes/MD&A are silent
A5: Anios | B5: FY21A | C5: FY22A | D5: FY23A | E5: FY24A | F5: FY25A | G5: FY26E | H5: FY27E | I5: FY28E | J5: FY29E | K5: FY30E
A7: A. Capacity and generation (MW -> MWh)
A8: Capacity MW - El Alto | F8: 73.18 | G8: 73.18 | H8: 73.18 | I8: 73.18 | J8: 73.18 | K8: 73.18
A9: Capacity MW - Pedregalito 1 | F9: 20.1 | G9: 20.1 | H9: 20.1 | I9: 20.1 | J9: 20.1 | K9: 20.1
A10: Capacity MW - Pedregalito 2 | F10: 12.5 | G10: 12.5 | H10: 12.5 | I10: 12.5 | J10: 12.5 | K10: 12.5
A11: Capacity MW - Cochea | F11: 15.5 | G11: 15.5 | H11: 15.5 | I11: 15.5 | J11: 15.5 | K11: 15.5
A12: Capacity MW - Mini Central El Alto | F12: 0.98 | G12: 0.98 | H12: 0.98 | I12: 0.98 | J12: 0.98 | K12: 0.98
A13: Capacity MW - Pedregalito Solar | F13: 9.9 | G13: 9.9 | H13: 9.9 | I13: 9.9 | J13: 9.9 | K13: 9.9
A14: Total visible capacity (MW) | F14: =F8+F9+F10+F11+F12+F13 -> 132.16 | G14: =G8+G9+G10+G11+G12+G13 -> 132.16 | H14: =H8+H9+H10+H11+H12+H13 -> 132.16 | I14: =I8+I9+I10+I11+I12+I13 -> 132.16 | J14: =J8+J9+J10+J11+J12+J13 -> 132.16 | K14: =K8+K9+K10+K11+K12+K13 -> 132.16
A17: NOT_DISCLOSED: disponibilidad (AVF) no divulgada en el filing — el CF neto ya la embebe.
A18: Plant factor / net CF - active | B18: NOT_DISCLOSED | C18: NOT_DISCLOSED | D18: 0.35 | E18: 0.465 | F18: 0.407 | G18: =G20 -> 0.41 | H18: =H20 -> 0.41 | I18: =I20 -> 0.41 | J18: =J20 -> 0.41 | K18: =K20 -> 0.41
A19: Bear | G19: 0.35 | H19: 0.35 | I19: 0.35 | J19: 0.35 | K19: 0.35
A20: Base | G20: 0.41 | H20: 0.41 | I20: 0.41 | J20: 0.41 | K20: 0.41
A21: Bull | G21: 0.46 | H21: 0.46 | I21: 0.46 | J21: 0.46 | K21: 0.46
A22: Hours per year | G22: 8760 | H22: 8760 | I22: 8760 | J22: 8760 | K22: 8760
A23: Generation MWh - El Alto | B23: NOT_DISCLOSED | C23: NOT_DISCLOSED | D23: NOT_DISCLOSED | E23: NOT_DISCLOSED | F23: NOT_DISCLOSED | G23: =G8*G22*G18 -> 262833.29 | H23: =H8*H22*H18 -> 262833.29 | I23: =I8*I22*I18 -> 262833.29 | J23: =J8*J22*J18 -> 262833.29 | K23: =K8*K22*K18 -> 262833.29
A24: Generation MWh - Pedregalito 1 | B24: NOT_DISCLOSED | C24: NOT_DISCLOSED | D24: NOT_DISCLOSED | E24: NOT_DISCLOSED | F24: NOT_DISCLOSED | G24: =G9*G22*G18 -> 72191.16 | H24: =H9*H22*H18 -> 72191.16 | I24: =I9*I22*I18 -> 72191.16 | J24: =J9*J22*J18 -> 72191.16 | K24: =K9*K22*K18 -> 72191.16
A25: Generation MWh - Pedregalito 2 | B25: NOT_DISCLOSED | C25: NOT_DISCLOSED | D25: NOT_DISCLOSED | E25: NOT_DISCLOSED | F25: NOT_DISCLOSED | G25: =G10*G22*G18 -> 44895 | H25: =H10*H22*H18 -> 44895 | I25: =I10*I22*I18 -> 44895 | J25: =J10*J22*J18 -> 44895 | K25: =K10*K22*K18 -> 44895
A26: Generation MWh - Cochea | B26: NOT_DISCLOSED | C26: NOT_DISCLOSED | D26: NOT_DISCLOSED | E26: NOT_DISCLOSED | F26: NOT_DISCLOSED | G26: =G11*G22*G18 -> 55669.8 | H26: =H11*H22*H18 -> 55669.8 | I26: =I11*I22*I18 -> 55669.8 | J26: =J11*J22*J18 -> 55669.8 | K26: =K11*K22*K18 -> 55669.8
A27: Generation MWh - Mini Central El Alto | B27: NOT_DISCLOSED | C27: NOT_DISCLOSED | D27: NOT_DISCLOSED | E27: NOT_DISCLOSED | F27: NOT_DISCLOSED | G27: =G12*G22*G18 -> 3519.768 | H27: =H12*H22*H18 -> 3519.768 | I27: =I12*I22*I18 -> 3519.768 | J27: =J12*J22*J18 -> 3519.768 | K27: =K12*K22*K18 -> 3519.768
A28: Generation MWh - Pedregalito Solar | B28: NOT_DISCLOSED | C28: NOT_DISCLOSED | D28: NOT_DISCLOSED | E28: NOT_DISCLOSED | F28: NOT_DISCLOSED | G28: =G13*G22*G18 -> 35556.84 | H28: =H13*H22*H18 -> 35556.84 | I28: =I13*I22*I18 -> 35556.84 | J28: =J13*J22*J18 -> 35556.84 | K28: =K13*K22*K18 -> 35556.84
A29: Historical generation MWh from filing | B29: NOT_DISCLOSED | C29: NOT_DISCLOSED | D29: 374482 | E29: 497784 | F29: 470665 | G29: NOT_DISCLOSED | H29: NOT_DISCLOSED | I29: NOT_DISCLOSED | J29: NOT_DISCLOSED | K29: NOT_DISCLOSED
A30: Total generation MWh | B30: NOT_DISCLOSED | C30: NOT_DISCLOSED | D30: 374482 | E30: 497784 | F30: 470665 | G30: =G23+G24+G25+G26+G27+G28 -> 474665.86 | H30: =H23+H24+H25+H26+H27+H28 -> 474665.86 | I30: =I23+I24+I25+I26+I27+I28 -> 474665.86 | J30: =J23+J24+J25+J26+J27+J28 -> 474665.86 | K30: =K23+K24+K25+K26+K27+K28 -> 474665.86
A32: A2. CND per-plant physical layer (MW x CF x 8.760 -> GWh, tied to CND)
A33: Source: CND generacion_YYYY.xlsx (hoja Generacion, fila 19 TOTAL, col GENPED/RCHICO/ALTOVALLE/HCAISAN/PEDREGALITO SOLAR POWER) + sector research note + maintainer research note
A34: Historical FY21-25 only (blue literals, cited); forecast columns explicit NOT_DISCLOSED — per-plant CND forecast wiring is Tasks 2-4.
A35: Pedregalito 1 (GENPED) - MW (CND/ASEP) | B35: 20.089 | C35: 20.089 | D35: 20.089 | E35: 20.089 | F35: 20.089 | G35: 20.089 | H35: 20.089 | I35: 20.089 | J35: 20.089 | K35: 20.089
A36: Pedregalito 1 (GENPED) - GWh (CND actual) | B36: 74.031 | C36: 94.227 | D36: 63.029 | E36: 80.932 | F36: 74.984 | G36: NOT_DISCLOSED | H36: NOT_DISCLOSED | I36: NOT_DISCLOSED | J36: NOT_DISCLOSED | K36: NOT_DISCLOSED
A37: Pedregalito 1 (GENPED) - CF literal (GWh/(MW*8.76)) | B37: =IF(AND(ISNUMBER(B36),ISNUMBER(B35)),B36/(B35*8.76),"") -> 0.42067935 | C37: =IF(AND(ISNUMBER(C36),ISNUMBER(C35)),C36/(C35*8.76),"") -> 0.53544262 | D37: =IF(AND(ISNUMBER(D36),ISNUMBER(D35)),D36/(D35*8.76),"") -> 0.35816075 | E37: =IF(AND(ISNUMBER(E36),ISNUMBER(E35)),E36/(E35*8.76),"") -> 0.45989411 | F37: =IF(AND(ISNUMBER(F36),ISNUMBER(F35)),F36/(F35*8.76),"") -> 0.42609475 | G37: =IF(AND(ISNUMBER(G36),ISNUMBER(G35)),G36/(G35*8.76),"") | H37: =IF(AND(ISNUMBER(H36),ISNUMBER(H35)),H36/(H35*8.76),"") | I37: =IF(AND(ISNUMBER(I36),ISNUMBER(I35)),I36/(I35*8.76),"") | ... K37: =IF(AND(ISNUMBER(K36),ISNUMBER(K35)),K36/(K35*8.76),"")
A38: Note: Discrepancia §7.1 (data-foundation, NO resuelta): MW=20.089 ASEP (adoptado) vs 19.9 MW en el registro de concesiones .csv; una versión previa usaba 20.1.
A39: Pedregalito 2 (RCHICO) - MW (CND/ASEP) | B39: 12.52 | C39: 12.52 | D39: 12.52 | E39: 12.52 | F39: 12.52 | G39: 12.52 | H39: 12.52 | I39: 12.52 | J39: 12.52 | K39: 12.52
A40: Pedregalito 2 (RCHICO) - GWh (CND actual) | B40: 47.312 | C40: 59.896 | D40: 39.863 | E40: 51.05 | F40: 48.083 | G40: NOT_DISCLOSED | H40: NOT_DISCLOSED | I40: NOT_DISCLOSED | J40: NOT_DISCLOSED | K40: NOT_DISCLOSED
A41: Pedregalito 2 (RCHICO) - CF literal (GWh/(MW*8.76)) | B41: =IF(AND(ISNUMBER(B40),ISNUMBER(B39)),B40/(B39*8.76),"") -> 0.43138285 | C41: =IF(AND(ISNUMBER(C40),ISNUMBER(C39)),C40/(C39*8.76),"") -> 0.54612164 | D41: =IF(AND(ISNUMBER(D40),ISNUMBER(D39)),D40/(D39*8.76),"") -> 0.36346412 | E41: =IF(AND(ISNUMBER(E40),ISNUMBER(E39)),E40/(E39*8.76),"") -> 0.4654653 | F41: =IF(AND(ISNUMBER(F40),ISNUMBER(F39)),F40/(F39*8.76),"") -> 0.43841269 | G41: =IF(AND(ISNUMBER(G40),ISNUMBER(G39)),G40/(G39*8.76),"") | H41: =IF(AND(ISNUMBER(H40),ISNUMBER(H39)),H40/(H39*8.76),"") | I41: =IF(AND(ISNUMBER(I40),ISNUMBER(I39)),I40/(I39*8.76),"") | ... K41: =IF(AND(ISNUMBER(K40),ISNUMBER(K39)),K40/(K39*8.76),"")
A42: Cochea (ALTOVALLE) - MW (CND/ASEP) | B42: 15.5 | C42: 15.5 | D42: 15.5 | E42: 15.5 | F42: 15.5 | G42: 15.5 | H42: 15.5 | I42: 15.5 | J42: 15.5 | K42: 15.5
A43: Cochea (ALTOVALLE) - GWh (CND actual) | B43: 54.274 | C43: 78.092 | D43: 54.207 | E43: 69.298 | F43: 64.129 | G43: NOT_DISCLOSED | H43: NOT_DISCLOSED | I43: NOT_DISCLOSED | J43: NOT_DISCLOSED | K43: NOT_DISCLOSED
A44: Cochea (ALTOVALLE) - CF literal (GWh/(MW*8.76)) | B44: =IF(AND(ISNUMBER(B43),ISNUMBER(B42)),B43/(B42*8.76),"") -> 0.39972014 | C44: =IF(AND(ISNUMBER(C43),ISNUMBER(C42)),C43/(C42*8.76),"") -> 0.57513625 | D44: =IF(AND(ISNUMBER(D43),ISNUMBER(D42)),D43/(D42*8.76),"") -> 0.39922669 | E44: =IF(AND(ISNUMBER(E43),ISNUMBER(E42)),E43/(E42*8.76),"") -> 0.51036972 | F44: =IF(AND(ISNUMBER(F43),ISNUMBER(F42)),F43/(F42*8.76),"") -> 0.47230078 | G44: =IF(AND(ISNUMBER(G43),ISNUMBER(G42)),G43/(G42*8.76),"") | H44: =IF(AND(ISNUMBER(H43),ISNUMBER(H42)),H43/(H42*8.76),"") | I44: =IF(AND(ISNUMBER(I43),ISNUMBER(I42)),I43/(I42*8.76),"") | ... K44: =IF(AND(ISNUMBER(K43),ISNUMBER(K42)),K43/(K42*8.76),"")
...

Sheet Debt_Schedule
A1: Panama Power Holdings, Inc. y Subsidiarias
A2: Debt_Schedule — Bonos 2020 (Hydro Caisán) · DSCR / LLCR / PLCR · covenant ≥ 1.25x (Nota 16)
A3: Saldo bruto y covenant: Nota 16 + MD&A EE.FF. FY2025 (5.875% fijo, amort. trim. $1.75M, barrido $2.0M/año)
A5: Años | B5: FY21A | C5: FY22A | D5: FY23A | E5: FY24A | F5: FY25A | G5: FY26E | H5: FY27E | I5: FY28E | J5: FY29E | K5: FY30E
A7: A. ROLL DE DEUDA — Bonos 2020 (saldo bruto a capital, Nota 16)
A8: Saldo bruto inicial | F8: =E11 -> 140250000 | G8: =F11 -> 131250000 | H8: =G11 -> 122250000 | I8: =H11 -> 113250000 | J8: =I11 -> 104250000 | K8: =J11 -> 95250000
A9: (−) Amortización programada (4 × $1.75M/trim., Nota 16) | F9: 7000000 | G9: 7000000 | H9: 7000000 | I9: 7000000 | J9: 7000000 | K9: 7000000
A10: (−) Barrido de caja anual ($2.0M, Nota 16) | F10: 2000000 | G10: 2000000 | H10: 2000000 | I10: 2000000 | J10: 2000000 | K10: 2000000
A11: Saldo bruto final | C11: 158250000 | D11: 153000000 | E11: 140250000 | F11: =F8-F9-F10 -> 131250000 | G11: =G8-G9-G10 -> 122250000 | H11: =H8-H9-H10 -> 113250000 | I11: =I8-I9-I10 -> 104250000 | J11: =J8-J9-J10 -> 95250000 | K11: =K8-K9-K10 -> 86250000
A13: B. INTERESES Y COSTOS FINANCIEROS (→ ModeloFinanciero!20)
A14: Tasa de interés fija Bonos 2020 (Nota 16) | F14: 0.05875 | G14: 0.05875 | H14: 0.05875 | I14: 0.05875 | J14: 0.05875 | K14: 0.05875
A15: Gasto de interés bonos (tasa × saldo bruto promedio) | F15: =0.05875*(F8+F11)/2 -> 7975312.5 | G15: =0.05875*(G8+G11)/2 -> 7446562.5 | H15: =0.05875*(H8+H11)/2 -> 6917812.5 | I15: =0.05875*(I8+I11)/2 -> 6389062.5 | J15: =0.05875*(J8+J11)/2 -> 5860312.5 | K15: =0.05875*(K8+K11)/2 -> 5331562.5
A16: (+) Amortización costos financiamiento diferidos (Nota 16) | F16: 208786 | G16: 208786 | H16: 208786 | I16: 208786 | J16: 208786 | K16: 172783
A17: (+) Otros costos financieros (préstamos/otros, plano FY25A) | F17: 497097 | G17: 497097 | H17: 497097 | I17: 497097 | J17: 497097 | K17: 497097
A18: Costos financieros totales (→ MF!20) | F18: =F15+F16+F17 -> 8681195.5 | G18: =G15+G16+G17 -> 8152445.5 | H18: =H15+H16+H17 -> 7623695.5 | I18: =I15+I16+I17 -> 7094945.5 | J18: =J15+J16+J17 -> 6566195.5 | K18: =K15+K16+K17 -> 6001442.5
A20: C. COBERTURA DE SERVICIO DE DEUDA (DSCR) — covenant Nota 16 (≥ 1.25x)
A21: EBITDA (MF: util. operativa + D&A − ingreso crédito fiscal) | B21: =ModeloFinanciero!B19+ModeloFinanciero!B12-ModeloFinanciero!B11 -> 29850167 | C21: =ModeloFinanciero!C19+ModeloFinanciero!C12-ModeloFinanciero!C11 -> 38912517 | D21: =ModeloFinanciero!D19+ModeloFinanciero!D12-ModeloFinanciero!D11 -> 30407494 | E21: =ModeloFinanciero!E19+ModeloFinanciero!E12-ModeloFinanciero!E11 -> 34831675 | F21: =ModeloFinanciero!F19+ModeloFinanciero!F12-ModeloFinanciero!F11 -> 32921080 | G21: =ModeloFinanciero!G19+ModeloFinanciero!G12-ModeloFinanciero!G11 -> 23190749 | H21: =ModeloFinanciero!H19+ModeloFinanciero!H12-ModeloFinanciero!H11 -> 13165697 | I21: =ModeloFinanciero!I19+ModeloFinanciero!I12-ModeloFinanciero!I11 -> 18742244 | ... K21: =ModeloFinanciero!K19+ModeloFinanciero!K12-ModeloFinanciero!K11 -> 11215760
A22: Servicio de deuda (interés + amort. programada + barrido) | F22: =F15+F9+F10 -> 16975312 | G22: =G15+G9+G10 -> 16446562 | H22: =H15+H9+H10 -> 15917812 | I22: =I15+I9+I10 -> 15389062 | J22: =J15+J9+J10 -> 14860312 | K22: =K15+K9+K10 -> 14331562
A23: DSCR covenant (EBITDA / servicio de deuda) | F23: =IFERROR(F21/F22,"") -> 1.9393505 | G23: =IFERROR(G21/G22,"") -> 1.4100667 | H23: =IFERROR(H21/H22,"") -> 0.82710468 | I23: =IFERROR(I21/I22,"") -> 1.2178938 | J23: =IFERROR(J21/J22,"") -> 1.2532773 | K23: =IFERROR(K21/K22,"") -> 0.78259156
A24: Covenant mínimo (Nota 16) | F24: 1.25 | G24: 1.25 | H24: 1.25 | I24: 1.25 | J24: 1.25 | K24: 1.25
A25: ESTADO covenant | G25: =IFERROR(IF(G23>=1.25,"CUMPLE","INCUMPLE <1.25x"),"") -> CUMPLE | H25: =IFERROR(IF(H23>=1.25,"CUMPLE","INCUMPLE <1.25x"),"") -> INCUMPLE <1.25x | I25: =IFERROR(IF(I23>=1.25,"CUMPLE","INCUMPLE <1.25x"),"") -> INCUMPLE <1.25x | J25: =IFERROR(IF(J23>=1.25,"CUMPLE","INCUMPLE <1.25x"),"") -> CUMPLE | K25: =IFERROR(IF(K23>=1.25,"CUMPLE","INCUMPLE <1.25x"),"") -> INCUMPLE <1.25x
A26: NOTA FY25A: modelo DSCR 1.94x vs Nota 16 divulgado 1.84x — diferencia metodológica: interés avg-balance bond-only $7,975,313 vs Gasto por intereses Nota 16 $8,323,100 (−$347,788) + servicio de deuda anualizado $9.0M vs suma trimestral real MD&A $9,652,587; columnas forecast no afectadas.
A28: D. DSCR ANALÍTICO (CFADS) — lente crédito
A29: CFADS (EBITDA − impuesto pagado − capex mantenimiento) | F29: =F21+ModeloFinanciero!F24-ABS(ModeloFinanciero!F96) -> 27591926 | G29: =G21+ModeloFinanciero!G24-ABS(ModeloFinanciero!G96) -> 21031036 | H29: =H21+ModeloFinanciero!H24-ABS(ModeloFinanciero!H96) -> 14277460 | I29: =I21+ModeloFinanciero!I24-ABS(ModeloFinanciero!I96) -> 17750732 | J29: =J21+ModeloFinanciero!J24-ABS(ModeloFinanciero!J96) -> 17491130 | K29: =K21+ModeloFinanciero!K24-ABS(ModeloFinanciero!K96) -> 12440411
A30: DSCR analítico (CFADS / servicio de deuda) | F30: =IFERROR(F29/F22,"") -> 1.6254149 | G30: =IFERROR(G29/G22,"") -> 1.2787497 | H30: =IFERROR(H29/H22,"") -> 0.89694864 | I30: =IFERROR(I29/I22,"") -> 1.1534642 | J30: =IFERROR(J29/J22,"") -> 1.1770365 | K30: =IFERROR(K29/K22,"") -> 0.86804289
A32: E. LLCR / PLCR — cobertura vida-préstamo / vida-proyecto (nuevas; @Kd 5.875%, no WACC)
A33: Tasa de descuento Kd (costo de deuda, Nota 16) | G33: 0.05875 | H33: 0.05875 | I33: 0.05875 | J33: 0.05875 | K33: 0.05875
