Workbook

Sheet Cover
A1: Tyson Foods Institutional Financial Model
A2: TSN | USD millions | Historical FY2021-FY2025 | Interim Q2 FY2026 | Forecast FY2026-FY2030
A4: Model status | B4: =Checks!B3 -> OK
A5: Active scenario | B5: =Assumptions!B5 -> Base
A6: Valuation date / latest actual | B6: 46109
A7: DCF value / share | B7: =DCF!B30 -> 108.90302
A8: Exit multiple value / share | B8: =DCF!B34 -> 91.735803
A9: FY2026E reported sales | B9: =Forecast_3Stmt!C7 -> 57202.244
A10: FY2026E operating income | B10: =Forecast_3Stmt!C12 -> 2440.7169
A11: FY2026E free cash flow | B11: =Forecast_3Stmt!C64 -> 1820.7999
A12: Claim mappings | B12: =COUNTA(Sources!A5:A718) -> 714
A13: Model version | B13: 2.0.0
A14: Governance status | B14: OWNER-GATED; INDEPENDENT CERTIFICATION PENDING
A15: Model Architecture
A16: Flow | B16: Sources -> historical statements -> protein drivers -> assumptions -> integrated forecast -> debt/credit -> DCF/sensitivity -> checks
A17: Scenario control | B17: Assumptions!B4: 1 Base / 2 Bull / 3 Bear
A18: Governance boundary | B18: Tyson facts and one-offs are source-mapped; unsourced market/comps inputs are not forced. This model is a donor-company mechanism, not a Panama forecast.
A21: Series | B21: 2021A | C21: 2022A | D21: 2023A | E21: 2024A | F21: 2025A | G21: 2026E | H21: 2027E | I21: 2028E | J21: 2029E | K21: 2030E
A22: Sales | B22: =Historical_IS!B7 -> 47049 | C22: =Historical_IS!C7 -> 53282 | D22: =Historical_IS!D7 -> 52881 | E22: =Historical_IS!E7 -> 53309 | F22: =Historical_IS!F7 -> 54441 | G22: =Forecast_3Stmt!C7 -> 57202.244 | H22: =Forecast_3Stmt!D7 -> 59200.932 | I22: =Forecast_3Stmt!E7 -> 61279.299 | J22: =Forecast_3Stmt!F7 -> 63440.813 | K22: =Forecast_3Stmt!G7 -> 65689.103
A36: Segment | B36: FY2025A | C36: FY2030E
A37: Beef | B37: =Segment_Build!F7 -> 21623 | C37: =Segment_Build!K7 -> 24079.777
A38: Pork | B38: =Segment_Build!F8 -> 5781 | C38: =Segment_Build!K8 -> 6972.6694
A39: Chicken | B39: =Segment_Build!F9 -> 16837 | C39: =Segment_Build!K9 -> 21964.647
A40: Prepared Foods | B40: =Segment_Build!F10 -> 9930 | C40: =Segment_Build!K10 -> 12270.421
A41: International | B41: =Segment_Build!F11 -> 2291 | C41: =Segment_Build!K11 -> 2789.5374

Sheet Historical_IS
A1: Historical Income Statement
A2: USD millions except per-share data; audited GAAP actuals
A4: Metric | B4: 2021A | C4: 2022A | D4: 2023A | E4: 2024A | F4: 2025A
A6: Consolidated Income Statement
A7: Sales | B7: 47049 | C7: 53282 | D7: 52881 | E7: 53309 | F7: 54441
A8: Cost of sales | B8: 40523 | C8: 46614 | D8: 50250 | E8: 49682 | F8: 50879
A9: Gross profit | B9: 6526 | C9: 6668 | D9: 2631 | E9: 3627 | F9: 3562
A10: SG&A | B10: 2130 | C10: 2258 | D10: 2245 | E10: 2218 | F10: 2121
A11: Goodwill impairment | B11: 0 | C11: 0 | D11: 781 | E11: 0 | F11: 343
A12: Operating income | B12: 4396 | C12: 4410 | D12: -395 | E12: 1409 | F12: 1098
A13: Interest income | B13: 8 | C13: 17 | D13: 30 | E13: 89 | F13: 73
A14: Interest expense | B14: 428 | C14: 365 | D14: 355 | E14: 481 | F14: 449
A15: Other income, net | B15: 65 | C15: 87 | D15: 42 | E15: 75 | F15: 47
A16: Income before taxes | B16: 4041 | C16: 4149 | D16: -678 | E16: 1092 | F16: 769
A17: Income tax expense | B17: 981 | C17: 900 | D17: -29 | E17: 270 | F17: 262
A18: Net income including NCI | B18: 3060 | C18: 3249 | D18: -649 | E18: 822 | F18: 507
... A22: Diluted weighted-average shares | B22: 365 | C22: 363 | D22: 284 | E22: 356 | F22: 357

Sheet Historical_BS
A1: Historical Balance Sheet
A2: USD millions except per-share data; audited GAAP actuals
A4: Metric | B4: 2021A | C4: 2022A | D4: 2023A | E4: 2024A | F4: 2025A
A6: Assets
A7: Cash and cash equivalents | B7: 2507 | C7: 1031 | D7: 573 | E7: 1717 | F7: 1229
A8: Accounts receivable | B8: 2400 | C8: 2577 | D8: 2476 | E8: 2406 | F8: 2524
A9: Inventories | B9: 4382 | C9: 5514 | D9: 5328 | E9: 5195 | F9: 5681
A10: Other current assets | B10: 533 | C10: 508 | D10: 345 | E10: 433 | F10: 482
A11: Total current assets | B11: 9822 | C11: 9630 | D11: 8722 | E11: 9751 | F11: 9916
A12: Net PP&E | B12: 7837 | C12: 8685 | D12: 9634 | E12: 9442 | F12: 9204
A13: Goodwill | B13: 10549 | C13: 10513 | D13: 9878 | E13: 9819 | F13: 9469
A14: Intangible assets | B14: 6519 | C14: 6252 | D14: 6098 | E14: 5875 | F14: 5624
A15: Other assets | B15: 1582 | C15: 1741 | D15: 1919 | E15: 2213 | F15: 2445
A16: Total assets | B16: 36309 | C16: 36821 | D16: 36251 | E16: 37100 | F16: 36658
A18: Liabilities and Equity
A19: Current debt | B19: 1067 | C19: 459 | D19: 1895 | E19: 74 | F19: 909
A20: Accounts payable | B20: 2225 | C20: 2483 | D20: 2594 | E20: 2402 | F20: 2601
A21: Other current liabilities | B21: 3033 | C21: 2371 | D21: 2010 | E21: 2311 | F21: 2879
A22: Total current liabilities | B22: 6325 | C22: 5313 | D22: 6499 | E22: 4787 | F22: 6389
A23: Long-term debt | B23: 8281 | C23: 7862 | D23: 7611 | E23: 9713 | F23: 7921
A24: Deferred income taxes | B24: 2195 | C24: 2458 | D24: 2308 | E24: 2285 | F24: 2195
A25: Other liabilities | B25: 1654 | C25: 1377 | D25: 1578 | E25: 1801 | F25: 1926
A26: Total liabilities | B26: 18455 | C26: 17010 | D26: 17996 | E26: 18586 | F26: 18431
A27: Equity attributable to Tyson | B27: 17723 | C27: 19702 | D27: 18133 | E27: 18390 | F27: 18085
A28: Equity attributable to NCI | B28: 131 | C28: 109 | D28: 122 | E28: 124 | F28: 142
A29: Total shareholders' equity | B29: 17854 | C29: 19811 | D29: 18255 | E29: 18514 | F29: 18227
A30: Total liabilities and equity | B30: =B26+B29 -> 36309 | C30: =C26+C29 -> 36821 | D30: =D26+D29 -> 36251 | E30: =E26+E29 -> 37100 | F30: =F26+F29 -> 36658

Sheet Historical_CF
A1: Historical Cash Flow Statement
A2: USD millions except per-share data; audited GAAP actuals
A4: Metric | B4: 2021A | C4: 2022A | D4: 2023A | E4: 2024A | F4: 2025A
A6: Cash Flow Statement
A7: Net income | B7: 3060 | C7: 3249 | D7: -649 | E7: 822 | F7: 507
A8: Depreciation | B8: 934 | C8: 945 | D8: 1100 | E8: 1159 | F8: 1093
A9: Amortization | B9: 280 | C9: 257 | D9: 239 | E9: 241 | F9: 268
A10: Deferred income taxes | B10: -125 | C10: 264 | D10: -183 | E10: -45 | F10: -76
A11: Impairments and disposals | B11: 60 | C11: 34 | D11: 882 | E11: 131 | F11: 469
A12: Stock-based compensation | B12: 91 | C12: 93 | D12: 61 | E12: 101 | F12: 100
A13: Working capital and other operating changes | B13: =B14-SUM(B7:B12) -> -460 | C13: =C14-SUM(C7:C12) -> -2155 | D13: =D14-SUM(D7:D12) -> 302 | E13: =E14-SUM(E7:E12) -> 181 | F13: =F14-SUM(F7:F12) -> -206
A14: Cash provided by operating activities | B14: 3840 | C14: 2687 | D14: 1752 | E14: 2590 | F14: 2155
A15: Capital expenditures | B15: -1209 | C15: -1887 | D15: -1939 | E15: -1132 | F15: -978
A16: Cash used for investing activities | B16: 58 | C16: -1935 | D16: -2299 | E16: -888 | F16: -665
A17: Debt issuance | B17: 585 | C17: 103 | D17: 1130 | E17: 2415 | F17: 175
A18: Debt payments | B18: -2632 | C18: -1191 | D18: -603 | E18: -1641 | F18: -1262
A19: Share repurchases | B19: -67 | C19: -702 | D19: -354 | E19: -49 | F19: -196
A20: Dividends | B20: -636 | C20: -653 | D20: -670 | E20: -684 | F20: -697
A21: Cash from financing activities | B21: -2731 | C21: -2323 | D21: 88 | E21: -581 | F21: -1977
A22: FX and other cash movement | B22: =B23-B14-B16-B21 -> 4 | C22: =C23-C14-C16-C21 -> -35 | D22: =D23-D14-D16-D21 -> 1 | E22: =E23-E14-E16-E21 -> 23 | F22: =F23-F14-F16-F21 -> -1
A23: Change in cash | B23: 1171 | C23: -1606 | D23: -458 | E23: 1144 | F23: -488
A24: Ending cash | B24: 2507 | C24: 1031 | D24: 573 | E24: 1717 | F24: 1229
A25: Free cash flow | B25: =B14+B15 -> 2631 | C25: =C14+C15 -> 800 | D25: =D14+D15 -> -187 | E25: =E14+E15 -> 1458 | F25: =F14+F15 -> 1177

Sheet Segment_Build
A1: Segment Build
A2: FY21-FY22 use legacy allocation; FY23-FY25 use June 2026 five-segment recast
A4: Metric | B4: 2021A | C4: 2022A | D4: 2023A | E4: 2024A | F4: 2025A | G4: 2026E | H4: 2027E | I4: 2028E | J4: 2029E | K4: 2030E
A6: Sales by Segment
A7: Beef | B7: 17999 | C7: 19854 | D7: 19325 | E7: 20479 | F7: 21623 | G7: =F7*(1+Protein_Drivers!B66)*(1+Protein_Drivers!G66)*(1+Assumptions!$B$97) -> 22245.992 | H7: =G7*(1+Protein_Drivers!C66)*(1+Protein_Drivers!H66) -> 22690.912 | I7: =H7*(1+Protein_Drivers!D66)*(1+Protein_Drivers!I66) -> 23144.73 | J7: =I7*(1+Protein_Drivers!E66)*(1+Protein_Drivers!J66) -> 23607.625 | K7: =J7*(1+Protein_Drivers!F66)*(1+Protein_Drivers!K66) -> 24079.777
A8: Pork | B8: 6277 | C8: 6414 | D8: 5768 | E8: 5903 | F8: 5781 | G8: =F8*(1+Protein_Drivers!B67)*(1+Protein_Drivers!G67)*(1+Assumptions!$B$97) -> 6190.317 | H8: =G8*(1+Protein_Drivers!C67)*(1+Protein_Drivers!H67) -> 6377.2646 | I8: =H8*(1+Protein_Drivers!D67)*(1+Protein_Drivers!I67) -> 6569.858 | J8: =I8*(1+Protein_Drivers!E67)*(1+Protein_Drivers!J67) -> 6768.2677 | K8: =J8*(1+Protein_Drivers!F67)*(1+Protein_Drivers!K67) -> 6972.6694
A9: Chicken | B9: 13733 | C9: 16961 | D9: 17060 | E9: 16425 | F9: 16837 | G9: =F9*(1+Protein_Drivers!B68)*(1+Protein_Drivers!G68)*(1+Assumptions!$B$97) -> 18029.124 | H9: =G9*(1+Protein_Drivers!C68)*(1+Protein_Drivers!H68) -> 18941.398 | I9: =H9*(1+Protein_Drivers!D68)*(1+Protein_Drivers!I68) -> 19899.833 | J9: =I9*(1+Protein_Drivers!E68)*(1+Protein_Drivers!J68) -> 20906.764 | K9: =J9*(1+Protein_Drivers!F68)*(1+Protein_Drivers!K68) -> 21964.647
A10: Prepared Foods | B10: 8853 | C10: 9689 | D10: 9845 | E10: 9851 | F10: 9930 | G10: =F10*(1+Protein_Drivers!B69)*(1+Protein_Drivers!G69)*(1+Assumptions!$B$97) -> 10476.713 | H10: =G10*(1+Protein_Drivers!C69)*(1+Protein_Drivers!H69) -> 10898.925 | I10: =H10*(1+Protein_Drivers!D69)*(1+Protein_Drivers!I69) -> 11338.152 | J10: =I10*(1+Protein_Drivers!E69)*(1+Protein_Drivers!J69) -> 11795.079 | K10: =J10*(1+Protein_Drivers!F69)*(1+Protein_Drivers!K69) -> 12270.421
A11: International | B11: 1990 | C11: 2355 | D11: 2515 | E11: 2353 | F11: 2291 | G11: =F11*(1+Protein_Drivers!B70)*(1+Protein_Drivers!G70)*(1+Assumptions!$B$97) -> 2381.7588 | H11: =G11*(1+Protein_Drivers!C70)*(1+Protein_Drivers!H70) -> 2477.7437 | I11: =H11*(1+Protein_Drivers!D70)*(1+Protein_Drivers!I70) -> 2577.5968 | J11: =I11*(1+Protein_Drivers!E70)*(1+Protein_Drivers!J70) -> 2681.474 | K11: =J11*(1+Protein_Drivers!F70)*(1+Protein_Drivers!K70) -> 2789.5374
A12: Intersegment eliminations | B12: -1803 | C12: -1991 | D12: -1632 | E12: -1702 | F12: -2021 | G12: =F12*(1+Protein_Drivers!B71)*(1+Protein_Drivers!G71)*(1+Assumptions!$B$97) -> -2121.6613 | H12: =G12*(1+Protein_Drivers!C71)*(1+Protein_Drivers!H71) -> -2185.3112 | I12: =H12*(1+Protein_Drivers!D71)*(1+Protein_Drivers!I71) -> -2250.8705 | J12: =I12*(1+Protein_Drivers!E71)*(1+Protein_Drivers!J71) -> -2318.3966 | K12: =J12*(1+Protein_Drivers!F71)*(1+Protein_Drivers!K71) -> -2387.9485
A13: Total sales | B13: =SUM(B7:B12) -> 47049 | C13: =SUM(C7:C12) -> 53282 | D13: =SUM(D7:D12) -> 52881 | E13: =SUM(E7:E12) -> 53309 | F13: =SUM(F7:F12) -> 54441 | G13: =SUM(G7:G12) -> 57202.244 | H13: =SUM(H7:H12) -> 59200.932 | I13: =SUM(I7:I12) -> 61279.299 | ... K13: =SUM(K7:K12) -> 65689.103
A15: Segment Operating Income
A16: Beef operating income | B16: 3240 | C16: 2502 | D16: 38 | E16: -246 | F16: -984 | G16: =G7*(Assumptions!B71+Protein_Drivers!B76) -> -424.89845 | H16: =H7*(Assumptions!C71+Protein_Drivers!C76) -> -113.45456 | I16: =I7*(Assumptions!D71+Protein_Drivers!D76) -> 0 | J16: =J7*(Assumptions!E71+Protein_Drivers!E76) -> 118.03812 | K16: =K7*(Assumptions!F71+Protein_Drivers!F76) -> 240.79777
A17: Pork operating income | B17: 328 | C17: 193 | D17: -75 | E17: 26 | F17: -141 | G17: =G8*(Assumptions!B72+Protein_Drivers!B77) -> 285.99265 | H17: =H8*(Assumptions!C72+Protein_Drivers!C77) -> 299.73144 | I17: =I8*(Assumptions!D72+Protein_Drivers!D77) -> 315.35318 | J17: =J8*(Assumptions!E72+Protein_Drivers!E77) -> 331.64512 | K17: =K8*(Assumptions!F72+Protein_Drivers!F77) -> 348.63347
A18: Chicken operating income | B18: -625 | C18: 955 | D18: -378 | E18: 1397 | F18: 1860 | G18: =G9*(Assumptions!B73+Protein_Drivers!B78) -> 2053.5173 | H18: =H9*(Assumptions!C73+Protein_Drivers!C78) -> 2121.4366 | I18: =I9*(Assumptions!D73+Protein_Drivers!D78) -> 2188.9816 | J18: =J9*(Assumptions!E73+Protein_Drivers!E78) -> 2257.9305 | K18: =K9*(Assumptions!F73+Protein_Drivers!F78) -> 2328.2525
A19: Prepared Foods operating income | B19: 1456 | C19: 746 | D19: 1157 | E19: 1224 | F19: 1248 | G19: =G10*(Assumptions!B74+Protein_Drivers!B79) -> 1331.5903 | H19: =H10*(Assumptions!C74+Protein_Drivers!C79) -> 1395.0624 | I19: =I10*(Assumptions!D74+Protein_Drivers!D79) -> 1462.6216 | J19: =J10*(Assumptions!E74+Protein_Drivers!E79) -> 1533.3603 | K19: =K10*(Assumptions!F74+Protein_Drivers!F79) -> 1595.1547
A20: International operating income | B20: -3 | C20: 14 | D20: -158 | E20: 28 | F20: 155 | G20: =G11*(Assumptions!B75+Protein_Drivers!B80) -> 178.39374 | H20: =H11*(Assumptions!C75+Protein_Drivers!C80) -> 188.30852 | I20: =I11*(Assumptions!D75+Protein_Drivers!D80) -> 201.05255 | J20: =J11*(Assumptions!E75+Protein_Drivers!E80) -> 211.83644 | K20: =K11*(Assumptions!F75+Protein_Drivers!F80) -> 223.16299
A21: Total segment operating income | B21: =SUM(B16:B20) -> 4396 | C21: =SUM(C16:C20) -> 4410 | D21: =SUM(D16:D20) -> 584 | E21: =SUM(E16:E20) -> 2429 | F21: =SUM(F16:F20) -> 2138 | G21: =SUM(G16:G20) -> 3424.5955 | H21: =SUM(H16:H20) -> 3891.0844 | I21: =SUM(I16:I20) -> 4168.0089 | ... K21: =SUM(K16:K20) -> 4736.0015
A22: Corporate expenses | B22: 0 | C22: 0 | D22: -750 | E22: -791 | F22: -783 | G22: =-G13*(Assumptions!$B$79-Assumptions!$B$85) -> -697.86738 | H22: =-H13*(Assumptions!$B$79-Assumptions!$B$85) -> -722.25137 | I22: =-I13*(Assumptions!$B$79-Assumptions!$B$85) -> -747.60744 | J22: =-J13*(Assumptions!$B$79-Assumptions!$B$85) -> -773.97792 | K22: =-K13*(Assumptions!$B$79-Assumptions!$B$85) -> -801.40705
A23: Amortization | B23: 0 | C23: 0 | D23: -229 | E23: -229 | F23: -257 | G23: =-G13*Assumptions!$B$85 -> -286.01122 | H23: =-H13*Assumptions!$B$85 -> -296.00466 | I23: =-I13*Assumptions!$B$85 -> -306.39649 | J23: =-J13*Assumptions!$B$85 -> -317.20406 | K23: =-K13*Assumptions!$B$85 -> -328.44551
A24: Consolidated operating income | B24: =SUM(B21:B23) -> 4396 | C24: =SUM(C21:C23) -> 4410 | D24: =SUM(D21:D23) -> -395 | E24: =SUM(E21:E23) -> 1409 | F24: =SUM(F21:F23) -> 1098 | G24: =SUM(G21:G23) -> 2440.7169 | H24: =SUM(H21:H23) -> 2872.8283 | I24: =SUM(I21:I23) -> 3114.005 | ... K24: =SUM(K21:K23) -> 3606.1489

Sheet Assumptions
A1: Assumptions & Scenarios
A2: Blue/yellow cells are editable analyst inputs. FY2026 guidance is on a comparable 52-week basis.
A4: Scenario selector (1 Base / 2 Bull / 3 Bear) | B4: 1
A5: Active scenario | B5: =IF(B4=1,"Base",IF(B4=2,"Bull","Bear")) -> Base
A8: Base Price / Mix Growth
A9: Segment | B9: 2026E | C9: 2027E | D9: 2028E | E9: 2029E | F9: 2030E
A10: Beef | B10: 0.03 | C10: 0.02 | D10: 0.02 | E10: 0.02 | F10: 0.02
A11: Pork | B11: 0.03 | C11: 0.02 | D11: 0.02 | E11: 0.02 | F11: 0.02
A12: Chicken | B12: 0.03 | C12: 0.03 | D12: 0.03 | E12: 0.03 | F12: 0.03
A13: Prepared Foods | B13: 0.03 | C13: 0.03 | D13: 0.03 | E13: 0.03 | F13: 0.03
A14: International | B14: 0.02 | C14: 0.03 | D14: 0.03 | E14: 0.03 | F14: 0.03
A15: Intersegment eliminations | B15: 0.03 | C15: 0.03 | D15: 0.03 | E15: 0.03 | F15: 0.03
A17: Bull Price / Mix Growth
A18: Segment | B18: 2026E | C18: 2027E | D18: 2028E | E18: 2029E | F18: 2030E
A19: Beef | B19: 0.05 | C19: 0.04 | D19: 0.04 | E19: 0.04 | F19: 0.04
A20: Pork | B20: 0.05 | C20: 0.04 | D20: 0.04 | E20: 0.04 | F20: 0.04
A21: Chicken | B21: 0.05 | C21: 0.05 | D21: 0.05 | E21: 0.05 | F21: 0.05
A22: Prepared Foods | B22: 0.05 | C22: 0.05 | D22: 0.05 | E22: 0.05 | F22: 0.05
A23: International | B23: 0.04 | C23: 0.05 | D23: 0.05 | E23: 0.05 | F23: 0.05
A24: Intersegment eliminations | B24: 0.05 | C24: 0.05 | D24: 0.05 | E24: 0.05 | F24: 0.05
A26: Bear Price / Mix Growth
A27: Segment | B27: 2026E | C27: 2027E | D27: 2028E | E27: 2029E | F27: 2030E
A28: Beef | B28: 0 | C28: -0.01 | D28: -0.01 | E28: -0.01 | F28: -0.01
A29: Pork | B29: 0 | C29: -0.01 | D29: -0.01 | E29: -0.01 | F29: -0.01
A30: Chicken | B30: 0 | C30: 0 | D30: 0 | E30: 0 | F30: 0
A31: Prepared Foods | B31: 0 | C31: 0 | D31: 0 | E31: 0 | F31: 0
A32: International | B32: -0.01 | C32: 0 | D32: 0 | E32: 0 | F32: 0
A33: Intersegment eliminations | B33: 0 | C33: 0 | D33: 0 | E33: 0 | F33: 0
A35: Active Price / Mix Growth
A36: Segment | B36: 2026E | C36: 2027E | D36: 2028E | E36: 2029E | F36: 2030E
A37: Beef | B37: =IF($B$4=1,B10,IF($B$4=2,B19,B28)) -> 0.03 | C37: =IF($B$4=1,C10,IF($B$4=2,C19,C28)) -> 0.02 | D37: =IF($B$4=1,D10,IF($B$4=2,D19,D28)) -> 0.02 | E37: =IF($B$4=1,E10,IF($B$4=2,E19,E28)) -> 0.02 | F37: =IF($B$4=1,F10,IF($B$4=2,F19,F28)) -> 0.02
A38: Pork | B38: =IF($B$4=1,B11,IF($B$4=2,B20,B29)) -> 0.03 | C38: =IF($B$4=1,C11,IF($B$4=2,C20,C29)) -> 0.02 | D38: =IF($B$4=1,D11,IF($B$4=2,D20,D29)) -> 0.02 | E38: =IF($B$4=1,E11,IF($B$4=2,E20,E29)) -> 0.02 | F38: =IF($B$4=1,F11,IF($B$4=2,F20,F29)) -> 0.02
A39: Chicken | B39: =IF($B$4=1,B12,IF($B$4=2,B21,B30)) -> 0.03 | C39: =IF($B$4=1,C12,IF($B$4=2,C21,C30)) -> 0.03 | D39: =IF($B$4=1,D12,IF($B$4=2,D21,D30)) -> 0.03 | E39: =IF($B$4=1,E12,IF($B$4=2,E21,E30)) -> 0.03 | F39: =IF($B$4=1,F12,IF($B$4=2,F21,F30)) -> 0.03
A40: Prepared Foods | B40: =IF($B$4=1,B13,IF($B$4=2,B22,B31)) -> 0.03 | C40: =IF($B$4=1,C13,IF($B$4=2,C22,C31)) -> 0.03 | D40: =IF($B$4=1,D13,IF($B$4=2,D22,D31)) -> 0.03 | E40: =IF($B$4=1,E13,IF($B$4=2,E22,E31)) -> 0.03 | F40: =IF($B$4=1,F13,IF($B$4=2,F22,F31)) -> 0.03
A41: International | B41: =IF($B$4=1,B14,IF($B$4=2,B23,B32)) -> 0.02 | C41: =IF($B$4=1,C14,IF($B$4=2,C23,C32)) -> 0.03 | D41: =IF($B$4=1,D14,IF($B$4=2,D23,D32)) -> 0.03 | E41: =IF($B$4=1,E14,IF($B$4=2,E23,E32)) -> 0.03 | F41: =IF($B$4=1,F14,IF($B$4=2,F23,F32)) -> 0.03
A42: Intersegment eliminations | B42: =IF($B$4=1,B15,IF($B$4=2,B24,B33)) -> 0.03 | C42: =IF($B$4=1,C15,IF($B$4=2,C24,C33)) -> 0.03 | D42: =IF($B$4=1,D15,IF($B$4=2,D24,D33)) -> 0.03 | E42: =IF($B$4=1,E15,IF($B$4=2,E24,E33)) -> 0.03 | F42: =IF($B$4=1,F15,IF($B$4=2,F24,F33)) -> 0.03
A45: Base Segment Operating Margin
A46: Segment | B46: 2026E | C46: 2027E | D46: 2028E | E46: 2029E | F46: 2030E
A47: Beef | B47: -0.0191 | C47: -0.005 | D47: 0 | E47: 0.005 | F47: 0.01
A48: Pork | B48: 0.0462 | C48: 0.047 | D48: 0.048 | E48: 0.049 | F48: 0.05
...

Sheet Protein_Drivers
A1: Protein Economics & Volume-Price-Mix
A2: Tyson donor-company facts drive independent volume, price/mix and protein-input margin mechanics; they are not Panama assumptions
A6: Reported Sales Change Bridge
A7: Metric | B7: FY2024 vs FY2023 | C7: FY2025 vs FY2024 | D7: 6M FY2026 vs 6M FY2025
A8: Prior-period sales | B8: 52881 | C8: 53309 | D8: 26697
A9: Volume effect | B9: 19 | C9: -10 | D9: -354
A10: Average price effect | B10: 298 | C10: 1795 | D10: 1430
A11: Legal-contingency effect | B11: 111 | C11: -653 | D11: 193
A12: Calculated current sales | B12: =SUM(B8:B11) -> 53309 | C12: =SUM(C8:C11) -> 54441 | D12: =SUM(D8:D11) -> 27966
A13: Reported current sales | B13: 53309 | C13: 54441 | D13: 27966
A14: Bridge check | B14: =B12-B13 -> 0 | C14: =C12-C13 -> 0 | D14: =D12-D13 -> 0
A17: Segment Volume / Average Price
A18: Segment | B18: FY25 volume | C18: FY25 price | D18: 6M FY26 volume | E18: 6M FY26 price
A19: Beef | B19: -0.019 | C19: 0.09 | D19: -0.101 | E19: 0.143
A20: Pork | B20: -0.017 | C20: 0.053 | D20: 0.03 | E20: 0.014
A21: Chicken | B21: 0.026 | C21: -0.001 | D21: 0.027 | E21: 0.009
A22: Prepared Foods | B22: -0.025 | C22: 0.033 | D22: 0.003 | E22: 0.062
A23: International | D23: -0.009 | E23: 0.017
A26: Reported Cost-of-Sales Change Bridge
A27: Metric | B27: FY2024 vs FY2023 | C27: FY2025 vs FY2024 | D27: 6M FY2026 vs 6M FY2025
A28: Prior-period cost of sales | B28: 50250 | C28: 49682 | D28: 25002
A29: Volume effect | B29: 18 | C29: -10 | D29: -328
A30: Input cost / pound effect | B30: -586 | C30: 1207 | D30: 1522
A31: Calculated current cost of sales | B31: =SUM(B28:B30) -> 49682 | C31: =SUM(C28:C30) -> 50879 | D31: =SUM(D28:D30) -> 26196
A32: Reported current cost of sales | B32: 49682 | C32: 50879 | D32: 26196
A33: Bridge check | B33: =B31-B32 -> 0 | C33: =C31-C32 -> 0 | D33: =D31-D32 -> 0
A36: Input-Cost Decomposition
A37: Driver | B37: FY2025 vs FY2024 | C37: 6M FY2026 vs 6M FY2025
A38: Live cattle / Beef | B38: 1840 | C38: 1450
A39: Prepared Foods raw materials | B39: 345 | C39: 160
A40: Live hogs / Pork | B40: 295 | C40: 55
A41: Chicken feed ingredients | B41: -340 | C41: -60
A42: Freight and transportation | B42: -110 | C42: 45
A43: Restructuring charges | B43: 43 | C43: 33
A44: Legal contingency accruals | B44: -89 | C44: 21
A45: Plant closures and disposals | B45: -165 | C45: -23
A46: Commodity derivatives | C46: -57
A47: Facility fire / insurance | B47: -34
A48: Other mix, operating costs and productivity (derived residual) | B48: =B50-SUM(B38:B47) -> -578 | C48: =C50-SUM(C38:C47) -> -102
A49: Decomposed total | B49: =SUM(B38:B48) -> 1207 | C49: =SUM(C38:C48) -> 1522
...

Sheet Forecast_3Stmt
A1: Integrated Three-Statement Forecast
A2: FY2026E-FY2030E; 53rd week bridged explicitly; USD millions except per-share data
A4: Metric | B4: 2025A | C4: 2026E | D4: 2027E | E4: 2028E | F4: 2029E | G4: 2030E
A6: Income Statement
A7: Sales | B7: 54441 | C7: =Segment_Build!G13 -> 57202.244 | D7: =Segment_Build!H13 -> 59200.932 | E7: =Segment_Build!I13 -> 61279.299 | F7: =Segment_Build!J13 -> 63440.813 | G7: =Segment_Build!K13 -> 65689.103
A8: Growth | C8: =C7/B7-1 -> 0.050719938 | D8: =D7/C7-1 -> 0.034940722 | E8: =E7/D7-1 -> 0.035106994 | F8: =F7/E7-1 -> 0.035273158 | G8: =G7/F7-1 -> 0.035439168
A9: Cost of sales | B9: 50879 | C9: =C7-C10 -> 52473.437 | D9: =D7-D10 -> 53960.066 | E9: =E7-E10 -> 55714.122 | F9: =F7-F10 -> 57541.552 | G9: =G7-G10 -> 59455.39
A10: Gross profit | B10: 3562 | C10: =SUM(C11:C12) -> 4728.8066 | D10: =SUM(D11:D12) -> 5240.8656 | E10: =SUM(E11:E12) -> 5565.1769 | F10: =SUM(F11:F12) -> 5899.261 | G10: =SUM(G11:G12) -> 6233.713
A11: SG&A | B11: 2121 | C11: =C7*Assumptions!$B$80 -> 2288.0898 | D11: =D7*Assumptions!$B$80 -> 2368.0373 | E11: =E7*Assumptions!$B$80 -> 2451.1719 | F11: =F7*Assumptions!$B$80 -> 2537.6325 | G11: =G7*Assumptions!$B$80 -> 2627.5641
A12: Operating income | B12: 1098 | C12: =Segment_Build!G24 -> 2440.7169 | D12: =Segment_Build!H24 -> 2872.8283 | E12: =Segment_Build!I24 -> 3114.005 | F12: =Segment_Build!J24 -> 3361.6285 | G12: =Segment_Build!K24 -> 3606.1489
A13: Operating margin | B13: 0.0202 | C13: =C12/C7 -> 0.042668201 | D13: =D12/D7 -> 0.048526742 | E13: =E12/E7 -> 0.050816589 | F13: =F12/F7 -> 0.052988421 | G13: =G12/G7 -> 0.054897217
A14: Interest income | B14: 73 | C14: =Schedules!B36*Assumptions!$B$98 -> 12.29 | D14: =Schedules!C36*Assumptions!$B$98 -> 11.440449 | E14: =Schedules!D36*Assumptions!$B$98 -> 11.840186 | F14: =Schedules!E36*Assumptions!$B$98 -> 12.25586 | G14: =Schedules!F36*Assumptions!$B$98 -> 12.688163
A15: Interest expense | B15: 449 | C15: =Schedules!C33 -> 365 | D15: =Schedules!D33 -> 346.12144 | E15: =Schedules!E33 -> 282.21389 | F15: =Schedules!F33 -> 212.92068 | G15: =Schedules!G33 -> 137.49037
A16: Income before taxes | B16: 769 | C16: =SUM(C12,C14)-C15 -> 2088.0069 | D16: =SUM(D12,D14)-D15 -> 2538.1474 | E16: =SUM(E12,E14)-E15 -> 2843.6312 | F16: =SUM(F12,F14)-F15 -> 3160.9637 | G16: =SUM(G12,G14)-G15 -> 3481.3467
A17: Income tax expense | B17: 262 | C17: =C16*Assumptions!$B$81 -> 522.00172 | D17: =D16*Assumptions!$B$81 -> 634.53684 | E17: =E16*Assumptions!$B$81 -> 710.90781 | F17: =F16*Assumptions!$B$81 -> 790.24093 | G17: =G16*Assumptions!$B$81 -> 870.33667
A18: Net income including NCI | B18: 507 | C18: =C16-C17 -> 1566.0052 | D18: =D16-D17 -> 1903.6105 | E18: =E16-E17 -> 2132.7234 | F18: =F16-F17 -> 2370.7228 | G18: =G16-G17 -> 2611.01
A19: Net income attributable to NCI | B19: 33 | C19: =C18*Assumptions!$B$99 -> 31.320103 | D19: =D18*Assumptions!$B$99 -> 38.07221 | E19: =E18*Assumptions!$B$99 -> 42.654469 | F19: =F18*Assumptions!$B$99 -> 47.414456 | G19: =G18*Assumptions!$B$99 -> 52.2202
A20: Net income attributable to Tyson | B20: 474 | C20: =C18-C19 -> 1534.685 | D20: =D18-D19 -> 1865.5383 | E20: =E18-E19 -> 2090.069 | F20: =F18-F19 -> 2323.3083 | G20: =G18-G19 -> 2558.7898
A21: Diluted shares | B21: 357 | C21: =Schedules!C43 -> 354 | D21: =Schedules!D43 -> 354 | E21: =Schedules!E43 -> 354 | F21: =Schedules!F43 -> 354 | G21: =Schedules!G43 -> 354
A22: Diluted EPS | B22: 1.33 | C22: =C20/C21 -> 4.3352685 | D22: =D20/D21 -> 5.2698822 | E22: =E20/E21 -> 5.9041496 | F22: =F20/F21 -> 6.5630179 | G22: =G20/G21 -> 7.2282198
A25: Balance Sheet
A26: Cash | B26: 1229 | C26: =Schedules!C36 -> 1144.0449 | D26: =Schedules!D36 -> 1184.0186 | E26: =Schedules!E36 -> 1225.586 | F26: =Schedules!F36 -> 1268.8163 | G26: =Schedules!G36 -> 1313.7821
A27: Accounts receivable | B27: 2524 | C27: =Schedules!C8 -> 2664.2141 | D27: =Schedules!D8 -> 2757.3037 | E27: =Schedules!E8 -> 2854.1043 | F27: =Schedules!F8 -> 2954.7776 | G27: =Schedules!G8 -> 3059.4925
A28: Inventories | B28: 5681 | C28: =Schedules!C10 -> 5750.5137 | D28: =Schedules!D10 -> 5913.4319 | E28: =Schedules!E10 -> 6105.6572 | F28: =Schedules!F10 -> 6305.9235 | G28: =Schedules!G10 -> 6515.6591
A29: Other current assets | B29: 482 | C29: =Schedules!C14 -> 514.8202 | D29: =Schedules!D14 -> 532.80839 | E29: =Schedules!E14 -> 551.51369 | F29: =Schedules!F14 -> 570.96732 | G29: =Schedules!G14 -> 591.20192
A30: Total current assets | B30: 9916 | C30: =SUM(C26:C29) -> 10073.593 | D30: =SUM(D26:D29) -> 10387.563 | E30: =SUM(E26:E29) -> 10736.861 | F30: =SUM(F26:F29) -> 11100.485 | G30: =SUM(G26:G29) -> 11480.136
A31: Net PP&E | B31: 9204 | C31: =Schedules!C23 -> 8917.9888 | D31: =Schedules!D23 -> 8621.9841 | E31: =Schedules!E23 -> 8315.5876 | F31: =Schedules!F23 -> 7998.3836 | G31: =Schedules!G23 -> 7669.938
A32: Goodwill | B32: 9469 | C32: =B32*(1+Assumptions!$B$103) -> 9469 | D32: =C32*(1+Assumptions!$B$103) -> 9469 | E32: =D32*(1+Assumptions!$B$103) -> 9469 | F32: =E32*(1+Assumptions!$B$103) -> 9469 | G32: =F32*(1+Assumptions!$B$103) -> 9469
A33: Intangible assets | B33: 5624 | C33: =Schedules!C25 -> 5337.9888 | D33: =Schedules!D25 -> 5041.9841 | E33: =Schedules!E25 -> 4735.5876 | F33: =Schedules!F25 -> 4418.3836 | G33: =Schedules!G25 -> 4089.938
A34: Other assets | B34: 2445 | C34: =B34*(1+Assumptions!$B$104) -> 2445 | D34: =C34*(1+Assumptions!$B$104) -> 2445 | E34: =D34*(1+Assumptions!$B$104) -> 2445 | F34: =E34*(1+Assumptions!$B$104) -> 2445 | G34: =F34*(1+Assumptions!$B$104) -> 2445
A35: Total assets | B35: 36658 | C35: =SUM(C30:C34) -> 36243.57 | D35: =SUM(D30:D34) -> 35965.531 | E35: =SUM(E30:E34) -> 35702.036 | F35: =SUM(F30:F34) -> 35431.252 | G35: =SUM(G30:G34) -> 35154.012
A36: Current debt | B36: 909 | C36: =Schedules!C31 -> 769.15875 | D36: =Schedules!D31 -> 627.14199 | E36: =Schedules!E31 -> 473.15707 | F36: =Schedules!F31 -> 305.53416 | G36: =Schedules!G31 -> 124.15657
A37: Accounts payable | B37: 2601 | C37: =Schedules!C12 -> 2659.6126 | D37: =Schedules!D12 -> 2734.9623 | E37: =Schedules!E12 -> 2823.8664 | F37: =Schedules!F12 -> 2916.4896 | G37: =Schedules!G12 -> 3013.4924
A38: Other current liabilities | B38: 2879 | C38: =Schedules!C16 -> 2745.7077 | D38: =Schedules!D16 -> 2841.6447 | E38: =Schedules!E16 -> 2941.4063 | F38: =Schedules!F16 -> 3045.159 | G38: =Schedules!G16 -> 3153.0769
A39: Total current liabilities | B39: 6389 | C39: =SUM(C36:C38) -> 6174.4791 | D39: =SUM(D36:D38) -> 6203.749 | E39: =SUM(E36:E38) -> 6238.4298 | F39: =SUM(F36:F38) -> 6267.1828 | G39: =SUM(G36:G38) -> 6290.7258
A40: Long-term debt | B40: 7921 | C40: =Schedules!C32 -> 6922.4288 | D40: =Schedules!D32 -> 5644.2779 | E40: =Schedules!E32 -> 4258.4136 | F40: =Schedules!F32 -> 2749.8074 | G40: =Schedules!G32 -> 1117.4091
A41: Deferred income taxes | B41: 2195 | C41: =B41*(1+Assumptions!$B$105) -> 2195 | D41: =C41*(1+Assumptions!$B$105) -> 2195 | E41: =D41*(1+Assumptions!$B$105) -> 2195 | F41: =E41*(1+Assumptions!$B$105) -> 2195 | G41: =F41*(1+Assumptions!$B$105) -> 2195
A42: Other liabilities | B42: 1926 | C42: =B42*(1+Assumptions!$B$106) -> 1926 | D42: =C42*(1+Assumptions!$B$106) -> 1926 | E42: =D42*(1+Assumptions!$B$106) -> 1926 | F42: =E42*(1+Assumptions!$B$106) -> 1926 | G42: =F42*(1+Assumptions!$B$106) -> 1926
A43: Total liabilities | B43: 18431 | C43: =SUM(C39:C42) -> 17217.908 | D43: =SUM(D39:D42) -> 15969.027 | E43: =SUM(E39:E42) -> 14617.843 | F43: =SUM(F39:F42) -> 13137.99 | G43: =SUM(G39:G42) -> 11529.135
A44: Equity attributable to Tyson | B44: 18085 | C44: =Schedules!C41 -> 18852.343 | D44: =Schedules!D41 -> 19785.112 | E44: =Schedules!E41 -> 20830.146 | F44: =Schedules!F41 -> 21991.8 | G44: =Schedules!G41 -> 23271.195
...

Sheet Schedules
A1: Operating, Debt & Share Schedules
A2: Debt repayment is capped at beginning debt; excess cash accumulates above the minimum cash floor
A4: Metric | B4: 2025A | C4: 2026E | D4: 2027E | E4: 2028E | F4: 2029E | G4: 2030E
A6: Working Capital
A7: AR days | B7: 16.9 | C7: =Assumptions!$B$87 -> 17 | D7: =Assumptions!$B$87 -> 17 | E7: =Assumptions!$B$87 -> 17 | F7: =Assumptions!$B$87 -> 17 | G7: =Assumptions!$B$87 -> 17
A8: Accounts receivable | B8: 2524 | C8: =Forecast_3Stmt!C7*C7/365 -> 2664.2141 | D8: =Forecast_3Stmt!D7*D7/365 -> 2757.3037 | E8: =Forecast_3Stmt!E7*E7/365 -> 2854.1043 | F8: =Forecast_3Stmt!F7*F7/365 -> 2954.7776 | G8: =Forecast_3Stmt!G7*G7/365 -> 3059.4925
A9: Inventory days | B9: 40.8 | C9: =Assumptions!$B$88 -> 40 | D9: =Assumptions!$B$88 -> 40 | E9: =Assumptions!$B$88 -> 40 | F9: =Assumptions!$B$88 -> 40 | G9: =Assumptions!$B$88 -> 40
A10: Inventory | B10: 5681 | C10: =Forecast_3Stmt!C9*C9/365 -> 5750.5137 | D10: =Forecast_3Stmt!D9*D9/365 -> 5913.4319 | E10: =Forecast_3Stmt!E9*E9/365 -> 6105.6572 | F10: =Forecast_3Stmt!F9*F9/365 -> 6305.9235 | G10: =Forecast_3Stmt!G9*G9/365 -> 6515.6591
A11: AP days | B11: 18.7 | C11: =Assumptions!$B$89 -> 18.5 | D11: =Assumptions!$B$89 -> 18.5 | E11: =Assumptions!$B$89 -> 18.5 | F11: =Assumptions!$B$89 -> 18.5 | G11: =Assumptions!$B$89 -> 18.5
A12: Accounts payable | B12: 2601 | C12: =Forecast_3Stmt!C9*C11/365 -> 2659.6126 | D12: =Forecast_3Stmt!D9*D11/365 -> 2734.9623 | E12: =Forecast_3Stmt!E9*E11/365 -> 2823.8664 | F12: =Forecast_3Stmt!F9*F11/365 -> 2916.4896 | G12: =Forecast_3Stmt!G9*G11/365 -> 3013.4924
A13: Other current assets / sales | B13: 0.0089 | C13: =Assumptions!$B$90 -> 0.009 | D13: =Assumptions!$B$90 -> 0.009 | E13: =Assumptions!$B$90 -> 0.009 | F13: =Assumptions!$B$90 -> 0.009 | G13: =Assumptions!$B$90 -> 0.009
A14: Other current assets | B14: 482 | C14: =Forecast_3Stmt!C7*C13 -> 514.8202 | D14: =Forecast_3Stmt!D7*D13 -> 532.80839 | E14: =Forecast_3Stmt!E7*E13 -> 551.51369 | F14: =Forecast_3Stmt!F7*F13 -> 570.96732 | G14: =Forecast_3Stmt!G7*G13 -> 591.20192
A15: Other current liabilities / sales | B15: 0.0529 | C15: =Assumptions!$B$91 -> 0.048 | D15: =Assumptions!$B$91 -> 0.048 | E15: =Assumptions!$B$91 -> 0.048 | F15: =Assumptions!$B$91 -> 0.048 | G15: =Assumptions!$B$91 -> 0.048
A16: Other current liabilities | B16: 2879 | C16: =Forecast_3Stmt!C7*C15 -> 2745.7077 | D16: =Forecast_3Stmt!D7*D15 -> 2841.6447 | E16: =Forecast_3Stmt!E7*E15 -> 2941.4063 | F16: =Forecast_3Stmt!F7*F15 -> 3045.159 | G16: =Forecast_3Stmt!G7*G15 -> 3153.0769
A17: Operating NWC | B17: 3207 | C17: =SUM(C8,C10,C14)-SUM(C12,C16) -> 3524.2277 | D17: =SUM(D8,D10,D14)-SUM(D12,D16) -> 3626.937 | E17: =SUM(E8,E10,E14)-SUM(E12,E16) -> 3746.0024 | F17: =SUM(F8,F10,F14)-SUM(F12,F16) -> 3870.0198 | G17: =SUM(G8,G10,G14)-SUM(G12,G16) -> 3999.7842
A18: Change in operating NWC | C18: =C17-B17 -> 317.2277 | D18: =D17-C17 -> 102.70928 | E18: =E17-D17 -> 119.06542 | F18: =F17-E17 -> 124.01736 | G18: =G17-F17 -> 129.76447
A20: PP&E and Intangibles
A21: Capital expenditures | B21: 978 | C21: =Forecast_3Stmt!C7*Assumptions!$B$86 -> 858.03366 | D21: =Forecast_3Stmt!D7*Assumptions!$B$86 -> 888.01398 | E21: =Forecast_3Stmt!E7*Assumptions!$B$86 -> 919.18948 | F21: =Forecast_3Stmt!F7*Assumptions!$B$86 -> 951.61219 | G21: =Forecast_3Stmt!G7*Assumptions!$B$86 -> 985.33654
A22: Depreciation | B22: 1093 | C22: =Forecast_3Stmt!C7*Assumptions!$B$84 -> 1144.0449 | D22: =Forecast_3Stmt!D7*Assumptions!$B$84 -> 1184.0186 | E22: =Forecast_3Stmt!E7*Assumptions!$B$84 -> 1225.586 | F22: =Forecast_3Stmt!F7*Assumptions!$B$84 -> 1268.8163 | G22: =Forecast_3Stmt!G7*Assumptions!$B$84 -> 1313.7821
A23: Net PP&E | B23: 9204 | C23: =B23+C21-C22 -> 8917.9888 | D23: =C23+D21-D22 -> 8621.9841 | E23: =D23+E21-E22 -> 8315.5876 | F23: =E23+F21-F22 -> 7998.3836 | G23: =F23+G21-G22 -> 7669.938
A24: Amortization | B24: 268 | C24: =Forecast_3Stmt!C7*Assumptions!$B$85 -> 286.01122 | D24: =Forecast_3Stmt!D7*Assumptions!$B$85 -> 296.00466 | E24: =Forecast_3Stmt!E7*Assumptions!$B$85 -> 306.39649 | F24: =Forecast_3Stmt!F7*Assumptions!$B$85 -> 317.20406 | G24: =Forecast_3Stmt!G7*Assumptions!$B$85 -> 328.44551
A25: Intangible assets | B25: 5624 | C25: =B25-C24 -> 5337.9888 | D25: =C25-D24 -> 5041.9841 | E25: =D25-E24 -> 4735.5876 | F25: =E25-F24 -> 4418.3836 | G25: =F25-G24 -> 4089.938
A27: Cash, Debt & Equity
A28: Beginning gross debt | B28: 8830 | C28: =B30 -> 8830 | D28: =C30 -> 7691.5875 | E28: =D30 -> 6271.4199 | F28: =E30 -> 4731.5707 | G28: =F30 -> 3055.3416
A29: Financing requirement / (repayment) | C29: =MAX(-C28,C35-B36-Forecast_3Stmt!C56-Forecast_3Stmt!C57-C40) -> -1138.4125 | D29: =MAX(-D28,D35-C36-Forecast_3Stmt!D56-Forecast_3Stmt!D57-D40) -> -1420.1676 | E29: =MAX(-E28,E35-D36-Forecast_3Stmt!E56-Forecast_3Stmt!E57-E40) -> -1539.8492 | F29: =MAX(-F28,F35-E36-Forecast_3Stmt!F56-Forecast_3Stmt!F57-F40) -> -1676.2291 | G29: =MAX(-G28,G35-F36-Forecast_3Stmt!G56-Forecast_3Stmt!G57-G40) -> -1813.7759
A30: Ending gross debt | B30: 8830 | C30: =C28+C29 -> 7691.5875 | D30: =D28+D29 -> 6271.4199 | E30: =E28+E29 -> 4731.5707 | F30: =F28+F29 -> 3055.3416 | G30: =G28+G29 -> 1241.5657
A31: Current debt | B31: 909 | C31: =C30*Assumptions!$B$100 -> 769.15875 | D31: =D30*Assumptions!$B$100 -> 627.14199 | E31: =E30*Assumptions!$B$100 -> 473.15707 | F31: =F30*Assumptions!$B$100 -> 305.53416 | G31: =G30*Assumptions!$B$100 -> 124.15657
A32: Long-term debt | B32: 7921 | C32: =C30-C31 -> 6922.4288 | D32: =D30-D31 -> 5644.2779 | E32: =E30-E31 -> 4258.4136 | F32: =F30-F31 -> 2749.8074 | G32: =G30-G31 -> 1117.4091
A33: Interest expense | B33: 449 | C33: =Assumptions!$B$82 -> 365 | D33: =D28*Assumptions!$B$83 -> 346.12144 | E33: =E28*Assumptions!$B$83 -> 282.21389 | F33: =F28*Assumptions!$B$83 -> 212.92068 | G33: =G28*Assumptions!$B$83 -> 137.49037
A34: Minimum cash / sales | B34: 0.0226 | C34: =Assumptions!$B$93 -> 0.02 | D34: =Assumptions!$B$93 -> 0.02 | E34: =Assumptions!$B$93 -> 0.02 | F34: =Assumptions!$B$93 -> 0.02 | G34: =Assumptions!$B$93 -> 0.02
A35: Minimum ending cash | B35: 1229 | C35: =Forecast_3Stmt!C7*C34 -> 1144.0449 | D35: =Forecast_3Stmt!D7*D34 -> 1184.0186 | E35: =Forecast_3Stmt!E7*E34 -> 1225.586 | F35: =Forecast_3Stmt!F7*F34 -> 1268.8163 | G35: =Forecast_3Stmt!G7*G34 -> 1313.7821
A36: CFS ending cash | B36: 1229 | C36: =B36+Forecast_3Stmt!C56+Forecast_3Stmt!C57+C29+C40 -> 1144.0449 | D36: =C36+Forecast_3Stmt!D56+Forecast_3Stmt!D57+D29+D40 -> 1184.0186 | E36: =D36+Forecast_3Stmt!E56+Forecast_3Stmt!E57+E29+E40 -> 1225.586 | F36: =E36+Forecast_3Stmt!F56+Forecast_3Stmt!F57+F29+F40 -> 1268.8163 | G36: =F36+Forecast_3Stmt!G56+Forecast_3Stmt!G57+G29+G40 -> 1313.7821
A37: Cash floor surplus / (shortfall) | B37: 0 | C37: =C36-C35 -> 0 | D37: =D36-D35 -> 0 | E37: =E36-E35 -> 0 | F37: =F36-F35 -> 0 | G37: =G36-G35 -> 0
A38: Beginning Tyson equity | B38: 18085 | C38: =B41 -> 18085 | D38: =C41 -> 18852.343 | E38: =D41 -> 19785.112 | F38: =E41 -> 20830.146 | G38: =F41 -> 21991.8
A39: Tyson net income | B39: 474 | C39: =Forecast_3Stmt!C20 -> 1534.685 | D39: =Forecast_3Stmt!D20 -> 1865.5383 | E39: =Forecast_3Stmt!E20 -> 2090.069 | F39: =Forecast_3Stmt!F20 -> 2323.3083 | G39: =Forecast_3Stmt!G20 -> 2558.7898
A40: Dividends | B40: -697 | C40: =-Forecast_3Stmt!C20*Assumptions!$B$92 -> -767.34252 | D40: =-Forecast_3Stmt!D20*Assumptions!$B$92 -> -932.76915 | E40: =-Forecast_3Stmt!E20*Assumptions!$B$92 -> -1045.0345 | F40: =-Forecast_3Stmt!F20*Assumptions!$B$92 -> -1161.6542 | G40: =-Forecast_3Stmt!G20*Assumptions!$B$92 -> -1279.3949
A41: Ending Tyson equity | B41: 18085 | C41: =SUM(C38:C40) -> 18852.343 | D41: =SUM(D38:D40) -> 19785.112 | E41: =SUM(E38:E40) -> 20830.146 | F41: =SUM(F38:F40) -> 21991.8 | G41: =SUM(G38:G40) -> 23271.195
A42: NCI equity | B42: 142 | C42: =B42+Forecast_3Stmt!C19 -> 173.3201 | D42: =C42+Forecast_3Stmt!D19 -> 211.39231 | E42: =D42+Forecast_3Stmt!E19 -> 254.04678 | F42: =E42+Forecast_3Stmt!F19 -> 301.46124 | G42: =F42+Forecast_3Stmt!G19 -> 353.68144
A43: Diluted shares | B43: 357 | C43: =Assumptions!$B$101 -> 354 | D43: =Assumptions!$B$101 -> 354 | E43: =Assumptions!$B$101 -> 354 | F43: =Assumptions!$B$101 -> 354 | G43: =Assumptions!$B$101 -> 354

Sheet Interim_Bridge
A1: FY2026 Interim Bridge
A2: 6M actual + H2 estimate = comparable 52-week FY2026; week 53 shown separately
A4: Metric | B4: 6M Actual | C4: H2E (52w) | D4: FY26E (52w) | E4: Week 53 | F4: FY26E Reported
A6: Consolidated Bridge
A7: Sales | B7: 27966 | C7: =D7-B7 -> 28156.957 | D7: =F7/(1+Assumptions!$B$97) -> 56122.957 | E7: =F7-D7 -> 1079.2876 | F7: =Segment_Build!G13 -> 57202.244
A8: Operating income | B8: 737 | C8: =D8-B8 -> 1657.6656 | D8: =F8/(1+Assumptions!$B$97) -> 2394.6656 | E8: =F8-D8 -> 46.051262 | F8: =Segment_Build!G24 -> 2440.7169
A9: Cash from operating activities | B9: 829 | C9: =D9-B9 -> 1799.2895 | D9: =F9/(1+Assumptions!$B$97) -> 2628.2895 | E9: =F9-D9 -> 50.544029 | F9: =Forecast_3Stmt!C56 -> 2678.8336
A10: Capital expenditures | B10: 397 | C10: =D10-B10 -> 444.84435 | D10: =F10/(1+Assumptions!$B$97) -> 841.84435 | E10: =F10-D10 -> 16.189314 | F10: =Schedules!C21 -> 858.03366
A11: FY2026 GAAP-to-adjusted items | D11: =Assumptions!B107 -> 0 | F11: =Assumptions!B107 -> 0
A12: Adjusted / normalized operating income | B12: =B8 -> 737 | C12: =C8 -> 1657.6656 | D12: =D8+D11 -> 2394.6656 | E12: =E8 -> 46.051262 | F12: =F8+F11 -> 2440.7169
A13: Segment Sales Bridge
A14: Beef | B14: 10976 | C14: =D14-B14 -> 10850.256 | D14: =F14/(1+Assumptions!$B$97) -> 21826.256 | E14: =F14-D14 -> 419.7357 | F14: =Segment_Build!G7 -> 22245.992
A15: Pork | B15: 3188 | C15: =D15-B15 -> 2885.5186 | D15: =F15/(1+Assumptions!$B$97) -> 6073.5186 | E15: =F15-D15 -> 116.79843 | F15: =Segment_Build!G8 -> 6190.317
A16: Chicken | B16: 8498 | C16: =D16-B16 -> 9190.9522 | D16: =F16/(1+Assumptions!$B$97) -> 17688.952 | E16: =F16-D16 -> 340.17216 | F16: =Segment_Build!G9 -> 18029.124
A17: Prepared Foods | B17: 5184 | C17: =D17-B17 -> 5095.0395 | D17: =F17/(1+Assumptions!$B$97) -> 10279.04 | E17: =F17-D17 -> 197.67384 | F17: =Segment_Build!G10 -> 10476.713
A18: International | B18: 1159 | C18: =D18-B18 -> 1177.82 | D18: =F18/(1+Assumptions!$B$97) -> 2336.82 | E18: =F18-D18 -> 44.938846 | F18: =Segment_Build!G11 -> 2381.7588
A19: Intersegment eliminations | B19: -1039 | C19: =D19-B19 -> -1042.63 | D19: =F19/(1+Assumptions!$B$97) -> -2081.63 | E19: =F19-D19 -> -40.031346 | F19: =Segment_Build!G12 -> -2121.6613
A20: Total sales | B20: =SUM(B14:B19) -> 27966 | C20: =SUM(C14:C19) -> 28156.957 | D20: =SUM(D14:D19) -> 56122.957 | E20: =SUM(E14:E19) -> 1079.2876 | F20: =SUM(F14:F19) -> 57202.244
A22: Segment Operating Income Bridge
A23: Beef | B23: -559 | C23: =D23-B23 -> 142.11851 | D23: =F23/(1+Assumptions!$B$97) -> -416.88149 | E23: =F23-D23 -> -8.0169518 | F23: =Segment_Build!G16 -> -424.89845
A24: Pork | B24: 91 | C24: =D24-B24 -> 189.59656 | D24: =F24/(1+Assumptions!$B$97) -> 280.59656 | E24: =F24-D24 -> 5.3960877 | F24: =Segment_Build!G17 -> 285.99265
A25: Chicken | B25: 955 | C25: =D25-B25 -> 1059.7717 | D25: =F25/(1+Assumptions!$B$97) -> 2014.7717 | E25: =F25-D25 -> 38.745609 | F25: =Segment_Build!G18 -> 2053.5173
A26: Prepared Foods | B26: 670 | C26: =D26-B26 -> 636.46592 | D26: =F26/(1+Assumptions!$B$97) -> 1306.4659 | E26: =F26-D26 -> 25.124345 | F26: =Segment_Build!G19 -> 1331.5903
A27: International | B27: 79 | C27: =D27-B27 -> 96.027818 | D27: =F27/(1+Assumptions!$B$97) -> 175.02782 | E27: =F27-D27 -> 3.3659196 | F27: =Segment_Build!G20 -> 178.39374
A28: Corporate expenses | B28: -391 | C28: =D28-B28 -> -293.70007 | D28: =F28/(1+Assumptions!$B$97) -> -684.70007 | E28: =F28-D28 -> -13.167309 | F28: =Segment_Build!G22 -> -697.86738
A29: Amortization | B29: -108 | C29: =D29-B29 -> -172.61478 | D29: =F29/(1+Assumptions!$B$97) -> -280.61478 | E29: =F29-D29 -> -5.3964381 | F29: =Segment_Build!G23 -> -286.01122
A30: Consolidated operating income | B30: =SUM(B23:B29) -> 737 | C30: =SUM(C23:C29) -> 1657.6656 | D30: =SUM(D23:D29) -> 2394.6656 | E30: =SUM(E23:E29) -> 46.051262 | F30: =SUM(F23:F29) -> 2440.7169

Sheet Debt_Credit
A1: Debt, Liquidity & Covenant Analysis
A2: Q2 FY2026 filed debt stack; no undisclosed covenant threshold is invented
A4: Debt Stack at March 28, 2026
A5: Instrument | B5: Carrying amount | C5: Coupon | D5: Maturity | E5: Source / note
A6: Commercial paper | B6: 30 | C6: 0.04 | D6: <5 days | E6: S05 | Note 6 Debt
A7: 3.55% senior notes | B7: 1350 | C7: 0.0355 | D7: Jun-2027 | E7: S05 | Note 6 Debt
A8: 7.00% senior notes | B8: 18 | C8: 0.07 | D8: Jan-2028 | E8: S05 | Note 6 Debt
A9: 4.35% senior notes | B9: 1000 | C9: 0.0435 | D9: Mar-2029 | E9: S05 | Note 6 Debt
A10: 5.40% senior notes | B10: 600 | C10: 0.054 | D10: Mar-2029 | E10: S05 | Note 6 Debt
A11: 6.13% senior notes | B11: 157 | C11: 0.0613 | D11: Nov-2032 | E11: S05 | Note 6 Debt
A12: 5.70% senior notes | B12: 900 | C12: 0.057 | D12: Mar-2034 | E12: S05 | Note 6 Debt
A13: 4.88% senior notes | B13: 500 | C13: 0.0488 | D13: Aug-2034 | E13: S05 | Note 6 Debt
A14: 4.95% senior notes | B14: 500 | C14: 0.0495 | D14: Feb-2036 | E14: S05 | Note 6 Debt
A15: 5.15% senior notes | B15: 497 | C15: 0.0515 | D15: Aug-2044 | E15: S05 | Note 6 Debt
A16: 4.55% senior notes | B16: 713 | C16: 0.0455 | D16: Jun-2047 | E16: S05 | Note 6 Debt
A17: 5.10% senior notes | B17: 1485 | C17: 0.051 | D17: Sep-2048 | E17: S05 | Note 6 Debt
A18: Senior note discounts | B18: -34 | D18: N/A | E18: S05 | Note 6 Debt
A19: Finance leases | B19: 173 | D19: Various | E19: S05 | Note 6 Debt
A20: Other debt | B20: 235 | D20: Various | E20: S05 | Note 6 Debt
A21: Unamortized issuance costs | B21: -41 | D21: N/A | E21: S05 | Note 6 Debt
A22: Total debt | B22: =SUM(B6:B21) -> 8083
A23: Current debt | B23: 141
A24: Long-term debt | B24: 7942
A25: Classification check | B25: =B22-B23-B24 -> 0
A28: Credit & Liquidity Snapshot
A29: Metric | B29: Value | C29: Source / treatment
A30: Debt fair value | B30: 7823 | C30: S05 | Note 11 fair value
A31: Fixed-rate debt | B31: 8016 | C31: S05 | market-risk disclosure
A32: Weighted average fixed rate | B32: 0.049 | C32: S05 | market-risk disclosure
A33: Cash | B33: 500 | C33: S05 | balance sheet
A34: Net debt | B34: =B22-B33 -> 7583 | C34: Derived
A35: Total liquidity | B35: 3700 | C35: S06 | company-reported
A36: Minimum liquidity target | B36: 1000 | C36: S06 | management target
A37: Revolver commitment | B37: 2500 | C37: S05 | Note 6
A38: Revolver borrowed | B38: 0 | C38: S05 | Note 6
A39: Revolving term commitment | B39: 750 | C39: S05 | Note 6
A40: Revolving term borrowed | B40: 0 | C40: S05 | Note 6
A41: Liquidity headroom vs target | B41: =B35-B36 -> 2700 | C41: Derived
A44: Covenant & Refinancing Register
A45: Topic | B45: Requirement / fact | C45: Threshold | D45: Status | E45: Credit implication | F45: Source
...

Sheet DCF
A1: Discounted Cash Flow Valuation
A2: Valuation date 2026-03-28; H2 FY26 stub then FY27-FY30 mid-year convention; WACC/TGR/exit multiple are analyst inputs
A4: Metric | B4: As of / Input | C4: Remaining FY26E (incl. week 53) | D4: 2027E | E4: 2028E | F4: 2029E | G4: 2030E
A6: Unlevered Free Cash Flow
A7: Sales | C7: =Interim_Bridge!F7-Interim_Bridge!B7 -> 29236.244 | D7: =Forecast_3Stmt!D7 -> 59200.932 | E7: =Forecast_3Stmt!E7 -> 61279.299 | F7: =Forecast_3Stmt!F7 -> 63440.813 | G7: =Forecast_3Stmt!G7 -> 65689.103
A8: Growth | D8: =Forecast_3Stmt!D8 -> 0.034940722 | E8: =Forecast_3Stmt!E8 -> 0.035106994 | F8: =Forecast_3Stmt!F8 -> 0.035273158 | G8: =Forecast_3Stmt!G8 -> 0.035439168
A9: EBIT | C9: =Interim_Bridge!F8-Interim_Bridge!B8 -> 1703.7169 | D9: =Forecast_3Stmt!D12 -> 2872.8283 | E9: =Forecast_3Stmt!E12 -> 3114.005 | F9: =Forecast_3Stmt!F12 -> 3361.6285 | G9: =Forecast_3Stmt!G12 -> 3606.1489
A10: Cash tax on EBIT | C10: =C9*Assumptions!$B$81 -> 425.92922 | D10: =D9*Assumptions!$B$81 -> 718.20709 | E10: =E9*Assumptions!$B$81 -> 778.50124 | F10: =F9*Assumptions!$B$81 -> 840.40713 | G10: =G9*Assumptions!$B$81 -> 901.53723
A11: NOPAT | C11: =C9-C10 -> 1277.7877 | D11: =D9-D10 -> 2154.6213 | E11: =E9-E10 -> 2335.5037 | F11: =F9-F10 -> 2521.2214 | G11: =G9-G10 -> 2704.6117
A12: D&A | C12: =SUM(Forecast_3Stmt!C53:C54)*C7/Forecast_3Stmt!C7 -> 730.9061 | D12: =SUM(Forecast_3Stmt!D53:Forecast_3Stmt!D54) -> 1480.0233 | E12: =SUM(Forecast_3Stmt!E53:Forecast_3Stmt!E54) -> 1531.9825 | F12: =SUM(Forecast_3Stmt!F53:Forecast_3Stmt!F54) -> 1586.0203 | G12: =SUM(Forecast_3Stmt!G53:Forecast_3Stmt!G54) -> 1642.2276
A13: Capital expenditures | C13: =Interim_Bridge!F10-Interim_Bridge!B10 -> 461.03366 | D13: =-Forecast_3Stmt!D57 -> 888.01398 | E13: =-Forecast_3Stmt!E57 -> 919.18948 | F13: =-Forecast_3Stmt!F57 -> 951.61219 | G13: =-Forecast_3Stmt!G57 -> 985.33654
A14: Change in operating NWC | C14: =Schedules!C18*C7/Forecast_3Stmt!C7 -> 162.13606 | D14: =Schedules!D18 -> 102.70928 | E14: =Schedules!E18 -> 119.06542 | F14: =Schedules!F18 -> 124.01736 | G14: =Schedules!G18 -> 129.76447
A15: Unlevered FCF | C15: =SUM(C11:C12)-SUM(C13:C14) -> 1385.524 | D15: =SUM(D11:D12)-SUM(D13:D14) -> 2643.9213 | E15: =SUM(E11:E12)-SUM(E13:E14) -> 2829.2313 | F15: =SUM(F11:F12)-SUM(F13:F14) -> 3031.6122 | G15: =SUM(G11:G12)-SUM(G13:G14) -> 3231.7382
A16: Discount factor | C16: =1/(1+Assumptions!$B$94)^0.25 -> 0.97981157 | D16: =1/(1+Assumptions!$B$94)^1 -> 0.92165899 | E16: =1/(1+Assumptions!$B$94)^2 -> 0.84945529 | F16: =1/(1+Assumptions!$B$94)^3 -> 0.7829081 | G16: =1/(1+Assumptions!$B$94)^4 -> 0.72157428
A17: PV of FCF | C17: =C15*C16 -> 1357.5525 | D17: =D15*D16 -> 2436.7938 | E17: =E15*E16 -> 2403.3055 | F17: =F15*F16 -> 2373.4737 | G17: =G15*G16 -> 2331.9392
A19: Enterprise-to-Equity Bridge
A20: Terminal value - Gordon growth | B20: =G15*(1+Assumptions!$B$95)/(Assumptions!$B$94-Assumptions!$B$95) -> 50713.431
A21: Terminal discount period (years) | B21: 4.5
A22: PV of terminal value | B22: =B20/(1+Assumptions!$B$94)^B21 -> 35130.891
A23: Enterprise value - Gordon growth | B23: =SUM(C17:G17)+B22 -> 46033.956
A24: Cash | B24: 500
A25: Gross debt | B25: 8083
A26: Net debt | B26: 7583
A27: Noncontrolling interest | B27: 103
A28: Equity value - Gordon growth | B28: =B23+B24-B25-B27 -> 38347.956
A29: If-converted shares | B29: =Assumptions!$B$102 -> 352.1294
A30: Value per share - Gordon growth | B30: =B28/B29 -> 108.90302
A31: 2030E EBITDA | B31: =G9+G12 -> 5248.3765
A32: Terminal EV at exit multiple | B32: =B31*Assumptions!$B$96 -> 41987.012
A33: Enterprise value - exit multiple | B33: =SUM(C17:G17)+B32/(1+Assumptions!$B$94)^B21 -> 39988.873
A34: Value per share - exit multiple | B34: =(B33+B24-B25-B27)/B29 -> 91.735803
A35: Share Bridge
A36: Class A shares outstanding | B36: 282.1204
A37: Class B shares outstanding | B37: 70.009005
A38: If-converted shares | B38: =SUM(B36:B37) -> 352.1294
A39: Bridge check | B39: =B38-B29 -> 0

Sheet Sensitivity
A1: DCF Sensitivity
A2: Gordon-growth value per share across WACC and terminal-growth assumptions
A5: WACC / Terminal Growth Sensitivity
A7: WACC / TGR | B7: 0.01 | C7: 0.015 | D7: 0.02 | E7: 0.025 | F7: 0.03
A8: 0.075 | B8: =(DCF!C$15/(1+$A8)^0.25+DCF!D$15/(1+$A8)^1+DCF!E$15/(1+$A8)^2+DCF!F$15/(1+$A8)^3+DCF!G$15/(1+$A8)^4+(DCF!$G$15*(1+B$7)/($A8-B$7))/(1+$A8)^4.5+DCF!$B$24-DCF!$B$25-DCF!$B$27)/DCF!$B$29 -> 112.76872 | C8: =(DCF!C$15/(1+$A8)^0.25+DCF!D$15/(1+$A8)^1+DCF!E$15/(1+$A8)^2+DCF!F$15/(1+$A8)^3+DCF!G$15/(1+$A8)^4+(DCF!$G$15*(1+C$7)/($A8-C$7))/(1+$A8)^4.5+DCF!$B$24-DCF!$B$25-DCF!$B$27)/DCF!$B$29 -> 121.90374 | D8: =(DCF!C$15/(1+$A8)^0.25+DCF!D$15/(1+$A8)^1+DCF!E$15/(1+$A8)^2+DCF!F$15/(1+$A8)^3+DCF!G$15/(1+$A8)^4+(DCF!$G$15*(1+D$7)/($A8-D$7))/(1+$A8)^4.5+DCF!$B$24-DCF!$B$25-DCF!$B$27)/DCF!$B$29 -> 132.69968 | E8: =(DCF!C$15/(1+$A8)^0.25+DCF!D$15/(1+$A8)^1+DCF!E$15/(1+$A8)^2+DCF!F$15/(1+$A8)^3+DCF!G$15/(1+$A8)^4+(DCF!$G$15*(1+E$7)/($A8-E$7))/(1+$A8)^4.5+DCF!$B$24-DCF!$B$25-DCF!$B$27)/DCF!$B$29 -> 145.6548 | F8: =(DCF!C$15/(1+$A8)^0.25+DCF!D$15/(1+$A8)^1+DCF!E$15/(1+$A8)^2+DCF!F$15/(1+$A8)^3+DCF!G$15/(1+$A8)^4+(DCF!$G$15*(1+F$7)/($A8-F$7))/(1+$A8)^4.5+DCF!$B$24-DCF!$B$25-DCF!$B$27)/DCF!$B$29 -> 161.48884
A9: 0.08 | B9: =(DCF!C$15/(1+$A9)^0.25+DCF!D$15/(1+$A9)^1+DCF!E$15/(1+$A9)^2+DCF!F$15/(1+$A9)^3+DCF!G$15/(1+$A9)^4+(DCF!$G$15*(1+B$7)/($A9-B$7))/(1+$A9)^4.5+DCF!$B$24-DCF!$B$25-DCF!$B$27)/DCF!$B$29 -> 103.11258 | C9: =(DCF!C$15/(1+$A9)^0.25+DCF!D$15/(1+$A9)^1+DCF!E$15/(1+$A9)^2+DCF!F$15/(1+$A9)^3+DCF!G$15/(1+$A9)^4+(DCF!$G$15*(1+C$7)/($A9-C$7))/(1+$A9)^4.5+DCF!$B$24-DCF!$B$25-DCF!$B$27)/DCF!$B$29 -> 110.81646 | D9: =(DCF!C$15/(1+$A9)^0.25+DCF!D$15/(1+$A9)^1+DCF!E$15/(1+$A9)^2+DCF!F$15/(1+$A9)^3+DCF!G$15/(1+$A9)^4+(DCF!$G$15*(1+D$7)/($A9-D$7))/(1+$A9)^4.5+DCF!$B$24-DCF!$B$25-DCF!$B$27)/DCF!$B$29 -> 119.80431 | E9: =(DCF!C$15/(1+$A9)^0.25+DCF!D$15/(1+$A9)^1+DCF!E$15/(1+$A9)^2+DCF!F$15/(1+$A9)^3+DCF!G$15/(1+$A9)^4+(DCF!$G$15*(1+E$7)/($A9-E$7))/(1+$A9)^4.5+DCF!$B$24-DCF!$B$25-DCF!$B$27)/DCF!$B$29 -> 130.42632 | F9: =(DCF!C$15/(1+$A9)^0.25+DCF!D$15/(1+$A9)^1+DCF!E$15/(1+$A9)^2+DCF!F$15/(1+$A9)^3+DCF!G$15/(1+$A9)^4+(DCF!$G$15*(1+F$7)/($A9-F$7))/(1+$A9)^4.5+DCF!$B$24-DCF!$B$25-DCF!$B$27)/DCF!$B$29 -> 143.17274
A10: 0.085 | B10: =(DCF!C$15/(1+$A10)^0.25+DCF!D$15/(1+$A10)^1+DCF!E$15/(1+$A10)^2+DCF!F$15/(1+$A10)^3+DCF!G$15/(1+$A10)^4+(DCF!$G$15*(1+B$7)/($A10-B$7))/(1+$A10)^4.5+DCF!$B$24-DCF!$B$25-DCF!$B$27)/DCF!$B$29 -> 94.753063 | C10: =(DCF!C$15/(1+$A10)^0.25+DCF!D$15/(1+$A10)^1+DCF!E$15/(1+$A10)^2+DCF!F$15/(1+$A10)^3+DCF!G$15/(1+$A10)^4+(DCF!$G$15*(1+C$7)/($A10-C$7))/(1+$A10)^4.5+DCF!$B$24-DCF!$B$25-DCF!$B$27)/DCF!$B$29 -> 101.32269 | D10: =(DCF!C$15/(1+$A10)^0.25+DCF!D$15/(1+$A10)^1+DCF!E$15/(1+$A10)^2+DCF!F$15/(1+$A10)^3+DCF!G$15/(1+$A10)^4+(DCF!$G$15*(1+D$7)/($A10-D$7))/(1+$A10)^4.5+DCF!$B$24-DCF!$B$25-DCF!$B$27)/DCF!$B$29 -> 108.90302 | E10: =(DCF!C$15/(1+$A10)^0.25+DCF!D$15/(1+$A10)^1+DCF!E$15/(1+$A10)^2+DCF!F$15/(1+$A10)^3+DCF!G$15/(1+$A10)^4+(DCF!$G$15*(1+E$7)/($A10-E$7))/(1+$A10)^4.5+DCF!$B$24-DCF!$B$25-DCF!$B$27)/DCF!$B$29 -> 117.74675 | F10: =(DCF!C$15/(1+$A10)^0.25+DCF!D$15/(1+$A10)^1+DCF!E$15/(1+$A10)^2+DCF!F$15/(1+$A10)^3+DCF!G$15/(1+$A10)^4+(DCF!$G$15*(1+F$7)/($A10-F$7))/(1+$A10)^4.5+DCF!$B$24-DCF!$B$25-DCF!$B$27)/DCF!$B$29 -> 128.19842
A11: 0.09 | B11: =(DCF!C$15/(1+$A11)^0.25+DCF!D$15/(1+$A11)^1+DCF!E$15/(1+$A11)^2+DCF!F$15/(1+$A11)^3+DCF!G$15/(1+$A11)^4+(DCF!$G$15*(1+B$7)/($A11-B$7))/(1+$A11)^4.5+DCF!$B$24-DCF!$B$25-DCF!$B$27)/DCF!$B$29 -> 87.446727 | C11: =(DCF!C$15/(1+$A11)^0.25+DCF!D$15/(1+$A11)^1+DCF!E$15/(1+$A11)^2+DCF!F$15/(1+$A11)^3+DCF!G$15/(1+$A11)^4+(DCF!$G$15*(1+C$7)/($A11-C$7))/(1+$A11)^4.5+DCF!$B$24-DCF!$B$25-DCF!$B$27)/DCF!$B$29 -> 93.103385 | D11: =(DCF!C$15/(1+$A11)^0.25+DCF!D$15/(1+$A11)^1+DCF!E$15/(1+$A11)^2+DCF!F$15/(1+$A11)^3+DCF!G$15/(1+$A11)^4+(DCF!$G$15*(1+D$7)/($A11-D$7))/(1+$A11)^4.5+DCF!$B$24-DCF!$B$25-DCF!$B$27)/DCF!$B$29 -> 99.568137 | E11: =(DCF!C$15/(1+$A11)^0.25+DCF!D$15/(1+$A11)^1+DCF!E$15/(1+$A11)^2+DCF!F$15/(1+$A11)^3+DCF!G$15/(1+$A11)^4+(DCF!$G$15*(1+E$7)/($A11-E$7))/(1+$A11)^4.5+DCF!$B$24-DCF!$B$25-DCF!$B$27)/DCF!$B$29 -> 107.02747 | F11: =(DCF!C$15/(1+$A11)^0.25+DCF!D$15/(1+$A11)^1+DCF!E$15/(1+$A11)^2+DCF!F$15/(1+$A11)^3+DCF!G$15/(1+$A11)^4+(DCF!$G$15*(1+F$7)/($A11-F$7))/(1+$A11)^4.5+DCF!$B$24-DCF!$B$25-DCF!$B$27)/DCF!$B$29 -> 115.73002
A12: 0.095 | B12: =(DCF!C$15/(1+$A12)^0.25+DCF!D$15/(1+$A12)^1+DCF!E$15/(1+$A12)^2+DCF!F$15/(1+$A12)^3+DCF!G$15/(1+$A12)^4+(DCF!$G$15*(1+B$7)/($A12-B$7))/(1+$A12)^4.5+DCF!$B$24-DCF!$B$25-DCF!$B$27)/DCF!$B$29 -> 81.00742 | C12: =(DCF!C$15/(1+$A12)^0.25+DCF!D$15/(1+$A12)^1+DCF!E$15/(1+$A12)^2+DCF!F$15/(1+$A12)^3+DCF!G$15/(1+$A12)^4+(DCF!$G$15*(1+C$7)/($A12-C$7))/(1+$A12)^4.5+DCF!$B$24-DCF!$B$25-DCF!$B$27)/DCF!$B$29 -> 85.919275 | D12: =(DCF!C$15/(1+$A12)^0.25+DCF!D$15/(1+$A12)^1+DCF!E$15/(1+$A12)^2+DCF!F$15/(1+$A12)^3+DCF!G$15/(1+$A12)^4+(DCF!$G$15*(1+D$7)/($A12-D$7))/(1+$A12)^4.5+DCF!$B$24-DCF!$B$25-DCF!$B$27)/DCF!$B$29 -> 91.486044 | E12: =(DCF!C$15/(1+$A12)^0.25+DCF!D$15/(1+$A12)^1+DCF!E$15/(1+$A12)^2+DCF!F$15/(1+$A12)^3+DCF!G$15/(1+$A12)^4+(DCF!$G$15*(1+E$7)/($A12-E$7))/(1+$A12)^4.5+DCF!$B$24-DCF!$B$25-DCF!$B$27)/DCF!$B$29 -> 97.848066 | F12: =(DCF!C$15/(1+$A12)^0.25+DCF!D$15/(1+$A12)^1+DCF!E$15/(1+$A12)^2+DCF!F$15/(1+$A12)^3+DCF!G$15/(1+$A12)^4+(DCF!$G$15*(1+F$7)/($A12-F$7))/(1+$A12)^4.5+DCF!$B$24-DCF!$B$25-DCF!$B$27)/DCF!$B$29 -> 105.18886
A15: Key Inputs
A16: Base WACC | B16: =Assumptions!B94 -> 0.085
A17: Base terminal growth | B17: =Assumptions!B95 -> 0.02
A18: Base DCF value per share | B18: =DCF!B30 -> 108.90302

Sheet Sources
A1: Claim-Level Source Ledger
A2: Every material source input maps to a destination cell; valuation assumptions are explicitly unsourced
A4: Claim ID | B4: Metric | C4: Period / Date | D4: Source ID | E4: Source title | F4: Accession / identity | G4: Retrieved | H4: URL | I4: Exact locator | J4: Source value | K4: Unit / currency | L4: Destination | M4: Transformation | N4: Class / assumption status | O4: Status
A5: CLM-0001 | B5: Sales | C5: FY2021 | D5: S01 | E5: Tyson Foods FY2022 Form 10-K | F5: 0000100493-22-000097 | G5: 46219 | H5: https://www.sec.gov/Archives/edgar/data/100493/000010049322000097/tsn-20221001.htm | I5: FY2022 10-K, Consolidated Statements of Income, lines 1671-1699 | Sales | FY2021 | J5: 47049 | K5: USD mm | L5: Historical_IS!B7 | M5: Direct transcription from audited filing | N5: Audited filing | Primary / audited | O5: MAPPED
A6: CLM-0002 | B6: Sales | C6: FY2022 | D6: S01 | E6: Tyson Foods FY2022 Form 10-K | F6: 0000100493-22-000097 | G6: 46219 | H6: https://www.sec.gov/Archives/edgar/data/100493/000010049322000097/tsn-20221001.htm | I6: FY2022 10-K, Consolidated Statements of Income, lines 1671-1699 | Sales | FY2022 | J6: 53282 | K6: USD mm | L6: Historical_IS!C7 | M6: Direct transcription from audited filing | N6: Audited filing | Primary / audited | O6: MAPPED
A7: CLM-0003 | B7: Sales | C7: FY2023 | D7: S03 | E7: Tyson Foods FY2025 Form 10-K | F7: 0000100493-25-000095 | G7: 46219 | H7: https://www.sec.gov/Archives/edgar/data/100493/000010049325000095/tsn-20250927.htm | I7: FY2025 10-K, Consolidated Statements of Income, lines 1640-1654 | Sales | FY2023 | J7: 52881 | K7: USD mm | L7: Historical_IS!D7 | M7: Direct transcription from audited filing | N7: Audited filing | Primary / audited | O7: MAPPED
A8: CLM-0004 | B8: Sales | C8: FY2024 | D8: S03 | E8: Tyson Foods FY2025 Form 10-K | F8: 0000100493-25-000095 | G8: 46219 | H8: https://www.sec.gov/Archives/edgar/data/100493/000010049325000095/tsn-20250927.htm | I8: FY2025 10-K, Consolidated Statements of Income, lines 1640-1654 | Sales | FY2024 | J8: 53309 | K8: USD mm | L8: Historical_IS!E7 | M8: Direct transcription from audited filing | N8: Audited filing | Primary / audited | O8: MAPPED
A9: CLM-0005 | B9: Sales | C9: FY2025 | D9: S03 | E9: Tyson Foods FY2025 Form 10-K | F9: 0000100493-25-000095 | G9: 46219 | H9: https://www.sec.gov/Archives/edgar/data/100493/000010049325000095/tsn-20250927.htm | I9: FY2025 10-K, Consolidated Statements of Income, lines 1640-1654 | Sales | FY2025 | J9: 54441 | K9: USD mm | L9: Historical_IS!F7 | M9: Direct transcription from audited filing | N9: Audited filing | Primary / audited | O9: MAPPED
A10: CLM-0006 | B10: Cost of sales | C10: FY2021 | D10: S01 | E10: Tyson Foods FY2022 Form 10-K | F10: 0000100493-22-000097 | G10: 46219 | H10: https://www.sec.gov/Archives/edgar/data/100493/000010049322000097/tsn-20221001.htm | I10: FY2022 10-K, Consolidated Statements of Income, lines 1671-1699 | Cost of sales | FY2021 | J10: 40523 | K10: USD mm | L10: Historical_IS!B8 | M10: Direct transcription from audited filing | N10: Audited filing | Primary / audited | O10: MAPPED
A11: CLM-0007 | B11: Cost of sales | C11: FY2022 | D11: S01 | E11: Tyson Foods FY2022 Form 10-K | F11: 0000100493-22-000097 | G11: 46219 | H11: https://www.sec.gov/Archives/edgar/data/100493/000010049322000097/tsn-20221001.htm | I11: FY2022 10-K, Consolidated Statements of Income, lines 1671-1699 | Cost of sales | FY2022 | J11: 46614 | K11: USD mm | L11: Historical_IS!C8 | M11: Direct transcription from audited filing | N11: Audited filing | Primary / audited | O11: MAPPED
A12: CLM-0008 | B12: Cost of sales | C12: FY2023 | D12: S03 | E12: Tyson Foods FY2025 Form 10-K | F12: 0000100493-25-000095 | G12: 46219 | H12: https://www.sec.gov/Archives/edgar/data/100493/000010049325000095/tsn-20250927.htm | I12: FY2025 10-K, Consolidated Statements of Income, lines 1640-1654 | Cost of sales | FY2023 | J12: 50250 | K12: USD mm | L12: Historical_IS!D8 | M12: Direct transcription from audited filing | N12: Audited filing | Primary / audited | O12: MAPPED
A13: CLM-0009 | B13: Cost of sales | C13: FY2024 | D13: S03 | E13: Tyson Foods FY2025 Form 10-K | F13: 0000100493-25-000095 | G13: 46219 | H13: https://www.sec.gov/Archives/edgar/data/100493/000010049325000095/tsn-20250927.htm | I13: FY2025 10-K, Consolidated Statements of Income, lines 1640-1654 | Cost of sales | FY2024 | J13: 49682 | K13: USD mm | L13: Historical_IS!E8 | M13: Direct transcription from audited filing | N13: Audited filing | Primary / audited | O13: MAPPED
A14: CLM-0010 | B14: Cost of sales | C14: FY2025 | D14: S03 | E14: Tyson Foods FY2025 Form 10-K | F14: 0000100493-25-000095 | G14: 46219 | H14: https://www.sec.gov/Archives/edgar/data/100493/000010049325000095/tsn-20250927.htm | I14: FY2025 10-K, Consolidated Statements of Income, lines 1640-1654 | Cost of sales | FY2025 | J14: 50879 | K14: USD mm | L14: Historical_IS!F8 | M14: Direct transcription from audited filing | N14: Audited filing | Primary / audited | O14: MAPPED
A15: CLM-0011 | B15: Gross profit | C15: FY2021 | D15: S01 | E15: Tyson Foods FY2022 Form 10-K | F15: 0000100493-22-000097 | G15: 46219 | H15: https://www.sec.gov/Archives/edgar/data/100493/000010049322000097/tsn-20221001.htm | I15: FY2022 10-K, Consolidated Statements of Income, lines 1671-1699 | Gross profit | FY2021 | J15: 6526 | K15: USD mm | L15: Historical_IS!B9 | M15: Direct transcription from audited filing | N15: Audited filing | Primary / audited | O15: MAPPED
A16: CLM-0012 | B16: Gross profit | C16: FY2022 | D16: S01 | E16: Tyson Foods FY2022 Form 10-K | F16: 0000100493-22-000097 | G16: 46219 | H16: https://www.sec.gov/Archives/edgar/data/100493/000010049322000097/tsn-20221001.htm | I16: FY2022 10-K, Consolidated Statements of Income, lines 1671-1699 | Gross profit | FY2022 | J16: 6668 | K16: USD mm | L16: Historical_IS!C9 | M16: Direct transcription from audited filing | N16: Audited filing | Primary / audited | O16: MAPPED
... A189: CLM-0185 | B189: Total shareholders' equity | C189: FY2025 | D189: S03 | E189: Tyson Foods FY2025 Form 10-K | F189: 0000100493-25-000095 | G189: 46219 | H189: https://www.sec.gov/Archives/edgar/data/100493/000010049325000095/tsn-20250927.htm | I189: FY2025 10-K, Consolidated Balance Sheets, lines 1686-1717 | Total shareholders' equity | FY2025 | J189: 18227 | K189: USD mm | L189: Historical_BS!F29 | M189: Direct transcription from audited filing | N189: Audited filing | Primary / audited | O189: MAPPED
A190: CLM-0186 | B190: Total liabilities and equity | C190: FY2021 | D190: DERIVED | E190: Workbook formula | F190: N/A | G190: 46219 | H190: N/A - workbook formula | I190: Derived from adjacent sourced statement rows | J190: Formula: =B26+B29 | K190: USD mm | L190: Historical_BS!B30 | M190: Formula: =B26+B29 | N190: Derived | Derived formula | O190: FORMULA
