Workbook

Sheet 00_Cover
A1: Samsung Electronics Co., Ltd. — Institutional Financial Model
A2: Consumer electronics / semiconductors | USD millions | As of 2026-07-15
A4: Model field | B4: Value
A5: Ticker / identifier | B5: KRX: 005930
A6: Model archetype | B6: Operating company / DCF
A7: Decision readiness | B7: Official-results operating model
A8: Reporting currency | B8: KRW
A9: Model currency | B9: USD millions
A10: Market-data date | B10: Not applicable
A11: Current market price | B11: Not available
A12: Primary source | B12: https://news.samsung.com/global/samsung-electronics-announces-fourth-quarter-and-fy-2025-results
A13: Key limitation | B13: KRW trillion disclosures translated to USD at the current FX snapshot.
A15: Institutional-grade means auditable sources, explicit assumptions, formula-driven forecasts, valuation, sensitivities, checks and governance. It does not mean that missing private-company disclosures have been invented.

Sheet Sources
A1: Sources and data lineage
A2: Every hardcode is mapped to a source, date, currency and transformation.
A4: Source ID | B4: Use | C4: URL / reference | D4: As of | E4: Source currency | F4: Transformation | G4: Limitation | H4: Status
A5: S1 | B5: Historical financials | C5: https://news.samsung.com/global/samsung-electronics-announces-fourth-quarter-and-fy-2025-results | D5: Latest annual filing/results | E5: KRW | F5: Converted at current snapshot FX (KRW to USD = 0.00067253) | G5: KRW trillion disclosures translated to USD at the current FX snapshot. | H5: Official-results operating model
A6: S2 | B6: Market price | C6: Not applicable | D6: 2026-07-15 | E6: N/A | F6: Dated market input; not a historical financial source | G6: Market prices move after the as-of date | H6: Not loaded
A7: S3 | B7: FX snapshot | C7: Yahoo Finance KRW/USD chart snapshot | D7: 2026-07-15 | E7: KRW | F7: KRW per USD, inverted | G7: Current FX used across historical years for comparability; not historical spot | H7: Loaded
A8: S4 | B8: Forecast assumptions | C8: Model Assumptions sheet | D8: 2026-07-15 | E8: USD | F8: User-editable scenario inputs | G8: Forecasts are estimates, not reported facts | H8: Model input

Sheet Historical
A1: Historical financials
A2: USD millions; converted from audited KRW statements via the documented/interpolated USD_Hist FX layer (Sources_Audited).
A4: Metric | B4: 2021A | C4: 2022A | D4: 2023A | E4: 2024A | F4: 2025A | G4: Source tag / note | H4: Quality
A5: Revenue | B5: =USD_Hist!B6 -> 244390.56 | C5: =USD_Hist!C6 -> 246698.33 | D5: =USD_Hist!D6 -> 198247.86 | E5: =USD_Hist!E6 -> 220579.03 | F5: =USD_Hist!F6 -> 234621.48 | G5: Audited FS via USD_Hist (documented/interpolated FX) | H5: Source-backed / audited
A6: Gross profit | B6: =USD_Hist!B7 -> 98937.546 | C6: =USD_Hist!C7 -> 91575.489 | D6: =USD_Hist!D7 -> 60137.594 | E6: =USD_Hist!E7 -> 83803.677 | F6: =USD_Hist!F7 -> 92391.412 | G6: Audited FS via USD_Hist (documented/interpolated FX) | H6: Source-backed / audited
A7: Operating income / EBIT | B7: =USD_Hist!B8 -> 45130.939 | C7: =USD_Hist!C8 -> 35406.459 | D7: =USD_Hist!D8 -> 5027.8504 | E7: =USD_Hist!E8 -> 23992.552 | F7: =USD_Hist!F8 -> 30664.152 | G7: Audited FS via USD_Hist (documented/interpolated FX) | H7: Source-backed / audited
A8: Net income | B8: =USD_Hist!B9 -> 34301.315 | C8: =USD_Hist!C9 -> 44673.737 | D8: =USD_Hist!D9 -> 11081.218 | E8: =USD_Hist!E9 -> 24649.003 | F8: =USD_Hist!F9 -> 31128.256 | G8: Audited FS via USD_Hist (documented/interpolated FX) | H8: Source-backed / audited
A9: Cash from operations | B9: =USD_Hist!B10 -> 56905.88 | C9: =USD_Hist!C10 -> 50755.932 | D9: =USD_Hist!D10 -> 33792.781 | E9: =USD_Hist!E10 -> 53506.124 | F9: =USD_Hist!F10 -> 60001.229 | G9: Audited FS via USD_Hist (documented/interpolated FX) | H9: Source-backed / audited
A10: Capital expenditure | B10: =USD_Hist!B11 -> -41187.412 | C10: =USD_Hist!C11 -> -40347.911 | D10: =USD_Hist!D11 -> -44108.728 | E10: =USD_Hist!E11 -> -37687.805 | F10: =USD_Hist!F11 -> -33421.839 | G10: Audited FS via USD_Hist (documented/interpolated FX) | H10: Source-backed / audited
A11: Assets | B11: =USD_Hist!B12 -> 372891.26 | C11: =USD_Hist!C12 -> 366029.45 | D11: =USD_Hist!D12 -> 349053.67 | E11: =USD_Hist!E12 -> 377221.45 | F11: =USD_Hist!F12 -> 398724.31 | G11: Audited FS via USD_Hist (documented/interpolated FX) | H11: Source-backed / audited
A12: Liabilities | B12: =USD_Hist!B13 -> 106391.3 | C12: =USD_Hist!C13 -> 76462.755 | D12: =USD_Hist!D13 -> 70612.283 | E12: =USD_Hist!E13 -> 82360.312 | F12: =USD_Hist!F13 -> 91864.893 | G12: Audited FS via USD_Hist (documented/interpolated FX) | H12: Source-backed / audited
A13: Equity | B13: =USD_Hist!B14 -> 266499.95 | C13: =USD_Hist!C14 -> 289566.69 | D13: =USD_Hist!D14 -> 278441.39 | E13: =USD_Hist!E14 -> 294861.14 | F13: =USD_Hist!F14 -> 306859.42 | G13: Audited FS via USD_Hist (documented/interpolated FX) | H13: Source-backed / audited
A14: Cash | B14: =USD_Hist!B15 -> 34115.686 | C14: =USD_Hist!C15 -> 40552.206 | D14: =USD_Hist!D15 -> 52890.158 | E14: =USD_Hist!E15 -> 39373.447 | F14: =USD_Hist!F15 -> 40689.771 | G14: Audited FS via USD_Hist (documented/interpolated FX) | H14: Source-backed / audited
A15: Debt | B15: =(BS_Hist!B33+BS_Hist!B39+BS_Hist!B45+BS_Hist!B46)/Sources_Audited!B21 -> 16075.789 | C15: =(BS_Hist!C33+BS_Hist!C39+BS_Hist!C45+BS_Hist!C46)/Sources_Audited!C21 -> 8434.5766 | D15: =(BS_Hist!D33+BS_Hist!D39+BS_Hist!D45+BS_Hist!D46)/Sources_Audited!D21 -> 9712.6941 | E15: =(BS_Hist!E33+BS_Hist!E39+BS_Hist!E45+BS_Hist!E46)/Sources_Audited!E21 -> 14171.637 | F15: =(BS_Hist!F33+BS_Hist!F39+BS_Hist!F45+BS_Hist!F46)/Sources_Audited!F21 -> 17750.416 | G15: Sum of short-term borrowings + current portion of LT liabilities + debentures + long-term borrowings (BS_Hist), converted via USD FX layer | H15: Computed from audited components (not a single published line)
A16: Diluted shares (mm) | B16: =USD_Hist!B16 -> 6793.1091 | C16: =USD_Hist!C16 -> 6792.8532 | D16: =USD_Hist!D16 -> 6791.8353 | E16: =USD_Hist!E16 -> 6792.1945 | F16: =USD_Hist!F16 -> 6703.1586 | G16: Implied = NI attributable to parent / diluted EPS (IS_Hist, both audited); currency-neutral | H16: Computed from audited components (not a single published line)

Sheet Assumptions
A1: Assumptions and scenarios
A2: Blue-font cells are user inputs. Scenario selector: 1 = Base, 2 = Bull, 3 = Bear.
A3: Scenario selector | B3: 1
A4: Metric | B4: Bear | C4: Base | D4: Bull | E4: Active | F4: Rationale / source
A5: Revenue growth | B5: =C5-0.03 -> 0.01513475 | C5: =(IS_Hist!F5/IS_Hist!B5)^(1/4)-1 -> 0.04513475 | D5: =C5+0.03 -> 0.07513475 | E5: =CHOOSE($B$3,C5,D5,B5) -> 0.04513475 | F5: FY2021A->FY2025A revenue CAGR from audited IS_Hist (KRW); Bull/Bear = Base +/-3pp
A6: EBIT margin | B6: =C6-0.03 -> 0.10069627 | C6: =IS_Hist!F9/IS_Hist!F5 -> 0.13069627 | D6: =C6+0.03 -> 0.16069627 | E6: =CHOOSE($B$3,C6,D6,B6) -> 0.13069627 | F6: FY2025A actual operating margin (Operating profit / Revenue) from audited IS_Hist; Bull/Bear = Base +/-3pp
A7: Cash tax rate | B7: =C7+0.03 -> 0.11638923 | C7: =IS_Hist!F16/IS_Hist!F15 -> 0.086389226 | D7: =MAX(C7-0.03,0) -> 0.056389226 | E7: =CHOOSE($B$3,C7,D7,B7) -> 0.086389226 | F7: FY2025A effective tax rate (income tax expense / profit before tax) from audited IS_Hist, used as cash-tax proxy; Bull/Bear = Base -/+3pp
A8: D&A / revenue | B8: =C8+0.01 -> 0.15514306 | C8: =SUMPRODUCT(CF_Hist!B7:F7/IS_Hist!B5:F5)/5 -> 0.14514306 | D8: =MAX(C8-0.01,0) -> 0.13514306 | E8: =CHOOSE($B$3,C8,D8,B8) -> 0.14514306 | F8: FY2021A-FY2025A average (CF_Hist "Adjustments" / Revenue) from audited CF_Hist/IS_Hist, used as a D&A proxy — Note 27 does not disclose D&A separately from other non-cash items (equity-method income, stock comp, FX, provisions) in the extracted statements, so this is a broader non-cash-addback proxy, not pure D&A; Bull/Bear = Base -/+1pp. Placeholder 0.03/0.04/0.05 replaced because it was inconsistent with the audited capex/revenue driver below (produced a mechanically negative FCFF in perpetuity).
A9: Capex / revenue | B9: =C9+0.015 -> 0.18857682 | C9: =-SUMPRODUCT(CF_Hist!B29:F29/IS_Hist!B5:F5)/5 -> 0.17357682 | D9: =MAX(C9-0.015,0) -> 0.15857682 | E9: =CHOOSE($B$3,C9,D9,B9) -> 0.17357682 | F9: FY2021A-FY2025A average (Acquisition of PP&E / Revenue) from audited CF_Hist/IS_Hist; Bull/Bear = Base -/+1.5pp
A10: NWC investment / incremental revenue | B10: 0.025 | C10: 0.015 | D10: 0.005 | E10: =CHOOSE($B$3,C10,D10,B10) -> 0.015 | F10: Granular working-capital schedule not available from the headline statements extracted here; sector-typical placeholder pending Note-level detail — NOT sourced from audited statements.
A11: WACC | B11: 0.11 | C11: 0.09 | D11: 0.075 | E11: =CHOOSE($B$3,C11,D11,B11) -> 0.09 | F11: USD discount-rate assumption
A12: Terminal growth | B12: 0.015 | C12: 0.025 | D12: 0.035 | E12: =CHOOSE($B$3,C12,D12,B12) -> 0.025 | F12: Long-run nominal USD growth

Sheet Forecast
A1: Forecast model
A2: Formula-driven five-year projection in USD millions, base year (2025A) bridged from the audited KRW statements (IS_Hist/CF_Hist/BS_Hist) via USD_Hist; growth/margin drivers are currency-neutral ratios anchored in Assumptions.
A4: Metric | B4: 2025A | C4: 2026E | D4: 2027E | E4: 2028E | F4: 2029E | G4: 2030E
A5: Revenue | B5: =USD_Hist!F6 -> 234621.48 | C5: =B5*(1+Assumptions!$E$5) -> 245211.06 | D5: =C5*(1+Assumptions!$E$5) -> 256278.6 | E5: =D5*(1+Assumptions!$E$5) -> 267845.67 | F5: =E5*(1+Assumptions!$E$5) -> 279934.82 | G5: =F5*(1+Assumptions!$E$5) -> 292569.61
A6: Growth | C6: =IF(B5<>0,C5/B5-1,0) -> 0.04513475 | D6: =IF(C5<>0,D5/C5-1,0) -> 0.04513475 | E6: =IF(D5<>0,E5/D5-1,0) -> 0.04513475 | F6: =IF(E5<>0,F5/E5-1,0) -> 0.04513475 | G6: =IF(F5<>0,G5/F5-1,0) -> 0.04513475
A7: EBIT margin | B7: =USD_Hist!F8/USD_Hist!F6 -> 0.13069627 | C7: =Assumptions!$E$6 -> 0.13069627 | D7: =Assumptions!$E$6 -> 0.13069627 | E7: =Assumptions!$E$6 -> 0.13069627 | F7: =Assumptions!$E$6 -> 0.13069627 | G7: =Assumptions!$E$6 -> 0.13069627
A8: EBIT | B8: =USD_Hist!F8 -> 30664.152 | C8: =C5*C7 -> 32048.171 | D8: =D5*D7 -> 33494.657 | E8: =E5*E7 -> 35006.43 | F8: =F5*F7 -> 36586.436 | G8: =G5*G7 -> 38237.756
A9: Cash tax rate | C9: =Assumptions!$E$7 -> 0.086389226 | D9: =Assumptions!$E$7 -> 0.086389226 | E9: =Assumptions!$E$7 -> 0.086389226 | F9: =Assumptions!$E$7 -> 0.086389226 | G9: =Assumptions!$E$7 -> 0.086389226
A10: NOPAT | C10: =C8*(1-C9) -> 29279.554 | D10: =D8*(1-D9) -> 30601.079 | E10: =E8*(1-E9) -> 31982.251 | F10: =F8*(1-F9) -> 33425.762 | G10: =G8*(1-G9) -> 34934.426
A11: D&A | C11: =C5*Assumptions!$E$8 -> 35590.685 | D11: =D5*Assumptions!$E$8 -> 37197.062 | E11: =E5*Assumptions!$E$8 -> 38875.942 | F11: =F5*Assumptions!$E$8 -> 40630.598 | G11: =G5*Assumptions!$E$8 -> 42464.45
A12: Capital expenditure | C12: =-C5*Assumptions!$E$9 -> -42562.957 | D12: =-D5*Assumptions!$E$9 -> -44484.025 | E12: =-E5*Assumptions!$E$9 -> -46491.801 | F12: =-F5*Assumptions!$E$9 -> -48590.197 | G12: =-G5*Assumptions!$E$9 -> -50783.303
A13: Change in NWC | C13: =-(C5-B5)*Assumptions!$E$10 -> -158.84373 | D13: =-(D5-C5)*Assumptions!$E$10 -> -166.0131 | E13: =-(E5-D5)*Assumptions!$E$10 -> -173.50606 | F13: =-(F5-E5)*Assumptions!$E$10 -> -181.33721 | G13: =-(G5-F5)*Assumptions!$E$10 -> -189.52182
A14: FCFF | C14: =C10+C11+C12+C13 -> 22148.438 | D14: =D10+D11+D12+D13 -> 23148.103 | E14: =E10+E11+E12+E13 -> 24192.886 | F14: =F10+F11+F12+F13 -> 25284.826 | G14: =G10+G11+G12+G13 -> 26426.051
A15: Cash | B15: =USD_Hist!F15 -> 40689.771 | C15: =$B$15 -> 40689.771 | D15: =$B$15 -> 40689.771 | E15: =$B$15 -> 40689.771 | F15: =$B$15 -> 40689.771 | G15: =$B$15 -> 40689.771
A16: Debt | B16: =(BS_Hist!F33+BS_Hist!F39+BS_Hist!F45+BS_Hist!F46)/Sources_Audited!F21 -> 17750.416 | C16: =$B$16 -> 17750.416 | D16: =$B$16 -> 17750.416 | E16: =$B$16 -> 17750.416 | F16: =$B$16 -> 17750.416 | G16: =$B$16 -> 17750.416

Sheet Valuation
A1: Discounted cash flow valuation
A2: Valuation is formula-driven and scenario-sensitive; private-company outputs are enterprise-value ranges only.
A4: Metric | B4: Year 1 | C4: Year 2 | D4: Year 3 | E4: Year 4 | F4: Year 5 | G4: Total / output
A5: FCFF | B5: =Forecast!C14 -> 22148.438 | C5: =Forecast!D14 -> 23148.103 | D5: =Forecast!E14 -> 24192.886 | E5: =Forecast!F14 -> 25284.826 | F5: =Forecast!G14 -> 26426.051
A6: Discount factor | B6: =1/(1+Assumptions!$E$11)^1 -> 0.91743119 | C6: =1/(1+Assumptions!$E$11)^2 -> 0.84167999 | D6: =1/(1+Assumptions!$E$11)^3 -> 0.77218348 | E6: =1/(1+Assumptions!$E$11)^4 -> 0.70842521 | F6: =1/(1+Assumptions!$E$11)^5 -> 0.64993139
A7: PV FCFF | B7: =B5*B6 -> 20319.668 | C7: =C5*C6 -> 19483.295 | D7: =D5*D6 -> 18681.347 | E7: =E5*E6 -> 17912.408 | F7: =F5*F6 -> 17175.12
A9: Output | B9: Value
A10: PV explicit FCFF | B10: =SUM(B7:F7) -> 93571.839
A11: Terminal value | B11: =IF(Assumptions!$E$11>Assumptions!$E$12,F5*(1+Assumptions!$E$12)/(Assumptions!$E$11-Assumptions!$E$12),0) -> 416718.49
A12: PV terminal value | B12: =B11*F6 -> 270838.43
A13: Enterprise value | B13: =B10+B12 -> 364410.27
A14: Cash | B14: =Forecast!B15 -> 40689.771
A15: Debt | B15: =Forecast!B16 -> 17750.416
A16: Equity value | B16: =B13+B14-B15 -> 387349.62
A17: Diluted shares (mm) | B17: =USD_Hist!F16 -> 6703.1586
A18: Implied value / share | B18: =IF(B17>0,B16/B17,0) -> 57.786134
A19: Current market price
A20: Upside / (downside) | B20: =IF(B19>0,B18/B19-1,0) -> 0

Sheet Sensitivity
A1: Valuation sensitivity
A2: Enterprise value sensitivity to WACC and terminal growth.
A4: WACC / g | B4: 0.07 | C4: 0.08 | D4: 0.09 | E4: 0.1 | F4: 0.11
A5: 0.01 | B5: =SUMPRODUCT(Valuation!$B$5:$F$5,1/(1+B$4)^{1,2,3,4,5})+IF(B$4>$A5,Valuation!$F$5*(1+$A5)/(B$4-$A5)/(1+B$4)^5,0) -> 415961.32 | C5: =SUMPRODUCT(Valuation!$B$5:$F$5,1/(1+C$4)^{1,2,3,4,5})+IF(C$4>$A5,Valuation!$F$5*(1+$A5)/(C$4-$A5)/(1+C$4)^5,0) -> 355628.58 | D5: =SUMPRODUCT(Valuation!$B$5:$F$5,1/(1+D$4)^{1,2,3,4,5})+IF(D$4>$A5,Valuation!$F$5*(1+$A5)/(D$4-$A5)/(1+D$4)^5,0) -> 310407.73 | E5: =SUMPRODUCT(Valuation!$B$5:$F$5,1/(1+E$4)^{1,2,3,4,5})+IF(E$4>$A5,Valuation!$F$5*(1+$A5)/(E$4-$A5)/(1+E$4)^5,0) -> 275260.27 | F5: =SUMPRODUCT(Valuation!$B$5:$F$5,1/(1+F$4)^{1,2,3,4,5})+IF(F$4>$A5,Valuation!$F$5*(1+$A5)/(F$4-$A5)/(1+F$4)^5,0) -> 247163.18
A6: 0.02 | B6: =SUMPRODUCT(Valuation!$B$5:$F$5,1/(1+B$4)^{1,2,3,4,5})+IF(B$4>$A6,Valuation!$F$5*(1+$A6)/(B$4-$A6)/(1+B$4)^5,0) -> 483162.35 | C6: =SUMPRODUCT(Valuation!$B$5:$F$5,1/(1+C$4)^{1,2,3,4,5})+IF(C$4>$A6,Valuation!$F$5*(1+$A6)/(C$4-$A6)/(1+C$4)^5,0) -> 401876.04 | D6: =SUMPRODUCT(Valuation!$B$5:$F$5,1/(1+D$4)^{1,2,3,4,5})+IF(D$4>$A6,Valuation!$F$5*(1+$A6)/(D$4-$A6)/(1+D$4)^5,0) -> 343837.87 | E6: =SUMPRODUCT(Valuation!$B$5:$F$5,1/(1+E$4)^{1,2,3,4,5})+IF(E$4>$A6,Valuation!$F$5*(1+$A6)/(E$4-$A6)/(1+E$4)^5,0) -> 300328.81 | F6: =SUMPRODUCT(Valuation!$B$5:$F$5,1/(1+F$4)^{1,2,3,4,5})+IF(F$4>$A6,Valuation!$F$5*(1+$A6)/(F$4-$A6)/(1+F$4)^5,0) -> 266505.02
A7: 0.03 | B7: =SUMPRODUCT(Valuation!$B$5:$F$5,1/(1+B$4)^{1,2,3,4,5})+IF(B$4>$A7,Valuation!$F$5*(1+$A7)/(B$4-$A7)/(1+B$4)^5,0) -> 583963.89 | C7: =SUMPRODUCT(Valuation!$B$5:$F$5,1/(1+C$4)^{1,2,3,4,5})+IF(C$4>$A7,Valuation!$F$5*(1+$A7)/(C$4-$A7)/(1+C$4)^5,0) -> 466622.5 | D7: =SUMPRODUCT(Valuation!$B$5:$F$5,1/(1+D$4)^{1,2,3,4,5})+IF(D$4>$A7,Valuation!$F$5*(1+$A7)/(D$4-$A7)/(1+D$4)^5,0) -> 388411.39 | E7: =SUMPRODUCT(Valuation!$B$5:$F$5,1/(1+E$4)^{1,2,3,4,5})+IF(E$4>$A7,Valuation!$F$5*(1+$A7)/(E$4-$A7)/(1+E$4)^5,0) -> 332559.79 | F7: =SUMPRODUCT(Valuation!$B$5:$F$5,1/(1+F$4)^{1,2,3,4,5})+IF(F$4>$A7,Valuation!$F$5*(1+$A7)/(F$4-$A7)/(1+F$4)^5,0) -> 290682.32
A8: 0.04 | B8: =SUMPRODUCT(Valuation!$B$5:$F$5,1/(1+B$4)^{1,2,3,4,5})+IF(B$4>$A8,Valuation!$F$5*(1+$A8)/(B$4-$A8)/(1+B$4)^5,0) -> 751966.45 | C8: =SUMPRODUCT(Valuation!$B$5:$F$5,1/(1+C$4)^{1,2,3,4,5})+IF(C$4>$A8,Valuation!$F$5*(1+$A8)/(C$4-$A8)/(1+C$4)^5,0) -> 563742.18 | D8: =SUMPRODUCT(Valuation!$B$5:$F$5,1/(1+D$4)^{1,2,3,4,5})+IF(D$4>$A8,Valuation!$F$5*(1+$A8)/(D$4-$A8)/(1+D$4)^5,0) -> 450814.33 | E8: =SUMPRODUCT(Valuation!$B$5:$F$5,1/(1+E$4)^{1,2,3,4,5})+IF(E$4>$A8,Valuation!$F$5*(1+$A8)/(E$4-$A8)/(1+E$4)^5,0) -> 375534.43 | F8: =SUMPRODUCT(Valuation!$B$5:$F$5,1/(1+F$4)^{1,2,3,4,5})+IF(F$4>$A8,Valuation!$F$5*(1+$A8)/(F$4-$A8)/(1+F$4)^5,0) -> 321767.43
A9: 0.05 | B9: =SUMPRODUCT(Valuation!$B$5:$F$5,1/(1+B$4)^{1,2,3,4,5})+IF(B$4>$A9,Valuation!$F$5*(1+$A9)/(B$4-$A9)/(1+B$4)^5,0) -> 1087971.6 | C9: =SUMPRODUCT(Valuation!$B$5:$F$5,1/(1+C$4)^{1,2,3,4,5})+IF(C$4>$A9,Valuation!$F$5*(1+$A9)/(C$4-$A9)/(1+C$4)^5,0) -> 725608.31 | D9: =SUMPRODUCT(Valuation!$B$5:$F$5,1/(1+D$4)^{1,2,3,4,5})+IF(D$4>$A9,Valuation!$F$5*(1+$A9)/(D$4-$A9)/(1+D$4)^5,0) -> 544418.73 | E9: =SUMPRODUCT(Valuation!$B$5:$F$5,1/(1+E$4)^{1,2,3,4,5})+IF(E$4>$A9,Valuation!$F$5*(1+$A9)/(E$4-$A9)/(1+E$4)^5,0) -> 435698.92 | F9: =SUMPRODUCT(Valuation!$B$5:$F$5,1/(1+F$4)^{1,2,3,4,5})+IF(F$4>$A9,Valuation!$F$5*(1+$A9)/(F$4-$A9)/(1+F$4)^5,0) -> 363214.23

Sheet Checks
A1: Model checks
A2: All critical checks should read PASS before decision use.
A4: Check | B4: Result | C4: Severity | D4: Interpretation
A5: Forecast revenue non-negative | B5: =IF(MIN(Forecast!C5:G5)>=0,"PASS","FAIL") -> PASS | C5: Critical | D5: No negative revenue
A6: FCFF formula populated | B6: =IF(COUNT(Forecast!C14:G14)=5,"PASS","FAIL") -> PASS | C6: Critical | D6: Five forecast cash flows
A7: WACC exceeds terminal growth | B7: =IF(Assumptions!E11>Assumptions!E12,"PASS","FAIL") -> PASS | C7: Critical | D7: Required for convergent DCF
A8: Valuation bridge | B8: =IF(ABS(Valuation!B16-(Valuation!B13+Valuation!B14-Valuation!B15))<0.1,"PASS","FAIL") -> PASS | C8: Critical | D8: EV plus cash less debt equals equity value
A9: Historical source coverage | B9: =IF(COUNTBLANK(Historical!B5:F16)=0,"PASS","LIMITED") -> PASS | C9: Readiness | D9: All 12 historical metrics x 5 years now source-backed via audited statements and the documented/interpolated USD FX bridge (USD_Hist); Debt and Diluted shares are computed from audited components, not single published lines.
A11: Overall gate | B11: =IF(COUNTIF(B5:B9,"FAIL")=0,IF(COUNTIF(B5:B9,"LIMITED")=0,"PASS","PASS WITH LIMITATIONS"),"FAIL") -> PASS
A12: Decision use | B12: Official-results operating model

Sheet Sector_KPIs
A1: Sector KPI framework
A2: A decision-useful model requires sector drivers beyond the three statements.
A4: KPI | B4: Historical | C4: Forecast | D4: Status / source requirement
A5: Revenue by platform | D5: Input-ready; populate from issuer operating disclosures
A6: Units / wafer shipments | D6: Input-ready; populate from issuer operating disclosures
A7: ASP | D7: Input-ready; populate from issuer operating disclosures
A8: Gross margin | D8: Input-ready; populate from issuer operating disclosures
A9: R&D intensity | D9: Input-ready; populate from issuer operating disclosures
A10: Capex intensity | D10: Input-ready; populate from issuer operating disclosures
A11: Backlog | D11: Input-ready; populate from issuer operating disclosures
A12: Inventory days | D12: Input-ready; populate from issuer operating disclosures
A13: Free cash flow | D13: Input-ready; populate from issuer operating disclosures

Sheet Change_Log
A1: Change log and governance
A2: Version history and model-owner review record.
A4: Date | B4: Version | C4: Author | D4: Change | E4: Evidence | F4: Reviewer status
A5: 2026-07-15 | B5: 1.0 | C5: Codex | D5: Initial institutional model framework and source pack | E5: https://news.samsung.com/global/samsung-electronics-announces-fourth-quarter-and-fy-2025-results | F5: Builder-verified
A6: 2026-07-15 | B6: 1.0 | C6: Codex | D6: Formula, package and visual QA | E6: Checks sheet and preview artifacts | F6: Pending owner investment judgment
A7: 46223 | B7: Elevation pass 1: added audited FY2021-FY2025 statement sheets IS_Hist/CI_Hist/BS_Hist/CF_Hist (KRW mm, published constants), Checks_TieOut (27 tie-outs incl. cross-statement), Sources_Audited. Root model untouched; v2 saved under the maintainer's archive. Built via Mog SDK. | C7: Claude (run 96e5b44b)
A8: 46224 | B8: Rewire pass (run 41538014): added SCE_Hist (audited FY2021A-FY2025A, KRW constants, extracted from Samsung/*_sce.pdf) with 20 tie-outs incl. cross-statement checks vs BS_Hist/IS_Hist/CI_Hist; added USD_Hist FX conversion layer (documented rates FY2021/23/25, linear-interpolated FY2022/24, all in Sources_Audited) with round-trip checks; rewired Forecast base year (2025A) and cash/debt to the audited USD bridge; rewired Assumptions Base-case drivers (revenue growth, EBIT margin, tax rate, capex/revenue, D&A/revenue non-cash-addback proxy) to formulas over audited KRW/CF data; backfilled legacy Historical sheet from USD_Hist, closing the "LIMITED" historical-coverage gate. Only the NWC/revenue driver remains an explicitly flagged sector placeholder (not sourced from audited statements — granular working-capital note detail unavailable in extracted PDFs). Root model untouched; saved under the maintainer's archive. Built via Mog SDK. | C8: Claude (run 41538014)
A9: 46224 | B9: Remediation (audit run 41538014, samsung-rewire_AUDIT.md finding #3): corrected FY2025A USD convenience-translation rate in Sources_Audited!F21 from 1421.87 to 1421.89 to match the audited FY2025 FS Note 2.18 literal disclosure ("W1,421.89 to $1") and the PDF's own implied USD-column rate (1421.8852). Sources_Audited!D6 (=F21), !E21 (=AVERAGE(D21,F21), FY2024A interpolation) and USD_Hist!E5/F5 (=Sources_Audited!E21/F21) and all downstream USD_Hist/Forecast/Valuation USD figures recalculate automatically off this single hardcoded source cell -- no other cell in the workbook held a hardcoded copy of the old rate (verified by full-workbook scan). Immaterial impact (~0.001% on USD-layer figures only per audit); no KRW figures, tie-outs, or checks affected. | C9: Claude (remediation, session da993791)

Sheet IS_Hist
A1: Samsung Electronics — Consolidated Statements of Profit or Loss (audited)
A2: KRW millions. FY2021 per FY2021 audited FS; FY2022-23 per FY2023 audited FS; FY2024-25 per FY2025 audited FS (samsung.com IR).
A4: Line item | B4: FY2021A | C4: FY2022A | D4: FY2023A | E4: FY2024A | F4: FY2025A | G4: Note ref
A5: Revenue | B5: 279604799 | C5: 302231360 | D5: 258935494 | E5: 300870903 | F5: 333605938 | G5: 29/30
A6: Cost of sales | B6: 166411342 | C6: 190041770 | D6: 180388580 | E6: 186562268 | F6: 202235513 | G6: 21
A7: Gross profit | B7: 113193457 | C7: 112189590 | D7: 78546914 | E7: 114308635 | F7: 131370425
A8: Selling and administrative expenses | B8: 61559601 | C8: 68812960 | D8: 71979938 | E8: 81582674 | F8: 87769374 | G8: 21, 22
A9: Operating profit | B9: 51633856 | C9: 43376630 | D9: 6566976 | E9: 32725961 | F9: 43601051 | G9: 29/30
A10: Other non-operating income | B10: 2205695 | C10: 1962071 | D10: 1180448 | E10: 1960338 | F10: 2267083 | G10: 23
A11: Other non-operating expense | B11: 2055971 | C11: 1790176 | D11: 1083327 | E11: 1625229 | F11: 1575901 | G11: 23
A12: Share of net profit of associates and joint ventures | B12: 729614 | C12: 1090643 | D12: 887550 | E12: 751044 | F12: 682700 | G12: 9
A13: Financial income | B13: 8543187 | C13: 20828995 | D13: 16100148 | E13: 16703304 | F13: 16240302 | G13: 24
A14: Financial expense | B14: 7704554 | C14: 19027689 | D14: 12645530 | E14: 12985684 | F14: 11733764 | G14: 24
A15: Profit before income tax | B15: 53351827 | C15: 46440474 | D15: 11006265 | E15: 37529734 | F15: 49481471
A16: Income tax expense (benefit) | B16: 13444377 | C16: -9213603 | D16: -4480835 | E16: 3078383 | F16: 4274666 | G16: 25
A17: Profit for the year | B17: 39907450 | C17: 55654077 | D17: 15487100 | E17: 34451351 | F17: 45206805
A19: Profit attributable to:
A20: Owners of the parent company | B20: 39243791 | C20: 54730018 | D20: 14473401 | E20: 33621363 | F20: 44260956
A21: Non-controlling interests | B21: 663659 | C21: 924059 | D21: 1013699 | E21: 829988 | F21: 945849
A23: Earnings per share — basic (KRW) | B23: 5777 | C23: 8057 | D23: 2131 | E23: 4950 | F23: 6605 | G23: 26
A24: Earnings per share — diluted (KRW) | B24: 5777 | C24: 8057 | D24: 2131 | E24: 4950 | F24: 6603 | G24: 26

Sheet CI_Hist
A1: Samsung Electronics — Consolidated Statements of Comprehensive Income (audited)
A2: KRW millions. Same source basis as IS_Hist.
A4: Line item | B4: FY2021A | C4: FY2022A | D4: FY2023A | E4: FY2024A | F4: FY2025A | G4: Note ref
A5: Profit for the year | B5: 39907450 | C5: 55654077 | D5: 15487100 | E5: 34451351 | F5: 45206805
A6: Items that will not be reclassified to profit or loss:
A7: Gain (loss) on valuation of FVOCI financial assets, net of tax | B7: 2980896 | C7: -1969498 | D7: 1481091 | E7: 2300166 | F7: 4678338 | G7: 6, 20
A8: Share of OCI of associates and JVs (non-reclassifiable), net of tax | B8: 51816 | C8: -6318 | D8: 13150 | E8: -71581 | F8: 92804 | G8: 9, 20
A9: Remeasurement of net defined benefit liabilities (assets), net of tax | B9: -524606 | C9: 1153679 | D9: -828298 | E9: -766078 | F9: 106691 | G9: 14, 20
A10: Items that may be reclassified to profit or loss:
A11: Share of OCI of associates and JVs (reclassifiable), net of tax | B11: 160163 | C11: -44192 | D11: 61962 | E11: 305327 | F11: 244161 | G11: 9, 20
A12: Foreign currency translation differences, net of tax | B12: 7283620 | C12: 4884886 | D12: 2621479 | E12: 15116099 | F12: 960019 | G12: 20
A13: Gain (loss) on valuation of cash flow hedge derivatives | B13: 50410 | C13: -12893 | D13: 927 | E13: -38946 | F13: 1706 | G13: 20
A14: Other comprehensive income for the year, net of tax | B14: 10002299 | C14: 4005664 | D14: 3350311 | E14: 16844987 | F14: 6083719
A15: Total comprehensive income for the year | B15: 49909749 | C15: 59659741 | D15: 18837411 | E15: 51296338 | F15: 51290524
A16: Comprehensive income attributable to:
A17: Owners of the parent company | B17: 49037912 | C17: 58745107 | D17: 17845661 | E17: 50048199 | F17: 49903963
A18: Non-controlling interests | B18: 871837 | C18: 914634 | D18: 991750 | E18: 1248139 | F18: 1386561

Sheet BS_Hist
A1: Samsung Electronics — Consolidated Statements of Financial Position (audited)
A2: KRW millions, as of December 31. Same source basis as IS_Hist. Blank = line not presented that year.
A4: Line item | B4: FY2021A | C4: FY2022A | D4: FY2023A | E4: FY2024A | F4: FY2025A | G4: Note ref
A5: Assets
A6: Current assets
A7: Cash and cash equivalents | B7: 39031415 | C7: 49680710 | D7: 69080893 | E7: 53705579 | F7: 57856378 | G7: 4, 28/29
A8: Short-term financial instruments | B8: 81708986 | C8: 65102886 | D8: 22690924 | E8: 58909334 | F8: 67965021 | G8: 4, 28/29
A9: Short-term financial assets at amortized cost | B9: 3369034 | C9: 414610 | D9: 608281 | G9: 4, 28
A10: Short-term financial assets at FV through profit or loss | B10: 40757 | C10: 29080 | D10: 27112 | E10: 36877 | F10: 25715 | G10: 4, 6, 28/29
A11: Trade receivables | B11: 40713415 | C11: 35721563 | D11: 36647393 | E11: 43623073 | F11: 51127642 | G11: 4, 5, 7, 28/29
A12: Non-trade receivables | B12: 4497257 | C12: 6149209 | D12: 6633248 | E12: 9622974 | F12: 7481327 | G12: 4, 7, 28/29
A13: Prepaid expenses | B13: 2336252 | C13: 2867823 | D13: 3366130 | E13: 3362824 | F13: 3627172
A14: Inventories | B14: 41384404 | C14: 52187866 | D14: 51625874 | E14: 51754865 | F14: 52636828 | G14: 8
A15: Other current assets | B15: 5081665 | C15: 6316834 | D15: 5038838 | E15: 6046740 | F15: 6964529 | G15: 4, 28/29
A16: Assets held-for-sale | D16: 217864 | G16: 33
A17: Total current assets | B17: 218163185 | C17: 218470581 | D17: 195936557 | E17: 227062266 | F17: 247684612
A18: Non-current assets
A19: Financial assets at FV through other comprehensive income | B19: 13965839 | C19: 11397012 | D19: 7481297 | E19: 10580932 | F19: 16295005 | G19: 4, 6, 28/29
A20: Financial assets at FV through profit or loss (non-current) | B20: 1525344 | C20: 1405468 | D20: 1431394 | E20: 1175749 | F20: 1280501 | G20: 4, 6, 28/29
A21: Investments in associates and joint ventures | B21: 8932251 | C21: 10893869 | D21: 11767444 | E21: 12592117 | F21: 13772121 | G21: 9
A22: Property, plant and equipment | B22: 149928539 | C22: 168045388 | D22: 187256262 | E22: 205945209 | F22: 215304784 | G22: 10
A23: Intangible assets | B23: 20236244 | C23: 20217754 | D23: 22741862 | E23: 23738566 | F23: 29480565 | G23: 11
A24: Net defined benefit assets | B24: 2809590 | C24: 5851972 | D24: 4905219 | E24: 3089571 | F24: 4271547 | G24: 14
A25: Deferred income tax assets | B25: 4261214 | C25: 5101318 | D25: 10211797 | E25: 14236468 | F25: 18840559 | G25: 25
A26: Other non-current assets | B26: 6798952 | C26: 7041145 | D26: 14174148 | E26: 16111070 | F26: 20012416 | G26: 4, 7, 28/29
A27: Total non-current assets | B27: 208457973 | C27: 229953926 | D27: 259969423 | E27: 287469682 | F27: 319257498
A28: Total assets | B28: 426621158 | C28: 448424507 | D28: 455905980 | E28: 514531948 | F28: 566942110
A30: Liabilities
A31: Current liabilities
A32: Trade payables | B32: 13453351 | C32: 10644686 | D32: 11319824 | E32: 12370177 | F32: 13039380 | G32: 4, 28/29
A33: Short-term borrowings | B33: 13687793 | C33: 5147315 | D33: 7114601 | E33: 13172504 | F33: 17574980 | G33: 4, 5, 12, 28/29
A34: Other payables | B34: 15584866 | C34: 17592366 | D34: 15324119 | E34: 18547365 | F34: 21365657 | G34: 4, 28/29
A35: Advances received | B35: 1224812 | C35: 1314934 | D35: 1492602 | E35: 1841420 | F35: 1933598 | G35: 17
A36: Withholdings | B36: 1294052 | C36: 1298244 | D36: 892441 | E36: 991812 | F36: 1001885 | G36: 4, 28/29
A37: Accrued expenses | B37: 27928031 | C37: 29211487 | D37: 26013273 | E37: 29613258 | F37: 32707431 | G37: 4, 17, 28/29
A38: Current income tax liabilities | B38: 6749149 | C38: 4250397 | D38: 3358715 | E38: 4340171 | F38: 7037174
A39: Current portion of long-term liabilities | B39: 1329968 | C39: 1089162 | D39: 1308875 | E39: 2207290 | F39: 1177508 | G39: 4, 12, 13, 28/29
A40: Provisions | B40: 5372872 | C40: 5844907 | D40: 6524876 | E40: 8216469 | F40: 7690559 | G40: 15
A41: Other current liabilities | B41: 1492239 | C41: 1951354 | D41: 2308472 | E41: 2025833 | F41: 2883176 | G41: 4, 17, 28/29
A42: Liabilities held-for-sale | D42: 61654 | G42: 33
...

Sheet CF_Hist
A1: Samsung Electronics — Consolidated Statements of Cash Flows (audited)
A2: KRW millions. Same source basis as IS_Hist. Signs as published (outflows negative).
A4: Line item | B4: FY2021A | C4: FY2022A | D4: FY2023A | E4: FY2024A | F4: FY2025A | G4: Note ref
A5: Operating activities
A6: Profit for the year | B6: 39907450 | C6: 55654077 | D6: 15487100 | E6: 34451351 | F6: 45206805
A7: Adjustments | B7: 49055633 | C7: 33073439 | D7: 36519534 | E7: 42947079 | F7: 52395616 | G7: 27
A8: Changes in assets and liabilities from operating activities | B8: -16286884 | C8: -16998948 | D8: -5458745 | E8: -1567557 | F8: -9613906 | G8: 27
A9: Cash generated from operations | B9: 72676199 | C9: 71728568 | D9: 46547889 | E9: 75830873 | F9: 87988515
A10: Interest received | B10: 1406706 | C10: 2136795 | D10: 4786010 | E10: 4008359 | F10: 4680553
A11: Interest paid | B11: -434441 | C11: -714543 | D11: -844691 | E11: -675049 | F11: -469730
A12: Dividends received | B12: 299033 | C12: 529421 | D12: 269169 | E12: 268482 | F12: 253105
A13: Income tax paid | B13: -8842049 | C13: -11498895 | D13: -6620950 | E13: -6450044 | F13: -7137295
A14: Net cash provided by operating activities | B14: 65105448 | C14: 62181346 | D14: 44137427 | E14: 72982621 | F14: 85315148
A16: Investing activities
A17: Net change in short-term financial instruments | B17: 10917128 | C17: 15214321 | D17: 39421565 | E17: -32976756 | F17: -6701150
A18: Net change in short-term financial assets at amortized cost | B18: -336959 | C18: 3050104 | D18: -195616 | E18: 620858
A19: Net change in short-term financial assets at FVPL | B19: 30694 | C19: 11677 | D19: 2718 | E19: -9735 | F19: 11163
A20: Disposal of long-term financial instruments | B20: 10216082 | C20: 8272909 | D20: 4565426 | E20: 4100008 | F20: 4519179
A21: Acquisition of long-term financial instruments | B21: -6981810 | C21: -4393754 | D21: -5307770 | E21: -3987279 | F21: -13533556
A22: Disposal of FVOCI financial assets | B22: 2919888 | C22: 496090 | D22: 6521568 | E22: 389680 | F22: 851834
A23: Acquisition of FVOCI financial assets | B23: -1121201 | C23: -37687 | D23: -124488 | E23: -185876 | F23: -129636
A24: Disposal of FVPL financial assets | B24: 350212 | C24: 166315 | D24: 63962 | E24: 309970 | F24: 142584
A25: Acquisition of FVPL financial assets | B25: -208262 | C25: -158244 | D25: -130459 | E25: -70982 | F25: -146774
A26: Disposal of investments in associates and JVs | B26: 19169 | C26: 13233 | D26: 33457 | E26: 33178 | F26: 6643
A27: Acquisition of investments in associates and JVs | B27: -47090 | C27: -907958 | D27: -78690 | E27: -11710 | F27: -325146
A28: Disposal of property, plant and equipment | B28: 358284 | C28: 217878 | D28: 98341 | E28: 156191 | F28: 149828
A29: Acquisition of property, plant and equipment | B29: -47122106 | C29: -49430428 | D29: -57611292 | E29: -51406355 | F29: -47522179
A30: Disposal of intangible assets | B30: 1752 | C30: 23462 | D30: 11744 | E30: 15869 | F30: 13554
A31: Acquisition of intangible assets | B31: -2706915 | C31: -3696304 | D31: -2922875 | E31: -2335284 | F31: -4630970
A32: Receipt of government grants | F32: 1722357
A33: Cash outflow from business combinations | B33: -5926 | C33: -31383 | D33: -356511 | E33: -142156 | F33: -3131539
A34: Cash inflow from business divestiture | F34: 418093
A35: Cash inflow from disposal of held-for-sale assets | B35: 661168 | E35: 101563
A36: Cash inflow (outflow) from other investing activities | B36: 8129 | C36: -413035 | D36: -913897 | E36: 17114 | F36: -226491
A37: Net cash used in investing activities | B37: -33047763 | C37: -31602804 | D37: -16922817 | E37: -85381702 | F37: -68512206
A39: Financing activities
A40: Net change in short-term borrowings | B40: -2616943 | C40: -8339149 | D40: 2145400 | E40: 5871346 | F40: 4655349 | G40: 27
A41: Increase in long-term borrowings | B41: 58279 | C41: 271997 | D41: 354712 | E41: 404954 | F41: 2807001 | G41: 27
A42: Repayment of debentures and long-term borrowings | B42: -894749 | C42: -1508465 | D42: -1219579 | E42: -1364508 | F42: -2852971 | G42: 27
A43: Dividends paid | B43: -20510350 | C43: -9814426 | D43: -9864474 | E43: -10888749 | F43: -9897183
...

Sheet Checks_TieOut
A1: Tie-out checks — audited historical statements (all deltas must be 0; KRW millions)
A2: MASTER | B2: =IF(COUNTIF(G5:G56,"FAIL")=0,"OK — ALL TIE-OUTS PASS","FAIL") -> OK — ALL TIE-OUTS PASS
A4: Check | B4: FY2021A | C4: FY2022A | D4: FY2023A | E4: FY2024A | F4: FY2025A | G4: Status
A5: IS: Gross profit = Revenue − COGS | B5: =IS_Hist!B5-IS_Hist!B6-IS_Hist!B7 -> 0 | C5: =IS_Hist!C5-IS_Hist!C6-IS_Hist!C7 -> 0 | D5: =IS_Hist!D5-IS_Hist!D6-IS_Hist!D7 -> 0 | E5: =IS_Hist!E5-IS_Hist!E6-IS_Hist!E7 -> 0 | F5: =IS_Hist!F5-IS_Hist!F6-IS_Hist!F7 -> 0 | G5: =IF(AND(ABS(N(B5))<=0.5,ABS(N(C5))<=0.5,ABS(N(D5))<=0.5,ABS(N(E5))<=0.5,ABS(N(F5))<=0.5),"PASS","FAIL") -> PASS
A6: IS: Operating profit = Gross − SG&A | B6: =IS_Hist!B7-IS_Hist!B8-IS_Hist!B9 -> 0 | C6: =IS_Hist!C7-IS_Hist!C8-IS_Hist!C9 -> 0 | D6: =IS_Hist!D7-IS_Hist!D8-IS_Hist!D9 -> 0 | E6: =IS_Hist!E7-IS_Hist!E8-IS_Hist!E9 -> 0 | F6: =IS_Hist!F7-IS_Hist!F8-IS_Hist!F9 -> 0 | G6: =IF(AND(ABS(N(B6))<=0.5,ABS(N(C6))<=0.5,ABS(N(D6))<=0.5,ABS(N(E6))<=0.5,ABS(N(F6))<=0.5),"PASS","FAIL") -> PASS
A7: IS: PBT chain | B7: =IS_Hist!B9+IS_Hist!B10-IS_Hist!B11+IS_Hist!B12+IS_Hist!B13-IS_Hist!B14-IS_Hist!B15 -> 0 | C7: =IS_Hist!C9+IS_Hist!C10-IS_Hist!C11+IS_Hist!C12+IS_Hist!C13-IS_Hist!C14-IS_Hist!C15 -> 0 | D7: =IS_Hist!D9+IS_Hist!D10-IS_Hist!D11+IS_Hist!D12+IS_Hist!D13-IS_Hist!D14-IS_Hist!D15 -> 0 | E7: =IS_Hist!E9+IS_Hist!E10-IS_Hist!E11+IS_Hist!E12+IS_Hist!E13-IS_Hist!E14-IS_Hist!E15 -> 0 | F7: =IS_Hist!F9+IS_Hist!F10-IS_Hist!F11+IS_Hist!F12+IS_Hist!F13-IS_Hist!F14-IS_Hist!F15 -> 0 | G7: =IF(AND(ABS(N(B7))<=0.5,ABS(N(C7))<=0.5,ABS(N(D7))<=0.5,ABS(N(E7))<=0.5,ABS(N(F7))<=0.5),"PASS","FAIL") -> PASS
A8: IS: NI = PBT − tax | B8: =IS_Hist!B15-IS_Hist!B16-IS_Hist!B17 -> 0 | C8: =IS_Hist!C15-IS_Hist!C16-IS_Hist!C17 -> 0 | D8: =IS_Hist!D15-IS_Hist!D16-IS_Hist!D17 -> 0 | E8: =IS_Hist!E15-IS_Hist!E16-IS_Hist!E17 -> 0 | F8: =IS_Hist!F15-IS_Hist!F16-IS_Hist!F17 -> 0 | G8: =IF(AND(ABS(N(B8))<=0.5,ABS(N(C8))<=0.5,ABS(N(D8))<=0.5,ABS(N(E8))<=0.5,ABS(N(F8))<=0.5),"PASS","FAIL") -> PASS
A9: IS: NI = parent + NCI | B9: =IS_Hist!B20+IS_Hist!B21-IS_Hist!B17 -> 0 | C9: =IS_Hist!C20+IS_Hist!C21-IS_Hist!C17 -> 0 | D9: =IS_Hist!D20+IS_Hist!D21-IS_Hist!D17 -> 0 | E9: =IS_Hist!E20+IS_Hist!E21-IS_Hist!E17 -> 0 | F9: =IS_Hist!F20+IS_Hist!F21-IS_Hist!F17 -> 0 | G9: =IF(AND(ABS(N(B9))<=0.5,ABS(N(C9))<=0.5,ABS(N(D9))<=0.5,ABS(N(E9))<=0.5,ABS(N(F9))<=0.5),"PASS","FAIL") -> PASS
A10: CI: OCI total = sum of components | B10: =SUM(CI_Hist!B7:B9)+SUM(CI_Hist!B11:B13)-CI_Hist!B14 -> 0 | C10: =SUM(CI_Hist!C7:C9)+SUM(CI_Hist!C11:C13)-CI_Hist!C14 -> 0 | D10: =SUM(CI_Hist!D7:D9)+SUM(CI_Hist!D11:D13)-CI_Hist!D14 -> 0 | E10: =SUM(CI_Hist!E7:E9)+SUM(CI_Hist!E11:E13)-CI_Hist!E14 -> 0 | F10: =SUM(CI_Hist!F7:F9)+SUM(CI_Hist!F11:F13)-CI_Hist!F14 -> 0 | G10: =IF(AND(ABS(N(B10))<=0.5,ABS(N(C10))<=0.5,ABS(N(D10))<=0.5,ABS(N(E10))<=0.5,ABS(N(F10))<=0.5),"PASS","FAIL") -> PASS
A11: CI: TCI = NI + OCI | B11: =CI_Hist!B5+CI_Hist!B14-CI_Hist!B15 -> 0 | C11: =CI_Hist!C5+CI_Hist!C14-CI_Hist!C15 -> 0 | D11: =CI_Hist!D5+CI_Hist!D14-CI_Hist!D15 -> 0 | E11: =CI_Hist!E5+CI_Hist!E14-CI_Hist!E15 -> 0 | F11: =CI_Hist!F5+CI_Hist!F14-CI_Hist!F15 -> 0 | G11: =IF(AND(ABS(N(B11))<=0.5,ABS(N(C11))<=0.5,ABS(N(D11))<=0.5,ABS(N(E11))<=0.5,ABS(N(F11))<=0.5),"PASS","FAIL") -> PASS
A12: CI: TCI = parent + NCI | B12: =CI_Hist!B17+CI_Hist!B18-CI_Hist!B15 -> 0 | C12: =CI_Hist!C17+CI_Hist!C18-CI_Hist!C15 -> 0 | D12: =CI_Hist!D17+CI_Hist!D18-CI_Hist!D15 -> 0 | E12: =CI_Hist!E17+CI_Hist!E18-CI_Hist!E15 -> 0 | F12: =CI_Hist!F17+CI_Hist!F18-CI_Hist!F15 -> 0 | G12: =IF(AND(ABS(N(B12))<=0.5,ABS(N(C12))<=0.5,ABS(N(D12))<=0.5,ABS(N(E12))<=0.5,ABS(N(F12))<=0.5),"PASS","FAIL") -> PASS
A13: BS: Current assets sum | B13: =SUM(BS_Hist!B7:B16)-BS_Hist!B17 -> 0 | C13: =SUM(BS_Hist!C7:C16)-BS_Hist!C17 -> 0 | D13: =SUM(BS_Hist!D7:D16)-BS_Hist!D17 -> 0 | E13: =SUM(BS_Hist!E7:E16)-BS_Hist!E17 -> 0 | F13: =SUM(BS_Hist!F7:F16)-BS_Hist!F17 -> 0 | G13: =IF(AND(ABS(N(B13))<=0.5,ABS(N(C13))<=0.5,ABS(N(D13))<=0.5,ABS(N(E13))<=0.5,ABS(N(F13))<=0.5),"PASS","FAIL") -> PASS
A14: BS: Non-current assets sum | B14: =SUM(BS_Hist!B19:B26)-BS_Hist!B27 -> 0 | C14: =SUM(BS_Hist!C19:C26)-BS_Hist!C27 -> 0 | D14: =SUM(BS_Hist!D19:D26)-BS_Hist!D27 -> 0 | E14: =SUM(BS_Hist!E19:E26)-BS_Hist!E27 -> 0 | F14: =SUM(BS_Hist!F19:F26)-BS_Hist!F27 -> 0 | G14: =IF(AND(ABS(N(B14))<=0.5,ABS(N(C14))<=0.5,ABS(N(D14))<=0.5,ABS(N(E14))<=0.5,ABS(N(F14))<=0.5),"PASS","FAIL") -> PASS
A15: BS: Total assets = CA + NCA | B15: =BS_Hist!B17+BS_Hist!B27-BS_Hist!B28 -> 0 | C15: =BS_Hist!C17+BS_Hist!C27-BS_Hist!C28 -> 0 | D15: =BS_Hist!D17+BS_Hist!D27-BS_Hist!D28 -> 0 | E15: =BS_Hist!E17+BS_Hist!E27-BS_Hist!E28 -> 0 | F15: =BS_Hist!F17+BS_Hist!F27-BS_Hist!F28 -> 0 | G15: =IF(AND(ABS(N(B15))<=0.5,ABS(N(C15))<=0.5,ABS(N(D15))<=0.5,ABS(N(E15))<=0.5,ABS(N(F15))<=0.5),"PASS","FAIL") -> PASS
A16: BS: Current liabilities sum | B16: =SUM(BS_Hist!B32:B42)-BS_Hist!B43 -> 0 | C16: =SUM(BS_Hist!C32:C42)-BS_Hist!C43 -> 0 | D16: =SUM(BS_Hist!D32:D42)-BS_Hist!D43 -> 0 | E16: =SUM(BS_Hist!E32:E42)-BS_Hist!E43 -> 0 | F16: =SUM(BS_Hist!F32:F42)-BS_Hist!F43 -> 0 | G16: =IF(AND(ABS(N(B16))<=0.5,ABS(N(C16))<=0.5,ABS(N(D16))<=0.5,ABS(N(E16))<=0.5,ABS(N(F16))<=0.5),"PASS","FAIL") -> PASS
A17: BS: Non-current liabilities sum | B17: =SUM(BS_Hist!B45:B51)-BS_Hist!B52 -> 0 | C17: =SUM(BS_Hist!C45:C51)-BS_Hist!C52 -> 0 | D17: =SUM(BS_Hist!D45:D51)-BS_Hist!D52 -> 0 | E17: =SUM(BS_Hist!E45:E51)-BS_Hist!E52 -> 0 | F17: =SUM(BS_Hist!F45:F51)-BS_Hist!F52 -> 0 | G17: =IF(AND(ABS(N(B17))<=0.5,ABS(N(C17))<=0.5,ABS(N(D17))<=0.5,ABS(N(E17))<=0.5,ABS(N(F17))<=0.5),"PASS","FAIL") -> PASS
A18: BS: Total liabilities = CL + NCL | B18: =BS_Hist!B43+BS_Hist!B52-BS_Hist!B53 -> 0 | C18: =BS_Hist!C43+BS_Hist!C52-BS_Hist!C53 -> 0 | D18: =BS_Hist!D43+BS_Hist!D52-BS_Hist!D53 -> 0 | E18: =BS_Hist!E43+BS_Hist!E52-BS_Hist!E53 -> 0 | F18: =BS_Hist!F43+BS_Hist!F52-BS_Hist!F53 -> 0 | G18: =IF(AND(ABS(N(B18))<=0.5,ABS(N(C18))<=0.5,ABS(N(D18))<=0.5,ABS(N(E18))<=0.5,ABS(N(F18))<=0.5),"PASS","FAIL") -> PASS
A19: BS: Parent equity sum | B19: =SUM(BS_Hist!B56:B60)-BS_Hist!B61 -> 0 | C19: =SUM(BS_Hist!C56:C60)-BS_Hist!C61 -> 0 | D19: =SUM(BS_Hist!D56:D60)-BS_Hist!D61 -> 0 | E19: =SUM(BS_Hist!E56:E60)-BS_Hist!E61 -> 0 | F19: =SUM(BS_Hist!F56:F60)-BS_Hist!F61 -> 0 | G19: =IF(AND(ABS(N(B19))<=0.5,ABS(N(C19))<=0.5,ABS(N(D19))<=0.5,ABS(N(E19))<=0.5,ABS(N(F19))<=0.5),"PASS","FAIL") -> PASS
A20: BS: Total equity = parent + NCI | B20: =BS_Hist!B61+BS_Hist!B62-BS_Hist!B63 -> 0 | C20: =BS_Hist!C61+BS_Hist!C62-BS_Hist!C63 -> 0 | D20: =BS_Hist!D61+BS_Hist!D62-BS_Hist!D63 -> 0 | E20: =BS_Hist!E61+BS_Hist!E62-BS_Hist!E63 -> 0 | F20: =BS_Hist!F61+BS_Hist!F62-BS_Hist!F63 -> 0 | G20: =IF(AND(ABS(N(B20))<=0.5,ABS(N(C20))<=0.5,ABS(N(D20))<=0.5,ABS(N(E20))<=0.5,ABS(N(F20))<=0.5),"PASS","FAIL") -> PASS
A21: BS: TL&E = TL + TE | B21: =BS_Hist!B53+BS_Hist!B63-BS_Hist!B64 -> 0 | C21: =BS_Hist!C53+BS_Hist!C63-BS_Hist!C64 -> 0 | D21: =BS_Hist!D53+BS_Hist!D63-BS_Hist!D64 -> 0 | E21: =BS_Hist!E53+BS_Hist!E63-BS_Hist!E64 -> 0 | F21: =BS_Hist!F53+BS_Hist!F63-BS_Hist!F64 -> 0 | G21: =IF(AND(ABS(N(B21))<=0.5,ABS(N(C21))<=0.5,ABS(N(D21))<=0.5,ABS(N(E21))<=0.5,ABS(N(F21))<=0.5),"PASS","FAIL") -> PASS
A22: BS: Balance (TA − TL&E) | B22: =BS_Hist!B28-BS_Hist!B64 -> 0 | C22: =BS_Hist!C28-BS_Hist!C64 -> 0 | D22: =BS_Hist!D28-BS_Hist!D64 -> 0 | E22: =BS_Hist!E28-BS_Hist!E64 -> 0 | F22: =BS_Hist!F28-BS_Hist!F64 -> 0 | G22: =IF(AND(ABS(N(B22))<=0.5,ABS(N(C22))<=0.5,ABS(N(D22))<=0.5,ABS(N(E22))<=0.5,ABS(N(F22))<=0.5),"PASS","FAIL") -> PASS
A23: CF: Cash generated from operations | B23: =SUM(CF_Hist!B6:B8)-CF_Hist!B9 -> 0 | C23: =SUM(CF_Hist!C6:C8)-CF_Hist!C9 -> 0 | D23: =SUM(CF_Hist!D6:D8)-CF_Hist!D9 -> 0 | E23: =SUM(CF_Hist!E6:E8)-CF_Hist!E9 -> 0 | F23: =SUM(CF_Hist!F6:F8)-CF_Hist!F9 -> 0 | G23: =IF(AND(ABS(N(B23))<=0.5,ABS(N(C23))<=0.5,ABS(N(D23))<=0.5,ABS(N(E23))<=0.5,ABS(N(F23))<=0.5),"PASS","FAIL") -> PASS
A24: CF: CFO chain | B24: =CF_Hist!B9+SUM(CF_Hist!B10:B13)-CF_Hist!B14 -> 0 | C24: =CF_Hist!C9+SUM(CF_Hist!C10:C13)-CF_Hist!C14 -> 0 | D24: =CF_Hist!D9+SUM(CF_Hist!D10:D13)-CF_Hist!D14 -> 0 | E24: =CF_Hist!E9+SUM(CF_Hist!E10:E13)-CF_Hist!E14 -> 0 | F24: =CF_Hist!F9+SUM(CF_Hist!F10:F13)-CF_Hist!F14 -> 0 | G24: =IF(AND(ABS(N(B24))<=0.5,ABS(N(C24))<=0.5,ABS(N(D24))<=0.5,ABS(N(E24))<=0.5,ABS(N(F24))<=0.5),"PASS","FAIL") -> PASS
A25: CF: CFI sum | B25: =SUM(CF_Hist!B17:B36)-CF_Hist!B37 -> 0 | C25: =SUM(CF_Hist!C17:C36)-CF_Hist!C37 -> 0 | D25: =SUM(CF_Hist!D17:D36)-CF_Hist!D37 -> 0 | E25: =SUM(CF_Hist!E17:E36)-CF_Hist!E37 -> 0 | F25: =SUM(CF_Hist!F17:F36)-CF_Hist!F37 -> 0 | G25: =IF(AND(ABS(N(B25))<=0.5,ABS(N(C25))<=0.5,ABS(N(D25))<=0.5,ABS(N(E25))<=0.5,ABS(N(F25))<=0.5),"PASS","FAIL") -> PASS
A26: CF: CFF sum | B26: =SUM(CF_Hist!B40:B45)-CF_Hist!B46 -> 0 | C26: =SUM(CF_Hist!C40:C45)-CF_Hist!C46 -> 0 | D26: =SUM(CF_Hist!D40:D45)-CF_Hist!D46 -> 0 | E26: =SUM(CF_Hist!E40:E45)-CF_Hist!E46 -> 0 | F26: =SUM(CF_Hist!F40:F45)-CF_Hist!F46 -> 0 | G26: =IF(AND(ABS(N(B26))<=0.5,ABS(N(C26))<=0.5,ABS(N(D26))<=0.5,ABS(N(E26))<=0.5,ABS(N(F26))<=0.5),"PASS","FAIL") -> PASS
A27: CF: Net change = CFO+CFI+CFF+reclass+FX | B27: =CF_Hist!B14+CF_Hist!B37+CF_Hist!B46+N(CF_Hist!B48)+CF_Hist!B49-CF_Hist!B50 -> 0 | C27: =CF_Hist!C14+CF_Hist!C37+CF_Hist!C46+N(CF_Hist!C48)+CF_Hist!C49-CF_Hist!C50 -> 0 | D27: =CF_Hist!D14+CF_Hist!D37+CF_Hist!D46+N(CF_Hist!D48)+CF_Hist!D49-CF_Hist!D50 -> 0 | E27: =CF_Hist!E14+CF_Hist!E37+CF_Hist!E46+N(CF_Hist!E48)+CF_Hist!E49-CF_Hist!E50 -> 0 | F27: =CF_Hist!F14+CF_Hist!F37+CF_Hist!F46+N(CF_Hist!F48)+CF_Hist!F49-CF_Hist!F50 -> 0 | G27: =IF(AND(ABS(N(B27))<=0.5,ABS(N(C27))<=0.5,ABS(N(D27))<=0.5,ABS(N(E27))<=0.5,ABS(N(F27))<=0.5),"PASS","FAIL") -> PASS
A28: CF: End cash = begin + change | B28: =CF_Hist!B51+CF_Hist!B50-CF_Hist!B52 -> 0 | C28: =CF_Hist!C51+CF_Hist!C50-CF_Hist!C52 -> 0 | D28: =CF_Hist!D51+CF_Hist!D50-CF_Hist!D52 -> 0 | E28: =CF_Hist!E51+CF_Hist!E50-CF_Hist!E52 -> 0 | F28: =CF_Hist!F51+CF_Hist!F50-CF_Hist!F52 -> 0 | G28: =IF(AND(ABS(N(B28))<=0.5,ABS(N(C28))<=0.5,ABS(N(D28))<=0.5,ABS(N(E28))<=0.5,ABS(N(F28))<=0.5),"PASS","FAIL") -> PASS
A29: X: CF end cash = BS cash | B29: =CF_Hist!B52-BS_Hist!B7 -> 0 | C29: =CF_Hist!C52-BS_Hist!C7 -> 0 | D29: =CF_Hist!D52-BS_Hist!D7 -> 0 | E29: =CF_Hist!E52-BS_Hist!E7 -> 0 | F29: =CF_Hist!F52-BS_Hist!F7 -> 0 | G29: =IF(AND(ABS(N(B29))<=0.5,ABS(N(C29))<=0.5,ABS(N(D29))<=0.5,ABS(N(E29))<=0.5,ABS(N(F29))<=0.5),"PASS","FAIL") -> PASS
A30: X: CF profit = IS profit | B30: =CF_Hist!B6-IS_Hist!B17 -> 0 | C30: =CF_Hist!C6-IS_Hist!C17 -> 0 | D30: =CF_Hist!D6-IS_Hist!D17 -> 0 | E30: =CF_Hist!E6-IS_Hist!E17 -> 0 | F30: =CF_Hist!F6-IS_Hist!F17 -> 0 | G30: =IF(AND(ABS(N(B30))<=0.5,ABS(N(C30))<=0.5,ABS(N(D30))<=0.5,ABS(N(E30))<=0.5,ABS(N(F30))<=0.5),"PASS","FAIL") -> PASS
A31: SCE: Opening parent = prior-year closing parent (FY22-FY25) | C31: =SCE_Hist!C11-SCE_Hist!B41 -> 0 | D31: =SCE_Hist!D11-SCE_Hist!C41 -> 0 | E31: =SCE_Hist!E11-SCE_Hist!D41 -> 0 | F31: =SCE_Hist!F11-SCE_Hist!E41 -> 0 | G31: =IF(AND(ABS(N(C31))<=0.5,ABS(N(D31))<=0.5,ABS(N(E31))<=0.5,ABS(N(F31))<=0.5),"PASS","FAIL") -> PASS
A32: SCE: Opening nci = prior-year closing nci (FY22-FY25) | C32: =SCE_Hist!C12-SCE_Hist!B42 -> 0 | D32: =SCE_Hist!D12-SCE_Hist!C42 -> 0 | E32: =SCE_Hist!E12-SCE_Hist!D42 -> 0 | F32: =SCE_Hist!F12-SCE_Hist!E42 -> 0 | G32: =IF(AND(ABS(N(C32))<=0.5,ABS(N(D32))<=0.5,ABS(N(E32))<=0.5,ABS(N(F32))<=0.5),"PASS","FAIL") -> PASS
A33: SCE: Opening tot = prior-year closing tot (FY22-FY25) | C33: =SCE_Hist!C13-SCE_Hist!B43 -> 0 | D33: =SCE_Hist!D13-SCE_Hist!C43 -> 0 | E33: =SCE_Hist!E13-SCE_Hist!D43 -> 0 | F33: =SCE_Hist!F13-SCE_Hist!E43 -> 0 | G33: =IF(AND(ABS(N(C33))<=0.5,ABS(N(D33))<=0.5,ABS(N(E33))<=0.5,ABS(N(F33))<=0.5),"PASS","FAIL") -> PASS
A34: SCE: TCI = Profit + OCI (parent) | B34: =SCE_Hist!B16+SCE_Hist!B19-SCE_Hist!B22 -> 0 | C34: =SCE_Hist!C16+SCE_Hist!C19-SCE_Hist!C22 -> 0 | D34: =SCE_Hist!D16+SCE_Hist!D19-SCE_Hist!D22 -> 0 | E34: =SCE_Hist!E16+SCE_Hist!E19-SCE_Hist!E22 -> 0 | F34: =SCE_Hist!F16+SCE_Hist!F19-SCE_Hist!F22 -> 0 | G34: =IF(AND(ABS(N(B34))<=0.5,ABS(N(C34))<=0.5,ABS(N(D34))<=0.5,ABS(N(E34))<=0.5,ABS(N(F34))<=0.5),"PASS","FAIL") -> PASS
A35: SCE: TCI = Profit + OCI (nci) | B35: =SCE_Hist!B17+SCE_Hist!B20-SCE_Hist!B23 -> 0 | C35: =SCE_Hist!C17+SCE_Hist!C20-SCE_Hist!C23 -> 0 | D35: =SCE_Hist!D17+SCE_Hist!D20-SCE_Hist!D23 -> 0 | E35: =SCE_Hist!E17+SCE_Hist!E20-SCE_Hist!E23 -> 0 | F35: =SCE_Hist!F17+SCE_Hist!F20-SCE_Hist!F23 -> 0 | G35: =IF(AND(ABS(N(B35))<=0.5,ABS(N(C35))<=0.5,ABS(N(D35))<=0.5,ABS(N(E35))<=0.5,ABS(N(F35))<=0.5),"PASS","FAIL") -> PASS
A36: SCE: TCI = Profit + OCI (total) | B36: =SCE_Hist!B18+SCE_Hist!B21-SCE_Hist!B24 -> 0 | C36: =SCE_Hist!C18+SCE_Hist!C21-SCE_Hist!C24 -> 0 | D36: =SCE_Hist!D18+SCE_Hist!D21-SCE_Hist!D24 -> 0 | E36: =SCE_Hist!E18+SCE_Hist!E21-SCE_Hist!E24 -> 0 | F36: =SCE_Hist!F18+SCE_Hist!F21-SCE_Hist!F24 -> 0 | G36: =IF(AND(ABS(N(B36))<=0.5,ABS(N(C36))<=0.5,ABS(N(D36))<=0.5,ABS(N(E36))<=0.5,ABS(N(F36))<=0.5),"PASS","FAIL") -> PASS
A37: SCE: Total transactions with owners = Dividends + Other (parent) | B37: =SCE_Hist!B25+SCE_Hist!B28-SCE_Hist!B31 -> 0 | C37: =SCE_Hist!C25+SCE_Hist!C28-SCE_Hist!C31 -> 0 | D37: =SCE_Hist!D25+SCE_Hist!D28-SCE_Hist!D31 -> 0 | E37: =SCE_Hist!E25+SCE_Hist!E28-SCE_Hist!E31 -> 0 | F37: =SCE_Hist!F25+SCE_Hist!F28-SCE_Hist!F31 -> 0 | G37: =IF(AND(ABS(N(B37))<=0.5,ABS(N(C37))<=0.5,ABS(N(D37))<=0.5,ABS(N(E37))<=0.5,ABS(N(F37))<=0.5),"PASS","FAIL") -> PASS
A38: SCE: Total transactions with owners = Dividends + Other (nci) | B38: =SCE_Hist!B26+SCE_Hist!B29-SCE_Hist!B32 -> 0 | C38: =SCE_Hist!C26+SCE_Hist!C29-SCE_Hist!C32 -> 0 | D38: =SCE_Hist!D26+SCE_Hist!D29-SCE_Hist!D32 -> 0 | E38: =SCE_Hist!E26+SCE_Hist!E29-SCE_Hist!E32 -> 0 | F38: =SCE_Hist!F26+SCE_Hist!F29-SCE_Hist!F32 -> 0 | G38: =IF(AND(ABS(N(B38))<=0.5,ABS(N(C38))<=0.5,ABS(N(D38))<=0.5,ABS(N(E38))<=0.5,ABS(N(F38))<=0.5),"PASS","FAIL") -> PASS
A39: SCE: Total transactions with owners = Dividends + Other (total) | B39: =SCE_Hist!B27+SCE_Hist!B30-SCE_Hist!B33 -> 0 | C39: =SCE_Hist!C27+SCE_Hist!C30-SCE_Hist!C33 -> 0 | D39: =SCE_Hist!D27+SCE_Hist!D30-SCE_Hist!D33 -> 0 | E39: =SCE_Hist!E27+SCE_Hist!E30-SCE_Hist!E33 -> 0 | F39: =SCE_Hist!F27+SCE_Hist!F30-SCE_Hist!F33 -> 0 | G39: =IF(AND(ABS(N(B39))<=0.5,ABS(N(C39))<=0.5,ABS(N(D39))<=0.5,ABS(N(E39))<=0.5,ABS(N(F39))<=0.5),"PASS","FAIL") -> PASS
A40: SCE: Closing parent = Opening + TCI + Total txns (parent) | B40: =SCE_Hist!B11+SCE_Hist!B22+SCE_Hist!B31-SCE_Hist!B41 -> 0 | C40: =SCE_Hist!C11+SCE_Hist!C22+SCE_Hist!C31-SCE_Hist!C41 -> 0 | D40: =SCE_Hist!D11+SCE_Hist!D22+SCE_Hist!D31-SCE_Hist!D41 -> 0 | E40: =SCE_Hist!E11+SCE_Hist!E22+SCE_Hist!E31-SCE_Hist!E41 -> 0 | F40: =SCE_Hist!F11+SCE_Hist!F22+SCE_Hist!F31-SCE_Hist!F41 -> 0 | G40: =IF(AND(ABS(N(B40))<=0.5,ABS(N(C40))<=0.5,ABS(N(D40))<=0.5,ABS(N(E40))<=0.5,ABS(N(F40))<=0.5),"PASS","FAIL") -> PASS
A41: SCE: Closing NCI = Opening + TCI + Total txns (NCI) | B41: =SCE_Hist!B12+SCE_Hist!B23+SCE_Hist!B32-SCE_Hist!B42 -> 0 | C41: =SCE_Hist!C12+SCE_Hist!C23+SCE_Hist!C32-SCE_Hist!C42 -> 0 | D41: =SCE_Hist!D12+SCE_Hist!D23+SCE_Hist!D32-SCE_Hist!D42 -> 0 | E41: =SCE_Hist!E12+SCE_Hist!E23+SCE_Hist!E32-SCE_Hist!E42 -> 0 | F41: =SCE_Hist!F12+SCE_Hist!F23+SCE_Hist!F32-SCE_Hist!F42 -> 0 | G41: =IF(AND(ABS(N(B41))<=0.5,ABS(N(C41))<=0.5,ABS(N(D41))<=0.5,ABS(N(E41))<=0.5,ABS(N(F41))<=0.5),"PASS","FAIL") -> PASS
...

Sheet Sources_Audited
A1: Audited source register — Samsung Electronics consolidated FS (samsung.com IR PDFs)
A3: Model year | B3: Source report | C3: Files (BS / IS+CI / CF) | D3: Implied USD presentation rate (KRW/USD)
A4: FY2021A | B4: FY2021 audited consolidated FS (Note 2.29 USD convenience translation) | C4: 2021_con_quarter04_bs.pdf | _soi.pdf | _cf.pdf | D4: =B21 -> 1144.09
A5: FY2022A + FY2023A | B5: FY2023 audited consolidated FS (comparatives used for FY2022; Note 2.18) | C5: 2023_con_quarter04_bs.pdf | _soi.pdf | _cf.pdf | D5: =D21 -> 1306.12
A6: FY2024A + FY2025A | B6: FY2025 audited consolidated FS (comparatives used for FY2024; Note 2.18) | C6: 2025_con_quarter04_bs.pdf | _soi.pdf | _cf.pdf | D6: =F21 -> 1421.89
A8: Notes: statements entered as published constants (KRW millions); all recomputation in Checks_TieOut. Statement of changes in equity (sce PDFs) and note-level schedules pending next elevation pass. Duplicate "(1)" PDF copies in folder are byte-identical downloads.
A9: Prior Historical sheet values (USD mm) are inconsistent with audited USD presentation (e.g. FY2025 revenue 224,356 vs audited USD 234,622) — presentation-currency policy decision pending before rewiring Forecast/Valuation.
A11: Statement of Changes in Equity (SCE) — audited source register
A12: Model year | B12: Source report | C12: File
A13: FY2021A | B13: FY2021 audited consolidated FS SCE | C13: 2021_con_quarter04_sce.pdf
A14: FY2022A | B14: FY2022 audited consolidated FS SCE (also carried as comparative in FY2023 SCE) | C14: 2022_con_quarter04_sce.pdf
A15: FY2023A | B15: FY2023 audited consolidated FS SCE | C15: 2023_con_quarter04_sce.pdf
A16: FY2024A | B16: FY2024 SCE not separately extractable (2024_con_quarter04_sce.pdf yielded no text layer); used as comparative year in FY2025 audited consolidated FS SCE instead — same fleet, not an external source | C16: 2025_con_quarter04_sce.pdf (FY2024 comparative column)
A17: FY2025A | B17: FY2025 audited consolidated FS SCE | C17: 2025_con_quarter04_sce.pdf
A19: USD conversion rates by year (KRW per USD) — implied from audited convenience-translation notes; interpolated where not separately disclosed
A20: Metric | B20: FY2021A | C20: FY2022A | D20: FY2023A | E20: FY2024A | F20: FY2025A
A21: Rate (KRW/USD) | B21: 1144.09 | C21: =AVERAGE(B21,D21) -> 1225.105 | D21: 1306.12 | E21: =AVERAGE(D21,F21) -> 1364.005 | F21: 1421.89
A22: Rate basis | B22: Documented (FY2021 audited FS, Note 2.29 USD convenience translation) | C22: Interpolated (linear, average of FY2021A and FY2023A documented anchors — FY2022 audited FS did not carry a USD convenience-translation column) | D22: Documented (FY2023 audited FS, Note 2.18 USD convenience translation) | E22: Interpolated (linear, average of FY2023A and FY2025A documented anchors — FY2024 audited FS did not carry a USD convenience-translation column) | F22: Documented (FY2025 audited FS, Note 2.18 USD convenience translation)
A24: Rewire pass (run 41538014): added SCE_Hist (audited constants), USD_Hist (formula layer converting IS_Hist/BS_Hist/CF_Hist to USD at the rates above), rewired Forecast base year + Assumptions Base-case drivers (revenue growth, EBIT margin, tax rate, capex/revenue, D&A/revenue proxy) to reference the audited KRW base directly (see Change_Log). Only NWC/incremental-revenue remains a sector-typical placeholder — Samsung does not disclose working-capital detail separately in the headline notes extracted here; flagged in Assumptions!F10, not sourced from audited statements.

Sheet SCE_Hist
A1: Samsung Electronics — Consolidated Statement of Changes in Equity (audited)
A2: KRW millions. FY2021/FY2022/FY2023 per FY2021/FY2023 audited FS; FY2024/FY2025 per FY2025 audited FS (samsung.com IR). Extracted from *_sce.pdf via pdftotext -layout.
A4: Line item | B4: FY2021A | C4: FY2022A | D4: FY2023A | E4: FY2024A | F4: FY2025A
A5: Opening balance (Jan 1)
A6: Preference shares | B6: 119467 | C6: 119467 | D6: 119467 | E6: 119467 | F6: 119467
A7: Ordinary shares | B7: 778047 | C7: 778047 | D7: 778047 | E7: 778047 | F7: 778047
A8: Share premium | B8: 4403893 | C8: 4403893 | D8: 4403893 | E8: 4403893 | F8: 4403893
A9: Retained earnings | B9: 271068211 | C9: 293064763 | D9: 337946407 | E9: 346652238 | F9: 370513188
A10: Other components of equity | B10: -8687155 | C10: -2128473 | D10: 1938328 | E10: 1280130 | F10: 15873008
A11: Equity attributable to owners of the parent company | B11: 267670331 | C11: 296237697 | D11: 345186142 | E11: 353233775 | F11: 391687603
A12: Non-controlling interests | B12: 8277685 | C12: 8662234 | D12: 9563462 | E12: 10444090 | F12: 10504467
A13: Total equity | B13: 275948016 | C13: 304899931 | D13: 354749604 | E13: 363677865 | F13: 402192070
A15: Movements during the year
A16: Profit for the year — owners of parent | B16: 39243791 | C16: 54730018 | D16: 14473401 | E16: 33621363 | F16: 44260956
A17: Profit for the year — non-controlling interests | B17: 663659 | C17: 924059 | D17: 1013699 | E17: 829988 | F17: 945849
A18: Profit for the year — total | B18: 39907450 | C18: 55654077 | D18: 15487100 | E18: 34451351 | F18: 45206805
A19: Other comprehensive income — owners of parent | B19: 9794121 | C19: 4015089 | D19: 3372260 | E19: 16426836 | F19: 5643007
A20: Other comprehensive income — non-controlling interests | B20: 208178 | C20: -9425 | D20: -21949 | E20: 418151 | F20: 440712
A21: Other comprehensive income — total | B21: 10002299 | C21: 4005664 | D21: 3350311 | E21: 16844987 | F21: 6083719
A22: Total comprehensive income — owners of parent | B22: 49037912 | C22: 58745107 | D22: 17845661 | E22: 50048199 | F22: 49903963
A23: Total comprehensive income — non-controlling interests | B23: 871837 | C23: 914634 | D23: 991750 | E23: 1248139 | F23: 1386561
A24: Total comprehensive income — total | B24: 49909749 | C24: 59659741 | D24: 18837411 | E24: 51296338 | F24: 51290524
A25: Dividends declared — owners of parent | B25: -20480721 | C25: -9809437 | D25: -9809437 | E25: -9809437 | F25: -9808728
A26: Dividends declared — non-controlling interests | B26: -32005 | C26: -5523 | D26: -101984 | E26: -1102625 | F26: -87444
A27: Dividends declared — total | B27: -20512726 | C27: -9814960 | D27: -9911421 | E27: -10912062 | F27: -9896172
... A33: Total transactions with owners — total | B33: -20957834 | C33: -9810068 | D33: -9909150 | E33: -12782133 | F33: -17162257
A35: Closing balance (Dec 31)
A36: Preference shares | B36: 119467 | C36: 119467 | D36: 119467 | E36: 119467 | F36: 119467
A37: Ordinary shares | B37: 778047 | C37: 778047 | D37: 778047 | E37: 778047 | F37: 778047
A38: Share premium | B38: 4403893 | C38: 4403893 | D38: 4403893 | E38: 4403893 | F38: 4403893
A39: Retained earnings | B39: 293064763 | C39: 337946407 | D39: 346652238 | E39: 370513188 | F39: 402135600
A40: Other components of equity | B40: -2128473 | C40: 1938328 | D40: 1280130 | E40: 15873008 | F40: 16876248
A41: Equity attributable to owners of the parent company | B41: 296237697 | C41: 345186142 | D41: 353233775 | E41: 391687603 | F41: 424313255
A42: Non-controlling interests | B42: 8662234 | C42: 9563462 | D42: 10444090 | E42: 10504467 | F42: 12007082
A43: Total equity | B43: 304899931 | C43: 354749604 | D43: 363677865 | E43: 402192070 | F43: 436320337

Sheet USD_Hist
A1: Samsung Electronics — USD conversion layer (documented/interpolated implied rates)
A2: USD millions. Native KRW values from IS_Hist/CF_Hist/BS_Hist (audited constants) divided by the FX rate row below. FY2021/FY2023/FY2025 rates are audited convenience-translation implied rates (Sources_Audited); FY2022/FY2024 rates are linear interpolations between adjacent documented anchors (not separately audited).
A4: Line item | B4: FY2021A | C4: FY2022A | D4: FY2023A | E4: FY2024A | F4: FY2025A
A5: FX rate used (KRW per USD) | B5: =Sources_Audited!B21 -> 1144.09 | C5: =Sources_Audited!C21 -> 1225.105 | D5: =Sources_Audited!D21 -> 1306.12 | E5: =Sources_Audited!E21 -> 1364.005 | F5: =Sources_Audited!F21 -> 1421.89
A6: Revenue | B6: =IS_Hist!B5/B5 -> 244390.56 | C6: =IS_Hist!C5/C5 -> 246698.33 | D6: =IS_Hist!D5/D5 -> 198247.86 | E6: =IS_Hist!E5/E5 -> 220579.03 | F6: =IS_Hist!F5/F5 -> 234621.48
A7: Gross profit | B7: =IS_Hist!B7/B5 -> 98937.546 | C7: =IS_Hist!C7/C5 -> 91575.489 | D7: =IS_Hist!D7/D5 -> 60137.594 | E7: =IS_Hist!E7/E5 -> 83803.677 | F7: =IS_Hist!F7/F5 -> 92391.412
A8: Operating profit (EBIT) | B8: =IS_Hist!B9/B5 -> 45130.939 | C8: =IS_Hist!C9/C5 -> 35406.459 | D8: =IS_Hist!D9/D5 -> 5027.8504 | E8: =IS_Hist!E9/E5 -> 23992.552 | F8: =IS_Hist!F9/F5 -> 30664.152
A9: Net income (owners of parent) | B9: =IS_Hist!B20/B5 -> 34301.315 | C9: =IS_Hist!C20/C5 -> 44673.737 | D9: =IS_Hist!D20/D5 -> 11081.218 | E9: =IS_Hist!E20/E5 -> 24649.003 | F9: =IS_Hist!F20/F5 -> 31128.256
A10: Net cash provided by operating activities | B10: =CF_Hist!B14/B5 -> 56905.88 | C10: =CF_Hist!C14/C5 -> 50755.932 | D10: =CF_Hist!D14/D5 -> 33792.781 | E10: =CF_Hist!E14/E5 -> 53506.124 | F10: =CF_Hist!F14/F5 -> 60001.229
A11: Acquisition of property, plant and equipment (capex, outflow negative) | B11: =CF_Hist!B29/B5 -> -41187.412 | C11: =CF_Hist!C29/C5 -> -40347.911 | D11: =CF_Hist!D29/D5 -> -44108.728 | E11: =CF_Hist!E29/E5 -> -37687.805 | F11: =CF_Hist!F29/F5 -> -33421.839
A12: Total assets | B12: =BS_Hist!B28/B5 -> 372891.26 | C12: =BS_Hist!C28/C5 -> 366029.45 | D12: =BS_Hist!D28/D5 -> 349053.67 | E12: =BS_Hist!E28/E5 -> 377221.45 | F12: =BS_Hist!F28/F5 -> 398724.31
A13: Total liabilities | B13: =BS_Hist!B53/B5 -> 106391.3 | C13: =BS_Hist!C53/C5 -> 76462.755 | D13: =BS_Hist!D53/D5 -> 70612.283 | E13: =BS_Hist!E53/E5 -> 82360.312 | F13: =BS_Hist!F53/F5 -> 91864.893
A14: Total equity | B14: =BS_Hist!B63/B5 -> 266499.95 | C14: =BS_Hist!C63/C5 -> 289566.69 | D14: =BS_Hist!D63/D5 -> 278441.39 | E14: =BS_Hist!E63/E5 -> 294861.14 | F14: =BS_Hist!F63/F5 -> 306859.42
A15: Cash and cash equivalents | B15: =BS_Hist!B7/B5 -> 34115.686 | C15: =BS_Hist!C7/C5 -> 40552.206 | D15: =BS_Hist!D7/D5 -> 52890.158 | E15: =BS_Hist!E7/E5 -> 39373.447 | F15: =BS_Hist!F7/F5 -> 40689.771
